{"jsonrpc":"2.0","method":"subscription","params":{"channel":"book.ETH-PERPETUAL.raw","data":{"timestamp":1734114541170,"type":"change","change_id":15557282163,"instrument_name":"ETH-PERPETUAL","bids":[],"asks":[["new",3898.25,8.0e4]],"prev_change_id":15557282162}}}
{"jsonrpc":"2.0","method":"subscription","params":{"channel":"book.ETH-PERPETUAL.raw","data":{"timestamp":1734114541170,"type":"change","change_id":15557282163,"instrument_name":"ETH-PERPETUAL","bids":[],"asks":[["new",3898.25,8.0e4]],"prev_change_id":15557282162}}}
{"jsonrpc":"2.0","method":"subscription","params":{"channel":"book.ETH-PERPETUAL.raw","data":{"timestamp":1734114541172,"type":"change","change_id":15557282164,"instrument_name":"ETH-PERPETUAL","bids":[["change",3880.85,1.0e5]],"asks":[],"prev_change_id":15557282163}}}
{"jsonrpc":"2.0","method":"subscription","params":{"channel":"book.ETH-PERPETUAL.raw","data":{"timestamp":1734114541172,"type":"change","change_id":15557282164,"instrument_name":"ETH-PERPETUAL","bids":[["change",3880.85,1.0e5]],"asks":[],"prev_change_id":15557282163}}}
{"jsonrpc":"2.0","method":"subscription","params":{"channel":"book.ETH-PERPETUAL.raw","data":{"timestamp":1734114541174,"type":"change","change_id":15557282165,"instrument_name":"ETH-PERPETUAL","bids":[],"asks":[["change",3898.25,1.0e5]],"prev_change_id":15557282164}}}
{"jsonrpc":"2.0","method":"subscription","params":{"channel":"book.ETH-PERPETUAL.raw","data":{"timestamp":1734114541174,"type":"change","change_id":15557282165,"instrument_name":"ETH-PERPETUAL","bids":[],"asks":[["change",3898.25,1.0e5]],"prev_change_id":15557282164}}}
{"jsonrpc":"2.0","method":"subscription","params":{"channel":"book.ETH-PERPETUAL.raw","data":{"timestamp":1734114541176,"type":"change","change_id":15557282166,"instrument_name":"ETH-PERPETUAL","bids":[["change",3880.85,1.8e5]],"asks":[],"prev_change_id":15557282165}}}
{"jsonrpc":"2.0","method":"subscription","params":{"channel":"book.ETH-PERPETUAL.raw","data":{"timestamp":1734114541176,"type":"change","change_id":15557282166,"instrument_name":"ETH-PERPETUAL","bids":[["change",3880.85,1.8e5]],"asks":[],"prev_change_id":15557282165}}}
{"jsonrpc":"2.0","method":"subscription","params":{"channel":"book.ETH-PERPETUAL.raw","data":{"timestamp":1734114541177,"type":"change","change_id":15557282167,"instrument_name":"ETH-PERPETUAL","bids":[],"asks":[["change",3898.25,1.8e5]],"prev_change_id":15557282166}}}
{"jsonrpc":"2.0","method":"subscription","params":{"channel":"book.ETH-PERPETUAL.raw","data":{"timestamp":1734114541177,"type":"change","change_id":15557282167,"instrument_name":"ETH-PERPETUAL","bids":[],"asks":[["change",3898.25,1.8e5]],"prev_change_id":15557282166}}}
{"jsonrpc":"2.0","method":"subscription","params":{"channel":"book.ETH-PERPETUAL.raw","data":{"timestamp":1734114541179,"type":"change","change_id":15557282168,"instrument_name":"ETH-PERPETUAL","bids":[["change",3880.85,2.0e5]],"asks":[],"prev_change_id":15557282167}}}
{"jsonrpc":"2.0","method":"subscription","params":{"channel":"book.ETH-PERPETUAL.raw","data":{"timestamp":1734114541179,"type":"change","change_id":15557282168,"instrument_name":"ETH-PERPETUAL","bids":[["change",3880.85,2.0e5]],"asks":[],"prev_change_id":15557282167}}}
{"jsonrpc":"2.0","method":"subscription","params":{"channel":"book.ETH-PERPETUAL.raw","data":{"timestamp":1734114541180,"type":"change","change_id":15557282169,"instrument_name":"ETH-PERPETUAL","bids":[],"asks":[["change",3898.25,2.0e5]],"prev_change_id":15557282168}}}
{"jsonrpc":"2.0","method":"subscription","params":{"channel":"book.ETH-PERPETUAL.raw","data":{"timestamp":1734114541180,"type":"change","change_id":15557282169,"instrument_name":"ETH-PERPETUAL","bids":[],"asks":[["change",3898.25,2.0e5]],"prev_change_id":15557282168}}}
{"jsonrpc":"2.0","method":"subscription","params":{"channel":"book.ETH-PERPETUAL.raw","data":{"timestamp":1734114541260,"type":"change","change_id":15557282170,"instrument_name":"ETH-PERPETUAL","bids":[["delete",3880.85,0.0]],"asks":[["delete",3898.25,0.0]],"prev_change_id":15557282169}}}
{"jsonrpc":"2.0","method":"subscription","params":{"channel":"book.ETH-PERPETUAL.raw","data":{"timestamp":1734114541260,"type":"change","change_id":15557282170,"instrument_name":"ETH-PERPETUAL","bids":[["delete",3880.85,0.0]],"asks":[["delete",3898.25,0.0]],"prev_change_id":15557282169}}}
{"jsonrpc":"2.0","method":"subscription","params":{"channel":"book.ETH-PERPETUAL.raw","data":{"timestamp":1734114541442,"type":"change","change_id":15557282171,"instrument_name":"ETH-PERPETUAL","bids":[["new",3880.95,8.0e4]],"asks":[],"prev_change_id":15557282170}}}
{"jsonrpc":"2.0","method":"subscription","params":{"channel":"book.ETH-PERPETUAL.raw","data":{"timestamp":1734114541442,"type":"change","change_id":15557282171,"instrument_name":"ETH-PERPETUAL","bids":[["new",3880.95,8.0e4]],"asks":[],"prev_change_id":15557282170}}}
{"jsonrpc":"2.0","method":"subscription","params":{"channel":"book.ETH-PERPETUAL.raw","data":{"timestamp":1734114541444,"type":"change","change_id":15557282172,"instrument_name":"ETH-PERPETUAL","bids":[],"asks":[["new",3898.2,8.0e4]],"prev_change_id":15557282171}}}
{"jsonrpc":"2.0","method":"subscription","params":{"channel":"book.ETH-PERPETUAL.raw","data":{"timestamp":1734114541444,"type":"change","change_id":15557282172,"instrument_name":"ETH-PERPETUAL","bids":[],"asks":[["new",3898.2,8.0e4]],"prev_change_id":15557282171}}}
{"jsonrpc":"2.0","method":"subscription","params":{"channel":"book.ETH-PERPETUAL.raw","data":{"timestamp":1734114541445,"type":"change","change_id":15557282173,"instrument_name":"ETH-PERPETUAL","bids":[["change",3880.95,1.6e5]],"asks":[],"prev_change_id":15557282172}}}
{"jsonrpc":"2.0","method":"subscription","params":{"channel":"book.ETH-PERPETUAL.raw","data":{"timestamp":1734114541445,"type":"change","change_id":15557282173,"instrument_name":"ETH-PERPETUAL","bids":[["change",3880.95,1.6e5]],"asks":[],"prev_change_id":15557282172}}}
{"jsonrpc":"2.0","method":"subscription","params":{"channel":"book.ETH-PERPETUAL.raw","data":{"timestamp":1734114541448,"type":"change","change_id":15557282174,"instrument_name":"ETH-PERPETUAL","bids":[],"asks":[["change",3898.2,1.6e5]],"prev_change_id":15557282173}}}
{"jsonrpc":"2.0","method":"subscription","params":{"channel":"book.ETH-PERPETUAL.raw","data":{"timestamp":1734114541448,"type":"change","change_id":15557282174,"instrument_name":"ETH-PERPETUAL","bids":[],"asks":[["change",3898.2,1.6e5]],"prev_change_id":15557282173}}}
{"jsonrpc":"2.0","method":"subscription","params":{"channel":"book.ETH-PERPETUAL.raw","data":{"timestamp":1734114541579,"type":"change","change_id":15557282176,"instrument_name":"ETH-PERPETUAL","bids":[["delete",3880.95,0.0]],"asks":[["delete",3898.2,0.0]],"prev_change_id":15557282174}}}
{"jsonrpc":"2.0","method":"subscription","params":{"channel":"book.ETH-PERPETUAL.raw","data":{"timestamp":1734114541579,"type":"change","change_id":15557282176,"instrument_name":"ETH-PERPETUAL","bids":[["delete",3880.95,0.0]],"asks":[["delete",3898.2,0.0]],"prev_change_id":15557282174}}}
{"jsonrpc":"2.0","method":"subscription","params":{"channel":"book.ETH-PERPETUAL.raw","data":{"timestamp":1734114541592,"type":"change","change_id":15557282183,"instrument_name":"ETH-PERPETUAL","bids":[],"asks":[["new",3909.9,500.0],["delete",3921.75,0.0]],"prev_change_id":15557282176}}}
{"jsonrpc":"2.0","method":"subscription","params":{"channel":"book.ETH-PERPETUAL.raw","data":{"timestamp":1734114541592,"type":"change","change_id":15557282183,"instrument_name":"ETH-PERPETUAL","bids":[],"asks":[["new",3909.9,500.0],["delete",3921.75,0.0]],"prev_change_id":15557282176}}}
{"jsonrpc":"2.0","method":"subscription","params":{"channel":"book.ETH-PERPETUAL.raw","data":{"timestamp":1734114541782,"type":"change","change_id":15557282207,"instrument_name":"ETH-PERPETUAL","bids":[["new",3881.0,8.0e4]],"asks":[],"prev_change_id":15557282183}}}
{"jsonrpc":"2.0","method":"subscription","params":{"channel":"book.ETH-PERPETUAL.raw","data":{"timestamp":1734114541782,"type":"change","change_id":15557282207,"instrument_name":"ETH-PERPETUAL","bids":[["new",3881.0,8.0e4]],"asks":[],"prev_change_id":15557282183}}}
{"jsonrpc":"2.0","method":"subscription","params":{"channel":"book.ETH-PERPETUAL.raw","data":{"timestamp":1734114541783,"type":"change","change_id":15557282208,"instrument_name":"ETH-PERPETUAL","bids":[],"asks":[["new",3898.15,8.0e4]],"prev_change_id":15557282207}}}
{"jsonrpc":"2.0","method":"subscription","params":{"channel":"book.ETH-PERPETUAL.raw","data":{"timestamp":1734114541783,"type":"change","change_id":15557282208,"instrument_name":"ETH-PERPETUAL","bids":[],"asks":[["new",3898.15,8.0e4]],"prev_change_id":15557282207}}}
{"jsonrpc":"2.0","method":"subscription","params":{"channel":"book.ETH-PERPETUAL.raw","data":{"timestamp":1734114541784,"type":"change","change_id":15557282209,"instrument_name":"ETH-PERPETUAL","bids":[["change",3881.0,1.0e5]],"asks":[],"prev_change_id":15557282208}}}
{"jsonrpc":"2.0","method":"subscription","params":{"channel":"book.ETH-PERPETUAL.raw","data":{"timestamp":1734114541784,"type":"change","change_id":15557282209,"instrument_name":"ETH-PERPETUAL","bids":[["change",3881.0,1.0e5]],"asks":[],"prev_change_id":15557282208}}}
{"jsonrpc":"2.0","method":"subscription","params":{"channel":"book.ETH-PERPETUAL.raw","data":{"timestamp":1734114541786,"type":"change","change_id":15557282210,"instrument_name":"ETH-PERPETUAL","bids":[["change",3881.0,1.8e5]],"asks":[],"prev_change_id":15557282209}}}
{"jsonrpc":"2.0","method":"subscription","params":{"channel":"book.ETH-PERPETUAL.raw","data":{"timestamp":1734114541786,"type":"change","change_id":15557282210,"instrument_name":"ETH-PERPETUAL","bids":[["change",3881.0,1.8e5]],"asks":[],"prev_change_id":15557282209}}}
{"jsonrpc":"2.0","method":"subscription","params":{"channel":"book.ETH-PERPETUAL.raw","data":{"timestamp":1734114541787,"type":"change","change_id":15557282211,"instrument_name":"ETH-PERPETUAL","bids":[],"asks":[["change",3898.15,1.6e5]],"prev_change_id":15557282210}}}
{"jsonrpc":"2.0","method":"subscription","params":{"channel":"book.ETH-PERPETUAL.raw","data":{"timestamp":1734114541787,"type":"change","change_id":15557282211,"instrument_name":"ETH-PERPETUAL","bids":[],"asks":[["change",3898.15,1.6e5]],"prev_change_id":15557282210}}}
{"jsonrpc":"2.0","method":"subscription","params":{"channel":"book.ETH-PERPETUAL.raw","data":{"timestamp":1734114541796,"type":"change","change_id":15557282212,"instrument_name":"ETH-PERPETUAL","bids":[["change",3881.0,2.0e5]],"asks":[],"prev_change_id":15557282211}}}
{"jsonrpc":"2.0","method":"subscription","params":{"channel":"book.ETH-PERPETUAL.raw","data":{"timestamp":1734114541796,"type":"change","change_id":15557282212,"instrument_name":"ETH-PERPETUAL","bids":[["change",3881.0,2.0e5]],"asks":[],"prev_change_id":15557282211}}}
{"jsonrpc":"2.0","method":"subscription","params":{"channel":"book.ETH-PERPETUAL.raw","data":{"timestamp":1734114541873,"type":"change","change_id":15557282213,"instrument_name":"ETH-PERPETUAL","bids":[["delete",3881.0,0.0]],"asks":[["delete",3898.15,0.0]],"prev_change_id":15557282212}}}
{"jsonrpc":"2.0","method":"subscription","params":{"channel":"book.ETH-PERPETUAL.raw","data":{"timestamp":1734114541873,"type":"change","change_id":15557282213,"instrument_name":"ETH-PERPETUAL","bids":[["delete",3881.0,0.0]],"asks":[["delete",3898.15,0.0]],"prev_change_id":15557282212}}}
{"jsonrpc":"2.0","method":"subscription","params":{"channel":"book.ETH-PERPETUAL.raw","data":{"timestamp":1734114541949,"type":"change","change_id":15557282214,"instrument_name":"ETH-PERPETUAL","bids":[],"asks":[["delete",3917.95,0.0],["new",3929.45,500.0]],"prev_change_id":15557282213}}}
{"jsonrpc":"2.0","method":"subscription","params":{"channel":"book.ETH-PERPETUAL.raw","data":{"timestamp":1734114541949,"type":"change","change_id":15557282214,"instrument_name":"ETH-PERPETUAL","bids":[],"asks":[["delete",3917.95,0.0],["new",3929.45,500.0]],"prev_change_id":15557282213}}}
{"jsonrpc":"2.0","method":"subscription","params":{"channel":"book.ETH-PERPETUAL.raw","data":{"timestamp":1734114542066,"type":"change","change_id":15557282217,"instrument_name":"ETH-PERPETUAL","bids":[["new",3880.95,8.0e4]],"asks":[],"prev_change_id":15557282214}}}
{"jsonrpc":"2.0","method":"subscription","params":{"channel":"book.ETH-PERPETUAL.raw","data":{"timestamp":1734114542066,"type":"change","change_id":15557282217,"instrument_name":"ETH-PERPETUAL","bids":[["new",3880.95,8.0e4]],"asks":[],"prev_change_id":15557282214}}}
{"jsonrpc":"2.0","method":"subscription","params":{"channel":"book.ETH-PERPETUAL.raw","data":{"timestamp":1734114542068,"type":"change","change_id":15557282218,"instrument_name":"ETH-PERPETUAL","bids":[],"asks":[["new",3897.95,8.0e4]],"prev_change_id":15557282217}}}
{"jsonrpc":"2.0","method":"subscription","params":{"channel":"book.ETH-PERPETUAL.raw","data":{"timestamp":1734114542068,"type":"change","change_id":15557282218,"instrument_name":"ETH-PERPETUAL","bids":[],"asks":[["new",3897.95,8.0e4]],"prev_change_id":15557282217}}}
{"jsonrpc":"2.0","method":"subscription","params":{"channel":"book.ETH-PERPETUAL.raw","data":{"timestamp":1734114542070,"type":"change","change_id":15557282219,"instrument_name":"ETH-PERPETUAL","bids":[["change",3880.95,1.0e5]],"asks":[],"prev_change_id":15557282218}}}
{"jsonrpc":"2.0","method":"subscription","params":{"channel":"book.ETH-PERPETUAL.raw","data":{"timestamp":1734114542070,"type":"change","change_id":15557282219,"instrument_name":"ETH-PERPETUAL","bids":[["change",3880.95,1.0e5]],"asks":[],"prev_change_id":15557282218}}}
{"jsonrpc":"2.0","method":"subscription","params":{"channel":"book.ETH-PERPETUAL.raw","data":{"timestamp":1734114542075,"type":"change","change_id":15557282220,"instrument_name":"ETH-PERPETUAL","bids":[["new",3880.8,8.0e4]],"asks":[],"prev_change_id":15557282219}}}
{"jsonrpc":"2.0","method":"subscription","params":{"channel":"book.ETH-PERPETUAL.raw","data":{"timestamp":1734114542075,"type":"change","change_id":15557282220,"instrument_name":"ETH-PERPETUAL","bids":[["new",3880.8,8.0e4]],"asks":[],"prev_change_id":15557282219}}}
{"jsonrpc":"2.0","method":"subscription","params":{"channel":"book.ETH-PERPETUAL.raw","data":{"timestamp":1734114542078,"type":"change","change_id":15557282221,"instrument_name":"ETH-PERPETUAL","bids":[],"asks":[["new",3897.85,8.0e4]],"prev_change_id":15557282220}}}
{"jsonrpc":"2.0","method":"subscription","params":{"channel":"book.ETH-PERPETUAL.raw","data":{"timestamp":1734114542078,"type":"change","change_id":15557282221,"instrument_name":"ETH-PERPETUAL","bids":[],"asks":[["new",3897.85,8.0e4]],"prev_change_id":15557282220}}}
{"jsonrpc":"2.0","method":"subscription","params":{"channel":"book.ETH-PERPETUAL.raw","data":{"timestamp":1734114542082,"type":"change","change_id":15557282222,"instrument_name":"ETH-PERPETUAL","bids":[["change",3880.8,1.0e5]],"asks":[],"prev_change_id":15557282221}}}
{"jsonrpc":"2.0","method":"subscription","params":{"channel":"book.ETH-PERPETUAL.raw","data":{"timestamp":1734114542082,"type":"change","change_id":15557282222,"instrument_name":"ETH-PERPETUAL","bids":[["change",3880.8,1.0e5]],"asks":[],"prev_change_id":15557282221}}}
{"jsonrpc":"2.0","method":"subscription","params":{"channel":"book.ETH-PERPETUAL.raw","data":{"timestamp":1734114542185,"type":"change","change_id":15557282225,"instrument_name":"ETH-PERPETUAL","bids":[["delete",3880.95,0.0],["delete",3880.8,0.0]],"asks":[["delete",3897.85,0.0],["delete",3897.95,0.0]],"prev_change_id":15557282222}}}
{"jsonrpc":"2.0","method":"subscription","params":{"channel":"book.ETH-PERPETUAL.raw","data":{"timestamp":1734114542185,"type":"change","change_id":15557282225,"instrument_name":"ETH-PERPETUAL","bids":[["delete",3880.95,0.0],["delete",3880.8,0.0]],"asks":[["delete",3897.85,0.0],["delete",3897.95,0.0]],"prev_change_id":15557282222}}}
{"jsonrpc":"2.0","method":"subscription","params":{"channel":"book.ETH-PERPETUAL.raw","data":{"timestamp":1734114542372,"type":"change","change_id":15557282226,"instrument_name":"ETH-PERPETUAL","bids":[["new",3880.4,8.0e4]],"asks":[],"prev_change_id":15557282225}}}
{"jsonrpc":"2.0","method":"subscription","params":{"channel":"book.ETH-PERPETUAL.raw","data":{"timestamp":1734114542372,"type":"change","change_id":15557282226,"instrument_name":"ETH-PERPETUAL","bids":[["new",3880.4,8.0e4]],"asks":[],"prev_change_id":15557282225}}}
{"jsonrpc":"2.0","method":"subscription","params":{"channel":"book.ETH-PERPETUAL.raw","data":{"timestamp":1734114542373,"type":"change","change_id":15557282227,"instrument_name":"ETH-PERPETUAL","bids":[],"asks":[["new",3897.3,8.0e4]],"prev_change_id":15557282226}}}
{"jsonrpc":"2.0","method":"subscription","params":{"channel":"book.ETH-PERPETUAL.raw","data":{"timestamp":1734114542373,"type":"change","change_id":15557282227,"instrument_name":"ETH-PERPETUAL","bids":[],"asks":[["new",3897.3,8.0e4]],"prev_change_id":15557282226}}}
{"jsonrpc":"2.0","method":"subscription","params":{"channel":"book.ETH-PERPETUAL.raw","data":{"timestamp":1734114542374,"type":"change","change_id":15557282228,"instrument_name":"ETH-PERPETUAL","bids":[["change",3880.4,1.0e5]],"asks":[],"prev_change_id":15557282227}}}
{"jsonrpc":"2.0","method":"subscription","params":{"channel":"book.ETH-PERPETUAL.raw","data":{"timestamp":1734114542374,"type":"change","change_id":15557282228,"instrument_name":"ETH-PERPETUAL","bids":[["change",3880.4,1.0e5]],"asks":[],"prev_change_id":15557282227}}}
{"jsonrpc":"2.0","method":"subscription","params":{"channel":"book.ETH-PERPETUAL.raw","data":{"timestamp":1734114542376,"type":"change","change_id":15557282229,"instrument_name":"ETH-PERPETUAL","bids":[["new",3880.35,3.2e5]],"asks":[],"prev_change_id":15557282228}}}
{"jsonrpc":"2.0","method":"subscription","params":{"channel":"book.ETH-PERPETUAL.raw","data":{"timestamp":1734114542376,"type":"change","change_id":15557282229,"instrument_name":"ETH-PERPETUAL","bids":[["new",3880.35,3.2e5]],"asks":[],"prev_change_id":15557282228}}}
{"jsonrpc":"2.0","method":"subscription","params":{"channel":"book.ETH-PERPETUAL.raw","data":{"timestamp":1734114542377,"type":"change","change_id":15557282231,"instrument_name":"ETH-PERPETUAL","bids":[["change",3880.4,1.8e5]],"asks":[],"prev_change_id":15557282229}}}
{"jsonrpc":"2.0","method":"subscription","params":{"channel":"book.ETH-PERPETUAL.raw","data":{"timestamp":1734114542377,"type":"change","change_id":15557282231,"instrument_name":"ETH-PERPETUAL","bids":[["change",3880.4,1.8e5]],"asks":[],"prev_change_id":15557282229}}}
{"jsonrpc":"2.0","method":"subscription","params":{"channel":"book.ETH-PERPETUAL.raw","data":{"timestamp":1734114542378,"type":"change","change_id":15557282232,"instrument_name":"ETH-PERPETUAL","bids":[],"asks":[["change",3897.3,1.6e5]],"prev_change_id":15557282231}}}
{"jsonrpc":"2.0","method":"subscription","params":{"channel":"book.ETH-PERPETUAL.raw","data":{"timestamp":1734114542378,"type":"change","change_id":15557282232,"instrument_name":"ETH-PERPETUAL","bids":[],"asks":[["change",3897.3,1.6e5]],"prev_change_id":15557282231}}}
{"jsonrpc":"2.0","method":"subscription","params":{"channel":"book.ETH-PERPETUAL.raw","data":{"timestamp":1734114542380,"type":"change","change_id":15557282233,"instrument_name":"ETH-PERPETUAL","bids":[["change",3880.4,2.0e5]],"asks":[],"prev_change_id":15557282232}}}
{"jsonrpc":"2.0","method":"subscription","params":{"channel":"book.ETH-PERPETUAL.raw","data":{"timestamp":1734114542380,"type":"change","change_id":15557282233,"instrument_name":"ETH-PERPETUAL","bids":[["change",3880.4,2.0e5]],"asks":[],"prev_change_id":15557282232}}}
{"jsonrpc":"2.0","method":"subscription","params":{"channel":"book.ETH-PERPETUAL.raw","data":{"timestamp":1734114542381,"type":"change","change_id":15557282234,"instrument_name":"ETH-PERPETUAL","bids":[["change",3880.35,6.4e5]],"asks":[],"prev_change_id":15557282233}}}
{"jsonrpc":"2.0","method":"subscription","params":{"channel":"book.ETH-PERPETUAL.raw","data":{"timestamp":1734114542381,"type":"change","change_id":15557282234,"instrument_name":"ETH-PERPETUAL","bids":[["change",3880.35,6.4e5]],"asks":[],"prev_change_id":15557282233}}}
{"jsonrpc":"2.0","method":"subscription","params":{"channel":"book.ETH-PERPETUAL.raw","data":{"timestamp":1734114542496,"type":"change","change_id":15557282237,"instrument_name":"ETH-PERPETUAL","bids":[["delete",3880.4,0.0],["delete",3880.35,0.0]],"asks":[["delete",3897.3,0.0]],"prev_change_id":15557282234}}}
{"jsonrpc":"2.0","method":"subscription","params":{"channel":"book.ETH-PERPETUAL.raw","data":{"timestamp":1734114542496,"type":"change","change_id":15557282237,"instrument_name":"ETH-PERPETUAL","bids":[["delete",3880.4,0.0],["delete",3880.35,0.0]],"asks":[["delete",3897.3,0.0]],"prev_change_id":15557282234}}}
{"jsonrpc":"2.0","method":"subscription","params":{"channel":"book.ETH-PERPETUAL.raw","data":{"timestamp":1734114542678,"type":"change","change_id":15557282242,"instrument_name":"ETH-PERPETUAL","bids":[],"asks":[["new",3897.1,8.0e4]],"prev_change_id":15557282237}}}
{"jsonrpc":"2.0","method":"subscription","params":{"channel":"book.ETH-PERPETUAL.raw","data":{"timestamp":1734114542678,"type":"change","change_id":15557282242,"instrument_name":"ETH-PERPETUAL","bids":[],"asks":[["new",3897.1,8.0e4]],"prev_change_id":15557282237}}}
{"jsonrpc":"2.0","method":"subscription","params":{"channel":"book.ETH-PERPETUAL.raw","data":{"timestamp":1734114542679,"type":"change","change_id":15557282243,"instrument_name":"ETH-PERPETUAL","bids":[["new",3880.3,8.0e4]],"asks":[],"prev_change_id":15557282242}}}
{"jsonrpc":"2.0","method":"subscription","params":{"channel":"book.ETH-PERPETUAL.raw","data":{"timestamp":1734114542679,"type":"change","change_id":15557282243,"instrument_name":"ETH-PERPETUAL","bids":[["new",3880.3,8.0e4]],"asks":[],"prev_change_id":15557282242}}}
{"jsonrpc":"2.0","method":"subscription","params":{"channel":"book.ETH-PERPETUAL.raw","data":{"timestamp":1734114542681,"type":"change","change_id":15557282244,"instrument_name":"ETH-PERPETUAL","bids":[],"asks":[["change",3897.1,1.6e5]],"prev_change_id":15557282243}}}
{"jsonrpc":"2.0","method":"subscription","params":{"channel":"book.ETH-PERPETUAL.raw","data":{"timestamp":1734114542681,"type":"change","change_id":15557282244,"instrument_name":"ETH-PERPETUAL","bids":[],"asks":[["change",3897.1,1.6e5]],"prev_change_id":15557282243}}}
{"jsonrpc":"2.0","method":"subscription","params":{"channel":"book.ETH-PERPETUAL.raw","data":{"timestamp":1734114542682,"type":"change","change_id":15557282245,"instrument_name":"ETH-PERPETUAL","bids":[["change",3880.3,1.6e5]],"asks":[],"prev_change_id":15557282244}}}
{"jsonrpc":"2.0","method":"subscription","params":{"channel":"book.ETH-PERPETUAL.raw","data":{"timestamp":1734114542682,"type":"change","change_id":15557282245,"instrument_name":"ETH-PERPETUAL","bids":[["change",3880.3,1.6e5]],"asks":[],"prev_change_id":15557282244}}}
{"jsonrpc":"2.0","method":"subscription","params":{"channel":"book.ETH-PERPETUAL.raw","data":{"timestamp":1734114542808,"type":"change","change_id":15557282248,"instrument_name":"ETH-PERPETUAL","bids":[["delete",3880.3,0.0]],"asks":[["delete",3897.1,0.0]],"prev_change_id":15557282245}}}
{"jsonrpc":"2.0","method":"subscription","params":{"channel":"book.ETH-PERPETUAL.raw","data":{"timestamp":1734114542808,"type":"change","change_id":15557282248,"instrument_name":"ETH-PERPETUAL","bids":[["delete",3880.3,0.0]],"asks":[["delete",3897.1,0.0]],"prev_change_id":15557282245}}}
{"jsonrpc":"2.0","method":"subscription","params":{"channel":"book.ETH-PERPETUAL.raw","data":{"timestamp":1734114543010,"type":"change","change_id":15557282252,"instrument_name":"ETH-PERPETUAL","bids":[],"asks":[["new",3897.3,8.0e4]],"prev_change_id":15557282248}}}
{"jsonrpc":"2.0","method":"subscription","params":{"channel":"book.ETH-PERPETUAL.raw","data":{"timestamp":1734114543010,"type":"change","change_id":15557282252,"instrument_name":"ETH-PERPETUAL","bids":[],"asks":[["new",3897.3,8.0e4]],"prev_change_id":15557282248}}}
{"jsonrpc":"2.0","method":"subscription","params":{"channel":"book.ETH-PERPETUAL.raw","data":{"timestamp":1734114543012,"type":"change","change_id":15557282253,"instrument_name":"ETH-PERPETUAL","bids":[["new",3880.25,8.0e4]],"asks":[],"prev_change_id":15557282252}}}
{"jsonrpc":"2.0","method":"subscription","params":{"channel":"book.ETH-PERPETUAL.raw","data":{"timestamp":1734114543012,"type":"change","change_id":15557282253,"instrument_name":"ETH-PERPETUAL","bids":[["new",3880.25,8.0e4]],"asks":[],"prev_change_id":15557282252}}}
{"jsonrpc":"2.0","method":"subscription","params":{"channel":"book.ETH-PERPETUAL.raw","data":{"timestamp":1734114543014,"type":"change","change_id":15557282254,"instrument_name":"ETH-PERPETUAL","bids":[],"asks":[["change",3897.3,1.0e5]],"prev_change_id":15557282253}}}
{"jsonrpc":"2.0","method":"subscription","params":{"channel":"book.ETH-PERPETUAL.raw","data":{"timestamp":1734114543014,"type":"change","change_id":15557282254,"instrument_name":"ETH-PERPETUAL","bids":[],"asks":[["change",3897.3,1.0e5]],"prev_change_id":15557282253}}}
{"jsonrpc":"2.0","method":"subscription","params":{"channel":"book.ETH-PERPETUAL.raw","data":{"timestamp":1734114543016,"type":"change","change_id":15557282255,"instrument_name":"ETH-PERPETUAL","bids":[],"asks":[["change",3897.3,1.8e5]],"prev_change_id":15557282254}}}
{"jsonrpc":"2.0","method":"subscription","params":{"channel":"book.ETH-PERPETUAL.raw","data":{"timestamp":1734114543016,"type":"change","change_id":15557282255,"instrument_name":"ETH-PERPETUAL","bids":[],"asks":[["change",3897.3,1.8e5]],"prev_change_id":15557282254}}}
{"jsonrpc":"2.0","method":"subscription","params":{"channel":"book.ETH-PERPETUAL.raw","data":{"timestamp":1734114543018,"type":"change","change_id":15557282256,"instrument_name":"ETH-PERPETUAL","bids":[["change",3880.25,1.6e5]],"asks":[],"prev_change_id":15557282255}}}
{"jsonrpc":"2.0","method":"subscription","params":{"channel":"book.ETH-PERPETUAL.raw","data":{"timestamp":1734114543018,"type":"change","change_id":15557282256,"instrument_name":"ETH-PERPETUAL","bids":[["change",3880.25,1.6e5]],"asks":[],"prev_change_id":15557282255}}}
{"jsonrpc":"2.0","method":"subscription","params":{"channel":"book.ETH-PERPETUAL.raw","data":{"timestamp":1734114543020,"type":"change","change_id":15557282257,"instrument_name":"ETH-PERPETUAL","bids":[],"asks":[["change",3897.3,2.0e5]],"prev_change_id":15557282256}}}
{"jsonrpc":"2.0","method":"subscription","params":{"channel":"book.ETH-PERPETUAL.raw","data":{"timestamp":1734114543020,"type":"change","change_id":15557282257,"instrument_name":"ETH-PERPETUAL","bids":[],"asks":[["change",3897.3,2.0e5]],"prev_change_id":15557282256}}}
{"jsonrpc":"2.0","method":"subscription","params":{"channel":"book.ETH-PERPETUAL.raw","data":{"timestamp":1734114543160,"type":"change","change_id":15557282259,"instrument_name":"ETH-PERPETUAL","bids":[["delete",3880.25,0.0]],"asks":[["delete",3897.3,0.0]],"prev_change_id":15557282257}}}
{"jsonrpc":"2.0","method":"subscription","params":{"channel":"book.ETH-PERPETUAL.raw","data":{"timestamp":1734114543160,"type":"change","change_id":15557282259,"instrument_name":"ETH-PERPETUAL","bids":[["delete",3880.25,0.0]],"asks":[["delete",3897.3,0.0]],"prev_change_id":15557282257}}}
{"jsonrpc":"2.0","method":"subscription","params":{"channel":"book.ETH-PERPETUAL.raw","data":{"timestamp":1734114543172,"type":"change","change_id":15557282260,"instrument_name":"ETH-PERPETUAL","bids":[["new",3841.4,700.0],["delete",3833.4,0.0]],"asks":[],"prev_change_id":15557282259}}}
{"jsonrpc":"2.0","method":"subscription","params":{"channel":"book.ETH-PERPETUAL.raw","data":{"timestamp":1734114543172,"type":"change","change_id":15557282260,"instrument_name":"ETH-PERPETUAL","bids":[["new",3841.4,700.0],["delete",3833.4,0.0]],"asks":[],"prev_change_id":15557282259}}}
{"jsonrpc":"2.0","method":"subscription","params":{"channel":"book.ETH-PERPETUAL.raw","data":{"timestamp":1734114543173,"type":"change","change_id":15557282261,"instrument_name":"ETH-PERPETUAL","bids":[["new",3860.8,500.0],["delete",3852.75,0.0]],"asks":[],"prev_change_id":15557282260}}}
{"jsonrpc":"2.0","method":"subscription","params":{"channel":"book.ETH-PERPETUAL.raw","data":{"timestamp":1734114543173,"type":"change","change_id":15557282261,"instrument_name":"ETH-PERPETUAL","bids":[["new",3860.8,500.0],["delete",3852.75,0.0]],"asks":[],"prev_change_id":15557282260}}}
{"jsonrpc":"2.0","method":"subscription","params":{"channel":"book.ETH-PERPETUAL.raw","data":{"timestamp":1734114543419,"type":"change","change_id":15557282263,"instrument_name":"ETH-PERPETUAL","bids":[],"asks":[["new",3897.4,8.0e4]],"prev_change_id":15557282261}}}
{"jsonrpc":"2.0","method":"subscription","params":{"channel":"book.ETH-PERPETUAL.raw","data":{"timestamp":1734114543419,"type":"change","change_id":15557282263,"instrument_name":"ETH-PERPETUAL","bids":[],"asks":[["new",3897.4,8.0e4]],"prev_change_id":15557282261}}}
{"jsonrpc":"2.0","method":"subscription","params":{"channel":"book.ETH-PERPETUAL.raw","data":{"timestamp":1734114543426,"type":"change","change_id":15557282264,"instrument_name":"ETH-PERPETUAL","bids":[["new",3880.35,8.0e4]],"asks":[],"prev_change_id":15557282263}}}
{"jsonrpc":"2.0","method":"subscription","params":{"channel":"book.ETH-PERPETUAL.raw","data":{"timestamp":1734114543426,"type":"change","change_id":15557282264,"instrument_name":"ETH-PERPETUAL","bids":[["new",3880.35,8.0e4]],"asks":[],"prev_change_id":15557282263}}}
{"jsonrpc":"2.0","method":"subscription","params":{"channel":"book.ETH-PERPETUAL.raw","data":{"timestamp":1734114543430,"type":"change","change_id":15557282265,"instrument_name":"ETH-PERPETUAL","bids":[],"asks":[["change",3897.4,1.0e5]],"prev_change_id":15557282264}}}
{"jsonrpc":"2.0","method":"subscription","params":{"channel":"book.ETH-PERPETUAL.raw","data":{"timestamp":1734114543430,"type":"change","change_id":15557282265,"instrument_name":"ETH-PERPETUAL","bids":[],"asks":[["change",3897.4,1.0e5]],"prev_change_id":15557282264}}}
{"jsonrpc":"2.0","method":"subscription","params":{"channel":"book.ETH-PERPETUAL.raw","data":{"timestamp":1734114543431,"type":"change","change_id":15557282266,"instrument_name":"ETH-PERPETUAL","bids":[["change",3880.35,1.0e5]],"asks":[],"prev_change_id":15557282265}}}
{"jsonrpc":"2.0","method":"subscription","params":{"channel":"book.ETH-PERPETUAL.raw","data":{"timestamp":1734114543431,"type":"change","change_id":15557282266,"instrument_name":"ETH-PERPETUAL","bids":[["change",3880.35,1.0e5]],"asks":[],"prev_change_id":15557282265}}}
{"jsonrpc":"2.0","method":"subscription","params":{"channel":"book.ETH-PERPETUAL.raw","data":{"timestamp":1734114543432,"type":"change","change_id":15557282267,"instrument_name":"ETH-PERPETUAL","bids":[],"asks":[["change",3897.4,1.8e5]],"prev_change_id":15557282266}}}
{"jsonrpc":"2.0","method":"subscription","params":{"channel":"book.ETH-PERPETUAL.raw","data":{"timestamp":1734114543432,"type":"change","change_id":15557282267,"instrument_name":"ETH-PERPETUAL","bids":[],"asks":[["change",3897.4,1.8e5]],"prev_change_id":15557282266}}}
{"jsonrpc":"2.0","method":"subscription","params":{"channel":"book.ETH-PERPETUAL.raw","data":{"timestamp":1734114543432,"type":"change","change_id":15557282268,"instrument_name":"ETH-PERPETUAL","bids":[["change",3880.35,1.8e5]],"asks":[],"prev_change_id":15557282267}}}
{"jsonrpc":"2.0","method":"subscription","params":{"channel":"book.ETH-PERPETUAL.raw","data":{"timestamp":1734114543432,"type":"change","change_id":15557282268,"instrument_name":"ETH-PERPETUAL","bids":[["change",3880.35,1.8e5]],"asks":[],"prev_change_id":15557282267}}}
{"jsonrpc":"2.0","method":"subscription","params":{"channel":"book.ETH-PERPETUAL.raw","data":{"timestamp":1734114543433,"type":"change","change_id":15557282269,"instrument_name":"ETH-PERPETUAL","bids":[],"asks":[["change",3897.4,2.0e5]],"prev_change_id":15557282268}}}
{"jsonrpc":"2.0","method":"subscription","params":{"channel":"book.ETH-PERPETUAL.raw","data":{"timestamp":1734114543433,"type":"change","change_id":15557282269,"instrument_name":"ETH-PERPETUAL","bids":[],"asks":[["change",3897.4,2.0e5]],"prev_change_id":15557282268}}}
{"jsonrpc":"2.0","method":"subscription","params":{"channel":"book.ETH-PERPETUAL.raw","data":{"timestamp":1734114543434,"type":"change","change_id":15557282270,"instrument_name":"ETH-PERPETUAL","bids":[["change",3880.35,2.0e5]],"asks":[],"prev_change_id":15557282269}}}
{"jsonrpc":"2.0","method":"subscription","params":{"channel":"book.ETH-PERPETUAL.raw","data":{"timestamp":1734114543434,"type":"change","change_id":15557282270,"instrument_name":"ETH-PERPETUAL","bids":[["change",3880.35,2.0e5]],"asks":[],"prev_change_id":15557282269}}}
{"jsonrpc":"2.0","method":"subscription","params":{"channel":"book.ETH-PERPETUAL.raw","data":{"timestamp":1734114543518,"type":"change","change_id":15557282272,"instrument_name":"ETH-PERPETUAL","bids":[["delete",3880.35,0.0]],"asks":[["delete",3897.4,0.0]],"prev_change_id":15557282270}}}
{"jsonrpc":"2.0","method":"subscription","params":{"channel":"book.ETH-PERPETUAL.raw","data":{"timestamp":1734114543518,"type":"change","change_id":15557282272,"instrument_name":"ETH-PERPETUAL","bids":[["delete",3880.35,0.0]],"asks":[["delete",3897.4,0.0]],"prev_change_id":15557282270}}}
{"jsonrpc":"2.0","method":"subscription","params":{"channel":"book.ETH-PERPETUAL.raw","data":{"timestamp":1734114543572,"type":"change","change_id":15557282273,"instrument_name":"ETH-PERPETUAL","bids":[["new",3868.7,500.0],["delete",3860.5,0.0]],"asks":[],"prev_change_id":15557282272}}}
{"jsonrpc":"2.0","method":"subscription","params":{"channel":"book.ETH-PERPETUAL.raw","data":{"timestamp":1734114543572,"type":"change","change_id":15557282273,"instrument_name":"ETH-PERPETUAL","bids":[["new",3868.7,500.0],["delete",3860.5,0.0]],"asks":[],"prev_change_id":15557282272}}}
{"jsonrpc":"2.0","method":"subscription","params":{"channel":"book.ETH-PERPETUAL.raw","data":{"timestamp":1734114543704,"type":"change","change_id":15557282336,"instrument_name":"ETH-PERPETUAL","bids":[],"asks":[["new",3897.35,8.0e4]],"prev_change_id":15557282273}}}
{"jsonrpc":"2.0","method":"subscription","params":{"channel":"book.ETH-PERPETUAL.raw","data":{"timestamp":1734114543704,"type":"change","change_id":15557282336,"instrument_name":"ETH-PERPETUAL","bids":[],"asks":[["new",3897.35,8.0e4]],"prev_change_id":15557282273}}}
{"jsonrpc":"2.0","method":"subscription","params":{"channel":"book.ETH-PERPETUAL.raw","data":{"timestamp":1734114543706,"type":"change","change_id":15557282338,"instrument_name":"ETH-PERPETUAL","bids":[["new",3880.4,8.0e4]],"asks":[],"prev_change_id":15557282336}}}
{"jsonrpc":"2.0","method":"subscription","params":{"channel":"book.ETH-PERPETUAL.raw","data":{"timestamp":1734114543706,"type":"change","change_id":15557282338,"instrument_name":"ETH-PERPETUAL","bids":[["new",3880.4,8.0e4]],"asks":[],"prev_change_id":15557282336}}}
{"jsonrpc":"2.0","method":"subscription","params":{"channel":"book.ETH-PERPETUAL.raw","data":{"timestamp":1734114543707,"type":"change","change_id":15557282341,"instrument_name":"ETH-PERPETUAL","bids":[["change",3880.4,1.0e5]],"asks":[],"prev_change_id":15557282338}}}
{"jsonrpc":"2.0","method":"subscription","params":{"channel":"book.ETH-PERPETUAL.raw","data":{"timestamp":1734114543707,"type":"change","change_id":15557282341,"instrument_name":"ETH-PERPETUAL","bids":[["change",3880.4,1.0e5]],"asks":[],"prev_change_id":15557282338}}}
{"jsonrpc":"2.0","method":"subscription","params":{"channel":"book.ETH-PERPETUAL.raw","data":{"timestamp":1734114543709,"type":"change","change_id":15557282344,"instrument_name":"ETH-PERPETUAL","bids":[],"asks":[["change",3897.35,1.6e5]],"prev_change_id":15557282341}}}
{"jsonrpc":"2.0","method":"subscription","params":{"channel":"book.ETH-PERPETUAL.raw","data":{"timestamp":1734114543709,"type":"change","change_id":15557282344,"instrument_name":"ETH-PERPETUAL","bids":[],"asks":[["change",3897.35,1.6e5]],"prev_change_id":15557282341}}}
{"jsonrpc":"2.0","method":"subscription","params":{"channel":"book.ETH-PERPETUAL.raw","data":{"timestamp":1734114543710,"type":"change","change_id":15557282346,"instrument_name":"ETH-PERPETUAL","bids":[["change",3880.4,1.8e5]],"asks":[],"prev_change_id":15557282344}}}
{"jsonrpc":"2.0","method":"subscription","params":{"channel":"book.ETH-PERPETUAL.raw","data":{"timestamp":1734114543710,"type":"change","change_id":15557282346,"instrument_name":"ETH-PERPETUAL","bids":[["change",3880.4,1.8e5]],"asks":[],"prev_change_id":15557282344}}}
{"jsonrpc":"2.0","method":"subscription","params":{"channel":"book.ETH-PERPETUAL.raw","data":{"timestamp":1734114543712,"type":"change","change_id":15557282348,"instrument_name":"ETH-PERPETUAL","bids":[["change",3880.4,2.0e5]],"asks":[],"prev_change_id":15557282346}}}
{"jsonrpc":"2.0","method":"subscription","params":{"channel":"book.ETH-PERPETUAL.raw","data":{"timestamp":1734114543712,"type":"change","change_id":15557282348,"instrument_name":"ETH-PERPETUAL","bids":[["change",3880.4,2.0e5]],"asks":[],"prev_change_id":15557282346}}}
{"jsonrpc":"2.0","method":"subscription","params":{"channel":"book.ETH-PERPETUAL.raw","data":{"timestamp":1734114543842,"type":"change","change_id":15557282371,"instrument_name":"ETH-PERPETUAL","bids":[["delete",3880.4,0.0]],"asks":[["delete",3897.35,0.0]],"prev_change_id":15557282348}}}
{"jsonrpc":"2.0","method":"subscription","params":{"channel":"book.ETH-PERPETUAL.raw","data":{"timestamp":1734114543842,"type":"change","change_id":15557282371,"instrument_name":"ETH-PERPETUAL","bids":[["delete",3880.4,0.0]],"asks":[["delete",3897.35,0.0]],"prev_change_id":15557282348}}}
{"jsonrpc":"2.0","method":"subscription","params":{"channel":"book.ETH-PERPETUAL.raw","data":{"timestamp":1734114544196,"type":"change","change_id":15557282378,"instrument_name":"ETH-PERPETUAL","bids":[["new",3880.3,8.0e4]],"asks":[],"prev_change_id":15557282371}}}
{"jsonrpc":"2.0","method":"subscription","params":{"channel":"book.ETH-PERPETUAL.raw","data":{"timestamp":1734114544196,"type":"change","change_id":15557282378,"instrument_name":"ETH-PERPETUAL","bids":[["new",3880.3,8.0e4]],"asks":[],"prev_change_id":15557282371}}}
{"jsonrpc":"2.0","method":"subscription","params":{"channel":"book.ETH-PERPETUAL.raw","data":{"timestamp":1734114544200,"type":"change","change_id":15557282379,"instrument_name":"ETH-PERPETUAL","bids":[],"asks":[["new",3897.55,8.0e4]],"prev_change_id":15557282378}}}
{"jsonrpc":"2.0","method":"subscription","params":{"channel":"book.ETH-PERPETUAL.raw","data":{"timestamp":1734114544200,"type":"change","change_id":15557282379,"instrument_name":"ETH-PERPETUAL","bids":[],"asks":[["new",3897.55,8.0e4]],"prev_change_id":15557282378}}}
{"jsonrpc":"2.0","method":"subscription","params":{"channel":"book.ETH-PERPETUAL.raw","data":{"timestamp":1734114544202,"type":"change","change_id":15557282380,"instrument_name":"ETH-PERPETUAL","bids":[["change",3880.3,1.0e5]],"asks":[],"prev_change_id":15557282379}}}
{"jsonrpc":"2.0","method":"subscription","params":{"channel":"book.ETH-PERPETUAL.raw","data":{"timestamp":1734114544202,"type":"change","change_id":15557282380,"instrument_name":"ETH-PERPETUAL","bids":[["change",3880.3,1.0e5]],"asks":[],"prev_change_id":15557282379}}}
{"jsonrpc":"2.0","method":"subscription","params":{"channel":"book.ETH-PERPETUAL.raw","data":{"timestamp":1734114544204,"type":"change","change_id":15557282381,"instrument_name":"ETH-PERPETUAL","bids":[],"asks":[["change",3897.55,1.0e5]],"prev_change_id":15557282380}}}
{"jsonrpc":"2.0","method":"subscription","params":{"channel":"book.ETH-PERPETUAL.raw","data":{"timestamp":1734114544204,"type":"change","change_id":15557282381,"instrument_name":"ETH-PERPETUAL","bids":[],"asks":[["change",3897.55,1.0e5]],"prev_change_id":15557282380}}}
{"jsonrpc":"2.0","method":"subscription","params":{"channel":"book.ETH-PERPETUAL.raw","data":{"timestamp":1734114544208,"type":"change","change_id":15557282382,"instrument_name":"ETH-PERPETUAL","bids":[["new",3880.2,8.0e4]],"asks":[],"prev_change_id":15557282381}}}
{"jsonrpc":"2.0","method":"subscription","params":{"channel":"book.ETH-PERPETUAL.raw","data":{"timestamp":1734114544208,"type":"change","change_id":15557282382,"instrument_name":"ETH-PERPETUAL","bids":[["new",3880.2,8.0e4]],"asks":[],"prev_change_id":15557282381}}}
{"jsonrpc":"2.0","method":"subscription","params":{"channel":"book.ETH-PERPETUAL.raw","data":{"timestamp":1734114544211,"type":"change","change_id":15557282383,"instrument_name":"ETH-PERPETUAL","bids":[],"asks":[["new",3897.45,8.0e4]],"prev_change_id":15557282382}}}
{"jsonrpc":"2.0","method":"subscription","params":{"channel":"book.ETH-PERPETUAL.raw","data":{"timestamp":1734114544211,"type":"change","change_id":15557282383,"instrument_name":"ETH-PERPETUAL","bids":[],"asks":[["new",3897.45,8.0e4]],"prev_change_id":15557282382}}}
{"jsonrpc":"2.0","method":"subscription","params":{"channel":"book.ETH-PERPETUAL.raw","data":{"timestamp":1734114544213,"type":"change","change_id":15557282384,"instrument_name":"ETH-PERPETUAL","bids":[["change",3880.2,1.0e5]],"asks":[],"prev_change_id":15557282383}}}
{"jsonrpc":"2.0","method":"subscription","params":{"channel":"book.ETH-PERPETUAL.raw","data":{"timestamp":1734114544213,"type":"change","change_id":15557282384,"instrument_name":"ETH-PERPETUAL","bids":[["change",3880.2,1.0e5]],"asks":[],"prev_change_id":15557282383}}}
{"jsonrpc":"2.0","method":"subscription","params":{"channel":"book.ETH-PERPETUAL.raw","data":{"timestamp":1734114544217,"type":"change","change_id":15557282385,"instrument_name":"ETH-PERPETUAL","bids":[],"asks":[["change",3897.45,1.0e5]],"prev_change_id":15557282384}}}
{"jsonrpc":"2.0","method":"subscription","params":{"channel":"book.ETH-PERPETUAL.raw","data":{"timestamp":1734114544217,"type":"change","change_id":15557282385,"instrument_name":"ETH-PERPETUAL","bids":[],"asks":[["change",3897.45,1.0e5]],"prev_change_id":15557282384}}}
{"jsonrpc":"2.0","method":"subscription","params":{"channel":"book.ETH-PERPETUAL.raw","data":{"timestamp":1734114544405,"type":"change","change_id":15557282387,"instrument_name":"ETH-PERPETUAL","bids":[["delete",3880.3,0.0],["delete",3880.2,0.0]],"asks":[["delete",3897.45,0.0],["delete",3897.55,0.0]],"prev_change_id":15557282385}}}
{"jsonrpc":"2.0","method":"subscription","params":{"channel":"book.ETH-PERPETUAL.raw","data":{"timestamp":1734114544405,"type":"change","change_id":15557282387,"instrument_name":"ETH-PERPETUAL","bids":[["delete",3880.3,0.0],["delete",3880.2,0.0]],"asks":[["delete",3897.45,0.0],["delete",3897.55,0.0]],"prev_change_id":15557282385}}}
{"jsonrpc":"2.0","method":"subscription","params":{"channel":"book.ETH-PERPETUAL.raw","data":{"timestamp":1734114544550,"type":"change","change_id":15557282388,"instrument_name":"ETH-PERPETUAL","bids":[],"asks":[["delete",3937.95,0.0],["new",3949.05,700.0]],"prev_change_id":15557282387}}}
{"jsonrpc":"2.0","method":"subscription","params":{"channel":"book.ETH-PERPETUAL.raw","data":{"timestamp":1734114544550,"type":"change","change_id":15557282388,"instrument_name":"ETH-PERPETUAL","bids":[],"asks":[["delete",3937.95,0.0],["new",3949.05,700.0]],"prev_change_id":15557282387}}}
{"jsonrpc":"2.0","method":"subscription","params":{"channel":"book.ETH-PERPETUAL.raw","data":{"timestamp":1734114544597,"type":"change","change_id":15557282394,"instrument_name":"ETH-PERPETUAL","bids":[["new",3880.15,8.0e4]],"asks":[],"prev_change_id":15557282388}}}
{"jsonrpc":"2.0","method":"subscription","params":{"channel":"book.ETH-PERPETUAL.raw","data":{"timestamp":1734114544597,"type":"change","change_id":15557282394,"instrument_name":"ETH-PERPETUAL","bids":[["new",3880.15,8.0e4]],"asks":[],"prev_change_id":15557282388}}}
{"jsonrpc":"2.0","method":"subscription","params":{"channel":"book.ETH-PERPETUAL.raw","data":{"timestamp":1734114544598,"type":"change","change_id":15557282396,"instrument_name":"ETH-PERPETUAL","bids":[],"asks":[["new",3897.3,8.0e4]],"prev_change_id":15557282394}}}
{"jsonrpc":"2.0","method":"subscription","params":{"channel":"book.ETH-PERPETUAL.raw","data":{"timestamp":1734114544598,"type":"change","change_id":15557282396,"instrument_name":"ETH-PERPETUAL","bids":[],"asks":[["new",3897.3,8.0e4]],"prev_change_id":15557282394}}}
{"jsonrpc":"2.0","method":"subscription","params":{"channel":"book.ETH-PERPETUAL.raw","data":{"timestamp":1734114544599,"type":"change","change_id":15557282398,"instrument_name":"ETH-PERPETUAL","bids":[["change",3880.15,1.0e5]],"asks":[],"prev_change_id":15557282396}}}
{"jsonrpc":"2.0","method":"subscription","params":{"channel":"book.ETH-PERPETUAL.raw","data":{"timestamp":1734114544599,"type":"change","change_id":15557282398,"instrument_name":"ETH-PERPETUAL","bids":[["change",3880.15,1.0e5]],"asks":[],"prev_change_id":15557282396}}}
{"jsonrpc":"2.0","method":"subscription","params":{"channel":"book.ETH-PERPETUAL.raw","data":{"timestamp":1734114544601,"type":"change","change_id":15557282399,"instrument_name":"ETH-PERPETUAL","bids":[],"asks":[["change",3897.3,1.0e5]],"prev_change_id":15557282398}}}
{"jsonrpc":"2.0","method":"subscription","params":{"channel":"book.ETH-PERPETUAL.raw","data":{"timestamp":1734114544601,"type":"change","change_id":15557282399,"instrument_name":"ETH-PERPETUAL","bids":[],"asks":[["change",3897.3,1.0e5]],"prev_change_id":15557282398}}}
{"jsonrpc":"2.0","method":"subscription","params":{"channel":"book.ETH-PERPETUAL.raw","data":{"timestamp":1734114544601,"type":"change","change_id":15557282400,"instrument_name":"ETH-PERPETUAL","bids":[["change",3880.15,4.2e5]],"asks":[],"prev_change_id":15557282399}}}
{"jsonrpc":"2.0","method":"subscription","params":{"channel":"book.ETH-PERPETUAL.raw","data":{"timestamp":1734114544601,"type":"change","change_id":15557282400,"instrument_name":"ETH-PERPETUAL","bids":[["change",3880.15,4.2e5]],"asks":[],"prev_change_id":15557282399}}}
{"jsonrpc":"2.0","method":"subscription","params":{"channel":"book.ETH-PERPETUAL.raw","data":{"timestamp":1734114544603,"type":"change","change_id":15557282401,"instrument_name":"ETH-PERPETUAL","bids":[["change",3880.15,5.0e5]],"asks":[],"prev_change_id":15557282400}}}
{"jsonrpc":"2.0","method":"subscription","params":{"channel":"book.ETH-PERPETUAL.raw","data":{"timestamp":1734114544603,"type":"change","change_id":15557282401,"instrument_name":"ETH-PERPETUAL","bids":[["change",3880.15,5.0e5]],"asks":[],"prev_change_id":15557282400}}}
{"jsonrpc":"2.0","method":"subscription","params":{"channel":"book.ETH-PERPETUAL.raw","data":{"timestamp":1734114544604,"type":"change","change_id":15557282402,"instrument_name":"ETH-PERPETUAL","bids":[],"asks":[["change",3897.3,1.8e5]],"prev_change_id":15557282401}}}
{"jsonrpc":"2.0","method":"subscription","params":{"channel":"book.ETH-PERPETUAL.raw","data":{"timestamp":1734114544604,"type":"change","change_id":15557282402,"instrument_name":"ETH-PERPETUAL","bids":[],"asks":[["change",3897.3,1.8e5]],"prev_change_id":15557282401}}}
{"jsonrpc":"2.0","method":"subscription","params":{"channel":"book.ETH-PERPETUAL.raw","data":{"timestamp":1734114544605,"type":"change","change_id":15557282403,"instrument_name":"ETH-PERPETUAL","bids":[["change",3880.15,5.2e5]],"asks":[],"prev_change_id":15557282402}}}
{"jsonrpc":"2.0","method":"subscription","params":{"channel":"book.ETH-PERPETUAL.raw","data":{"timestamp":1734114544605,"type":"change","change_id":15557282403,"instrument_name":"ETH-PERPETUAL","bids":[["change",3880.15,5.2e5]],"asks":[],"prev_change_id":15557282402}}}
{"jsonrpc":"2.0","method":"subscription","params":{"channel":"book.ETH-PERPETUAL.raw","data":{"timestamp":1734114544606,"type":"change","change_id":15557282405,"instrument_name":"ETH-PERPETUAL","bids":[],"asks":[["change",3897.3,2.0e5]],"prev_change_id":15557282403}}}
{"jsonrpc":"2.0","method":"subscription","params":{"channel":"book.ETH-PERPETUAL.raw","data":{"timestamp":1734114544606,"type":"change","change_id":15557282405,"instrument_name":"ETH-PERPETUAL","bids":[],"asks":[["change",3897.3,2.0e5]],"prev_change_id":15557282403}}}
{"jsonrpc":"2.0","method":"subscription","params":{"channel":"book.ETH-PERPETUAL.raw","data":{"timestamp":1734114544607,"type":"change","change_id":15557282406,"instrument_name":"ETH-PERPETUAL","bids":[["change",3880.15,8.4e5]],"asks":[],"prev_change_id":15557282405}}}
{"jsonrpc":"2.0","method":"subscription","params":{"channel":"book.ETH-PERPETUAL.raw","data":{"timestamp":1734114544607,"type":"change","change_id":15557282406,"instrument_name":"ETH-PERPETUAL","bids":[["change",3880.15,8.4e5]],"asks":[],"prev_change_id":15557282405}}}
{"jsonrpc":"2.0","method":"subscription","params":{"channel":"book.ETH-PERPETUAL.raw","data":{"timestamp":1734114544790,"type":"change","change_id":15557282421,"instrument_name":"ETH-PERPETUAL","bids":[["delete",3880.15,0.0]],"asks":[["delete",3897.3,0.0]],"prev_change_id":15557282406}}}
{"jsonrpc":"2.0","method":"subscription","params":{"channel":"book.ETH-PERPETUAL.raw","data":{"timestamp":1734114544790,"type":"change","change_id":15557282421,"instrument_name":"ETH-PERPETUAL","bids":[["delete",3880.15,0.0]],"asks":[["delete",3897.3,0.0]],"prev_change_id":15557282406}}}
{"jsonrpc":"2.0","method":"subscription","params":{"channel":"book.ETH-PERPETUAL.raw","data":{"timestamp":1734114545085,"type":"change","change_id":15557282424,"instrument_name":"ETH-PERPETUAL","bids":[["new",3880.3,8.0e4]],"asks":[],"prev_change_id":15557282421}}}
{"jsonrpc":"2.0","method":"subscription","params":{"channel":"book.ETH-PERPETUAL.raw","data":{"timestamp":1734114545085,"type":"change","change_id":15557282424,"instrument_name":"ETH-PERPETUAL","bids":[["new",3880.3,8.0e4]],"asks":[],"prev_change_id":15557282421}}}
{"jsonrpc":"2.0","method":"subscription","params":{"channel":"book.ETH-PERPETUAL.raw","data":{"timestamp":1734114545086,"type":"change","change_id":15557282425,"instrument_name":"ETH-PERPETUAL","bids":[],"asks":[["new",3897.25,8.0e4]],"prev_change_id":15557282424}}}
{"jsonrpc":"2.0","method":"subscription","params":{"channel":"book.ETH-PERPETUAL.raw","data":{"timestamp":1734114545086,"type":"change","change_id":15557282425,"instrument_name":"ETH-PERPETUAL","bids":[],"asks":[["new",3897.25,8.0e4]],"prev_change_id":15557282424}}}
{"jsonrpc":"2.0","method":"subscription","params":{"channel":"book.ETH-PERPETUAL.raw","data":{"timestamp":1734114545087,"type":"change","change_id":15557282426,"instrument_name":"ETH-PERPETUAL","bids":[["change",3880.3,1.0e5]],"asks":[],"prev_change_id":15557282425}}}
{"jsonrpc":"2.0","method":"subscription","params":{"channel":"book.ETH-PERPETUAL.raw","data":{"timestamp":1734114545087,"type":"change","change_id":15557282426,"instrument_name":"ETH-PERPETUAL","bids":[["change",3880.3,1.0e5]],"asks":[],"prev_change_id":15557282425}}}
{"jsonrpc":"2.0","method":"subscription","params":{"channel":"book.ETH-PERPETUAL.raw","data":{"timestamp":1734114545090,"type":"change","change_id":15557282427,"instrument_name":"ETH-PERPETUAL","bids":[],"asks":[["change",3897.25,1.0e5]],"prev_change_id":15557282426}}}
{"jsonrpc":"2.0","method":"subscription","params":{"channel":"book.ETH-PERPETUAL.raw","data":{"timestamp":1734114545090,"type":"change","change_id":15557282427,"instrument_name":"ETH-PERPETUAL","bids":[],"asks":[["change",3897.25,1.0e5]],"prev_change_id":15557282426}}}
{"jsonrpc":"2.0","method":"subscription","params":{"channel":"book.ETH-PERPETUAL.raw","data":{"timestamp":1734114545092,"type":"change","change_id":15557282428,"instrument_name":"ETH-PERPETUAL","bids":[["change",3880.3,1.8e5]],"asks":[],"prev_change_id":15557282427}}}
{"jsonrpc":"2.0","method":"subscription","params":{"channel":"book.ETH-PERPETUAL.raw","data":{"timestamp":1734114545092,"type":"change","change_id":15557282428,"instrument_name":"ETH-PERPETUAL","bids":[["change",3880.3,1.8e5]],"asks":[],"prev_change_id":15557282427}}}
{"jsonrpc":"2.0","method":"subscription","params":{"channel":"book.ETH-PERPETUAL.raw","data":{"timestamp":1734114545096,"type":"change","change_id":15557282429,"instrument_name":"ETH-PERPETUAL","bids":[],"asks":[["change",3897.25,1.8e5]],"prev_change_id":15557282428}}}
{"jsonrpc":"2.0","method":"subscription","params":{"channel":"book.ETH-PERPETUAL.raw","data":{"timestamp":1734114545096,"type":"change","change_id":15557282429,"instrument_name":"ETH-PERPETUAL","bids":[],"asks":[["change",3897.25,1.8e5]],"prev_change_id":15557282428}}}
{"jsonrpc":"2.0","method":"subscription","params":{"channel":"book.ETH-PERPETUAL.raw","data":{"timestamp":1734114545098,"type":"change","change_id":15557282430,"instrument_name":"ETH-PERPETUAL","bids":[["change",3880.3,2.0e5]],"asks":[],"prev_change_id":15557282429}}}
{"jsonrpc":"2.0","method":"subscription","params":{"channel":"book.ETH-PERPETUAL.raw","data":{"timestamp":1734114545098,"type":"change","change_id":15557282430,"instrument_name":"ETH-PERPETUAL","bids":[["change",3880.3,2.0e5]],"asks":[],"prev_change_id":15557282429}}}
{"jsonrpc":"2.0","method":"subscription","params":{"channel":"book.ETH-PERPETUAL.raw","data":{"timestamp":1734114545103,"type":"change","change_id":15557282431,"instrument_name":"ETH-PERPETUAL","bids":[],"asks":[["change",3897.25,2.0e5]],"prev_change_id":15557282430}}}
{"jsonrpc":"2.0","method":"subscription","params":{"channel":"book.ETH-PERPETUAL.raw","data":{"timestamp":1734114545103,"type":"change","change_id":15557282431,"instrument_name":"ETH-PERPETUAL","bids":[],"asks":[["change",3897.25,2.0e5]],"prev_change_id":15557282430}}}
{"jsonrpc":"2.0","method":"subscription","params":{"channel":"book.ETH-PERPETUAL.raw","data":{"timestamp":1734114545307,"type":"change","change_id":15557282432,"instrument_name":"ETH-PERPETUAL","bids":[["delete",3880.3,0.0]],"asks":[["delete",3897.25,0.0]],"prev_change_id":15557282431}}}
{"jsonrpc":"2.0","method":"subscription","params":{"channel":"book.ETH-PERPETUAL.raw","data":{"timestamp":1734114545307,"type":"change","change_id":15557282432,"instrument_name":"ETH-PERPETUAL","bids":[["delete",3880.3,0.0]],"asks":[["delete",3897.25,0.0]],"prev_change_id":15557282431}}}
{"jsonrpc":"2.0","method":"subscription","params":{"channel":"book.ETH-PERPETUAL.raw","data":{"timestamp":1734114545521,"type":"change","change_id":15557282433,"instrument_name":"ETH-PERPETUAL","bids":[["new",3880.4,8.0e4]],"asks":[],"prev_change_id":15557282432}}}
{"jsonrpc":"2.0","method":"subscription","params":{"channel":"book.ETH-PERPETUAL.raw","data":{"timestamp":1734114545521,"type":"change","change_id":15557282433,"instrument_name":"ETH-PERPETUAL","bids":[["new",3880.4,8.0e4]],"asks":[],"prev_change_id":15557282432}}}
{"jsonrpc":"2.0","method":"subscription","params":{"channel":"book.ETH-PERPETUAL.raw","data":{"timestamp":1734114545523,"type":"change","change_id":15557282434,"instrument_name":"ETH-PERPETUAL","bids":[],"asks":[["new",3897.2,8.0e4]],"prev_change_id":15557282433}}}
{"jsonrpc":"2.0","method":"subscription","params":{"channel":"book.ETH-PERPETUAL.raw","data":{"timestamp":1734114545523,"type":"change","change_id":15557282434,"instrument_name":"ETH-PERPETUAL","bids":[],"asks":[["new",3897.2,8.0e4]],"prev_change_id":15557282433}}}
{"jsonrpc":"2.0","method":"subscription","params":{"channel":"book.ETH-PERPETUAL.raw","data":{"timestamp":1734114545524,"type":"change","change_id":15557282435,"instrument_name":"ETH-PERPETUAL","bids":[["change",3880.4,1.0e5]],"asks":[],"prev_change_id":15557282434}}}
{"jsonrpc":"2.0","method":"subscription","params":{"channel":"book.ETH-PERPETUAL.raw","data":{"timestamp":1734114545524,"type":"change","change_id":15557282435,"instrument_name":"ETH-PERPETUAL","bids":[["change",3880.4,1.0e5]],"asks":[],"prev_change_id":15557282434}}}
{"jsonrpc":"2.0","method":"subscription","params":{"channel":"book.ETH-PERPETUAL.raw","data":{"timestamp":1734114545526,"type":"change","change_id":15557282436,"instrument_name":"ETH-PERPETUAL","bids":[],"asks":[["change",3897.2,1.0e5]],"prev_change_id":15557282435}}}
{"jsonrpc":"2.0","method":"subscription","params":{"channel":"book.ETH-PERPETUAL.raw","data":{"timestamp":1734114545526,"type":"change","change_id":15557282436,"instrument_name":"ETH-PERPETUAL","bids":[],"asks":[["change",3897.2,1.0e5]],"prev_change_id":15557282435}}}
{"jsonrpc":"2.0","method":"subscription","params":{"channel":"book.ETH-PERPETUAL.raw","data":{"timestamp":1734114545528,"type":"change","change_id":15557282437,"instrument_name":"ETH-PERPETUAL","bids":[["change",3880.4,4.2e5]],"asks":[],"prev_change_id":15557282436}}}
{"jsonrpc":"2.0","method":"subscription","params":{"channel":"book.ETH-PERPETUAL.raw","data":{"timestamp":1734114545528,"type":"change","change_id":15557282437,"instrument_name":"ETH-PERPETUAL","bids":[["change",3880.4,4.2e5]],"asks":[],"prev_change_id":15557282436}}}
{"jsonrpc":"2.0","method":"subscription","params":{"channel":"book.ETH-PERPETUAL.raw","data":{"timestamp":1734114545529,"type":"change","change_id":15557282438,"instrument_name":"ETH-PERPETUAL","bids":[["change",3880.4,5.0e5]],"asks":[],"prev_change_id":15557282437}}}
{"jsonrpc":"2.0","method":"subscription","params":{"channel":"book.ETH-PERPETUAL.raw","data":{"timestamp":1734114545529,"type":"change","change_id":15557282438,"instrument_name":"ETH-PERPETUAL","bids":[["change",3880.4,5.0e5]],"asks":[],"prev_change_id":15557282437}}}
{"jsonrpc":"2.0","method":"subscription","params":{"channel":"book.ETH-PERPETUAL.raw","data":{"timestamp":1734114545531,"type":"change","change_id":15557282439,"instrument_name":"ETH-PERPETUAL","bids":[],"asks":[["change",3897.2,1.8e5]],"prev_change_id":15557282438}}}
{"jsonrpc":"2.0","method":"subscription","params":{"channel":"book.ETH-PERPETUAL.raw","data":{"timestamp":1734114545531,"type":"change","change_id":15557282439,"instrument_name":"ETH-PERPETUAL","bids":[],"asks":[["change",3897.2,1.8e5]],"prev_change_id":15557282438}}}
{"jsonrpc":"2.0","method":"subscription","params":{"channel":"book.ETH-PERPETUAL.raw","data":{"timestamp":1734114545533,"type":"change","change_id":15557282440,"instrument_name":"ETH-PERPETUAL","bids":[["change",3880.4,5.2e5]],"asks":[],"prev_change_id":15557282439}}}
{"jsonrpc":"2.0","method":"subscription","params":{"channel":"book.ETH-PERPETUAL.raw","data":{"timestamp":1734114545533,"type":"change","change_id":15557282440,"instrument_name":"ETH-PERPETUAL","bids":[["change",3880.4,5.2e5]],"asks":[],"prev_change_id":15557282439}}}
{"jsonrpc":"2.0","method":"subscription","params":{"channel":"book.ETH-PERPETUAL.raw","data":{"timestamp":1734114545535,"type":"change","change_id":15557282441,"instrument_name":"ETH-PERPETUAL","bids":[],"asks":[["change",3897.2,2.0e5]],"prev_change_id":15557282440}}}
{"jsonrpc":"2.0","method":"subscription","params":{"channel":"book.ETH-PERPETUAL.raw","data":{"timestamp":1734114545535,"type":"change","change_id":15557282441,"instrument_name":"ETH-PERPETUAL","bids":[],"asks":[["change",3897.2,2.0e5]],"prev_change_id":15557282440}}}
{"jsonrpc":"2.0","method":"subscription","params":{"channel":"book.ETH-PERPETUAL.raw","data":{"timestamp":1734114545536,"type":"change","change_id":15557282442,"instrument_name":"ETH-PERPETUAL","bids":[["change",3880.4,8.4e5]],"asks":[],"prev_change_id":15557282441}}}
{"jsonrpc":"2.0","method":"subscription","params":{"channel":"book.ETH-PERPETUAL.raw","data":{"timestamp":1734114545536,"type":"change","change_id":15557282442,"instrument_name":"ETH-PERPETUAL","bids":[["change",3880.4,8.4e5]],"asks":[],"prev_change_id":15557282441}}}
{"jsonrpc":"2.0","method":"subscription","params":{"channel":"book.ETH-PERPETUAL.raw","data":{"timestamp":1734114545691,"type":"change","change_id":15557282489,"instrument_name":"ETH-PERPETUAL","bids":[["delete",3880.4,0.0]],"asks":[["delete",3897.2,0.0]],"prev_change_id":15557282442}}}
{"jsonrpc":"2.0","method":"subscription","params":{"channel":"book.ETH-PERPETUAL.raw","data":{"timestamp":1734114545691,"type":"change","change_id":15557282489,"instrument_name":"ETH-PERPETUAL","bids":[["delete",3880.4,0.0]],"asks":[["delete",3897.2,0.0]],"prev_change_id":15557282442}}}
{"jsonrpc":"2.0","method":"subscription","params":{"channel":"book.ETH-PERPETUAL.raw","data":{"timestamp":1734114545891,"type":"change","change_id":15557282508,"instrument_name":"ETH-PERPETUAL","bids":[["new",3880.45,8.0e4]],"asks":[],"prev_change_id":15557282489}}}
{"jsonrpc":"2.0","method":"subscription","params":{"channel":"book.ETH-PERPETUAL.raw","data":{"timestamp":1734114545891,"type":"change","change_id":15557282508,"instrument_name":"ETH-PERPETUAL","bids":[["new",3880.45,8.0e4]],"asks":[],"prev_change_id":15557282489}}}
{"jsonrpc":"2.0","method":"subscription","params":{"channel":"book.ETH-PERPETUAL.raw","data":{"timestamp":1734114545893,"type":"change","change_id":15557282509,"instrument_name":"ETH-PERPETUAL","bids":[],"asks":[["new",3897.15,8.0e4]],"prev_change_id":15557282508}}}
{"jsonrpc":"2.0","method":"subscription","params":{"channel":"book.ETH-PERPETUAL.raw","data":{"timestamp":1734114545893,"type":"change","change_id":15557282509,"instrument_name":"ETH-PERPETUAL","bids":[],"asks":[["new",3897.15,8.0e4]],"prev_change_id":15557282508}}}
{"jsonrpc":"2.0","method":"subscription","params":{"channel":"book.ETH-PERPETUAL.raw","data":{"timestamp":1734114545894,"type":"change","change_id":15557282510,"instrument_name":"ETH-PERPETUAL","bids":[["change",3880.45,1.0e5]],"asks":[],"prev_change_id":15557282509}}}
{"jsonrpc":"2.0","method":"subscription","params":{"channel":"book.ETH-PERPETUAL.raw","data":{"timestamp":1734114545894,"type":"change","change_id":15557282510,"instrument_name":"ETH-PERPETUAL","bids":[["change",3880.45,1.0e5]],"asks":[],"prev_change_id":15557282509}}}
{"jsonrpc":"2.0","method":"subscription","params":{"channel":"book.ETH-PERPETUAL.raw","data":{"timestamp":1734114545895,"type":"change","change_id":15557282511,"instrument_name":"ETH-PERPETUAL","bids":[["change",3880.45,1.8e5]],"asks":[],"prev_change_id":15557282510}}}
{"jsonrpc":"2.0","method":"subscription","params":{"channel":"book.ETH-PERPETUAL.raw","data":{"timestamp":1734114545895,"type":"change","change_id":15557282511,"instrument_name":"ETH-PERPETUAL","bids":[["change",3880.45,1.8e5]],"asks":[],"prev_change_id":15557282510}}}
{"jsonrpc":"2.0","method":"subscription","params":{"channel":"book.ETH-PERPETUAL.raw","data":{"timestamp":1734114545898,"type":"change","change_id":15557282512,"instrument_name":"ETH-PERPETUAL","bids":[],"asks":[["change",3897.15,1.6e5]],"prev_change_id":15557282511}}}
{"jsonrpc":"2.0","method":"subscription","params":{"channel":"book.ETH-PERPETUAL.raw","data":{"timestamp":1734114545898,"type":"change","change_id":15557282512,"instrument_name":"ETH-PERPETUAL","bids":[],"asks":[["change",3897.15,1.6e5]],"prev_change_id":15557282511}}}
{"jsonrpc":"2.0","method":"subscription","params":{"channel":"book.ETH-PERPETUAL.raw","data":{"timestamp":1734114545900,"type":"change","change_id":15557282513,"instrument_name":"ETH-PERPETUAL","bids":[["change",3880.45,2.0e5]],"asks":[],"prev_change_id":15557282512}}}
{"jsonrpc":"2.0","method":"subscription","params":{"channel":"book.ETH-PERPETUAL.raw","data":{"timestamp":1734114545900,"type":"change","change_id":15557282513,"instrument_name":"ETH-PERPETUAL","bids":[["change",3880.45,2.0e5]],"asks":[],"prev_change_id":15557282512}}}
{"jsonrpc":"2.0","method":"subscription","params":{"channel":"book.ETH-PERPETUAL.raw","data":{"timestamp":1734114545987,"type":"change","change_id":15557282514,"instrument_name":"ETH-PERPETUAL","bids":[["delete",3880.45,0.0]],"asks":[["delete",3897.15,0.0]],"prev_change_id":15557282513}}}
{"jsonrpc":"2.0","method":"subscription","params":{"channel":"book.ETH-PERPETUAL.raw","data":{"timestamp":1734114545987,"type":"change","change_id":15557282514,"instrument_name":"ETH-PERPETUAL","bids":[["delete",3880.45,0.0]],"asks":[["delete",3897.15,0.0]],"prev_change_id":15557282513}}}
{"jsonrpc":"2.0","method":"subscription","params":{"channel":"book.ETH-PERPETUAL.raw","data":{"timestamp":1734114546178,"type":"change","change_id":15557282517,"instrument_name":"ETH-PERPETUAL","bids":[["new",3880.5,8.0e4]],"asks":[],"prev_change_id":15557282514}}}
{"jsonrpc":"2.0","method":"subscription","params":{"channel":"book.ETH-PERPETUAL.raw","data":{"timestamp":1734114546178,"type":"change","change_id":15557282517,"instrument_name":"ETH-PERPETUAL","bids":[["new",3880.5,8.0e4]],"asks":[],"prev_change_id":15557282514}}}
{"jsonrpc":"2.0","method":"subscription","params":{"channel":"book.ETH-PERPETUAL.raw","data":{"timestamp":1734114546180,"type":"change","change_id":15557282518,"instrument_name":"ETH-PERPETUAL","bids":[],"asks":[["new",3897.1,8.0e4]],"prev_change_id":15557282517}}}
{"jsonrpc":"2.0","method":"subscription","params":{"channel":"book.ETH-PERPETUAL.raw","data":{"timestamp":1734114546180,"type":"change","change_id":15557282518,"instrument_name":"ETH-PERPETUAL","bids":[],"asks":[["new",3897.1,8.0e4]],"prev_change_id":15557282517}}}
{"jsonrpc":"2.0","method":"subscription","params":{"channel":"book.ETH-PERPETUAL.raw","data":{"timestamp":1734114546181,"type":"change","change_id":15557282519,"instrument_name":"ETH-PERPETUAL","bids":[["change",3880.5,1.0e5]],"asks":[],"prev_change_id":15557282518}}}
{"jsonrpc":"2.0","method":"subscription","params":{"channel":"book.ETH-PERPETUAL.raw","data":{"timestamp":1734114546181,"type":"change","change_id":15557282519,"instrument_name":"ETH-PERPETUAL","bids":[["change",3880.5,1.0e5]],"asks":[],"prev_change_id":15557282518}}}
{"jsonrpc":"2.0","method":"subscription","params":{"channel":"book.ETH-PERPETUAL.raw","data":{"timestamp":1734114546183,"type":"change","change_id":15557282520,"instrument_name":"ETH-PERPETUAL","bids":[["change",3880.5,1.8e5]],"asks":[],"prev_change_id":15557282519}}}
{"jsonrpc":"2.0","method":"subscription","params":{"channel":"book.ETH-PERPETUAL.raw","data":{"timestamp":1734114546183,"type":"change","change_id":15557282520,"instrument_name":"ETH-PERPETUAL","bids":[["change",3880.5,1.8e5]],"asks":[],"prev_change_id":15557282519}}}
{"jsonrpc":"2.0","method":"subscription","params":{"channel":"book.ETH-PERPETUAL.raw","data":{"timestamp":1734114546184,"type":"change","change_id":15557282521,"instrument_name":"ETH-PERPETUAL","bids":[],"asks":[["change",3897.1,1.6e5]],"prev_change_id":15557282520}}}
{"jsonrpc":"2.0","method":"subscription","params":{"channel":"book.ETH-PERPETUAL.raw","data":{"timestamp":1734114546184,"type":"change","change_id":15557282521,"instrument_name":"ETH-PERPETUAL","bids":[],"asks":[["change",3897.1,1.6e5]],"prev_change_id":15557282520}}}
{"jsonrpc":"2.0","method":"subscription","params":{"channel":"book.ETH-PERPETUAL.raw","data":{"timestamp":1734114546185,"type":"change","change_id":15557282522,"instrument_name":"ETH-PERPETUAL","bids":[["change",3880.5,2.0e5]],"asks":[],"prev_change_id":15557282521}}}
{"jsonrpc":"2.0","method":"subscription","params":{"channel":"book.ETH-PERPETUAL.raw","data":{"timestamp":1734114546185,"type":"change","change_id":15557282522,"instrument_name":"ETH-PERPETUAL","bids":[["change",3880.5,2.0e5]],"asks":[],"prev_change_id":15557282521}}}
{"jsonrpc":"2.0","method":"subscription","params":{"channel":"book.ETH-PERPETUAL.raw","data":{"timestamp":1734114546273,"type":"change","change_id":15557282523,"instrument_name":"ETH-PERPETUAL","bids":[["delete",3880.5,0.0]],"asks":[["delete",3897.1,0.0]],"prev_change_id":15557282522}}}
{"jsonrpc":"2.0","method":"subscription","params":{"channel":"book.ETH-PERPETUAL.raw","data":{"timestamp":1734114546273,"type":"change","change_id":15557282523,"instrument_name":"ETH-PERPETUAL","bids":[["delete",3880.5,0.0]],"asks":[["delete",3897.1,0.0]],"prev_change_id":15557282522}}}
{"jsonrpc":"2.0","method":"subscription","params":{"channel":"book.ETH-PERPETUAL.raw","data":{"timestamp":1734114546460,"type":"change","change_id":15557282525,"instrument_name":"ETH-PERPETUAL","bids":[["new",3880.5,8.0e4]],"asks":[],"prev_change_id":15557282523}}}
{"jsonrpc":"2.0","method":"subscription","params":{"channel":"book.ETH-PERPETUAL.raw","data":{"timestamp":1734114546460,"type":"change","change_id":15557282525,"instrument_name":"ETH-PERPETUAL","bids":[["new",3880.5,8.0e4]],"asks":[],"prev_change_id":15557282523}}}
{"jsonrpc":"2.0","method":"subscription","params":{"channel":"book.ETH-PERPETUAL.raw","data":{"timestamp":1734114546463,"type":"change","change_id":15557282526,"instrument_name":"ETH-PERPETUAL","bids":[],"asks":[["new",3897.0,8.0e4]],"prev_change_id":15557282525}}}
{"jsonrpc":"2.0","method":"subscription","params":{"channel":"book.ETH-PERPETUAL.raw","data":{"timestamp":1734114546463,"type":"change","change_id":15557282526,"instrument_name":"ETH-PERPETUAL","bids":[],"asks":[["new",3897.0,8.0e4]],"prev_change_id":15557282525}}}
{"jsonrpc":"2.0","method":"subscription","params":{"channel":"book.ETH-PERPETUAL.raw","data":{"timestamp":1734114546464,"type":"change","change_id":15557282527,"instrument_name":"ETH-PERPETUAL","bids":[["change",3880.5,1.0e5]],"asks":[],"prev_change_id":15557282526}}}
{"jsonrpc":"2.0","method":"subscription","params":{"channel":"book.ETH-PERPETUAL.raw","data":{"timestamp":1734114546464,"type":"change","change_id":15557282527,"instrument_name":"ETH-PERPETUAL","bids":[["change",3880.5,1.0e5]],"asks":[],"prev_change_id":15557282526}}}
{"jsonrpc":"2.0","method":"subscription","params":{"channel":"book.ETH-PERPETUAL.raw","data":{"timestamp":1734114546465,"type":"change","change_id":15557282528,"instrument_name":"ETH-PERPETUAL","bids":[["change",3880.5,1.8e5]],"asks":[],"prev_change_id":15557282527}}}
{"jsonrpc":"2.0","method":"subscription","params":{"channel":"book.ETH-PERPETUAL.raw","data":{"timestamp":1734114546465,"type":"change","change_id":15557282528,"instrument_name":"ETH-PERPETUAL","bids":[["change",3880.5,1.8e5]],"asks":[],"prev_change_id":15557282527}}}
{"jsonrpc":"2.0","method":"subscription","params":{"channel":"book.ETH-PERPETUAL.raw","data":{"timestamp":1734114546466,"type":"change","change_id":15557282529,"instrument_name":"ETH-PERPETUAL","bids":[],"asks":[["change",3897.0,1.6e5]],"prev_change_id":15557282528}}}
{"jsonrpc":"2.0","method":"subscription","params":{"channel":"book.ETH-PERPETUAL.raw","data":{"timestamp":1734114546466,"type":"change","change_id":15557282529,"instrument_name":"ETH-PERPETUAL","bids":[],"asks":[["change",3897.0,1.6e5]],"prev_change_id":15557282528}}}
{"jsonrpc":"2.0","method":"subscription","params":{"channel":"book.ETH-PERPETUAL.raw","data":{"timestamp":1734114546467,"type":"change","change_id":15557282530,"instrument_name":"ETH-PERPETUAL","bids":[["change",3880.5,2.0e5]],"asks":[],"prev_change_id":15557282529}}}
{"jsonrpc":"2.0","method":"subscription","params":{"channel":"book.ETH-PERPETUAL.raw","data":{"timestamp":1734114546467,"type":"change","change_id":15557282530,"instrument_name":"ETH-PERPETUAL","bids":[["change",3880.5,2.0e5]],"asks":[],"prev_change_id":15557282529}}}
{"jsonrpc":"2.0","method":"subscription","params":{"channel":"book.ETH-PERPETUAL.raw","data":{"timestamp":1734114546598,"type":"change","change_id":15557282531,"instrument_name":"ETH-PERPETUAL","bids":[["delete",3880.5,0.0]],"asks":[["delete",3897.0,0.0]],"prev_change_id":15557282530}}}
{"jsonrpc":"2.0","method":"subscription","params":{"channel":"book.ETH-PERPETUAL.raw","data":{"timestamp":1734114546598,"type":"change","change_id":15557282531,"instrument_name":"ETH-PERPETUAL","bids":[["delete",3880.5,0.0]],"asks":[["delete",3897.0,0.0]],"prev_change_id":15557282530}}}
{"jsonrpc":"2.0","method":"subscription","params":{"channel":"book.ETH-PERPETUAL.raw","data":{"timestamp":1734114546748,"type":"change","change_id":15557282538,"instrument_name":"ETH-PERPETUAL","bids":[],"asks":[["delete",3909.9,0.0],["new",3921.65,500.0]],"prev_change_id":15557282531}}}
{"jsonrpc":"2.0","method":"subscription","params":{"channel":"book.ETH-PERPETUAL.raw","data":{"timestamp":1734114546748,"type":"change","change_id":15557282538,"instrument_name":"ETH-PERPETUAL","bids":[],"asks":[["delete",3909.9,0.0],["new",3921.65,500.0]],"prev_change_id":15557282531}}}
{"jsonrpc":"2.0","method":"subscription","params":{"channel":"book.ETH-PERPETUAL.raw","data":{"timestamp":1734114546812,"type":"change","change_id":15557282539,"instrument_name":"ETH-PERPETUAL","bids":[["new",3880.55,8.0e4]],"asks":[],"prev_change_id":15557282538}}}
{"jsonrpc":"2.0","method":"subscription","params":{"channel":"book.ETH-PERPETUAL.raw","data":{"timestamp":1734114546812,"type":"change","change_id":15557282539,"instrument_name":"ETH-PERPETUAL","bids":[["new",3880.55,8.0e4]],"asks":[],"prev_change_id":15557282538}}}
{"jsonrpc":"2.0","method":"subscription","params":{"channel":"book.ETH-PERPETUAL.raw","data":{"timestamp":1734114546813,"type":"change","change_id":15557282540,"instrument_name":"ETH-PERPETUAL","bids":[],"asks":[["new",3896.95,8.0e4]],"prev_change_id":15557282539}}}
{"jsonrpc":"2.0","method":"subscription","params":{"channel":"book.ETH-PERPETUAL.raw","data":{"timestamp":1734114546813,"type":"change","change_id":15557282540,"instrument_name":"ETH-PERPETUAL","bids":[],"asks":[["new",3896.95,8.0e4]],"prev_change_id":15557282539}}}
{"jsonrpc":"2.0","method":"subscription","params":{"channel":"book.ETH-PERPETUAL.raw","data":{"timestamp":1734114546814,"type":"change","change_id":15557282541,"instrument_name":"ETH-PERPETUAL","bids":[["change",3880.55,1.0e5]],"asks":[],"prev_change_id":15557282540}}}
{"jsonrpc":"2.0","method":"subscription","params":{"channel":"book.ETH-PERPETUAL.raw","data":{"timestamp":1734114546814,"type":"change","change_id":15557282541,"instrument_name":"ETH-PERPETUAL","bids":[["change",3880.55,1.0e5]],"asks":[],"prev_change_id":15557282540}}}
{"jsonrpc":"2.0","method":"subscription","params":{"channel":"book.ETH-PERPETUAL.raw","data":{"timestamp":1734114546816,"type":"change","change_id":15557282542,"instrument_name":"ETH-PERPETUAL","bids":[["change",3880.55,1.8e5]],"asks":[],"prev_change_id":15557282541}}}
{"jsonrpc":"2.0","method":"subscription","params":{"channel":"book.ETH-PERPETUAL.raw","data":{"timestamp":1734114546816,"type":"change","change_id":15557282542,"instrument_name":"ETH-PERPETUAL","bids":[["change",3880.55,1.8e5]],"asks":[],"prev_change_id":15557282541}}}
{"jsonrpc":"2.0","method":"subscription","params":{"channel":"book.ETH-PERPETUAL.raw","data":{"timestamp":1734114546816,"type":"change","change_id":15557282543,"instrument_name":"ETH-PERPETUAL","bids":[],"asks":[["change",3896.95,1.6e5]],"prev_change_id":15557282542}}}
{"jsonrpc":"2.0","method":"subscription","params":{"channel":"book.ETH-PERPETUAL.raw","data":{"timestamp":1734114546816,"type":"change","change_id":15557282543,"instrument_name":"ETH-PERPETUAL","bids":[],"asks":[["change",3896.95,1.6e5]],"prev_change_id":15557282542}}}
{"jsonrpc":"2.0","method":"subscription","params":{"channel":"book.ETH-PERPETUAL.raw","data":{"timestamp":1734114546817,"type":"change","change_id":15557282544,"instrument_name":"ETH-PERPETUAL","bids":[["change",3880.55,2.0e5]],"asks":[],"prev_change_id":15557282543}}}
{"jsonrpc":"2.0","method":"subscription","params":{"channel":"book.ETH-PERPETUAL.raw","data":{"timestamp":1734114546817,"type":"change","change_id":15557282544,"instrument_name":"ETH-PERPETUAL","bids":[["change",3880.55,2.0e5]],"asks":[],"prev_change_id":15557282543}}}
{"jsonrpc":"2.0","method":"subscription","params":{"channel":"book.ETH-PERPETUAL.raw","data":{"timestamp":1734114546961,"type":"change","change_id":15557282545,"instrument_name":"ETH-PERPETUAL","bids":[["delete",3880.55,0.0]],"asks":[["delete",3896.95,0.0]],"prev_change_id":15557282544}}}
{"jsonrpc":"2.0","method":"subscription","params":{"channel":"book.ETH-PERPETUAL.raw","data":{"timestamp":1734114546961,"type":"change","change_id":15557282545,"instrument_name":"ETH-PERPETUAL","bids":[["delete",3880.55,0.0]],"asks":[["delete",3896.95,0.0]],"prev_change_id":15557282544}}}
{"jsonrpc":"2.0","method":"subscription","params":{"channel":"book.ETH-PERPETUAL.raw","data":{"timestamp":1734114547143,"type":"change","change_id":15557282547,"instrument_name":"ETH-PERPETUAL","bids":[["new",3880.6,8.0e4]],"asks":[],"prev_change_id":15557282545}}}
{"jsonrpc":"2.0","method":"subscription","params":{"channel":"book.ETH-PERPETUAL.raw","data":{"timestamp":1734114547143,"type":"change","change_id":15557282547,"instrument_name":"ETH-PERPETUAL","bids":[["new",3880.6,8.0e4]],"asks":[],"prev_change_id":15557282545}}}
{"jsonrpc":"2.0","method":"subscription","params":{"channel":"book.ETH-PERPETUAL.raw","data":{"timestamp":1734114547145,"type":"change","change_id":15557282548,"instrument_name":"ETH-PERPETUAL","bids":[],"asks":[["new",3896.95,8.0e4]],"prev_change_id":15557282547}}}
{"jsonrpc":"2.0","method":"subscription","params":{"channel":"book.ETH-PERPETUAL.raw","data":{"timestamp":1734114547145,"type":"change","change_id":15557282548,"instrument_name":"ETH-PERPETUAL","bids":[],"asks":[["new",3896.95,8.0e4]],"prev_change_id":15557282547}}}
{"jsonrpc":"2.0","method":"subscription","params":{"channel":"book.ETH-PERPETUAL.raw","data":{"timestamp":1734114547148,"type":"change","change_id":15557282549,"instrument_name":"ETH-PERPETUAL","bids":[["change",3880.6,1.0e5]],"asks":[],"prev_change_id":15557282548}}}
{"jsonrpc":"2.0","method":"subscription","params":{"channel":"book.ETH-PERPETUAL.raw","data":{"timestamp":1734114547148,"type":"change","change_id":15557282549,"instrument_name":"ETH-PERPETUAL","bids":[["change",3880.6,1.0e5]],"asks":[],"prev_change_id":15557282548}}}
{"jsonrpc":"2.0","method":"subscription","params":{"channel":"book.ETH-PERPETUAL.raw","data":{"timestamp":1734114547149,"type":"change","change_id":15557282550,"instrument_name":"ETH-PERPETUAL","bids":[["change",3880.6,1.8e5]],"asks":[],"prev_change_id":15557282549}}}
{"jsonrpc":"2.0","method":"subscription","params":{"channel":"book.ETH-PERPETUAL.raw","data":{"timestamp":1734114547149,"type":"change","change_id":15557282550,"instrument_name":"ETH-PERPETUAL","bids":[["change",3880.6,1.8e5]],"asks":[],"prev_change_id":15557282549}}}
{"jsonrpc":"2.0","method":"subscription","params":{"channel":"book.ETH-PERPETUAL.raw","data":{"timestamp":1734114547150,"type":"change","change_id":15557282551,"instrument_name":"ETH-PERPETUAL","bids":[],"asks":[["change",3896.95,1.6e5]],"prev_change_id":15557282550}}}
{"jsonrpc":"2.0","method":"subscription","params":{"channel":"book.ETH-PERPETUAL.raw","data":{"timestamp":1734114547150,"type":"change","change_id":15557282551,"instrument_name":"ETH-PERPETUAL","bids":[],"asks":[["change",3896.95,1.6e5]],"prev_change_id":15557282550}}}
{"jsonrpc":"2.0","method":"subscription","params":{"channel":"book.ETH-PERPETUAL.raw","data":{"timestamp":1734114547151,"type":"change","change_id":15557282552,"instrument_name":"ETH-PERPETUAL","bids":[["change",3880.6,2.0e5]],"asks":[],"prev_change_id":15557282551}}}
{"jsonrpc":"2.0","method":"subscription","params":{"channel":"book.ETH-PERPETUAL.raw","data":{"timestamp":1734114547151,"type":"change","change_id":15557282552,"instrument_name":"ETH-PERPETUAL","bids":[["change",3880.6,2.0e5]],"asks":[],"prev_change_id":15557282551}}}
{"jsonrpc":"2.0","method":"subscription","params":{"channel":"book.ETH-PERPETUAL.raw","data":{"timestamp":1734114547293,"type":"change","change_id":15557282553,"instrument_name":"ETH-PERPETUAL","bids":[["delete",3880.6,0.0]],"asks":[["delete",3896.95,0.0]],"prev_change_id":15557282552}}}
{"jsonrpc":"2.0","method":"subscription","params":{"channel":"book.ETH-PERPETUAL.raw","data":{"timestamp":1734114547293,"type":"change","change_id":15557282553,"instrument_name":"ETH-PERPETUAL","bids":[["delete",3880.6,0.0]],"asks":[["delete",3896.95,0.0]],"prev_change_id":15557282552}}}
{"jsonrpc":"2.0","method":"subscription","params":{"channel":"book.ETH-PERPETUAL.raw","data":{"timestamp":1734114547294,"type":"change","change_id":15557282554,"instrument_name":"ETH-PERPETUAL","bids":[],"asks":[["new",3916.45,500.0],["delete",3929.45,0.0]],"prev_change_id":15557282553}}}
{"jsonrpc":"2.0","method":"subscription","params":{"channel":"book.ETH-PERPETUAL.raw","data":{"timestamp":1734114547294,"type":"change","change_id":15557282554,"instrument_name":"ETH-PERPETUAL","bids":[],"asks":[["new",3916.45,500.0],["delete",3929.45,0.0]],"prev_change_id":15557282553}}}
{"jsonrpc":"2.0","method":"subscription","params":{"channel":"book.ETH-PERPETUAL.raw","data":{"timestamp":1734114547477,"type":"change","change_id":15557282555,"instrument_name":"ETH-PERPETUAL","bids":[["new",3880.55,8.0e4]],"asks":[],"prev_change_id":15557282554}}}
{"jsonrpc":"2.0","method":"subscription","params":{"channel":"book.ETH-PERPETUAL.raw","data":{"timestamp":1734114547477,"type":"change","change_id":15557282555,"instrument_name":"ETH-PERPETUAL","bids":[["new",3880.55,8.0e4]],"asks":[],"prev_change_id":15557282554}}}
{"jsonrpc":"2.0","method":"subscription","params":{"channel":"book.ETH-PERPETUAL.raw","data":{"timestamp":1734114547479,"type":"change","change_id":15557282556,"instrument_name":"ETH-PERPETUAL","bids":[],"asks":[["new",3896.85,8.0e4]],"prev_change_id":15557282555}}}
{"jsonrpc":"2.0","method":"subscription","params":{"channel":"book.ETH-PERPETUAL.raw","data":{"timestamp":1734114547479,"type":"change","change_id":15557282556,"instrument_name":"ETH-PERPETUAL","bids":[],"asks":[["new",3896.85,8.0e4]],"prev_change_id":15557282555}}}
{"jsonrpc":"2.0","method":"subscription","params":{"channel":"book.ETH-PERPETUAL.raw","data":{"timestamp":1734114547481,"type":"change","change_id":15557282557,"instrument_name":"ETH-PERPETUAL","bids":[["change",3880.55,1.0e5]],"asks":[],"prev_change_id":15557282556}}}
{"jsonrpc":"2.0","method":"subscription","params":{"channel":"book.ETH-PERPETUAL.raw","data":{"timestamp":1734114547481,"type":"change","change_id":15557282557,"instrument_name":"ETH-PERPETUAL","bids":[["change",3880.55,1.0e5]],"asks":[],"prev_change_id":15557282556}}}
{"jsonrpc":"2.0","method":"subscription","params":{"channel":"book.ETH-PERPETUAL.raw","data":{"timestamp":1734114547483,"type":"change","change_id":15557282558,"instrument_name":"ETH-PERPETUAL","bids":[["change",3880.55,1.8e5]],"asks":[],"prev_change_id":15557282557}}}
{"jsonrpc":"2.0","method":"subscription","params":{"channel":"book.ETH-PERPETUAL.raw","data":{"timestamp":1734114547483,"type":"change","change_id":15557282558,"instrument_name":"ETH-PERPETUAL","bids":[["change",3880.55,1.8e5]],"asks":[],"prev_change_id":15557282557}}}
{"jsonrpc":"2.0","method":"subscription","params":{"channel":"book.ETH-PERPETUAL.raw","data":{"timestamp":1734114547487,"type":"change","change_id":15557282559,"instrument_name":"ETH-PERPETUAL","bids":[],"asks":[["change",3896.85,1.6e5]],"prev_change_id":15557282558}}}
{"jsonrpc":"2.0","method":"subscription","params":{"channel":"book.ETH-PERPETUAL.raw","data":{"timestamp":1734114547487,"type":"change","change_id":15557282559,"instrument_name":"ETH-PERPETUAL","bids":[],"asks":[["change",3896.85,1.6e5]],"prev_change_id":15557282558}}}
{"jsonrpc":"2.0","method":"subscription","params":{"channel":"book.ETH-PERPETUAL.raw","data":{"timestamp":1734114547488,"type":"change","change_id":15557282560,"instrument_name":"ETH-PERPETUAL","bids":[["change",3880.55,2.0e5]],"asks":[],"prev_change_id":15557282559}}}
{"jsonrpc":"2.0","method":"subscription","params":{"channel":"book.ETH-PERPETUAL.raw","data":{"timestamp":1734114547488,"type":"change","change_id":15557282560,"instrument_name":"ETH-PERPETUAL","bids":[["change",3880.55,2.0e5]],"asks":[],"prev_change_id":15557282559}}}
{"jsonrpc":"2.0","method":"subscription","params":{"channel":"book.ETH-PERPETUAL.raw","data":{"timestamp":1734114547623,"type":"change","change_id":15557282565,"instrument_name":"ETH-PERPETUAL","bids":[["delete",3880.55,0.0]],"asks":[["delete",3896.85,0.0]],"prev_change_id":15557282560}}}
{"jsonrpc":"2.0","method":"subscription","params":{"channel":"book.ETH-PERPETUAL.raw","data":{"timestamp":1734114547623,"type":"change","change_id":15557282565,"instrument_name":"ETH-PERPETUAL","bids":[["delete",3880.55,0.0]],"asks":[["delete",3896.85,0.0]],"prev_change_id":15557282560}}}
{"jsonrpc":"2.0","method":"subscription","params":{"channel":"book.ETH-PERPETUAL.raw","data":{"timestamp":1734114547851,"type":"change","change_id":15557282604,"instrument_name":"ETH-PERPETUAL","bids":[["new",3880.6,8.0e4]],"asks":[],"prev_change_id":15557282565}}}
{"jsonrpc":"2.0","method":"subscription","params":{"channel":"book.ETH-PERPETUAL.raw","data":{"timestamp":1734114547851,"type":"change","change_id":15557282604,"instrument_name":"ETH-PERPETUAL","bids":[["new",3880.6,8.0e4]],"asks":[],"prev_change_id":15557282565}}}
{"jsonrpc":"2.0","method":"subscription","params":{"channel":"book.ETH-PERPETUAL.raw","data":{"timestamp":1734114547853,"type":"change","change_id":15557282605,"instrument_name":"ETH-PERPETUAL","bids":[],"asks":[["new",3896.8,8.0e4]],"prev_change_id":15557282604}}}
{"jsonrpc":"2.0","method":"subscription","params":{"channel":"book.ETH-PERPETUAL.raw","data":{"timestamp":1734114547853,"type":"change","change_id":15557282605,"instrument_name":"ETH-PERPETUAL","bids":[],"asks":[["new",3896.8,8.0e4]],"prev_change_id":15557282604}}}
{"jsonrpc":"2.0","method":"subscription","params":{"channel":"book.ETH-PERPETUAL.raw","data":{"timestamp":1734114547855,"type":"change","change_id":15557282606,"instrument_name":"ETH-PERPETUAL","bids":[["change",3880.6,1.0e5]],"asks":[],"prev_change_id":15557282605}}}
{"jsonrpc":"2.0","method":"subscription","params":{"channel":"book.ETH-PERPETUAL.raw","data":{"timestamp":1734114547855,"type":"change","change_id":15557282606,"instrument_name":"ETH-PERPETUAL","bids":[["change",3880.6,1.0e5]],"asks":[],"prev_change_id":15557282605}}}
{"jsonrpc":"2.0","method":"subscription","params":{"channel":"book.ETH-PERPETUAL.raw","data":{"timestamp":1734114547858,"type":"change","change_id":15557282607,"instrument_name":"ETH-PERPETUAL","bids":[],"asks":[["change",3896.8,1.0e5]],"prev_change_id":15557282606}}}
{"jsonrpc":"2.0","method":"subscription","params":{"channel":"book.ETH-PERPETUAL.raw","data":{"timestamp":1734114547858,"type":"change","change_id":15557282607,"instrument_name":"ETH-PERPETUAL","bids":[],"asks":[["change",3896.8,1.0e5]],"prev_change_id":15557282606}}}
{"jsonrpc":"2.0","method":"subscription","params":{"channel":"book.ETH-PERPETUAL.raw","data":{"timestamp":1734114547859,"type":"change","change_id":15557282608,"instrument_name":"ETH-PERPETUAL","bids":[["change",3880.6,1.8e5]],"asks":[],"prev_change_id":15557282607}}}
{"jsonrpc":"2.0","method":"subscription","params":{"channel":"book.ETH-PERPETUAL.raw","data":{"timestamp":1734114547859,"type":"change","change_id":15557282608,"instrument_name":"ETH-PERPETUAL","bids":[["change",3880.6,1.8e5]],"asks":[],"prev_change_id":15557282607}}}
{"jsonrpc":"2.0","method":"subscription","params":{"channel":"book.ETH-PERPETUAL.raw","data":{"timestamp":1734114547861,"type":"change","change_id":15557282609,"instrument_name":"ETH-PERPETUAL","bids":[],"asks":[["change",3896.8,1.8e5]],"prev_change_id":15557282608}}}
{"jsonrpc":"2.0","method":"subscription","params":{"channel":"book.ETH-PERPETUAL.raw","data":{"timestamp":1734114547861,"type":"change","change_id":15557282609,"instrument_name":"ETH-PERPETUAL","bids":[],"asks":[["change",3896.8,1.8e5]],"prev_change_id":15557282608}}}
{"jsonrpc":"2.0","method":"subscription","params":{"channel":"book.ETH-PERPETUAL.raw","data":{"timestamp":1734114547863,"type":"change","change_id":15557282610,"instrument_name":"ETH-PERPETUAL","bids":[["change",3880.6,2.0e5]],"asks":[],"prev_change_id":15557282609}}}
{"jsonrpc":"2.0","method":"subscription","params":{"channel":"book.ETH-PERPETUAL.raw","data":{"timestamp":1734114547863,"type":"change","change_id":15557282610,"instrument_name":"ETH-PERPETUAL","bids":[["change",3880.6,2.0e5]],"asks":[],"prev_change_id":15557282609}}}
{"jsonrpc":"2.0","method":"subscription","params":{"channel":"book.ETH-PERPETUAL.raw","data":{"timestamp":1734114547866,"type":"change","change_id":15557282611,"instrument_name":"ETH-PERPETUAL","bids":[],"asks":[["change",3896.8,2.0e5]],"prev_change_id":15557282610}}}
{"jsonrpc":"2.0","method":"subscription","params":{"channel":"book.ETH-PERPETUAL.raw","data":{"timestamp":1734114547866,"type":"change","change_id":15557282611,"instrument_name":"ETH-PERPETUAL","bids":[],"asks":[["change",3896.8,2.0e5]],"prev_change_id":15557282610}}}
{"jsonrpc":"2.0","method":"subscription","params":{"channel":"book.ETH-PERPETUAL.raw","data":{"timestamp":1734114547968,"type":"change","change_id":15557282612,"instrument_name":"ETH-PERPETUAL","bids":[["delete",3880.6,0.0]],"asks":[["delete",3896.8,0.0]],"prev_change_id":15557282611}}}
{"jsonrpc":"2.0","method":"subscription","params":{"channel":"book.ETH-PERPETUAL.raw","data":{"timestamp":1734114547968,"type":"change","change_id":15557282612,"instrument_name":"ETH-PERPETUAL","bids":[["delete",3880.6,0.0]],"asks":[["delete",3896.8,0.0]],"prev_change_id":15557282611}}}
{"jsonrpc":"2.0","method":"subscription","params":{"channel":"book.ETH-PERPETUAL.raw","data":{"timestamp":1734114547968,"type":"change","change_id":15557282613,"instrument_name":"ETH-PERPETUAL","bids":[["new",1942.0,1.0]],"asks":[],"prev_change_id":15557282612}}}
{"jsonrpc":"2.0","method":"subscription","params":{"channel":"book.ETH-PERPETUAL.raw","data":{"timestamp":1734114547968,"type":"change","change_id":15557282613,"instrument_name":"ETH-PERPETUAL","bids":[["new",1942.0,1.0]],"asks":[],"prev_change_id":15557282612}}}
{"jsonrpc":"2.0","method":"subscription","params":{"channel":"book.ETH-PERPETUAL.raw","data":{"timestamp":1734114548163,"type":"change","change_id":15557282615,"instrument_name":"ETH-PERPETUAL","bids":[["new",3880.65,8.0e4]],"asks":[],"prev_change_id":15557282613}}}
{"jsonrpc":"2.0","method":"subscription","params":{"channel":"book.ETH-PERPETUAL.raw","data":{"timestamp":1734114548163,"type":"change","change_id":15557282615,"instrument_name":"ETH-PERPETUAL","bids":[["new",3880.65,8.0e4]],"asks":[],"prev_change_id":15557282613}}}
{"jsonrpc":"2.0","method":"subscription","params":{"channel":"book.ETH-PERPETUAL.raw","data":{"timestamp":1734114548164,"type":"change","change_id":15557282616,"instrument_name":"ETH-PERPETUAL","bids":[],"asks":[["new",3896.75,8.0e4]],"prev_change_id":15557282615}}}
{"jsonrpc":"2.0","method":"subscription","params":{"channel":"book.ETH-PERPETUAL.raw","data":{"timestamp":1734114548164,"type":"change","change_id":15557282616,"instrument_name":"ETH-PERPETUAL","bids":[],"asks":[["new",3896.75,8.0e4]],"prev_change_id":15557282615}}}
{"jsonrpc":"2.0","method":"subscription","params":{"channel":"book.ETH-PERPETUAL.raw","data":{"timestamp":1734114548165,"type":"change","change_id":15557282617,"instrument_name":"ETH-PERPETUAL","bids":[["change",3880.65,1.6e5]],"asks":[],"prev_change_id":15557282616}}}
{"jsonrpc":"2.0","method":"subscription","params":{"channel":"book.ETH-PERPETUAL.raw","data":{"timestamp":1734114548165,"type":"change","change_id":15557282617,"instrument_name":"ETH-PERPETUAL","bids":[["change",3880.65,1.6e5]],"asks":[],"prev_change_id":15557282616}}}
{"jsonrpc":"2.0","method":"subscription","params":{"channel":"book.ETH-PERPETUAL.raw","data":{"timestamp":1734114548167,"type":"change","change_id":15557282618,"instrument_name":"ETH-PERPETUAL","bids":[],"asks":[["change",3896.75,1.6e5]],"prev_change_id":15557282617}}}
{"jsonrpc":"2.0","method":"subscription","params":{"channel":"book.ETH-PERPETUAL.raw","data":{"timestamp":1734114548167,"type":"change","change_id":15557282618,"instrument_name":"ETH-PERPETUAL","bids":[],"asks":[["change",3896.75,1.6e5]],"prev_change_id":15557282617}}}
{"jsonrpc":"2.0","method":"subscription","params":{"channel":"book.ETH-PERPETUAL.raw","data":{"timestamp":1734114548274,"type":"change","change_id":15557282619,"instrument_name":"ETH-PERPETUAL","bids":[["delete",3880.65,0.0]],"asks":[["delete",3896.75,0.0]],"prev_change_id":15557282618}}}
{"jsonrpc":"2.0","method":"subscription","params":{"channel":"book.ETH-PERPETUAL.raw","data":{"timestamp":1734114548274,"type":"change","change_id":15557282619,"instrument_name":"ETH-PERPETUAL","bids":[["delete",3880.65,0.0]],"asks":[["delete",3896.75,0.0]],"prev_change_id":15557282618}}}
{"jsonrpc":"2.0","method":"subscription","params":{"channel":"book.ETH-PERPETUAL.raw","data":{"timestamp":1734114548424,"type":"change","change_id":15557282620,"instrument_name":"ETH-PERPETUAL","bids":[["delete",3841.4,0.0],["new",3833.4,700.0]],"asks":[],"prev_change_id":15557282619}}}
{"jsonrpc":"2.0","method":"subscription","params":{"channel":"book.ETH-PERPETUAL.raw","data":{"timestamp":1734114548424,"type":"change","change_id":15557282620,"instrument_name":"ETH-PERPETUAL","bids":[["delete",3841.4,0.0],["new",3833.4,700.0]],"asks":[],"prev_change_id":15557282619}}}
{"jsonrpc":"2.0","method":"subscription","params":{"channel":"book.ETH-PERPETUAL.raw","data":{"timestamp":1734114548426,"type":"change","change_id":15557282621,"instrument_name":"ETH-PERPETUAL","bids":[["delete",3860.8,0.0],["new",3852.75,500.0]],"asks":[],"prev_change_id":15557282620}}}
{"jsonrpc":"2.0","method":"subscription","params":{"channel":"book.ETH-PERPETUAL.raw","data":{"timestamp":1734114548426,"type":"change","change_id":15557282621,"instrument_name":"ETH-PERPETUAL","bids":[["delete",3860.8,0.0],["new",3852.75,500.0]],"asks":[],"prev_change_id":15557282620}}}
{"jsonrpc":"2.0","method":"subscription","params":{"channel":"book.ETH-PERPETUAL.raw","data":{"timestamp":1734114548465,"type":"change","change_id":15557282622,"instrument_name":"ETH-PERPETUAL","bids":[["new",3880.65,8.0e4]],"asks":[],"prev_change_id":15557282621}}}
{"jsonrpc":"2.0","method":"subscription","params":{"channel":"book.ETH-PERPETUAL.raw","data":{"timestamp":1734114548465,"type":"change","change_id":15557282622,"instrument_name":"ETH-PERPETUAL","bids":[["new",3880.65,8.0e4]],"asks":[],"prev_change_id":15557282621}}}
{"jsonrpc":"2.0","method":"subscription","params":{"channel":"book.ETH-PERPETUAL.raw","data":{"timestamp":1734114548466,"type":"change","change_id":15557282623,"instrument_name":"ETH-PERPETUAL","bids":[],"asks":[["new",3896.75,8.0e4]],"prev_change_id":15557282622}}}
{"jsonrpc":"2.0","method":"subscription","params":{"channel":"book.ETH-PERPETUAL.raw","data":{"timestamp":1734114548466,"type":"change","change_id":15557282623,"instrument_name":"ETH-PERPETUAL","bids":[],"asks":[["new",3896.75,8.0e4]],"prev_change_id":15557282622}}}
{"jsonrpc":"2.0","method":"subscription","params":{"channel":"book.ETH-PERPETUAL.raw","data":{"timestamp":1734114548467,"type":"change","change_id":15557282624,"instrument_name":"ETH-PERPETUAL","bids":[["change",3880.65,1.0e5]],"asks":[],"prev_change_id":15557282623}}}
{"jsonrpc":"2.0","method":"subscription","params":{"channel":"book.ETH-PERPETUAL.raw","data":{"timestamp":1734114548467,"type":"change","change_id":15557282624,"instrument_name":"ETH-PERPETUAL","bids":[["change",3880.65,1.0e5]],"asks":[],"prev_change_id":15557282623}}}
{"jsonrpc":"2.0","method":"subscription","params":{"channel":"book.ETH-PERPETUAL.raw","data":{"timestamp":1734114548468,"type":"change","change_id":15557282625,"instrument_name":"ETH-PERPETUAL","bids":[],"asks":[["change",3896.75,1.0e5]],"prev_change_id":15557282624}}}
{"jsonrpc":"2.0","method":"subscription","params":{"channel":"book.ETH-PERPETUAL.raw","data":{"timestamp":1734114548468,"type":"change","change_id":15557282625,"instrument_name":"ETH-PERPETUAL","bids":[],"asks":[["change",3896.75,1.0e5]],"prev_change_id":15557282624}}}
{"jsonrpc":"2.0","method":"subscription","params":{"channel":"book.ETH-PERPETUAL.raw","data":{"timestamp":1734114548469,"type":"change","change_id":15557282626,"instrument_name":"ETH-PERPETUAL","bids":[["change",3880.65,1.8e5]],"asks":[],"prev_change_id":15557282625}}}
{"jsonrpc":"2.0","method":"subscription","params":{"channel":"book.ETH-PERPETUAL.raw","data":{"timestamp":1734114548469,"type":"change","change_id":15557282626,"instrument_name":"ETH-PERPETUAL","bids":[["change",3880.65,1.8e5]],"asks":[],"prev_change_id":15557282625}}}
{"jsonrpc":"2.0","method":"subscription","params":{"channel":"book.ETH-PERPETUAL.raw","data":{"timestamp":1734114548470,"type":"change","change_id":15557282627,"instrument_name":"ETH-PERPETUAL","bids":[],"asks":[["change",3896.75,1.8e5]],"prev_change_id":15557282626}}}
{"jsonrpc":"2.0","method":"subscription","params":{"channel":"book.ETH-PERPETUAL.raw","data":{"timestamp":1734114548470,"type":"change","change_id":15557282627,"instrument_name":"ETH-PERPETUAL","bids":[],"asks":[["change",3896.75,1.8e5]],"prev_change_id":15557282626}}}
{"jsonrpc":"2.0","method":"subscription","params":{"channel":"book.ETH-PERPETUAL.raw","data":{"timestamp":1734114548471,"type":"change","change_id":15557282628,"instrument_name":"ETH-PERPETUAL","bids":[["change",3880.65,2.0e5]],"asks":[],"prev_change_id":15557282627}}}
{"jsonrpc":"2.0","method":"subscription","params":{"channel":"book.ETH-PERPETUAL.raw","data":{"timestamp":1734114548471,"type":"change","change_id":15557282628,"instrument_name":"ETH-PERPETUAL","bids":[["change",3880.65,2.0e5]],"asks":[],"prev_change_id":15557282627}}}
{"jsonrpc":"2.0","method":"subscription","params":{"channel":"book.ETH-PERPETUAL.raw","data":{"timestamp":1734114548472,"type":"change","change_id":15557282629,"instrument_name":"ETH-PERPETUAL","bids":[],"asks":[["change",3896.75,2.0e5]],"prev_change_id":15557282628}}}
{"jsonrpc":"2.0","method":"subscription","params":{"channel":"book.ETH-PERPETUAL.raw","data":{"timestamp":1734114548472,"type":"change","change_id":15557282629,"instrument_name":"ETH-PERPETUAL","bids":[],"asks":[["change",3896.75,2.0e5]],"prev_change_id":15557282628}}}
{"jsonrpc":"2.0","method":"subscription","params":{"channel":"book.ETH-PERPETUAL.raw","data":{"timestamp":1734114548626,"type":"change","change_id":15557282633,"instrument_name":"ETH-PERPETUAL","bids":[["delete",3880.65,0.0]],"asks":[["delete",3896.75,0.0]],"prev_change_id":15557282629}}}
{"jsonrpc":"2.0","method":"subscription","params":{"channel":"book.ETH-PERPETUAL.raw","data":{"timestamp":1734114548626,"type":"change","change_id":15557282633,"instrument_name":"ETH-PERPETUAL","bids":[["delete",3880.65,0.0]],"asks":[["delete",3896.75,0.0]],"prev_change_id":15557282629}}}
{"jsonrpc":"2.0","method":"subscription","params":{"channel":"book.ETH-PERPETUAL.raw","data":{"timestamp":1734114548772,"type":"change","change_id":15557282658,"instrument_name":"ETH-PERPETUAL","bids":[["delete",3868.7,0.0],["new",3860.5,500.0]],"asks":[],"prev_change_id":15557282633}}}
{"jsonrpc":"2.0","method":"subscription","params":{"channel":"book.ETH-PERPETUAL.raw","data":{"timestamp":1734114548772,"type":"change","change_id":15557282658,"instrument_name":"ETH-PERPETUAL","bids":[["delete",3868.7,0.0],["new",3860.5,500.0]],"asks":[],"prev_change_id":15557282633}}}
{"jsonrpc":"2.0","method":"subscription","params":{"channel":"book.ETH-PERPETUAL.raw","data":{"timestamp":1734114548814,"type":"change","change_id":15557282659,"instrument_name":"ETH-PERPETUAL","bids":[["new",3880.7,8.0e4]],"asks":[],"prev_change_id":15557282658}}}
{"jsonrpc":"2.0","method":"subscription","params":{"channel":"book.ETH-PERPETUAL.raw","data":{"timestamp":1734114548814,"type":"change","change_id":15557282659,"instrument_name":"ETH-PERPETUAL","bids":[["new",3880.7,8.0e4]],"asks":[],"prev_change_id":15557282658}}}
{"jsonrpc":"2.0","method":"subscription","params":{"channel":"book.ETH-PERPETUAL.raw","data":{"timestamp":1734114548815,"type":"change","change_id":15557282660,"instrument_name":"ETH-PERPETUAL","bids":[],"asks":[["new",3896.7,8.0e4]],"prev_change_id":15557282659}}}
{"jsonrpc":"2.0","method":"subscription","params":{"channel":"book.ETH-PERPETUAL.raw","data":{"timestamp":1734114548815,"type":"change","change_id":15557282660,"instrument_name":"ETH-PERPETUAL","bids":[],"asks":[["new",3896.7,8.0e4]],"prev_change_id":15557282659}}}
{"jsonrpc":"2.0","method":"subscription","params":{"channel":"book.ETH-PERPETUAL.raw","data":{"timestamp":1734114548816,"type":"change","change_id":15557282661,"instrument_name":"ETH-PERPETUAL","bids":[["change",3880.7,1.0e5]],"asks":[],"prev_change_id":15557282660}}}
{"jsonrpc":"2.0","method":"subscription","params":{"channel":"book.ETH-PERPETUAL.raw","data":{"timestamp":1734114548816,"type":"change","change_id":15557282661,"instrument_name":"ETH-PERPETUAL","bids":[["change",3880.7,1.0e5]],"asks":[],"prev_change_id":15557282660}}}
{"jsonrpc":"2.0","method":"subscription","params":{"channel":"book.ETH-PERPETUAL.raw","data":{"timestamp":1734114548817,"type":"change","change_id":15557282662,"instrument_name":"ETH-PERPETUAL","bids":[["change",3880.7,1.8e5]],"asks":[],"prev_change_id":15557282661}}}
{"jsonrpc":"2.0","method":"subscription","params":{"channel":"book.ETH-PERPETUAL.raw","data":{"timestamp":1734114548817,"type":"change","change_id":15557282662,"instrument_name":"ETH-PERPETUAL","bids":[["change",3880.7,1.8e5]],"asks":[],"prev_change_id":15557282661}}}
{"jsonrpc":"2.0","method":"subscription","params":{"channel":"book.ETH-PERPETUAL.raw","data":{"timestamp":1734114548818,"type":"change","change_id":15557282663,"instrument_name":"ETH-PERPETUAL","bids":[],"asks":[["change",3896.7,1.6e5]],"prev_change_id":15557282662}}}
{"jsonrpc":"2.0","method":"subscription","params":{"channel":"book.ETH-PERPETUAL.raw","data":{"timestamp":1734114548818,"type":"change","change_id":15557282663,"instrument_name":"ETH-PERPETUAL","bids":[],"asks":[["change",3896.7,1.6e5]],"prev_change_id":15557282662}}}
{"jsonrpc":"2.0","method":"subscription","params":{"channel":"book.ETH-PERPETUAL.raw","data":{"timestamp":1734114548819,"type":"change","change_id":15557282664,"instrument_name":"ETH-PERPETUAL","bids":[["change",3880.7,2.0e5]],"asks":[],"prev_change_id":15557282663}}}
{"jsonrpc":"2.0","method":"subscription","params":{"channel":"book.ETH-PERPETUAL.raw","data":{"timestamp":1734114548819,"type":"change","change_id":15557282664,"instrument_name":"ETH-PERPETUAL","bids":[["change",3880.7,2.0e5]],"asks":[],"prev_change_id":15557282663}}}
{"jsonrpc":"2.0","method":"subscription","params":{"channel":"book.ETH-PERPETUAL.raw","data":{"timestamp":1734114548969,"type":"change","change_id":15557282665,"instrument_name":"ETH-PERPETUAL","bids":[["delete",3880.7,0.0]],"asks":[["delete",3896.7,0.0]],"prev_change_id":15557282664}}}
{"jsonrpc":"2.0","method":"subscription","params":{"channel":"book.ETH-PERPETUAL.raw","data":{"timestamp":1734114548969,"type":"change","change_id":15557282665,"instrument_name":"ETH-PERPETUAL","bids":[["delete",3880.7,0.0]],"asks":[["delete",3896.7,0.0]],"prev_change_id":15557282664}}}
{"jsonrpc":"2.0","method":"subscription","params":{"channel":"book.ETH-PERPETUAL.raw","data":{"timestamp":1734114549157,"type":"change","change_id":15557282667,"instrument_name":"ETH-PERPETUAL","bids":[["new",3880.75,8.0e4]],"asks":[],"prev_change_id":15557282665}}}
{"jsonrpc":"2.0","method":"subscription","params":{"channel":"book.ETH-PERPETUAL.raw","data":{"timestamp":1734114549157,"type":"change","change_id":15557282667,"instrument_name":"ETH-PERPETUAL","bids":[["new",3880.75,8.0e4]],"asks":[],"prev_change_id":15557282665}}}
{"jsonrpc":"2.0","method":"subscription","params":{"channel":"book.ETH-PERPETUAL.raw","data":{"timestamp":1734114549158,"type":"change","change_id":15557282668,"instrument_name":"ETH-PERPETUAL","bids":[],"asks":[["new",3896.65,8.0e4]],"prev_change_id":15557282667}}}
{"jsonrpc":"2.0","method":"subscription","params":{"channel":"book.ETH-PERPETUAL.raw","data":{"timestamp":1734114549158,"type":"change","change_id":15557282668,"instrument_name":"ETH-PERPETUAL","bids":[],"asks":[["new",3896.65,8.0e4]],"prev_change_id":15557282667}}}
{"jsonrpc":"2.0","method":"subscription","params":{"channel":"book.ETH-PERPETUAL.raw","data":{"timestamp":1734114549159,"type":"change","change_id":15557282669,"instrument_name":"ETH-PERPETUAL","bids":[["change",3880.75,1.0e5]],"asks":[],"prev_change_id":15557282668}}}
{"jsonrpc":"2.0","method":"subscription","params":{"channel":"book.ETH-PERPETUAL.raw","data":{"timestamp":1734114549159,"type":"change","change_id":15557282669,"instrument_name":"ETH-PERPETUAL","bids":[["change",3880.75,1.0e5]],"asks":[],"prev_change_id":15557282668}}}
{"jsonrpc":"2.0","method":"subscription","params":{"channel":"book.ETH-PERPETUAL.raw","data":{"timestamp":1734114549165,"type":"change","change_id":15557282670,"instrument_name":"ETH-PERPETUAL","bids":[["change",3880.75,1.8e5]],"asks":[],"prev_change_id":15557282669}}}
{"jsonrpc":"2.0","method":"subscription","params":{"channel":"book.ETH-PERPETUAL.raw","data":{"timestamp":1734114549165,"type":"change","change_id":15557282670,"instrument_name":"ETH-PERPETUAL","bids":[["change",3880.75,1.8e5]],"asks":[],"prev_change_id":15557282669}}}
{"jsonrpc":"2.0","method":"subscription","params":{"channel":"book.ETH-PERPETUAL.raw","data":{"timestamp":1734114549166,"type":"change","change_id":15557282671,"instrument_name":"ETH-PERPETUAL","bids":[],"asks":[["change",3896.65,1.6e5]],"prev_change_id":15557282670}}}
{"jsonrpc":"2.0","method":"subscription","params":{"channel":"book.ETH-PERPETUAL.raw","data":{"timestamp":1734114549166,"type":"change","change_id":15557282671,"instrument_name":"ETH-PERPETUAL","bids":[],"asks":[["change",3896.65,1.6e5]],"prev_change_id":15557282670}}}
{"jsonrpc":"2.0","method":"subscription","params":{"channel":"book.ETH-PERPETUAL.raw","data":{"timestamp":1734114549168,"type":"change","change_id":15557282672,"instrument_name":"ETH-PERPETUAL","bids":[["change",3880.75,2.0e5]],"asks":[],"prev_change_id":15557282671}}}
{"jsonrpc":"2.0","method":"subscription","params":{"channel":"book.ETH-PERPETUAL.raw","data":{"timestamp":1734114549168,"type":"change","change_id":15557282672,"instrument_name":"ETH-PERPETUAL","bids":[["change",3880.75,2.0e5]],"asks":[],"prev_change_id":15557282671}}}
{"jsonrpc":"2.0","method":"subscription","params":{"channel":"book.ETH-PERPETUAL.raw","data":{"timestamp":1734114549333,"type":"change","change_id":15557282673,"instrument_name":"ETH-PERPETUAL","bids":[["delete",3880.75,0.0]],"asks":[["delete",3896.65,0.0]],"prev_change_id":15557282672}}}
{"jsonrpc":"2.0","method":"subscription","params":{"channel":"book.ETH-PERPETUAL.raw","data":{"timestamp":1734114549333,"type":"change","change_id":15557282673,"instrument_name":"ETH-PERPETUAL","bids":[["delete",3880.75,0.0]],"asks":[["delete",3896.65,0.0]],"prev_change_id":15557282672}}}
{"jsonrpc":"2.0","method":"subscription","params":{"channel":"book.ETH-PERPETUAL.raw","data":{"timestamp":1734114549516,"type":"change","change_id":15557282674,"instrument_name":"ETH-PERPETUAL","bids":[["new",3880.9,8.0e4]],"asks":[],"prev_change_id":15557282673}}}
{"jsonrpc":"2.0","method":"subscription","params":{"channel":"book.ETH-PERPETUAL.raw","data":{"timestamp":1734114549516,"type":"change","change_id":15557282674,"instrument_name":"ETH-PERPETUAL","bids":[["new",3880.9,8.0e4]],"asks":[],"prev_change_id":15557282673}}}
{"jsonrpc":"2.0","method":"subscription","params":{"channel":"book.ETH-PERPETUAL.raw","data":{"timestamp":1734114549519,"type":"change","change_id":15557282675,"instrument_name":"ETH-PERPETUAL","bids":[],"asks":[["new",3896.8,8.0e4]],"prev_change_id":15557282674}}}
{"jsonrpc":"2.0","method":"subscription","params":{"channel":"book.ETH-PERPETUAL.raw","data":{"timestamp":1734114549519,"type":"change","change_id":15557282675,"instrument_name":"ETH-PERPETUAL","bids":[],"asks":[["new",3896.8,8.0e4]],"prev_change_id":15557282674}}}
{"jsonrpc":"2.0","method":"subscription","params":{"channel":"book.ETH-PERPETUAL.raw","data":{"timestamp":1734114549520,"type":"change","change_id":15557282676,"instrument_name":"ETH-PERPETUAL","bids":[["change",3880.9,1.0e5]],"asks":[],"prev_change_id":15557282675}}}
{"jsonrpc":"2.0","method":"subscription","params":{"channel":"book.ETH-PERPETUAL.raw","data":{"timestamp":1734114549520,"type":"change","change_id":15557282676,"instrument_name":"ETH-PERPETUAL","bids":[["change",3880.9,1.0e5]],"asks":[],"prev_change_id":15557282675}}}
{"jsonrpc":"2.0","method":"subscription","params":{"channel":"book.ETH-PERPETUAL.raw","data":{"timestamp":1734114549521,"type":"change","change_id":15557282677,"instrument_name":"ETH-PERPETUAL","bids":[["change",3880.9,1.8e5]],"asks":[],"prev_change_id":15557282676}}}
{"jsonrpc":"2.0","method":"subscription","params":{"channel":"book.ETH-PERPETUAL.raw","data":{"timestamp":1734114549521,"type":"change","change_id":15557282677,"instrument_name":"ETH-PERPETUAL","bids":[["change",3880.9,1.8e5]],"asks":[],"prev_change_id":15557282676}}}
{"jsonrpc":"2.0","method":"subscription","params":{"channel":"book.ETH-PERPETUAL.raw","data":{"timestamp":1734114549522,"type":"change","change_id":15557282678,"instrument_name":"ETH-PERPETUAL","bids":[],"asks":[["change",3896.8,1.6e5]],"prev_change_id":15557282677}}}
{"jsonrpc":"2.0","method":"subscription","params":{"channel":"book.ETH-PERPETUAL.raw","data":{"timestamp":1734114549522,"type":"change","change_id":15557282678,"instrument_name":"ETH-PERPETUAL","bids":[],"asks":[["change",3896.8,1.6e5]],"prev_change_id":15557282677}}}
{"jsonrpc":"2.0","method":"subscription","params":{"channel":"book.ETH-PERPETUAL.raw","data":{"timestamp":1734114549523,"type":"change","change_id":15557282679,"instrument_name":"ETH-PERPETUAL","bids":[["change",3880.9,2.0e5]],"asks":[],"prev_change_id":15557282678}}}
{"jsonrpc":"2.0","method":"subscription","params":{"channel":"book.ETH-PERPETUAL.raw","data":{"timestamp":1734114549523,"type":"change","change_id":15557282679,"instrument_name":"ETH-PERPETUAL","bids":[["change",3880.9,2.0e5]],"asks":[],"prev_change_id":15557282678}}}
{"jsonrpc":"2.0","method":"subscription","params":{"channel":"book.ETH-PERPETUAL.raw","data":{"timestamp":1734114549525,"type":"change","change_id":15557282680,"instrument_name":"ETH-PERPETUAL","bids":[],"asks":[["change",3896.8,1.8e5]],"prev_change_id":15557282679}}}
{"jsonrpc":"2.0","method":"subscription","params":{"channel":"book.ETH-PERPETUAL.raw","data":{"timestamp":1734114549525,"type":"change","change_id":15557282680,"instrument_name":"ETH-PERPETUAL","bids":[],"asks":[["change",3896.8,1.8e5]],"prev_change_id":15557282679}}}
{"jsonrpc":"2.0","method":"subscription","params":{"channel":"book.ETH-PERPETUAL.raw","data":{"timestamp":1734114549657,"type":"change","change_id":15557282683,"instrument_name":"ETH-PERPETUAL","bids":[["delete",3880.9,0.0]],"asks":[["delete",3896.8,0.0]],"prev_change_id":15557282680}}}
{"jsonrpc":"2.0","method":"subscription","params":{"channel":"book.ETH-PERPETUAL.raw","data":{"timestamp":1734114549657,"type":"change","change_id":15557282683,"instrument_name":"ETH-PERPETUAL","bids":[["delete",3880.9,0.0]],"asks":[["delete",3896.8,0.0]],"prev_change_id":15557282680}}}
{"jsonrpc":"2.0","method":"subscription","params":{"channel":"book.ETH-PERPETUAL.raw","data":{"timestamp":1734114549844,"type":"change","change_id":15557282684,"instrument_name":"ETH-PERPETUAL","bids":[["new",3880.95,8.0e4]],"asks":[],"prev_change_id":15557282683}}}
{"jsonrpc":"2.0","method":"subscription","params":{"channel":"book.ETH-PERPETUAL.raw","data":{"timestamp":1734114549844,"type":"change","change_id":15557282684,"instrument_name":"ETH-PERPETUAL","bids":[["new",3880.95,8.0e4]],"asks":[],"prev_change_id":15557282683}}}
{"jsonrpc":"2.0","method":"subscription","params":{"channel":"book.ETH-PERPETUAL.raw","data":{"timestamp":1734114549847,"type":"change","change_id":15557282685,"instrument_name":"ETH-PERPETUAL","bids":[],"asks":[["new",3896.75,8.0e4]],"prev_change_id":15557282684}}}
{"jsonrpc":"2.0","method":"subscription","params":{"channel":"book.ETH-PERPETUAL.raw","data":{"timestamp":1734114549847,"type":"change","change_id":15557282685,"instrument_name":"ETH-PERPETUAL","bids":[],"asks":[["new",3896.75,8.0e4]],"prev_change_id":15557282684}}}
{"jsonrpc":"2.0","method":"subscription","params":{"channel":"book.ETH-PERPETUAL.raw","data":{"timestamp":1734114549848,"type":"change","change_id":15557282686,"instrument_name":"ETH-PERPETUAL","bids":[["change",3880.95,1.6e5]],"asks":[],"prev_change_id":15557282685}}}
{"jsonrpc":"2.0","method":"subscription","params":{"channel":"book.ETH-PERPETUAL.raw","data":{"timestamp":1734114549848,"type":"change","change_id":15557282686,"instrument_name":"ETH-PERPETUAL","bids":[["change",3880.95,1.6e5]],"asks":[],"prev_change_id":15557282685}}}
{"jsonrpc":"2.0","method":"subscription","params":{"channel":"book.ETH-PERPETUAL.raw","data":{"timestamp":1734114549850,"type":"change","change_id":15557282687,"instrument_name":"ETH-PERPETUAL","bids":[],"asks":[["change",3896.75,1.6e5]],"prev_change_id":15557282686}}}
{"jsonrpc":"2.0","method":"subscription","params":{"channel":"book.ETH-PERPETUAL.raw","data":{"timestamp":1734114549850,"type":"change","change_id":15557282687,"instrument_name":"ETH-PERPETUAL","bids":[],"asks":[["change",3896.75,1.6e5]],"prev_change_id":15557282686}}}
{"jsonrpc":"2.0","method":"subscription","params":{"channel":"book.ETH-PERPETUAL.raw","data":{"timestamp":1734114549851,"type":"change","change_id":15557282688,"instrument_name":"ETH-PERPETUAL","bids":[["change",3880.95,1.8e5]],"asks":[],"prev_change_id":15557282687}}}
{"jsonrpc":"2.0","method":"subscription","params":{"channel":"book.ETH-PERPETUAL.raw","data":{"timestamp":1734114549851,"type":"change","change_id":15557282688,"instrument_name":"ETH-PERPETUAL","bids":[["change",3880.95,1.8e5]],"asks":[],"prev_change_id":15557282687}}}
{"jsonrpc":"2.0","method":"subscription","params":{"channel":"book.ETH-PERPETUAL.raw","data":{"timestamp":1734114549992,"type":"change","change_id":15557282691,"instrument_name":"ETH-PERPETUAL","bids":[["delete",3880.95,0.0]],"asks":[["delete",3896.75,0.0]],"prev_change_id":15557282688}}}
{"jsonrpc":"2.0","method":"subscription","params":{"channel":"book.ETH-PERPETUAL.raw","data":{"timestamp":1734114549992,"type":"change","change_id":15557282691,"instrument_name":"ETH-PERPETUAL","bids":[["delete",3880.95,0.0]],"asks":[["delete",3896.75,0.0]],"prev_change_id":15557282688}}}
{"jsonrpc":"2.0","method":"subscription","params":{"channel":"book.ETH-PERPETUAL.raw","data":{"timestamp":1734114549995,"type":"change","change_id":15557282692,"instrument_name":"ETH-PERPETUAL","bids":[],"asks":[["new",3935.75,700.0],["delete",3949.05,0.0]],"prev_change_id":15557282691}}}
{"jsonrpc":"2.0","method":"subscription","params":{"channel":"book.ETH-PERPETUAL.raw","data":{"timestamp":1734114549995,"type":"change","change_id":15557282692,"instrument_name":"ETH-PERPETUAL","bids":[],"asks":[["new",3935.75,700.0],["delete",3949.05,0.0]],"prev_change_id":15557282691}}}
{"jsonrpc":"2.0","method":"subscription","params":{"channel":"book.ETH-PERPETUAL.raw","data":{"timestamp":1734114550178,"type":"change","change_id":15557282694,"instrument_name":"ETH-PERPETUAL","bids":[["new",3880.95,8.0e4]],"asks":[],"prev_change_id":15557282692}}}
{"jsonrpc":"2.0","method":"subscription","params":{"channel":"book.ETH-PERPETUAL.raw","data":{"timestamp":1734114550178,"type":"change","change_id":15557282694,"instrument_name":"ETH-PERPETUAL","bids":[["new",3880.95,8.0e4]],"asks":[],"prev_change_id":15557282692}}}
{"jsonrpc":"2.0","method":"subscription","params":{"channel":"book.ETH-PERPETUAL.raw","data":{"timestamp":1734114550179,"type":"change","change_id":15557282695,"instrument_name":"ETH-PERPETUAL","bids":[],"asks":[["new",3896.75,8.0e4]],"prev_change_id":15557282694}}}
{"jsonrpc":"2.0","method":"subscription","params":{"channel":"book.ETH-PERPETUAL.raw","data":{"timestamp":1734114550179,"type":"change","change_id":15557282695,"instrument_name":"ETH-PERPETUAL","bids":[],"asks":[["new",3896.75,8.0e4]],"prev_change_id":15557282694}}}
{"jsonrpc":"2.0","method":"subscription","params":{"channel":"book.ETH-PERPETUAL.raw","data":{"timestamp":1734114550180,"type":"change","change_id":15557282696,"instrument_name":"ETH-PERPETUAL","bids":[["change",3880.95,1.0e5]],"asks":[],"prev_change_id":15557282695}}}
{"jsonrpc":"2.0","method":"subscription","params":{"channel":"book.ETH-PERPETUAL.raw","data":{"timestamp":1734114550180,"type":"change","change_id":15557282696,"instrument_name":"ETH-PERPETUAL","bids":[["change",3880.95,1.0e5]],"asks":[],"prev_change_id":15557282695}}}
{"jsonrpc":"2.0","method":"subscription","params":{"channel":"book.ETH-PERPETUAL.raw","data":{"timestamp":1734114550181,"type":"change","change_id":15557282697,"instrument_name":"ETH-PERPETUAL","bids":[["change",3880.95,1.8e5]],"asks":[],"prev_change_id":15557282696}}}
{"jsonrpc":"2.0","method":"subscription","params":{"channel":"book.ETH-PERPETUAL.raw","data":{"timestamp":1734114550181,"type":"change","change_id":15557282697,"instrument_name":"ETH-PERPETUAL","bids":[["change",3880.95,1.8e5]],"asks":[],"prev_change_id":15557282696}}}
{"jsonrpc":"2.0","method":"subscription","params":{"channel":"book.ETH-PERPETUAL.raw","data":{"timestamp":1734114550182,"type":"change","change_id":15557282698,"instrument_name":"ETH-PERPETUAL","bids":[],"asks":[["change",3896.75,1.6e5]],"prev_change_id":15557282697}}}
{"jsonrpc":"2.0","method":"subscription","params":{"channel":"book.ETH-PERPETUAL.raw","data":{"timestamp":1734114550182,"type":"change","change_id":15557282698,"instrument_name":"ETH-PERPETUAL","bids":[],"asks":[["change",3896.75,1.6e5]],"prev_change_id":15557282697}}}
{"jsonrpc":"2.0","method":"subscription","params":{"channel":"book.ETH-PERPETUAL.raw","data":{"timestamp":1734114550183,"type":"change","change_id":15557282699,"instrument_name":"ETH-PERPETUAL","bids":[["change",3880.95,2.0e5]],"asks":[],"prev_change_id":15557282698}}}
{"jsonrpc":"2.0","method":"subscription","params":{"channel":"book.ETH-PERPETUAL.raw","data":{"timestamp":1734114550183,"type":"change","change_id":15557282699,"instrument_name":"ETH-PERPETUAL","bids":[["change",3880.95,2.0e5]],"asks":[],"prev_change_id":15557282698}}}
{"jsonrpc":"2.0","method":"subscription","params":{"channel":"book.ETH-PERPETUAL.raw","data":{"timestamp":1734114550327,"type":"change","change_id":15557282700,"instrument_name":"ETH-PERPETUAL","bids":[["delete",3880.95,0.0]],"asks":[["delete",3896.75,0.0]],"prev_change_id":15557282699}}}
{"jsonrpc":"2.0","method":"subscription","params":{"channel":"book.ETH-PERPETUAL.raw","data":{"timestamp":1734114550327,"type":"change","change_id":15557282700,"instrument_name":"ETH-PERPETUAL","bids":[["delete",3880.95,0.0]],"asks":[["delete",3896.75,0.0]],"prev_change_id":15557282699}}}
{"jsonrpc":"2.0","method":"subscription","params":{"channel":"book.ETH-PERPETUAL.raw","data":{"timestamp":1734114550523,"type":"change","change_id":15557282701,"instrument_name":"ETH-PERPETUAL","bids":[],"asks":[["new",3896.8,8.0e4]],"prev_change_id":15557282700}}}
{"jsonrpc":"2.0","method":"subscription","params":{"channel":"book.ETH-PERPETUAL.raw","data":{"timestamp":1734114550523,"type":"change","change_id":15557282701,"instrument_name":"ETH-PERPETUAL","bids":[],"asks":[["new",3896.8,8.0e4]],"prev_change_id":15557282700}}}
{"jsonrpc":"2.0","method":"subscription","params":{"channel":"book.ETH-PERPETUAL.raw","data":{"timestamp":1734114550524,"type":"change","change_id":15557282702,"instrument_name":"ETH-PERPETUAL","bids":[["new",3881.05,8.0e4]],"asks":[],"prev_change_id":15557282701}}}
{"jsonrpc":"2.0","method":"subscription","params":{"channel":"book.ETH-PERPETUAL.raw","data":{"timestamp":1734114550524,"type":"change","change_id":15557282702,"instrument_name":"ETH-PERPETUAL","bids":[["new",3881.05,8.0e4]],"asks":[],"prev_change_id":15557282701}}}
{"jsonrpc":"2.0","method":"subscription","params":{"channel":"book.ETH-PERPETUAL.raw","data":{"timestamp":1734114550525,"type":"change","change_id":15557282703,"instrument_name":"ETH-PERPETUAL","bids":[],"asks":[["change",3896.8,1.0e5]],"prev_change_id":15557282702}}}
{"jsonrpc":"2.0","method":"subscription","params":{"channel":"book.ETH-PERPETUAL.raw","data":{"timestamp":1734114550525,"type":"change","change_id":15557282703,"instrument_name":"ETH-PERPETUAL","bids":[],"asks":[["change",3896.8,1.0e5]],"prev_change_id":15557282702}}}
{"jsonrpc":"2.0","method":"subscription","params":{"channel":"book.ETH-PERPETUAL.raw","data":{"timestamp":1734114550526,"type":"change","change_id":15557282704,"instrument_name":"ETH-PERPETUAL","bids":[["change",3881.05,1.0e5]],"asks":[],"prev_change_id":15557282703}}}
{"jsonrpc":"2.0","method":"subscription","params":{"channel":"book.ETH-PERPETUAL.raw","data":{"timestamp":1734114550526,"type":"change","change_id":15557282704,"instrument_name":"ETH-PERPETUAL","bids":[["change",3881.05,1.0e5]],"asks":[],"prev_change_id":15557282703}}}
{"jsonrpc":"2.0","method":"subscription","params":{"channel":"book.ETH-PERPETUAL.raw","data":{"timestamp":1734114550527,"type":"change","change_id":15557282705,"instrument_name":"ETH-PERPETUAL","bids":[],"asks":[["change",3896.8,1.8e5]],"prev_change_id":15557282704}}}
{"jsonrpc":"2.0","method":"subscription","params":{"channel":"book.ETH-PERPETUAL.raw","data":{"timestamp":1734114550527,"type":"change","change_id":15557282705,"instrument_name":"ETH-PERPETUAL","bids":[],"asks":[["change",3896.8,1.8e5]],"prev_change_id":15557282704}}}
{"jsonrpc":"2.0","method":"subscription","params":{"channel":"book.ETH-PERPETUAL.raw","data":{"timestamp":1734114550528,"type":"change","change_id":15557282706,"instrument_name":"ETH-PERPETUAL","bids":[["change",3881.05,1.8e5]],"asks":[],"prev_change_id":15557282705}}}
{"jsonrpc":"2.0","method":"subscription","params":{"channel":"book.ETH-PERPETUAL.raw","data":{"timestamp":1734114550528,"type":"change","change_id":15557282706,"instrument_name":"ETH-PERPETUAL","bids":[["change",3881.05,1.8e5]],"asks":[],"prev_change_id":15557282705}}}
{"jsonrpc":"2.0","method":"subscription","params":{"channel":"book.ETH-PERPETUAL.raw","data":{"timestamp":1734114550529,"type":"change","change_id":15557282707,"instrument_name":"ETH-PERPETUAL","bids":[],"asks":[["change",3896.8,2.0e5]],"prev_change_id":15557282706}}}
{"jsonrpc":"2.0","method":"subscription","params":{"channel":"book.ETH-PERPETUAL.raw","data":{"timestamp":1734114550529,"type":"change","change_id":15557282707,"instrument_name":"ETH-PERPETUAL","bids":[],"asks":[["change",3896.8,2.0e5]],"prev_change_id":15557282706}}}
{"jsonrpc":"2.0","method":"subscription","params":{"channel":"book.ETH-PERPETUAL.raw","data":{"timestamp":1734114550530,"type":"change","change_id":15557282708,"instrument_name":"ETH-PERPETUAL","bids":[["change",3881.05,2.0e5]],"asks":[],"prev_change_id":15557282707}}}
{"jsonrpc":"2.0","method":"subscription","params":{"channel":"book.ETH-PERPETUAL.raw","data":{"timestamp":1734114550530,"type":"change","change_id":15557282708,"instrument_name":"ETH-PERPETUAL","bids":[["change",3881.05,2.0e5]],"asks":[],"prev_change_id":15557282707}}}
{"jsonrpc":"2.0","method":"subscription","params":{"channel":"book.ETH-PERPETUAL.raw","data":{"timestamp":1734114550682,"type":"change","change_id":15557282723,"instrument_name":"ETH-PERPETUAL","bids":[["delete",3881.05,0.0]],"asks":[["delete",3896.8,0.0]],"prev_change_id":15557282708}}}
{"jsonrpc":"2.0","method":"subscription","params":{"channel":"book.ETH-PERPETUAL.raw","data":{"timestamp":1734114550682,"type":"change","change_id":15557282723,"instrument_name":"ETH-PERPETUAL","bids":[["delete",3881.05,0.0]],"asks":[["delete",3896.8,0.0]],"prev_change_id":15557282708}}}
{"jsonrpc":"2.0","method":"subscription","params":{"channel":"book.ETH-PERPETUAL.raw","data":{"timestamp":1734114550855,"type":"change","change_id":15557282757,"instrument_name":"ETH-PERPETUAL","bids":[["new",3881.05,8.0e4]],"asks":[],"prev_change_id":15557282723}}}
{"jsonrpc":"2.0","method":"subscription","params":{"channel":"book.ETH-PERPETUAL.raw","data":{"timestamp":1734114550855,"type":"change","change_id":15557282757,"instrument_name":"ETH-PERPETUAL","bids":[["new",3881.05,8.0e4]],"asks":[],"prev_change_id":15557282723}}}
{"jsonrpc":"2.0","method":"subscription","params":{"channel":"book.ETH-PERPETUAL.raw","data":{"timestamp":1734114550857,"type":"change","change_id":15557282758,"instrument_name":"ETH-PERPETUAL","bids":[],"asks":[["new",3896.75,8.0e4]],"prev_change_id":15557282757}}}
{"jsonrpc":"2.0","method":"subscription","params":{"channel":"book.ETH-PERPETUAL.raw","data":{"timestamp":1734114550857,"type":"change","change_id":15557282758,"instrument_name":"ETH-PERPETUAL","bids":[],"asks":[["new",3896.75,8.0e4]],"prev_change_id":15557282757}}}
{"jsonrpc":"2.0","method":"subscription","params":{"channel":"book.ETH-PERPETUAL.raw","data":{"timestamp":1734114550858,"type":"change","change_id":15557282759,"instrument_name":"ETH-PERPETUAL","bids":[["change",3881.05,1.6e5]],"asks":[],"prev_change_id":15557282758}}}
{"jsonrpc":"2.0","method":"subscription","params":{"channel":"book.ETH-PERPETUAL.raw","data":{"timestamp":1734114550858,"type":"change","change_id":15557282759,"instrument_name":"ETH-PERPETUAL","bids":[["change",3881.05,1.6e5]],"asks":[],"prev_change_id":15557282758}}}
{"jsonrpc":"2.0","method":"subscription","params":{"channel":"book.ETH-PERPETUAL.raw","data":{"timestamp":1734114550860,"type":"change","change_id":15557282760,"instrument_name":"ETH-PERPETUAL","bids":[],"asks":[["change",3896.75,1.6e5]],"prev_change_id":15557282759}}}
{"jsonrpc":"2.0","method":"subscription","params":{"channel":"book.ETH-PERPETUAL.raw","data":{"timestamp":1734114550860,"type":"change","change_id":15557282760,"instrument_name":"ETH-PERPETUAL","bids":[],"asks":[["change",3896.75,1.6e5]],"prev_change_id":15557282759}}}
{"jsonrpc":"2.0","method":"subscription","params":{"channel":"book.ETH-PERPETUAL.raw","data":{"timestamp":1734114550989,"type":"change","change_id":15557282764,"instrument_name":"ETH-PERPETUAL","bids":[["delete",3881.05,0.0]],"asks":[["delete",3896.75,0.0]],"prev_change_id":15557282760}}}
{"jsonrpc":"2.0","method":"subscription","params":{"channel":"book.ETH-PERPETUAL.raw","data":{"timestamp":1734114550989,"type":"change","change_id":15557282764,"instrument_name":"ETH-PERPETUAL","bids":[["delete",3881.05,0.0]],"asks":[["delete",3896.75,0.0]],"prev_change_id":15557282760}}}
{"jsonrpc":"2.0","method":"subscription","params":{"channel":"book.ETH-PERPETUAL.raw","data":{"timestamp":1734114551177,"type":"change","change_id":15557282765,"instrument_name":"ETH-PERPETUAL","bids":[["new",3881.15,8.0e4]],"asks":[],"prev_change_id":15557282764}}}
{"jsonrpc":"2.0","method":"subscription","params":{"channel":"book.ETH-PERPETUAL.raw","data":{"timestamp":1734114551177,"type":"change","change_id":15557282765,"instrument_name":"ETH-PERPETUAL","bids":[["new",3881.15,8.0e4]],"asks":[],"prev_change_id":15557282764}}}
{"jsonrpc":"2.0","method":"subscription","params":{"channel":"book.ETH-PERPETUAL.raw","data":{"timestamp":1734114551179,"type":"change","change_id":15557282766,"instrument_name":"ETH-PERPETUAL","bids":[],"asks":[["new",3896.8,8.0e4]],"prev_change_id":15557282765}}}
{"jsonrpc":"2.0","method":"subscription","params":{"channel":"book.ETH-PERPETUAL.raw","data":{"timestamp":1734114551179,"type":"change","change_id":15557282766,"instrument_name":"ETH-PERPETUAL","bids":[],"asks":[["new",3896.8,8.0e4]],"prev_change_id":15557282765}}}
{"jsonrpc":"2.0","method":"subscription","params":{"channel":"book.ETH-PERPETUAL.raw","data":{"timestamp":1734114551181,"type":"change","change_id":15557282767,"instrument_name":"ETH-PERPETUAL","bids":[["change",3881.15,1.0e5]],"asks":[],"prev_change_id":15557282766}}}
{"jsonrpc":"2.0","method":"subscription","params":{"channel":"book.ETH-PERPETUAL.raw","data":{"timestamp":1734114551181,"type":"change","change_id":15557282767,"instrument_name":"ETH-PERPETUAL","bids":[["change",3881.15,1.0e5]],"asks":[],"prev_change_id":15557282766}}}
{"jsonrpc":"2.0","method":"subscription","params":{"channel":"book.ETH-PERPETUAL.raw","data":{"timestamp":1734114551182,"type":"change","change_id":15557282768,"instrument_name":"ETH-PERPETUAL","bids":[["change",3881.15,1.8e5]],"asks":[],"prev_change_id":15557282767}}}
{"jsonrpc":"2.0","method":"subscription","params":{"channel":"book.ETH-PERPETUAL.raw","data":{"timestamp":1734114551182,"type":"change","change_id":15557282768,"instrument_name":"ETH-PERPETUAL","bids":[["change",3881.15,1.8e5]],"asks":[],"prev_change_id":15557282767}}}
{"jsonrpc":"2.0","method":"subscription","params":{"channel":"book.ETH-PERPETUAL.raw","data":{"timestamp":1734114551184,"type":"change","change_id":15557282769,"instrument_name":"ETH-PERPETUAL","bids":[],"asks":[["change",3896.8,1.6e5]],"prev_change_id":15557282768}}}
{"jsonrpc":"2.0","method":"subscription","params":{"channel":"book.ETH-PERPETUAL.raw","data":{"timestamp":1734114551184,"type":"change","change_id":15557282769,"instrument_name":"ETH-PERPETUAL","bids":[],"asks":[["change",3896.8,1.6e5]],"prev_change_id":15557282768}}}
{"jsonrpc":"2.0","method":"subscription","params":{"channel":"book.ETH-PERPETUAL.raw","data":{"timestamp":1734114551185,"type":"change","change_id":15557282770,"instrument_name":"ETH-PERPETUAL","bids":[["change",3881.15,2.0e5]],"asks":[],"prev_change_id":15557282769}}}
{"jsonrpc":"2.0","method":"subscription","params":{"channel":"book.ETH-PERPETUAL.raw","data":{"timestamp":1734114551185,"type":"change","change_id":15557282770,"instrument_name":"ETH-PERPETUAL","bids":[["change",3881.15,2.0e5]],"asks":[],"prev_change_id":15557282769}}}
{"jsonrpc":"2.0","method":"subscription","params":{"channel":"book.ETH-PERPETUAL.raw","data":{"timestamp":1734114551315,"type":"change","change_id":15557282771,"instrument_name":"ETH-PERPETUAL","bids":[["delete",3881.15,0.0]],"asks":[["delete",3896.8,0.0]],"prev_change_id":15557282770}}}
{"jsonrpc":"2.0","method":"subscription","params":{"channel":"book.ETH-PERPETUAL.raw","data":{"timestamp":1734114551315,"type":"change","change_id":15557282771,"instrument_name":"ETH-PERPETUAL","bids":[["delete",3881.15,0.0]],"asks":[["delete",3896.8,0.0]],"prev_change_id":15557282770}}}
{"jsonrpc":"2.0","method":"subscription","params":{"channel":"book.ETH-PERPETUAL.raw","data":{"timestamp":1734114551516,"type":"change","change_id":15557282774,"instrument_name":"ETH-PERPETUAL","bids":[["new",3881.2,8.0e4]],"asks":[],"prev_change_id":15557282771}}}
{"jsonrpc":"2.0","method":"subscription","params":{"channel":"book.ETH-PERPETUAL.raw","data":{"timestamp":1734114551516,"type":"change","change_id":15557282774,"instrument_name":"ETH-PERPETUAL","bids":[["new",3881.2,8.0e4]],"asks":[],"prev_change_id":15557282771}}}
{"jsonrpc":"2.0","method":"subscription","params":{"channel":"book.ETH-PERPETUAL.raw","data":{"timestamp":1734114551518,"type":"change","change_id":15557282775,"instrument_name":"ETH-PERPETUAL","bids":[],"asks":[["new",3896.85,8.0e4]],"prev_change_id":15557282774}}}
{"jsonrpc":"2.0","method":"subscription","params":{"channel":"book.ETH-PERPETUAL.raw","data":{"timestamp":1734114551518,"type":"change","change_id":15557282775,"instrument_name":"ETH-PERPETUAL","bids":[],"asks":[["new",3896.85,8.0e4]],"prev_change_id":15557282774}}}
{"jsonrpc":"2.0","method":"subscription","params":{"channel":"book.ETH-PERPETUAL.raw","data":{"timestamp":1734114551519,"type":"change","change_id":15557282776,"instrument_name":"ETH-PERPETUAL","bids":[["change",3881.2,1.0e5]],"asks":[],"prev_change_id":15557282775}}}
{"jsonrpc":"2.0","method":"subscription","params":{"channel":"book.ETH-PERPETUAL.raw","data":{"timestamp":1734114551519,"type":"change","change_id":15557282776,"instrument_name":"ETH-PERPETUAL","bids":[["change",3881.2,1.0e5]],"asks":[],"prev_change_id":15557282775}}}
{"jsonrpc":"2.0","method":"subscription","params":{"channel":"book.ETH-PERPETUAL.raw","data":{"timestamp":1734114551521,"type":"change","change_id":15557282777,"instrument_name":"ETH-PERPETUAL","bids":[["change",3881.2,1.8e5]],"asks":[],"prev_change_id":15557282776}}}
{"jsonrpc":"2.0","method":"subscription","params":{"channel":"book.ETH-PERPETUAL.raw","data":{"timestamp":1734114551521,"type":"change","change_id":15557282777,"instrument_name":"ETH-PERPETUAL","bids":[["change",3881.2,1.8e5]],"asks":[],"prev_change_id":15557282776}}}
{"jsonrpc":"2.0","method":"subscription","params":{"channel":"book.ETH-PERPETUAL.raw","data":{"timestamp":1734114551522,"type":"change","change_id":15557282778,"instrument_name":"ETH-PERPETUAL","bids":[],"asks":[["change",3896.85,1.6e5]],"prev_change_id":15557282777}}}
{"jsonrpc":"2.0","method":"subscription","params":{"channel":"book.ETH-PERPETUAL.raw","data":{"timestamp":1734114551522,"type":"change","change_id":15557282778,"instrument_name":"ETH-PERPETUAL","bids":[],"asks":[["change",3896.85,1.6e5]],"prev_change_id":15557282777}}}
{"jsonrpc":"2.0","method":"subscription","params":{"channel":"book.ETH-PERPETUAL.raw","data":{"timestamp":1734114551525,"type":"change","change_id":15557282779,"instrument_name":"ETH-PERPETUAL","bids":[["change",3881.2,2.0e5]],"asks":[],"prev_change_id":15557282778}}}
{"jsonrpc":"2.0","method":"subscription","params":{"channel":"book.ETH-PERPETUAL.raw","data":{"timestamp":1734114551525,"type":"change","change_id":15557282779,"instrument_name":"ETH-PERPETUAL","bids":[["change",3881.2,2.0e5]],"asks":[],"prev_change_id":15557282778}}}
{"jsonrpc":"2.0","method":"subscription","params":{"channel":"book.ETH-PERPETUAL.raw","data":{"timestamp":1734114551525,"type":"change","change_id":15557282780,"instrument_name":"ETH-PERPETUAL","bids":[],"asks":[["change",3896.85,1.8e5]],"prev_change_id":15557282779}}}
{"jsonrpc":"2.0","method":"subscription","params":{"channel":"book.ETH-PERPETUAL.raw","data":{"timestamp":1734114551525,"type":"change","change_id":15557282780,"instrument_name":"ETH-PERPETUAL","bids":[],"asks":[["change",3896.85,1.8e5]],"prev_change_id":15557282779}}}
{"jsonrpc":"2.0","method":"subscription","params":{"channel":"book.ETH-PERPETUAL.raw","data":{"timestamp":1734114551644,"type":"change","change_id":15557282784,"instrument_name":"ETH-PERPETUAL","bids":[["delete",3881.2,0.0]],"asks":[["delete",3896.85,0.0]],"prev_change_id":15557282780}}}
{"jsonrpc":"2.0","method":"subscription","params":{"channel":"book.ETH-PERPETUAL.raw","data":{"timestamp":1734114551644,"type":"change","change_id":15557282784,"instrument_name":"ETH-PERPETUAL","bids":[["delete",3881.2,0.0]],"asks":[["delete",3896.85,0.0]],"prev_change_id":15557282780}}}
{"jsonrpc":"2.0","method":"subscription","params":{"channel":"book.ETH-PERPETUAL.raw","data":{"timestamp":1734114551834,"type":"change","change_id":15557282804,"instrument_name":"ETH-PERPETUAL","bids":[],"asks":[["new",3896.85,8.0e4]],"prev_change_id":15557282784}}}
{"jsonrpc":"2.0","method":"subscription","params":{"channel":"book.ETH-PERPETUAL.raw","data":{"timestamp":1734114551834,"type":"change","change_id":15557282804,"instrument_name":"ETH-PERPETUAL","bids":[],"asks":[["new",3896.85,8.0e4]],"prev_change_id":15557282784}}}
{"jsonrpc":"2.0","method":"subscription","params":{"channel":"book.ETH-PERPETUAL.raw","data":{"timestamp":1734114551836,"type":"change","change_id":15557282805,"instrument_name":"ETH-PERPETUAL","bids":[["new",3881.25,8.0e4]],"asks":[],"prev_change_id":15557282804}}}
{"jsonrpc":"2.0","method":"subscription","params":{"channel":"book.ETH-PERPETUAL.raw","data":{"timestamp":1734114551836,"type":"change","change_id":15557282805,"instrument_name":"ETH-PERPETUAL","bids":[["new",3881.25,8.0e4]],"asks":[],"prev_change_id":15557282804}}}
{"jsonrpc":"2.0","method":"subscription","params":{"channel":"book.ETH-PERPETUAL.raw","data":{"timestamp":1734114551838,"type":"change","change_id":15557282806,"instrument_name":"ETH-PERPETUAL","bids":[],"asks":[["change",3896.85,1.6e5]],"prev_change_id":15557282805}}}
{"jsonrpc":"2.0","method":"subscription","params":{"channel":"book.ETH-PERPETUAL.raw","data":{"timestamp":1734114551838,"type":"change","change_id":15557282806,"instrument_name":"ETH-PERPETUAL","bids":[],"asks":[["change",3896.85,1.6e5]],"prev_change_id":15557282805}}}
{"jsonrpc":"2.0","method":"subscription","params":{"channel":"book.ETH-PERPETUAL.raw","data":{"timestamp":1734114551839,"type":"change","change_id":15557282807,"instrument_name":"ETH-PERPETUAL","bids":[["change",3881.25,1.6e5]],"asks":[],"prev_change_id":15557282806}}}
{"jsonrpc":"2.0","method":"subscription","params":{"channel":"book.ETH-PERPETUAL.raw","data":{"timestamp":1734114551839,"type":"change","change_id":15557282807,"instrument_name":"ETH-PERPETUAL","bids":[["change",3881.25,1.6e5]],"asks":[],"prev_change_id":15557282806}}}
{"jsonrpc":"2.0","method":"subscription","params":{"channel":"book.ETH-PERPETUAL.raw","data":{"timestamp":1734114551980,"type":"change","change_id":15557282809,"instrument_name":"ETH-PERPETUAL","bids":[["delete",3881.25,0.0]],"asks":[["delete",3896.85,0.0]],"prev_change_id":15557282807}}}
{"jsonrpc":"2.0","method":"subscription","params":{"channel":"book.ETH-PERPETUAL.raw","data":{"timestamp":1734114551980,"type":"change","change_id":15557282809,"instrument_name":"ETH-PERPETUAL","bids":[["delete",3881.25,0.0]],"asks":[["delete",3896.85,0.0]],"prev_change_id":15557282807}}}
{"jsonrpc":"2.0","method":"subscription","params":{"channel":"book.ETH-PERPETUAL.raw","data":{"timestamp":1734114551980,"type":"change","change_id":15557282810,"instrument_name":"ETH-PERPETUAL","bids":[],"asks":[["new",3908.55,500.0],["delete",3921.65,0.0]],"prev_change_id":15557282809}}}
{"jsonrpc":"2.0","method":"subscription","params":{"channel":"book.ETH-PERPETUAL.raw","data":{"timestamp":1734114551980,"type":"change","change_id":15557282810,"instrument_name":"ETH-PERPETUAL","bids":[],"asks":[["new",3908.55,500.0],["delete",3921.65,0.0]],"prev_change_id":15557282809}}}
{"jsonrpc":"2.0","method":"subscription","params":{"channel":"book.ETH-PERPETUAL.raw","data":{"timestamp":1734114552171,"type":"change","change_id":15557282813,"instrument_name":"ETH-PERPETUAL","bids":[["new",3881.25,8.0e4]],"asks":[],"prev_change_id":15557282810}}}
{"jsonrpc":"2.0","method":"subscription","params":{"channel":"book.ETH-PERPETUAL.raw","data":{"timestamp":1734114552171,"type":"change","change_id":15557282813,"instrument_name":"ETH-PERPETUAL","bids":[["new",3881.25,8.0e4]],"asks":[],"prev_change_id":15557282810}}}
{"jsonrpc":"2.0","method":"subscription","params":{"channel":"book.ETH-PERPETUAL.raw","data":{"timestamp":1734114552176,"type":"change","change_id":15557282814,"instrument_name":"ETH-PERPETUAL","bids":[],"asks":[["new",3896.85,8.0e4]],"prev_change_id":15557282813}}}
{"jsonrpc":"2.0","method":"subscription","params":{"channel":"book.ETH-PERPETUAL.raw","data":{"timestamp":1734114552176,"type":"change","change_id":15557282814,"instrument_name":"ETH-PERPETUAL","bids":[],"asks":[["new",3896.85,8.0e4]],"prev_change_id":15557282813}}}
{"jsonrpc":"2.0","method":"subscription","params":{"channel":"book.ETH-PERPETUAL.raw","data":{"timestamp":1734114552177,"type":"change","change_id":15557282815,"instrument_name":"ETH-PERPETUAL","bids":[["change",3881.25,1.0e5]],"asks":[],"prev_change_id":15557282814}}}
{"jsonrpc":"2.0","method":"subscription","params":{"channel":"book.ETH-PERPETUAL.raw","data":{"timestamp":1734114552177,"type":"change","change_id":15557282815,"instrument_name":"ETH-PERPETUAL","bids":[["change",3881.25,1.0e5]],"asks":[],"prev_change_id":15557282814}}}
{"jsonrpc":"2.0","method":"subscription","params":{"channel":"book.ETH-PERPETUAL.raw","data":{"timestamp":1734114552178,"type":"change","change_id":15557282816,"instrument_name":"ETH-PERPETUAL","bids":[],"asks":[["change",3896.85,1.0e5]],"prev_change_id":15557282815}}}
{"jsonrpc":"2.0","method":"subscription","params":{"channel":"book.ETH-PERPETUAL.raw","data":{"timestamp":1734114552178,"type":"change","change_id":15557282816,"instrument_name":"ETH-PERPETUAL","bids":[],"asks":[["change",3896.85,1.0e5]],"prev_change_id":15557282815}}}
{"jsonrpc":"2.0","method":"subscription","params":{"channel":"book.ETH-PERPETUAL.raw","data":{"timestamp":1734114552179,"type":"change","change_id":15557282817,"instrument_name":"ETH-PERPETUAL","bids":[["change",3881.25,1.8e5]],"asks":[],"prev_change_id":15557282816}}}
{"jsonrpc":"2.0","method":"subscription","params":{"channel":"book.ETH-PERPETUAL.raw","data":{"timestamp":1734114552179,"type":"change","change_id":15557282817,"instrument_name":"ETH-PERPETUAL","bids":[["change",3881.25,1.8e5]],"asks":[],"prev_change_id":15557282816}}}
{"jsonrpc":"2.0","method":"subscription","params":{"channel":"book.ETH-PERPETUAL.raw","data":{"timestamp":1734114552180,"type":"change","change_id":15557282818,"instrument_name":"ETH-PERPETUAL","bids":[],"asks":[["change",3896.85,1.8e5]],"prev_change_id":15557282817}}}
{"jsonrpc":"2.0","method":"subscription","params":{"channel":"book.ETH-PERPETUAL.raw","data":{"timestamp":1734114552180,"type":"change","change_id":15557282818,"instrument_name":"ETH-PERPETUAL","bids":[],"asks":[["change",3896.85,1.8e5]],"prev_change_id":15557282817}}}
{"jsonrpc":"2.0","method":"subscription","params":{"channel":"book.ETH-PERPETUAL.raw","data":{"timestamp":1734114552181,"type":"change","change_id":15557282819,"instrument_name":"ETH-PERPETUAL","bids":[["change",3881.25,2.0e5]],"asks":[],"prev_change_id":15557282818}}}
{"jsonrpc":"2.0","method":"subscription","params":{"channel":"book.ETH-PERPETUAL.raw","data":{"timestamp":1734114552181,"type":"change","change_id":15557282819,"instrument_name":"ETH-PERPETUAL","bids":[["change",3881.25,2.0e5]],"asks":[],"prev_change_id":15557282818}}}
{"jsonrpc":"2.0","method":"subscription","params":{"channel":"book.ETH-PERPETUAL.raw","data":{"timestamp":1734114552184,"type":"change","change_id":15557282820,"instrument_name":"ETH-PERPETUAL","bids":[],"asks":[["change",3896.85,2.0e5]],"prev_change_id":15557282819}}}
{"jsonrpc":"2.0","method":"subscription","params":{"channel":"book.ETH-PERPETUAL.raw","data":{"timestamp":1734114552184,"type":"change","change_id":15557282820,"instrument_name":"ETH-PERPETUAL","bids":[],"asks":[["change",3896.85,2.0e5]],"prev_change_id":15557282819}}}
{"jsonrpc":"2.0","method":"subscription","params":{"channel":"book.ETH-PERPETUAL.raw","data":{"timestamp":1734114552260,"type":"change","change_id":15557282821,"instrument_name":"ETH-PERPETUAL","bids":[["delete",3881.25,0.0]],"asks":[["delete",3896.85,0.0]],"prev_change_id":15557282820}}}
{"jsonrpc":"2.0","method":"subscription","params":{"channel":"book.ETH-PERPETUAL.raw","data":{"timestamp":1734114552260,"type":"change","change_id":15557282821,"instrument_name":"ETH-PERPETUAL","bids":[["delete",3881.25,0.0]],"asks":[["delete",3896.85,0.0]],"prev_change_id":15557282820}}}
{"jsonrpc":"2.0","method":"subscription","params":{"channel":"book.ETH-PERPETUAL.raw","data":{"timestamp":1734114552447,"type":"change","change_id":15557282822,"instrument_name":"ETH-PERPETUAL","bids":[["new",3881.3,8.0e4]],"asks":[],"prev_change_id":15557282821}}}
{"jsonrpc":"2.0","method":"subscription","params":{"channel":"book.ETH-PERPETUAL.raw","data":{"timestamp":1734114552447,"type":"change","change_id":15557282822,"instrument_name":"ETH-PERPETUAL","bids":[["new",3881.3,8.0e4]],"asks":[],"prev_change_id":15557282821}}}
{"jsonrpc":"2.0","method":"subscription","params":{"channel":"book.ETH-PERPETUAL.raw","data":{"timestamp":1734114552449,"type":"change","change_id":15557282823,"instrument_name":"ETH-PERPETUAL","bids":[],"asks":[["new",3896.8,8.0e4]],"prev_change_id":15557282822}}}
{"jsonrpc":"2.0","method":"subscription","params":{"channel":"book.ETH-PERPETUAL.raw","data":{"timestamp":1734114552449,"type":"change","change_id":15557282823,"instrument_name":"ETH-PERPETUAL","bids":[],"asks":[["new",3896.8,8.0e4]],"prev_change_id":15557282822}}}
{"jsonrpc":"2.0","method":"subscription","params":{"channel":"book.ETH-PERPETUAL.raw","data":{"timestamp":1734114552450,"type":"change","change_id":15557282824,"instrument_name":"ETH-PERPETUAL","bids":[["change",3881.3,1.6e5]],"asks":[],"prev_change_id":15557282823}}}
{"jsonrpc":"2.0","method":"subscription","params":{"channel":"book.ETH-PERPETUAL.raw","data":{"timestamp":1734114552450,"type":"change","change_id":15557282824,"instrument_name":"ETH-PERPETUAL","bids":[["change",3881.3,1.6e5]],"asks":[],"prev_change_id":15557282823}}}
{"jsonrpc":"2.0","method":"subscription","params":{"channel":"book.ETH-PERPETUAL.raw","data":{"timestamp":1734114552451,"type":"change","change_id":15557282825,"instrument_name":"ETH-PERPETUAL","bids":[],"asks":[["change",3896.8,1.6e5]],"prev_change_id":15557282824}}}
{"jsonrpc":"2.0","method":"subscription","params":{"channel":"book.ETH-PERPETUAL.raw","data":{"timestamp":1734114552451,"type":"change","change_id":15557282825,"instrument_name":"ETH-PERPETUAL","bids":[],"asks":[["change",3896.8,1.6e5]],"prev_change_id":15557282824}}}
{"jsonrpc":"2.0","method":"subscription","params":{"channel":"book.ETH-PERPETUAL.raw","data":{"timestamp":1734114552582,"type":"change","change_id":15557282827,"instrument_name":"ETH-PERPETUAL","bids":[["delete",3881.3,0.0]],"asks":[["delete",3896.8,0.0]],"prev_change_id":15557282825}}}
{"jsonrpc":"2.0","method":"subscription","params":{"channel":"book.ETH-PERPETUAL.raw","data":{"timestamp":1734114552582,"type":"change","change_id":15557282827,"instrument_name":"ETH-PERPETUAL","bids":[["delete",3881.3,0.0]],"asks":[["delete",3896.8,0.0]],"prev_change_id":15557282825}}}
{"jsonrpc":"2.0","method":"subscription","params":{"channel":"book.ETH-PERPETUAL.raw","data":{"timestamp":1734114552595,"type":"change","change_id":15557282828,"instrument_name":"ETH-PERPETUAL","bids":[],"asks":[["delete",3916.45,0.0],["new",3928.1,500.0]],"prev_change_id":15557282827}}}
{"jsonrpc":"2.0","method":"subscription","params":{"channel":"book.ETH-PERPETUAL.raw","data":{"timestamp":1734114552595,"type":"change","change_id":15557282828,"instrument_name":"ETH-PERPETUAL","bids":[],"asks":[["delete",3916.45,0.0],["new",3928.1,500.0]],"prev_change_id":15557282827}}}
{"jsonrpc":"2.0","method":"subscription","params":{"channel":"book.ETH-PERPETUAL.raw","data":{"timestamp":1734114552791,"type":"change","change_id":15557282908,"instrument_name":"ETH-PERPETUAL","bids":[["new",3881.3,8.0e4]],"asks":[],"prev_change_id":15557282828}}}
{"jsonrpc":"2.0","method":"subscription","params":{"channel":"book.ETH-PERPETUAL.raw","data":{"timestamp":1734114552791,"type":"change","change_id":15557282908,"instrument_name":"ETH-PERPETUAL","bids":[["new",3881.3,8.0e4]],"asks":[],"prev_change_id":15557282828}}}
{"jsonrpc":"2.0","method":"subscription","params":{"channel":"book.ETH-PERPETUAL.raw","data":{"timestamp":1734114552792,"type":"change","change_id":15557282910,"instrument_name":"ETH-PERPETUAL","bids":[],"asks":[["new",3896.8,8.0e4]],"prev_change_id":15557282908}}}
{"jsonrpc":"2.0","method":"subscription","params":{"channel":"book.ETH-PERPETUAL.raw","data":{"timestamp":1734114552792,"type":"change","change_id":15557282910,"instrument_name":"ETH-PERPETUAL","bids":[],"asks":[["new",3896.8,8.0e4]],"prev_change_id":15557282908}}}
{"jsonrpc":"2.0","method":"subscription","params":{"channel":"book.ETH-PERPETUAL.raw","data":{"timestamp":1734114552793,"type":"change","change_id":15557282911,"instrument_name":"ETH-PERPETUAL","bids":[["change",3881.3,1.0e5]],"asks":[],"prev_change_id":15557282910}}}
{"jsonrpc":"2.0","method":"subscription","params":{"channel":"book.ETH-PERPETUAL.raw","data":{"timestamp":1734114552793,"type":"change","change_id":15557282911,"instrument_name":"ETH-PERPETUAL","bids":[["change",3881.3,1.0e5]],"asks":[],"prev_change_id":15557282910}}}
{"jsonrpc":"2.0","method":"subscription","params":{"channel":"book.ETH-PERPETUAL.raw","data":{"timestamp":1734114552794,"type":"change","change_id":15557282913,"instrument_name":"ETH-PERPETUAL","bids":[],"asks":[["change",3896.8,1.0e5]],"prev_change_id":15557282911}}}
{"jsonrpc":"2.0","method":"subscription","params":{"channel":"book.ETH-PERPETUAL.raw","data":{"timestamp":1734114552794,"type":"change","change_id":15557282913,"instrument_name":"ETH-PERPETUAL","bids":[],"asks":[["change",3896.8,1.0e5]],"prev_change_id":15557282911}}}
{"jsonrpc":"2.0","method":"subscription","params":{"channel":"book.ETH-PERPETUAL.raw","data":{"timestamp":1734114552795,"type":"change","change_id":15557282915,"instrument_name":"ETH-PERPETUAL","bids":[["change",3881.3,1.8e5]],"asks":[],"prev_change_id":15557282913}}}
{"jsonrpc":"2.0","method":"subscription","params":{"channel":"book.ETH-PERPETUAL.raw","data":{"timestamp":1734114552795,"type":"change","change_id":15557282915,"instrument_name":"ETH-PERPETUAL","bids":[["change",3881.3,1.8e5]],"asks":[],"prev_change_id":15557282913}}}
{"jsonrpc":"2.0","method":"subscription","params":{"channel":"book.ETH-PERPETUAL.raw","data":{"timestamp":1734114552796,"type":"change","change_id":15557282916,"instrument_name":"ETH-PERPETUAL","bids":[],"asks":[["change",3896.8,1.8e5]],"prev_change_id":15557282915}}}
{"jsonrpc":"2.0","method":"subscription","params":{"channel":"book.ETH-PERPETUAL.raw","data":{"timestamp":1734114552796,"type":"change","change_id":15557282916,"instrument_name":"ETH-PERPETUAL","bids":[],"asks":[["change",3896.8,1.8e5]],"prev_change_id":15557282915}}}
{"jsonrpc":"2.0","method":"subscription","params":{"channel":"book.ETH-PERPETUAL.raw","data":{"timestamp":1734114552797,"type":"change","change_id":15557282918,"instrument_name":"ETH-PERPETUAL","bids":[["change",3881.3,2.0e5]],"asks":[],"prev_change_id":15557282916}}}
{"jsonrpc":"2.0","method":"subscription","params":{"channel":"book.ETH-PERPETUAL.raw","data":{"timestamp":1734114552797,"type":"change","change_id":15557282918,"instrument_name":"ETH-PERPETUAL","bids":[["change",3881.3,2.0e5]],"asks":[],"prev_change_id":15557282916}}}
{"jsonrpc":"2.0","method":"subscription","params":{"channel":"book.ETH-PERPETUAL.raw","data":{"timestamp":1734114552798,"type":"change","change_id":15557282919,"instrument_name":"ETH-PERPETUAL","bids":[],"asks":[["change",3896.8,2.0e5]],"prev_change_id":15557282918}}}
{"jsonrpc":"2.0","method":"subscription","params":{"channel":"book.ETH-PERPETUAL.raw","data":{"timestamp":1734114552798,"type":"change","change_id":15557282919,"instrument_name":"ETH-PERPETUAL","bids":[],"asks":[["change",3896.8,2.0e5]],"prev_change_id":15557282918}}}
{"jsonrpc":"2.0","method":"subscription","params":{"channel":"book.ETH-PERPETUAL.raw","data":{"timestamp":1734114552882,"type":"change","change_id":15557282920,"instrument_name":"ETH-PERPETUAL","bids":[["delete",3881.3,0.0]],"asks":[["delete",3896.8,0.0]],"prev_change_id":15557282919}}}
{"jsonrpc":"2.0","method":"subscription","params":{"channel":"book.ETH-PERPETUAL.raw","data":{"timestamp":1734114552882,"type":"change","change_id":15557282920,"instrument_name":"ETH-PERPETUAL","bids":[["delete",3881.3,0.0]],"asks":[["delete",3896.8,0.0]],"prev_change_id":15557282919}}}
{"jsonrpc":"2.0","method":"subscription","params":{"channel":"book.ETH-PERPETUAL.raw","data":{"timestamp":1734114553072,"type":"change","change_id":15557282921,"instrument_name":"ETH-PERPETUAL","bids":[["new",3881.3,8.0e4]],"asks":[],"prev_change_id":15557282920}}}
{"jsonrpc":"2.0","method":"subscription","params":{"channel":"book.ETH-PERPETUAL.raw","data":{"timestamp":1734114553072,"type":"change","change_id":15557282921,"instrument_name":"ETH-PERPETUAL","bids":[["new",3881.3,8.0e4]],"asks":[],"prev_change_id":15557282920}}}
{"jsonrpc":"2.0","method":"subscription","params":{"channel":"book.ETH-PERPETUAL.raw","data":{"timestamp":1734114553073,"type":"change","change_id":15557282922,"instrument_name":"ETH-PERPETUAL","bids":[],"asks":[["new",3896.8,8.0e4]],"prev_change_id":15557282921}}}
{"jsonrpc":"2.0","method":"subscription","params":{"channel":"book.ETH-PERPETUAL.raw","data":{"timestamp":1734114553073,"type":"change","change_id":15557282922,"instrument_name":"ETH-PERPETUAL","bids":[],"asks":[["new",3896.8,8.0e4]],"prev_change_id":15557282921}}}
{"jsonrpc":"2.0","method":"subscription","params":{"channel":"book.ETH-PERPETUAL.raw","data":{"timestamp":1734114553075,"type":"change","change_id":15557282923,"instrument_name":"ETH-PERPETUAL","bids":[["change",3881.3,1.6e5]],"asks":[],"prev_change_id":15557282922}}}
{"jsonrpc":"2.0","method":"subscription","params":{"channel":"book.ETH-PERPETUAL.raw","data":{"timestamp":1734114553075,"type":"change","change_id":15557282923,"instrument_name":"ETH-PERPETUAL","bids":[["change",3881.3,1.6e5]],"asks":[],"prev_change_id":15557282922}}}
{"jsonrpc":"2.0","method":"subscription","params":{"channel":"book.ETH-PERPETUAL.raw","data":{"timestamp":1734114553076,"type":"change","change_id":15557282924,"instrument_name":"ETH-PERPETUAL","bids":[],"asks":[["change",3896.8,1.6e5]],"prev_change_id":15557282923}}}
{"jsonrpc":"2.0","method":"subscription","params":{"channel":"book.ETH-PERPETUAL.raw","data":{"timestamp":1734114553076,"type":"change","change_id":15557282924,"instrument_name":"ETH-PERPETUAL","bids":[],"asks":[["change",3896.8,1.6e5]],"prev_change_id":15557282923}}}
{"jsonrpc":"2.0","method":"subscription","params":{"channel":"book.ETH-PERPETUAL.raw","data":{"timestamp":1734114553119,"type":"change","change_id":15557282925,"instrument_name":"ETH-PERPETUAL","bids":[["change",10.0,122.0]],"asks":[],"prev_change_id":15557282924}}}
{"jsonrpc":"2.0","method":"subscription","params":{"channel":"book.ETH-PERPETUAL.raw","data":{"timestamp":1734114553119,"type":"change","change_id":15557282925,"instrument_name":"ETH-PERPETUAL","bids":[["change",10.0,122.0]],"asks":[],"prev_change_id":15557282924}}}
{"jsonrpc":"2.0","method":"subscription","params":{"channel":"book.ETH-PERPETUAL.raw","data":{"timestamp":1734114553207,"type":"change","change_id":15557282926,"instrument_name":"ETH-PERPETUAL","bids":[["delete",3881.3,0.0]],"asks":[["delete",3896.8,0.0]],"prev_change_id":15557282925}}}
{"jsonrpc":"2.0","method":"subscription","params":{"channel":"book.ETH-PERPETUAL.raw","data":{"timestamp":1734114553207,"type":"change","change_id":15557282926,"instrument_name":"ETH-PERPETUAL","bids":[["delete",3881.3,0.0]],"asks":[["delete",3896.8,0.0]],"prev_change_id":15557282925}}}
{"jsonrpc":"2.0","method":"subscription","params":{"channel":"book.ETH-PERPETUAL.raw","data":{"timestamp":1734114553406,"type":"change","change_id":15557282927,"instrument_name":"ETH-PERPETUAL","bids":[],"asks":[["new",3896.8,8.0e4]],"prev_change_id":15557282926}}}
{"jsonrpc":"2.0","method":"subscription","params":{"channel":"book.ETH-PERPETUAL.raw","data":{"timestamp":1734114553406,"type":"change","change_id":15557282927,"instrument_name":"ETH-PERPETUAL","bids":[],"asks":[["new",3896.8,8.0e4]],"prev_change_id":15557282926}}}
{"jsonrpc":"2.0","method":"subscription","params":{"channel":"book.ETH-PERPETUAL.raw","data":{"timestamp":1734114553411,"type":"change","change_id":15557282929,"instrument_name":"ETH-PERPETUAL","bids":[["new",3881.35,8.0e4]],"asks":[],"prev_change_id":15557282927}}}
{"jsonrpc":"2.0","method":"subscription","params":{"channel":"book.ETH-PERPETUAL.raw","data":{"timestamp":1734114553411,"type":"change","change_id":15557282929,"instrument_name":"ETH-PERPETUAL","bids":[["new",3881.35,8.0e4]],"asks":[],"prev_change_id":15557282927}}}
{"jsonrpc":"2.0","method":"subscription","params":{"channel":"book.ETH-PERPETUAL.raw","data":{"timestamp":1734114553412,"type":"change","change_id":15557282930,"instrument_name":"ETH-PERPETUAL","bids":[],"asks":[["change",3896.8,1.0e5]],"prev_change_id":15557282929}}}
{"jsonrpc":"2.0","method":"subscription","params":{"channel":"book.ETH-PERPETUAL.raw","data":{"timestamp":1734114553412,"type":"change","change_id":15557282930,"instrument_name":"ETH-PERPETUAL","bids":[],"asks":[["change",3896.8,1.0e5]],"prev_change_id":15557282929}}}
{"jsonrpc":"2.0","method":"subscription","params":{"channel":"book.ETH-PERPETUAL.raw","data":{"timestamp":1734114553413,"type":"change","change_id":15557282931,"instrument_name":"ETH-PERPETUAL","bids":[],"asks":[["change",3896.8,1.8e5]],"prev_change_id":15557282930}}}
{"jsonrpc":"2.0","method":"subscription","params":{"channel":"book.ETH-PERPETUAL.raw","data":{"timestamp":1734114553413,"type":"change","change_id":15557282931,"instrument_name":"ETH-PERPETUAL","bids":[],"asks":[["change",3896.8,1.8e5]],"prev_change_id":15557282930}}}
{"jsonrpc":"2.0","method":"subscription","params":{"channel":"book.ETH-PERPETUAL.raw","data":{"timestamp":1734114553414,"type":"change","change_id":15557282932,"instrument_name":"ETH-PERPETUAL","bids":[["change",3881.35,1.6e5]],"asks":[],"prev_change_id":15557282931}}}
{"jsonrpc":"2.0","method":"subscription","params":{"channel":"book.ETH-PERPETUAL.raw","data":{"timestamp":1734114553414,"type":"change","change_id":15557282932,"instrument_name":"ETH-PERPETUAL","bids":[["change",3881.35,1.6e5]],"asks":[],"prev_change_id":15557282931}}}
{"jsonrpc":"2.0","method":"subscription","params":{"channel":"book.ETH-PERPETUAL.raw","data":{"timestamp":1734114553415,"type":"change","change_id":15557282933,"instrument_name":"ETH-PERPETUAL","bids":[],"asks":[["change",3896.8,2.0e5]],"prev_change_id":15557282932}}}
{"jsonrpc":"2.0","method":"subscription","params":{"channel":"book.ETH-PERPETUAL.raw","data":{"timestamp":1734114553415,"type":"change","change_id":15557282933,"instrument_name":"ETH-PERPETUAL","bids":[],"asks":[["change",3896.8,2.0e5]],"prev_change_id":15557282932}}}
{"jsonrpc":"2.0","method":"subscription","params":{"channel":"book.ETH-PERPETUAL.raw","data":{"timestamp":1734114553494,"type":"change","change_id":15557282934,"instrument_name":"ETH-PERPETUAL","bids":[["delete",3881.35,0.0]],"asks":[["delete",3896.8,0.0]],"prev_change_id":15557282933}}}
{"jsonrpc":"2.0","method":"subscription","params":{"channel":"book.ETH-PERPETUAL.raw","data":{"timestamp":1734114553494,"type":"change","change_id":15557282934,"instrument_name":"ETH-PERPETUAL","bids":[["delete",3881.35,0.0]],"asks":[["delete",3896.8,0.0]],"prev_change_id":15557282933}}}
{"jsonrpc":"2.0","method":"subscription","params":{"channel":"book.ETH-PERPETUAL.raw","data":{"timestamp":1734114553673,"type":"change","change_id":15557282943,"instrument_name":"ETH-PERPETUAL","bids":[["new",3881.35,8.0e4]],"asks":[],"prev_change_id":15557282934}}}
{"jsonrpc":"2.0","method":"subscription","params":{"channel":"book.ETH-PERPETUAL.raw","data":{"timestamp":1734114553673,"type":"change","change_id":15557282943,"instrument_name":"ETH-PERPETUAL","bids":[["new",3881.35,8.0e4]],"asks":[],"prev_change_id":15557282934}}}
{"jsonrpc":"2.0","method":"subscription","params":{"channel":"book.ETH-PERPETUAL.raw","data":{"timestamp":1734114553687,"type":"change","change_id":15557282944,"instrument_name":"ETH-PERPETUAL","bids":[],"asks":[["new",3896.8,8.0e4]],"prev_change_id":15557282943}}}
{"jsonrpc":"2.0","method":"subscription","params":{"channel":"book.ETH-PERPETUAL.raw","data":{"timestamp":1734114553687,"type":"change","change_id":15557282944,"instrument_name":"ETH-PERPETUAL","bids":[],"asks":[["new",3896.8,8.0e4]],"prev_change_id":15557282943}}}
{"jsonrpc":"2.0","method":"subscription","params":{"channel":"book.ETH-PERPETUAL.raw","data":{"timestamp":1734114553690,"type":"change","change_id":15557282946,"instrument_name":"ETH-PERPETUAL","bids":[["change",3881.35,1.0e5]],"asks":[],"prev_change_id":15557282944}}}
{"jsonrpc":"2.0","method":"subscription","params":{"channel":"book.ETH-PERPETUAL.raw","data":{"timestamp":1734114553690,"type":"change","change_id":15557282946,"instrument_name":"ETH-PERPETUAL","bids":[["change",3881.35,1.0e5]],"asks":[],"prev_change_id":15557282944}}}
{"jsonrpc":"2.0","method":"subscription","params":{"channel":"book.ETH-PERPETUAL.raw","data":{"timestamp":1734114553691,"type":"change","change_id":15557282947,"instrument_name":"ETH-PERPETUAL","bids":[["change",3881.35,1.8e5]],"asks":[],"prev_change_id":15557282946}}}
{"jsonrpc":"2.0","method":"subscription","params":{"channel":"book.ETH-PERPETUAL.raw","data":{"timestamp":1734114553691,"type":"change","change_id":15557282947,"instrument_name":"ETH-PERPETUAL","bids":[["change",3881.35,1.8e5]],"asks":[],"prev_change_id":15557282946}}}
{"jsonrpc":"2.0","method":"subscription","params":{"channel":"book.ETH-PERPETUAL.raw","data":{"timestamp":1734114553692,"type":"change","change_id":15557282948,"instrument_name":"ETH-PERPETUAL","bids":[],"asks":[["change",3896.8,1.6e5]],"prev_change_id":15557282947}}}
{"jsonrpc":"2.0","method":"subscription","params":{"channel":"book.ETH-PERPETUAL.raw","data":{"timestamp":1734114553692,"type":"change","change_id":15557282948,"instrument_name":"ETH-PERPETUAL","bids":[],"asks":[["change",3896.8,1.6e5]],"prev_change_id":15557282947}}}
{"jsonrpc":"2.0","method":"subscription","params":{"channel":"book.ETH-PERPETUAL.raw","data":{"timestamp":1734114553693,"type":"change","change_id":15557282949,"instrument_name":"ETH-PERPETUAL","bids":[["change",3881.35,2.0e5]],"asks":[],"prev_change_id":15557282948}}}
{"jsonrpc":"2.0","method":"subscription","params":{"channel":"book.ETH-PERPETUAL.raw","data":{"timestamp":1734114553693,"type":"change","change_id":15557282949,"instrument_name":"ETH-PERPETUAL","bids":[["change",3881.35,2.0e5]],"asks":[],"prev_change_id":15557282948}}}
{"jsonrpc":"2.0","method":"subscription","params":{"channel":"book.ETH-PERPETUAL.raw","data":{"timestamp":1734114553778,"type":"change","change_id":15557282973,"instrument_name":"ETH-PERPETUAL","bids":[["delete",3881.35,0.0]],"asks":[["delete",3896.8,0.0]],"prev_change_id":15557282949}}}
{"jsonrpc":"2.0","method":"subscription","params":{"channel":"book.ETH-PERPETUAL.raw","data":{"timestamp":1734114553778,"type":"change","change_id":15557282973,"instrument_name":"ETH-PERPETUAL","bids":[["delete",3881.35,0.0]],"asks":[["delete",3896.8,0.0]],"prev_change_id":15557282949}}}
{"jsonrpc":"2.0","method":"subscription","params":{"channel":"book.ETH-PERPETUAL.raw","data":{"timestamp":1734114553820,"type":"change","change_id":15557282974,"instrument_name":"ETH-PERPETUAL","bids":[["new",3842.5,700.0],["delete",3833.4,0.0]],"asks":[],"prev_change_id":15557282973}}}
{"jsonrpc":"2.0","method":"subscription","params":{"channel":"book.ETH-PERPETUAL.raw","data":{"timestamp":1734114553820,"type":"change","change_id":15557282974,"instrument_name":"ETH-PERPETUAL","bids":[["new",3842.5,700.0],["delete",3833.4,0.0]],"asks":[],"prev_change_id":15557282973}}}
{"jsonrpc":"2.0","method":"subscription","params":{"channel":"book.ETH-PERPETUAL.raw","data":{"timestamp":1734114553820,"type":"change","change_id":15557282975,"instrument_name":"ETH-PERPETUAL","bids":[["new",3861.9,500.0],["delete",3852.75,0.0]],"asks":[],"prev_change_id":15557282974}}}
{"jsonrpc":"2.0","method":"subscription","params":{"channel":"book.ETH-PERPETUAL.raw","data":{"timestamp":1734114553820,"type":"change","change_id":15557282975,"instrument_name":"ETH-PERPETUAL","bids":[["new",3861.9,500.0],["delete",3852.75,0.0]],"asks":[],"prev_change_id":15557282974}}}
{"jsonrpc":"2.0","method":"subscription","params":{"channel":"book.ETH-PERPETUAL.raw","data":{"timestamp":1734114553980,"type":"change","change_id":15557282976,"instrument_name":"ETH-PERPETUAL","bids":[["new",3881.35,8.0e4]],"asks":[],"prev_change_id":15557282975}}}
{"jsonrpc":"2.0","method":"subscription","params":{"channel":"book.ETH-PERPETUAL.raw","data":{"timestamp":1734114553980,"type":"change","change_id":15557282976,"instrument_name":"ETH-PERPETUAL","bids":[["new",3881.35,8.0e4]],"asks":[],"prev_change_id":15557282975}}}
{"jsonrpc":"2.0","method":"subscription","params":{"channel":"book.ETH-PERPETUAL.raw","data":{"timestamp":1734114553981,"type":"change","change_id":15557282977,"instrument_name":"ETH-PERPETUAL","bids":[],"asks":[["new",3896.75,8.0e4]],"prev_change_id":15557282976}}}
{"jsonrpc":"2.0","method":"subscription","params":{"channel":"book.ETH-PERPETUAL.raw","data":{"timestamp":1734114553981,"type":"change","change_id":15557282977,"instrument_name":"ETH-PERPETUAL","bids":[],"asks":[["new",3896.75,8.0e4]],"prev_change_id":15557282976}}}
{"jsonrpc":"2.0","method":"subscription","params":{"channel":"book.ETH-PERPETUAL.raw","data":{"timestamp":1734114553982,"type":"change","change_id":15557282978,"instrument_name":"ETH-PERPETUAL","bids":[["change",3881.35,1.0e5]],"asks":[],"prev_change_id":15557282977}}}
{"jsonrpc":"2.0","method":"subscription","params":{"channel":"book.ETH-PERPETUAL.raw","data":{"timestamp":1734114553982,"type":"change","change_id":15557282978,"instrument_name":"ETH-PERPETUAL","bids":[["change",3881.35,1.0e5]],"asks":[],"prev_change_id":15557282977}}}
{"jsonrpc":"2.0","method":"subscription","params":{"channel":"book.ETH-PERPETUAL.raw","data":{"timestamp":1734114553983,"type":"change","change_id":15557282979,"instrument_name":"ETH-PERPETUAL","bids":[["change",3881.35,1.8e5]],"asks":[],"prev_change_id":15557282978}}}
{"jsonrpc":"2.0","method":"subscription","params":{"channel":"book.ETH-PERPETUAL.raw","data":{"timestamp":1734114553983,"type":"change","change_id":15557282979,"instrument_name":"ETH-PERPETUAL","bids":[["change",3881.35,1.8e5]],"asks":[],"prev_change_id":15557282978}}}
{"jsonrpc":"2.0","method":"subscription","params":{"channel":"book.ETH-PERPETUAL.raw","data":{"timestamp":1734114553984,"type":"change","change_id":15557282980,"instrument_name":"ETH-PERPETUAL","bids":[],"asks":[["change",3896.75,1.6e5]],"prev_change_id":15557282979}}}
{"jsonrpc":"2.0","method":"subscription","params":{"channel":"book.ETH-PERPETUAL.raw","data":{"timestamp":1734114553984,"type":"change","change_id":15557282980,"instrument_name":"ETH-PERPETUAL","bids":[],"asks":[["change",3896.75,1.6e5]],"prev_change_id":15557282979}}}
{"jsonrpc":"2.0","method":"subscription","params":{"channel":"book.ETH-PERPETUAL.raw","data":{"timestamp":1734114553985,"type":"change","change_id":15557282981,"instrument_name":"ETH-PERPETUAL","bids":[["change",3881.35,2.0e5]],"asks":[],"prev_change_id":15557282980}}}
{"jsonrpc":"2.0","method":"subscription","params":{"channel":"book.ETH-PERPETUAL.raw","data":{"timestamp":1734114553985,"type":"change","change_id":15557282981,"instrument_name":"ETH-PERPETUAL","bids":[["change",3881.35,2.0e5]],"asks":[],"prev_change_id":15557282980}}}
{"jsonrpc":"2.0","method":"subscription","params":{"channel":"book.ETH-PERPETUAL.raw","data":{"timestamp":1734114554125,"type":"change","change_id":15557282985,"instrument_name":"ETH-PERPETUAL","bids":[["new",3869.7,500.0],["delete",3860.5,0.0]],"asks":[],"prev_change_id":15557282981}}}
{"jsonrpc":"2.0","method":"subscription","params":{"channel":"book.ETH-PERPETUAL.raw","data":{"timestamp":1734114554125,"type":"change","change_id":15557282985,"instrument_name":"ETH-PERPETUAL","bids":[["new",3869.7,500.0],["delete",3860.5,0.0]],"asks":[],"prev_change_id":15557282981}}}
{"jsonrpc":"2.0","method":"subscription","params":{"channel":"book.ETH-PERPETUAL.raw","data":{"timestamp":1734114554146,"type":"change","change_id":15557282986,"instrument_name":"ETH-PERPETUAL","bids":[["delete",3881.35,0.0]],"asks":[["delete",3896.75,0.0]],"prev_change_id":15557282985}}}
{"jsonrpc":"2.0","method":"subscription","params":{"channel":"book.ETH-PERPETUAL.raw","data":{"timestamp":1734114554146,"type":"change","change_id":15557282986,"instrument_name":"ETH-PERPETUAL","bids":[["delete",3881.35,0.0]],"asks":[["delete",3896.75,0.0]],"prev_change_id":15557282985}}}
{"jsonrpc":"2.0","method":"subscription","params":{"channel":"book.ETH-PERPETUAL.raw","data":{"timestamp":1734114554342,"type":"change","change_id":15557282988,"instrument_name":"ETH-PERPETUAL","bids":[["new",3881.3,8.0e4]],"asks":[],"prev_change_id":15557282986}}}
{"jsonrpc":"2.0","method":"subscription","params":{"channel":"book.ETH-PERPETUAL.raw","data":{"timestamp":1734114554342,"type":"change","change_id":15557282988,"instrument_name":"ETH-PERPETUAL","bids":[["new",3881.3,8.0e4]],"asks":[],"prev_change_id":15557282986}}}
{"jsonrpc":"2.0","method":"subscription","params":{"channel":"book.ETH-PERPETUAL.raw","data":{"timestamp":1734114554344,"type":"change","change_id":15557282989,"instrument_name":"ETH-PERPETUAL","bids":[],"asks":[["new",3896.7,8.0e4]],"prev_change_id":15557282988}}}
{"jsonrpc":"2.0","method":"subscription","params":{"channel":"book.ETH-PERPETUAL.raw","data":{"timestamp":1734114554344,"type":"change","change_id":15557282989,"instrument_name":"ETH-PERPETUAL","bids":[],"asks":[["new",3896.7,8.0e4]],"prev_change_id":15557282988}}}
{"jsonrpc":"2.0","method":"subscription","params":{"channel":"book.ETH-PERPETUAL.raw","data":{"timestamp":1734114554346,"type":"change","change_id":15557282990,"instrument_name":"ETH-PERPETUAL","bids":[["change",3881.3,1.0e5]],"asks":[],"prev_change_id":15557282989}}}
{"jsonrpc":"2.0","method":"subscription","params":{"channel":"book.ETH-PERPETUAL.raw","data":{"timestamp":1734114554346,"type":"change","change_id":15557282990,"instrument_name":"ETH-PERPETUAL","bids":[["change",3881.3,1.0e5]],"asks":[],"prev_change_id":15557282989}}}
{"jsonrpc":"2.0","method":"subscription","params":{"channel":"book.ETH-PERPETUAL.raw","data":{"timestamp":1734114554348,"type":"change","change_id":15557282991,"instrument_name":"ETH-PERPETUAL","bids":[],"asks":[["change",3896.7,1.0e5]],"prev_change_id":15557282990}}}
{"jsonrpc":"2.0","method":"subscription","params":{"channel":"book.ETH-PERPETUAL.raw","data":{"timestamp":1734114554348,"type":"change","change_id":15557282991,"instrument_name":"ETH-PERPETUAL","bids":[],"asks":[["change",3896.7,1.0e5]],"prev_change_id":15557282990}}}
{"jsonrpc":"2.0","method":"subscription","params":{"channel":"book.ETH-PERPETUAL.raw","data":{"timestamp":1734114554349,"type":"change","change_id":15557282992,"instrument_name":"ETH-PERPETUAL","bids":[["change",3881.3,1.8e5]],"asks":[],"prev_change_id":15557282991}}}
{"jsonrpc":"2.0","method":"subscription","params":{"channel":"book.ETH-PERPETUAL.raw","data":{"timestamp":1734114554349,"type":"change","change_id":15557282992,"instrument_name":"ETH-PERPETUAL","bids":[["change",3881.3,1.8e5]],"asks":[],"prev_change_id":15557282991}}}
{"jsonrpc":"2.0","method":"subscription","params":{"channel":"book.ETH-PERPETUAL.raw","data":{"timestamp":1734114554351,"type":"change","change_id":15557282993,"instrument_name":"ETH-PERPETUAL","bids":[],"asks":[["change",3896.7,1.8e5]],"prev_change_id":15557282992}}}
{"jsonrpc":"2.0","method":"subscription","params":{"channel":"book.ETH-PERPETUAL.raw","data":{"timestamp":1734114554351,"type":"change","change_id":15557282993,"instrument_name":"ETH-PERPETUAL","bids":[],"asks":[["change",3896.7,1.8e5]],"prev_change_id":15557282992}}}
{"jsonrpc":"2.0","method":"subscription","params":{"channel":"book.ETH-PERPETUAL.raw","data":{"timestamp":1734114554352,"type":"change","change_id":15557282994,"instrument_name":"ETH-PERPETUAL","bids":[["change",3881.3,2.0e5]],"asks":[],"prev_change_id":15557282993}}}
{"jsonrpc":"2.0","method":"subscription","params":{"channel":"book.ETH-PERPETUAL.raw","data":{"timestamp":1734114554352,"type":"change","change_id":15557282994,"instrument_name":"ETH-PERPETUAL","bids":[["change",3881.3,2.0e5]],"asks":[],"prev_change_id":15557282993}}}
{"jsonrpc":"2.0","method":"subscription","params":{"channel":"book.ETH-PERPETUAL.raw","data":{"timestamp":1734114554353,"type":"change","change_id":15557282995,"instrument_name":"ETH-PERPETUAL","bids":[],"asks":[["change",3896.7,2.0e5]],"prev_change_id":15557282994}}}
{"jsonrpc":"2.0","method":"subscription","params":{"channel":"book.ETH-PERPETUAL.raw","data":{"timestamp":1734114554353,"type":"change","change_id":15557282995,"instrument_name":"ETH-PERPETUAL","bids":[],"asks":[["change",3896.7,2.0e5]],"prev_change_id":15557282994}}}
{"jsonrpc":"2.0","method":"subscription","params":{"channel":"book.ETH-PERPETUAL.raw","data":{"timestamp":1734114554471,"type":"change","change_id":15557282996,"instrument_name":"ETH-PERPETUAL","bids":[["delete",3881.3,0.0]],"asks":[["delete",3896.7,0.0]],"prev_change_id":15557282995}}}
{"jsonrpc":"2.0","method":"subscription","params":{"channel":"book.ETH-PERPETUAL.raw","data":{"timestamp":1734114554471,"type":"change","change_id":15557282996,"instrument_name":"ETH-PERPETUAL","bids":[["delete",3881.3,0.0]],"asks":[["delete",3896.7,0.0]],"prev_change_id":15557282995}}}
{"jsonrpc":"2.0","method":"subscription","params":{"channel":"book.ETH-PERPETUAL.raw","data":{"timestamp":1734114554657,"type":"change","change_id":15557282998,"instrument_name":"ETH-PERPETUAL","bids":[["new",3881.3,8.0e4]],"asks":[],"prev_change_id":15557282996}}}
{"jsonrpc":"2.0","method":"subscription","params":{"channel":"book.ETH-PERPETUAL.raw","data":{"timestamp":1734114554657,"type":"change","change_id":15557282998,"instrument_name":"ETH-PERPETUAL","bids":[["new",3881.3,8.0e4]],"asks":[],"prev_change_id":15557282996}}}
{"jsonrpc":"2.0","method":"subscription","params":{"channel":"book.ETH-PERPETUAL.raw","data":{"timestamp":1734114554659,"type":"change","change_id":15557282999,"instrument_name":"ETH-PERPETUAL","bids":[],"asks":[["new",3896.7,8.0e4]],"prev_change_id":15557282998}}}
{"jsonrpc":"2.0","method":"subscription","params":{"channel":"book.ETH-PERPETUAL.raw","data":{"timestamp":1734114554659,"type":"change","change_id":15557282999,"instrument_name":"ETH-PERPETUAL","bids":[],"asks":[["new",3896.7,8.0e4]],"prev_change_id":15557282998}}}
{"jsonrpc":"2.0","method":"subscription","params":{"channel":"book.ETH-PERPETUAL.raw","data":{"timestamp":1734114554660,"type":"change","change_id":15557283000,"instrument_name":"ETH-PERPETUAL","bids":[["change",3881.3,1.6e5]],"asks":[],"prev_change_id":15557282999}}}
{"jsonrpc":"2.0","method":"subscription","params":{"channel":"book.ETH-PERPETUAL.raw","data":{"timestamp":1734114554660,"type":"change","change_id":15557283000,"instrument_name":"ETH-PERPETUAL","bids":[["change",3881.3,1.6e5]],"asks":[],"prev_change_id":15557282999}}}
{"jsonrpc":"2.0","method":"subscription","params":{"channel":"book.ETH-PERPETUAL.raw","data":{"timestamp":1734114554662,"type":"change","change_id":15557283001,"instrument_name":"ETH-PERPETUAL","bids":[],"asks":[["change",3896.7,1.6e5]],"prev_change_id":15557283000}}}
{"jsonrpc":"2.0","method":"subscription","params":{"channel":"book.ETH-PERPETUAL.raw","data":{"timestamp":1734114554662,"type":"change","change_id":15557283001,"instrument_name":"ETH-PERPETUAL","bids":[],"asks":[["change",3896.7,1.6e5]],"prev_change_id":15557283000}}}
{"jsonrpc":"2.0","method":"subscription","params":{"channel":"book.ETH-PERPETUAL.raw","data":{"timestamp":1734114554793,"type":"change","change_id":15557283032,"instrument_name":"ETH-PERPETUAL","bids":[["delete",3881.3,0.0]],"asks":[["delete",3896.7,0.0]],"prev_change_id":15557283001}}}
{"jsonrpc":"2.0","method":"subscription","params":{"channel":"book.ETH-PERPETUAL.raw","data":{"timestamp":1734114554793,"type":"change","change_id":15557283032,"instrument_name":"ETH-PERPETUAL","bids":[["delete",3881.3,0.0]],"asks":[["delete",3896.7,0.0]],"prev_change_id":15557283001}}}
{"jsonrpc":"2.0","method":"subscription","params":{"channel":"book.ETH-PERPETUAL.raw","data":{"timestamp":1734114554904,"type":"change","change_id":15557283033,"instrument_name":"ETH-PERPETUAL","bids":[["delete",3872.15,0.0]],"asks":[],"prev_change_id":15557283032}}}
{"jsonrpc":"2.0","method":"subscription","params":{"channel":"book.ETH-PERPETUAL.raw","data":{"timestamp":1734114554904,"type":"change","change_id":15557283033,"instrument_name":"ETH-PERPETUAL","bids":[["delete",3872.15,0.0]],"asks":[],"prev_change_id":15557283032}}}
{"jsonrpc":"2.0","method":"subscription","params":{"channel":"book.ETH-PERPETUAL.raw","data":{"timestamp":1734114554979,"type":"change","change_id":15557283034,"instrument_name":"ETH-PERPETUAL","bids":[["new",3881.3,8.0e4]],"asks":[],"prev_change_id":15557283033}}}
{"jsonrpc":"2.0","method":"subscription","params":{"channel":"book.ETH-PERPETUAL.raw","data":{"timestamp":1734114554979,"type":"change","change_id":15557283034,"instrument_name":"ETH-PERPETUAL","bids":[["new",3881.3,8.0e4]],"asks":[],"prev_change_id":15557283033}}}
{"jsonrpc":"2.0","method":"subscription","params":{"channel":"book.ETH-PERPETUAL.raw","data":{"timestamp":1734114554980,"type":"change","change_id":15557283036,"instrument_name":"ETH-PERPETUAL","bids":[],"asks":[["new",3896.7,8.0e4]],"prev_change_id":15557283034}}}
{"jsonrpc":"2.0","method":"subscription","params":{"channel":"book.ETH-PERPETUAL.raw","data":{"timestamp":1734114554980,"type":"change","change_id":15557283036,"instrument_name":"ETH-PERPETUAL","bids":[],"asks":[["new",3896.7,8.0e4]],"prev_change_id":15557283034}}}
{"jsonrpc":"2.0","method":"subscription","params":{"channel":"book.ETH-PERPETUAL.raw","data":{"timestamp":1734114554981,"type":"change","change_id":15557283037,"instrument_name":"ETH-PERPETUAL","bids":[["change",3881.3,1.0e5]],"asks":[],"prev_change_id":15557283036}}}
{"jsonrpc":"2.0","method":"subscription","params":{"channel":"book.ETH-PERPETUAL.raw","data":{"timestamp":1734114554981,"type":"change","change_id":15557283037,"instrument_name":"ETH-PERPETUAL","bids":[["change",3881.3,1.0e5]],"asks":[],"prev_change_id":15557283036}}}
{"jsonrpc":"2.0","method":"subscription","params":{"channel":"book.ETH-PERPETUAL.raw","data":{"timestamp":1734114554982,"type":"change","change_id":15557283038,"instrument_name":"ETH-PERPETUAL","bids":[["change",3881.3,1.8e5]],"asks":[],"prev_change_id":15557283037}}}
{"jsonrpc":"2.0","method":"subscription","params":{"channel":"book.ETH-PERPETUAL.raw","data":{"timestamp":1734114554982,"type":"change","change_id":15557283038,"instrument_name":"ETH-PERPETUAL","bids":[["change",3881.3,1.8e5]],"asks":[],"prev_change_id":15557283037}}}
{"jsonrpc":"2.0","method":"subscription","params":{"channel":"book.ETH-PERPETUAL.raw","data":{"timestamp":1734114554983,"type":"change","change_id":15557283039,"instrument_name":"ETH-PERPETUAL","bids":[],"asks":[["change",3896.7,1.6e5]],"prev_change_id":15557283038}}}
{"jsonrpc":"2.0","method":"subscription","params":{"channel":"book.ETH-PERPETUAL.raw","data":{"timestamp":1734114554983,"type":"change","change_id":15557283039,"instrument_name":"ETH-PERPETUAL","bids":[],"asks":[["change",3896.7,1.6e5]],"prev_change_id":15557283038}}}
{"jsonrpc":"2.0","method":"subscription","params":{"channel":"book.ETH-PERPETUAL.raw","data":{"timestamp":1734114554984,"type":"change","change_id":15557283040,"instrument_name":"ETH-PERPETUAL","bids":[["change",3881.3,2.0e5]],"asks":[],"prev_change_id":15557283039}}}
{"jsonrpc":"2.0","method":"subscription","params":{"channel":"book.ETH-PERPETUAL.raw","data":{"timestamp":1734114554984,"type":"change","change_id":15557283040,"instrument_name":"ETH-PERPETUAL","bids":[["change",3881.3,2.0e5]],"asks":[],"prev_change_id":15557283039}}}
{"jsonrpc":"2.0","method":"subscription","params":{"channel":"book.ETH-PERPETUAL.raw","data":{"timestamp":1734114555107,"type":"change","change_id":15557283042,"instrument_name":"ETH-PERPETUAL","bids":[["delete",3881.3,0.0]],"asks":[["delete",3896.7,0.0]],"prev_change_id":15557283040}}}
{"jsonrpc":"2.0","method":"subscription","params":{"channel":"book.ETH-PERPETUAL.raw","data":{"timestamp":1734114555107,"type":"change","change_id":15557283042,"instrument_name":"ETH-PERPETUAL","bids":[["delete",3881.3,0.0]],"asks":[["delete",3896.7,0.0]],"prev_change_id":15557283040}}}
{"jsonrpc":"2.0","method":"subscription","params":{"channel":"book.ETH-PERPETUAL.raw","data":{"timestamp":1734114555252,"type":"change","change_id":15557283044,"instrument_name":"ETH-PERPETUAL","bids":[],"asks":[["delete",3935.75,0.0],["new",3948.1,700.0]],"prev_change_id":15557283042}}}
{"jsonrpc":"2.0","method":"subscription","params":{"channel":"book.ETH-PERPETUAL.raw","data":{"timestamp":1734114555252,"type":"change","change_id":15557283044,"instrument_name":"ETH-PERPETUAL","bids":[],"asks":[["delete",3935.75,0.0],["new",3948.1,700.0]],"prev_change_id":15557283042}}}
{"jsonrpc":"2.0","method":"subscription","params":{"channel":"book.ETH-PERPETUAL.raw","data":{"timestamp":1734114555303,"type":"change","change_id":15557283045,"instrument_name":"ETH-PERPETUAL","bids":[["new",3881.35,8.0e4]],"asks":[],"prev_change_id":15557283044}}}
{"jsonrpc":"2.0","method":"subscription","params":{"channel":"book.ETH-PERPETUAL.raw","data":{"timestamp":1734114555303,"type":"change","change_id":15557283045,"instrument_name":"ETH-PERPETUAL","bids":[["new",3881.35,8.0e4]],"asks":[],"prev_change_id":15557283044}}}
{"jsonrpc":"2.0","method":"subscription","params":{"channel":"book.ETH-PERPETUAL.raw","data":{"timestamp":1734114555304,"type":"change","change_id":15557283046,"instrument_name":"ETH-PERPETUAL","bids":[],"asks":[["new",3896.7,8.0e4]],"prev_change_id":15557283045}}}
{"jsonrpc":"2.0","method":"subscription","params":{"channel":"book.ETH-PERPETUAL.raw","data":{"timestamp":1734114555304,"type":"change","change_id":15557283046,"instrument_name":"ETH-PERPETUAL","bids":[],"asks":[["new",3896.7,8.0e4]],"prev_change_id":15557283045}}}
{"jsonrpc":"2.0","method":"subscription","params":{"channel":"book.ETH-PERPETUAL.raw","data":{"timestamp":1734114555305,"type":"change","change_id":15557283047,"instrument_name":"ETH-PERPETUAL","bids":[["change",3881.35,1.0e5]],"asks":[],"prev_change_id":15557283046}}}
{"jsonrpc":"2.0","method":"subscription","params":{"channel":"book.ETH-PERPETUAL.raw","data":{"timestamp":1734114555305,"type":"change","change_id":15557283047,"instrument_name":"ETH-PERPETUAL","bids":[["change",3881.35,1.0e5]],"asks":[],"prev_change_id":15557283046}}}
{"jsonrpc":"2.0","method":"subscription","params":{"channel":"book.ETH-PERPETUAL.raw","data":{"timestamp":1734114555306,"type":"change","change_id":15557283048,"instrument_name":"ETH-PERPETUAL","bids":[["change",3881.35,1.8e5]],"asks":[],"prev_change_id":15557283047}}}
{"jsonrpc":"2.0","method":"subscription","params":{"channel":"book.ETH-PERPETUAL.raw","data":{"timestamp":1734114555306,"type":"change","change_id":15557283048,"instrument_name":"ETH-PERPETUAL","bids":[["change",3881.35,1.8e5]],"asks":[],"prev_change_id":15557283047}}}
{"jsonrpc":"2.0","method":"subscription","params":{"channel":"book.ETH-PERPETUAL.raw","data":{"timestamp":1734114555308,"type":"change","change_id":15557283049,"instrument_name":"ETH-PERPETUAL","bids":[],"asks":[["change",3896.7,1.6e5]],"prev_change_id":15557283048}}}
{"jsonrpc":"2.0","method":"subscription","params":{"channel":"book.ETH-PERPETUAL.raw","data":{"timestamp":1734114555308,"type":"change","change_id":15557283049,"instrument_name":"ETH-PERPETUAL","bids":[],"asks":[["change",3896.7,1.6e5]],"prev_change_id":15557283048}}}
{"jsonrpc":"2.0","method":"subscription","params":{"channel":"book.ETH-PERPETUAL.raw","data":{"timestamp":1734114555309,"type":"change","change_id":15557283050,"instrument_name":"ETH-PERPETUAL","bids":[["change",3881.35,2.0e5]],"asks":[],"prev_change_id":15557283049}}}
{"jsonrpc":"2.0","method":"subscription","params":{"channel":"book.ETH-PERPETUAL.raw","data":{"timestamp":1734114555309,"type":"change","change_id":15557283050,"instrument_name":"ETH-PERPETUAL","bids":[["change",3881.35,2.0e5]],"asks":[],"prev_change_id":15557283049}}}
{"jsonrpc":"2.0","method":"subscription","params":{"channel":"book.ETH-PERPETUAL.raw","data":{"timestamp":1734114555470,"type":"change","change_id":15557283051,"instrument_name":"ETH-PERPETUAL","bids":[["delete",3881.35,0.0]],"asks":[["delete",3896.7,0.0]],"prev_change_id":15557283050}}}
{"jsonrpc":"2.0","method":"subscription","params":{"channel":"book.ETH-PERPETUAL.raw","data":{"timestamp":1734114555470,"type":"change","change_id":15557283051,"instrument_name":"ETH-PERPETUAL","bids":[["delete",3881.35,0.0]],"asks":[["delete",3896.7,0.0]],"prev_change_id":15557283050}}}
{"jsonrpc":"2.0","method":"subscription","params":{"channel":"book.ETH-PERPETUAL.raw","data":{"timestamp":1734114555687,"type":"change","change_id":15557283056,"instrument_name":"ETH-PERPETUAL","bids":[["new",3881.35,8.0e4]],"asks":[],"prev_change_id":15557283051}}}
{"jsonrpc":"2.0","method":"subscription","params":{"channel":"book.ETH-PERPETUAL.raw","data":{"timestamp":1734114555687,"type":"change","change_id":15557283056,"instrument_name":"ETH-PERPETUAL","bids":[["new",3881.35,8.0e4]],"asks":[],"prev_change_id":15557283051}}}
{"jsonrpc":"2.0","method":"subscription","params":{"channel":"book.ETH-PERPETUAL.raw","data":{"timestamp":1734114555689,"type":"change","change_id":15557283058,"instrument_name":"ETH-PERPETUAL","bids":[],"asks":[["new",3896.65,8.0e4]],"prev_change_id":15557283056}}}
{"jsonrpc":"2.0","method":"subscription","params":{"channel":"book.ETH-PERPETUAL.raw","data":{"timestamp":1734114555689,"type":"change","change_id":15557283058,"instrument_name":"ETH-PERPETUAL","bids":[],"asks":[["new",3896.65,8.0e4]],"prev_change_id":15557283056}}}
{"jsonrpc":"2.0","method":"subscription","params":{"channel":"book.ETH-PERPETUAL.raw","data":{"timestamp":1734114555690,"type":"change","change_id":15557283059,"instrument_name":"ETH-PERPETUAL","bids":[["change",3881.35,1.0e5]],"asks":[],"prev_change_id":15557283058}}}
{"jsonrpc":"2.0","method":"subscription","params":{"channel":"book.ETH-PERPETUAL.raw","data":{"timestamp":1734114555690,"type":"change","change_id":15557283059,"instrument_name":"ETH-PERPETUAL","bids":[["change",3881.35,1.0e5]],"asks":[],"prev_change_id":15557283058}}}
{"jsonrpc":"2.0","method":"subscription","params":{"channel":"book.ETH-PERPETUAL.raw","data":{"timestamp":1734114555691,"type":"change","change_id":15557283060,"instrument_name":"ETH-PERPETUAL","bids":[],"asks":[["change",3896.65,1.0e5]],"prev_change_id":15557283059}}}
{"jsonrpc":"2.0","method":"subscription","params":{"channel":"book.ETH-PERPETUAL.raw","data":{"timestamp":1734114555691,"type":"change","change_id":15557283060,"instrument_name":"ETH-PERPETUAL","bids":[],"asks":[["change",3896.65,1.0e5]],"prev_change_id":15557283059}}}
{"jsonrpc":"2.0","method":"subscription","params":{"channel":"book.ETH-PERPETUAL.raw","data":{"timestamp":1734114555696,"type":"change","change_id":15557283063,"instrument_name":"ETH-PERPETUAL","bids":[["change",3881.35,1.8e5]],"asks":[],"prev_change_id":15557283060}}}
{"jsonrpc":"2.0","method":"subscription","params":{"channel":"book.ETH-PERPETUAL.raw","data":{"timestamp":1734114555696,"type":"change","change_id":15557283063,"instrument_name":"ETH-PERPETUAL","bids":[["change",3881.35,1.8e5]],"asks":[],"prev_change_id":15557283060}}}
{"jsonrpc":"2.0","method":"subscription","params":{"channel":"book.ETH-PERPETUAL.raw","data":{"timestamp":1734114555697,"type":"change","change_id":15557283064,"instrument_name":"ETH-PERPETUAL","bids":[],"asks":[["change",3896.65,1.8e5]],"prev_change_id":15557283063}}}
{"jsonrpc":"2.0","method":"subscription","params":{"channel":"book.ETH-PERPETUAL.raw","data":{"timestamp":1734114555697,"type":"change","change_id":15557283064,"instrument_name":"ETH-PERPETUAL","bids":[],"asks":[["change",3896.65,1.8e5]],"prev_change_id":15557283063}}}
{"jsonrpc":"2.0","method":"subscription","params":{"channel":"book.ETH-PERPETUAL.raw","data":{"timestamp":1734114555698,"type":"change","change_id":15557283065,"instrument_name":"ETH-PERPETUAL","bids":[["change",3881.35,2.0e5]],"asks":[],"prev_change_id":15557283064}}}
{"jsonrpc":"2.0","method":"subscription","params":{"channel":"book.ETH-PERPETUAL.raw","data":{"timestamp":1734114555698,"type":"change","change_id":15557283065,"instrument_name":"ETH-PERPETUAL","bids":[["change",3881.35,2.0e5]],"asks":[],"prev_change_id":15557283064}}}
{"jsonrpc":"2.0","method":"subscription","params":{"channel":"book.ETH-PERPETUAL.raw","data":{"timestamp":1734114555699,"type":"change","change_id":15557283066,"instrument_name":"ETH-PERPETUAL","bids":[],"asks":[["change",3896.65,2.0e5]],"prev_change_id":15557283065}}}
{"jsonrpc":"2.0","method":"subscription","params":{"channel":"book.ETH-PERPETUAL.raw","data":{"timestamp":1734114555699,"type":"change","change_id":15557283066,"instrument_name":"ETH-PERPETUAL","bids":[],"asks":[["change",3896.65,2.0e5]],"prev_change_id":15557283065}}}
{"jsonrpc":"2.0","method":"subscription","params":{"channel":"book.ETH-PERPETUAL.raw","data":{"timestamp":1734114555786,"type":"change","change_id":15557283069,"instrument_name":"ETH-PERPETUAL","bids":[["delete",3881.35,0.0]],"asks":[["delete",3896.65,0.0]],"prev_change_id":15557283066}}}
{"jsonrpc":"2.0","method":"subscription","params":{"channel":"book.ETH-PERPETUAL.raw","data":{"timestamp":1734114555786,"type":"change","change_id":15557283069,"instrument_name":"ETH-PERPETUAL","bids":[["delete",3881.35,0.0]],"asks":[["delete",3896.65,0.0]],"prev_change_id":15557283066}}}
{"jsonrpc":"2.0","method":"subscription","params":{"channel":"book.ETH-PERPETUAL.raw","data":{"timestamp":1734114555973,"type":"change","change_id":15557283070,"instrument_name":"ETH-PERPETUAL","bids":[["new",3881.35,8.0e4]],"asks":[],"prev_change_id":15557283069}}}
{"jsonrpc":"2.0","method":"subscription","params":{"channel":"book.ETH-PERPETUAL.raw","data":{"timestamp":1734114555973,"type":"change","change_id":15557283070,"instrument_name":"ETH-PERPETUAL","bids":[["new",3881.35,8.0e4]],"asks":[],"prev_change_id":15557283069}}}
{"jsonrpc":"2.0","method":"subscription","params":{"channel":"book.ETH-PERPETUAL.raw","data":{"timestamp":1734114555974,"type":"change","change_id":15557283071,"instrument_name":"ETH-PERPETUAL","bids":[],"asks":[["new",3896.65,8.0e4]],"prev_change_id":15557283070}}}
{"jsonrpc":"2.0","method":"subscription","params":{"channel":"book.ETH-PERPETUAL.raw","data":{"timestamp":1734114555974,"type":"change","change_id":15557283071,"instrument_name":"ETH-PERPETUAL","bids":[],"asks":[["new",3896.65,8.0e4]],"prev_change_id":15557283070}}}
{"jsonrpc":"2.0","method":"subscription","params":{"channel":"book.ETH-PERPETUAL.raw","data":{"timestamp":1734114555975,"type":"change","change_id":15557283072,"instrument_name":"ETH-PERPETUAL","bids":[["change",3881.35,1.6e5]],"asks":[],"prev_change_id":15557283071}}}
{"jsonrpc":"2.0","method":"subscription","params":{"channel":"book.ETH-PERPETUAL.raw","data":{"timestamp":1734114555975,"type":"change","change_id":15557283072,"instrument_name":"ETH-PERPETUAL","bids":[["change",3881.35,1.6e5]],"asks":[],"prev_change_id":15557283071}}}
{"jsonrpc":"2.0","method":"subscription","params":{"channel":"book.ETH-PERPETUAL.raw","data":{"timestamp":1734114555976,"type":"change","change_id":15557283073,"instrument_name":"ETH-PERPETUAL","bids":[],"asks":[["change",3896.65,1.6e5]],"prev_change_id":15557283072}}}
{"jsonrpc":"2.0","method":"subscription","params":{"channel":"book.ETH-PERPETUAL.raw","data":{"timestamp":1734114555976,"type":"change","change_id":15557283073,"instrument_name":"ETH-PERPETUAL","bids":[],"asks":[["change",3896.65,1.6e5]],"prev_change_id":15557283072}}}
{"jsonrpc":"2.0","method":"subscription","params":{"channel":"book.ETH-PERPETUAL.raw","data":{"timestamp":1734114556103,"type":"change","change_id":15557283074,"instrument_name":"ETH-PERPETUAL","bids":[["delete",3881.35,0.0]],"asks":[["delete",3896.65,0.0]],"prev_change_id":15557283073}}}
{"jsonrpc":"2.0","method":"subscription","params":{"channel":"book.ETH-PERPETUAL.raw","data":{"timestamp":1734114556103,"type":"change","change_id":15557283074,"instrument_name":"ETH-PERPETUAL","bids":[["delete",3881.35,0.0]],"asks":[["delete",3896.65,0.0]],"prev_change_id":15557283073}}}
{"jsonrpc":"2.0","method":"subscription","params":{"channel":"book.ETH-PERPETUAL.raw","data":{"timestamp":1734114556299,"type":"change","change_id":15557283076,"instrument_name":"ETH-PERPETUAL","bids":[["new",3881.35,8.0e4]],"asks":[],"prev_change_id":15557283074}}}
{"jsonrpc":"2.0","method":"subscription","params":{"channel":"book.ETH-PERPETUAL.raw","data":{"timestamp":1734114556299,"type":"change","change_id":15557283076,"instrument_name":"ETH-PERPETUAL","bids":[["new",3881.35,8.0e4]],"asks":[],"prev_change_id":15557283074}}}
{"jsonrpc":"2.0","method":"subscription","params":{"channel":"book.ETH-PERPETUAL.raw","data":{"timestamp":1734114556301,"type":"change","change_id":15557283077,"instrument_name":"ETH-PERPETUAL","bids":[],"asks":[["new",3896.65,8.0e4]],"prev_change_id":15557283076}}}
{"jsonrpc":"2.0","method":"subscription","params":{"channel":"book.ETH-PERPETUAL.raw","data":{"timestamp":1734114556301,"type":"change","change_id":15557283077,"instrument_name":"ETH-PERPETUAL","bids":[],"asks":[["new",3896.65,8.0e4]],"prev_change_id":15557283076}}}
{"jsonrpc":"2.0","method":"subscription","params":{"channel":"book.ETH-PERPETUAL.raw","data":{"timestamp":1734114556302,"type":"change","change_id":15557283078,"instrument_name":"ETH-PERPETUAL","bids":[["change",3881.35,1.0e5]],"asks":[],"prev_change_id":15557283077}}}
{"jsonrpc":"2.0","method":"subscription","params":{"channel":"book.ETH-PERPETUAL.raw","data":{"timestamp":1734114556302,"type":"change","change_id":15557283078,"instrument_name":"ETH-PERPETUAL","bids":[["change",3881.35,1.0e5]],"asks":[],"prev_change_id":15557283077}}}
{"jsonrpc":"2.0","method":"subscription","params":{"channel":"book.ETH-PERPETUAL.raw","data":{"timestamp":1734114556304,"type":"change","change_id":15557283079,"instrument_name":"ETH-PERPETUAL","bids":[],"asks":[["change",3896.65,1.0e5]],"prev_change_id":15557283078}}}
{"jsonrpc":"2.0","method":"subscription","params":{"channel":"book.ETH-PERPETUAL.raw","data":{"timestamp":1734114556304,"type":"change","change_id":15557283079,"instrument_name":"ETH-PERPETUAL","bids":[],"asks":[["change",3896.65,1.0e5]],"prev_change_id":15557283078}}}
{"jsonrpc":"2.0","method":"subscription","params":{"channel":"book.ETH-PERPETUAL.raw","data":{"timestamp":1734114556305,"type":"change","change_id":15557283080,"instrument_name":"ETH-PERPETUAL","bids":[["change",3881.35,1.8e5]],"asks":[],"prev_change_id":15557283079}}}
{"jsonrpc":"2.0","method":"subscription","params":{"channel":"book.ETH-PERPETUAL.raw","data":{"timestamp":1734114556305,"type":"change","change_id":15557283080,"instrument_name":"ETH-PERPETUAL","bids":[["change",3881.35,1.8e5]],"asks":[],"prev_change_id":15557283079}}}
{"jsonrpc":"2.0","method":"subscription","params":{"channel":"book.ETH-PERPETUAL.raw","data":{"timestamp":1734114556307,"type":"change","change_id":15557283081,"instrument_name":"ETH-PERPETUAL","bids":[],"asks":[["change",3896.65,1.8e5]],"prev_change_id":15557283080}}}
{"jsonrpc":"2.0","method":"subscription","params":{"channel":"book.ETH-PERPETUAL.raw","data":{"timestamp":1734114556307,"type":"change","change_id":15557283081,"instrument_name":"ETH-PERPETUAL","bids":[],"asks":[["change",3896.65,1.8e5]],"prev_change_id":15557283080}}}
{"jsonrpc":"2.0","method":"subscription","params":{"channel":"book.ETH-PERPETUAL.raw","data":{"timestamp":1734114556309,"type":"change","change_id":15557283082,"instrument_name":"ETH-PERPETUAL","bids":[["change",3881.35,2.0e5]],"asks":[],"prev_change_id":15557283081}}}
{"jsonrpc":"2.0","method":"subscription","params":{"channel":"book.ETH-PERPETUAL.raw","data":{"timestamp":1734114556309,"type":"change","change_id":15557283082,"instrument_name":"ETH-PERPETUAL","bids":[["change",3881.35,2.0e5]],"asks":[],"prev_change_id":15557283081}}}
{"jsonrpc":"2.0","method":"subscription","params":{"channel":"book.ETH-PERPETUAL.raw","data":{"timestamp":1734114556310,"type":"change","change_id":15557283083,"instrument_name":"ETH-PERPETUAL","bids":[],"asks":[["change",3896.65,2.0e5]],"prev_change_id":15557283082}}}
{"jsonrpc":"2.0","method":"subscription","params":{"channel":"book.ETH-PERPETUAL.raw","data":{"timestamp":1734114556310,"type":"change","change_id":15557283083,"instrument_name":"ETH-PERPETUAL","bids":[],"asks":[["change",3896.65,2.0e5]],"prev_change_id":15557283082}}}
{"jsonrpc":"2.0","method":"subscription","params":{"channel":"book.ETH-PERPETUAL.raw","data":{"timestamp":1734114556423,"type":"change","change_id":15557283085,"instrument_name":"ETH-PERPETUAL","bids":[["delete",3881.35,0.0]],"asks":[["delete",3896.65,0.0]],"prev_change_id":15557283083}}}
{"jsonrpc":"2.0","method":"subscription","params":{"channel":"book.ETH-PERPETUAL.raw","data":{"timestamp":1734114556423,"type":"change","change_id":15557283085,"instrument_name":"ETH-PERPETUAL","bids":[["delete",3881.35,0.0]],"asks":[["delete",3896.65,0.0]],"prev_change_id":15557283083}}}
{"jsonrpc":"2.0","method":"subscription","params":{"channel":"book.ETH-PERPETUAL.raw","data":{"timestamp":1734114556629,"type":"change","change_id":15557283094,"instrument_name":"ETH-PERPETUAL","bids":[["new",3881.2,8.0e4]],"asks":[],"prev_change_id":15557283085}}}
{"jsonrpc":"2.0","method":"subscription","params":{"channel":"book.ETH-PERPETUAL.raw","data":{"timestamp":1734114556629,"type":"change","change_id":15557283094,"instrument_name":"ETH-PERPETUAL","bids":[["new",3881.2,8.0e4]],"asks":[],"prev_change_id":15557283085}}}
{"jsonrpc":"2.0","method":"subscription","params":{"channel":"book.ETH-PERPETUAL.raw","data":{"timestamp":1734114556631,"type":"change","change_id":15557283095,"instrument_name":"ETH-PERPETUAL","bids":[],"asks":[["new",3896.5,8.0e4]],"prev_change_id":15557283094}}}
{"jsonrpc":"2.0","method":"subscription","params":{"channel":"book.ETH-PERPETUAL.raw","data":{"timestamp":1734114556631,"type":"change","change_id":15557283095,"instrument_name":"ETH-PERPETUAL","bids":[],"asks":[["new",3896.5,8.0e4]],"prev_change_id":15557283094}}}
{"jsonrpc":"2.0","method":"subscription","params":{"channel":"book.ETH-PERPETUAL.raw","data":{"timestamp":1734114556632,"type":"change","change_id":15557283096,"instrument_name":"ETH-PERPETUAL","bids":[["change",3881.2,1.0e5]],"asks":[],"prev_change_id":15557283095}}}
{"jsonrpc":"2.0","method":"subscription","params":{"channel":"book.ETH-PERPETUAL.raw","data":{"timestamp":1734114556632,"type":"change","change_id":15557283096,"instrument_name":"ETH-PERPETUAL","bids":[["change",3881.2,1.0e5]],"asks":[],"prev_change_id":15557283095}}}
{"jsonrpc":"2.0","method":"subscription","params":{"channel":"book.ETH-PERPETUAL.raw","data":{"timestamp":1734114556633,"type":"change","change_id":15557283097,"instrument_name":"ETH-PERPETUAL","bids":[["change",3881.2,1.8e5]],"asks":[],"prev_change_id":15557283096}}}
{"jsonrpc":"2.0","method":"subscription","params":{"channel":"book.ETH-PERPETUAL.raw","data":{"timestamp":1734114556633,"type":"change","change_id":15557283097,"instrument_name":"ETH-PERPETUAL","bids":[["change",3881.2,1.8e5]],"asks":[],"prev_change_id":15557283096}}}
{"jsonrpc":"2.0","method":"subscription","params":{"channel":"book.ETH-PERPETUAL.raw","data":{"timestamp":1734114556635,"type":"change","change_id":15557283098,"instrument_name":"ETH-PERPETUAL","bids":[],"asks":[["change",3896.5,1.6e5]],"prev_change_id":15557283097}}}
{"jsonrpc":"2.0","method":"subscription","params":{"channel":"book.ETH-PERPETUAL.raw","data":{"timestamp":1734114556635,"type":"change","change_id":15557283098,"instrument_name":"ETH-PERPETUAL","bids":[],"asks":[["change",3896.5,1.6e5]],"prev_change_id":15557283097}}}
{"jsonrpc":"2.0","method":"subscription","params":{"channel":"book.ETH-PERPETUAL.raw","data":{"timestamp":1734114556636,"type":"change","change_id":15557283099,"instrument_name":"ETH-PERPETUAL","bids":[["change",3881.2,2.0e5]],"asks":[],"prev_change_id":15557283098}}}
{"jsonrpc":"2.0","method":"subscription","params":{"channel":"book.ETH-PERPETUAL.raw","data":{"timestamp":1734114556636,"type":"change","change_id":15557283099,"instrument_name":"ETH-PERPETUAL","bids":[["change",3881.2,2.0e5]],"asks":[],"prev_change_id":15557283098}}}
{"jsonrpc":"2.0","method":"subscription","params":{"channel":"book.ETH-PERPETUAL.raw","data":{"timestamp":1734114556776,"type":"change","change_id":15557283127,"instrument_name":"ETH-PERPETUAL","bids":[["delete",3881.2,0.0]],"asks":[["delete",3896.5,0.0]],"prev_change_id":15557283099}}}
{"jsonrpc":"2.0","method":"subscription","params":{"channel":"book.ETH-PERPETUAL.raw","data":{"timestamp":1734114556776,"type":"change","change_id":15557283127,"instrument_name":"ETH-PERPETUAL","bids":[["delete",3881.2,0.0]],"asks":[["delete",3896.5,0.0]],"prev_change_id":15557283099}}}
{"jsonrpc":"2.0","method":"subscription","params":{"channel":"book.ETH-PERPETUAL.raw","data":{"timestamp":1734114556985,"type":"change","change_id":15557283130,"instrument_name":"ETH-PERPETUAL","bids":[["new",3881.2,8.0e4]],"asks":[],"prev_change_id":15557283127}}}
{"jsonrpc":"2.0","method":"subscription","params":{"channel":"book.ETH-PERPETUAL.raw","data":{"timestamp":1734114556985,"type":"change","change_id":15557283130,"instrument_name":"ETH-PERPETUAL","bids":[["new",3881.2,8.0e4]],"asks":[],"prev_change_id":15557283127}}}
