{"jsonrpc":"2.0","method":"subscription","params":{"channel":"book.ETH-PERPETUAL.raw","data":{"timestamp":1734114588070,"type":"change","change_id":15557284439,"instrument_name":"ETH-PERPETUAL","bids":[["change",3881.65,2.0e5]],"asks":[],"prev_change_id":15557284438}}}
{"jsonrpc":"2.0","method":"subscription","params":{"channel":"book.ETH-PERPETUAL.raw","data":{"timestamp":1734114588070,"type":"change","change_id":15557284439,"instrument_name":"ETH-PERPETUAL","bids":[["change",3881.65,2.0e5]],"asks":[],"prev_change_id":15557284438}}}
{"jsonrpc":"2.0","method":"subscription","params":{"channel":"book.ETH-PERPETUAL.raw","data":{"timestamp":1734114588160,"type":"change","change_id":15557284442,"instrument_name":"ETH-PERPETUAL","bids":[["delete",3881.65,0.0]],"asks":[["delete",3896.65,0.0]],"prev_change_id":15557284439}}}
{"jsonrpc":"2.0","method":"subscription","params":{"channel":"book.ETH-PERPETUAL.raw","data":{"timestamp":1734114588160,"type":"change","change_id":15557284442,"instrument_name":"ETH-PERPETUAL","bids":[["delete",3881.65,0.0]],"asks":[["delete",3896.65,0.0]],"prev_change_id":15557284439}}}
{"jsonrpc":"2.0","method":"subscription","params":{"channel":"book.ETH-PERPETUAL.raw","data":{"timestamp":1734114588350,"type":"change","change_id":15557284445,"instrument_name":"ETH-PERPETUAL","bids":[],"asks":[["new",3896.65,8.0e4]],"prev_change_id":15557284442}}}
{"jsonrpc":"2.0","method":"subscription","params":{"channel":"book.ETH-PERPETUAL.raw","data":{"timestamp":1734114588350,"type":"change","change_id":15557284445,"instrument_name":"ETH-PERPETUAL","bids":[],"asks":[["new",3896.65,8.0e4]],"prev_change_id":15557284442}}}
{"jsonrpc":"2.0","method":"subscription","params":{"channel":"book.ETH-PERPETUAL.raw","data":{"timestamp":1734114588352,"type":"change","change_id":15557284446,"instrument_name":"ETH-PERPETUAL","bids":[["new",3881.65,8.0e4]],"asks":[],"prev_change_id":15557284445}}}
{"jsonrpc":"2.0","method":"subscription","params":{"channel":"book.ETH-PERPETUAL.raw","data":{"timestamp":1734114588352,"type":"change","change_id":15557284446,"instrument_name":"ETH-PERPETUAL","bids":[["new",3881.65,8.0e4]],"asks":[],"prev_change_id":15557284445}}}
{"jsonrpc":"2.0","method":"subscription","params":{"channel":"book.ETH-PERPETUAL.raw","data":{"timestamp":1734114588354,"type":"change","change_id":15557284447,"instrument_name":"ETH-PERPETUAL","bids":[],"asks":[["change",3896.65,1.6e5]],"prev_change_id":15557284446}}}
{"jsonrpc":"2.0","method":"subscription","params":{"channel":"book.ETH-PERPETUAL.raw","data":{"timestamp":1734114588354,"type":"change","change_id":15557284447,"instrument_name":"ETH-PERPETUAL","bids":[],"asks":[["change",3896.65,1.6e5]],"prev_change_id":15557284446}}}
{"jsonrpc":"2.0","method":"subscription","params":{"channel":"book.ETH-PERPETUAL.raw","data":{"timestamp":1734114588355,"type":"change","change_id":15557284448,"instrument_name":"ETH-PERPETUAL","bids":[["change",3881.65,1.6e5]],"asks":[],"prev_change_id":15557284447}}}
{"jsonrpc":"2.0","method":"subscription","params":{"channel":"book.ETH-PERPETUAL.raw","data":{"timestamp":1734114588355,"type":"change","change_id":15557284448,"instrument_name":"ETH-PERPETUAL","bids":[["change",3881.65,1.6e5]],"asks":[],"prev_change_id":15557284447}}}
{"jsonrpc":"2.0","method":"subscription","params":{"channel":"book.ETH-PERPETUAL.raw","data":{"timestamp":1734114588473,"type":"change","change_id":15557284449,"instrument_name":"ETH-PERPETUAL","bids":[["delete",3881.65,0.0]],"asks":[["delete",3896.65,0.0]],"prev_change_id":15557284448}}}
{"jsonrpc":"2.0","method":"subscription","params":{"channel":"book.ETH-PERPETUAL.raw","data":{"timestamp":1734114588473,"type":"change","change_id":15557284449,"instrument_name":"ETH-PERPETUAL","bids":[["delete",3881.65,0.0]],"asks":[["delete",3896.65,0.0]],"prev_change_id":15557284448}}}
{"jsonrpc":"2.0","method":"subscription","params":{"channel":"book.ETH-PERPETUAL.raw","data":{"timestamp":1734114588671,"type":"change","change_id":15557284450,"instrument_name":"ETH-PERPETUAL","bids":[],"asks":[["new",3896.65,8.0e4]],"prev_change_id":15557284449}}}
{"jsonrpc":"2.0","method":"subscription","params":{"channel":"book.ETH-PERPETUAL.raw","data":{"timestamp":1734114588671,"type":"change","change_id":15557284450,"instrument_name":"ETH-PERPETUAL","bids":[],"asks":[["new",3896.65,8.0e4]],"prev_change_id":15557284449}}}
{"jsonrpc":"2.0","method":"subscription","params":{"channel":"book.ETH-PERPETUAL.raw","data":{"timestamp":1734114588672,"type":"change","change_id":15557284451,"instrument_name":"ETH-PERPETUAL","bids":[["new",3881.65,8.0e4]],"asks":[],"prev_change_id":15557284450}}}
{"jsonrpc":"2.0","method":"subscription","params":{"channel":"book.ETH-PERPETUAL.raw","data":{"timestamp":1734114588672,"type":"change","change_id":15557284451,"instrument_name":"ETH-PERPETUAL","bids":[["new",3881.65,8.0e4]],"asks":[],"prev_change_id":15557284450}}}
{"jsonrpc":"2.0","method":"subscription","params":{"channel":"book.ETH-PERPETUAL.raw","data":{"timestamp":1734114588673,"type":"change","change_id":15557284452,"instrument_name":"ETH-PERPETUAL","bids":[],"asks":[["change",3896.65,1.0e5]],"prev_change_id":15557284451}}}
{"jsonrpc":"2.0","method":"subscription","params":{"channel":"book.ETH-PERPETUAL.raw","data":{"timestamp":1734114588673,"type":"change","change_id":15557284452,"instrument_name":"ETH-PERPETUAL","bids":[],"asks":[["change",3896.65,1.0e5]],"prev_change_id":15557284451}}}
{"jsonrpc":"2.0","method":"subscription","params":{"channel":"book.ETH-PERPETUAL.raw","data":{"timestamp":1734114588674,"type":"change","change_id":15557284453,"instrument_name":"ETH-PERPETUAL","bids":[],"asks":[["change",3896.65,1.8e5]],"prev_change_id":15557284452}}}
{"jsonrpc":"2.0","method":"subscription","params":{"channel":"book.ETH-PERPETUAL.raw","data":{"timestamp":1734114588674,"type":"change","change_id":15557284453,"instrument_name":"ETH-PERPETUAL","bids":[],"asks":[["change",3896.65,1.8e5]],"prev_change_id":15557284452}}}
{"jsonrpc":"2.0","method":"subscription","params":{"channel":"book.ETH-PERPETUAL.raw","data":{"timestamp":1734114588675,"type":"change","change_id":15557284454,"instrument_name":"ETH-PERPETUAL","bids":[["change",3881.65,1.6e5]],"asks":[],"prev_change_id":15557284453}}}
{"jsonrpc":"2.0","method":"subscription","params":{"channel":"book.ETH-PERPETUAL.raw","data":{"timestamp":1734114588675,"type":"change","change_id":15557284454,"instrument_name":"ETH-PERPETUAL","bids":[["change",3881.65,1.6e5]],"asks":[],"prev_change_id":15557284453}}}
{"jsonrpc":"2.0","method":"subscription","params":{"channel":"book.ETH-PERPETUAL.raw","data":{"timestamp":1734114588676,"type":"change","change_id":15557284455,"instrument_name":"ETH-PERPETUAL","bids":[],"asks":[["change",3896.65,2.0e5]],"prev_change_id":15557284454}}}
{"jsonrpc":"2.0","method":"subscription","params":{"channel":"book.ETH-PERPETUAL.raw","data":{"timestamp":1734114588676,"type":"change","change_id":15557284455,"instrument_name":"ETH-PERPETUAL","bids":[],"asks":[["change",3896.65,2.0e5]],"prev_change_id":15557284454}}}
{"jsonrpc":"2.0","method":"subscription","params":{"channel":"book.ETH-PERPETUAL.raw","data":{"timestamp":1734114588812,"type":"change","change_id":15557284456,"instrument_name":"ETH-PERPETUAL","bids":[["delete",3881.65,0.0]],"asks":[["delete",3896.65,0.0]],"prev_change_id":15557284455}}}
{"jsonrpc":"2.0","method":"subscription","params":{"channel":"book.ETH-PERPETUAL.raw","data":{"timestamp":1734114588812,"type":"change","change_id":15557284456,"instrument_name":"ETH-PERPETUAL","bids":[["delete",3881.65,0.0]],"asks":[["delete",3896.65,0.0]],"prev_change_id":15557284455}}}
{"jsonrpc":"2.0","method":"subscription","params":{"channel":"book.ETH-PERPETUAL.raw","data":{"timestamp":1734114588960,"type":"change","change_id":15557284478,"instrument_name":"ETH-PERPETUAL","bids":[],"asks":[["delete",3908.1,0.0],["new",3919.85,500.0]],"prev_change_id":15557284456}}}
{"jsonrpc":"2.0","method":"subscription","params":{"channel":"book.ETH-PERPETUAL.raw","data":{"timestamp":1734114588960,"type":"change","change_id":15557284478,"instrument_name":"ETH-PERPETUAL","bids":[],"asks":[["delete",3908.1,0.0],["new",3919.85,500.0]],"prev_change_id":15557284456}}}
{"jsonrpc":"2.0","method":"subscription","params":{"channel":"book.ETH-PERPETUAL.raw","data":{"timestamp":1734114588974,"type":"change","change_id":15557284489,"instrument_name":"ETH-PERPETUAL","bids":[["delete",1942.0,0.0]],"asks":[],"prev_change_id":15557284478}}}
{"jsonrpc":"2.0","method":"subscription","params":{"channel":"book.ETH-PERPETUAL.raw","data":{"timestamp":1734114588974,"type":"change","change_id":15557284489,"instrument_name":"ETH-PERPETUAL","bids":[["delete",1942.0,0.0]],"asks":[],"prev_change_id":15557284478}}}
{"jsonrpc":"2.0","method":"subscription","params":{"channel":"book.ETH-PERPETUAL.raw","data":{"timestamp":1734114589026,"type":"change","change_id":15557284493,"instrument_name":"ETH-PERPETUAL","bids":[],"asks":[["new",3896.65,8.0e4]],"prev_change_id":15557284489}}}
{"jsonrpc":"2.0","method":"subscription","params":{"channel":"book.ETH-PERPETUAL.raw","data":{"timestamp":1734114589026,"type":"change","change_id":15557284493,"instrument_name":"ETH-PERPETUAL","bids":[],"asks":[["new",3896.65,8.0e4]],"prev_change_id":15557284489}}}
{"jsonrpc":"2.0","method":"subscription","params":{"channel":"book.ETH-PERPETUAL.raw","data":{"timestamp":1734114589027,"type":"change","change_id":15557284494,"instrument_name":"ETH-PERPETUAL","bids":[["new",3881.65,8.0e4]],"asks":[],"prev_change_id":15557284493}}}
{"jsonrpc":"2.0","method":"subscription","params":{"channel":"book.ETH-PERPETUAL.raw","data":{"timestamp":1734114589027,"type":"change","change_id":15557284494,"instrument_name":"ETH-PERPETUAL","bids":[["new",3881.65,8.0e4]],"asks":[],"prev_change_id":15557284493}}}
{"jsonrpc":"2.0","method":"subscription","params":{"channel":"book.ETH-PERPETUAL.raw","data":{"timestamp":1734114589028,"type":"change","change_id":15557284495,"instrument_name":"ETH-PERPETUAL","bids":[],"asks":[["change",3896.65,1.0e5]],"prev_change_id":15557284494}}}
{"jsonrpc":"2.0","method":"subscription","params":{"channel":"book.ETH-PERPETUAL.raw","data":{"timestamp":1734114589028,"type":"change","change_id":15557284495,"instrument_name":"ETH-PERPETUAL","bids":[],"asks":[["change",3896.65,1.0e5]],"prev_change_id":15557284494}}}
{"jsonrpc":"2.0","method":"subscription","params":{"channel":"book.ETH-PERPETUAL.raw","data":{"timestamp":1734114589029,"type":"change","change_id":15557284496,"instrument_name":"ETH-PERPETUAL","bids":[],"asks":[["change",3896.65,1.8e5]],"prev_change_id":15557284495}}}
{"jsonrpc":"2.0","method":"subscription","params":{"channel":"book.ETH-PERPETUAL.raw","data":{"timestamp":1734114589029,"type":"change","change_id":15557284496,"instrument_name":"ETH-PERPETUAL","bids":[],"asks":[["change",3896.65,1.8e5]],"prev_change_id":15557284495}}}
{"jsonrpc":"2.0","method":"subscription","params":{"channel":"book.ETH-PERPETUAL.raw","data":{"timestamp":1734114589030,"type":"change","change_id":15557284497,"instrument_name":"ETH-PERPETUAL","bids":[["change",3881.65,1.6e5]],"asks":[],"prev_change_id":15557284496}}}
{"jsonrpc":"2.0","method":"subscription","params":{"channel":"book.ETH-PERPETUAL.raw","data":{"timestamp":1734114589030,"type":"change","change_id":15557284497,"instrument_name":"ETH-PERPETUAL","bids":[["change",3881.65,1.6e5]],"asks":[],"prev_change_id":15557284496}}}
{"jsonrpc":"2.0","method":"subscription","params":{"channel":"book.ETH-PERPETUAL.raw","data":{"timestamp":1734114589031,"type":"change","change_id":15557284498,"instrument_name":"ETH-PERPETUAL","bids":[],"asks":[["change",3896.65,2.0e5]],"prev_change_id":15557284497}}}
{"jsonrpc":"2.0","method":"subscription","params":{"channel":"book.ETH-PERPETUAL.raw","data":{"timestamp":1734114589031,"type":"change","change_id":15557284498,"instrument_name":"ETH-PERPETUAL","bids":[],"asks":[["change",3896.65,2.0e5]],"prev_change_id":15557284497}}}
{"jsonrpc":"2.0","method":"subscription","params":{"channel":"book.ETH-PERPETUAL.raw","data":{"timestamp":1734114589032,"type":"change","change_id":15557284499,"instrument_name":"ETH-PERPETUAL","bids":[["change",3881.65,1.8e5]],"asks":[],"prev_change_id":15557284498}}}
{"jsonrpc":"2.0","method":"subscription","params":{"channel":"book.ETH-PERPETUAL.raw","data":{"timestamp":1734114589032,"type":"change","change_id":15557284499,"instrument_name":"ETH-PERPETUAL","bids":[["change",3881.65,1.8e5]],"asks":[],"prev_change_id":15557284498}}}
{"jsonrpc":"2.0","method":"subscription","params":{"channel":"book.ETH-PERPETUAL.raw","data":{"timestamp":1734114589212,"type":"change","change_id":15557284519,"instrument_name":"ETH-PERPETUAL","bids":[["delete",3881.65,0.0]],"asks":[["delete",3896.65,0.0]],"prev_change_id":15557284499}}}
{"jsonrpc":"2.0","method":"subscription","params":{"channel":"book.ETH-PERPETUAL.raw","data":{"timestamp":1734114589212,"type":"change","change_id":15557284519,"instrument_name":"ETH-PERPETUAL","bids":[["delete",3881.65,0.0]],"asks":[["delete",3896.65,0.0]],"prev_change_id":15557284499}}}
{"jsonrpc":"2.0","method":"subscription","params":{"channel":"book.ETH-PERPETUAL.raw","data":{"timestamp":1734114589387,"type":"change","change_id":15557284521,"instrument_name":"ETH-PERPETUAL","bids":[],"asks":[["new",3896.65,8.0e4]],"prev_change_id":15557284519}}}
{"jsonrpc":"2.0","method":"subscription","params":{"channel":"book.ETH-PERPETUAL.raw","data":{"timestamp":1734114589387,"type":"change","change_id":15557284521,"instrument_name":"ETH-PERPETUAL","bids":[],"asks":[["new",3896.65,8.0e4]],"prev_change_id":15557284519}}}
{"jsonrpc":"2.0","method":"subscription","params":{"channel":"book.ETH-PERPETUAL.raw","data":{"timestamp":1734114589388,"type":"change","change_id":15557284522,"instrument_name":"ETH-PERPETUAL","bids":[["new",3881.65,8.0e4]],"asks":[],"prev_change_id":15557284521}}}
{"jsonrpc":"2.0","method":"subscription","params":{"channel":"book.ETH-PERPETUAL.raw","data":{"timestamp":1734114589388,"type":"change","change_id":15557284522,"instrument_name":"ETH-PERPETUAL","bids":[["new",3881.65,8.0e4]],"asks":[],"prev_change_id":15557284521}}}
{"jsonrpc":"2.0","method":"subscription","params":{"channel":"book.ETH-PERPETUAL.raw","data":{"timestamp":1734114589390,"type":"change","change_id":15557284523,"instrument_name":"ETH-PERPETUAL","bids":[],"asks":[["change",3896.65,1.0e5]],"prev_change_id":15557284522}}}
{"jsonrpc":"2.0","method":"subscription","params":{"channel":"book.ETH-PERPETUAL.raw","data":{"timestamp":1734114589390,"type":"change","change_id":15557284523,"instrument_name":"ETH-PERPETUAL","bids":[],"asks":[["change",3896.65,1.0e5]],"prev_change_id":15557284522}}}
{"jsonrpc":"2.0","method":"subscription","params":{"channel":"book.ETH-PERPETUAL.raw","data":{"timestamp":1734114589392,"type":"change","change_id":15557284524,"instrument_name":"ETH-PERPETUAL","bids":[["change",3881.65,1.0e5]],"asks":[],"prev_change_id":15557284523}}}
{"jsonrpc":"2.0","method":"subscription","params":{"channel":"book.ETH-PERPETUAL.raw","data":{"timestamp":1734114589392,"type":"change","change_id":15557284524,"instrument_name":"ETH-PERPETUAL","bids":[["change",3881.65,1.0e5]],"asks":[],"prev_change_id":15557284523}}}
{"jsonrpc":"2.0","method":"subscription","params":{"channel":"book.ETH-PERPETUAL.raw","data":{"timestamp":1734114589393,"type":"change","change_id":15557284525,"instrument_name":"ETH-PERPETUAL","bids":[],"asks":[["change",3896.65,1.8e5]],"prev_change_id":15557284524}}}
{"jsonrpc":"2.0","method":"subscription","params":{"channel":"book.ETH-PERPETUAL.raw","data":{"timestamp":1734114589393,"type":"change","change_id":15557284525,"instrument_name":"ETH-PERPETUAL","bids":[],"asks":[["change",3896.65,1.8e5]],"prev_change_id":15557284524}}}
{"jsonrpc":"2.0","method":"subscription","params":{"channel":"book.ETH-PERPETUAL.raw","data":{"timestamp":1734114589394,"type":"change","change_id":15557284526,"instrument_name":"ETH-PERPETUAL","bids":[["change",3881.65,1.8e5]],"asks":[],"prev_change_id":15557284525}}}
{"jsonrpc":"2.0","method":"subscription","params":{"channel":"book.ETH-PERPETUAL.raw","data":{"timestamp":1734114589394,"type":"change","change_id":15557284526,"instrument_name":"ETH-PERPETUAL","bids":[["change",3881.65,1.8e5]],"asks":[],"prev_change_id":15557284525}}}
{"jsonrpc":"2.0","method":"subscription","params":{"channel":"book.ETH-PERPETUAL.raw","data":{"timestamp":1734114589396,"type":"change","change_id":15557284527,"instrument_name":"ETH-PERPETUAL","bids":[],"asks":[["change",3896.65,2.0e5]],"prev_change_id":15557284526}}}
{"jsonrpc":"2.0","method":"subscription","params":{"channel":"book.ETH-PERPETUAL.raw","data":{"timestamp":1734114589396,"type":"change","change_id":15557284527,"instrument_name":"ETH-PERPETUAL","bids":[],"asks":[["change",3896.65,2.0e5]],"prev_change_id":15557284526}}}
{"jsonrpc":"2.0","method":"subscription","params":{"channel":"book.ETH-PERPETUAL.raw","data":{"timestamp":1734114589397,"type":"change","change_id":15557284528,"instrument_name":"ETH-PERPETUAL","bids":[["change",3881.65,2.0e5]],"asks":[],"prev_change_id":15557284527}}}
{"jsonrpc":"2.0","method":"subscription","params":{"channel":"book.ETH-PERPETUAL.raw","data":{"timestamp":1734114589397,"type":"change","change_id":15557284528,"instrument_name":"ETH-PERPETUAL","bids":[["change",3881.65,2.0e5]],"asks":[],"prev_change_id":15557284527}}}
{"jsonrpc":"2.0","method":"subscription","params":{"channel":"book.ETH-PERPETUAL.raw","data":{"timestamp":1734114589531,"type":"change","change_id":15557284529,"instrument_name":"ETH-PERPETUAL","bids":[],"asks":[["new",3916.15,500.0],["delete",3927.65,0.0]],"prev_change_id":15557284528}}}
{"jsonrpc":"2.0","method":"subscription","params":{"channel":"book.ETH-PERPETUAL.raw","data":{"timestamp":1734114589531,"type":"change","change_id":15557284529,"instrument_name":"ETH-PERPETUAL","bids":[],"asks":[["new",3916.15,500.0],["delete",3927.65,0.0]],"prev_change_id":15557284528}}}
{"jsonrpc":"2.0","method":"subscription","params":{"channel":"book.ETH-PERPETUAL.raw","data":{"timestamp":1734114589588,"type":"change","change_id":15557284530,"instrument_name":"ETH-PERPETUAL","bids":[["delete",3881.65,0.0]],"asks":[["delete",3896.65,0.0]],"prev_change_id":15557284529}}}
{"jsonrpc":"2.0","method":"subscription","params":{"channel":"book.ETH-PERPETUAL.raw","data":{"timestamp":1734114589588,"type":"change","change_id":15557284530,"instrument_name":"ETH-PERPETUAL","bids":[["delete",3881.65,0.0]],"asks":[["delete",3896.65,0.0]],"prev_change_id":15557284529}}}
{"jsonrpc":"2.0","method":"subscription","params":{"channel":"book.ETH-PERPETUAL.raw","data":{"timestamp":1734114589779,"type":"change","change_id":15557284535,"instrument_name":"ETH-PERPETUAL","bids":[],"asks":[["new",3896.65,8.0e4]],"prev_change_id":15557284530}}}
{"jsonrpc":"2.0","method":"subscription","params":{"channel":"book.ETH-PERPETUAL.raw","data":{"timestamp":1734114589779,"type":"change","change_id":15557284535,"instrument_name":"ETH-PERPETUAL","bids":[],"asks":[["new",3896.65,8.0e4]],"prev_change_id":15557284530}}}
{"jsonrpc":"2.0","method":"subscription","params":{"channel":"book.ETH-PERPETUAL.raw","data":{"timestamp":1734114589781,"type":"change","change_id":15557284536,"instrument_name":"ETH-PERPETUAL","bids":[["new",3881.65,8.0e4]],"asks":[],"prev_change_id":15557284535}}}
{"jsonrpc":"2.0","method":"subscription","params":{"channel":"book.ETH-PERPETUAL.raw","data":{"timestamp":1734114589781,"type":"change","change_id":15557284536,"instrument_name":"ETH-PERPETUAL","bids":[["new",3881.65,8.0e4]],"asks":[],"prev_change_id":15557284535}}}
{"jsonrpc":"2.0","method":"subscription","params":{"channel":"book.ETH-PERPETUAL.raw","data":{"timestamp":1734114589782,"type":"change","change_id":15557284537,"instrument_name":"ETH-PERPETUAL","bids":[],"asks":[["change",3896.65,1.0e5]],"prev_change_id":15557284536}}}
{"jsonrpc":"2.0","method":"subscription","params":{"channel":"book.ETH-PERPETUAL.raw","data":{"timestamp":1734114589782,"type":"change","change_id":15557284537,"instrument_name":"ETH-PERPETUAL","bids":[],"asks":[["change",3896.65,1.0e5]],"prev_change_id":15557284536}}}
{"jsonrpc":"2.0","method":"subscription","params":{"channel":"book.ETH-PERPETUAL.raw","data":{"timestamp":1734114589784,"type":"change","change_id":15557284538,"instrument_name":"ETH-PERPETUAL","bids":[],"asks":[["change",3896.65,1.8e5]],"prev_change_id":15557284537}}}
{"jsonrpc":"2.0","method":"subscription","params":{"channel":"book.ETH-PERPETUAL.raw","data":{"timestamp":1734114589784,"type":"change","change_id":15557284538,"instrument_name":"ETH-PERPETUAL","bids":[],"asks":[["change",3896.65,1.8e5]],"prev_change_id":15557284537}}}
{"jsonrpc":"2.0","method":"subscription","params":{"channel":"book.ETH-PERPETUAL.raw","data":{"timestamp":1734114589785,"type":"change","change_id":15557284539,"instrument_name":"ETH-PERPETUAL","bids":[["change",3881.65,1.6e5]],"asks":[],"prev_change_id":15557284538}}}
{"jsonrpc":"2.0","method":"subscription","params":{"channel":"book.ETH-PERPETUAL.raw","data":{"timestamp":1734114589785,"type":"change","change_id":15557284539,"instrument_name":"ETH-PERPETUAL","bids":[["change",3881.65,1.6e5]],"asks":[],"prev_change_id":15557284538}}}
{"jsonrpc":"2.0","method":"subscription","params":{"channel":"book.ETH-PERPETUAL.raw","data":{"timestamp":1734114589787,"type":"change","change_id":15557284540,"instrument_name":"ETH-PERPETUAL","bids":[],"asks":[["change",3896.65,2.0e5]],"prev_change_id":15557284539}}}
{"jsonrpc":"2.0","method":"subscription","params":{"channel":"book.ETH-PERPETUAL.raw","data":{"timestamp":1734114589787,"type":"change","change_id":15557284540,"instrument_name":"ETH-PERPETUAL","bids":[],"asks":[["change",3896.65,2.0e5]],"prev_change_id":15557284539}}}
{"jsonrpc":"2.0","method":"subscription","params":{"channel":"book.ETH-PERPETUAL.raw","data":{"timestamp":1734114589912,"type":"change","change_id":15557284542,"instrument_name":"ETH-PERPETUAL","bids":[["delete",3881.65,0.0]],"asks":[["delete",3896.65,0.0]],"prev_change_id":15557284540}}}
{"jsonrpc":"2.0","method":"subscription","params":{"channel":"book.ETH-PERPETUAL.raw","data":{"timestamp":1734114589912,"type":"change","change_id":15557284542,"instrument_name":"ETH-PERPETUAL","bids":[["delete",3881.65,0.0]],"asks":[["delete",3896.65,0.0]],"prev_change_id":15557284540}}}
{"jsonrpc":"2.0","method":"subscription","params":{"channel":"book.ETH-PERPETUAL.raw","data":{"timestamp":1734114590112,"type":"change","change_id":15557284549,"instrument_name":"ETH-PERPETUAL","bids":[],"asks":[["new",3896.6,8.0e4]],"prev_change_id":15557284542}}}
{"jsonrpc":"2.0","method":"subscription","params":{"channel":"book.ETH-PERPETUAL.raw","data":{"timestamp":1734114590112,"type":"change","change_id":15557284549,"instrument_name":"ETH-PERPETUAL","bids":[],"asks":[["new",3896.6,8.0e4]],"prev_change_id":15557284542}}}
{"jsonrpc":"2.0","method":"subscription","params":{"channel":"book.ETH-PERPETUAL.raw","data":{"timestamp":1734114590114,"type":"change","change_id":15557284550,"instrument_name":"ETH-PERPETUAL","bids":[["new",3881.6,8.0e4]],"asks":[],"prev_change_id":15557284549}}}
{"jsonrpc":"2.0","method":"subscription","params":{"channel":"book.ETH-PERPETUAL.raw","data":{"timestamp":1734114590114,"type":"change","change_id":15557284550,"instrument_name":"ETH-PERPETUAL","bids":[["new",3881.6,8.0e4]],"asks":[],"prev_change_id":15557284549}}}
{"jsonrpc":"2.0","method":"subscription","params":{"channel":"book.ETH-PERPETUAL.raw","data":{"timestamp":1734114590123,"type":"change","change_id":15557284551,"instrument_name":"ETH-PERPETUAL","bids":[],"asks":[["change",3896.6,1.0e5]],"prev_change_id":15557284550}}}
{"jsonrpc":"2.0","method":"subscription","params":{"channel":"book.ETH-PERPETUAL.raw","data":{"timestamp":1734114590123,"type":"change","change_id":15557284551,"instrument_name":"ETH-PERPETUAL","bids":[],"asks":[["change",3896.6,1.0e5]],"prev_change_id":15557284550}}}
{"jsonrpc":"2.0","method":"subscription","params":{"channel":"book.ETH-PERPETUAL.raw","data":{"timestamp":1734114590128,"type":"change","change_id":15557284552,"instrument_name":"ETH-PERPETUAL","bids":[],"asks":[["change",3896.6,1.8e5]],"prev_change_id":15557284551}}}
{"jsonrpc":"2.0","method":"subscription","params":{"channel":"book.ETH-PERPETUAL.raw","data":{"timestamp":1734114590128,"type":"change","change_id":15557284552,"instrument_name":"ETH-PERPETUAL","bids":[],"asks":[["change",3896.6,1.8e5]],"prev_change_id":15557284551}}}
{"jsonrpc":"2.0","method":"subscription","params":{"channel":"book.ETH-PERPETUAL.raw","data":{"timestamp":1734114590129,"type":"change","change_id":15557284554,"instrument_name":"ETH-PERPETUAL","bids":[["change",3881.6,1.6e5]],"asks":[],"prev_change_id":15557284552}}}
{"jsonrpc":"2.0","method":"subscription","params":{"channel":"book.ETH-PERPETUAL.raw","data":{"timestamp":1734114590129,"type":"change","change_id":15557284554,"instrument_name":"ETH-PERPETUAL","bids":[["change",3881.6,1.6e5]],"asks":[],"prev_change_id":15557284552}}}
{"jsonrpc":"2.0","method":"subscription","params":{"channel":"book.ETH-PERPETUAL.raw","data":{"timestamp":1734114590130,"type":"change","change_id":15557284555,"instrument_name":"ETH-PERPETUAL","bids":[],"asks":[["change",3896.6,2.0e5]],"prev_change_id":15557284554}}}
{"jsonrpc":"2.0","method":"subscription","params":{"channel":"book.ETH-PERPETUAL.raw","data":{"timestamp":1734114590130,"type":"change","change_id":15557284555,"instrument_name":"ETH-PERPETUAL","bids":[],"asks":[["change",3896.6,2.0e5]],"prev_change_id":15557284554}}}
{"jsonrpc":"2.0","method":"subscription","params":{"channel":"book.ETH-PERPETUAL.raw","data":{"timestamp":1734114590252,"type":"change","change_id":15557284556,"instrument_name":"ETH-PERPETUAL","bids":[["delete",3881.6,0.0]],"asks":[["delete",3896.6,0.0]],"prev_change_id":15557284555}}}
{"jsonrpc":"2.0","method":"subscription","params":{"channel":"book.ETH-PERPETUAL.raw","data":{"timestamp":1734114590252,"type":"change","change_id":15557284556,"instrument_name":"ETH-PERPETUAL","bids":[["delete",3881.6,0.0]],"asks":[["delete",3896.6,0.0]],"prev_change_id":15557284555}}}
{"jsonrpc":"2.0","method":"subscription","params":{"channel":"book.ETH-PERPETUAL.raw","data":{"timestamp":1734114590448,"type":"change","change_id":15557284560,"instrument_name":"ETH-PERPETUAL","bids":[],"asks":[["new",3896.6,8.0e4]],"prev_change_id":15557284556}}}
{"jsonrpc":"2.0","method":"subscription","params":{"channel":"book.ETH-PERPETUAL.raw","data":{"timestamp":1734114590448,"type":"change","change_id":15557284560,"instrument_name":"ETH-PERPETUAL","bids":[],"asks":[["new",3896.6,8.0e4]],"prev_change_id":15557284556}}}
{"jsonrpc":"2.0","method":"subscription","params":{"channel":"book.ETH-PERPETUAL.raw","data":{"timestamp":1734114590449,"type":"change","change_id":15557284561,"instrument_name":"ETH-PERPETUAL","bids":[["new",3881.6,8.0e4]],"asks":[],"prev_change_id":15557284560}}}
{"jsonrpc":"2.0","method":"subscription","params":{"channel":"book.ETH-PERPETUAL.raw","data":{"timestamp":1734114590449,"type":"change","change_id":15557284561,"instrument_name":"ETH-PERPETUAL","bids":[["new",3881.6,8.0e4]],"asks":[],"prev_change_id":15557284560}}}
{"jsonrpc":"2.0","method":"subscription","params":{"channel":"book.ETH-PERPETUAL.raw","data":{"timestamp":1734114590450,"type":"change","change_id":15557284562,"instrument_name":"ETH-PERPETUAL","bids":[],"asks":[["change",3896.6,1.0e5]],"prev_change_id":15557284561}}}
{"jsonrpc":"2.0","method":"subscription","params":{"channel":"book.ETH-PERPETUAL.raw","data":{"timestamp":1734114590450,"type":"change","change_id":15557284562,"instrument_name":"ETH-PERPETUAL","bids":[],"asks":[["change",3896.6,1.0e5]],"prev_change_id":15557284561}}}
{"jsonrpc":"2.0","method":"subscription","params":{"channel":"book.ETH-PERPETUAL.raw","data":{"timestamp":1734114590452,"type":"change","change_id":15557284563,"instrument_name":"ETH-PERPETUAL","bids":[],"asks":[["change",3896.6,1.8e5]],"prev_change_id":15557284562}}}
{"jsonrpc":"2.0","method":"subscription","params":{"channel":"book.ETH-PERPETUAL.raw","data":{"timestamp":1734114590452,"type":"change","change_id":15557284563,"instrument_name":"ETH-PERPETUAL","bids":[],"asks":[["change",3896.6,1.8e5]],"prev_change_id":15557284562}}}
{"jsonrpc":"2.0","method":"subscription","params":{"channel":"book.ETH-PERPETUAL.raw","data":{"timestamp":1734114590453,"type":"change","change_id":15557284564,"instrument_name":"ETH-PERPETUAL","bids":[["change",3881.6,1.6e5]],"asks":[],"prev_change_id":15557284563}}}
{"jsonrpc":"2.0","method":"subscription","params":{"channel":"book.ETH-PERPETUAL.raw","data":{"timestamp":1734114590453,"type":"change","change_id":15557284564,"instrument_name":"ETH-PERPETUAL","bids":[["change",3881.6,1.6e5]],"asks":[],"prev_change_id":15557284563}}}
{"jsonrpc":"2.0","method":"subscription","params":{"channel":"book.ETH-PERPETUAL.raw","data":{"timestamp":1734114590455,"type":"change","change_id":15557284565,"instrument_name":"ETH-PERPETUAL","bids":[],"asks":[["change",3896.6,2.0e5]],"prev_change_id":15557284564}}}
{"jsonrpc":"2.0","method":"subscription","params":{"channel":"book.ETH-PERPETUAL.raw","data":{"timestamp":1734114590455,"type":"change","change_id":15557284565,"instrument_name":"ETH-PERPETUAL","bids":[],"asks":[["change",3896.6,2.0e5]],"prev_change_id":15557284564}}}
{"jsonrpc":"2.0","method":"subscription","params":{"channel":"book.ETH-PERPETUAL.raw","data":{"timestamp":1734114590534,"type":"change","change_id":15557284586,"instrument_name":"ETH-PERPETUAL","bids":[["delete",3881.6,0.0]],"asks":[["delete",3896.6,0.0]],"prev_change_id":15557284565}}}
{"jsonrpc":"2.0","method":"subscription","params":{"channel":"book.ETH-PERPETUAL.raw","data":{"timestamp":1734114590534,"type":"change","change_id":15557284586,"instrument_name":"ETH-PERPETUAL","bids":[["delete",3881.6,0.0]],"asks":[["delete",3896.6,0.0]],"prev_change_id":15557284565}}}
{"jsonrpc":"2.0","method":"subscription","params":{"channel":"book.ETH-PERPETUAL.raw","data":{"timestamp":1734114590712,"type":"change","change_id":15557284589,"instrument_name":"ETH-PERPETUAL","bids":[],"asks":[["new",3896.6,8.0e4]],"prev_change_id":15557284586}}}
{"jsonrpc":"2.0","method":"subscription","params":{"channel":"book.ETH-PERPETUAL.raw","data":{"timestamp":1734114590712,"type":"change","change_id":15557284589,"instrument_name":"ETH-PERPETUAL","bids":[],"asks":[["new",3896.6,8.0e4]],"prev_change_id":15557284586}}}
{"jsonrpc":"2.0","method":"subscription","params":{"channel":"book.ETH-PERPETUAL.raw","data":{"timestamp":1734114590714,"type":"change","change_id":15557284590,"instrument_name":"ETH-PERPETUAL","bids":[["new",3881.6,8.0e4]],"asks":[],"prev_change_id":15557284589}}}
{"jsonrpc":"2.0","method":"subscription","params":{"channel":"book.ETH-PERPETUAL.raw","data":{"timestamp":1734114590714,"type":"change","change_id":15557284590,"instrument_name":"ETH-PERPETUAL","bids":[["new",3881.6,8.0e4]],"asks":[],"prev_change_id":15557284589}}}
{"jsonrpc":"2.0","method":"subscription","params":{"channel":"book.ETH-PERPETUAL.raw","data":{"timestamp":1734114590715,"type":"change","change_id":15557284591,"instrument_name":"ETH-PERPETUAL","bids":[],"asks":[["change",3896.6,1.0e5]],"prev_change_id":15557284590}}}
{"jsonrpc":"2.0","method":"subscription","params":{"channel":"book.ETH-PERPETUAL.raw","data":{"timestamp":1734114590715,"type":"change","change_id":15557284591,"instrument_name":"ETH-PERPETUAL","bids":[],"asks":[["change",3896.6,1.0e5]],"prev_change_id":15557284590}}}
{"jsonrpc":"2.0","method":"subscription","params":{"channel":"book.ETH-PERPETUAL.raw","data":{"timestamp":1734114590716,"type":"change","change_id":15557284592,"instrument_name":"ETH-PERPETUAL","bids":[],"asks":[["change",3896.6,1.8e5]],"prev_change_id":15557284591}}}
{"jsonrpc":"2.0","method":"subscription","params":{"channel":"book.ETH-PERPETUAL.raw","data":{"timestamp":1734114590716,"type":"change","change_id":15557284592,"instrument_name":"ETH-PERPETUAL","bids":[],"asks":[["change",3896.6,1.8e5]],"prev_change_id":15557284591}}}
{"jsonrpc":"2.0","method":"subscription","params":{"channel":"book.ETH-PERPETUAL.raw","data":{"timestamp":1734114590718,"type":"change","change_id":15557284593,"instrument_name":"ETH-PERPETUAL","bids":[["change",3881.6,1.6e5]],"asks":[],"prev_change_id":15557284592}}}
{"jsonrpc":"2.0","method":"subscription","params":{"channel":"book.ETH-PERPETUAL.raw","data":{"timestamp":1734114590718,"type":"change","change_id":15557284593,"instrument_name":"ETH-PERPETUAL","bids":[["change",3881.6,1.6e5]],"asks":[],"prev_change_id":15557284592}}}
{"jsonrpc":"2.0","method":"subscription","params":{"channel":"book.ETH-PERPETUAL.raw","data":{"timestamp":1734114590720,"type":"change","change_id":15557284594,"instrument_name":"ETH-PERPETUAL","bids":[],"asks":[["change",3896.6,2.0e5]],"prev_change_id":15557284593}}}
{"jsonrpc":"2.0","method":"subscription","params":{"channel":"book.ETH-PERPETUAL.raw","data":{"timestamp":1734114590720,"type":"change","change_id":15557284594,"instrument_name":"ETH-PERPETUAL","bids":[],"asks":[["change",3896.6,2.0e5]],"prev_change_id":15557284593}}}
{"jsonrpc":"2.0","method":"subscription","params":{"channel":"book.ETH-PERPETUAL.raw","data":{"timestamp":1734114590808,"type":"change","change_id":15557284595,"instrument_name":"ETH-PERPETUAL","bids":[["delete",3881.6,0.0]],"asks":[["delete",3896.6,0.0]],"prev_change_id":15557284594}}}
{"jsonrpc":"2.0","method":"subscription","params":{"channel":"book.ETH-PERPETUAL.raw","data":{"timestamp":1734114590808,"type":"change","change_id":15557284595,"instrument_name":"ETH-PERPETUAL","bids":[["delete",3881.6,0.0]],"asks":[["delete",3896.6,0.0]],"prev_change_id":15557284594}}}
{"jsonrpc":"2.0","method":"subscription","params":{"channel":"book.ETH-PERPETUAL.raw","data":{"timestamp":1734114590974,"type":"change","change_id":15557284610,"instrument_name":"ETH-PERPETUAL","bids":[["new",1942.0,1.0]],"asks":[],"prev_change_id":15557284595}}}
{"jsonrpc":"2.0","method":"subscription","params":{"channel":"book.ETH-PERPETUAL.raw","data":{"timestamp":1734114590974,"type":"change","change_id":15557284610,"instrument_name":"ETH-PERPETUAL","bids":[["new",1942.0,1.0]],"asks":[],"prev_change_id":15557284595}}}
{"jsonrpc":"2.0","method":"subscription","params":{"channel":"book.ETH-PERPETUAL.raw","data":{"timestamp":1734114591024,"type":"change","change_id":15557284611,"instrument_name":"ETH-PERPETUAL","bids":[],"asks":[["new",3896.6,8.0e4]],"prev_change_id":15557284610}}}
{"jsonrpc":"2.0","method":"subscription","params":{"channel":"book.ETH-PERPETUAL.raw","data":{"timestamp":1734114591024,"type":"change","change_id":15557284611,"instrument_name":"ETH-PERPETUAL","bids":[],"asks":[["new",3896.6,8.0e4]],"prev_change_id":15557284610}}}
{"jsonrpc":"2.0","method":"subscription","params":{"channel":"book.ETH-PERPETUAL.raw","data":{"timestamp":1734114591025,"type":"change","change_id":15557284612,"instrument_name":"ETH-PERPETUAL","bids":[["new",3881.6,8.0e4]],"asks":[],"prev_change_id":15557284611}}}
{"jsonrpc":"2.0","method":"subscription","params":{"channel":"book.ETH-PERPETUAL.raw","data":{"timestamp":1734114591025,"type":"change","change_id":15557284612,"instrument_name":"ETH-PERPETUAL","bids":[["new",3881.6,8.0e4]],"asks":[],"prev_change_id":15557284611}}}
{"jsonrpc":"2.0","method":"subscription","params":{"channel":"book.ETH-PERPETUAL.raw","data":{"timestamp":1734114591026,"type":"change","change_id":15557284613,"instrument_name":"ETH-PERPETUAL","bids":[],"asks":[["change",3896.6,1.0e5]],"prev_change_id":15557284612}}}
{"jsonrpc":"2.0","method":"subscription","params":{"channel":"book.ETH-PERPETUAL.raw","data":{"timestamp":1734114591026,"type":"change","change_id":15557284613,"instrument_name":"ETH-PERPETUAL","bids":[],"asks":[["change",3896.6,1.0e5]],"prev_change_id":15557284612}}}
{"jsonrpc":"2.0","method":"subscription","params":{"channel":"book.ETH-PERPETUAL.raw","data":{"timestamp":1734114591027,"type":"change","change_id":15557284614,"instrument_name":"ETH-PERPETUAL","bids":[],"asks":[["change",3896.6,1.8e5]],"prev_change_id":15557284613}}}
{"jsonrpc":"2.0","method":"subscription","params":{"channel":"book.ETH-PERPETUAL.raw","data":{"timestamp":1734114591027,"type":"change","change_id":15557284614,"instrument_name":"ETH-PERPETUAL","bids":[],"asks":[["change",3896.6,1.8e5]],"prev_change_id":15557284613}}}
{"jsonrpc":"2.0","method":"subscription","params":{"channel":"book.ETH-PERPETUAL.raw","data":{"timestamp":1734114591028,"type":"change","change_id":15557284615,"instrument_name":"ETH-PERPETUAL","bids":[["change",3881.6,1.6e5]],"asks":[],"prev_change_id":15557284614}}}
{"jsonrpc":"2.0","method":"subscription","params":{"channel":"book.ETH-PERPETUAL.raw","data":{"timestamp":1734114591028,"type":"change","change_id":15557284615,"instrument_name":"ETH-PERPETUAL","bids":[["change",3881.6,1.6e5]],"asks":[],"prev_change_id":15557284614}}}
{"jsonrpc":"2.0","method":"subscription","params":{"channel":"book.ETH-PERPETUAL.raw","data":{"timestamp":1734114591029,"type":"change","change_id":15557284616,"instrument_name":"ETH-PERPETUAL","bids":[],"asks":[["change",3896.6,2.0e5]],"prev_change_id":15557284615}}}
{"jsonrpc":"2.0","method":"subscription","params":{"channel":"book.ETH-PERPETUAL.raw","data":{"timestamp":1734114591029,"type":"change","change_id":15557284616,"instrument_name":"ETH-PERPETUAL","bids":[],"asks":[["change",3896.6,2.0e5]],"prev_change_id":15557284615}}}
{"jsonrpc":"2.0","method":"subscription","params":{"channel":"book.ETH-PERPETUAL.raw","data":{"timestamp":1734114591153,"type":"change","change_id":15557284619,"instrument_name":"ETH-PERPETUAL","bids":[["delete",3881.6,0.0]],"asks":[["delete",3896.6,0.0]],"prev_change_id":15557284616}}}
{"jsonrpc":"2.0","method":"subscription","params":{"channel":"book.ETH-PERPETUAL.raw","data":{"timestamp":1734114591153,"type":"change","change_id":15557284619,"instrument_name":"ETH-PERPETUAL","bids":[["delete",3881.6,0.0]],"asks":[["delete",3896.6,0.0]],"prev_change_id":15557284616}}}
{"jsonrpc":"2.0","method":"subscription","params":{"channel":"book.ETH-PERPETUAL.raw","data":{"timestamp":1734114591351,"type":"change","change_id":15557284621,"instrument_name":"ETH-PERPETUAL","bids":[["new",3881.25,8.0e4]],"asks":[],"prev_change_id":15557284619}}}
{"jsonrpc":"2.0","method":"subscription","params":{"channel":"book.ETH-PERPETUAL.raw","data":{"timestamp":1734114591351,"type":"change","change_id":15557284621,"instrument_name":"ETH-PERPETUAL","bids":[["new",3881.25,8.0e4]],"asks":[],"prev_change_id":15557284619}}}
{"jsonrpc":"2.0","method":"subscription","params":{"channel":"book.ETH-PERPETUAL.raw","data":{"timestamp":1734114591353,"type":"change","change_id":15557284622,"instrument_name":"ETH-PERPETUAL","bids":[],"asks":[["new",3896.25,8.0e4]],"prev_change_id":15557284621}}}
{"jsonrpc":"2.0","method":"subscription","params":{"channel":"book.ETH-PERPETUAL.raw","data":{"timestamp":1734114591353,"type":"change","change_id":15557284622,"instrument_name":"ETH-PERPETUAL","bids":[],"asks":[["new",3896.25,8.0e4]],"prev_change_id":15557284621}}}
{"jsonrpc":"2.0","method":"subscription","params":{"channel":"book.ETH-PERPETUAL.raw","data":{"timestamp":1734114591356,"type":"change","change_id":15557284623,"instrument_name":"ETH-PERPETUAL","bids":[],"asks":[["change",3896.25,1.0e5]],"prev_change_id":15557284622}}}
{"jsonrpc":"2.0","method":"subscription","params":{"channel":"book.ETH-PERPETUAL.raw","data":{"timestamp":1734114591356,"type":"change","change_id":15557284623,"instrument_name":"ETH-PERPETUAL","bids":[],"asks":[["change",3896.25,1.0e5]],"prev_change_id":15557284622}}}
{"jsonrpc":"2.0","method":"subscription","params":{"channel":"book.ETH-PERPETUAL.raw","data":{"timestamp":1734114591357,"type":"change","change_id":15557284624,"instrument_name":"ETH-PERPETUAL","bids":[["change",3881.25,1.6e5]],"asks":[],"prev_change_id":15557284623}}}
{"jsonrpc":"2.0","method":"subscription","params":{"channel":"book.ETH-PERPETUAL.raw","data":{"timestamp":1734114591357,"type":"change","change_id":15557284624,"instrument_name":"ETH-PERPETUAL","bids":[["change",3881.25,1.6e5]],"asks":[],"prev_change_id":15557284623}}}
{"jsonrpc":"2.0","method":"subscription","params":{"channel":"book.ETH-PERPETUAL.raw","data":{"timestamp":1734114591358,"type":"change","change_id":15557284625,"instrument_name":"ETH-PERPETUAL","bids":[],"asks":[["change",3896.25,1.8e5]],"prev_change_id":15557284624}}}
{"jsonrpc":"2.0","method":"subscription","params":{"channel":"book.ETH-PERPETUAL.raw","data":{"timestamp":1734114591358,"type":"change","change_id":15557284625,"instrument_name":"ETH-PERPETUAL","bids":[],"asks":[["change",3896.25,1.8e5]],"prev_change_id":15557284624}}}
{"jsonrpc":"2.0","method":"subscription","params":{"channel":"book.ETH-PERPETUAL.raw","data":{"timestamp":1734114591360,"type":"change","change_id":15557284626,"instrument_name":"ETH-PERPETUAL","bids":[],"asks":[["change",3896.25,2.0e5]],"prev_change_id":15557284625}}}
{"jsonrpc":"2.0","method":"subscription","params":{"channel":"book.ETH-PERPETUAL.raw","data":{"timestamp":1734114591360,"type":"change","change_id":15557284626,"instrument_name":"ETH-PERPETUAL","bids":[],"asks":[["change",3896.25,2.0e5]],"prev_change_id":15557284625}}}
{"jsonrpc":"2.0","method":"subscription","params":{"channel":"book.ETH-PERPETUAL.raw","data":{"timestamp":1734114591500,"type":"change","change_id":15557284638,"instrument_name":"ETH-PERPETUAL","bids":[["delete",3881.25,0.0]],"asks":[["delete",3896.25,0.0]],"prev_change_id":15557284626}}}
{"jsonrpc":"2.0","method":"subscription","params":{"channel":"book.ETH-PERPETUAL.raw","data":{"timestamp":1734114591500,"type":"change","change_id":15557284638,"instrument_name":"ETH-PERPETUAL","bids":[["delete",3881.25,0.0]],"asks":[["delete",3896.25,0.0]],"prev_change_id":15557284626}}}
{"jsonrpc":"2.0","method":"subscription","params":{"channel":"book.ETH-PERPETUAL.raw","data":{"timestamp":1734114591802,"type":"change","change_id":15557284639,"instrument_name":"ETH-PERPETUAL","bids":[],"asks":[["new",3896.25,8.0e4]],"prev_change_id":15557284638}}}
{"jsonrpc":"2.0","method":"subscription","params":{"channel":"book.ETH-PERPETUAL.raw","data":{"timestamp":1734114591802,"type":"change","change_id":15557284639,"instrument_name":"ETH-PERPETUAL","bids":[],"asks":[["new",3896.25,8.0e4]],"prev_change_id":15557284638}}}
{"jsonrpc":"2.0","method":"subscription","params":{"channel":"book.ETH-PERPETUAL.raw","data":{"timestamp":1734114591803,"type":"change","change_id":15557284640,"instrument_name":"ETH-PERPETUAL","bids":[["new",3881.25,8.0e4]],"asks":[],"prev_change_id":15557284639}}}
{"jsonrpc":"2.0","method":"subscription","params":{"channel":"book.ETH-PERPETUAL.raw","data":{"timestamp":1734114591803,"type":"change","change_id":15557284640,"instrument_name":"ETH-PERPETUAL","bids":[["new",3881.25,8.0e4]],"asks":[],"prev_change_id":15557284639}}}
{"jsonrpc":"2.0","method":"subscription","params":{"channel":"book.ETH-PERPETUAL.raw","data":{"timestamp":1734114591806,"type":"change","change_id":15557284641,"instrument_name":"ETH-PERPETUAL","bids":[],"asks":[["change",3896.25,1.0e5]],"prev_change_id":15557284640}}}
{"jsonrpc":"2.0","method":"subscription","params":{"channel":"book.ETH-PERPETUAL.raw","data":{"timestamp":1734114591806,"type":"change","change_id":15557284641,"instrument_name":"ETH-PERPETUAL","bids":[],"asks":[["change",3896.25,1.0e5]],"prev_change_id":15557284640}}}
{"jsonrpc":"2.0","method":"subscription","params":{"channel":"book.ETH-PERPETUAL.raw","data":{"timestamp":1734114591808,"type":"change","change_id":15557284642,"instrument_name":"ETH-PERPETUAL","bids":[["change",3881.25,1.0e5]],"asks":[],"prev_change_id":15557284641}}}
{"jsonrpc":"2.0","method":"subscription","params":{"channel":"book.ETH-PERPETUAL.raw","data":{"timestamp":1734114591808,"type":"change","change_id":15557284642,"instrument_name":"ETH-PERPETUAL","bids":[["change",3881.25,1.0e5]],"asks":[],"prev_change_id":15557284641}}}
{"jsonrpc":"2.0","method":"subscription","params":{"channel":"book.ETH-PERPETUAL.raw","data":{"timestamp":1734114591811,"type":"change","change_id":15557284643,"instrument_name":"ETH-PERPETUAL","bids":[],"asks":[["change",3896.25,1.8e5]],"prev_change_id":15557284642}}}
{"jsonrpc":"2.0","method":"subscription","params":{"channel":"book.ETH-PERPETUAL.raw","data":{"timestamp":1734114591811,"type":"change","change_id":15557284643,"instrument_name":"ETH-PERPETUAL","bids":[],"asks":[["change",3896.25,1.8e5]],"prev_change_id":15557284642}}}
{"jsonrpc":"2.0","method":"subscription","params":{"channel":"book.ETH-PERPETUAL.raw","data":{"timestamp":1734114591813,"type":"change","change_id":15557284644,"instrument_name":"ETH-PERPETUAL","bids":[["change",3881.25,1.8e5]],"asks":[],"prev_change_id":15557284643}}}
{"jsonrpc":"2.0","method":"subscription","params":{"channel":"book.ETH-PERPETUAL.raw","data":{"timestamp":1734114591813,"type":"change","change_id":15557284644,"instrument_name":"ETH-PERPETUAL","bids":[["change",3881.25,1.8e5]],"asks":[],"prev_change_id":15557284643}}}
{"jsonrpc":"2.0","method":"subscription","params":{"channel":"book.ETH-PERPETUAL.raw","data":{"timestamp":1734114591816,"type":"change","change_id":15557284645,"instrument_name":"ETH-PERPETUAL","bids":[],"asks":[["change",3896.25,2.0e5]],"prev_change_id":15557284644}}}
{"jsonrpc":"2.0","method":"subscription","params":{"channel":"book.ETH-PERPETUAL.raw","data":{"timestamp":1734114591816,"type":"change","change_id":15557284645,"instrument_name":"ETH-PERPETUAL","bids":[],"asks":[["change",3896.25,2.0e5]],"prev_change_id":15557284644}}}
{"jsonrpc":"2.0","method":"subscription","params":{"channel":"book.ETH-PERPETUAL.raw","data":{"timestamp":1734114591819,"type":"change","change_id":15557284646,"instrument_name":"ETH-PERPETUAL","bids":[["change",3881.25,2.0e5]],"asks":[],"prev_change_id":15557284645}}}
{"jsonrpc":"2.0","method":"subscription","params":{"channel":"book.ETH-PERPETUAL.raw","data":{"timestamp":1734114591819,"type":"change","change_id":15557284646,"instrument_name":"ETH-PERPETUAL","bids":[["change",3881.25,2.0e5]],"asks":[],"prev_change_id":15557284645}}}
{"jsonrpc":"2.0","method":"subscription","params":{"channel":"book.ETH-PERPETUAL.raw","data":{"timestamp":1734114591951,"type":"change","change_id":15557284656,"instrument_name":"ETH-PERPETUAL","bids":[],"asks":[["new",3935.25,700.0],["delete",3947.75,0.0]],"prev_change_id":15557284646}}}
{"jsonrpc":"2.0","method":"subscription","params":{"channel":"book.ETH-PERPETUAL.raw","data":{"timestamp":1734114591951,"type":"change","change_id":15557284656,"instrument_name":"ETH-PERPETUAL","bids":[],"asks":[["new",3935.25,700.0],["delete",3947.75,0.0]],"prev_change_id":15557284646}}}
{"jsonrpc":"2.0","method":"subscription","params":{"channel":"book.ETH-PERPETUAL.raw","data":{"timestamp":1734114592037,"type":"change","change_id":15557284687,"instrument_name":"ETH-PERPETUAL","bids":[["delete",3881.25,0.0]],"asks":[["delete",3896.25,0.0]],"prev_change_id":15557284656}}}
{"jsonrpc":"2.0","method":"subscription","params":{"channel":"book.ETH-PERPETUAL.raw","data":{"timestamp":1734114592037,"type":"change","change_id":15557284687,"instrument_name":"ETH-PERPETUAL","bids":[["delete",3881.25,0.0]],"asks":[["delete",3896.25,0.0]],"prev_change_id":15557284656}}}
{"jsonrpc":"2.0","method":"subscription","params":{"channel":"book.ETH-PERPETUAL.raw","data":{"timestamp":1734114592335,"type":"change","change_id":15557284691,"instrument_name":"ETH-PERPETUAL","bids":[],"asks":[["new",3896.25,8.0e4]],"prev_change_id":15557284687}}}
{"jsonrpc":"2.0","method":"subscription","params":{"channel":"book.ETH-PERPETUAL.raw","data":{"timestamp":1734114592335,"type":"change","change_id":15557284691,"instrument_name":"ETH-PERPETUAL","bids":[],"asks":[["new",3896.25,8.0e4]],"prev_change_id":15557284687}}}
{"jsonrpc":"2.0","method":"subscription","params":{"channel":"book.ETH-PERPETUAL.raw","data":{"timestamp":1734114592337,"type":"change","change_id":15557284692,"instrument_name":"ETH-PERPETUAL","bids":[["new",3881.25,8.0e4]],"asks":[],"prev_change_id":15557284691}}}
{"jsonrpc":"2.0","method":"subscription","params":{"channel":"book.ETH-PERPETUAL.raw","data":{"timestamp":1734114592337,"type":"change","change_id":15557284692,"instrument_name":"ETH-PERPETUAL","bids":[["new",3881.25,8.0e4]],"asks":[],"prev_change_id":15557284691}}}
{"jsonrpc":"2.0","method":"subscription","params":{"channel":"book.ETH-PERPETUAL.raw","data":{"timestamp":1734114592340,"type":"change","change_id":15557284693,"instrument_name":"ETH-PERPETUAL","bids":[],"asks":[["change",3896.25,1.0e5]],"prev_change_id":15557284692}}}
{"jsonrpc":"2.0","method":"subscription","params":{"channel":"book.ETH-PERPETUAL.raw","data":{"timestamp":1734114592340,"type":"change","change_id":15557284693,"instrument_name":"ETH-PERPETUAL","bids":[],"asks":[["change",3896.25,1.0e5]],"prev_change_id":15557284692}}}
{"jsonrpc":"2.0","method":"subscription","params":{"channel":"book.ETH-PERPETUAL.raw","data":{"timestamp":1734114592342,"type":"change","change_id":15557284694,"instrument_name":"ETH-PERPETUAL","bids":[["change",3881.25,1.0e5]],"asks":[],"prev_change_id":15557284693}}}
{"jsonrpc":"2.0","method":"subscription","params":{"channel":"book.ETH-PERPETUAL.raw","data":{"timestamp":1734114592342,"type":"change","change_id":15557284694,"instrument_name":"ETH-PERPETUAL","bids":[["change",3881.25,1.0e5]],"asks":[],"prev_change_id":15557284693}}}
{"jsonrpc":"2.0","method":"subscription","params":{"channel":"book.ETH-PERPETUAL.raw","data":{"timestamp":1734114592345,"type":"change","change_id":15557284695,"instrument_name":"ETH-PERPETUAL","bids":[],"asks":[["change",3896.25,1.8e5]],"prev_change_id":15557284694}}}
{"jsonrpc":"2.0","method":"subscription","params":{"channel":"book.ETH-PERPETUAL.raw","data":{"timestamp":1734114592345,"type":"change","change_id":15557284695,"instrument_name":"ETH-PERPETUAL","bids":[],"asks":[["change",3896.25,1.8e5]],"prev_change_id":15557284694}}}
{"jsonrpc":"2.0","method":"subscription","params":{"channel":"book.ETH-PERPETUAL.raw","data":{"timestamp":1734114592347,"type":"change","change_id":15557284696,"instrument_name":"ETH-PERPETUAL","bids":[["change",3881.25,1.8e5]],"asks":[],"prev_change_id":15557284695}}}
{"jsonrpc":"2.0","method":"subscription","params":{"channel":"book.ETH-PERPETUAL.raw","data":{"timestamp":1734114592347,"type":"change","change_id":15557284696,"instrument_name":"ETH-PERPETUAL","bids":[["change",3881.25,1.8e5]],"asks":[],"prev_change_id":15557284695}}}
{"jsonrpc":"2.0","method":"subscription","params":{"channel":"book.ETH-PERPETUAL.raw","data":{"timestamp":1734114592350,"type":"change","change_id":15557284697,"instrument_name":"ETH-PERPETUAL","bids":[],"asks":[["change",3896.25,2.0e5]],"prev_change_id":15557284696}}}
{"jsonrpc":"2.0","method":"subscription","params":{"channel":"book.ETH-PERPETUAL.raw","data":{"timestamp":1734114592350,"type":"change","change_id":15557284697,"instrument_name":"ETH-PERPETUAL","bids":[],"asks":[["change",3896.25,2.0e5]],"prev_change_id":15557284696}}}
{"jsonrpc":"2.0","method":"subscription","params":{"channel":"book.ETH-PERPETUAL.raw","data":{"timestamp":1734114592351,"type":"change","change_id":15557284698,"instrument_name":"ETH-PERPETUAL","bids":[["change",3881.25,2.0e5]],"asks":[],"prev_change_id":15557284697}}}
{"jsonrpc":"2.0","method":"subscription","params":{"channel":"book.ETH-PERPETUAL.raw","data":{"timestamp":1734114592351,"type":"change","change_id":15557284698,"instrument_name":"ETH-PERPETUAL","bids":[["change",3881.25,2.0e5]],"asks":[],"prev_change_id":15557284697}}}
{"jsonrpc":"2.0","method":"subscription","params":{"channel":"book.ETH-PERPETUAL.raw","data":{"timestamp":1734114592521,"type":"change","change_id":15557284699,"instrument_name":"ETH-PERPETUAL","bids":[["delete",3881.25,0.0]],"asks":[["delete",3896.25,0.0]],"prev_change_id":15557284698}}}
{"jsonrpc":"2.0","method":"subscription","params":{"channel":"book.ETH-PERPETUAL.raw","data":{"timestamp":1734114592521,"type":"change","change_id":15557284699,"instrument_name":"ETH-PERPETUAL","bids":[["delete",3881.25,0.0]],"asks":[["delete",3896.25,0.0]],"prev_change_id":15557284698}}}
{"jsonrpc":"2.0","method":"subscription","params":{"channel":"book.ETH-PERPETUAL.raw","data":{"timestamp":1734114592712,"type":"change","change_id":15557284700,"instrument_name":"ETH-PERPETUAL","bids":[],"asks":[["new",3896.25,8.0e4]],"prev_change_id":15557284699}}}
{"jsonrpc":"2.0","method":"subscription","params":{"channel":"book.ETH-PERPETUAL.raw","data":{"timestamp":1734114592712,"type":"change","change_id":15557284700,"instrument_name":"ETH-PERPETUAL","bids":[],"asks":[["new",3896.25,8.0e4]],"prev_change_id":15557284699}}}
{"jsonrpc":"2.0","method":"subscription","params":{"channel":"book.ETH-PERPETUAL.raw","data":{"timestamp":1734114592713,"type":"change","change_id":15557284701,"instrument_name":"ETH-PERPETUAL","bids":[["new",3881.25,8.0e4]],"asks":[],"prev_change_id":15557284700}}}
{"jsonrpc":"2.0","method":"subscription","params":{"channel":"book.ETH-PERPETUAL.raw","data":{"timestamp":1734114592713,"type":"change","change_id":15557284701,"instrument_name":"ETH-PERPETUAL","bids":[["new",3881.25,8.0e4]],"asks":[],"prev_change_id":15557284700}}}
{"jsonrpc":"2.0","method":"subscription","params":{"channel":"book.ETH-PERPETUAL.raw","data":{"timestamp":1734114592715,"type":"change","change_id":15557284702,"instrument_name":"ETH-PERPETUAL","bids":[],"asks":[["change",3896.25,1.0e5]],"prev_change_id":15557284701}}}
{"jsonrpc":"2.0","method":"subscription","params":{"channel":"book.ETH-PERPETUAL.raw","data":{"timestamp":1734114592715,"type":"change","change_id":15557284702,"instrument_name":"ETH-PERPETUAL","bids":[],"asks":[["change",3896.25,1.0e5]],"prev_change_id":15557284701}}}
{"jsonrpc":"2.0","method":"subscription","params":{"channel":"book.ETH-PERPETUAL.raw","data":{"timestamp":1734114592716,"type":"change","change_id":15557284703,"instrument_name":"ETH-PERPETUAL","bids":[["change",3881.25,1.0e5]],"asks":[],"prev_change_id":15557284702}}}
{"jsonrpc":"2.0","method":"subscription","params":{"channel":"book.ETH-PERPETUAL.raw","data":{"timestamp":1734114592716,"type":"change","change_id":15557284703,"instrument_name":"ETH-PERPETUAL","bids":[["change",3881.25,1.0e5]],"asks":[],"prev_change_id":15557284702}}}
{"jsonrpc":"2.0","method":"subscription","params":{"channel":"book.ETH-PERPETUAL.raw","data":{"timestamp":1734114592718,"type":"change","change_id":15557284704,"instrument_name":"ETH-PERPETUAL","bids":[],"asks":[["change",3896.25,1.8e5]],"prev_change_id":15557284703}}}
{"jsonrpc":"2.0","method":"subscription","params":{"channel":"book.ETH-PERPETUAL.raw","data":{"timestamp":1734114592718,"type":"change","change_id":15557284704,"instrument_name":"ETH-PERPETUAL","bids":[],"asks":[["change",3896.25,1.8e5]],"prev_change_id":15557284703}}}
{"jsonrpc":"2.0","method":"subscription","params":{"channel":"book.ETH-PERPETUAL.raw","data":{"timestamp":1734114592719,"type":"change","change_id":15557284705,"instrument_name":"ETH-PERPETUAL","bids":[["change",3881.25,1.8e5]],"asks":[],"prev_change_id":15557284704}}}
{"jsonrpc":"2.0","method":"subscription","params":{"channel":"book.ETH-PERPETUAL.raw","data":{"timestamp":1734114592719,"type":"change","change_id":15557284705,"instrument_name":"ETH-PERPETUAL","bids":[["change",3881.25,1.8e5]],"asks":[],"prev_change_id":15557284704}}}
{"jsonrpc":"2.0","method":"subscription","params":{"channel":"book.ETH-PERPETUAL.raw","data":{"timestamp":1734114592721,"type":"change","change_id":15557284706,"instrument_name":"ETH-PERPETUAL","bids":[],"asks":[["change",3896.25,2.0e5]],"prev_change_id":15557284705}}}
{"jsonrpc":"2.0","method":"subscription","params":{"channel":"book.ETH-PERPETUAL.raw","data":{"timestamp":1734114592721,"type":"change","change_id":15557284706,"instrument_name":"ETH-PERPETUAL","bids":[],"asks":[["change",3896.25,2.0e5]],"prev_change_id":15557284705}}}
{"jsonrpc":"2.0","method":"subscription","params":{"channel":"book.ETH-PERPETUAL.raw","data":{"timestamp":1734114592722,"type":"change","change_id":15557284707,"instrument_name":"ETH-PERPETUAL","bids":[["change",3881.25,2.0e5]],"asks":[],"prev_change_id":15557284706}}}
{"jsonrpc":"2.0","method":"subscription","params":{"channel":"book.ETH-PERPETUAL.raw","data":{"timestamp":1734114592722,"type":"change","change_id":15557284707,"instrument_name":"ETH-PERPETUAL","bids":[["change",3881.25,2.0e5]],"asks":[],"prev_change_id":15557284706}}}
{"jsonrpc":"2.0","method":"subscription","params":{"channel":"book.ETH-PERPETUAL.raw","data":{"timestamp":1734114592813,"type":"change","change_id":15557284708,"instrument_name":"ETH-PERPETUAL","bids":[["delete",3881.25,0.0]],"asks":[["delete",3896.25,0.0]],"prev_change_id":15557284707}}}
{"jsonrpc":"2.0","method":"subscription","params":{"channel":"book.ETH-PERPETUAL.raw","data":{"timestamp":1734114592813,"type":"change","change_id":15557284708,"instrument_name":"ETH-PERPETUAL","bids":[["delete",3881.25,0.0]],"asks":[["delete",3896.25,0.0]],"prev_change_id":15557284707}}}
{"jsonrpc":"2.0","method":"subscription","params":{"channel":"book.ETH-PERPETUAL.raw","data":{"timestamp":1734114593026,"type":"change","change_id":15557284731,"instrument_name":"ETH-PERPETUAL","bids":[["delete",1942.0,0.0]],"asks":[],"prev_change_id":15557284708}}}
{"jsonrpc":"2.0","method":"subscription","params":{"channel":"book.ETH-PERPETUAL.raw","data":{"timestamp":1734114593026,"type":"change","change_id":15557284731,"instrument_name":"ETH-PERPETUAL","bids":[["delete",1942.0,0.0]],"asks":[],"prev_change_id":15557284708}}}
{"jsonrpc":"2.0","method":"subscription","params":{"channel":"book.ETH-PERPETUAL.raw","data":{"timestamp":1734114593026,"type":"change","change_id":15557284732,"instrument_name":"ETH-PERPETUAL","bids":[],"asks":[["new",3896.25,8.0e4]],"prev_change_id":15557284731}}}
{"jsonrpc":"2.0","method":"subscription","params":{"channel":"book.ETH-PERPETUAL.raw","data":{"timestamp":1734114593026,"type":"change","change_id":15557284732,"instrument_name":"ETH-PERPETUAL","bids":[],"asks":[["new",3896.25,8.0e4]],"prev_change_id":15557284731}}}
{"jsonrpc":"2.0","method":"subscription","params":{"channel":"book.ETH-PERPETUAL.raw","data":{"timestamp":1734114593028,"type":"change","change_id":15557284733,"instrument_name":"ETH-PERPETUAL","bids":[["new",3881.25,8.0e4]],"asks":[],"prev_change_id":15557284732}}}
{"jsonrpc":"2.0","method":"subscription","params":{"channel":"book.ETH-PERPETUAL.raw","data":{"timestamp":1734114593028,"type":"change","change_id":15557284733,"instrument_name":"ETH-PERPETUAL","bids":[["new",3881.25,8.0e4]],"asks":[],"prev_change_id":15557284732}}}
{"jsonrpc":"2.0","method":"subscription","params":{"channel":"book.ETH-PERPETUAL.raw","data":{"timestamp":1734114593029,"type":"change","change_id":15557284735,"instrument_name":"ETH-PERPETUAL","bids":[],"asks":[["change",3896.25,1.0e5]],"prev_change_id":15557284733}}}
{"jsonrpc":"2.0","method":"subscription","params":{"channel":"book.ETH-PERPETUAL.raw","data":{"timestamp":1734114593029,"type":"change","change_id":15557284735,"instrument_name":"ETH-PERPETUAL","bids":[],"asks":[["change",3896.25,1.0e5]],"prev_change_id":15557284733}}}
{"jsonrpc":"2.0","method":"subscription","params":{"channel":"book.ETH-PERPETUAL.raw","data":{"timestamp":1734114593030,"type":"change","change_id":15557284737,"instrument_name":"ETH-PERPETUAL","bids":[["change",3881.25,1.0e5]],"asks":[],"prev_change_id":15557284735}}}
{"jsonrpc":"2.0","method":"subscription","params":{"channel":"book.ETH-PERPETUAL.raw","data":{"timestamp":1734114593030,"type":"change","change_id":15557284737,"instrument_name":"ETH-PERPETUAL","bids":[["change",3881.25,1.0e5]],"asks":[],"prev_change_id":15557284735}}}
{"jsonrpc":"2.0","method":"subscription","params":{"channel":"book.ETH-PERPETUAL.raw","data":{"timestamp":1734114593030,"type":"change","change_id":15557284738,"instrument_name":"ETH-PERPETUAL","bids":[],"asks":[["change",3896.25,1.8e5]],"prev_change_id":15557284737}}}
{"jsonrpc":"2.0","method":"subscription","params":{"channel":"book.ETH-PERPETUAL.raw","data":{"timestamp":1734114593030,"type":"change","change_id":15557284738,"instrument_name":"ETH-PERPETUAL","bids":[],"asks":[["change",3896.25,1.8e5]],"prev_change_id":15557284737}}}
{"jsonrpc":"2.0","method":"subscription","params":{"channel":"book.ETH-PERPETUAL.raw","data":{"timestamp":1734114593032,"type":"change","change_id":15557284740,"instrument_name":"ETH-PERPETUAL","bids":[["change",3881.25,1.8e5]],"asks":[],"prev_change_id":15557284738}}}
{"jsonrpc":"2.0","method":"subscription","params":{"channel":"book.ETH-PERPETUAL.raw","data":{"timestamp":1734114593032,"type":"change","change_id":15557284740,"instrument_name":"ETH-PERPETUAL","bids":[["change",3881.25,1.8e5]],"asks":[],"prev_change_id":15557284738}}}
{"jsonrpc":"2.0","method":"subscription","params":{"channel":"book.ETH-PERPETUAL.raw","data":{"timestamp":1734114593032,"type":"change","change_id":15557284742,"instrument_name":"ETH-PERPETUAL","bids":[],"asks":[["change",3896.25,2.0e5]],"prev_change_id":15557284740}}}
{"jsonrpc":"2.0","method":"subscription","params":{"channel":"book.ETH-PERPETUAL.raw","data":{"timestamp":1734114593032,"type":"change","change_id":15557284742,"instrument_name":"ETH-PERPETUAL","bids":[],"asks":[["change",3896.25,2.0e5]],"prev_change_id":15557284740}}}
{"jsonrpc":"2.0","method":"subscription","params":{"channel":"book.ETH-PERPETUAL.raw","data":{"timestamp":1734114593033,"type":"change","change_id":15557284743,"instrument_name":"ETH-PERPETUAL","bids":[["change",3881.25,2.0e5]],"asks":[],"prev_change_id":15557284742}}}
{"jsonrpc":"2.0","method":"subscription","params":{"channel":"book.ETH-PERPETUAL.raw","data":{"timestamp":1734114593033,"type":"change","change_id":15557284743,"instrument_name":"ETH-PERPETUAL","bids":[["change",3881.25,2.0e5]],"asks":[],"prev_change_id":15557284742}}}
{"jsonrpc":"2.0","method":"subscription","params":{"channel":"book.ETH-PERPETUAL.raw","data":{"timestamp":1734114593176,"type":"change","change_id":15557284770,"instrument_name":"ETH-PERPETUAL","bids":[["delete",3881.25,0.0]],"asks":[["delete",3896.25,0.0]],"prev_change_id":15557284743}}}
{"jsonrpc":"2.0","method":"subscription","params":{"channel":"book.ETH-PERPETUAL.raw","data":{"timestamp":1734114593176,"type":"change","change_id":15557284770,"instrument_name":"ETH-PERPETUAL","bids":[["delete",3881.25,0.0]],"asks":[["delete",3896.25,0.0]],"prev_change_id":15557284743}}}
{"jsonrpc":"2.0","method":"subscription","params":{"channel":"book.ETH-PERPETUAL.raw","data":{"timestamp":1734114593381,"type":"change","change_id":15557284771,"instrument_name":"ETH-PERPETUAL","bids":[],"asks":[["new",3896.25,8.0e4]],"prev_change_id":15557284770}}}
{"jsonrpc":"2.0","method":"subscription","params":{"channel":"book.ETH-PERPETUAL.raw","data":{"timestamp":1734114593381,"type":"change","change_id":15557284771,"instrument_name":"ETH-PERPETUAL","bids":[],"asks":[["new",3896.25,8.0e4]],"prev_change_id":15557284770}}}
{"jsonrpc":"2.0","method":"subscription","params":{"channel":"book.ETH-PERPETUAL.raw","data":{"timestamp":1734114593383,"type":"change","change_id":15557284772,"instrument_name":"ETH-PERPETUAL","bids":[["new",3881.25,8.0e4]],"asks":[],"prev_change_id":15557284771}}}
{"jsonrpc":"2.0","method":"subscription","params":{"channel":"book.ETH-PERPETUAL.raw","data":{"timestamp":1734114593383,"type":"change","change_id":15557284772,"instrument_name":"ETH-PERPETUAL","bids":[["new",3881.25,8.0e4]],"asks":[],"prev_change_id":15557284771}}}
{"jsonrpc":"2.0","method":"subscription","params":{"channel":"book.ETH-PERPETUAL.raw","data":{"timestamp":1734114593384,"type":"change","change_id":15557284773,"instrument_name":"ETH-PERPETUAL","bids":[],"asks":[["change",3896.25,1.0e5]],"prev_change_id":15557284772}}}
{"jsonrpc":"2.0","method":"subscription","params":{"channel":"book.ETH-PERPETUAL.raw","data":{"timestamp":1734114593384,"type":"change","change_id":15557284773,"instrument_name":"ETH-PERPETUAL","bids":[],"asks":[["change",3896.25,1.0e5]],"prev_change_id":15557284772}}}
{"jsonrpc":"2.0","method":"subscription","params":{"channel":"book.ETH-PERPETUAL.raw","data":{"timestamp":1734114593386,"type":"change","change_id":15557284774,"instrument_name":"ETH-PERPETUAL","bids":[["change",3881.25,1.0e5]],"asks":[],"prev_change_id":15557284773}}}
{"jsonrpc":"2.0","method":"subscription","params":{"channel":"book.ETH-PERPETUAL.raw","data":{"timestamp":1734114593386,"type":"change","change_id":15557284774,"instrument_name":"ETH-PERPETUAL","bids":[["change",3881.25,1.0e5]],"asks":[],"prev_change_id":15557284773}}}
{"jsonrpc":"2.0","method":"subscription","params":{"channel":"book.ETH-PERPETUAL.raw","data":{"timestamp":1734114593387,"type":"change","change_id":15557284775,"instrument_name":"ETH-PERPETUAL","bids":[],"asks":[["change",3896.25,1.8e5]],"prev_change_id":15557284774}}}
{"jsonrpc":"2.0","method":"subscription","params":{"channel":"book.ETH-PERPETUAL.raw","data":{"timestamp":1734114593387,"type":"change","change_id":15557284775,"instrument_name":"ETH-PERPETUAL","bids":[],"asks":[["change",3896.25,1.8e5]],"prev_change_id":15557284774}}}
{"jsonrpc":"2.0","method":"subscription","params":{"channel":"book.ETH-PERPETUAL.raw","data":{"timestamp":1734114593389,"type":"change","change_id":15557284776,"instrument_name":"ETH-PERPETUAL","bids":[["change",3881.25,1.8e5]],"asks":[],"prev_change_id":15557284775}}}
{"jsonrpc":"2.0","method":"subscription","params":{"channel":"book.ETH-PERPETUAL.raw","data":{"timestamp":1734114593389,"type":"change","change_id":15557284776,"instrument_name":"ETH-PERPETUAL","bids":[["change",3881.25,1.8e5]],"asks":[],"prev_change_id":15557284775}}}
{"jsonrpc":"2.0","method":"subscription","params":{"channel":"book.ETH-PERPETUAL.raw","data":{"timestamp":1734114593392,"type":"change","change_id":15557284777,"instrument_name":"ETH-PERPETUAL","bids":[],"asks":[["change",3896.25,2.0e5]],"prev_change_id":15557284776}}}
{"jsonrpc":"2.0","method":"subscription","params":{"channel":"book.ETH-PERPETUAL.raw","data":{"timestamp":1734114593392,"type":"change","change_id":15557284777,"instrument_name":"ETH-PERPETUAL","bids":[],"asks":[["change",3896.25,2.0e5]],"prev_change_id":15557284776}}}
{"jsonrpc":"2.0","method":"subscription","params":{"channel":"book.ETH-PERPETUAL.raw","data":{"timestamp":1734114593393,"type":"change","change_id":15557284778,"instrument_name":"ETH-PERPETUAL","bids":[["change",3881.25,2.0e5]],"asks":[],"prev_change_id":15557284777}}}
{"jsonrpc":"2.0","method":"subscription","params":{"channel":"book.ETH-PERPETUAL.raw","data":{"timestamp":1734114593393,"type":"change","change_id":15557284778,"instrument_name":"ETH-PERPETUAL","bids":[["change",3881.25,2.0e5]],"asks":[],"prev_change_id":15557284777}}}
{"jsonrpc":"2.0","method":"subscription","params":{"channel":"book.ETH-PERPETUAL.raw","data":{"timestamp":1734114593520,"type":"change","change_id":15557284779,"instrument_name":"ETH-PERPETUAL","bids":[["delete",3881.25,0.0]],"asks":[["delete",3896.25,0.0]],"prev_change_id":15557284778}}}
{"jsonrpc":"2.0","method":"subscription","params":{"channel":"book.ETH-PERPETUAL.raw","data":{"timestamp":1734114593520,"type":"change","change_id":15557284779,"instrument_name":"ETH-PERPETUAL","bids":[["delete",3881.25,0.0]],"asks":[["delete",3896.25,0.0]],"prev_change_id":15557284778}}}
{"jsonrpc":"2.0","method":"subscription","params":{"channel":"book.ETH-PERPETUAL.raw","data":{"timestamp":1734114593644,"type":"change","change_id":15557284780,"instrument_name":"ETH-PERPETUAL","bids":[],"asks":[["new",3896.4,8.0e4]],"prev_change_id":15557284779}}}
{"jsonrpc":"2.0","method":"subscription","params":{"channel":"book.ETH-PERPETUAL.raw","data":{"timestamp":1734114593644,"type":"change","change_id":15557284780,"instrument_name":"ETH-PERPETUAL","bids":[],"asks":[["new",3896.4,8.0e4]],"prev_change_id":15557284779}}}
{"jsonrpc":"2.0","method":"subscription","params":{"channel":"book.ETH-PERPETUAL.raw","data":{"timestamp":1734114593645,"type":"change","change_id":15557284781,"instrument_name":"ETH-PERPETUAL","bids":[["new",3881.4,8.0e4]],"asks":[],"prev_change_id":15557284780}}}
{"jsonrpc":"2.0","method":"subscription","params":{"channel":"book.ETH-PERPETUAL.raw","data":{"timestamp":1734114593645,"type":"change","change_id":15557284781,"instrument_name":"ETH-PERPETUAL","bids":[["new",3881.4,8.0e4]],"asks":[],"prev_change_id":15557284780}}}
{"jsonrpc":"2.0","method":"subscription","params":{"channel":"book.ETH-PERPETUAL.raw","data":{"timestamp":1734114593824,"type":"change","change_id":15557284782,"instrument_name":"ETH-PERPETUAL","bids":[],"asks":[["new",3896.55,2.0e4]],"prev_change_id":15557284781}}}
{"jsonrpc":"2.0","method":"subscription","params":{"channel":"book.ETH-PERPETUAL.raw","data":{"timestamp":1734114593824,"type":"change","change_id":15557284782,"instrument_name":"ETH-PERPETUAL","bids":[],"asks":[["new",3896.55,2.0e4]],"prev_change_id":15557284781}}}
{"jsonrpc":"2.0","method":"subscription","params":{"channel":"book.ETH-PERPETUAL.raw","data":{"timestamp":1734114593826,"type":"change","change_id":15557284783,"instrument_name":"ETH-PERPETUAL","bids":[["new",3881.55,2.0e4]],"asks":[],"prev_change_id":15557284782}}}
{"jsonrpc":"2.0","method":"subscription","params":{"channel":"book.ETH-PERPETUAL.raw","data":{"timestamp":1734114593826,"type":"change","change_id":15557284783,"instrument_name":"ETH-PERPETUAL","bids":[["new",3881.55,2.0e4]],"asks":[],"prev_change_id":15557284782}}}
{"jsonrpc":"2.0","method":"subscription","params":{"channel":"book.ETH-PERPETUAL.raw","data":{"timestamp":1734114593829,"type":"change","change_id":15557284784,"instrument_name":"ETH-PERPETUAL","bids":[],"asks":[["change",3896.55,4.0e4]],"prev_change_id":15557284783}}}
{"jsonrpc":"2.0","method":"subscription","params":{"channel":"book.ETH-PERPETUAL.raw","data":{"timestamp":1734114593829,"type":"change","change_id":15557284784,"instrument_name":"ETH-PERPETUAL","bids":[],"asks":[["change",3896.55,4.0e4]],"prev_change_id":15557284783}}}
{"jsonrpc":"2.0","method":"subscription","params":{"channel":"book.ETH-PERPETUAL.raw","data":{"timestamp":1734114593832,"type":"change","change_id":15557284785,"instrument_name":"ETH-PERPETUAL","bids":[["change",3881.55,4.0e4]],"asks":[],"prev_change_id":15557284784}}}
{"jsonrpc":"2.0","method":"subscription","params":{"channel":"book.ETH-PERPETUAL.raw","data":{"timestamp":1734114593832,"type":"change","change_id":15557284785,"instrument_name":"ETH-PERPETUAL","bids":[["change",3881.55,4.0e4]],"asks":[],"prev_change_id":15557284784}}}
{"jsonrpc":"2.0","method":"subscription","params":{"channel":"book.ETH-PERPETUAL.raw","data":{"timestamp":1734114593975,"type":"change","change_id":15557284800,"instrument_name":"ETH-PERPETUAL","bids":[["delete",3881.55,0.0],["delete",3881.4,0.0]],"asks":[["delete",3896.4,0.0],["delete",3896.55,0.0]],"prev_change_id":15557284785}}}
{"jsonrpc":"2.0","method":"subscription","params":{"channel":"book.ETH-PERPETUAL.raw","data":{"timestamp":1734114593975,"type":"change","change_id":15557284800,"instrument_name":"ETH-PERPETUAL","bids":[["delete",3881.55,0.0],["delete",3881.4,0.0]],"asks":[["delete",3896.4,0.0],["delete",3896.55,0.0]],"prev_change_id":15557284785}}}
{"jsonrpc":"2.0","method":"subscription","params":{"channel":"book.ETH-PERPETUAL.raw","data":{"timestamp":1734114594237,"type":"change","change_id":15557284814,"instrument_name":"ETH-PERPETUAL","bids":[],"asks":[["new",3896.55,8.0e4]],"prev_change_id":15557284800}}}
{"jsonrpc":"2.0","method":"subscription","params":{"channel":"book.ETH-PERPETUAL.raw","data":{"timestamp":1734114594237,"type":"change","change_id":15557284814,"instrument_name":"ETH-PERPETUAL","bids":[],"asks":[["new",3896.55,8.0e4]],"prev_change_id":15557284800}}}
{"jsonrpc":"2.0","method":"subscription","params":{"channel":"book.ETH-PERPETUAL.raw","data":{"timestamp":1734114594240,"type":"change","change_id":15557284815,"instrument_name":"ETH-PERPETUAL","bids":[["new",3881.55,8.0e4]],"asks":[],"prev_change_id":15557284814}}}
{"jsonrpc":"2.0","method":"subscription","params":{"channel":"book.ETH-PERPETUAL.raw","data":{"timestamp":1734114594240,"type":"change","change_id":15557284815,"instrument_name":"ETH-PERPETUAL","bids":[["new",3881.55,8.0e4]],"asks":[],"prev_change_id":15557284814}}}
{"jsonrpc":"2.0","method":"subscription","params":{"channel":"book.ETH-PERPETUAL.raw","data":{"timestamp":1734114594242,"type":"change","change_id":15557284816,"instrument_name":"ETH-PERPETUAL","bids":[],"asks":[["change",3896.55,1.0e5]],"prev_change_id":15557284815}}}
{"jsonrpc":"2.0","method":"subscription","params":{"channel":"book.ETH-PERPETUAL.raw","data":{"timestamp":1734114594242,"type":"change","change_id":15557284816,"instrument_name":"ETH-PERPETUAL","bids":[],"asks":[["change",3896.55,1.0e5]],"prev_change_id":15557284815}}}
{"jsonrpc":"2.0","method":"subscription","params":{"channel":"book.ETH-PERPETUAL.raw","data":{"timestamp":1734114594244,"type":"change","change_id":15557284817,"instrument_name":"ETH-PERPETUAL","bids":[["change",3881.55,1.0e5]],"asks":[],"prev_change_id":15557284816}}}
{"jsonrpc":"2.0","method":"subscription","params":{"channel":"book.ETH-PERPETUAL.raw","data":{"timestamp":1734114594244,"type":"change","change_id":15557284817,"instrument_name":"ETH-PERPETUAL","bids":[["change",3881.55,1.0e5]],"asks":[],"prev_change_id":15557284816}}}
{"jsonrpc":"2.0","method":"subscription","params":{"channel":"book.ETH-PERPETUAL.raw","data":{"timestamp":1734114594246,"type":"change","change_id":15557284818,"instrument_name":"ETH-PERPETUAL","bids":[],"asks":[["change",3896.55,1.8e5]],"prev_change_id":15557284817}}}
{"jsonrpc":"2.0","method":"subscription","params":{"channel":"book.ETH-PERPETUAL.raw","data":{"timestamp":1734114594246,"type":"change","change_id":15557284818,"instrument_name":"ETH-PERPETUAL","bids":[],"asks":[["change",3896.55,1.8e5]],"prev_change_id":15557284817}}}
{"jsonrpc":"2.0","method":"subscription","params":{"channel":"book.ETH-PERPETUAL.raw","data":{"timestamp":1734114594249,"type":"change","change_id":15557284819,"instrument_name":"ETH-PERPETUAL","bids":[["change",3881.55,1.8e5]],"asks":[],"prev_change_id":15557284818}}}
{"jsonrpc":"2.0","method":"subscription","params":{"channel":"book.ETH-PERPETUAL.raw","data":{"timestamp":1734114594249,"type":"change","change_id":15557284819,"instrument_name":"ETH-PERPETUAL","bids":[["change",3881.55,1.8e5]],"asks":[],"prev_change_id":15557284818}}}
{"jsonrpc":"2.0","method":"subscription","params":{"channel":"book.ETH-PERPETUAL.raw","data":{"timestamp":1734114594251,"type":"change","change_id":15557284820,"instrument_name":"ETH-PERPETUAL","bids":[],"asks":[["change",3896.55,2.0e5]],"prev_change_id":15557284819}}}
{"jsonrpc":"2.0","method":"subscription","params":{"channel":"book.ETH-PERPETUAL.raw","data":{"timestamp":1734114594251,"type":"change","change_id":15557284820,"instrument_name":"ETH-PERPETUAL","bids":[],"asks":[["change",3896.55,2.0e5]],"prev_change_id":15557284819}}}
{"jsonrpc":"2.0","method":"subscription","params":{"channel":"book.ETH-PERPETUAL.raw","data":{"timestamp":1734114594254,"type":"change","change_id":15557284821,"instrument_name":"ETH-PERPETUAL","bids":[["change",3881.55,2.0e5]],"asks":[],"prev_change_id":15557284820}}}
{"jsonrpc":"2.0","method":"subscription","params":{"channel":"book.ETH-PERPETUAL.raw","data":{"timestamp":1734114594254,"type":"change","change_id":15557284821,"instrument_name":"ETH-PERPETUAL","bids":[["change",3881.55,2.0e5]],"asks":[],"prev_change_id":15557284820}}}
{"jsonrpc":"2.0","method":"subscription","params":{"channel":"book.ETH-PERPETUAL.raw","data":{"timestamp":1734114594372,"type":"change","change_id":15557284824,"instrument_name":"ETH-PERPETUAL","bids":[["delete",3881.55,0.0]],"asks":[["delete",3896.55,0.0]],"prev_change_id":15557284821}}}
{"jsonrpc":"2.0","method":"subscription","params":{"channel":"book.ETH-PERPETUAL.raw","data":{"timestamp":1734114594372,"type":"change","change_id":15557284824,"instrument_name":"ETH-PERPETUAL","bids":[["delete",3881.55,0.0]],"asks":[["delete",3896.55,0.0]],"prev_change_id":15557284821}}}
{"jsonrpc":"2.0","method":"subscription","params":{"channel":"book.ETH-PERPETUAL.raw","data":{"timestamp":1734114594382,"type":"change","change_id":15557284825,"instrument_name":"ETH-PERPETUAL","bids":[],"asks":[["new",3908.25,500.0],["delete",3919.85,0.0]],"prev_change_id":15557284824}}}
{"jsonrpc":"2.0","method":"subscription","params":{"channel":"book.ETH-PERPETUAL.raw","data":{"timestamp":1734114594382,"type":"change","change_id":15557284825,"instrument_name":"ETH-PERPETUAL","bids":[],"asks":[["new",3908.25,500.0],["delete",3919.85,0.0]],"prev_change_id":15557284824}}}
{"jsonrpc":"2.0","method":"subscription","params":{"channel":"book.ETH-PERPETUAL.raw","data":{"timestamp":1734114594546,"type":"change","change_id":15557284827,"instrument_name":"ETH-PERPETUAL","bids":[],"asks":[["new",3896.65,8.0e4]],"prev_change_id":15557284825}}}
{"jsonrpc":"2.0","method":"subscription","params":{"channel":"book.ETH-PERPETUAL.raw","data":{"timestamp":1734114594546,"type":"change","change_id":15557284827,"instrument_name":"ETH-PERPETUAL","bids":[],"asks":[["new",3896.65,8.0e4]],"prev_change_id":15557284825}}}
{"jsonrpc":"2.0","method":"subscription","params":{"channel":"book.ETH-PERPETUAL.raw","data":{"timestamp":1734114594548,"type":"change","change_id":15557284828,"instrument_name":"ETH-PERPETUAL","bids":[["new",3881.65,8.0e4]],"asks":[],"prev_change_id":15557284827}}}
{"jsonrpc":"2.0","method":"subscription","params":{"channel":"book.ETH-PERPETUAL.raw","data":{"timestamp":1734114594548,"type":"change","change_id":15557284828,"instrument_name":"ETH-PERPETUAL","bids":[["new",3881.65,8.0e4]],"asks":[],"prev_change_id":15557284827}}}
{"jsonrpc":"2.0","method":"subscription","params":{"channel":"book.ETH-PERPETUAL.raw","data":{"timestamp":1734114594549,"type":"change","change_id":15557284829,"instrument_name":"ETH-PERPETUAL","bids":[],"asks":[["change",3896.65,1.0e5]],"prev_change_id":15557284828}}}
{"jsonrpc":"2.0","method":"subscription","params":{"channel":"book.ETH-PERPETUAL.raw","data":{"timestamp":1734114594549,"type":"change","change_id":15557284829,"instrument_name":"ETH-PERPETUAL","bids":[],"asks":[["change",3896.65,1.0e5]],"prev_change_id":15557284828}}}
{"jsonrpc":"2.0","method":"subscription","params":{"channel":"book.ETH-PERPETUAL.raw","data":{"timestamp":1734114594551,"type":"change","change_id":15557284830,"instrument_name":"ETH-PERPETUAL","bids":[["change",3881.65,1.0e5]],"asks":[],"prev_change_id":15557284829}}}
{"jsonrpc":"2.0","method":"subscription","params":{"channel":"book.ETH-PERPETUAL.raw","data":{"timestamp":1734114594551,"type":"change","change_id":15557284830,"instrument_name":"ETH-PERPETUAL","bids":[["change",3881.65,1.0e5]],"asks":[],"prev_change_id":15557284829}}}
{"jsonrpc":"2.0","method":"subscription","params":{"channel":"book.ETH-PERPETUAL.raw","data":{"timestamp":1734114594552,"type":"change","change_id":15557284831,"instrument_name":"ETH-PERPETUAL","bids":[],"asks":[["change",3896.65,1.8e5]],"prev_change_id":15557284830}}}
{"jsonrpc":"2.0","method":"subscription","params":{"channel":"book.ETH-PERPETUAL.raw","data":{"timestamp":1734114594552,"type":"change","change_id":15557284831,"instrument_name":"ETH-PERPETUAL","bids":[],"asks":[["change",3896.65,1.8e5]],"prev_change_id":15557284830}}}
{"jsonrpc":"2.0","method":"subscription","params":{"channel":"book.ETH-PERPETUAL.raw","data":{"timestamp":1734114594553,"type":"change","change_id":15557284832,"instrument_name":"ETH-PERPETUAL","bids":[["change",3881.65,1.8e5]],"asks":[],"prev_change_id":15557284831}}}
{"jsonrpc":"2.0","method":"subscription","params":{"channel":"book.ETH-PERPETUAL.raw","data":{"timestamp":1734114594553,"type":"change","change_id":15557284832,"instrument_name":"ETH-PERPETUAL","bids":[["change",3881.65,1.8e5]],"asks":[],"prev_change_id":15557284831}}}
{"jsonrpc":"2.0","method":"subscription","params":{"channel":"book.ETH-PERPETUAL.raw","data":{"timestamp":1734114594555,"type":"change","change_id":15557284833,"instrument_name":"ETH-PERPETUAL","bids":[],"asks":[["change",3896.65,2.0e5]],"prev_change_id":15557284832}}}
{"jsonrpc":"2.0","method":"subscription","params":{"channel":"book.ETH-PERPETUAL.raw","data":{"timestamp":1734114594555,"type":"change","change_id":15557284833,"instrument_name":"ETH-PERPETUAL","bids":[],"asks":[["change",3896.65,2.0e5]],"prev_change_id":15557284832}}}
{"jsonrpc":"2.0","method":"subscription","params":{"channel":"book.ETH-PERPETUAL.raw","data":{"timestamp":1734114594557,"type":"change","change_id":15557284835,"instrument_name":"ETH-PERPETUAL","bids":[["change",3881.65,2.0e5]],"asks":[],"prev_change_id":15557284833}}}
{"jsonrpc":"2.0","method":"subscription","params":{"channel":"book.ETH-PERPETUAL.raw","data":{"timestamp":1734114594557,"type":"change","change_id":15557284835,"instrument_name":"ETH-PERPETUAL","bids":[["change",3881.65,2.0e5]],"asks":[],"prev_change_id":15557284833}}}
{"jsonrpc":"2.0","method":"subscription","params":{"channel":"book.ETH-PERPETUAL.raw","data":{"timestamp":1734114594641,"type":"change","change_id":15557284839,"instrument_name":"ETH-PERPETUAL","bids":[["delete",3881.65,0.0]],"asks":[["delete",3896.65,0.0]],"prev_change_id":15557284835}}}
{"jsonrpc":"2.0","method":"subscription","params":{"channel":"book.ETH-PERPETUAL.raw","data":{"timestamp":1734114594641,"type":"change","change_id":15557284839,"instrument_name":"ETH-PERPETUAL","bids":[["delete",3881.65,0.0]],"asks":[["delete",3896.65,0.0]],"prev_change_id":15557284835}}}
{"jsonrpc":"2.0","method":"subscription","params":{"channel":"book.ETH-PERPETUAL.raw","data":{"timestamp":1734114594787,"type":"change","change_id":15557284841,"instrument_name":"ETH-PERPETUAL","bids":[],"asks":[["delete",3916.15,0.0],["new",3927.8,500.0]],"prev_change_id":15557284839}}}
{"jsonrpc":"2.0","method":"subscription","params":{"channel":"book.ETH-PERPETUAL.raw","data":{"timestamp":1734114594787,"type":"change","change_id":15557284841,"instrument_name":"ETH-PERPETUAL","bids":[],"asks":[["delete",3916.15,0.0],["new",3927.8,500.0]],"prev_change_id":15557284839}}}
{"jsonrpc":"2.0","method":"subscription","params":{"channel":"book.ETH-PERPETUAL.raw","data":{"timestamp":1734114594808,"type":"change","change_id":15557284842,"instrument_name":"ETH-PERPETUAL","bids":[],"asks":[["new",3896.65,8.0e4]],"prev_change_id":15557284841}}}
{"jsonrpc":"2.0","method":"subscription","params":{"channel":"book.ETH-PERPETUAL.raw","data":{"timestamp":1734114594808,"type":"change","change_id":15557284842,"instrument_name":"ETH-PERPETUAL","bids":[],"asks":[["new",3896.65,8.0e4]],"prev_change_id":15557284841}}}
{"jsonrpc":"2.0","method":"subscription","params":{"channel":"book.ETH-PERPETUAL.raw","data":{"timestamp":1734114594810,"type":"change","change_id":15557284843,"instrument_name":"ETH-PERPETUAL","bids":[["new",3881.65,8.0e4]],"asks":[],"prev_change_id":15557284842}}}
{"jsonrpc":"2.0","method":"subscription","params":{"channel":"book.ETH-PERPETUAL.raw","data":{"timestamp":1734114594810,"type":"change","change_id":15557284843,"instrument_name":"ETH-PERPETUAL","bids":[["new",3881.65,8.0e4]],"asks":[],"prev_change_id":15557284842}}}
{"jsonrpc":"2.0","method":"subscription","params":{"channel":"book.ETH-PERPETUAL.raw","data":{"timestamp":1734114594811,"type":"change","change_id":15557284844,"instrument_name":"ETH-PERPETUAL","bids":[],"asks":[["change",3896.65,1.6e5]],"prev_change_id":15557284843}}}
{"jsonrpc":"2.0","method":"subscription","params":{"channel":"book.ETH-PERPETUAL.raw","data":{"timestamp":1734114594811,"type":"change","change_id":15557284844,"instrument_name":"ETH-PERPETUAL","bids":[],"asks":[["change",3896.65,1.6e5]],"prev_change_id":15557284843}}}
{"jsonrpc":"2.0","method":"subscription","params":{"channel":"book.ETH-PERPETUAL.raw","data":{"timestamp":1734114594813,"type":"change","change_id":15557284845,"instrument_name":"ETH-PERPETUAL","bids":[["change",3881.65,1.6e5]],"asks":[],"prev_change_id":15557284844}}}
{"jsonrpc":"2.0","method":"subscription","params":{"channel":"book.ETH-PERPETUAL.raw","data":{"timestamp":1734114594813,"type":"change","change_id":15557284845,"instrument_name":"ETH-PERPETUAL","bids":[["change",3881.65,1.6e5]],"asks":[],"prev_change_id":15557284844}}}
{"jsonrpc":"2.0","method":"subscription","params":{"channel":"book.ETH-PERPETUAL.raw","data":{"timestamp":1734114594931,"type":"change","change_id":15557284846,"instrument_name":"ETH-PERPETUAL","bids":[["delete",3881.65,0.0]],"asks":[["delete",3896.65,0.0]],"prev_change_id":15557284845}}}
{"jsonrpc":"2.0","method":"subscription","params":{"channel":"book.ETH-PERPETUAL.raw","data":{"timestamp":1734114594931,"type":"change","change_id":15557284846,"instrument_name":"ETH-PERPETUAL","bids":[["delete",3881.65,0.0]],"asks":[["delete",3896.65,0.0]],"prev_change_id":15557284845}}}
{"jsonrpc":"2.0","method":"subscription","params":{"channel":"book.ETH-PERPETUAL.raw","data":{"timestamp":1734114595113,"type":"change","change_id":15557284880,"instrument_name":"ETH-PERPETUAL","bids":[],"asks":[["new",3896.65,8.0e4]],"prev_change_id":15557284846}}}
{"jsonrpc":"2.0","method":"subscription","params":{"channel":"book.ETH-PERPETUAL.raw","data":{"timestamp":1734114595113,"type":"change","change_id":15557284880,"instrument_name":"ETH-PERPETUAL","bids":[],"asks":[["new",3896.65,8.0e4]],"prev_change_id":15557284846}}}
{"jsonrpc":"2.0","method":"subscription","params":{"channel":"book.ETH-PERPETUAL.raw","data":{"timestamp":1734114595114,"type":"change","change_id":15557284881,"instrument_name":"ETH-PERPETUAL","bids":[["new",3881.65,8.0e4]],"asks":[],"prev_change_id":15557284880}}}
{"jsonrpc":"2.0","method":"subscription","params":{"channel":"book.ETH-PERPETUAL.raw","data":{"timestamp":1734114595114,"type":"change","change_id":15557284881,"instrument_name":"ETH-PERPETUAL","bids":[["new",3881.65,8.0e4]],"asks":[],"prev_change_id":15557284880}}}
{"jsonrpc":"2.0","method":"subscription","params":{"channel":"book.ETH-PERPETUAL.raw","data":{"timestamp":1734114595115,"type":"change","change_id":15557284882,"instrument_name":"ETH-PERPETUAL","bids":[],"asks":[["change",3896.65,1.0e5]],"prev_change_id":15557284881}}}
{"jsonrpc":"2.0","method":"subscription","params":{"channel":"book.ETH-PERPETUAL.raw","data":{"timestamp":1734114595115,"type":"change","change_id":15557284882,"instrument_name":"ETH-PERPETUAL","bids":[],"asks":[["change",3896.65,1.0e5]],"prev_change_id":15557284881}}}
{"jsonrpc":"2.0","method":"subscription","params":{"channel":"book.ETH-PERPETUAL.raw","data":{"timestamp":1734114595116,"type":"change","change_id":15557284883,"instrument_name":"ETH-PERPETUAL","bids":[],"asks":[["change",3896.65,1.8e5]],"prev_change_id":15557284882}}}
{"jsonrpc":"2.0","method":"subscription","params":{"channel":"book.ETH-PERPETUAL.raw","data":{"timestamp":1734114595116,"type":"change","change_id":15557284883,"instrument_name":"ETH-PERPETUAL","bids":[],"asks":[["change",3896.65,1.8e5]],"prev_change_id":15557284882}}}
{"jsonrpc":"2.0","method":"subscription","params":{"channel":"book.ETH-PERPETUAL.raw","data":{"timestamp":1734114595117,"type":"change","change_id":15557284884,"instrument_name":"ETH-PERPETUAL","bids":[["change",3881.65,1.6e5]],"asks":[],"prev_change_id":15557284883}}}
{"jsonrpc":"2.0","method":"subscription","params":{"channel":"book.ETH-PERPETUAL.raw","data":{"timestamp":1734114595117,"type":"change","change_id":15557284884,"instrument_name":"ETH-PERPETUAL","bids":[["change",3881.65,1.6e5]],"asks":[],"prev_change_id":15557284883}}}
{"jsonrpc":"2.0","method":"subscription","params":{"channel":"book.ETH-PERPETUAL.raw","data":{"timestamp":1734114595118,"type":"change","change_id":15557284885,"instrument_name":"ETH-PERPETUAL","bids":[],"asks":[["change",3896.65,2.0e5]],"prev_change_id":15557284884}}}
{"jsonrpc":"2.0","method":"subscription","params":{"channel":"book.ETH-PERPETUAL.raw","data":{"timestamp":1734114595118,"type":"change","change_id":15557284885,"instrument_name":"ETH-PERPETUAL","bids":[],"asks":[["change",3896.65,2.0e5]],"prev_change_id":15557284884}}}
{"jsonrpc":"2.0","method":"subscription","params":{"channel":"book.ETH-PERPETUAL.raw","data":{"timestamp":1734114595259,"type":"change","change_id":15557284888,"instrument_name":"ETH-PERPETUAL","bids":[["delete",3881.65,0.0]],"asks":[["delete",3896.65,0.0]],"prev_change_id":15557284885}}}
{"jsonrpc":"2.0","method":"subscription","params":{"channel":"book.ETH-PERPETUAL.raw","data":{"timestamp":1734114595259,"type":"change","change_id":15557284888,"instrument_name":"ETH-PERPETUAL","bids":[["delete",3881.65,0.0]],"asks":[["delete",3896.65,0.0]],"prev_change_id":15557284885}}}
{"jsonrpc":"2.0","method":"subscription","params":{"channel":"book.ETH-PERPETUAL.raw","data":{"timestamp":1734114595470,"type":"change","change_id":15557284927,"instrument_name":"ETH-PERPETUAL","bids":[],"asks":[["new",3896.6,8.0e4]],"prev_change_id":15557284888}}}
{"jsonrpc":"2.0","method":"subscription","params":{"channel":"book.ETH-PERPETUAL.raw","data":{"timestamp":1734114595470,"type":"change","change_id":15557284927,"instrument_name":"ETH-PERPETUAL","bids":[],"asks":[["new",3896.6,8.0e4]],"prev_change_id":15557284888}}}
{"jsonrpc":"2.0","method":"subscription","params":{"channel":"book.ETH-PERPETUAL.raw","data":{"timestamp":1734114595471,"type":"change","change_id":15557284928,"instrument_name":"ETH-PERPETUAL","bids":[["new",3881.65,8.0e4]],"asks":[],"prev_change_id":15557284927}}}
{"jsonrpc":"2.0","method":"subscription","params":{"channel":"book.ETH-PERPETUAL.raw","data":{"timestamp":1734114595471,"type":"change","change_id":15557284928,"instrument_name":"ETH-PERPETUAL","bids":[["new",3881.65,8.0e4]],"asks":[],"prev_change_id":15557284927}}}
{"jsonrpc":"2.0","method":"subscription","params":{"channel":"book.ETH-PERPETUAL.raw","data":{"timestamp":1734114595473,"type":"change","change_id":15557284929,"instrument_name":"ETH-PERPETUAL","bids":[],"asks":[["change",3896.6,1.0e5]],"prev_change_id":15557284928}}}
{"jsonrpc":"2.0","method":"subscription","params":{"channel":"book.ETH-PERPETUAL.raw","data":{"timestamp":1734114595473,"type":"change","change_id":15557284929,"instrument_name":"ETH-PERPETUAL","bids":[],"asks":[["change",3896.6,1.0e5]],"prev_change_id":15557284928}}}
{"jsonrpc":"2.0","method":"subscription","params":{"channel":"book.ETH-PERPETUAL.raw","data":{"timestamp":1734114595477,"type":"change","change_id":15557284930,"instrument_name":"ETH-PERPETUAL","bids":[["change",3881.65,1.0e5]],"asks":[],"prev_change_id":15557284929}}}
{"jsonrpc":"2.0","method":"subscription","params":{"channel":"book.ETH-PERPETUAL.raw","data":{"timestamp":1734114595477,"type":"change","change_id":15557284930,"instrument_name":"ETH-PERPETUAL","bids":[["change",3881.65,1.0e5]],"asks":[],"prev_change_id":15557284929}}}
{"jsonrpc":"2.0","method":"subscription","params":{"channel":"book.ETH-PERPETUAL.raw","data":{"timestamp":1734114595478,"type":"change","change_id":15557284931,"instrument_name":"ETH-PERPETUAL","bids":[],"asks":[["change",3896.6,1.8e5]],"prev_change_id":15557284930}}}
{"jsonrpc":"2.0","method":"subscription","params":{"channel":"book.ETH-PERPETUAL.raw","data":{"timestamp":1734114595478,"type":"change","change_id":15557284931,"instrument_name":"ETH-PERPETUAL","bids":[],"asks":[["change",3896.6,1.8e5]],"prev_change_id":15557284930}}}
{"jsonrpc":"2.0","method":"subscription","params":{"channel":"book.ETH-PERPETUAL.raw","data":{"timestamp":1734114595481,"type":"change","change_id":15557284932,"instrument_name":"ETH-PERPETUAL","bids":[["change",3881.65,1.8e5]],"asks":[],"prev_change_id":15557284931}}}
{"jsonrpc":"2.0","method":"subscription","params":{"channel":"book.ETH-PERPETUAL.raw","data":{"timestamp":1734114595481,"type":"change","change_id":15557284932,"instrument_name":"ETH-PERPETUAL","bids":[["change",3881.65,1.8e5]],"asks":[],"prev_change_id":15557284931}}}
{"jsonrpc":"2.0","method":"subscription","params":{"channel":"book.ETH-PERPETUAL.raw","data":{"timestamp":1734114595484,"type":"change","change_id":15557284933,"instrument_name":"ETH-PERPETUAL","bids":[],"asks":[["change",3896.6,2.0e5]],"prev_change_id":15557284932}}}
{"jsonrpc":"2.0","method":"subscription","params":{"channel":"book.ETH-PERPETUAL.raw","data":{"timestamp":1734114595484,"type":"change","change_id":15557284933,"instrument_name":"ETH-PERPETUAL","bids":[],"asks":[["change",3896.6,2.0e5]],"prev_change_id":15557284932}}}
{"jsonrpc":"2.0","method":"subscription","params":{"channel":"book.ETH-PERPETUAL.raw","data":{"timestamp":1734114595487,"type":"change","change_id":15557284934,"instrument_name":"ETH-PERPETUAL","bids":[["change",3881.65,2.0e5]],"asks":[],"prev_change_id":15557284933}}}
{"jsonrpc":"2.0","method":"subscription","params":{"channel":"book.ETH-PERPETUAL.raw","data":{"timestamp":1734114595487,"type":"change","change_id":15557284934,"instrument_name":"ETH-PERPETUAL","bids":[["change",3881.65,2.0e5]],"asks":[],"prev_change_id":15557284933}}}
{"jsonrpc":"2.0","method":"subscription","params":{"channel":"book.ETH-PERPETUAL.raw","data":{"timestamp":1734114595621,"type":"change","change_id":15557284935,"instrument_name":"ETH-PERPETUAL","bids":[["delete",3881.65,0.0]],"asks":[["delete",3896.6,0.0]],"prev_change_id":15557284934}}}
{"jsonrpc":"2.0","method":"subscription","params":{"channel":"book.ETH-PERPETUAL.raw","data":{"timestamp":1734114595621,"type":"change","change_id":15557284935,"instrument_name":"ETH-PERPETUAL","bids":[["delete",3881.65,0.0]],"asks":[["delete",3896.6,0.0]],"prev_change_id":15557284934}}}
{"jsonrpc":"2.0","method":"subscription","params":{"channel":"book.ETH-PERPETUAL.raw","data":{"timestamp":1734114595852,"type":"change","change_id":15557284937,"instrument_name":"ETH-PERPETUAL","bids":[],"asks":[["new",3896.65,8.0e4]],"prev_change_id":15557284935}}}
{"jsonrpc":"2.0","method":"subscription","params":{"channel":"book.ETH-PERPETUAL.raw","data":{"timestamp":1734114595852,"type":"change","change_id":15557284937,"instrument_name":"ETH-PERPETUAL","bids":[],"asks":[["new",3896.65,8.0e4]],"prev_change_id":15557284935}}}
{"jsonrpc":"2.0","method":"subscription","params":{"channel":"book.ETH-PERPETUAL.raw","data":{"timestamp":1734114595854,"type":"change","change_id":15557284938,"instrument_name":"ETH-PERPETUAL","bids":[["new",3881.65,8.0e4]],"asks":[],"prev_change_id":15557284937}}}
{"jsonrpc":"2.0","method":"subscription","params":{"channel":"book.ETH-PERPETUAL.raw","data":{"timestamp":1734114595854,"type":"change","change_id":15557284938,"instrument_name":"ETH-PERPETUAL","bids":[["new",3881.65,8.0e4]],"asks":[],"prev_change_id":15557284937}}}
{"jsonrpc":"2.0","method":"subscription","params":{"channel":"book.ETH-PERPETUAL.raw","data":{"timestamp":1734114595855,"type":"change","change_id":15557284939,"instrument_name":"ETH-PERPETUAL","bids":[],"asks":[["change",3896.65,1.0e5]],"prev_change_id":15557284938}}}
{"jsonrpc":"2.0","method":"subscription","params":{"channel":"book.ETH-PERPETUAL.raw","data":{"timestamp":1734114595855,"type":"change","change_id":15557284939,"instrument_name":"ETH-PERPETUAL","bids":[],"asks":[["change",3896.65,1.0e5]],"prev_change_id":15557284938}}}
{"jsonrpc":"2.0","method":"subscription","params":{"channel":"book.ETH-PERPETUAL.raw","data":{"timestamp":1734114595861,"type":"change","change_id":15557284941,"instrument_name":"ETH-PERPETUAL","bids":[],"asks":[["change",3896.65,1.8e5]],"prev_change_id":15557284939}}}
{"jsonrpc":"2.0","method":"subscription","params":{"channel":"book.ETH-PERPETUAL.raw","data":{"timestamp":1734114595861,"type":"change","change_id":15557284941,"instrument_name":"ETH-PERPETUAL","bids":[],"asks":[["change",3896.65,1.8e5]],"prev_change_id":15557284939}}}
{"jsonrpc":"2.0","method":"subscription","params":{"channel":"book.ETH-PERPETUAL.raw","data":{"timestamp":1734114595862,"type":"change","change_id":15557284942,"instrument_name":"ETH-PERPETUAL","bids":[["change",3881.65,1.6e5]],"asks":[],"prev_change_id":15557284941}}}
{"jsonrpc":"2.0","method":"subscription","params":{"channel":"book.ETH-PERPETUAL.raw","data":{"timestamp":1734114595862,"type":"change","change_id":15557284942,"instrument_name":"ETH-PERPETUAL","bids":[["change",3881.65,1.6e5]],"asks":[],"prev_change_id":15557284941}}}
{"jsonrpc":"2.0","method":"subscription","params":{"channel":"book.ETH-PERPETUAL.raw","data":{"timestamp":1734114595863,"type":"change","change_id":15557284943,"instrument_name":"ETH-PERPETUAL","bids":[],"asks":[["change",3896.65,2.0e5]],"prev_change_id":15557284942}}}
{"jsonrpc":"2.0","method":"subscription","params":{"channel":"book.ETH-PERPETUAL.raw","data":{"timestamp":1734114595863,"type":"change","change_id":15557284943,"instrument_name":"ETH-PERPETUAL","bids":[],"asks":[["change",3896.65,2.0e5]],"prev_change_id":15557284942}}}
{"jsonrpc":"2.0","method":"subscription","params":{"channel":"book.ETH-PERPETUAL.raw","data":{"timestamp":1734114596031,"type":"change","change_id":15557284950,"instrument_name":"ETH-PERPETUAL","bids":[["delete",3881.65,0.0]],"asks":[["delete",3896.65,0.0]],"prev_change_id":15557284943}}}
{"jsonrpc":"2.0","method":"subscription","params":{"channel":"book.ETH-PERPETUAL.raw","data":{"timestamp":1734114596031,"type":"change","change_id":15557284950,"instrument_name":"ETH-PERPETUAL","bids":[["delete",3881.65,0.0]],"asks":[["delete",3896.65,0.0]],"prev_change_id":15557284943}}}
{"jsonrpc":"2.0","method":"subscription","params":{"channel":"book.ETH-PERPETUAL.raw","data":{"timestamp":1734114596284,"type":"change","change_id":15557284954,"instrument_name":"ETH-PERPETUAL","bids":[],"asks":[["new",3896.65,8.0e4]],"prev_change_id":15557284950}}}
{"jsonrpc":"2.0","method":"subscription","params":{"channel":"book.ETH-PERPETUAL.raw","data":{"timestamp":1734114596284,"type":"change","change_id":15557284954,"instrument_name":"ETH-PERPETUAL","bids":[],"asks":[["new",3896.65,8.0e4]],"prev_change_id":15557284950}}}
{"jsonrpc":"2.0","method":"subscription","params":{"channel":"book.ETH-PERPETUAL.raw","data":{"timestamp":1734114596286,"type":"change","change_id":15557284955,"instrument_name":"ETH-PERPETUAL","bids":[["new",3881.7,8.0e4]],"asks":[],"prev_change_id":15557284954}}}
{"jsonrpc":"2.0","method":"subscription","params":{"channel":"book.ETH-PERPETUAL.raw","data":{"timestamp":1734114596286,"type":"change","change_id":15557284955,"instrument_name":"ETH-PERPETUAL","bids":[["new",3881.7,8.0e4]],"asks":[],"prev_change_id":15557284954}}}
{"jsonrpc":"2.0","method":"subscription","params":{"channel":"book.ETH-PERPETUAL.raw","data":{"timestamp":1734114596287,"type":"change","change_id":15557284957,"instrument_name":"ETH-PERPETUAL","bids":[],"asks":[["change",3896.65,1.0e5]],"prev_change_id":15557284955}}}
{"jsonrpc":"2.0","method":"subscription","params":{"channel":"book.ETH-PERPETUAL.raw","data":{"timestamp":1734114596287,"type":"change","change_id":15557284957,"instrument_name":"ETH-PERPETUAL","bids":[],"asks":[["change",3896.65,1.0e5]],"prev_change_id":15557284955}}}
{"jsonrpc":"2.0","method":"subscription","params":{"channel":"book.ETH-PERPETUAL.raw","data":{"timestamp":1734114596288,"type":"change","change_id":15557284958,"instrument_name":"ETH-PERPETUAL","bids":[["change",3881.7,1.0e5]],"asks":[],"prev_change_id":15557284957}}}
{"jsonrpc":"2.0","method":"subscription","params":{"channel":"book.ETH-PERPETUAL.raw","data":{"timestamp":1734114596288,"type":"change","change_id":15557284958,"instrument_name":"ETH-PERPETUAL","bids":[["change",3881.7,1.0e5]],"asks":[],"prev_change_id":15557284957}}}
{"jsonrpc":"2.0","method":"subscription","params":{"channel":"book.ETH-PERPETUAL.raw","data":{"timestamp":1734114596290,"type":"change","change_id":15557284959,"instrument_name":"ETH-PERPETUAL","bids":[],"asks":[["change",3896.65,1.8e5]],"prev_change_id":15557284958}}}
{"jsonrpc":"2.0","method":"subscription","params":{"channel":"book.ETH-PERPETUAL.raw","data":{"timestamp":1734114596290,"type":"change","change_id":15557284959,"instrument_name":"ETH-PERPETUAL","bids":[],"asks":[["change",3896.65,1.8e5]],"prev_change_id":15557284958}}}
{"jsonrpc":"2.0","method":"subscription","params":{"channel":"book.ETH-PERPETUAL.raw","data":{"timestamp":1734114596291,"type":"change","change_id":15557284960,"instrument_name":"ETH-PERPETUAL","bids":[["change",3881.7,1.8e5]],"asks":[],"prev_change_id":15557284959}}}
{"jsonrpc":"2.0","method":"subscription","params":{"channel":"book.ETH-PERPETUAL.raw","data":{"timestamp":1734114596291,"type":"change","change_id":15557284960,"instrument_name":"ETH-PERPETUAL","bids":[["change",3881.7,1.8e5]],"asks":[],"prev_change_id":15557284959}}}
{"jsonrpc":"2.0","method":"subscription","params":{"channel":"book.ETH-PERPETUAL.raw","data":{"timestamp":1734114596292,"type":"change","change_id":15557284961,"instrument_name":"ETH-PERPETUAL","bids":[],"asks":[["change",3896.65,2.0e5]],"prev_change_id":15557284960}}}
{"jsonrpc":"2.0","method":"subscription","params":{"channel":"book.ETH-PERPETUAL.raw","data":{"timestamp":1734114596292,"type":"change","change_id":15557284961,"instrument_name":"ETH-PERPETUAL","bids":[],"asks":[["change",3896.65,2.0e5]],"prev_change_id":15557284960}}}
{"jsonrpc":"2.0","method":"subscription","params":{"channel":"book.ETH-PERPETUAL.raw","data":{"timestamp":1734114596294,"type":"change","change_id":15557284962,"instrument_name":"ETH-PERPETUAL","bids":[["change",3881.7,2.0e5]],"asks":[],"prev_change_id":15557284961}}}
{"jsonrpc":"2.0","method":"subscription","params":{"channel":"book.ETH-PERPETUAL.raw","data":{"timestamp":1734114596294,"type":"change","change_id":15557284962,"instrument_name":"ETH-PERPETUAL","bids":[["change",3881.7,2.0e5]],"asks":[],"prev_change_id":15557284961}}}
{"jsonrpc":"2.0","method":"subscription","params":{"channel":"book.ETH-PERPETUAL.raw","data":{"timestamp":1734114596450,"type":"change","change_id":15557284964,"instrument_name":"ETH-PERPETUAL","bids":[["delete",3881.7,0.0]],"asks":[["delete",3896.65,0.0]],"prev_change_id":15557284962}}}
{"jsonrpc":"2.0","method":"subscription","params":{"channel":"book.ETH-PERPETUAL.raw","data":{"timestamp":1734114596450,"type":"change","change_id":15557284964,"instrument_name":"ETH-PERPETUAL","bids":[["delete",3881.7,0.0]],"asks":[["delete",3896.65,0.0]],"prev_change_id":15557284962}}}
{"jsonrpc":"2.0","method":"subscription","params":{"channel":"book.ETH-PERPETUAL.raw","data":{"timestamp":1734114596665,"type":"change","change_id":15557284981,"instrument_name":"ETH-PERPETUAL","bids":[],"asks":[["new",3896.65,8.0e4]],"prev_change_id":15557284964}}}
{"jsonrpc":"2.0","method":"subscription","params":{"channel":"book.ETH-PERPETUAL.raw","data":{"timestamp":1734114596665,"type":"change","change_id":15557284981,"instrument_name":"ETH-PERPETUAL","bids":[],"asks":[["new",3896.65,8.0e4]],"prev_change_id":15557284964}}}
{"jsonrpc":"2.0","method":"subscription","params":{"channel":"book.ETH-PERPETUAL.raw","data":{"timestamp":1734114596668,"type":"change","change_id":15557284982,"instrument_name":"ETH-PERPETUAL","bids":[["new",3881.7,8.0e4]],"asks":[],"prev_change_id":15557284981}}}
{"jsonrpc":"2.0","method":"subscription","params":{"channel":"book.ETH-PERPETUAL.raw","data":{"timestamp":1734114596668,"type":"change","change_id":15557284982,"instrument_name":"ETH-PERPETUAL","bids":[["new",3881.7,8.0e4]],"asks":[],"prev_change_id":15557284981}}}
{"jsonrpc":"2.0","method":"subscription","params":{"channel":"book.ETH-PERPETUAL.raw","data":{"timestamp":1734114596670,"type":"change","change_id":15557284983,"instrument_name":"ETH-PERPETUAL","bids":[],"asks":[["change",3896.65,1.0e5]],"prev_change_id":15557284982}}}
{"jsonrpc":"2.0","method":"subscription","params":{"channel":"book.ETH-PERPETUAL.raw","data":{"timestamp":1734114596670,"type":"change","change_id":15557284983,"instrument_name":"ETH-PERPETUAL","bids":[],"asks":[["change",3896.65,1.0e5]],"prev_change_id":15557284982}}}
{"jsonrpc":"2.0","method":"subscription","params":{"channel":"book.ETH-PERPETUAL.raw","data":{"timestamp":1734114596672,"type":"change","change_id":15557284984,"instrument_name":"ETH-PERPETUAL","bids":[["change",3881.7,1.0e5]],"asks":[],"prev_change_id":15557284983}}}
{"jsonrpc":"2.0","method":"subscription","params":{"channel":"book.ETH-PERPETUAL.raw","data":{"timestamp":1734114596672,"type":"change","change_id":15557284984,"instrument_name":"ETH-PERPETUAL","bids":[["change",3881.7,1.0e5]],"asks":[],"prev_change_id":15557284983}}}
{"jsonrpc":"2.0","method":"subscription","params":{"channel":"book.ETH-PERPETUAL.raw","data":{"timestamp":1734114596675,"type":"change","change_id":15557284985,"instrument_name":"ETH-PERPETUAL","bids":[],"asks":[["change",3896.65,1.8e5]],"prev_change_id":15557284984}}}
{"jsonrpc":"2.0","method":"subscription","params":{"channel":"book.ETH-PERPETUAL.raw","data":{"timestamp":1734114596675,"type":"change","change_id":15557284985,"instrument_name":"ETH-PERPETUAL","bids":[],"asks":[["change",3896.65,1.8e5]],"prev_change_id":15557284984}}}
{"jsonrpc":"2.0","method":"subscription","params":{"channel":"book.ETH-PERPETUAL.raw","data":{"timestamp":1734114596699,"type":"change","change_id":15557284986,"instrument_name":"ETH-PERPETUAL","bids":[["change",3881.7,1.8e5]],"asks":[],"prev_change_id":15557284985}}}
{"jsonrpc":"2.0","method":"subscription","params":{"channel":"book.ETH-PERPETUAL.raw","data":{"timestamp":1734114596699,"type":"change","change_id":15557284986,"instrument_name":"ETH-PERPETUAL","bids":[["change",3881.7,1.8e5]],"asks":[],"prev_change_id":15557284985}}}
{"jsonrpc":"2.0","method":"subscription","params":{"channel":"book.ETH-PERPETUAL.raw","data":{"timestamp":1734114596724,"type":"change","change_id":15557284987,"instrument_name":"ETH-PERPETUAL","bids":[],"asks":[["change",3896.65,2.0e5]],"prev_change_id":15557284986}}}
{"jsonrpc":"2.0","method":"subscription","params":{"channel":"book.ETH-PERPETUAL.raw","data":{"timestamp":1734114596724,"type":"change","change_id":15557284987,"instrument_name":"ETH-PERPETUAL","bids":[],"asks":[["change",3896.65,2.0e5]],"prev_change_id":15557284986}}}
{"jsonrpc":"2.0","method":"subscription","params":{"channel":"book.ETH-PERPETUAL.raw","data":{"timestamp":1734114596726,"type":"change","change_id":15557284988,"instrument_name":"ETH-PERPETUAL","bids":[["change",3881.7,2.0e5]],"asks":[],"prev_change_id":15557284987}}}
{"jsonrpc":"2.0","method":"subscription","params":{"channel":"book.ETH-PERPETUAL.raw","data":{"timestamp":1734114596726,"type":"change","change_id":15557284988,"instrument_name":"ETH-PERPETUAL","bids":[["change",3881.7,2.0e5]],"asks":[],"prev_change_id":15557284987}}}
{"jsonrpc":"2.0","method":"subscription","params":{"channel":"book.ETH-PERPETUAL.raw","data":{"timestamp":1734114596766,"type":"change","change_id":15557284989,"instrument_name":"ETH-PERPETUAL","bids":[["delete",3881.7,0.0]],"asks":[["delete",3896.65,0.0]],"prev_change_id":15557284988}}}
{"jsonrpc":"2.0","method":"subscription","params":{"channel":"book.ETH-PERPETUAL.raw","data":{"timestamp":1734114596766,"type":"change","change_id":15557284989,"instrument_name":"ETH-PERPETUAL","bids":[["delete",3881.7,0.0]],"asks":[["delete",3896.65,0.0]],"prev_change_id":15557284988}}}
{"jsonrpc":"2.0","method":"subscription","params":{"channel":"book.ETH-PERPETUAL.raw","data":{"timestamp":1734114596807,"type":"change","change_id":15557284990,"instrument_name":"ETH-PERPETUAL","bids":[["delete",3.0,0.0]],"asks":[],"prev_change_id":15557284989}}}
{"jsonrpc":"2.0","method":"subscription","params":{"channel":"book.ETH-PERPETUAL.raw","data":{"timestamp":1734114596807,"type":"change","change_id":15557284990,"instrument_name":"ETH-PERPETUAL","bids":[["delete",3.0,0.0]],"asks":[],"prev_change_id":15557284989}}}
{"jsonrpc":"2.0","method":"subscription","params":{"channel":"book.ETH-PERPETUAL.raw","data":{"timestamp":1734114596938,"type":"change","change_id":15557284992,"instrument_name":"ETH-PERPETUAL","bids":[],"asks":[["new",3896.65,8.0e4]],"prev_change_id":15557284990}}}
{"jsonrpc":"2.0","method":"subscription","params":{"channel":"book.ETH-PERPETUAL.raw","data":{"timestamp":1734114596938,"type":"change","change_id":15557284992,"instrument_name":"ETH-PERPETUAL","bids":[],"asks":[["new",3896.65,8.0e4]],"prev_change_id":15557284990}}}
{"jsonrpc":"2.0","method":"subscription","params":{"channel":"book.ETH-PERPETUAL.raw","data":{"timestamp":1734114596940,"type":"change","change_id":15557284993,"instrument_name":"ETH-PERPETUAL","bids":[["new",3881.7,8.0e4]],"asks":[],"prev_change_id":15557284992}}}
{"jsonrpc":"2.0","method":"subscription","params":{"channel":"book.ETH-PERPETUAL.raw","data":{"timestamp":1734114596940,"type":"change","change_id":15557284993,"instrument_name":"ETH-PERPETUAL","bids":[["new",3881.7,8.0e4]],"asks":[],"prev_change_id":15557284992}}}
{"jsonrpc":"2.0","method":"subscription","params":{"channel":"book.ETH-PERPETUAL.raw","data":{"timestamp":1734114596942,"type":"change","change_id":15557284994,"instrument_name":"ETH-PERPETUAL","bids":[],"asks":[["change",3896.65,1.6e5]],"prev_change_id":15557284993}}}
{"jsonrpc":"2.0","method":"subscription","params":{"channel":"book.ETH-PERPETUAL.raw","data":{"timestamp":1734114596942,"type":"change","change_id":15557284994,"instrument_name":"ETH-PERPETUAL","bids":[],"asks":[["change",3896.65,1.6e5]],"prev_change_id":15557284993}}}
{"jsonrpc":"2.0","method":"subscription","params":{"channel":"book.ETH-PERPETUAL.raw","data":{"timestamp":1734114596943,"type":"change","change_id":15557284995,"instrument_name":"ETH-PERPETUAL","bids":[["change",3881.7,1.6e5]],"asks":[],"prev_change_id":15557284994}}}
{"jsonrpc":"2.0","method":"subscription","params":{"channel":"book.ETH-PERPETUAL.raw","data":{"timestamp":1734114596943,"type":"change","change_id":15557284995,"instrument_name":"ETH-PERPETUAL","bids":[["change",3881.7,1.6e5]],"asks":[],"prev_change_id":15557284994}}}
{"jsonrpc":"2.0","method":"subscription","params":{"channel":"book.ETH-PERPETUAL.raw","data":{"timestamp":1734114597061,"type":"change","change_id":15557285019,"instrument_name":"ETH-PERPETUAL","bids":[["delete",3881.7,0.0]],"asks":[["delete",3896.65,0.0]],"prev_change_id":15557284995}}}
{"jsonrpc":"2.0","method":"subscription","params":{"channel":"book.ETH-PERPETUAL.raw","data":{"timestamp":1734114597061,"type":"change","change_id":15557285019,"instrument_name":"ETH-PERPETUAL","bids":[["delete",3881.7,0.0]],"asks":[["delete",3896.65,0.0]],"prev_change_id":15557284995}}}
{"jsonrpc":"2.0","method":"subscription","params":{"channel":"book.ETH-PERPETUAL.raw","data":{"timestamp":1734114597208,"type":"change","change_id":15557285046,"instrument_name":"ETH-PERPETUAL","bids":[],"asks":[["delete",3935.25,0.0],["new",3947.85,700.0]],"prev_change_id":15557285019}}}
{"jsonrpc":"2.0","method":"subscription","params":{"channel":"book.ETH-PERPETUAL.raw","data":{"timestamp":1734114597208,"type":"change","change_id":15557285046,"instrument_name":"ETH-PERPETUAL","bids":[],"asks":[["delete",3935.25,0.0],["new",3947.85,700.0]],"prev_change_id":15557285019}}}
{"jsonrpc":"2.0","method":"subscription","params":{"channel":"book.ETH-PERPETUAL.raw","data":{"timestamp":1734114597246,"type":"change","change_id":15557285047,"instrument_name":"ETH-PERPETUAL","bids":[],"asks":[["new",3896.65,8.0e4]],"prev_change_id":15557285046}}}
{"jsonrpc":"2.0","method":"subscription","params":{"channel":"book.ETH-PERPETUAL.raw","data":{"timestamp":1734114597246,"type":"change","change_id":15557285047,"instrument_name":"ETH-PERPETUAL","bids":[],"asks":[["new",3896.65,8.0e4]],"prev_change_id":15557285046}}}
{"jsonrpc":"2.0","method":"subscription","params":{"channel":"book.ETH-PERPETUAL.raw","data":{"timestamp":1734114597247,"type":"change","change_id":15557285048,"instrument_name":"ETH-PERPETUAL","bids":[["new",3881.7,8.0e4]],"asks":[],"prev_change_id":15557285047}}}
{"jsonrpc":"2.0","method":"subscription","params":{"channel":"book.ETH-PERPETUAL.raw","data":{"timestamp":1734114597247,"type":"change","change_id":15557285048,"instrument_name":"ETH-PERPETUAL","bids":[["new",3881.7,8.0e4]],"asks":[],"prev_change_id":15557285047}}}
{"jsonrpc":"2.0","method":"subscription","params":{"channel":"book.ETH-PERPETUAL.raw","data":{"timestamp":1734114597248,"type":"change","change_id":15557285049,"instrument_name":"ETH-PERPETUAL","bids":[],"asks":[["change",3896.65,1.0e5]],"prev_change_id":15557285048}}}
{"jsonrpc":"2.0","method":"subscription","params":{"channel":"book.ETH-PERPETUAL.raw","data":{"timestamp":1734114597248,"type":"change","change_id":15557285049,"instrument_name":"ETH-PERPETUAL","bids":[],"asks":[["change",3896.65,1.0e5]],"prev_change_id":15557285048}}}
{"jsonrpc":"2.0","method":"subscription","params":{"channel":"book.ETH-PERPETUAL.raw","data":{"timestamp":1734114597250,"type":"change","change_id":15557285050,"instrument_name":"ETH-PERPETUAL","bids":[],"asks":[["change",3896.65,1.8e5]],"prev_change_id":15557285049}}}
{"jsonrpc":"2.0","method":"subscription","params":{"channel":"book.ETH-PERPETUAL.raw","data":{"timestamp":1734114597250,"type":"change","change_id":15557285050,"instrument_name":"ETH-PERPETUAL","bids":[],"asks":[["change",3896.65,1.8e5]],"prev_change_id":15557285049}}}
{"jsonrpc":"2.0","method":"subscription","params":{"channel":"book.ETH-PERPETUAL.raw","data":{"timestamp":1734114597251,"type":"change","change_id":15557285051,"instrument_name":"ETH-PERPETUAL","bids":[["change",3881.7,1.6e5]],"asks":[],"prev_change_id":15557285050}}}
{"jsonrpc":"2.0","method":"subscription","params":{"channel":"book.ETH-PERPETUAL.raw","data":{"timestamp":1734114597251,"type":"change","change_id":15557285051,"instrument_name":"ETH-PERPETUAL","bids":[["change",3881.7,1.6e5]],"asks":[],"prev_change_id":15557285050}}}
{"jsonrpc":"2.0","method":"subscription","params":{"channel":"book.ETH-PERPETUAL.raw","data":{"timestamp":1734114597252,"type":"change","change_id":15557285052,"instrument_name":"ETH-PERPETUAL","bids":[],"asks":[["change",3896.65,2.0e5]],"prev_change_id":15557285051}}}
{"jsonrpc":"2.0","method":"subscription","params":{"channel":"book.ETH-PERPETUAL.raw","data":{"timestamp":1734114597252,"type":"change","change_id":15557285052,"instrument_name":"ETH-PERPETUAL","bids":[],"asks":[["change",3896.65,2.0e5]],"prev_change_id":15557285051}}}
{"jsonrpc":"2.0","method":"subscription","params":{"channel":"book.ETH-PERPETUAL.raw","data":{"timestamp":1734114597253,"type":"change","change_id":15557285053,"instrument_name":"ETH-PERPETUAL","bids":[["change",3881.7,1.8e5]],"asks":[],"prev_change_id":15557285052}}}
{"jsonrpc":"2.0","method":"subscription","params":{"channel":"book.ETH-PERPETUAL.raw","data":{"timestamp":1734114597253,"type":"change","change_id":15557285053,"instrument_name":"ETH-PERPETUAL","bids":[["change",3881.7,1.8e5]],"asks":[],"prev_change_id":15557285052}}}
{"jsonrpc":"2.0","method":"subscription","params":{"channel":"book.ETH-PERPETUAL.raw","data":{"timestamp":1734114597380,"type":"change","change_id":15557285055,"instrument_name":"ETH-PERPETUAL","bids":[["delete",3881.7,0.0]],"asks":[["delete",3896.65,0.0]],"prev_change_id":15557285053}}}
{"jsonrpc":"2.0","method":"subscription","params":{"channel":"book.ETH-PERPETUAL.raw","data":{"timestamp":1734114597380,"type":"change","change_id":15557285055,"instrument_name":"ETH-PERPETUAL","bids":[["delete",3881.7,0.0]],"asks":[["delete",3896.65,0.0]],"prev_change_id":15557285053}}}
{"jsonrpc":"2.0","method":"subscription","params":{"channel":"book.ETH-PERPETUAL.raw","data":{"timestamp":1734114597556,"type":"change","change_id":15557285056,"instrument_name":"ETH-PERPETUAL","bids":[],"asks":[["new",3896.65,8.0e4]],"prev_change_id":15557285055}}}
{"jsonrpc":"2.0","method":"subscription","params":{"channel":"book.ETH-PERPETUAL.raw","data":{"timestamp":1734114597556,"type":"change","change_id":15557285056,"instrument_name":"ETH-PERPETUAL","bids":[],"asks":[["new",3896.65,8.0e4]],"prev_change_id":15557285055}}}
{"jsonrpc":"2.0","method":"subscription","params":{"channel":"book.ETH-PERPETUAL.raw","data":{"timestamp":1734114597558,"type":"change","change_id":15557285057,"instrument_name":"ETH-PERPETUAL","bids":[["new",3881.7,8.0e4]],"asks":[],"prev_change_id":15557285056}}}
{"jsonrpc":"2.0","method":"subscription","params":{"channel":"book.ETH-PERPETUAL.raw","data":{"timestamp":1734114597558,"type":"change","change_id":15557285057,"instrument_name":"ETH-PERPETUAL","bids":[["new",3881.7,8.0e4]],"asks":[],"prev_change_id":15557285056}}}
{"jsonrpc":"2.0","method":"subscription","params":{"channel":"book.ETH-PERPETUAL.raw","data":{"timestamp":1734114597559,"type":"change","change_id":15557285058,"instrument_name":"ETH-PERPETUAL","bids":[],"asks":[["change",3896.65,1.6e5]],"prev_change_id":15557285057}}}
{"jsonrpc":"2.0","method":"subscription","params":{"channel":"book.ETH-PERPETUAL.raw","data":{"timestamp":1734114597559,"type":"change","change_id":15557285058,"instrument_name":"ETH-PERPETUAL","bids":[],"asks":[["change",3896.65,1.6e5]],"prev_change_id":15557285057}}}
{"jsonrpc":"2.0","method":"subscription","params":{"channel":"book.ETH-PERPETUAL.raw","data":{"timestamp":1734114597561,"type":"change","change_id":15557285059,"instrument_name":"ETH-PERPETUAL","bids":[["change",3881.7,1.6e5]],"asks":[],"prev_change_id":15557285058}}}
{"jsonrpc":"2.0","method":"subscription","params":{"channel":"book.ETH-PERPETUAL.raw","data":{"timestamp":1734114597561,"type":"change","change_id":15557285059,"instrument_name":"ETH-PERPETUAL","bids":[["change",3881.7,1.6e5]],"asks":[],"prev_change_id":15557285058}}}
{"jsonrpc":"2.0","method":"subscription","params":{"channel":"book.ETH-PERPETUAL.raw","data":{"timestamp":1734114597734,"type":"change","change_id":15557285061,"instrument_name":"ETH-PERPETUAL","bids":[["delete",3881.7,0.0]],"asks":[["delete",3896.65,0.0]],"prev_change_id":15557285059}}}
{"jsonrpc":"2.0","method":"subscription","params":{"channel":"book.ETH-PERPETUAL.raw","data":{"timestamp":1734114597734,"type":"change","change_id":15557285061,"instrument_name":"ETH-PERPETUAL","bids":[["delete",3881.7,0.0]],"asks":[["delete",3896.65,0.0]],"prev_change_id":15557285059}}}
{"jsonrpc":"2.0","method":"subscription","params":{"channel":"book.ETH-PERPETUAL.raw","data":{"timestamp":1734114597963,"type":"change","change_id":15557285062,"instrument_name":"ETH-PERPETUAL","bids":[],"asks":[["new",3896.65,8.0e4]],"prev_change_id":15557285061}}}
{"jsonrpc":"2.0","method":"subscription","params":{"channel":"book.ETH-PERPETUAL.raw","data":{"timestamp":1734114597963,"type":"change","change_id":15557285062,"instrument_name":"ETH-PERPETUAL","bids":[],"asks":[["new",3896.65,8.0e4]],"prev_change_id":15557285061}}}
{"jsonrpc":"2.0","method":"subscription","params":{"channel":"book.ETH-PERPETUAL.raw","data":{"timestamp":1734114597966,"type":"change","change_id":15557285064,"instrument_name":"ETH-PERPETUAL","bids":[["new",3881.7,8.0e4]],"asks":[],"prev_change_id":15557285062}}}
{"jsonrpc":"2.0","method":"subscription","params":{"channel":"book.ETH-PERPETUAL.raw","data":{"timestamp":1734114597966,"type":"change","change_id":15557285064,"instrument_name":"ETH-PERPETUAL","bids":[["new",3881.7,8.0e4]],"asks":[],"prev_change_id":15557285062}}}
{"jsonrpc":"2.0","method":"subscription","params":{"channel":"book.ETH-PERPETUAL.raw","data":{"timestamp":1734114597969,"type":"change","change_id":15557285065,"instrument_name":"ETH-PERPETUAL","bids":[],"asks":[["change",3896.65,1.0e5]],"prev_change_id":15557285064}}}
{"jsonrpc":"2.0","method":"subscription","params":{"channel":"book.ETH-PERPETUAL.raw","data":{"timestamp":1734114597969,"type":"change","change_id":15557285065,"instrument_name":"ETH-PERPETUAL","bids":[],"asks":[["change",3896.65,1.0e5]],"prev_change_id":15557285064}}}
{"jsonrpc":"2.0","method":"subscription","params":{"channel":"book.ETH-PERPETUAL.raw","data":{"timestamp":1734114597970,"type":"change","change_id":15557285067,"instrument_name":"ETH-PERPETUAL","bids":[["change",3881.7,1.0e5]],"asks":[],"prev_change_id":15557285065}}}
{"jsonrpc":"2.0","method":"subscription","params":{"channel":"book.ETH-PERPETUAL.raw","data":{"timestamp":1734114597970,"type":"change","change_id":15557285067,"instrument_name":"ETH-PERPETUAL","bids":[["change",3881.7,1.0e5]],"asks":[],"prev_change_id":15557285065}}}
{"jsonrpc":"2.0","method":"subscription","params":{"channel":"book.ETH-PERPETUAL.raw","data":{"timestamp":1734114597971,"type":"change","change_id":15557285068,"instrument_name":"ETH-PERPETUAL","bids":[],"asks":[["change",3896.65,1.8e5]],"prev_change_id":15557285067}}}
{"jsonrpc":"2.0","method":"subscription","params":{"channel":"book.ETH-PERPETUAL.raw","data":{"timestamp":1734114597971,"type":"change","change_id":15557285068,"instrument_name":"ETH-PERPETUAL","bids":[],"asks":[["change",3896.65,1.8e5]],"prev_change_id":15557285067}}}
{"jsonrpc":"2.0","method":"subscription","params":{"channel":"book.ETH-PERPETUAL.raw","data":{"timestamp":1734114597972,"type":"change","change_id":15557285069,"instrument_name":"ETH-PERPETUAL","bids":[["change",3881.7,1.8e5]],"asks":[],"prev_change_id":15557285068}}}
{"jsonrpc":"2.0","method":"subscription","params":{"channel":"book.ETH-PERPETUAL.raw","data":{"timestamp":1734114597972,"type":"change","change_id":15557285069,"instrument_name":"ETH-PERPETUAL","bids":[["change",3881.7,1.8e5]],"asks":[],"prev_change_id":15557285068}}}
{"jsonrpc":"2.0","method":"subscription","params":{"channel":"book.ETH-PERPETUAL.raw","data":{"timestamp":1734114597973,"type":"change","change_id":15557285070,"instrument_name":"ETH-PERPETUAL","bids":[],"asks":[["change",3896.65,2.0e5]],"prev_change_id":15557285069}}}
{"jsonrpc":"2.0","method":"subscription","params":{"channel":"book.ETH-PERPETUAL.raw","data":{"timestamp":1734114597973,"type":"change","change_id":15557285070,"instrument_name":"ETH-PERPETUAL","bids":[],"asks":[["change",3896.65,2.0e5]],"prev_change_id":15557285069}}}
{"jsonrpc":"2.0","method":"subscription","params":{"channel":"book.ETH-PERPETUAL.raw","data":{"timestamp":1734114597974,"type":"change","change_id":15557285071,"instrument_name":"ETH-PERPETUAL","bids":[["change",3881.7,2.0e5]],"asks":[],"prev_change_id":15557285070}}}
{"jsonrpc":"2.0","method":"subscription","params":{"channel":"book.ETH-PERPETUAL.raw","data":{"timestamp":1734114597974,"type":"change","change_id":15557285071,"instrument_name":"ETH-PERPETUAL","bids":[["change",3881.7,2.0e5]],"asks":[],"prev_change_id":15557285070}}}
{"jsonrpc":"2.0","method":"subscription","params":{"channel":"book.ETH-PERPETUAL.raw","data":{"timestamp":1734114598096,"type":"change","change_id":15557285105,"instrument_name":"ETH-PERPETUAL","bids":[["delete",3881.7,0.0]],"asks":[["delete",3896.65,0.0]],"prev_change_id":15557285071}}}
{"jsonrpc":"2.0","method":"subscription","params":{"channel":"book.ETH-PERPETUAL.raw","data":{"timestamp":1734114598096,"type":"change","change_id":15557285105,"instrument_name":"ETH-PERPETUAL","bids":[["delete",3881.7,0.0]],"asks":[["delete",3896.65,0.0]],"prev_change_id":15557285071}}}
{"jsonrpc":"2.0","method":"subscription","params":{"channel":"book.ETH-PERPETUAL.raw","data":{"timestamp":1734114598370,"type":"change","change_id":15557285107,"instrument_name":"ETH-PERPETUAL","bids":[],"asks":[["new",3896.65,8.0e4]],"prev_change_id":15557285105}}}
{"jsonrpc":"2.0","method":"subscription","params":{"channel":"book.ETH-PERPETUAL.raw","data":{"timestamp":1734114598370,"type":"change","change_id":15557285107,"instrument_name":"ETH-PERPETUAL","bids":[],"asks":[["new",3896.65,8.0e4]],"prev_change_id":15557285105}}}
{"jsonrpc":"2.0","method":"subscription","params":{"channel":"book.ETH-PERPETUAL.raw","data":{"timestamp":1734114598372,"type":"change","change_id":15557285108,"instrument_name":"ETH-PERPETUAL","bids":[["new",3881.7,8.0e4]],"asks":[],"prev_change_id":15557285107}}}
{"jsonrpc":"2.0","method":"subscription","params":{"channel":"book.ETH-PERPETUAL.raw","data":{"timestamp":1734114598372,"type":"change","change_id":15557285108,"instrument_name":"ETH-PERPETUAL","bids":[["new",3881.7,8.0e4]],"asks":[],"prev_change_id":15557285107}}}
{"jsonrpc":"2.0","method":"subscription","params":{"channel":"book.ETH-PERPETUAL.raw","data":{"timestamp":1734114598375,"type":"change","change_id":15557285109,"instrument_name":"ETH-PERPETUAL","bids":[],"asks":[["change",3896.65,1.0e5]],"prev_change_id":15557285108}}}
{"jsonrpc":"2.0","method":"subscription","params":{"channel":"book.ETH-PERPETUAL.raw","data":{"timestamp":1734114598375,"type":"change","change_id":15557285109,"instrument_name":"ETH-PERPETUAL","bids":[],"asks":[["change",3896.65,1.0e5]],"prev_change_id":15557285108}}}
{"jsonrpc":"2.0","method":"subscription","params":{"channel":"book.ETH-PERPETUAL.raw","data":{"timestamp":1734114598378,"type":"change","change_id":15557285111,"instrument_name":"ETH-PERPETUAL","bids":[["change",3881.7,1.0e5]],"asks":[],"prev_change_id":15557285109}}}
{"jsonrpc":"2.0","method":"subscription","params":{"channel":"book.ETH-PERPETUAL.raw","data":{"timestamp":1734114598378,"type":"change","change_id":15557285111,"instrument_name":"ETH-PERPETUAL","bids":[["change",3881.7,1.0e5]],"asks":[],"prev_change_id":15557285109}}}
{"jsonrpc":"2.0","method":"subscription","params":{"channel":"book.ETH-PERPETUAL.raw","data":{"timestamp":1734114598380,"type":"change","change_id":15557285112,"instrument_name":"ETH-PERPETUAL","bids":[],"asks":[["change",3896.65,1.8e5]],"prev_change_id":15557285111}}}
{"jsonrpc":"2.0","method":"subscription","params":{"channel":"book.ETH-PERPETUAL.raw","data":{"timestamp":1734114598380,"type":"change","change_id":15557285112,"instrument_name":"ETH-PERPETUAL","bids":[],"asks":[["change",3896.65,1.8e5]],"prev_change_id":15557285111}}}
{"jsonrpc":"2.0","method":"subscription","params":{"channel":"book.ETH-PERPETUAL.raw","data":{"timestamp":1734114598383,"type":"change","change_id":15557285113,"instrument_name":"ETH-PERPETUAL","bids":[["change",3881.7,1.8e5]],"asks":[],"prev_change_id":15557285112}}}
{"jsonrpc":"2.0","method":"subscription","params":{"channel":"book.ETH-PERPETUAL.raw","data":{"timestamp":1734114598383,"type":"change","change_id":15557285113,"instrument_name":"ETH-PERPETUAL","bids":[["change",3881.7,1.8e5]],"asks":[],"prev_change_id":15557285112}}}
{"jsonrpc":"2.0","method":"subscription","params":{"channel":"book.ETH-PERPETUAL.raw","data":{"timestamp":1734114598385,"type":"change","change_id":15557285114,"instrument_name":"ETH-PERPETUAL","bids":[],"asks":[["change",3896.65,2.0e5]],"prev_change_id":15557285113}}}
{"jsonrpc":"2.0","method":"subscription","params":{"channel":"book.ETH-PERPETUAL.raw","data":{"timestamp":1734114598385,"type":"change","change_id":15557285114,"instrument_name":"ETH-PERPETUAL","bids":[],"asks":[["change",3896.65,2.0e5]],"prev_change_id":15557285113}}}
{"jsonrpc":"2.0","method":"subscription","params":{"channel":"book.ETH-PERPETUAL.raw","data":{"timestamp":1734114598388,"type":"change","change_id":15557285115,"instrument_name":"ETH-PERPETUAL","bids":[["change",3881.7,2.0e5]],"asks":[],"prev_change_id":15557285114}}}
{"jsonrpc":"2.0","method":"subscription","params":{"channel":"book.ETH-PERPETUAL.raw","data":{"timestamp":1734114598388,"type":"change","change_id":15557285115,"instrument_name":"ETH-PERPETUAL","bids":[["change",3881.7,2.0e5]],"asks":[],"prev_change_id":15557285114}}}
{"jsonrpc":"2.0","method":"subscription","params":{"channel":"book.ETH-PERPETUAL.raw","data":{"timestamp":1734114598512,"type":"change","change_id":15557285116,"instrument_name":"ETH-PERPETUAL","bids":[["delete",3881.7,0.0]],"asks":[["delete",3896.65,0.0]],"prev_change_id":15557285115}}}
{"jsonrpc":"2.0","method":"subscription","params":{"channel":"book.ETH-PERPETUAL.raw","data":{"timestamp":1734114598512,"type":"change","change_id":15557285116,"instrument_name":"ETH-PERPETUAL","bids":[["delete",3881.7,0.0]],"asks":[["delete",3896.65,0.0]],"prev_change_id":15557285115}}}
{"jsonrpc":"2.0","method":"subscription","params":{"channel":"book.ETH-PERPETUAL.raw","data":{"timestamp":1734114598747,"type":"change","change_id":15557285118,"instrument_name":"ETH-PERPETUAL","bids":[],"asks":[["new",3896.65,8.0e4]],"prev_change_id":15557285116}}}
{"jsonrpc":"2.0","method":"subscription","params":{"channel":"book.ETH-PERPETUAL.raw","data":{"timestamp":1734114598747,"type":"change","change_id":15557285118,"instrument_name":"ETH-PERPETUAL","bids":[],"asks":[["new",3896.65,8.0e4]],"prev_change_id":15557285116}}}
{"jsonrpc":"2.0","method":"subscription","params":{"channel":"book.ETH-PERPETUAL.raw","data":{"timestamp":1734114598750,"type":"change","change_id":15557285119,"instrument_name":"ETH-PERPETUAL","bids":[["new",3881.7,8.0e4]],"asks":[],"prev_change_id":15557285118}}}
{"jsonrpc":"2.0","method":"subscription","params":{"channel":"book.ETH-PERPETUAL.raw","data":{"timestamp":1734114598750,"type":"change","change_id":15557285119,"instrument_name":"ETH-PERPETUAL","bids":[["new",3881.7,8.0e4]],"asks":[],"prev_change_id":15557285118}}}
{"jsonrpc":"2.0","method":"subscription","params":{"channel":"book.ETH-PERPETUAL.raw","data":{"timestamp":1734114598752,"type":"change","change_id":15557285120,"instrument_name":"ETH-PERPETUAL","bids":[],"asks":[["change",3896.65,1.0e5]],"prev_change_id":15557285119}}}
{"jsonrpc":"2.0","method":"subscription","params":{"channel":"book.ETH-PERPETUAL.raw","data":{"timestamp":1734114598752,"type":"change","change_id":15557285120,"instrument_name":"ETH-PERPETUAL","bids":[],"asks":[["change",3896.65,1.0e5]],"prev_change_id":15557285119}}}
{"jsonrpc":"2.0","method":"subscription","params":{"channel":"book.ETH-PERPETUAL.raw","data":{"timestamp":1734114598756,"type":"change","change_id":15557285121,"instrument_name":"ETH-PERPETUAL","bids":[["change",3881.7,1.0e5]],"asks":[],"prev_change_id":15557285120}}}
{"jsonrpc":"2.0","method":"subscription","params":{"channel":"book.ETH-PERPETUAL.raw","data":{"timestamp":1734114598756,"type":"change","change_id":15557285121,"instrument_name":"ETH-PERPETUAL","bids":[["change",3881.7,1.0e5]],"asks":[],"prev_change_id":15557285120}}}
{"jsonrpc":"2.0","method":"subscription","params":{"channel":"book.ETH-PERPETUAL.raw","data":{"timestamp":1734114598759,"type":"change","change_id":15557285122,"instrument_name":"ETH-PERPETUAL","bids":[],"asks":[["new",3896.75,8.0e4]],"prev_change_id":15557285121}}}
{"jsonrpc":"2.0","method":"subscription","params":{"channel":"book.ETH-PERPETUAL.raw","data":{"timestamp":1734114598759,"type":"change","change_id":15557285122,"instrument_name":"ETH-PERPETUAL","bids":[],"asks":[["new",3896.75,8.0e4]],"prev_change_id":15557285121}}}
{"jsonrpc":"2.0","method":"subscription","params":{"channel":"book.ETH-PERPETUAL.raw","data":{"timestamp":1734114598762,"type":"change","change_id":15557285123,"instrument_name":"ETH-PERPETUAL","bids":[["new",3881.8,8.0e4]],"asks":[],"prev_change_id":15557285122}}}
{"jsonrpc":"2.0","method":"subscription","params":{"channel":"book.ETH-PERPETUAL.raw","data":{"timestamp":1734114598762,"type":"change","change_id":15557285123,"instrument_name":"ETH-PERPETUAL","bids":[["new",3881.8,8.0e4]],"asks":[],"prev_change_id":15557285122}}}
{"jsonrpc":"2.0","method":"subscription","params":{"channel":"book.ETH-PERPETUAL.raw","data":{"timestamp":1734114598764,"type":"change","change_id":15557285124,"instrument_name":"ETH-PERPETUAL","bids":[],"asks":[["change",3896.75,1.0e5]],"prev_change_id":15557285123}}}
{"jsonrpc":"2.0","method":"subscription","params":{"channel":"book.ETH-PERPETUAL.raw","data":{"timestamp":1734114598764,"type":"change","change_id":15557285124,"instrument_name":"ETH-PERPETUAL","bids":[],"asks":[["change",3896.75,1.0e5]],"prev_change_id":15557285123}}}
{"jsonrpc":"2.0","method":"subscription","params":{"channel":"book.ETH-PERPETUAL.raw","data":{"timestamp":1734114598768,"type":"change","change_id":15557285125,"instrument_name":"ETH-PERPETUAL","bids":[["change",3881.8,1.0e5]],"asks":[],"prev_change_id":15557285124}}}
{"jsonrpc":"2.0","method":"subscription","params":{"channel":"book.ETH-PERPETUAL.raw","data":{"timestamp":1734114598768,"type":"change","change_id":15557285125,"instrument_name":"ETH-PERPETUAL","bids":[["change",3881.8,1.0e5]],"asks":[],"prev_change_id":15557285124}}}
{"jsonrpc":"2.0","method":"subscription","params":{"channel":"book.ETH-PERPETUAL.raw","data":{"timestamp":1734114598926,"type":"change","change_id":15557285126,"instrument_name":"ETH-PERPETUAL","bids":[["delete",3881.8,0.0],["delete",3881.7,0.0]],"asks":[["delete",3896.65,0.0],["delete",3896.75,0.0]],"prev_change_id":15557285125}}}
{"jsonrpc":"2.0","method":"subscription","params":{"channel":"book.ETH-PERPETUAL.raw","data":{"timestamp":1734114598926,"type":"change","change_id":15557285126,"instrument_name":"ETH-PERPETUAL","bids":[["delete",3881.8,0.0],["delete",3881.7,0.0]],"asks":[["delete",3896.65,0.0],["delete",3896.75,0.0]],"prev_change_id":15557285125}}}
{"jsonrpc":"2.0","method":"subscription","params":{"channel":"book.ETH-PERPETUAL.raw","data":{"timestamp":1734114599033,"type":"change","change_id":15557285135,"instrument_name":"ETH-PERPETUAL","bids":[["new",3881.8,3870.0],["delete",3881.35,0.0]],"asks":[],"prev_change_id":15557285126}}}
{"jsonrpc":"2.0","method":"subscription","params":{"channel":"book.ETH-PERPETUAL.raw","data":{"timestamp":1734114599033,"type":"change","change_id":15557285135,"instrument_name":"ETH-PERPETUAL","bids":[["new",3881.8,3870.0],["delete",3881.35,0.0]],"asks":[],"prev_change_id":15557285126}}}
{"jsonrpc":"2.0","method":"subscription","params":{"channel":"book.ETH-PERPETUAL.raw","data":{"timestamp":1734114599166,"type":"change","change_id":15557285164,"instrument_name":"ETH-PERPETUAL","bids":[],"asks":[["new",3896.85,8.0e4]],"prev_change_id":15557285135}}}
{"jsonrpc":"2.0","method":"subscription","params":{"channel":"book.ETH-PERPETUAL.raw","data":{"timestamp":1734114599166,"type":"change","change_id":15557285164,"instrument_name":"ETH-PERPETUAL","bids":[],"asks":[["new",3896.85,8.0e4]],"prev_change_id":15557285135}}}
{"jsonrpc":"2.0","method":"subscription","params":{"channel":"book.ETH-PERPETUAL.raw","data":{"timestamp":1734114599169,"type":"change","change_id":15557285165,"instrument_name":"ETH-PERPETUAL","bids":[["new",3881.85,8.0e4]],"asks":[],"prev_change_id":15557285164}}}
{"jsonrpc":"2.0","method":"subscription","params":{"channel":"book.ETH-PERPETUAL.raw","data":{"timestamp":1734114599169,"type":"change","change_id":15557285165,"instrument_name":"ETH-PERPETUAL","bids":[["new",3881.85,8.0e4]],"asks":[],"prev_change_id":15557285164}}}
{"jsonrpc":"2.0","method":"subscription","params":{"channel":"book.ETH-PERPETUAL.raw","data":{"timestamp":1734114599170,"type":"change","change_id":15557285166,"instrument_name":"ETH-PERPETUAL","bids":[],"asks":[["change",3896.85,1.0e5]],"prev_change_id":15557285165}}}
{"jsonrpc":"2.0","method":"subscription","params":{"channel":"book.ETH-PERPETUAL.raw","data":{"timestamp":1734114599170,"type":"change","change_id":15557285166,"instrument_name":"ETH-PERPETUAL","bids":[],"asks":[["change",3896.85,1.0e5]],"prev_change_id":15557285165}}}
{"jsonrpc":"2.0","method":"subscription","params":{"channel":"book.ETH-PERPETUAL.raw","data":{"timestamp":1734114599172,"type":"change","change_id":15557285167,"instrument_name":"ETH-PERPETUAL","bids":[["change",3881.85,1.0e5]],"asks":[],"prev_change_id":15557285166}}}
{"jsonrpc":"2.0","method":"subscription","params":{"channel":"book.ETH-PERPETUAL.raw","data":{"timestamp":1734114599172,"type":"change","change_id":15557285167,"instrument_name":"ETH-PERPETUAL","bids":[["change",3881.85,1.0e5]],"asks":[],"prev_change_id":15557285166}}}
{"jsonrpc":"2.0","method":"subscription","params":{"channel":"book.ETH-PERPETUAL.raw","data":{"timestamp":1734114599174,"type":"change","change_id":15557285168,"instrument_name":"ETH-PERPETUAL","bids":[],"asks":[["change",3896.85,1.8e5]],"prev_change_id":15557285167}}}
{"jsonrpc":"2.0","method":"subscription","params":{"channel":"book.ETH-PERPETUAL.raw","data":{"timestamp":1734114599174,"type":"change","change_id":15557285168,"instrument_name":"ETH-PERPETUAL","bids":[],"asks":[["change",3896.85,1.8e5]],"prev_change_id":15557285167}}}
{"jsonrpc":"2.0","method":"subscription","params":{"channel":"book.ETH-PERPETUAL.raw","data":{"timestamp":1734114599178,"type":"change","change_id":15557285169,"instrument_name":"ETH-PERPETUAL","bids":[["change",3881.85,1.8e5]],"asks":[],"prev_change_id":15557285168}}}
{"jsonrpc":"2.0","method":"subscription","params":{"channel":"book.ETH-PERPETUAL.raw","data":{"timestamp":1734114599178,"type":"change","change_id":15557285169,"instrument_name":"ETH-PERPETUAL","bids":[["change",3881.85,1.8e5]],"asks":[],"prev_change_id":15557285168}}}
{"jsonrpc":"2.0","method":"subscription","params":{"channel":"book.ETH-PERPETUAL.raw","data":{"timestamp":1734114599179,"type":"change","change_id":15557285170,"instrument_name":"ETH-PERPETUAL","bids":[],"asks":[["change",3896.85,2.0e5]],"prev_change_id":15557285169}}}
{"jsonrpc":"2.0","method":"subscription","params":{"channel":"book.ETH-PERPETUAL.raw","data":{"timestamp":1734114599179,"type":"change","change_id":15557285170,"instrument_name":"ETH-PERPETUAL","bids":[],"asks":[["change",3896.85,2.0e5]],"prev_change_id":15557285169}}}
{"jsonrpc":"2.0","method":"subscription","params":{"channel":"book.ETH-PERPETUAL.raw","data":{"timestamp":1734114599183,"type":"change","change_id":15557285171,"instrument_name":"ETH-PERPETUAL","bids":[["change",3881.85,2.0e5]],"asks":[],"prev_change_id":15557285170}}}
{"jsonrpc":"2.0","method":"subscription","params":{"channel":"book.ETH-PERPETUAL.raw","data":{"timestamp":1734114599183,"type":"change","change_id":15557285171,"instrument_name":"ETH-PERPETUAL","bids":[["change",3881.85,2.0e5]],"asks":[],"prev_change_id":15557285170}}}
{"jsonrpc":"2.0","method":"subscription","params":{"channel":"book.ETH-PERPETUAL.raw","data":{"timestamp":1734114599316,"type":"change","change_id":15557285173,"instrument_name":"ETH-PERPETUAL","bids":[["delete",3881.85,0.0]],"asks":[["delete",3896.85,0.0]],"prev_change_id":15557285171}}}
{"jsonrpc":"2.0","method":"subscription","params":{"channel":"book.ETH-PERPETUAL.raw","data":{"timestamp":1734114599316,"type":"change","change_id":15557285173,"instrument_name":"ETH-PERPETUAL","bids":[["delete",3881.85,0.0]],"asks":[["delete",3896.85,0.0]],"prev_change_id":15557285171}}}
{"jsonrpc":"2.0","method":"subscription","params":{"channel":"book.ETH-PERPETUAL.raw","data":{"timestamp":1734114599516,"type":"change","change_id":15557285174,"instrument_name":"ETH-PERPETUAL","bids":[],"asks":[["new",3896.8,8.0e4]],"prev_change_id":15557285173}}}
{"jsonrpc":"2.0","method":"subscription","params":{"channel":"book.ETH-PERPETUAL.raw","data":{"timestamp":1734114599516,"type":"change","change_id":15557285174,"instrument_name":"ETH-PERPETUAL","bids":[],"asks":[["new",3896.8,8.0e4]],"prev_change_id":15557285173}}}
{"jsonrpc":"2.0","method":"subscription","params":{"channel":"book.ETH-PERPETUAL.raw","data":{"timestamp":1734114599518,"type":"change","change_id":15557285175,"instrument_name":"ETH-PERPETUAL","bids":[["new",3881.85,8.0e4]],"asks":[],"prev_change_id":15557285174}}}
{"jsonrpc":"2.0","method":"subscription","params":{"channel":"book.ETH-PERPETUAL.raw","data":{"timestamp":1734114599518,"type":"change","change_id":15557285175,"instrument_name":"ETH-PERPETUAL","bids":[["new",3881.85,8.0e4]],"asks":[],"prev_change_id":15557285174}}}
{"jsonrpc":"2.0","method":"subscription","params":{"channel":"book.ETH-PERPETUAL.raw","data":{"timestamp":1734114599519,"type":"change","change_id":15557285176,"instrument_name":"ETH-PERPETUAL","bids":[],"asks":[["change",3896.8,1.0e5]],"prev_change_id":15557285175}}}
{"jsonrpc":"2.0","method":"subscription","params":{"channel":"book.ETH-PERPETUAL.raw","data":{"timestamp":1734114599519,"type":"change","change_id":15557285176,"instrument_name":"ETH-PERPETUAL","bids":[],"asks":[["change",3896.8,1.0e5]],"prev_change_id":15557285175}}}
{"jsonrpc":"2.0","method":"subscription","params":{"channel":"book.ETH-PERPETUAL.raw","data":{"timestamp":1734114599520,"type":"change","change_id":15557285177,"instrument_name":"ETH-PERPETUAL","bids":[["change",3881.85,1.0e5]],"asks":[],"prev_change_id":15557285176}}}
{"jsonrpc":"2.0","method":"subscription","params":{"channel":"book.ETH-PERPETUAL.raw","data":{"timestamp":1734114599520,"type":"change","change_id":15557285177,"instrument_name":"ETH-PERPETUAL","bids":[["change",3881.85,1.0e5]],"asks":[],"prev_change_id":15557285176}}}
{"jsonrpc":"2.0","method":"subscription","params":{"channel":"book.ETH-PERPETUAL.raw","data":{"timestamp":1734114599522,"type":"change","change_id":15557285178,"instrument_name":"ETH-PERPETUAL","bids":[],"asks":[["change",3896.8,1.8e5]],"prev_change_id":15557285177}}}
{"jsonrpc":"2.0","method":"subscription","params":{"channel":"book.ETH-PERPETUAL.raw","data":{"timestamp":1734114599522,"type":"change","change_id":15557285178,"instrument_name":"ETH-PERPETUAL","bids":[],"asks":[["change",3896.8,1.8e5]],"prev_change_id":15557285177}}}
{"jsonrpc":"2.0","method":"subscription","params":{"channel":"book.ETH-PERPETUAL.raw","data":{"timestamp":1734114599523,"type":"change","change_id":15557285179,"instrument_name":"ETH-PERPETUAL","bids":[["change",3881.85,1.8e5]],"asks":[],"prev_change_id":15557285178}}}
{"jsonrpc":"2.0","method":"subscription","params":{"channel":"book.ETH-PERPETUAL.raw","data":{"timestamp":1734114599523,"type":"change","change_id":15557285179,"instrument_name":"ETH-PERPETUAL","bids":[["change",3881.85,1.8e5]],"asks":[],"prev_change_id":15557285178}}}
{"jsonrpc":"2.0","method":"subscription","params":{"channel":"book.ETH-PERPETUAL.raw","data":{"timestamp":1734114599525,"type":"change","change_id":15557285180,"instrument_name":"ETH-PERPETUAL","bids":[],"asks":[["change",3896.8,2.0e5]],"prev_change_id":15557285179}}}
{"jsonrpc":"2.0","method":"subscription","params":{"channel":"book.ETH-PERPETUAL.raw","data":{"timestamp":1734114599525,"type":"change","change_id":15557285180,"instrument_name":"ETH-PERPETUAL","bids":[],"asks":[["change",3896.8,2.0e5]],"prev_change_id":15557285179}}}
{"jsonrpc":"2.0","method":"subscription","params":{"channel":"book.ETH-PERPETUAL.raw","data":{"timestamp":1734114599526,"type":"change","change_id":15557285181,"instrument_name":"ETH-PERPETUAL","bids":[["change",3881.85,2.0e5]],"asks":[],"prev_change_id":15557285180}}}
{"jsonrpc":"2.0","method":"subscription","params":{"channel":"book.ETH-PERPETUAL.raw","data":{"timestamp":1734114599526,"type":"change","change_id":15557285181,"instrument_name":"ETH-PERPETUAL","bids":[["change",3881.85,2.0e5]],"asks":[],"prev_change_id":15557285180}}}
{"jsonrpc":"2.0","method":"subscription","params":{"channel":"book.ETH-PERPETUAL.raw","data":{"timestamp":1734114599626,"type":"change","change_id":15557285182,"instrument_name":"ETH-PERPETUAL","bids":[["delete",3881.85,0.0]],"asks":[["delete",3896.8,0.0]],"prev_change_id":15557285181}}}
{"jsonrpc":"2.0","method":"subscription","params":{"channel":"book.ETH-PERPETUAL.raw","data":{"timestamp":1734114599626,"type":"change","change_id":15557285182,"instrument_name":"ETH-PERPETUAL","bids":[["delete",3881.85,0.0]],"asks":[["delete",3896.8,0.0]],"prev_change_id":15557285181}}}
{"jsonrpc":"2.0","method":"subscription","params":{"channel":"book.ETH-PERPETUAL.raw","data":{"timestamp":1734114599770,"type":"change","change_id":15557285185,"instrument_name":"ETH-PERPETUAL","bids":[],"asks":[["delete",3908.25,0.0],["new",3920.0,500.0]],"prev_change_id":15557285182}}}
{"jsonrpc":"2.0","method":"subscription","params":{"channel":"book.ETH-PERPETUAL.raw","data":{"timestamp":1734114599770,"type":"change","change_id":15557285185,"instrument_name":"ETH-PERPETUAL","bids":[],"asks":[["delete",3908.25,0.0],["new",3920.0,500.0]],"prev_change_id":15557285182}}}
{"jsonrpc":"2.0","method":"subscription","params":{"channel":"book.ETH-PERPETUAL.raw","data":{"timestamp":1734114599812,"type":"change","change_id":15557285186,"instrument_name":"ETH-PERPETUAL","bids":[],"asks":[["new",3896.8,8.0e4]],"prev_change_id":15557285185}}}
{"jsonrpc":"2.0","method":"subscription","params":{"channel":"book.ETH-PERPETUAL.raw","data":{"timestamp":1734114599812,"type":"change","change_id":15557285186,"instrument_name":"ETH-PERPETUAL","bids":[],"asks":[["new",3896.8,8.0e4]],"prev_change_id":15557285185}}}
{"jsonrpc":"2.0","method":"subscription","params":{"channel":"book.ETH-PERPETUAL.raw","data":{"timestamp":1734114599814,"type":"change","change_id":15557285187,"instrument_name":"ETH-PERPETUAL","bids":[["new",3881.85,8.0e4]],"asks":[],"prev_change_id":15557285186}}}
{"jsonrpc":"2.0","method":"subscription","params":{"channel":"book.ETH-PERPETUAL.raw","data":{"timestamp":1734114599814,"type":"change","change_id":15557285187,"instrument_name":"ETH-PERPETUAL","bids":[["new",3881.85,8.0e4]],"asks":[],"prev_change_id":15557285186}}}
{"jsonrpc":"2.0","method":"subscription","params":{"channel":"book.ETH-PERPETUAL.raw","data":{"timestamp":1734114599814,"type":"change","change_id":15557285188,"instrument_name":"ETH-PERPETUAL","bids":[],"asks":[["change",3896.8,1.0e5]],"prev_change_id":15557285187}}}
{"jsonrpc":"2.0","method":"subscription","params":{"channel":"book.ETH-PERPETUAL.raw","data":{"timestamp":1734114599814,"type":"change","change_id":15557285188,"instrument_name":"ETH-PERPETUAL","bids":[],"asks":[["change",3896.8,1.0e5]],"prev_change_id":15557285187}}}
{"jsonrpc":"2.0","method":"subscription","params":{"channel":"book.ETH-PERPETUAL.raw","data":{"timestamp":1734114599816,"type":"change","change_id":15557285189,"instrument_name":"ETH-PERPETUAL","bids":[["change",3881.85,1.0e5]],"asks":[],"prev_change_id":15557285188}}}
{"jsonrpc":"2.0","method":"subscription","params":{"channel":"book.ETH-PERPETUAL.raw","data":{"timestamp":1734114599816,"type":"change","change_id":15557285189,"instrument_name":"ETH-PERPETUAL","bids":[["change",3881.85,1.0e5]],"asks":[],"prev_change_id":15557285188}}}
{"jsonrpc":"2.0","method":"subscription","params":{"channel":"book.ETH-PERPETUAL.raw","data":{"timestamp":1734114599818,"type":"change","change_id":15557285190,"instrument_name":"ETH-PERPETUAL","bids":[],"asks":[["change",3896.8,1.8e5]],"prev_change_id":15557285189}}}
{"jsonrpc":"2.0","method":"subscription","params":{"channel":"book.ETH-PERPETUAL.raw","data":{"timestamp":1734114599818,"type":"change","change_id":15557285190,"instrument_name":"ETH-PERPETUAL","bids":[],"asks":[["change",3896.8,1.8e5]],"prev_change_id":15557285189}}}
{"jsonrpc":"2.0","method":"subscription","params":{"channel":"book.ETH-PERPETUAL.raw","data":{"timestamp":1734114599819,"type":"change","change_id":15557285191,"instrument_name":"ETH-PERPETUAL","bids":[["change",3881.85,1.8e5]],"asks":[],"prev_change_id":15557285190}}}
{"jsonrpc":"2.0","method":"subscription","params":{"channel":"book.ETH-PERPETUAL.raw","data":{"timestamp":1734114599819,"type":"change","change_id":15557285191,"instrument_name":"ETH-PERPETUAL","bids":[["change",3881.85,1.8e5]],"asks":[],"prev_change_id":15557285190}}}
{"jsonrpc":"2.0","method":"subscription","params":{"channel":"book.ETH-PERPETUAL.raw","data":{"timestamp":1734114599820,"type":"change","change_id":15557285192,"instrument_name":"ETH-PERPETUAL","bids":[],"asks":[["change",3896.8,2.0e5]],"prev_change_id":15557285191}}}
{"jsonrpc":"2.0","method":"subscription","params":{"channel":"book.ETH-PERPETUAL.raw","data":{"timestamp":1734114599820,"type":"change","change_id":15557285192,"instrument_name":"ETH-PERPETUAL","bids":[],"asks":[["change",3896.8,2.0e5]],"prev_change_id":15557285191}}}
{"jsonrpc":"2.0","method":"subscription","params":{"channel":"book.ETH-PERPETUAL.raw","data":{"timestamp":1734114599821,"type":"change","change_id":15557285193,"instrument_name":"ETH-PERPETUAL","bids":[["change",3881.85,2.0e5]],"asks":[],"prev_change_id":15557285192}}}
{"jsonrpc":"2.0","method":"subscription","params":{"channel":"book.ETH-PERPETUAL.raw","data":{"timestamp":1734114599821,"type":"change","change_id":15557285193,"instrument_name":"ETH-PERPETUAL","bids":[["change",3881.85,2.0e5]],"asks":[],"prev_change_id":15557285192}}}
{"jsonrpc":"2.0","method":"subscription","params":{"channel":"book.ETH-PERPETUAL.raw","data":{"timestamp":1734114599901,"type":"change","change_id":15557285194,"instrument_name":"ETH-PERPETUAL","bids":[["delete",3881.85,0.0]],"asks":[["delete",3896.8,0.0]],"prev_change_id":15557285193}}}
{"jsonrpc":"2.0","method":"subscription","params":{"channel":"book.ETH-PERPETUAL.raw","data":{"timestamp":1734114599901,"type":"change","change_id":15557285194,"instrument_name":"ETH-PERPETUAL","bids":[["delete",3881.85,0.0]],"asks":[["delete",3896.8,0.0]],"prev_change_id":15557285193}}}
{"jsonrpc":"2.0","method":"subscription","params":{"channel":"book.ETH-PERPETUAL.raw","data":{"timestamp":1734114599958,"type":"change","change_id":15557285196,"instrument_name":"ETH-PERPETUAL","bids":[],"asks":[["new",3916.3,500.0],["delete",3927.8,0.0]],"prev_change_id":15557285194}}}
{"jsonrpc":"2.0","method":"subscription","params":{"channel":"book.ETH-PERPETUAL.raw","data":{"timestamp":1734114599958,"type":"change","change_id":15557285196,"instrument_name":"ETH-PERPETUAL","bids":[],"asks":[["new",3916.3,500.0],["delete",3927.8,0.0]],"prev_change_id":15557285194}}}
{"jsonrpc":"2.0","method":"subscription","params":{"channel":"book.ETH-PERPETUAL.raw","data":{"timestamp":1734114600171,"type":"change","change_id":15557285214,"instrument_name":"ETH-PERPETUAL","bids":[],"asks":[["new",3896.8,8.0e4]],"prev_change_id":15557285196}}}
{"jsonrpc":"2.0","method":"subscription","params":{"channel":"book.ETH-PERPETUAL.raw","data":{"timestamp":1734114600171,"type":"change","change_id":15557285214,"instrument_name":"ETH-PERPETUAL","bids":[],"asks":[["new",3896.8,8.0e4]],"prev_change_id":15557285196}}}
{"jsonrpc":"2.0","method":"subscription","params":{"channel":"book.ETH-PERPETUAL.raw","data":{"timestamp":1734114600174,"type":"change","change_id":15557285215,"instrument_name":"ETH-PERPETUAL","bids":[["new",3881.85,8.0e4]],"asks":[],"prev_change_id":15557285214}}}
{"jsonrpc":"2.0","method":"subscription","params":{"channel":"book.ETH-PERPETUAL.raw","data":{"timestamp":1734114600174,"type":"change","change_id":15557285215,"instrument_name":"ETH-PERPETUAL","bids":[["new",3881.85,8.0e4]],"asks":[],"prev_change_id":15557285214}}}
{"jsonrpc":"2.0","method":"subscription","params":{"channel":"book.ETH-PERPETUAL.raw","data":{"timestamp":1734114600179,"type":"change","change_id":15557285216,"instrument_name":"ETH-PERPETUAL","bids":[],"asks":[["change",3896.8,1.0e5]],"prev_change_id":15557285215}}}
{"jsonrpc":"2.0","method":"subscription","params":{"channel":"book.ETH-PERPETUAL.raw","data":{"timestamp":1734114600179,"type":"change","change_id":15557285216,"instrument_name":"ETH-PERPETUAL","bids":[],"asks":[["change",3896.8,1.0e5]],"prev_change_id":15557285215}}}
{"jsonrpc":"2.0","method":"subscription","params":{"channel":"book.ETH-PERPETUAL.raw","data":{"timestamp":1734114600184,"type":"change","change_id":15557285217,"instrument_name":"ETH-PERPETUAL","bids":[],"asks":[["change",3896.8,1.8e5]],"prev_change_id":15557285216}}}
{"jsonrpc":"2.0","method":"subscription","params":{"channel":"book.ETH-PERPETUAL.raw","data":{"timestamp":1734114600184,"type":"change","change_id":15557285217,"instrument_name":"ETH-PERPETUAL","bids":[],"asks":[["change",3896.8,1.8e5]],"prev_change_id":15557285216}}}
{"jsonrpc":"2.0","method":"subscription","params":{"channel":"book.ETH-PERPETUAL.raw","data":{"timestamp":1734114600185,"type":"change","change_id":15557285218,"instrument_name":"ETH-PERPETUAL","bids":[["change",3881.85,1.6e5]],"asks":[],"prev_change_id":15557285217}}}
{"jsonrpc":"2.0","method":"subscription","params":{"channel":"book.ETH-PERPETUAL.raw","data":{"timestamp":1734114600185,"type":"change","change_id":15557285218,"instrument_name":"ETH-PERPETUAL","bids":[["change",3881.85,1.6e5]],"asks":[],"prev_change_id":15557285217}}}
{"jsonrpc":"2.0","method":"subscription","params":{"channel":"book.ETH-PERPETUAL.raw","data":{"timestamp":1734114600186,"type":"change","change_id":15557285219,"instrument_name":"ETH-PERPETUAL","bids":[],"asks":[["change",3896.8,2.0e5]],"prev_change_id":15557285218}}}
{"jsonrpc":"2.0","method":"subscription","params":{"channel":"book.ETH-PERPETUAL.raw","data":{"timestamp":1734114600186,"type":"change","change_id":15557285219,"instrument_name":"ETH-PERPETUAL","bids":[],"asks":[["change",3896.8,2.0e5]],"prev_change_id":15557285218}}}
{"jsonrpc":"2.0","method":"subscription","params":{"channel":"book.ETH-PERPETUAL.raw","data":{"timestamp":1734114600188,"type":"change","change_id":15557285220,"instrument_name":"ETH-PERPETUAL","bids":[["change",3881.85,1.8e5]],"asks":[],"prev_change_id":15557285219}}}
{"jsonrpc":"2.0","method":"subscription","params":{"channel":"book.ETH-PERPETUAL.raw","data":{"timestamp":1734114600188,"type":"change","change_id":15557285220,"instrument_name":"ETH-PERPETUAL","bids":[["change",3881.85,1.8e5]],"asks":[],"prev_change_id":15557285219}}}
{"jsonrpc":"2.0","method":"subscription","params":{"channel":"book.ETH-PERPETUAL.raw","data":{"timestamp":1734114600271,"type":"change","change_id":15557285222,"instrument_name":"ETH-PERPETUAL","bids":[["delete",3881.85,0.0]],"asks":[["delete",3896.8,0.0]],"prev_change_id":15557285220}}}
{"jsonrpc":"2.0","method":"subscription","params":{"channel":"book.ETH-PERPETUAL.raw","data":{"timestamp":1734114600271,"type":"change","change_id":15557285222,"instrument_name":"ETH-PERPETUAL","bids":[["delete",3881.85,0.0]],"asks":[["delete",3896.8,0.0]],"prev_change_id":15557285220}}}
{"jsonrpc":"2.0","method":"subscription","params":{"channel":"book.ETH-PERPETUAL.raw","data":{"timestamp":1734114600478,"type":"change","change_id":15557285224,"instrument_name":"ETH-PERPETUAL","bids":[],"asks":[["new",3896.8,8.0e4]],"prev_change_id":15557285222}}}
{"jsonrpc":"2.0","method":"subscription","params":{"channel":"book.ETH-PERPETUAL.raw","data":{"timestamp":1734114600478,"type":"change","change_id":15557285224,"instrument_name":"ETH-PERPETUAL","bids":[],"asks":[["new",3896.8,8.0e4]],"prev_change_id":15557285222}}}
{"jsonrpc":"2.0","method":"subscription","params":{"channel":"book.ETH-PERPETUAL.raw","data":{"timestamp":1734114600481,"type":"change","change_id":15557285225,"instrument_name":"ETH-PERPETUAL","bids":[["new",3881.85,8.0e4]],"asks":[],"prev_change_id":15557285224}}}
{"jsonrpc":"2.0","method":"subscription","params":{"channel":"book.ETH-PERPETUAL.raw","data":{"timestamp":1734114600481,"type":"change","change_id":15557285225,"instrument_name":"ETH-PERPETUAL","bids":[["new",3881.85,8.0e4]],"asks":[],"prev_change_id":15557285224}}}
{"jsonrpc":"2.0","method":"subscription","params":{"channel":"book.ETH-PERPETUAL.raw","data":{"timestamp":1734114600482,"type":"change","change_id":15557285226,"instrument_name":"ETH-PERPETUAL","bids":[],"asks":[["change",3896.8,1.0e5]],"prev_change_id":15557285225}}}
{"jsonrpc":"2.0","method":"subscription","params":{"channel":"book.ETH-PERPETUAL.raw","data":{"timestamp":1734114600482,"type":"change","change_id":15557285226,"instrument_name":"ETH-PERPETUAL","bids":[],"asks":[["change",3896.8,1.0e5]],"prev_change_id":15557285225}}}
{"jsonrpc":"2.0","method":"subscription","params":{"channel":"book.ETH-PERPETUAL.raw","data":{"timestamp":1734114600486,"type":"change","change_id":15557285227,"instrument_name":"ETH-PERPETUAL","bids":[],"asks":[["new",3896.85,8.0e4]],"prev_change_id":15557285226}}}
{"jsonrpc":"2.0","method":"subscription","params":{"channel":"book.ETH-PERPETUAL.raw","data":{"timestamp":1734114600486,"type":"change","change_id":15557285227,"instrument_name":"ETH-PERPETUAL","bids":[],"asks":[["new",3896.85,8.0e4]],"prev_change_id":15557285226}}}
{"jsonrpc":"2.0","method":"subscription","params":{"channel":"book.ETH-PERPETUAL.raw","data":{"timestamp":1734114600489,"type":"change","change_id":15557285228,"instrument_name":"ETH-PERPETUAL","bids":[["change",3881.85,1.6e5]],"asks":[],"prev_change_id":15557285227}}}
{"jsonrpc":"2.0","method":"subscription","params":{"channel":"book.ETH-PERPETUAL.raw","data":{"timestamp":1734114600489,"type":"change","change_id":15557285228,"instrument_name":"ETH-PERPETUAL","bids":[["change",3881.85,1.6e5]],"asks":[],"prev_change_id":15557285227}}}
{"jsonrpc":"2.0","method":"subscription","params":{"channel":"book.ETH-PERPETUAL.raw","data":{"timestamp":1734114600494,"type":"change","change_id":15557285229,"instrument_name":"ETH-PERPETUAL","bids":[],"asks":[["change",3896.85,1.0e5]],"prev_change_id":15557285228}}}
{"jsonrpc":"2.0","method":"subscription","params":{"channel":"book.ETH-PERPETUAL.raw","data":{"timestamp":1734114600494,"type":"change","change_id":15557285229,"instrument_name":"ETH-PERPETUAL","bids":[],"asks":[["change",3896.85,1.0e5]],"prev_change_id":15557285228}}}
{"jsonrpc":"2.0","method":"subscription","params":{"channel":"book.ETH-PERPETUAL.raw","data":{"timestamp":1734114600609,"type":"change","change_id":15557285231,"instrument_name":"ETH-PERPETUAL","bids":[["delete",3881.85,0.0]],"asks":[["delete",3896.8,0.0],["delete",3896.85,0.0]],"prev_change_id":15557285229}}}
{"jsonrpc":"2.0","method":"subscription","params":{"channel":"book.ETH-PERPETUAL.raw","data":{"timestamp":1734114600609,"type":"change","change_id":15557285231,"instrument_name":"ETH-PERPETUAL","bids":[["delete",3881.85,0.0]],"asks":[["delete",3896.8,0.0],["delete",3896.85,0.0]],"prev_change_id":15557285229}}}
{"jsonrpc":"2.0","method":"subscription","params":{"channel":"book.ETH-PERPETUAL.raw","data":{"timestamp":1734114600824,"type":"change","change_id":15557285243,"instrument_name":"ETH-PERPETUAL","bids":[],"asks":[["new",3896.85,8.0e4]],"prev_change_id":15557285231}}}
{"jsonrpc":"2.0","method":"subscription","params":{"channel":"book.ETH-PERPETUAL.raw","data":{"timestamp":1734114600824,"type":"change","change_id":15557285243,"instrument_name":"ETH-PERPETUAL","bids":[],"asks":[["new",3896.85,8.0e4]],"prev_change_id":15557285231}}}
{"jsonrpc":"2.0","method":"subscription","params":{"channel":"book.ETH-PERPETUAL.raw","data":{"timestamp":1734114600826,"type":"change","change_id":15557285245,"instrument_name":"ETH-PERPETUAL","bids":[["new",3881.9,8.0e4]],"asks":[],"prev_change_id":15557285243}}}
{"jsonrpc":"2.0","method":"subscription","params":{"channel":"book.ETH-PERPETUAL.raw","data":{"timestamp":1734114600826,"type":"change","change_id":15557285245,"instrument_name":"ETH-PERPETUAL","bids":[["new",3881.9,8.0e4]],"asks":[],"prev_change_id":15557285243}}}
{"jsonrpc":"2.0","method":"subscription","params":{"channel":"book.ETH-PERPETUAL.raw","data":{"timestamp":1734114600827,"type":"change","change_id":15557285247,"instrument_name":"ETH-PERPETUAL","bids":[],"asks":[["change",3896.85,1.0e5]],"prev_change_id":15557285245}}}
{"jsonrpc":"2.0","method":"subscription","params":{"channel":"book.ETH-PERPETUAL.raw","data":{"timestamp":1734114600827,"type":"change","change_id":15557285247,"instrument_name":"ETH-PERPETUAL","bids":[],"asks":[["change",3896.85,1.0e5]],"prev_change_id":15557285245}}}
{"jsonrpc":"2.0","method":"subscription","params":{"channel":"book.ETH-PERPETUAL.raw","data":{"timestamp":1734114600829,"type":"change","change_id":15557285250,"instrument_name":"ETH-PERPETUAL","bids":[["change",3881.9,1.0e5]],"asks":[],"prev_change_id":15557285247}}}
{"jsonrpc":"2.0","method":"subscription","params":{"channel":"book.ETH-PERPETUAL.raw","data":{"timestamp":1734114600829,"type":"change","change_id":15557285250,"instrument_name":"ETH-PERPETUAL","bids":[["change",3881.9,1.0e5]],"asks":[],"prev_change_id":15557285247}}}
{"jsonrpc":"2.0","method":"subscription","params":{"channel":"book.ETH-PERPETUAL.raw","data":{"timestamp":1734114600831,"type":"change","change_id":15557285251,"instrument_name":"ETH-PERPETUAL","bids":[],"asks":[["change",3896.85,1.8e5]],"prev_change_id":15557285250}}}
{"jsonrpc":"2.0","method":"subscription","params":{"channel":"book.ETH-PERPETUAL.raw","data":{"timestamp":1734114600831,"type":"change","change_id":15557285251,"instrument_name":"ETH-PERPETUAL","bids":[],"asks":[["change",3896.85,1.8e5]],"prev_change_id":15557285250}}}
{"jsonrpc":"2.0","method":"subscription","params":{"channel":"book.ETH-PERPETUAL.raw","data":{"timestamp":1734114600832,"type":"change","change_id":15557285252,"instrument_name":"ETH-PERPETUAL","bids":[["change",3881.9,1.8e5]],"asks":[],"prev_change_id":15557285251}}}
{"jsonrpc":"2.0","method":"subscription","params":{"channel":"book.ETH-PERPETUAL.raw","data":{"timestamp":1734114600832,"type":"change","change_id":15557285252,"instrument_name":"ETH-PERPETUAL","bids":[["change",3881.9,1.8e5]],"asks":[],"prev_change_id":15557285251}}}
{"jsonrpc":"2.0","method":"subscription","params":{"channel":"book.ETH-PERPETUAL.raw","data":{"timestamp":1734114600834,"type":"change","change_id":15557285253,"instrument_name":"ETH-PERPETUAL","bids":[],"asks":[["change",3896.85,2.0e5]],"prev_change_id":15557285252}}}
{"jsonrpc":"2.0","method":"subscription","params":{"channel":"book.ETH-PERPETUAL.raw","data":{"timestamp":1734114600834,"type":"change","change_id":15557285253,"instrument_name":"ETH-PERPETUAL","bids":[],"asks":[["change",3896.85,2.0e5]],"prev_change_id":15557285252}}}
{"jsonrpc":"2.0","method":"subscription","params":{"channel":"book.ETH-PERPETUAL.raw","data":{"timestamp":1734114600840,"type":"change","change_id":15557285254,"instrument_name":"ETH-PERPETUAL","bids":[["change",3881.9,2.0e5]],"asks":[],"prev_change_id":15557285253}}}
{"jsonrpc":"2.0","method":"subscription","params":{"channel":"book.ETH-PERPETUAL.raw","data":{"timestamp":1734114600840,"type":"change","change_id":15557285254,"instrument_name":"ETH-PERPETUAL","bids":[["change",3881.9,2.0e5]],"asks":[],"prev_change_id":15557285253}}}
{"jsonrpc":"2.0","method":"subscription","params":{"channel":"book.ETH-PERPETUAL.raw","data":{"timestamp":1734114600926,"type":"change","change_id":15557285255,"instrument_name":"ETH-PERPETUAL","bids":[["delete",3881.9,0.0]],"asks":[["delete",3896.85,0.0]],"prev_change_id":15557285254}}}
{"jsonrpc":"2.0","method":"subscription","params":{"channel":"book.ETH-PERPETUAL.raw","data":{"timestamp":1734114600926,"type":"change","change_id":15557285255,"instrument_name":"ETH-PERPETUAL","bids":[["delete",3881.9,0.0]],"asks":[["delete",3896.85,0.0]],"prev_change_id":15557285254}}}
{"jsonrpc":"2.0","method":"subscription","params":{"channel":"book.ETH-PERPETUAL.raw","data":{"timestamp":1734114601238,"type":"change","change_id":15557285286,"instrument_name":"ETH-PERPETUAL","bids":[],"asks":[["new",3896.9,8.0e4]],"prev_change_id":15557285255}}}
{"jsonrpc":"2.0","method":"subscription","params":{"channel":"book.ETH-PERPETUAL.raw","data":{"timestamp":1734114601238,"type":"change","change_id":15557285286,"instrument_name":"ETH-PERPETUAL","bids":[],"asks":[["new",3896.9,8.0e4]],"prev_change_id":15557285255}}}
{"jsonrpc":"2.0","method":"subscription","params":{"channel":"book.ETH-PERPETUAL.raw","data":{"timestamp":1734114601241,"type":"change","change_id":15557285287,"instrument_name":"ETH-PERPETUAL","bids":[["new",3881.9,8.0e4]],"asks":[],"prev_change_id":15557285286}}}
{"jsonrpc":"2.0","method":"subscription","params":{"channel":"book.ETH-PERPETUAL.raw","data":{"timestamp":1734114601241,"type":"change","change_id":15557285287,"instrument_name":"ETH-PERPETUAL","bids":[["new",3881.9,8.0e4]],"asks":[],"prev_change_id":15557285286}}}
{"jsonrpc":"2.0","method":"subscription","params":{"channel":"book.ETH-PERPETUAL.raw","data":{"timestamp":1734114601244,"type":"change","change_id":15557285288,"instrument_name":"ETH-PERPETUAL","bids":[],"asks":[["change",3896.9,1.0e5]],"prev_change_id":15557285287}}}
{"jsonrpc":"2.0","method":"subscription","params":{"channel":"book.ETH-PERPETUAL.raw","data":{"timestamp":1734114601244,"type":"change","change_id":15557285288,"instrument_name":"ETH-PERPETUAL","bids":[],"asks":[["change",3896.9,1.0e5]],"prev_change_id":15557285287}}}
{"jsonrpc":"2.0","method":"subscription","params":{"channel":"book.ETH-PERPETUAL.raw","data":{"timestamp":1734114601248,"type":"change","change_id":15557285289,"instrument_name":"ETH-PERPETUAL","bids":[["change",3881.9,1.0e5]],"asks":[],"prev_change_id":15557285288}}}
{"jsonrpc":"2.0","method":"subscription","params":{"channel":"book.ETH-PERPETUAL.raw","data":{"timestamp":1734114601248,"type":"change","change_id":15557285289,"instrument_name":"ETH-PERPETUAL","bids":[["change",3881.9,1.0e5]],"asks":[],"prev_change_id":15557285288}}}
{"jsonrpc":"2.0","method":"subscription","params":{"channel":"book.ETH-PERPETUAL.raw","data":{"timestamp":1734114601252,"type":"change","change_id":15557285290,"instrument_name":"ETH-PERPETUAL","bids":[],"asks":[["new",3896.85,8.0e4]],"prev_change_id":15557285289}}}
{"jsonrpc":"2.0","method":"subscription","params":{"channel":"book.ETH-PERPETUAL.raw","data":{"timestamp":1734114601252,"type":"change","change_id":15557285290,"instrument_name":"ETH-PERPETUAL","bids":[],"asks":[["new",3896.85,8.0e4]],"prev_change_id":15557285289}}}
{"jsonrpc":"2.0","method":"subscription","params":{"channel":"book.ETH-PERPETUAL.raw","data":{"timestamp":1734114601255,"type":"change","change_id":15557285291,"instrument_name":"ETH-PERPETUAL","bids":[["new",3881.85,8.0e4]],"asks":[],"prev_change_id":15557285290}}}
{"jsonrpc":"2.0","method":"subscription","params":{"channel":"book.ETH-PERPETUAL.raw","data":{"timestamp":1734114601255,"type":"change","change_id":15557285291,"instrument_name":"ETH-PERPETUAL","bids":[["new",3881.85,8.0e4]],"asks":[],"prev_change_id":15557285290}}}
{"jsonrpc":"2.0","method":"subscription","params":{"channel":"book.ETH-PERPETUAL.raw","data":{"timestamp":1734114601258,"type":"change","change_id":15557285292,"instrument_name":"ETH-PERPETUAL","bids":[],"asks":[["change",3896.85,1.0e5]],"prev_change_id":15557285291}}}
{"jsonrpc":"2.0","method":"subscription","params":{"channel":"book.ETH-PERPETUAL.raw","data":{"timestamp":1734114601258,"type":"change","change_id":15557285292,"instrument_name":"ETH-PERPETUAL","bids":[],"asks":[["change",3896.85,1.0e5]],"prev_change_id":15557285291}}}
{"jsonrpc":"2.0","method":"subscription","params":{"channel":"book.ETH-PERPETUAL.raw","data":{"timestamp":1734114601262,"type":"change","change_id":15557285293,"instrument_name":"ETH-PERPETUAL","bids":[["change",3881.85,1.0e5]],"asks":[],"prev_change_id":15557285292}}}
{"jsonrpc":"2.0","method":"subscription","params":{"channel":"book.ETH-PERPETUAL.raw","data":{"timestamp":1734114601262,"type":"change","change_id":15557285293,"instrument_name":"ETH-PERPETUAL","bids":[["change",3881.85,1.0e5]],"asks":[],"prev_change_id":15557285292}}}
{"jsonrpc":"2.0","method":"subscription","params":{"channel":"book.ETH-PERPETUAL.raw","data":{"timestamp":1734114601403,"type":"change","change_id":15557285294,"instrument_name":"ETH-PERPETUAL","bids":[["delete",3881.9,0.0],["delete",3881.85,0.0]],"asks":[["delete",3896.85,0.0],["delete",3896.9,0.0]],"prev_change_id":15557285293}}}
{"jsonrpc":"2.0","method":"subscription","params":{"channel":"book.ETH-PERPETUAL.raw","data":{"timestamp":1734114601403,"type":"change","change_id":15557285294,"instrument_name":"ETH-PERPETUAL","bids":[["delete",3881.9,0.0],["delete",3881.85,0.0]],"asks":[["delete",3896.85,0.0],["delete",3896.9,0.0]],"prev_change_id":15557285293}}}
{"jsonrpc":"2.0","method":"subscription","params":{"channel":"book.ETH-PERPETUAL.raw","data":{"timestamp":1734114601771,"type":"change","change_id":15557285295,"instrument_name":"ETH-PERPETUAL","bids":[],"asks":[["new",3896.7,8.0e4]],"prev_change_id":15557285294}}}
{"jsonrpc":"2.0","method":"subscription","params":{"channel":"book.ETH-PERPETUAL.raw","data":{"timestamp":1734114601771,"type":"change","change_id":15557285295,"instrument_name":"ETH-PERPETUAL","bids":[],"asks":[["new",3896.7,8.0e4]],"prev_change_id":15557285294}}}
{"jsonrpc":"2.0","method":"subscription","params":{"channel":"book.ETH-PERPETUAL.raw","data":{"timestamp":1734114601772,"type":"change","change_id":15557285296,"instrument_name":"ETH-PERPETUAL","bids":[["new",3881.7,8.0e4]],"asks":[],"prev_change_id":15557285295}}}
{"jsonrpc":"2.0","method":"subscription","params":{"channel":"book.ETH-PERPETUAL.raw","data":{"timestamp":1734114601772,"type":"change","change_id":15557285296,"instrument_name":"ETH-PERPETUAL","bids":[["new",3881.7,8.0e4]],"asks":[],"prev_change_id":15557285295}}}
{"jsonrpc":"2.0","method":"subscription","params":{"channel":"book.ETH-PERPETUAL.raw","data":{"timestamp":1734114601773,"type":"change","change_id":15557285297,"instrument_name":"ETH-PERPETUAL","bids":[],"asks":[["change",3896.7,1.0e5]],"prev_change_id":15557285296}}}
{"jsonrpc":"2.0","method":"subscription","params":{"channel":"book.ETH-PERPETUAL.raw","data":{"timestamp":1734114601773,"type":"change","change_id":15557285297,"instrument_name":"ETH-PERPETUAL","bids":[],"asks":[["change",3896.7,1.0e5]],"prev_change_id":15557285296}}}
{"jsonrpc":"2.0","method":"subscription","params":{"channel":"book.ETH-PERPETUAL.raw","data":{"timestamp":1734114601775,"type":"change","change_id":15557285298,"instrument_name":"ETH-PERPETUAL","bids":[["change",3881.7,1.0e5]],"asks":[],"prev_change_id":15557285297}}}
{"jsonrpc":"2.0","method":"subscription","params":{"channel":"book.ETH-PERPETUAL.raw","data":{"timestamp":1734114601775,"type":"change","change_id":15557285298,"instrument_name":"ETH-PERPETUAL","bids":[["change",3881.7,1.0e5]],"asks":[],"prev_change_id":15557285297}}}
{"jsonrpc":"2.0","method":"subscription","params":{"channel":"book.ETH-PERPETUAL.raw","data":{"timestamp":1734114601776,"type":"change","change_id":15557285299,"instrument_name":"ETH-PERPETUAL","bids":[],"asks":[["change",3896.7,1.8e5]],"prev_change_id":15557285298}}}
{"jsonrpc":"2.0","method":"subscription","params":{"channel":"book.ETH-PERPETUAL.raw","data":{"timestamp":1734114601776,"type":"change","change_id":15557285299,"instrument_name":"ETH-PERPETUAL","bids":[],"asks":[["change",3896.7,1.8e5]],"prev_change_id":15557285298}}}
{"jsonrpc":"2.0","method":"subscription","params":{"channel":"book.ETH-PERPETUAL.raw","data":{"timestamp":1734114601777,"type":"change","change_id":15557285300,"instrument_name":"ETH-PERPETUAL","bids":[["change",3881.7,1.8e5]],"asks":[],"prev_change_id":15557285299}}}
{"jsonrpc":"2.0","method":"subscription","params":{"channel":"book.ETH-PERPETUAL.raw","data":{"timestamp":1734114601777,"type":"change","change_id":15557285300,"instrument_name":"ETH-PERPETUAL","bids":[["change",3881.7,1.8e5]],"asks":[],"prev_change_id":15557285299}}}
{"jsonrpc":"2.0","method":"subscription","params":{"channel":"book.ETH-PERPETUAL.raw","data":{"timestamp":1734114601778,"type":"change","change_id":15557285301,"instrument_name":"ETH-PERPETUAL","bids":[],"asks":[["change",3896.7,2.0e5]],"prev_change_id":15557285300}}}
{"jsonrpc":"2.0","method":"subscription","params":{"channel":"book.ETH-PERPETUAL.raw","data":{"timestamp":1734114601778,"type":"change","change_id":15557285301,"instrument_name":"ETH-PERPETUAL","bids":[],"asks":[["change",3896.7,2.0e5]],"prev_change_id":15557285300}}}
{"jsonrpc":"2.0","method":"subscription","params":{"channel":"book.ETH-PERPETUAL.raw","data":{"timestamp":1734114601779,"type":"change","change_id":15557285302,"instrument_name":"ETH-PERPETUAL","bids":[["change",3881.7,2.0e5]],"asks":[],"prev_change_id":15557285301}}}
{"jsonrpc":"2.0","method":"subscription","params":{"channel":"book.ETH-PERPETUAL.raw","data":{"timestamp":1734114601779,"type":"change","change_id":15557285302,"instrument_name":"ETH-PERPETUAL","bids":[["change",3881.7,2.0e5]],"asks":[],"prev_change_id":15557285301}}}
{"jsonrpc":"2.0","method":"subscription","params":{"channel":"book.ETH-PERPETUAL.raw","data":{"timestamp":1734114601986,"type":"change","change_id":15557285314,"instrument_name":"ETH-PERPETUAL","bids":[["delete",3881.7,0.0]],"asks":[["delete",3896.7,0.0]],"prev_change_id":15557285302}}}
{"jsonrpc":"2.0","method":"subscription","params":{"channel":"book.ETH-PERPETUAL.raw","data":{"timestamp":1734114601986,"type":"change","change_id":15557285314,"instrument_name":"ETH-PERPETUAL","bids":[["delete",3881.7,0.0]],"asks":[["delete",3896.7,0.0]],"prev_change_id":15557285302}}}
{"jsonrpc":"2.0","method":"subscription","params":{"channel":"book.ETH-PERPETUAL.raw","data":{"timestamp":1734114602493,"type":"change","change_id":15557285362,"instrument_name":"ETH-PERPETUAL","bids":[],"asks":[["new",3896.65,8.0e4]],"prev_change_id":15557285314}}}
{"jsonrpc":"2.0","method":"subscription","params":{"channel":"book.ETH-PERPETUAL.raw","data":{"timestamp":1734114602493,"type":"change","change_id":15557285362,"instrument_name":"ETH-PERPETUAL","bids":[],"asks":[["new",3896.65,8.0e4]],"prev_change_id":15557285314}}}
{"jsonrpc":"2.0","method":"subscription","params":{"channel":"book.ETH-PERPETUAL.raw","data":{"timestamp":1734114602497,"type":"change","change_id":15557285363,"instrument_name":"ETH-PERPETUAL","bids":[["new",3881.7,8.0e4]],"asks":[],"prev_change_id":15557285362}}}
{"jsonrpc":"2.0","method":"subscription","params":{"channel":"book.ETH-PERPETUAL.raw","data":{"timestamp":1734114602497,"type":"change","change_id":15557285363,"instrument_name":"ETH-PERPETUAL","bids":[["new",3881.7,8.0e4]],"asks":[],"prev_change_id":15557285362}}}
{"jsonrpc":"2.0","method":"subscription","params":{"channel":"book.ETH-PERPETUAL.raw","data":{"timestamp":1734114602498,"type":"change","change_id":15557285364,"instrument_name":"ETH-PERPETUAL","bids":[],"asks":[["change",3896.65,1.0e5]],"prev_change_id":15557285363}}}
{"jsonrpc":"2.0","method":"subscription","params":{"channel":"book.ETH-PERPETUAL.raw","data":{"timestamp":1734114602498,"type":"change","change_id":15557285364,"instrument_name":"ETH-PERPETUAL","bids":[],"asks":[["change",3896.65,1.0e5]],"prev_change_id":15557285363}}}
{"jsonrpc":"2.0","method":"subscription","params":{"channel":"book.ETH-PERPETUAL.raw","data":{"timestamp":1734114602503,"type":"change","change_id":15557285365,"instrument_name":"ETH-PERPETUAL","bids":[["change",3881.7,1.0e5]],"asks":[],"prev_change_id":15557285364}}}
{"jsonrpc":"2.0","method":"subscription","params":{"channel":"book.ETH-PERPETUAL.raw","data":{"timestamp":1734114602503,"type":"change","change_id":15557285365,"instrument_name":"ETH-PERPETUAL","bids":[["change",3881.7,1.0e5]],"asks":[],"prev_change_id":15557285364}}}
{"jsonrpc":"2.0","method":"subscription","params":{"channel":"book.ETH-PERPETUAL.raw","data":{"timestamp":1734114602504,"type":"change","change_id":15557285366,"instrument_name":"ETH-PERPETUAL","bids":[],"asks":[["new",3896.7,5.0e3]],"prev_change_id":15557285365}}}
{"jsonrpc":"2.0","method":"subscription","params":{"channel":"book.ETH-PERPETUAL.raw","data":{"timestamp":1734114602504,"type":"change","change_id":15557285366,"instrument_name":"ETH-PERPETUAL","bids":[],"asks":[["new",3896.7,5.0e3]],"prev_change_id":15557285365}}}
{"jsonrpc":"2.0","method":"subscription","params":{"channel":"book.ETH-PERPETUAL.raw","data":{"timestamp":1734114602506,"type":"change","change_id":15557285367,"instrument_name":"ETH-PERPETUAL","bids":[],"asks":[["change",3896.65,1.8e5]],"prev_change_id":15557285366}}}
{"jsonrpc":"2.0","method":"subscription","params":{"channel":"book.ETH-PERPETUAL.raw","data":{"timestamp":1734114602506,"type":"change","change_id":15557285367,"instrument_name":"ETH-PERPETUAL","bids":[],"asks":[["change",3896.65,1.8e5]],"prev_change_id":15557285366}}}
{"jsonrpc":"2.0","method":"subscription","params":{"channel":"book.ETH-PERPETUAL.raw","data":{"timestamp":1734114602509,"type":"change","change_id":15557285368,"instrument_name":"ETH-PERPETUAL","bids":[["change",3881.7,1.8e5]],"asks":[],"prev_change_id":15557285367}}}
{"jsonrpc":"2.0","method":"subscription","params":{"channel":"book.ETH-PERPETUAL.raw","data":{"timestamp":1734114602509,"type":"change","change_id":15557285368,"instrument_name":"ETH-PERPETUAL","bids":[["change",3881.7,1.8e5]],"asks":[],"prev_change_id":15557285367}}}
{"jsonrpc":"2.0","method":"subscription","params":{"channel":"book.ETH-PERPETUAL.raw","data":{"timestamp":1734114602512,"type":"change","change_id":15557285369,"instrument_name":"ETH-PERPETUAL","bids":[],"asks":[["change",3896.65,2.0e5]],"prev_change_id":15557285368}}}
{"jsonrpc":"2.0","method":"subscription","params":{"channel":"book.ETH-PERPETUAL.raw","data":{"timestamp":1734114602512,"type":"change","change_id":15557285369,"instrument_name":"ETH-PERPETUAL","bids":[],"asks":[["change",3896.65,2.0e5]],"prev_change_id":15557285368}}}
{"jsonrpc":"2.0","method":"subscription","params":{"channel":"book.ETH-PERPETUAL.raw","data":{"timestamp":1734114602514,"type":"change","change_id":15557285370,"instrument_name":"ETH-PERPETUAL","bids":[["change",3881.7,2.0e5]],"asks":[],"prev_change_id":15557285369}}}
{"jsonrpc":"2.0","method":"subscription","params":{"channel":"book.ETH-PERPETUAL.raw","data":{"timestamp":1734114602514,"type":"change","change_id":15557285370,"instrument_name":"ETH-PERPETUAL","bids":[["change",3881.7,2.0e5]],"asks":[],"prev_change_id":15557285369}}}
{"jsonrpc":"2.0","method":"subscription","params":{"channel":"book.ETH-PERPETUAL.raw","data":{"timestamp":1734114602518,"type":"change","change_id":15557285371,"instrument_name":"ETH-PERPETUAL","bids":[],"asks":[["change",3896.7,1.0e4]],"prev_change_id":15557285370}}}
{"jsonrpc":"2.0","method":"subscription","params":{"channel":"book.ETH-PERPETUAL.raw","data":{"timestamp":1734114602518,"type":"change","change_id":15557285371,"instrument_name":"ETH-PERPETUAL","bids":[],"asks":[["change",3896.7,1.0e4]],"prev_change_id":15557285370}}}
{"jsonrpc":"2.0","method":"subscription","params":{"channel":"book.ETH-PERPETUAL.raw","data":{"timestamp":1734114602640,"type":"change","change_id":15557285372,"instrument_name":"ETH-PERPETUAL","bids":[],"asks":[["new",3935.65,700.0],["delete",3947.85,0.0]],"prev_change_id":15557285371}}}
{"jsonrpc":"2.0","method":"subscription","params":{"channel":"book.ETH-PERPETUAL.raw","data":{"timestamp":1734114602640,"type":"change","change_id":15557285372,"instrument_name":"ETH-PERPETUAL","bids":[],"asks":[["new",3935.65,700.0],["delete",3947.85,0.0]],"prev_change_id":15557285371}}}
{"jsonrpc":"2.0","method":"subscription","params":{"channel":"book.ETH-PERPETUAL.raw","data":{"timestamp":1734114602702,"type":"change","change_id":15557285373,"instrument_name":"ETH-PERPETUAL","bids":[["delete",3881.7,0.0]],"asks":[["delete",3896.65,0.0],["delete",3896.7,0.0]],"prev_change_id":15557285372}}}
{"jsonrpc":"2.0","method":"subscription","params":{"channel":"book.ETH-PERPETUAL.raw","data":{"timestamp":1734114602702,"type":"change","change_id":15557285373,"instrument_name":"ETH-PERPETUAL","bids":[["delete",3881.7,0.0]],"asks":[["delete",3896.65,0.0],["delete",3896.7,0.0]],"prev_change_id":15557285372}}}
{"jsonrpc":"2.0","method":"subscription","params":{"channel":"book.ETH-PERPETUAL.raw","data":{"timestamp":1734114603312,"type":"change","change_id":15557285426,"instrument_name":"ETH-PERPETUAL","bids":[["new",3881.4,8.0e4]],"asks":[],"prev_change_id":15557285373}}}
{"jsonrpc":"2.0","method":"subscription","params":{"channel":"book.ETH-PERPETUAL.raw","data":{"timestamp":1734114603312,"type":"change","change_id":15557285426,"instrument_name":"ETH-PERPETUAL","bids":[["new",3881.4,8.0e4]],"asks":[],"prev_change_id":15557285373}}}
{"jsonrpc":"2.0","method":"subscription","params":{"channel":"book.ETH-PERPETUAL.raw","data":{"timestamp":1734114603315,"type":"change","change_id":15557285427,"instrument_name":"ETH-PERPETUAL","bids":[],"asks":[["new",3896.35,8.0e4]],"prev_change_id":15557285426}}}
{"jsonrpc":"2.0","method":"subscription","params":{"channel":"book.ETH-PERPETUAL.raw","data":{"timestamp":1734114603315,"type":"change","change_id":15557285427,"instrument_name":"ETH-PERPETUAL","bids":[],"asks":[["new",3896.35,8.0e4]],"prev_change_id":15557285426}}}
{"jsonrpc":"2.0","method":"subscription","params":{"channel":"book.ETH-PERPETUAL.raw","data":{"timestamp":1734114603318,"type":"change","change_id":15557285428,"instrument_name":"ETH-PERPETUAL","bids":[],"asks":[["change",3896.35,1.0e5]],"prev_change_id":15557285427}}}
{"jsonrpc":"2.0","method":"subscription","params":{"channel":"book.ETH-PERPETUAL.raw","data":{"timestamp":1734114603318,"type":"change","change_id":15557285428,"instrument_name":"ETH-PERPETUAL","bids":[],"asks":[["change",3896.35,1.0e5]],"prev_change_id":15557285427}}}
{"jsonrpc":"2.0","method":"subscription","params":{"channel":"book.ETH-PERPETUAL.raw","data":{"timestamp":1734114603320,"type":"change","change_id":15557285429,"instrument_name":"ETH-PERPETUAL","bids":[["change",3881.4,1.0e5]],"asks":[],"prev_change_id":15557285428}}}
{"jsonrpc":"2.0","method":"subscription","params":{"channel":"book.ETH-PERPETUAL.raw","data":{"timestamp":1734114603320,"type":"change","change_id":15557285429,"instrument_name":"ETH-PERPETUAL","bids":[["change",3881.4,1.0e5]],"asks":[],"prev_change_id":15557285428}}}
{"jsonrpc":"2.0","method":"subscription","params":{"channel":"book.ETH-PERPETUAL.raw","data":{"timestamp":1734114603323,"type":"change","change_id":15557285430,"instrument_name":"ETH-PERPETUAL","bids":[["new",3881.35,3.2e5]],"asks":[],"prev_change_id":15557285429}}}
{"jsonrpc":"2.0","method":"subscription","params":{"channel":"book.ETH-PERPETUAL.raw","data":{"timestamp":1734114603323,"type":"change","change_id":15557285430,"instrument_name":"ETH-PERPETUAL","bids":[["new",3881.35,3.2e5]],"asks":[],"prev_change_id":15557285429}}}
{"jsonrpc":"2.0","method":"subscription","params":{"channel":"book.ETH-PERPETUAL.raw","data":{"timestamp":1734114603326,"type":"change","change_id":15557285431,"instrument_name":"ETH-PERPETUAL","bids":[["change",3881.4,1.8e5]],"asks":[],"prev_change_id":15557285430}}}
{"jsonrpc":"2.0","method":"subscription","params":{"channel":"book.ETH-PERPETUAL.raw","data":{"timestamp":1734114603326,"type":"change","change_id":15557285431,"instrument_name":"ETH-PERPETUAL","bids":[["change",3881.4,1.8e5]],"asks":[],"prev_change_id":15557285430}}}
{"jsonrpc":"2.0","method":"subscription","params":{"channel":"book.ETH-PERPETUAL.raw","data":{"timestamp":1734114603330,"type":"change","change_id":15557285432,"instrument_name":"ETH-PERPETUAL","bids":[],"asks":[["change",3896.35,1.8e5]],"prev_change_id":15557285431}}}
{"jsonrpc":"2.0","method":"subscription","params":{"channel":"book.ETH-PERPETUAL.raw","data":{"timestamp":1734114603330,"type":"change","change_id":15557285432,"instrument_name":"ETH-PERPETUAL","bids":[],"asks":[["change",3896.35,1.8e5]],"prev_change_id":15557285431}}}
{"jsonrpc":"2.0","method":"subscription","params":{"channel":"book.ETH-PERPETUAL.raw","data":{"timestamp":1734114603333,"type":"change","change_id":15557285433,"instrument_name":"ETH-PERPETUAL","bids":[],"asks":[["change",3896.35,2.0e5]],"prev_change_id":15557285432}}}
{"jsonrpc":"2.0","method":"subscription","params":{"channel":"book.ETH-PERPETUAL.raw","data":{"timestamp":1734114603333,"type":"change","change_id":15557285433,"instrument_name":"ETH-PERPETUAL","bids":[],"asks":[["change",3896.35,2.0e5]],"prev_change_id":15557285432}}}
{"jsonrpc":"2.0","method":"subscription","params":{"channel":"book.ETH-PERPETUAL.raw","data":{"timestamp":1734114603337,"type":"change","change_id":15557285434,"instrument_name":"ETH-PERPETUAL","bids":[["change",3881.4,2.0e5]],"asks":[],"prev_change_id":15557285433}}}
{"jsonrpc":"2.0","method":"subscription","params":{"channel":"book.ETH-PERPETUAL.raw","data":{"timestamp":1734114603337,"type":"change","change_id":15557285434,"instrument_name":"ETH-PERPETUAL","bids":[["change",3881.4,2.0e5]],"asks":[],"prev_change_id":15557285433}}}
{"jsonrpc":"2.0","method":"subscription","params":{"channel":"book.ETH-PERPETUAL.raw","data":{"timestamp":1734114603338,"type":"change","change_id":15557285435,"instrument_name":"ETH-PERPETUAL","bids":[["change",3881.4,5.2e5]],"asks":[],"prev_change_id":15557285434}}}
{"jsonrpc":"2.0","method":"subscription","params":{"channel":"book.ETH-PERPETUAL.raw","data":{"timestamp":1734114603338,"type":"change","change_id":15557285435,"instrument_name":"ETH-PERPETUAL","bids":[["change",3881.4,5.2e5]],"asks":[],"prev_change_id":15557285434}}}
{"jsonrpc":"2.0","method":"subscription","params":{"channel":"book.ETH-PERPETUAL.raw","data":{"timestamp":1734114603466,"type":"change","change_id":15557285436,"instrument_name":"ETH-PERPETUAL","bids":[["delete",3881.4,0.0],["delete",3881.35,0.0]],"asks":[["delete",3896.35,0.0]],"prev_change_id":15557285435}}}
{"jsonrpc":"2.0","method":"subscription","params":{"channel":"book.ETH-PERPETUAL.raw","data":{"timestamp":1734114603466,"type":"change","change_id":15557285436,"instrument_name":"ETH-PERPETUAL","bids":[["delete",3881.4,0.0],["delete",3881.35,0.0]],"asks":[["delete",3896.35,0.0]],"prev_change_id":15557285435}}}
{"jsonrpc":"2.0","method":"subscription","params":{"channel":"book.ETH-PERPETUAL.raw","data":{"timestamp":1734114603844,"type":"change","change_id":15557285437,"instrument_name":"ETH-PERPETUAL","bids":[],"asks":[["new",3896.35,8.0e4]],"prev_change_id":15557285436}}}
{"jsonrpc":"2.0","method":"subscription","params":{"channel":"book.ETH-PERPETUAL.raw","data":{"timestamp":1734114603844,"type":"change","change_id":15557285437,"instrument_name":"ETH-PERPETUAL","bids":[],"asks":[["new",3896.35,8.0e4]],"prev_change_id":15557285436}}}
{"jsonrpc":"2.0","method":"subscription","params":{"channel":"book.ETH-PERPETUAL.raw","data":{"timestamp":1734114603847,"type":"change","change_id":15557285438,"instrument_name":"ETH-PERPETUAL","bids":[["new",3881.4,8.0e4]],"asks":[],"prev_change_id":15557285437}}}
{"jsonrpc":"2.0","method":"subscription","params":{"channel":"book.ETH-PERPETUAL.raw","data":{"timestamp":1734114603847,"type":"change","change_id":15557285438,"instrument_name":"ETH-PERPETUAL","bids":[["new",3881.4,8.0e4]],"asks":[],"prev_change_id":15557285437}}}
{"jsonrpc":"2.0","method":"subscription","params":{"channel":"book.ETH-PERPETUAL.raw","data":{"timestamp":1734114603850,"type":"change","change_id":15557285439,"instrument_name":"ETH-PERPETUAL","bids":[],"asks":[["change",3896.35,1.0e5]],"prev_change_id":15557285438}}}
{"jsonrpc":"2.0","method":"subscription","params":{"channel":"book.ETH-PERPETUAL.raw","data":{"timestamp":1734114603850,"type":"change","change_id":15557285439,"instrument_name":"ETH-PERPETUAL","bids":[],"asks":[["change",3896.35,1.0e5]],"prev_change_id":15557285438}}}
{"jsonrpc":"2.0","method":"subscription","params":{"channel":"book.ETH-PERPETUAL.raw","data":{"timestamp":1734114603879,"type":"change","change_id":15557285440,"instrument_name":"ETH-PERPETUAL","bids":[["change",3881.4,1.0e5]],"asks":[],"prev_change_id":15557285439}}}
{"jsonrpc":"2.0","method":"subscription","params":{"channel":"book.ETH-PERPETUAL.raw","data":{"timestamp":1734114603879,"type":"change","change_id":15557285440,"instrument_name":"ETH-PERPETUAL","bids":[["change",3881.4,1.0e5]],"asks":[],"prev_change_id":15557285439}}}
{"jsonrpc":"2.0","method":"subscription","params":{"channel":"book.ETH-PERPETUAL.raw","data":{"timestamp":1734114603880,"type":"change","change_id":15557285441,"instrument_name":"ETH-PERPETUAL","bids":[],"asks":[["change",3896.35,1.05e5]],"prev_change_id":15557285440}}}
{"jsonrpc":"2.0","method":"subscription","params":{"channel":"book.ETH-PERPETUAL.raw","data":{"timestamp":1734114603880,"type":"change","change_id":15557285441,"instrument_name":"ETH-PERPETUAL","bids":[],"asks":[["change",3896.35,1.05e5]],"prev_change_id":15557285440}}}
{"jsonrpc":"2.0","method":"subscription","params":{"channel":"book.ETH-PERPETUAL.raw","data":{"timestamp":1734114603880,"type":"change","change_id":15557285442,"instrument_name":"ETH-PERPETUAL","bids":[],"asks":[["change",3896.35,1.85e5]],"prev_change_id":15557285441}}}
{"jsonrpc":"2.0","method":"subscription","params":{"channel":"book.ETH-PERPETUAL.raw","data":{"timestamp":1734114603880,"type":"change","change_id":15557285442,"instrument_name":"ETH-PERPETUAL","bids":[],"asks":[["change",3896.35,1.85e5]],"prev_change_id":15557285441}}}
{"jsonrpc":"2.0","method":"subscription","params":{"channel":"book.ETH-PERPETUAL.raw","data":{"timestamp":1734114603881,"type":"change","change_id":15557285443,"instrument_name":"ETH-PERPETUAL","bids":[["change",3881.4,1.8e5]],"asks":[],"prev_change_id":15557285442}}}
{"jsonrpc":"2.0","method":"subscription","params":{"channel":"book.ETH-PERPETUAL.raw","data":{"timestamp":1734114603881,"type":"change","change_id":15557285443,"instrument_name":"ETH-PERPETUAL","bids":[["change",3881.4,1.8e5]],"asks":[],"prev_change_id":15557285442}}}
{"jsonrpc":"2.0","method":"subscription","params":{"channel":"book.ETH-PERPETUAL.raw","data":{"timestamp":1734114603893,"type":"change","change_id":15557285444,"instrument_name":"ETH-PERPETUAL","bids":[],"asks":[["change",3896.35,2.05e5]],"prev_change_id":15557285443}}}
{"jsonrpc":"2.0","method":"subscription","params":{"channel":"book.ETH-PERPETUAL.raw","data":{"timestamp":1734114603893,"type":"change","change_id":15557285444,"instrument_name":"ETH-PERPETUAL","bids":[],"asks":[["change",3896.35,2.05e5]],"prev_change_id":15557285443}}}
{"jsonrpc":"2.0","method":"subscription","params":{"channel":"book.ETH-PERPETUAL.raw","data":{"timestamp":1734114603896,"type":"change","change_id":15557285445,"instrument_name":"ETH-PERPETUAL","bids":[["change",3881.4,2.0e5]],"asks":[],"prev_change_id":15557285444}}}
{"jsonrpc":"2.0","method":"subscription","params":{"channel":"book.ETH-PERPETUAL.raw","data":{"timestamp":1734114603896,"type":"change","change_id":15557285445,"instrument_name":"ETH-PERPETUAL","bids":[["change",3881.4,2.0e5]],"asks":[],"prev_change_id":15557285444}}}
{"jsonrpc":"2.0","method":"subscription","params":{"channel":"book.ETH-PERPETUAL.raw","data":{"timestamp":1734114603898,"type":"change","change_id":15557285446,"instrument_name":"ETH-PERPETUAL","bids":[],"asks":[["change",3896.35,2.1e5]],"prev_change_id":15557285445}}}
{"jsonrpc":"2.0","method":"subscription","params":{"channel":"book.ETH-PERPETUAL.raw","data":{"timestamp":1734114603898,"type":"change","change_id":15557285446,"instrument_name":"ETH-PERPETUAL","bids":[],"asks":[["change",3896.35,2.1e5]],"prev_change_id":15557285445}}}
{"jsonrpc":"2.0","method":"subscription","params":{"channel":"book.ETH-PERPETUAL.raw","data":{"timestamp":1734114604097,"type":"change","change_id":15557285477,"instrument_name":"ETH-PERPETUAL","bids":[["delete",3881.4,0.0]],"asks":[["delete",3896.35,0.0]],"prev_change_id":15557285446}}}
{"jsonrpc":"2.0","method":"subscription","params":{"channel":"book.ETH-PERPETUAL.raw","data":{"timestamp":1734114604097,"type":"change","change_id":15557285477,"instrument_name":"ETH-PERPETUAL","bids":[["delete",3881.4,0.0]],"asks":[["delete",3896.35,0.0]],"prev_change_id":15557285446}}}
{"jsonrpc":"2.0","method":"subscription","params":{"channel":"book.ETH-PERPETUAL.raw","data":{"timestamp":1734114604494,"type":"change","change_id":15557285524,"instrument_name":"ETH-PERPETUAL","bids":[],"asks":[["new",3896.35,8.0e4]],"prev_change_id":15557285477}}}
{"jsonrpc":"2.0","method":"subscription","params":{"channel":"book.ETH-PERPETUAL.raw","data":{"timestamp":1734114604494,"type":"change","change_id":15557285524,"instrument_name":"ETH-PERPETUAL","bids":[],"asks":[["new",3896.35,8.0e4]],"prev_change_id":15557285477}}}
{"jsonrpc":"2.0","method":"subscription","params":{"channel":"book.ETH-PERPETUAL.raw","data":{"timestamp":1734114604497,"type":"change","change_id":15557285525,"instrument_name":"ETH-PERPETUAL","bids":[["new",3881.4,8.0e4]],"asks":[],"prev_change_id":15557285524}}}
{"jsonrpc":"2.0","method":"subscription","params":{"channel":"book.ETH-PERPETUAL.raw","data":{"timestamp":1734114604497,"type":"change","change_id":15557285525,"instrument_name":"ETH-PERPETUAL","bids":[["new",3881.4,8.0e4]],"asks":[],"prev_change_id":15557285524}}}
{"jsonrpc":"2.0","method":"subscription","params":{"channel":"book.ETH-PERPETUAL.raw","data":{"timestamp":1734114604499,"type":"change","change_id":15557285526,"instrument_name":"ETH-PERPETUAL","bids":[],"asks":[["change",3896.35,1.0e5]],"prev_change_id":15557285525}}}
{"jsonrpc":"2.0","method":"subscription","params":{"channel":"book.ETH-PERPETUAL.raw","data":{"timestamp":1734114604499,"type":"change","change_id":15557285526,"instrument_name":"ETH-PERPETUAL","bids":[],"asks":[["change",3896.35,1.0e5]],"prev_change_id":15557285525}}}
{"jsonrpc":"2.0","method":"subscription","params":{"channel":"book.ETH-PERPETUAL.raw","data":{"timestamp":1734114604501,"type":"change","change_id":15557285527,"instrument_name":"ETH-PERPETUAL","bids":[["change",3881.4,1.0e5]],"asks":[],"prev_change_id":15557285526}}}
{"jsonrpc":"2.0","method":"subscription","params":{"channel":"book.ETH-PERPETUAL.raw","data":{"timestamp":1734114604501,"type":"change","change_id":15557285527,"instrument_name":"ETH-PERPETUAL","bids":[["change",3881.4,1.0e5]],"asks":[],"prev_change_id":15557285526}}}
{"jsonrpc":"2.0","method":"subscription","params":{"channel":"book.ETH-PERPETUAL.raw","data":{"timestamp":1734114604505,"type":"change","change_id":15557285528,"instrument_name":"ETH-PERPETUAL","bids":[],"asks":[["change",3896.35,1.05e5]],"prev_change_id":15557285527}}}
{"jsonrpc":"2.0","method":"subscription","params":{"channel":"book.ETH-PERPETUAL.raw","data":{"timestamp":1734114604505,"type":"change","change_id":15557285528,"instrument_name":"ETH-PERPETUAL","bids":[],"asks":[["change",3896.35,1.05e5]],"prev_change_id":15557285527}}}
{"jsonrpc":"2.0","method":"subscription","params":{"channel":"book.ETH-PERPETUAL.raw","data":{"timestamp":1734114604508,"type":"change","change_id":15557285529,"instrument_name":"ETH-PERPETUAL","bids":[],"asks":[["change",3896.35,1.85e5]],"prev_change_id":15557285528}}}
{"jsonrpc":"2.0","method":"subscription","params":{"channel":"book.ETH-PERPETUAL.raw","data":{"timestamp":1734114604508,"type":"change","change_id":15557285529,"instrument_name":"ETH-PERPETUAL","bids":[],"asks":[["change",3896.35,1.85e5]],"prev_change_id":15557285528}}}
{"jsonrpc":"2.0","method":"subscription","params":{"channel":"book.ETH-PERPETUAL.raw","data":{"timestamp":1734114604511,"type":"change","change_id":15557285530,"instrument_name":"ETH-PERPETUAL","bids":[["change",3881.4,1.8e5]],"asks":[],"prev_change_id":15557285529}}}
{"jsonrpc":"2.0","method":"subscription","params":{"channel":"book.ETH-PERPETUAL.raw","data":{"timestamp":1734114604511,"type":"change","change_id":15557285530,"instrument_name":"ETH-PERPETUAL","bids":[["change",3881.4,1.8e5]],"asks":[],"prev_change_id":15557285529}}}
{"jsonrpc":"2.0","method":"subscription","params":{"channel":"book.ETH-PERPETUAL.raw","data":{"timestamp":1734114604515,"type":"change","change_id":15557285531,"instrument_name":"ETH-PERPETUAL","bids":[],"asks":[["change",3896.35,2.05e5]],"prev_change_id":15557285530}}}
{"jsonrpc":"2.0","method":"subscription","params":{"channel":"book.ETH-PERPETUAL.raw","data":{"timestamp":1734114604515,"type":"change","change_id":15557285531,"instrument_name":"ETH-PERPETUAL","bids":[],"asks":[["change",3896.35,2.05e5]],"prev_change_id":15557285530}}}
{"jsonrpc":"2.0","method":"subscription","params":{"channel":"book.ETH-PERPETUAL.raw","data":{"timestamp":1734114604518,"type":"change","change_id":15557285532,"instrument_name":"ETH-PERPETUAL","bids":[["change",3881.4,2.0e5]],"asks":[],"prev_change_id":15557285531}}}
{"jsonrpc":"2.0","method":"subscription","params":{"channel":"book.ETH-PERPETUAL.raw","data":{"timestamp":1734114604518,"type":"change","change_id":15557285532,"instrument_name":"ETH-PERPETUAL","bids":[["change",3881.4,2.0e5]],"asks":[],"prev_change_id":15557285531}}}
{"jsonrpc":"2.0","method":"subscription","params":{"channel":"book.ETH-PERPETUAL.raw","data":{"timestamp":1734114604522,"type":"change","change_id":15557285533,"instrument_name":"ETH-PERPETUAL","bids":[],"asks":[["change",3896.35,2.1e5]],"prev_change_id":15557285532}}}
{"jsonrpc":"2.0","method":"subscription","params":{"channel":"book.ETH-PERPETUAL.raw","data":{"timestamp":1734114604522,"type":"change","change_id":15557285533,"instrument_name":"ETH-PERPETUAL","bids":[],"asks":[["change",3896.35,2.1e5]],"prev_change_id":15557285532}}}
{"jsonrpc":"2.0","method":"subscription","params":{"channel":"book.ETH-PERPETUAL.raw","data":{"timestamp":1734114604824,"type":"change","change_id":15557285561,"instrument_name":"ETH-PERPETUAL","bids":[["delete",3881.4,0.0]],"asks":[["delete",3896.35,0.0]],"prev_change_id":15557285533}}}
{"jsonrpc":"2.0","method":"subscription","params":{"channel":"book.ETH-PERPETUAL.raw","data":{"timestamp":1734114604824,"type":"change","change_id":15557285561,"instrument_name":"ETH-PERPETUAL","bids":[["delete",3881.4,0.0]],"asks":[["delete",3896.35,0.0]],"prev_change_id":15557285533}}}
{"jsonrpc":"2.0","method":"subscription","params":{"channel":"book.ETH-PERPETUAL.raw","data":{"timestamp":1734114605208,"type":"change","change_id":15557285578,"instrument_name":"ETH-PERPETUAL","bids":[],"asks":[["new",3896.35,8.0e4]],"prev_change_id":15557285561}}}
{"jsonrpc":"2.0","method":"subscription","params":{"channel":"book.ETH-PERPETUAL.raw","data":{"timestamp":1734114605208,"type":"change","change_id":15557285578,"instrument_name":"ETH-PERPETUAL","bids":[],"asks":[["new",3896.35,8.0e4]],"prev_change_id":15557285561}}}
{"jsonrpc":"2.0","method":"subscription","params":{"channel":"book.ETH-PERPETUAL.raw","data":{"timestamp":1734114605215,"type":"change","change_id":15557285579,"instrument_name":"ETH-PERPETUAL","bids":[["new",3881.4,8.0e4]],"asks":[],"prev_change_id":15557285578}}}
{"jsonrpc":"2.0","method":"subscription","params":{"channel":"book.ETH-PERPETUAL.raw","data":{"timestamp":1734114605215,"type":"change","change_id":15557285579,"instrument_name":"ETH-PERPETUAL","bids":[["new",3881.4,8.0e4]],"asks":[],"prev_change_id":15557285578}}}
{"jsonrpc":"2.0","method":"subscription","params":{"channel":"book.ETH-PERPETUAL.raw","data":{"timestamp":1734114605216,"type":"change","change_id":15557285580,"instrument_name":"ETH-PERPETUAL","bids":[],"asks":[["change",3896.35,1.0e5]],"prev_change_id":15557285579}}}
{"jsonrpc":"2.0","method":"subscription","params":{"channel":"book.ETH-PERPETUAL.raw","data":{"timestamp":1734114605216,"type":"change","change_id":15557285580,"instrument_name":"ETH-PERPETUAL","bids":[],"asks":[["change",3896.35,1.0e5]],"prev_change_id":15557285579}}}
{"jsonrpc":"2.0","method":"subscription","params":{"channel":"book.ETH-PERPETUAL.raw","data":{"timestamp":1734114605217,"type":"change","change_id":15557285581,"instrument_name":"ETH-PERPETUAL","bids":[["change",3881.4,1.0e5]],"asks":[],"prev_change_id":15557285580}}}
{"jsonrpc":"2.0","method":"subscription","params":{"channel":"book.ETH-PERPETUAL.raw","data":{"timestamp":1734114605217,"type":"change","change_id":15557285581,"instrument_name":"ETH-PERPETUAL","bids":[["change",3881.4,1.0e5]],"asks":[],"prev_change_id":15557285580}}}
{"jsonrpc":"2.0","method":"subscription","params":{"channel":"book.ETH-PERPETUAL.raw","data":{"timestamp":1734114605219,"type":"change","change_id":15557285582,"instrument_name":"ETH-PERPETUAL","bids":[],"asks":[["change",3896.35,1.05e5]],"prev_change_id":15557285581}}}
{"jsonrpc":"2.0","method":"subscription","params":{"channel":"book.ETH-PERPETUAL.raw","data":{"timestamp":1734114605219,"type":"change","change_id":15557285582,"instrument_name":"ETH-PERPETUAL","bids":[],"asks":[["change",3896.35,1.05e5]],"prev_change_id":15557285581}}}
{"jsonrpc":"2.0","method":"subscription","params":{"channel":"book.ETH-PERPETUAL.raw","data":{"timestamp":1734114605225,"type":"change","change_id":15557285583,"instrument_name":"ETH-PERPETUAL","bids":[],"asks":[["change",3896.35,1.85e5]],"prev_change_id":15557285582}}}
{"jsonrpc":"2.0","method":"subscription","params":{"channel":"book.ETH-PERPETUAL.raw","data":{"timestamp":1734114605225,"type":"change","change_id":15557285583,"instrument_name":"ETH-PERPETUAL","bids":[],"asks":[["change",3896.35,1.85e5]],"prev_change_id":15557285582}}}
