{"jsonrpc":"2.0","method":"subscription","params":{"channel":"book.ETH-PERPETUAL.raw","data":{"timestamp":1734114556986,"type":"change","change_id":15557283131,"instrument_name":"ETH-PERPETUAL","bids":[],"asks":[["new",3896.5,8.0e4]],"prev_change_id":15557283130}}}
{"jsonrpc":"2.0","method":"subscription","params":{"channel":"book.ETH-PERPETUAL.raw","data":{"timestamp":1734114556986,"type":"change","change_id":15557283131,"instrument_name":"ETH-PERPETUAL","bids":[],"asks":[["new",3896.5,8.0e4]],"prev_change_id":15557283130}}}
{"jsonrpc":"2.0","method":"subscription","params":{"channel":"book.ETH-PERPETUAL.raw","data":{"timestamp":1734114556987,"type":"change","change_id":15557283132,"instrument_name":"ETH-PERPETUAL","bids":[["change",3881.2,1.0e5]],"asks":[],"prev_change_id":15557283131}}}
{"jsonrpc":"2.0","method":"subscription","params":{"channel":"book.ETH-PERPETUAL.raw","data":{"timestamp":1734114556987,"type":"change","change_id":15557283132,"instrument_name":"ETH-PERPETUAL","bids":[["change",3881.2,1.0e5]],"asks":[],"prev_change_id":15557283131}}}
{"jsonrpc":"2.0","method":"subscription","params":{"channel":"book.ETH-PERPETUAL.raw","data":{"timestamp":1734114556987,"type":"change","change_id":15557283133,"instrument_name":"ETH-PERPETUAL","bids":[["change",3881.2,1.8e5]],"asks":[],"prev_change_id":15557283132}}}
{"jsonrpc":"2.0","method":"subscription","params":{"channel":"book.ETH-PERPETUAL.raw","data":{"timestamp":1734114556987,"type":"change","change_id":15557283133,"instrument_name":"ETH-PERPETUAL","bids":[["change",3881.2,1.8e5]],"asks":[],"prev_change_id":15557283132}}}
{"jsonrpc":"2.0","method":"subscription","params":{"channel":"book.ETH-PERPETUAL.raw","data":{"timestamp":1734114556988,"type":"change","change_id":15557283134,"instrument_name":"ETH-PERPETUAL","bids":[],"asks":[["change",3896.5,1.6e5]],"prev_change_id":15557283133}}}
{"jsonrpc":"2.0","method":"subscription","params":{"channel":"book.ETH-PERPETUAL.raw","data":{"timestamp":1734114556988,"type":"change","change_id":15557283134,"instrument_name":"ETH-PERPETUAL","bids":[],"asks":[["change",3896.5,1.6e5]],"prev_change_id":15557283133}}}
{"jsonrpc":"2.0","method":"subscription","params":{"channel":"book.ETH-PERPETUAL.raw","data":{"timestamp":1734114556989,"type":"change","change_id":15557283135,"instrument_name":"ETH-PERPETUAL","bids":[["change",3881.2,2.0e5]],"asks":[],"prev_change_id":15557283134}}}
{"jsonrpc":"2.0","method":"subscription","params":{"channel":"book.ETH-PERPETUAL.raw","data":{"timestamp":1734114556989,"type":"change","change_id":15557283135,"instrument_name":"ETH-PERPETUAL","bids":[["change",3881.2,2.0e5]],"asks":[],"prev_change_id":15557283134}}}
{"jsonrpc":"2.0","method":"subscription","params":{"channel":"book.ETH-PERPETUAL.raw","data":{"timestamp":1734114557115,"type":"change","change_id":15557283138,"instrument_name":"ETH-PERPETUAL","bids":[["delete",3881.2,0.0]],"asks":[["delete",3896.5,0.0]],"prev_change_id":15557283135}}}
{"jsonrpc":"2.0","method":"subscription","params":{"channel":"book.ETH-PERPETUAL.raw","data":{"timestamp":1734114557115,"type":"change","change_id":15557283138,"instrument_name":"ETH-PERPETUAL","bids":[["delete",3881.2,0.0]],"asks":[["delete",3896.5,0.0]],"prev_change_id":15557283135}}}
{"jsonrpc":"2.0","method":"subscription","params":{"channel":"book.ETH-PERPETUAL.raw","data":{"timestamp":1734114557130,"type":"change","change_id":15557283139,"instrument_name":"ETH-PERPETUAL","bids":[],"asks":[["delete",3908.55,0.0],["new",3920.3,500.0]],"prev_change_id":15557283138}}}
{"jsonrpc":"2.0","method":"subscription","params":{"channel":"book.ETH-PERPETUAL.raw","data":{"timestamp":1734114557130,"type":"change","change_id":15557283139,"instrument_name":"ETH-PERPETUAL","bids":[],"asks":[["delete",3908.55,0.0],["new",3920.3,500.0]],"prev_change_id":15557283138}}}
{"jsonrpc":"2.0","method":"subscription","params":{"channel":"book.ETH-PERPETUAL.raw","data":{"timestamp":1734114557307,"type":"change","change_id":15557283141,"instrument_name":"ETH-PERPETUAL","bids":[["new",3881.15,8.0e4]],"asks":[],"prev_change_id":15557283139}}}
{"jsonrpc":"2.0","method":"subscription","params":{"channel":"book.ETH-PERPETUAL.raw","data":{"timestamp":1734114557307,"type":"change","change_id":15557283141,"instrument_name":"ETH-PERPETUAL","bids":[["new",3881.15,8.0e4]],"asks":[],"prev_change_id":15557283139}}}
{"jsonrpc":"2.0","method":"subscription","params":{"channel":"book.ETH-PERPETUAL.raw","data":{"timestamp":1734114557309,"type":"change","change_id":15557283142,"instrument_name":"ETH-PERPETUAL","bids":[],"asks":[["new",3896.4,8.0e4]],"prev_change_id":15557283141}}}
{"jsonrpc":"2.0","method":"subscription","params":{"channel":"book.ETH-PERPETUAL.raw","data":{"timestamp":1734114557309,"type":"change","change_id":15557283142,"instrument_name":"ETH-PERPETUAL","bids":[],"asks":[["new",3896.4,8.0e4]],"prev_change_id":15557283141}}}
{"jsonrpc":"2.0","method":"subscription","params":{"channel":"book.ETH-PERPETUAL.raw","data":{"timestamp":1734114557310,"type":"change","change_id":15557283143,"instrument_name":"ETH-PERPETUAL","bids":[["change",3881.15,1.0e5]],"asks":[],"prev_change_id":15557283142}}}
{"jsonrpc":"2.0","method":"subscription","params":{"channel":"book.ETH-PERPETUAL.raw","data":{"timestamp":1734114557310,"type":"change","change_id":15557283143,"instrument_name":"ETH-PERPETUAL","bids":[["change",3881.15,1.0e5]],"asks":[],"prev_change_id":15557283142}}}
{"jsonrpc":"2.0","method":"subscription","params":{"channel":"book.ETH-PERPETUAL.raw","data":{"timestamp":1734114557311,"type":"change","change_id":15557283144,"instrument_name":"ETH-PERPETUAL","bids":[["change",3881.15,1.8e5]],"asks":[],"prev_change_id":15557283143}}}
{"jsonrpc":"2.0","method":"subscription","params":{"channel":"book.ETH-PERPETUAL.raw","data":{"timestamp":1734114557311,"type":"change","change_id":15557283144,"instrument_name":"ETH-PERPETUAL","bids":[["change",3881.15,1.8e5]],"asks":[],"prev_change_id":15557283143}}}
{"jsonrpc":"2.0","method":"subscription","params":{"channel":"book.ETH-PERPETUAL.raw","data":{"timestamp":1734114557313,"type":"change","change_id":15557283145,"instrument_name":"ETH-PERPETUAL","bids":[],"asks":[["change",3896.4,1.6e5]],"prev_change_id":15557283144}}}
{"jsonrpc":"2.0","method":"subscription","params":{"channel":"book.ETH-PERPETUAL.raw","data":{"timestamp":1734114557313,"type":"change","change_id":15557283145,"instrument_name":"ETH-PERPETUAL","bids":[],"asks":[["change",3896.4,1.6e5]],"prev_change_id":15557283144}}}
{"jsonrpc":"2.0","method":"subscription","params":{"channel":"book.ETH-PERPETUAL.raw","data":{"timestamp":1734114557313,"type":"change","change_id":15557283146,"instrument_name":"ETH-PERPETUAL","bids":[["change",3881.15,2.0e5]],"asks":[],"prev_change_id":15557283145}}}
{"jsonrpc":"2.0","method":"subscription","params":{"channel":"book.ETH-PERPETUAL.raw","data":{"timestamp":1734114557313,"type":"change","change_id":15557283146,"instrument_name":"ETH-PERPETUAL","bids":[["change",3881.15,2.0e5]],"asks":[],"prev_change_id":15557283145}}}
{"jsonrpc":"2.0","method":"subscription","params":{"channel":"book.ETH-PERPETUAL.raw","data":{"timestamp":1734114557447,"type":"change","change_id":15557283147,"instrument_name":"ETH-PERPETUAL","bids":[["delete",3881.15,0.0]],"asks":[["delete",3896.4,0.0]],"prev_change_id":15557283146}}}
{"jsonrpc":"2.0","method":"subscription","params":{"channel":"book.ETH-PERPETUAL.raw","data":{"timestamp":1734114557447,"type":"change","change_id":15557283147,"instrument_name":"ETH-PERPETUAL","bids":[["delete",3881.15,0.0]],"asks":[["delete",3896.4,0.0]],"prev_change_id":15557283146}}}
{"jsonrpc":"2.0","method":"subscription","params":{"channel":"book.ETH-PERPETUAL.raw","data":{"timestamp":1734114557633,"type":"change","change_id":15557283148,"instrument_name":"ETH-PERPETUAL","bids":[["new",3881.15,8.0e4]],"asks":[],"prev_change_id":15557283147}}}
{"jsonrpc":"2.0","method":"subscription","params":{"channel":"book.ETH-PERPETUAL.raw","data":{"timestamp":1734114557633,"type":"change","change_id":15557283148,"instrument_name":"ETH-PERPETUAL","bids":[["new",3881.15,8.0e4]],"asks":[],"prev_change_id":15557283147}}}
{"jsonrpc":"2.0","method":"subscription","params":{"channel":"book.ETH-PERPETUAL.raw","data":{"timestamp":1734114557635,"type":"change","change_id":15557283149,"instrument_name":"ETH-PERPETUAL","bids":[],"asks":[["new",3896.4,8.0e4]],"prev_change_id":15557283148}}}
{"jsonrpc":"2.0","method":"subscription","params":{"channel":"book.ETH-PERPETUAL.raw","data":{"timestamp":1734114557635,"type":"change","change_id":15557283149,"instrument_name":"ETH-PERPETUAL","bids":[],"asks":[["new",3896.4,8.0e4]],"prev_change_id":15557283148}}}
{"jsonrpc":"2.0","method":"subscription","params":{"channel":"book.ETH-PERPETUAL.raw","data":{"timestamp":1734114557637,"type":"change","change_id":15557283150,"instrument_name":"ETH-PERPETUAL","bids":[["change",3881.15,1.0e5]],"asks":[],"prev_change_id":15557283149}}}
{"jsonrpc":"2.0","method":"subscription","params":{"channel":"book.ETH-PERPETUAL.raw","data":{"timestamp":1734114557637,"type":"change","change_id":15557283150,"instrument_name":"ETH-PERPETUAL","bids":[["change",3881.15,1.0e5]],"asks":[],"prev_change_id":15557283149}}}
{"jsonrpc":"2.0","method":"subscription","params":{"channel":"book.ETH-PERPETUAL.raw","data":{"timestamp":1734114557638,"type":"change","change_id":15557283151,"instrument_name":"ETH-PERPETUAL","bids":[["change",3881.15,1.8e5]],"asks":[],"prev_change_id":15557283150}}}
{"jsonrpc":"2.0","method":"subscription","params":{"channel":"book.ETH-PERPETUAL.raw","data":{"timestamp":1734114557638,"type":"change","change_id":15557283151,"instrument_name":"ETH-PERPETUAL","bids":[["change",3881.15,1.8e5]],"asks":[],"prev_change_id":15557283150}}}
{"jsonrpc":"2.0","method":"subscription","params":{"channel":"book.ETH-PERPETUAL.raw","data":{"timestamp":1734114557639,"type":"change","change_id":15557283152,"instrument_name":"ETH-PERPETUAL","bids":[],"asks":[["change",3896.4,1.6e5]],"prev_change_id":15557283151}}}
{"jsonrpc":"2.0","method":"subscription","params":{"channel":"book.ETH-PERPETUAL.raw","data":{"timestamp":1734114557639,"type":"change","change_id":15557283152,"instrument_name":"ETH-PERPETUAL","bids":[],"asks":[["change",3896.4,1.6e5]],"prev_change_id":15557283151}}}
{"jsonrpc":"2.0","method":"subscription","params":{"channel":"book.ETH-PERPETUAL.raw","data":{"timestamp":1734114557641,"type":"change","change_id":15557283153,"instrument_name":"ETH-PERPETUAL","bids":[["change",3881.15,2.0e5]],"asks":[],"prev_change_id":15557283152}}}
{"jsonrpc":"2.0","method":"subscription","params":{"channel":"book.ETH-PERPETUAL.raw","data":{"timestamp":1734114557641,"type":"change","change_id":15557283153,"instrument_name":"ETH-PERPETUAL","bids":[["change",3881.15,2.0e5]],"asks":[],"prev_change_id":15557283152}}}
{"jsonrpc":"2.0","method":"subscription","params":{"channel":"book.ETH-PERPETUAL.raw","data":{"timestamp":1734114557768,"type":"change","change_id":15557283168,"instrument_name":"ETH-PERPETUAL","bids":[["delete",3881.15,0.0]],"asks":[["delete",3896.4,0.0]],"prev_change_id":15557283153}}}
{"jsonrpc":"2.0","method":"subscription","params":{"channel":"book.ETH-PERPETUAL.raw","data":{"timestamp":1734114557768,"type":"change","change_id":15557283168,"instrument_name":"ETH-PERPETUAL","bids":[["delete",3881.15,0.0]],"asks":[["delete",3896.4,0.0]],"prev_change_id":15557283153}}}
{"jsonrpc":"2.0","method":"subscription","params":{"channel":"book.ETH-PERPETUAL.raw","data":{"timestamp":1734114557784,"type":"change","change_id":15557283169,"instrument_name":"ETH-PERPETUAL","bids":[],"asks":[["new",3915.9,500.0],["delete",3928.1,0.0]],"prev_change_id":15557283168}}}
{"jsonrpc":"2.0","method":"subscription","params":{"channel":"book.ETH-PERPETUAL.raw","data":{"timestamp":1734114557784,"type":"change","change_id":15557283169,"instrument_name":"ETH-PERPETUAL","bids":[],"asks":[["new",3915.9,500.0],["delete",3928.1,0.0]],"prev_change_id":15557283168}}}
{"jsonrpc":"2.0","method":"subscription","params":{"channel":"book.ETH-PERPETUAL.raw","data":{"timestamp":1734114557984,"type":"change","change_id":15557283170,"instrument_name":"ETH-PERPETUAL","bids":[["new",3881.15,8.0e4]],"asks":[],"prev_change_id":15557283169}}}
{"jsonrpc":"2.0","method":"subscription","params":{"channel":"book.ETH-PERPETUAL.raw","data":{"timestamp":1734114557984,"type":"change","change_id":15557283170,"instrument_name":"ETH-PERPETUAL","bids":[["new",3881.15,8.0e4]],"asks":[],"prev_change_id":15557283169}}}
{"jsonrpc":"2.0","method":"subscription","params":{"channel":"book.ETH-PERPETUAL.raw","data":{"timestamp":1734114557985,"type":"change","change_id":15557283171,"instrument_name":"ETH-PERPETUAL","bids":[],"asks":[["new",3896.4,8.0e4]],"prev_change_id":15557283170}}}
{"jsonrpc":"2.0","method":"subscription","params":{"channel":"book.ETH-PERPETUAL.raw","data":{"timestamp":1734114557985,"type":"change","change_id":15557283171,"instrument_name":"ETH-PERPETUAL","bids":[],"asks":[["new",3896.4,8.0e4]],"prev_change_id":15557283170}}}
{"jsonrpc":"2.0","method":"subscription","params":{"channel":"book.ETH-PERPETUAL.raw","data":{"timestamp":1734114557986,"type":"change","change_id":15557283172,"instrument_name":"ETH-PERPETUAL","bids":[["change",3881.15,1.0e5]],"asks":[],"prev_change_id":15557283171}}}
{"jsonrpc":"2.0","method":"subscription","params":{"channel":"book.ETH-PERPETUAL.raw","data":{"timestamp":1734114557986,"type":"change","change_id":15557283172,"instrument_name":"ETH-PERPETUAL","bids":[["change",3881.15,1.0e5]],"asks":[],"prev_change_id":15557283171}}}
{"jsonrpc":"2.0","method":"subscription","params":{"channel":"book.ETH-PERPETUAL.raw","data":{"timestamp":1734114557987,"type":"change","change_id":15557283173,"instrument_name":"ETH-PERPETUAL","bids":[["change",3881.15,1.8e5]],"asks":[],"prev_change_id":15557283172}}}
{"jsonrpc":"2.0","method":"subscription","params":{"channel":"book.ETH-PERPETUAL.raw","data":{"timestamp":1734114557987,"type":"change","change_id":15557283173,"instrument_name":"ETH-PERPETUAL","bids":[["change",3881.15,1.8e5]],"asks":[],"prev_change_id":15557283172}}}
{"jsonrpc":"2.0","method":"subscription","params":{"channel":"book.ETH-PERPETUAL.raw","data":{"timestamp":1734114557988,"type":"change","change_id":15557283174,"instrument_name":"ETH-PERPETUAL","bids":[],"asks":[["change",3896.4,1.6e5]],"prev_change_id":15557283173}}}
{"jsonrpc":"2.0","method":"subscription","params":{"channel":"book.ETH-PERPETUAL.raw","data":{"timestamp":1734114557988,"type":"change","change_id":15557283174,"instrument_name":"ETH-PERPETUAL","bids":[],"asks":[["change",3896.4,1.6e5]],"prev_change_id":15557283173}}}
{"jsonrpc":"2.0","method":"subscription","params":{"channel":"book.ETH-PERPETUAL.raw","data":{"timestamp":1734114557989,"type":"change","change_id":15557283175,"instrument_name":"ETH-PERPETUAL","bids":[["change",3881.15,2.0e5]],"asks":[],"prev_change_id":15557283174}}}
{"jsonrpc":"2.0","method":"subscription","params":{"channel":"book.ETH-PERPETUAL.raw","data":{"timestamp":1734114557989,"type":"change","change_id":15557283175,"instrument_name":"ETH-PERPETUAL","bids":[["change",3881.15,2.0e5]],"asks":[],"prev_change_id":15557283174}}}
{"jsonrpc":"2.0","method":"subscription","params":{"channel":"book.ETH-PERPETUAL.raw","data":{"timestamp":1734114558154,"type":"change","change_id":15557283176,"instrument_name":"ETH-PERPETUAL","bids":[["delete",3881.15,0.0]],"asks":[["delete",3896.4,0.0]],"prev_change_id":15557283175}}}
{"jsonrpc":"2.0","method":"subscription","params":{"channel":"book.ETH-PERPETUAL.raw","data":{"timestamp":1734114558154,"type":"change","change_id":15557283176,"instrument_name":"ETH-PERPETUAL","bids":[["delete",3881.15,0.0]],"asks":[["delete",3896.4,0.0]],"prev_change_id":15557283175}}}
{"jsonrpc":"2.0","method":"subscription","params":{"channel":"book.ETH-PERPETUAL.raw","data":{"timestamp":1734114558374,"type":"change","change_id":15557283178,"instrument_name":"ETH-PERPETUAL","bids":[["new",3881.15,8.0e4]],"asks":[],"prev_change_id":15557283176}}}
{"jsonrpc":"2.0","method":"subscription","params":{"channel":"book.ETH-PERPETUAL.raw","data":{"timestamp":1734114558374,"type":"change","change_id":15557283178,"instrument_name":"ETH-PERPETUAL","bids":[["new",3881.15,8.0e4]],"asks":[],"prev_change_id":15557283176}}}
{"jsonrpc":"2.0","method":"subscription","params":{"channel":"book.ETH-PERPETUAL.raw","data":{"timestamp":1734114558376,"type":"change","change_id":15557283179,"instrument_name":"ETH-PERPETUAL","bids":[],"asks":[["new",3896.35,8.0e4]],"prev_change_id":15557283178}}}
{"jsonrpc":"2.0","method":"subscription","params":{"channel":"book.ETH-PERPETUAL.raw","data":{"timestamp":1734114558376,"type":"change","change_id":15557283179,"instrument_name":"ETH-PERPETUAL","bids":[],"asks":[["new",3896.35,8.0e4]],"prev_change_id":15557283178}}}
{"jsonrpc":"2.0","method":"subscription","params":{"channel":"book.ETH-PERPETUAL.raw","data":{"timestamp":1734114558377,"type":"change","change_id":15557283180,"instrument_name":"ETH-PERPETUAL","bids":[["change",3881.15,1.0e5]],"asks":[],"prev_change_id":15557283179}}}
{"jsonrpc":"2.0","method":"subscription","params":{"channel":"book.ETH-PERPETUAL.raw","data":{"timestamp":1734114558377,"type":"change","change_id":15557283180,"instrument_name":"ETH-PERPETUAL","bids":[["change",3881.15,1.0e5]],"asks":[],"prev_change_id":15557283179}}}
{"jsonrpc":"2.0","method":"subscription","params":{"channel":"book.ETH-PERPETUAL.raw","data":{"timestamp":1734114558379,"type":"change","change_id":15557283181,"instrument_name":"ETH-PERPETUAL","bids":[],"asks":[["change",3896.35,1.0e5]],"prev_change_id":15557283180}}}
{"jsonrpc":"2.0","method":"subscription","params":{"channel":"book.ETH-PERPETUAL.raw","data":{"timestamp":1734114558379,"type":"change","change_id":15557283181,"instrument_name":"ETH-PERPETUAL","bids":[],"asks":[["change",3896.35,1.0e5]],"prev_change_id":15557283180}}}
{"jsonrpc":"2.0","method":"subscription","params":{"channel":"book.ETH-PERPETUAL.raw","data":{"timestamp":1734114558381,"type":"change","change_id":15557283182,"instrument_name":"ETH-PERPETUAL","bids":[["change",3881.15,1.8e5]],"asks":[],"prev_change_id":15557283181}}}
{"jsonrpc":"2.0","method":"subscription","params":{"channel":"book.ETH-PERPETUAL.raw","data":{"timestamp":1734114558381,"type":"change","change_id":15557283182,"instrument_name":"ETH-PERPETUAL","bids":[["change",3881.15,1.8e5]],"asks":[],"prev_change_id":15557283181}}}
{"jsonrpc":"2.0","method":"subscription","params":{"channel":"book.ETH-PERPETUAL.raw","data":{"timestamp":1734114558383,"type":"change","change_id":15557283183,"instrument_name":"ETH-PERPETUAL","bids":[],"asks":[["change",3896.35,1.8e5]],"prev_change_id":15557283182}}}
{"jsonrpc":"2.0","method":"subscription","params":{"channel":"book.ETH-PERPETUAL.raw","data":{"timestamp":1734114558383,"type":"change","change_id":15557283183,"instrument_name":"ETH-PERPETUAL","bids":[],"asks":[["change",3896.35,1.8e5]],"prev_change_id":15557283182}}}
{"jsonrpc":"2.0","method":"subscription","params":{"channel":"book.ETH-PERPETUAL.raw","data":{"timestamp":1734114558384,"type":"change","change_id":15557283184,"instrument_name":"ETH-PERPETUAL","bids":[["change",3881.15,2.0e5]],"asks":[],"prev_change_id":15557283183}}}
{"jsonrpc":"2.0","method":"subscription","params":{"channel":"book.ETH-PERPETUAL.raw","data":{"timestamp":1734114558384,"type":"change","change_id":15557283184,"instrument_name":"ETH-PERPETUAL","bids":[["change",3881.15,2.0e5]],"asks":[],"prev_change_id":15557283183}}}
{"jsonrpc":"2.0","method":"subscription","params":{"channel":"book.ETH-PERPETUAL.raw","data":{"timestamp":1734114558385,"type":"change","change_id":15557283185,"instrument_name":"ETH-PERPETUAL","bids":[],"asks":[["change",3896.35,2.0e5]],"prev_change_id":15557283184}}}
{"jsonrpc":"2.0","method":"subscription","params":{"channel":"book.ETH-PERPETUAL.raw","data":{"timestamp":1734114558385,"type":"change","change_id":15557283185,"instrument_name":"ETH-PERPETUAL","bids":[],"asks":[["change",3896.35,2.0e5]],"prev_change_id":15557283184}}}
{"jsonrpc":"2.0","method":"subscription","params":{"channel":"book.ETH-PERPETUAL.raw","data":{"timestamp":1734114558476,"type":"change","change_id":15557283186,"instrument_name":"ETH-PERPETUAL","bids":[["delete",3881.15,0.0]],"asks":[["delete",3896.35,0.0]],"prev_change_id":15557283185}}}
{"jsonrpc":"2.0","method":"subscription","params":{"channel":"book.ETH-PERPETUAL.raw","data":{"timestamp":1734114558476,"type":"change","change_id":15557283186,"instrument_name":"ETH-PERPETUAL","bids":[["delete",3881.15,0.0]],"asks":[["delete",3896.35,0.0]],"prev_change_id":15557283185}}}
{"jsonrpc":"2.0","method":"subscription","params":{"channel":"book.ETH-PERPETUAL.raw","data":{"timestamp":1734114558693,"type":"change","change_id":15557283187,"instrument_name":"ETH-PERPETUAL","bids":[["new",3881.2,8.0e4]],"asks":[],"prev_change_id":15557283186}}}
{"jsonrpc":"2.0","method":"subscription","params":{"channel":"book.ETH-PERPETUAL.raw","data":{"timestamp":1734114558693,"type":"change","change_id":15557283187,"instrument_name":"ETH-PERPETUAL","bids":[["new",3881.2,8.0e4]],"asks":[],"prev_change_id":15557283186}}}
{"jsonrpc":"2.0","method":"subscription","params":{"channel":"book.ETH-PERPETUAL.raw","data":{"timestamp":1734114558694,"type":"change","change_id":15557283189,"instrument_name":"ETH-PERPETUAL","bids":[],"asks":[["new",3896.4,8.0e4]],"prev_change_id":15557283187}}}
{"jsonrpc":"2.0","method":"subscription","params":{"channel":"book.ETH-PERPETUAL.raw","data":{"timestamp":1734114558694,"type":"change","change_id":15557283189,"instrument_name":"ETH-PERPETUAL","bids":[],"asks":[["new",3896.4,8.0e4]],"prev_change_id":15557283187}}}
{"jsonrpc":"2.0","method":"subscription","params":{"channel":"book.ETH-PERPETUAL.raw","data":{"timestamp":1734114558695,"type":"change","change_id":15557283191,"instrument_name":"ETH-PERPETUAL","bids":[["change",3881.2,1.0e5]],"asks":[],"prev_change_id":15557283189}}}
{"jsonrpc":"2.0","method":"subscription","params":{"channel":"book.ETH-PERPETUAL.raw","data":{"timestamp":1734114558695,"type":"change","change_id":15557283191,"instrument_name":"ETH-PERPETUAL","bids":[["change",3881.2,1.0e5]],"asks":[],"prev_change_id":15557283189}}}
{"jsonrpc":"2.0","method":"subscription","params":{"channel":"book.ETH-PERPETUAL.raw","data":{"timestamp":1734114558696,"type":"change","change_id":15557283193,"instrument_name":"ETH-PERPETUAL","bids":[["change",3881.2,1.8e5]],"asks":[],"prev_change_id":15557283191}}}
{"jsonrpc":"2.0","method":"subscription","params":{"channel":"book.ETH-PERPETUAL.raw","data":{"timestamp":1734114558696,"type":"change","change_id":15557283193,"instrument_name":"ETH-PERPETUAL","bids":[["change",3881.2,1.8e5]],"asks":[],"prev_change_id":15557283191}}}
{"jsonrpc":"2.0","method":"subscription","params":{"channel":"book.ETH-PERPETUAL.raw","data":{"timestamp":1734114558697,"type":"change","change_id":15557283194,"instrument_name":"ETH-PERPETUAL","bids":[],"asks":[["change",3896.4,1.6e5]],"prev_change_id":15557283193}}}
{"jsonrpc":"2.0","method":"subscription","params":{"channel":"book.ETH-PERPETUAL.raw","data":{"timestamp":1734114558697,"type":"change","change_id":15557283194,"instrument_name":"ETH-PERPETUAL","bids":[],"asks":[["change",3896.4,1.6e5]],"prev_change_id":15557283193}}}
{"jsonrpc":"2.0","method":"subscription","params":{"channel":"book.ETH-PERPETUAL.raw","data":{"timestamp":1734114558698,"type":"change","change_id":15557283195,"instrument_name":"ETH-PERPETUAL","bids":[["change",3881.2,2.0e5]],"asks":[],"prev_change_id":15557283194}}}
{"jsonrpc":"2.0","method":"subscription","params":{"channel":"book.ETH-PERPETUAL.raw","data":{"timestamp":1734114558698,"type":"change","change_id":15557283195,"instrument_name":"ETH-PERPETUAL","bids":[["change",3881.2,2.0e5]],"asks":[],"prev_change_id":15557283194}}}
{"jsonrpc":"2.0","method":"subscription","params":{"channel":"book.ETH-PERPETUAL.raw","data":{"timestamp":1734114558831,"type":"change","change_id":15557283210,"instrument_name":"ETH-PERPETUAL","bids":[["delete",3881.2,0.0]],"asks":[["delete",3896.4,0.0]],"prev_change_id":15557283195}}}
{"jsonrpc":"2.0","method":"subscription","params":{"channel":"book.ETH-PERPETUAL.raw","data":{"timestamp":1734114558831,"type":"change","change_id":15557283210,"instrument_name":"ETH-PERPETUAL","bids":[["delete",3881.2,0.0]],"asks":[["delete",3896.4,0.0]],"prev_change_id":15557283195}}}
{"jsonrpc":"2.0","method":"subscription","params":{"channel":"book.ETH-PERPETUAL.raw","data":{"timestamp":1734114558980,"type":"change","change_id":15557283211,"instrument_name":"ETH-PERPETUAL","bids":[["delete",3842.5,0.0],["new",3828.75,700.0]],"asks":[],"prev_change_id":15557283210}}}
{"jsonrpc":"2.0","method":"subscription","params":{"channel":"book.ETH-PERPETUAL.raw","data":{"timestamp":1734114558980,"type":"change","change_id":15557283211,"instrument_name":"ETH-PERPETUAL","bids":[["delete",3842.5,0.0],["new",3828.75,700.0]],"asks":[],"prev_change_id":15557283210}}}
{"jsonrpc":"2.0","method":"subscription","params":{"channel":"book.ETH-PERPETUAL.raw","data":{"timestamp":1734114558981,"type":"change","change_id":15557283212,"instrument_name":"ETH-PERPETUAL","bids":[["delete",3861.9,0.0],["new",3850.35,500.0]],"asks":[],"prev_change_id":15557283211}}}
{"jsonrpc":"2.0","method":"subscription","params":{"channel":"book.ETH-PERPETUAL.raw","data":{"timestamp":1734114558981,"type":"change","change_id":15557283212,"instrument_name":"ETH-PERPETUAL","bids":[["delete",3861.9,0.0],["new",3850.35,500.0]],"asks":[],"prev_change_id":15557283211}}}
{"jsonrpc":"2.0","method":"subscription","params":{"channel":"book.ETH-PERPETUAL.raw","data":{"timestamp":1734114559031,"type":"change","change_id":15557283213,"instrument_name":"ETH-PERPETUAL","bids":[],"asks":[["new",3896.4,8.0e4]],"prev_change_id":15557283212}}}
{"jsonrpc":"2.0","method":"subscription","params":{"channel":"book.ETH-PERPETUAL.raw","data":{"timestamp":1734114559031,"type":"change","change_id":15557283213,"instrument_name":"ETH-PERPETUAL","bids":[],"asks":[["new",3896.4,8.0e4]],"prev_change_id":15557283212}}}
{"jsonrpc":"2.0","method":"subscription","params":{"channel":"book.ETH-PERPETUAL.raw","data":{"timestamp":1734114559032,"type":"change","change_id":15557283214,"instrument_name":"ETH-PERPETUAL","bids":[["new",3881.2,8.0e4]],"asks":[],"prev_change_id":15557283213}}}
{"jsonrpc":"2.0","method":"subscription","params":{"channel":"book.ETH-PERPETUAL.raw","data":{"timestamp":1734114559032,"type":"change","change_id":15557283214,"instrument_name":"ETH-PERPETUAL","bids":[["new",3881.2,8.0e4]],"asks":[],"prev_change_id":15557283213}}}
{"jsonrpc":"2.0","method":"subscription","params":{"channel":"book.ETH-PERPETUAL.raw","data":{"timestamp":1734114559033,"type":"change","change_id":15557283215,"instrument_name":"ETH-PERPETUAL","bids":[["change",3881.2,1.0e5]],"asks":[],"prev_change_id":15557283214}}}
{"jsonrpc":"2.0","method":"subscription","params":{"channel":"book.ETH-PERPETUAL.raw","data":{"timestamp":1734114559033,"type":"change","change_id":15557283215,"instrument_name":"ETH-PERPETUAL","bids":[["change",3881.2,1.0e5]],"asks":[],"prev_change_id":15557283214}}}
{"jsonrpc":"2.0","method":"subscription","params":{"channel":"book.ETH-PERPETUAL.raw","data":{"timestamp":1734114559035,"type":"change","change_id":15557283216,"instrument_name":"ETH-PERPETUAL","bids":[],"asks":[["change",3896.4,1.0e5]],"prev_change_id":15557283215}}}
{"jsonrpc":"2.0","method":"subscription","params":{"channel":"book.ETH-PERPETUAL.raw","data":{"timestamp":1734114559035,"type":"change","change_id":15557283216,"instrument_name":"ETH-PERPETUAL","bids":[],"asks":[["change",3896.4,1.0e5]],"prev_change_id":15557283215}}}
{"jsonrpc":"2.0","method":"subscription","params":{"channel":"book.ETH-PERPETUAL.raw","data":{"timestamp":1734114559036,"type":"change","change_id":15557283217,"instrument_name":"ETH-PERPETUAL","bids":[],"asks":[["change",3896.4,1.8e5]],"prev_change_id":15557283216}}}
{"jsonrpc":"2.0","method":"subscription","params":{"channel":"book.ETH-PERPETUAL.raw","data":{"timestamp":1734114559036,"type":"change","change_id":15557283217,"instrument_name":"ETH-PERPETUAL","bids":[],"asks":[["change",3896.4,1.8e5]],"prev_change_id":15557283216}}}
{"jsonrpc":"2.0","method":"subscription","params":{"channel":"book.ETH-PERPETUAL.raw","data":{"timestamp":1734114559037,"type":"change","change_id":15557283218,"instrument_name":"ETH-PERPETUAL","bids":[["change",3881.2,1.8e5]],"asks":[],"prev_change_id":15557283217}}}
{"jsonrpc":"2.0","method":"subscription","params":{"channel":"book.ETH-PERPETUAL.raw","data":{"timestamp":1734114559037,"type":"change","change_id":15557283218,"instrument_name":"ETH-PERPETUAL","bids":[["change",3881.2,1.8e5]],"asks":[],"prev_change_id":15557283217}}}
{"jsonrpc":"2.0","method":"subscription","params":{"channel":"book.ETH-PERPETUAL.raw","data":{"timestamp":1734114559038,"type":"change","change_id":15557283219,"instrument_name":"ETH-PERPETUAL","bids":[["change",3881.2,2.0e5]],"asks":[],"prev_change_id":15557283218}}}
{"jsonrpc":"2.0","method":"subscription","params":{"channel":"book.ETH-PERPETUAL.raw","data":{"timestamp":1734114559038,"type":"change","change_id":15557283219,"instrument_name":"ETH-PERPETUAL","bids":[["change",3881.2,2.0e5]],"asks":[],"prev_change_id":15557283218}}}
{"jsonrpc":"2.0","method":"subscription","params":{"channel":"book.ETH-PERPETUAL.raw","data":{"timestamp":1734114559039,"type":"change","change_id":15557283220,"instrument_name":"ETH-PERPETUAL","bids":[],"asks":[["change",3896.4,2.0e5]],"prev_change_id":15557283219}}}
{"jsonrpc":"2.0","method":"subscription","params":{"channel":"book.ETH-PERPETUAL.raw","data":{"timestamp":1734114559039,"type":"change","change_id":15557283220,"instrument_name":"ETH-PERPETUAL","bids":[],"asks":[["change",3896.4,2.0e5]],"prev_change_id":15557283219}}}
{"jsonrpc":"2.0","method":"subscription","params":{"channel":"book.ETH-PERPETUAL.raw","data":{"timestamp":1734114559174,"type":"change","change_id":15557283222,"instrument_name":"ETH-PERPETUAL","bids":[["delete",3881.2,0.0]],"asks":[["delete",3896.4,0.0]],"prev_change_id":15557283220}}}
{"jsonrpc":"2.0","method":"subscription","params":{"channel":"book.ETH-PERPETUAL.raw","data":{"timestamp":1734114559174,"type":"change","change_id":15557283222,"instrument_name":"ETH-PERPETUAL","bids":[["delete",3881.2,0.0]],"asks":[["delete",3896.4,0.0]],"prev_change_id":15557283220}}}
{"jsonrpc":"2.0","method":"subscription","params":{"channel":"book.ETH-PERPETUAL.raw","data":{"timestamp":1734114559319,"type":"change","change_id":15557283223,"instrument_name":"ETH-PERPETUAL","bids":[["delete",3869.7,0.0],["new",3858.05,500.0]],"asks":[],"prev_change_id":15557283222}}}
{"jsonrpc":"2.0","method":"subscription","params":{"channel":"book.ETH-PERPETUAL.raw","data":{"timestamp":1734114559319,"type":"change","change_id":15557283223,"instrument_name":"ETH-PERPETUAL","bids":[["delete",3869.7,0.0],["new",3858.05,500.0]],"asks":[],"prev_change_id":15557283222}}}
{"jsonrpc":"2.0","method":"subscription","params":{"channel":"book.ETH-PERPETUAL.raw","data":{"timestamp":1734114559382,"type":"change","change_id":15557283224,"instrument_name":"ETH-PERPETUAL","bids":[["new",3881.2,8.0e4]],"asks":[],"prev_change_id":15557283223}}}
{"jsonrpc":"2.0","method":"subscription","params":{"channel":"book.ETH-PERPETUAL.raw","data":{"timestamp":1734114559382,"type":"change","change_id":15557283224,"instrument_name":"ETH-PERPETUAL","bids":[["new",3881.2,8.0e4]],"asks":[],"prev_change_id":15557283223}}}
{"jsonrpc":"2.0","method":"subscription","params":{"channel":"book.ETH-PERPETUAL.raw","data":{"timestamp":1734114559384,"type":"change","change_id":15557283225,"instrument_name":"ETH-PERPETUAL","bids":[],"asks":[["new",3896.4,8.0e4]],"prev_change_id":15557283224}}}
{"jsonrpc":"2.0","method":"subscription","params":{"channel":"book.ETH-PERPETUAL.raw","data":{"timestamp":1734114559384,"type":"change","change_id":15557283225,"instrument_name":"ETH-PERPETUAL","bids":[],"asks":[["new",3896.4,8.0e4]],"prev_change_id":15557283224}}}
{"jsonrpc":"2.0","method":"subscription","params":{"channel":"book.ETH-PERPETUAL.raw","data":{"timestamp":1734114559385,"type":"change","change_id":15557283226,"instrument_name":"ETH-PERPETUAL","bids":[["change",3881.2,1.6e5]],"asks":[],"prev_change_id":15557283225}}}
{"jsonrpc":"2.0","method":"subscription","params":{"channel":"book.ETH-PERPETUAL.raw","data":{"timestamp":1734114559385,"type":"change","change_id":15557283226,"instrument_name":"ETH-PERPETUAL","bids":[["change",3881.2,1.6e5]],"asks":[],"prev_change_id":15557283225}}}
{"jsonrpc":"2.0","method":"subscription","params":{"channel":"book.ETH-PERPETUAL.raw","data":{"timestamp":1734114559386,"type":"change","change_id":15557283227,"instrument_name":"ETH-PERPETUAL","bids":[],"asks":[["change",3896.4,1.6e5]],"prev_change_id":15557283226}}}
{"jsonrpc":"2.0","method":"subscription","params":{"channel":"book.ETH-PERPETUAL.raw","data":{"timestamp":1734114559386,"type":"change","change_id":15557283227,"instrument_name":"ETH-PERPETUAL","bids":[],"asks":[["change",3896.4,1.6e5]],"prev_change_id":15557283226}}}
{"jsonrpc":"2.0","method":"subscription","params":{"channel":"book.ETH-PERPETUAL.raw","data":{"timestamp":1734114559531,"type":"change","change_id":15557283228,"instrument_name":"ETH-PERPETUAL","bids":[["delete",3881.2,0.0]],"asks":[["delete",3896.4,0.0]],"prev_change_id":15557283227}}}
{"jsonrpc":"2.0","method":"subscription","params":{"channel":"book.ETH-PERPETUAL.raw","data":{"timestamp":1734114559531,"type":"change","change_id":15557283228,"instrument_name":"ETH-PERPETUAL","bids":[["delete",3881.2,0.0]],"asks":[["delete",3896.4,0.0]],"prev_change_id":15557283227}}}
{"jsonrpc":"2.0","method":"subscription","params":{"channel":"book.ETH-PERPETUAL.raw","data":{"timestamp":1734114559747,"type":"change","change_id":15557283245,"instrument_name":"ETH-PERPETUAL","bids":[["new",3881.25,8.0e4]],"asks":[],"prev_change_id":15557283228}}}
{"jsonrpc":"2.0","method":"subscription","params":{"channel":"book.ETH-PERPETUAL.raw","data":{"timestamp":1734114559747,"type":"change","change_id":15557283245,"instrument_name":"ETH-PERPETUAL","bids":[["new",3881.25,8.0e4]],"asks":[],"prev_change_id":15557283228}}}
{"jsonrpc":"2.0","method":"subscription","params":{"channel":"book.ETH-PERPETUAL.raw","data":{"timestamp":1734114559750,"type":"change","change_id":15557283246,"instrument_name":"ETH-PERPETUAL","bids":[],"asks":[["new",3896.4,8.0e4]],"prev_change_id":15557283245}}}
{"jsonrpc":"2.0","method":"subscription","params":{"channel":"book.ETH-PERPETUAL.raw","data":{"timestamp":1734114559750,"type":"change","change_id":15557283246,"instrument_name":"ETH-PERPETUAL","bids":[],"asks":[["new",3896.4,8.0e4]],"prev_change_id":15557283245}}}
{"jsonrpc":"2.0","method":"subscription","params":{"channel":"book.ETH-PERPETUAL.raw","data":{"timestamp":1734114559752,"type":"change","change_id":15557283247,"instrument_name":"ETH-PERPETUAL","bids":[["change",3881.25,1.0e5]],"asks":[],"prev_change_id":15557283246}}}
{"jsonrpc":"2.0","method":"subscription","params":{"channel":"book.ETH-PERPETUAL.raw","data":{"timestamp":1734114559752,"type":"change","change_id":15557283247,"instrument_name":"ETH-PERPETUAL","bids":[["change",3881.25,1.0e5]],"asks":[],"prev_change_id":15557283246}}}
{"jsonrpc":"2.0","method":"subscription","params":{"channel":"book.ETH-PERPETUAL.raw","data":{"timestamp":1734114559755,"type":"change","change_id":15557283248,"instrument_name":"ETH-PERPETUAL","bids":[],"asks":[["change",3896.4,1.0e5]],"prev_change_id":15557283247}}}
{"jsonrpc":"2.0","method":"subscription","params":{"channel":"book.ETH-PERPETUAL.raw","data":{"timestamp":1734114559755,"type":"change","change_id":15557283248,"instrument_name":"ETH-PERPETUAL","bids":[],"asks":[["change",3896.4,1.0e5]],"prev_change_id":15557283247}}}
{"jsonrpc":"2.0","method":"subscription","params":{"channel":"book.ETH-PERPETUAL.raw","data":{"timestamp":1734114559758,"type":"change","change_id":15557283250,"instrument_name":"ETH-PERPETUAL","bids":[["change",3881.25,1.8e5]],"asks":[],"prev_change_id":15557283248}}}
{"jsonrpc":"2.0","method":"subscription","params":{"channel":"book.ETH-PERPETUAL.raw","data":{"timestamp":1734114559758,"type":"change","change_id":15557283250,"instrument_name":"ETH-PERPETUAL","bids":[["change",3881.25,1.8e5]],"asks":[],"prev_change_id":15557283248}}}
{"jsonrpc":"2.0","method":"subscription","params":{"channel":"book.ETH-PERPETUAL.raw","data":{"timestamp":1734114559760,"type":"change","change_id":15557283253,"instrument_name":"ETH-PERPETUAL","bids":[],"asks":[["change",3896.4,1.8e5]],"prev_change_id":15557283250}}}
{"jsonrpc":"2.0","method":"subscription","params":{"channel":"book.ETH-PERPETUAL.raw","data":{"timestamp":1734114559760,"type":"change","change_id":15557283253,"instrument_name":"ETH-PERPETUAL","bids":[],"asks":[["change",3896.4,1.8e5]],"prev_change_id":15557283250}}}
{"jsonrpc":"2.0","method":"subscription","params":{"channel":"book.ETH-PERPETUAL.raw","data":{"timestamp":1734114559761,"type":"change","change_id":15557283254,"instrument_name":"ETH-PERPETUAL","bids":[["change",3881.25,2.0e5]],"asks":[],"prev_change_id":15557283253}}}
{"jsonrpc":"2.0","method":"subscription","params":{"channel":"book.ETH-PERPETUAL.raw","data":{"timestamp":1734114559761,"type":"change","change_id":15557283254,"instrument_name":"ETH-PERPETUAL","bids":[["change",3881.25,2.0e5]],"asks":[],"prev_change_id":15557283253}}}
{"jsonrpc":"2.0","method":"subscription","params":{"channel":"book.ETH-PERPETUAL.raw","data":{"timestamp":1734114559763,"type":"change","change_id":15557283256,"instrument_name":"ETH-PERPETUAL","bids":[],"asks":[["change",3896.4,2.0e5]],"prev_change_id":15557283254}}}
{"jsonrpc":"2.0","method":"subscription","params":{"channel":"book.ETH-PERPETUAL.raw","data":{"timestamp":1734114559763,"type":"change","change_id":15557283256,"instrument_name":"ETH-PERPETUAL","bids":[],"asks":[["change",3896.4,2.0e5]],"prev_change_id":15557283254}}}
{"jsonrpc":"2.0","method":"subscription","params":{"channel":"book.ETH-PERPETUAL.raw","data":{"timestamp":1734114559924,"type":"change","change_id":15557283262,"instrument_name":"ETH-PERPETUAL","bids":[["delete",3881.25,0.0]],"asks":[["delete",3896.4,0.0]],"prev_change_id":15557283256}}}
{"jsonrpc":"2.0","method":"subscription","params":{"channel":"book.ETH-PERPETUAL.raw","data":{"timestamp":1734114559924,"type":"change","change_id":15557283262,"instrument_name":"ETH-PERPETUAL","bids":[["delete",3881.25,0.0]],"asks":[["delete",3896.4,0.0]],"prev_change_id":15557283256}}}
{"jsonrpc":"2.0","method":"subscription","params":{"channel":"book.ETH-PERPETUAL.raw","data":{"timestamp":1734114560182,"type":"change","change_id":15557283264,"instrument_name":"ETH-PERPETUAL","bids":[["new",3881.25,8.0e4]],"asks":[],"prev_change_id":15557283262}}}
{"jsonrpc":"2.0","method":"subscription","params":{"channel":"book.ETH-PERPETUAL.raw","data":{"timestamp":1734114560182,"type":"change","change_id":15557283264,"instrument_name":"ETH-PERPETUAL","bids":[["new",3881.25,8.0e4]],"asks":[],"prev_change_id":15557283262}}}
{"jsonrpc":"2.0","method":"subscription","params":{"channel":"book.ETH-PERPETUAL.raw","data":{"timestamp":1734114560184,"type":"change","change_id":15557283265,"instrument_name":"ETH-PERPETUAL","bids":[],"asks":[["new",3896.4,8.0e4]],"prev_change_id":15557283264}}}
{"jsonrpc":"2.0","method":"subscription","params":{"channel":"book.ETH-PERPETUAL.raw","data":{"timestamp":1734114560184,"type":"change","change_id":15557283265,"instrument_name":"ETH-PERPETUAL","bids":[],"asks":[["new",3896.4,8.0e4]],"prev_change_id":15557283264}}}
{"jsonrpc":"2.0","method":"subscription","params":{"channel":"book.ETH-PERPETUAL.raw","data":{"timestamp":1734114560184,"type":"change","change_id":15557283266,"instrument_name":"ETH-PERPETUAL","bids":[["change",3881.25,1.0e5]],"asks":[],"prev_change_id":15557283265}}}
{"jsonrpc":"2.0","method":"subscription","params":{"channel":"book.ETH-PERPETUAL.raw","data":{"timestamp":1734114560184,"type":"change","change_id":15557283266,"instrument_name":"ETH-PERPETUAL","bids":[["change",3881.25,1.0e5]],"asks":[],"prev_change_id":15557283265}}}
{"jsonrpc":"2.0","method":"subscription","params":{"channel":"book.ETH-PERPETUAL.raw","data":{"timestamp":1734114560185,"type":"change","change_id":15557283267,"instrument_name":"ETH-PERPETUAL","bids":[],"asks":[["change",3896.4,1.0e5]],"prev_change_id":15557283266}}}
{"jsonrpc":"2.0","method":"subscription","params":{"channel":"book.ETH-PERPETUAL.raw","data":{"timestamp":1734114560185,"type":"change","change_id":15557283267,"instrument_name":"ETH-PERPETUAL","bids":[],"asks":[["change",3896.4,1.0e5]],"prev_change_id":15557283266}}}
{"jsonrpc":"2.0","method":"subscription","params":{"channel":"book.ETH-PERPETUAL.raw","data":{"timestamp":1734114560187,"type":"change","change_id":15557283268,"instrument_name":"ETH-PERPETUAL","bids":[["change",3881.25,1.8e5]],"asks":[],"prev_change_id":15557283267}}}
{"jsonrpc":"2.0","method":"subscription","params":{"channel":"book.ETH-PERPETUAL.raw","data":{"timestamp":1734114560187,"type":"change","change_id":15557283268,"instrument_name":"ETH-PERPETUAL","bids":[["change",3881.25,1.8e5]],"asks":[],"prev_change_id":15557283267}}}
{"jsonrpc":"2.0","method":"subscription","params":{"channel":"book.ETH-PERPETUAL.raw","data":{"timestamp":1734114560190,"type":"change","change_id":15557283269,"instrument_name":"ETH-PERPETUAL","bids":[],"asks":[["change",3896.4,1.8e5]],"prev_change_id":15557283268}}}
{"jsonrpc":"2.0","method":"subscription","params":{"channel":"book.ETH-PERPETUAL.raw","data":{"timestamp":1734114560190,"type":"change","change_id":15557283269,"instrument_name":"ETH-PERPETUAL","bids":[],"asks":[["change",3896.4,1.8e5]],"prev_change_id":15557283268}}}
{"jsonrpc":"2.0","method":"subscription","params":{"channel":"book.ETH-PERPETUAL.raw","data":{"timestamp":1734114560193,"type":"change","change_id":15557283270,"instrument_name":"ETH-PERPETUAL","bids":[["change",3881.25,2.0e5]],"asks":[],"prev_change_id":15557283269}}}
{"jsonrpc":"2.0","method":"subscription","params":{"channel":"book.ETH-PERPETUAL.raw","data":{"timestamp":1734114560193,"type":"change","change_id":15557283270,"instrument_name":"ETH-PERPETUAL","bids":[["change",3881.25,2.0e5]],"asks":[],"prev_change_id":15557283269}}}
{"jsonrpc":"2.0","method":"subscription","params":{"channel":"book.ETH-PERPETUAL.raw","data":{"timestamp":1734114560196,"type":"change","change_id":15557283271,"instrument_name":"ETH-PERPETUAL","bids":[],"asks":[["change",3896.4,2.0e5]],"prev_change_id":15557283270}}}
{"jsonrpc":"2.0","method":"subscription","params":{"channel":"book.ETH-PERPETUAL.raw","data":{"timestamp":1734114560196,"type":"change","change_id":15557283271,"instrument_name":"ETH-PERPETUAL","bids":[],"asks":[["change",3896.4,2.0e5]],"prev_change_id":15557283270}}}
{"jsonrpc":"2.0","method":"subscription","params":{"channel":"book.ETH-PERPETUAL.raw","data":{"timestamp":1734114560378,"type":"change","change_id":15557283272,"instrument_name":"ETH-PERPETUAL","bids":[["delete",3881.25,0.0]],"asks":[["delete",3896.4,0.0]],"prev_change_id":15557283271}}}
{"jsonrpc":"2.0","method":"subscription","params":{"channel":"book.ETH-PERPETUAL.raw","data":{"timestamp":1734114560378,"type":"change","change_id":15557283272,"instrument_name":"ETH-PERPETUAL","bids":[["delete",3881.25,0.0]],"asks":[["delete",3896.4,0.0]],"prev_change_id":15557283271}}}
{"jsonrpc":"2.0","method":"subscription","params":{"channel":"book.ETH-PERPETUAL.raw","data":{"timestamp":1734114560604,"type":"change","change_id":15557283273,"instrument_name":"ETH-PERPETUAL","bids":[["new",3881.2,8.0e4]],"asks":[],"prev_change_id":15557283272}}}
{"jsonrpc":"2.0","method":"subscription","params":{"channel":"book.ETH-PERPETUAL.raw","data":{"timestamp":1734114560604,"type":"change","change_id":15557283273,"instrument_name":"ETH-PERPETUAL","bids":[["new",3881.2,8.0e4]],"asks":[],"prev_change_id":15557283272}}}
{"jsonrpc":"2.0","method":"subscription","params":{"channel":"book.ETH-PERPETUAL.raw","data":{"timestamp":1734114560605,"type":"change","change_id":15557283274,"instrument_name":"ETH-PERPETUAL","bids":[],"asks":[["new",3896.35,8.0e4]],"prev_change_id":15557283273}}}
{"jsonrpc":"2.0","method":"subscription","params":{"channel":"book.ETH-PERPETUAL.raw","data":{"timestamp":1734114560605,"type":"change","change_id":15557283274,"instrument_name":"ETH-PERPETUAL","bids":[],"asks":[["new",3896.35,8.0e4]],"prev_change_id":15557283273}}}
{"jsonrpc":"2.0","method":"subscription","params":{"channel":"book.ETH-PERPETUAL.raw","data":{"timestamp":1734114560606,"type":"change","change_id":15557283275,"instrument_name":"ETH-PERPETUAL","bids":[["change",3881.2,1.0e5]],"asks":[],"prev_change_id":15557283274}}}
{"jsonrpc":"2.0","method":"subscription","params":{"channel":"book.ETH-PERPETUAL.raw","data":{"timestamp":1734114560606,"type":"change","change_id":15557283275,"instrument_name":"ETH-PERPETUAL","bids":[["change",3881.2,1.0e5]],"asks":[],"prev_change_id":15557283274}}}
{"jsonrpc":"2.0","method":"subscription","params":{"channel":"book.ETH-PERPETUAL.raw","data":{"timestamp":1734114560607,"type":"change","change_id":15557283276,"instrument_name":"ETH-PERPETUAL","bids":[],"asks":[["change",3896.35,1.0e5]],"prev_change_id":15557283275}}}
{"jsonrpc":"2.0","method":"subscription","params":{"channel":"book.ETH-PERPETUAL.raw","data":{"timestamp":1734114560607,"type":"change","change_id":15557283276,"instrument_name":"ETH-PERPETUAL","bids":[],"asks":[["change",3896.35,1.0e5]],"prev_change_id":15557283275}}}
{"jsonrpc":"2.0","method":"subscription","params":{"channel":"book.ETH-PERPETUAL.raw","data":{"timestamp":1734114560608,"type":"change","change_id":15557283277,"instrument_name":"ETH-PERPETUAL","bids":[["change",3881.2,1.8e5]],"asks":[],"prev_change_id":15557283276}}}
{"jsonrpc":"2.0","method":"subscription","params":{"channel":"book.ETH-PERPETUAL.raw","data":{"timestamp":1734114560608,"type":"change","change_id":15557283277,"instrument_name":"ETH-PERPETUAL","bids":[["change",3881.2,1.8e5]],"asks":[],"prev_change_id":15557283276}}}
{"jsonrpc":"2.0","method":"subscription","params":{"channel":"book.ETH-PERPETUAL.raw","data":{"timestamp":1734114560609,"type":"change","change_id":15557283278,"instrument_name":"ETH-PERPETUAL","bids":[],"asks":[["change",3896.35,1.8e5]],"prev_change_id":15557283277}}}
{"jsonrpc":"2.0","method":"subscription","params":{"channel":"book.ETH-PERPETUAL.raw","data":{"timestamp":1734114560609,"type":"change","change_id":15557283278,"instrument_name":"ETH-PERPETUAL","bids":[],"asks":[["change",3896.35,1.8e5]],"prev_change_id":15557283277}}}
{"jsonrpc":"2.0","method":"subscription","params":{"channel":"book.ETH-PERPETUAL.raw","data":{"timestamp":1734114560611,"type":"change","change_id":15557283279,"instrument_name":"ETH-PERPETUAL","bids":[["change",3881.2,2.0e5]],"asks":[],"prev_change_id":15557283278}}}
{"jsonrpc":"2.0","method":"subscription","params":{"channel":"book.ETH-PERPETUAL.raw","data":{"timestamp":1734114560611,"type":"change","change_id":15557283279,"instrument_name":"ETH-PERPETUAL","bids":[["change",3881.2,2.0e5]],"asks":[],"prev_change_id":15557283278}}}
{"jsonrpc":"2.0","method":"subscription","params":{"channel":"book.ETH-PERPETUAL.raw","data":{"timestamp":1734114560613,"type":"change","change_id":15557283280,"instrument_name":"ETH-PERPETUAL","bids":[],"asks":[["change",3896.35,2.0e5]],"prev_change_id":15557283279}}}
{"jsonrpc":"2.0","method":"subscription","params":{"channel":"book.ETH-PERPETUAL.raw","data":{"timestamp":1734114560613,"type":"change","change_id":15557283280,"instrument_name":"ETH-PERPETUAL","bids":[],"asks":[["change",3896.35,2.0e5]],"prev_change_id":15557283279}}}
{"jsonrpc":"2.0","method":"subscription","params":{"channel":"book.ETH-PERPETUAL.raw","data":{"timestamp":1734114560755,"type":"change","change_id":15557283297,"instrument_name":"ETH-PERPETUAL","bids":[],"asks":[["new",3935.35,700.0],["delete",3948.1,0.0]],"prev_change_id":15557283280}}}
{"jsonrpc":"2.0","method":"subscription","params":{"channel":"book.ETH-PERPETUAL.raw","data":{"timestamp":1734114560755,"type":"change","change_id":15557283297,"instrument_name":"ETH-PERPETUAL","bids":[],"asks":[["new",3935.35,700.0],["delete",3948.1,0.0]],"prev_change_id":15557283280}}}
{"jsonrpc":"2.0","method":"subscription","params":{"channel":"book.ETH-PERPETUAL.raw","data":{"timestamp":1734114560784,"type":"change","change_id":15557283308,"instrument_name":"ETH-PERPETUAL","bids":[["delete",3881.2,0.0]],"asks":[["delete",3896.35,0.0]],"prev_change_id":15557283297}}}
{"jsonrpc":"2.0","method":"subscription","params":{"channel":"book.ETH-PERPETUAL.raw","data":{"timestamp":1734114560784,"type":"change","change_id":15557283308,"instrument_name":"ETH-PERPETUAL","bids":[["delete",3881.2,0.0]],"asks":[["delete",3896.35,0.0]],"prev_change_id":15557283297}}}
{"jsonrpc":"2.0","method":"subscription","params":{"channel":"book.ETH-PERPETUAL.raw","data":{"timestamp":1734114560989,"type":"change","change_id":15557283316,"instrument_name":"ETH-PERPETUAL","bids":[["new",3881.2,8.0e4]],"asks":[],"prev_change_id":15557283308}}}
{"jsonrpc":"2.0","method":"subscription","params":{"channel":"book.ETH-PERPETUAL.raw","data":{"timestamp":1734114560989,"type":"change","change_id":15557283316,"instrument_name":"ETH-PERPETUAL","bids":[["new",3881.2,8.0e4]],"asks":[],"prev_change_id":15557283308}}}
{"jsonrpc":"2.0","method":"subscription","params":{"channel":"book.ETH-PERPETUAL.raw","data":{"timestamp":1734114560990,"type":"change","change_id":15557283317,"instrument_name":"ETH-PERPETUAL","bids":[],"asks":[["new",3896.35,8.0e4]],"prev_change_id":15557283316}}}
{"jsonrpc":"2.0","method":"subscription","params":{"channel":"book.ETH-PERPETUAL.raw","data":{"timestamp":1734114560990,"type":"change","change_id":15557283317,"instrument_name":"ETH-PERPETUAL","bids":[],"asks":[["new",3896.35,8.0e4]],"prev_change_id":15557283316}}}
{"jsonrpc":"2.0","method":"subscription","params":{"channel":"book.ETH-PERPETUAL.raw","data":{"timestamp":1734114560991,"type":"change","change_id":15557283318,"instrument_name":"ETH-PERPETUAL","bids":[["change",3881.2,1.0e5]],"asks":[],"prev_change_id":15557283317}}}
{"jsonrpc":"2.0","method":"subscription","params":{"channel":"book.ETH-PERPETUAL.raw","data":{"timestamp":1734114560991,"type":"change","change_id":15557283318,"instrument_name":"ETH-PERPETUAL","bids":[["change",3881.2,1.0e5]],"asks":[],"prev_change_id":15557283317}}}
{"jsonrpc":"2.0","method":"subscription","params":{"channel":"book.ETH-PERPETUAL.raw","data":{"timestamp":1734114560992,"type":"change","change_id":15557283319,"instrument_name":"ETH-PERPETUAL","bids":[],"asks":[["change",3896.35,1.0e5]],"prev_change_id":15557283318}}}
{"jsonrpc":"2.0","method":"subscription","params":{"channel":"book.ETH-PERPETUAL.raw","data":{"timestamp":1734114560992,"type":"change","change_id":15557283319,"instrument_name":"ETH-PERPETUAL","bids":[],"asks":[["change",3896.35,1.0e5]],"prev_change_id":15557283318}}}
{"jsonrpc":"2.0","method":"subscription","params":{"channel":"book.ETH-PERPETUAL.raw","data":{"timestamp":1734114560993,"type":"change","change_id":15557283320,"instrument_name":"ETH-PERPETUAL","bids":[["change",3881.2,1.8e5]],"asks":[],"prev_change_id":15557283319}}}
{"jsonrpc":"2.0","method":"subscription","params":{"channel":"book.ETH-PERPETUAL.raw","data":{"timestamp":1734114560993,"type":"change","change_id":15557283320,"instrument_name":"ETH-PERPETUAL","bids":[["change",3881.2,1.8e5]],"asks":[],"prev_change_id":15557283319}}}
{"jsonrpc":"2.0","method":"subscription","params":{"channel":"book.ETH-PERPETUAL.raw","data":{"timestamp":1734114560994,"type":"change","change_id":15557283321,"instrument_name":"ETH-PERPETUAL","bids":[],"asks":[["change",3896.35,1.8e5]],"prev_change_id":15557283320}}}
{"jsonrpc":"2.0","method":"subscription","params":{"channel":"book.ETH-PERPETUAL.raw","data":{"timestamp":1734114560994,"type":"change","change_id":15557283321,"instrument_name":"ETH-PERPETUAL","bids":[],"asks":[["change",3896.35,1.8e5]],"prev_change_id":15557283320}}}
{"jsonrpc":"2.0","method":"subscription","params":{"channel":"book.ETH-PERPETUAL.raw","data":{"timestamp":1734114560995,"type":"change","change_id":15557283322,"instrument_name":"ETH-PERPETUAL","bids":[["change",3881.2,2.0e5]],"asks":[],"prev_change_id":15557283321}}}
{"jsonrpc":"2.0","method":"subscription","params":{"channel":"book.ETH-PERPETUAL.raw","data":{"timestamp":1734114560995,"type":"change","change_id":15557283322,"instrument_name":"ETH-PERPETUAL","bids":[["change",3881.2,2.0e5]],"asks":[],"prev_change_id":15557283321}}}
{"jsonrpc":"2.0","method":"subscription","params":{"channel":"book.ETH-PERPETUAL.raw","data":{"timestamp":1734114560996,"type":"change","change_id":15557283323,"instrument_name":"ETH-PERPETUAL","bids":[],"asks":[["change",3896.35,2.0e5]],"prev_change_id":15557283322}}}
{"jsonrpc":"2.0","method":"subscription","params":{"channel":"book.ETH-PERPETUAL.raw","data":{"timestamp":1734114560996,"type":"change","change_id":15557283323,"instrument_name":"ETH-PERPETUAL","bids":[],"asks":[["change",3896.35,2.0e5]],"prev_change_id":15557283322}}}
{"jsonrpc":"2.0","method":"subscription","params":{"channel":"book.ETH-PERPETUAL.raw","data":{"timestamp":1734114561158,"type":"change","change_id":15557283324,"instrument_name":"ETH-PERPETUAL","bids":[["delete",3881.2,0.0]],"asks":[["delete",3896.35,0.0]],"prev_change_id":15557283323}}}
{"jsonrpc":"2.0","method":"subscription","params":{"channel":"book.ETH-PERPETUAL.raw","data":{"timestamp":1734114561158,"type":"change","change_id":15557283324,"instrument_name":"ETH-PERPETUAL","bids":[["delete",3881.2,0.0]],"asks":[["delete",3896.35,0.0]],"prev_change_id":15557283323}}}
{"jsonrpc":"2.0","method":"subscription","params":{"channel":"book.ETH-PERPETUAL.raw","data":{"timestamp":1734114561372,"type":"change","change_id":15557283326,"instrument_name":"ETH-PERPETUAL","bids":[],"asks":[["new",3896.4,8.0e4]],"prev_change_id":15557283324}}}
{"jsonrpc":"2.0","method":"subscription","params":{"channel":"book.ETH-PERPETUAL.raw","data":{"timestamp":1734114561372,"type":"change","change_id":15557283326,"instrument_name":"ETH-PERPETUAL","bids":[],"asks":[["new",3896.4,8.0e4]],"prev_change_id":15557283324}}}
{"jsonrpc":"2.0","method":"subscription","params":{"channel":"book.ETH-PERPETUAL.raw","data":{"timestamp":1734114561374,"type":"change","change_id":15557283327,"instrument_name":"ETH-PERPETUAL","bids":[["new",3881.25,8.0e4]],"asks":[],"prev_change_id":15557283326}}}
{"jsonrpc":"2.0","method":"subscription","params":{"channel":"book.ETH-PERPETUAL.raw","data":{"timestamp":1734114561374,"type":"change","change_id":15557283327,"instrument_name":"ETH-PERPETUAL","bids":[["new",3881.25,8.0e4]],"asks":[],"prev_change_id":15557283326}}}
{"jsonrpc":"2.0","method":"subscription","params":{"channel":"book.ETH-PERPETUAL.raw","data":{"timestamp":1734114561375,"type":"change","change_id":15557283328,"instrument_name":"ETH-PERPETUAL","bids":[["change",3881.25,1.0e5]],"asks":[],"prev_change_id":15557283327}}}
{"jsonrpc":"2.0","method":"subscription","params":{"channel":"book.ETH-PERPETUAL.raw","data":{"timestamp":1734114561375,"type":"change","change_id":15557283328,"instrument_name":"ETH-PERPETUAL","bids":[["change",3881.25,1.0e5]],"asks":[],"prev_change_id":15557283327}}}
{"jsonrpc":"2.0","method":"subscription","params":{"channel":"book.ETH-PERPETUAL.raw","data":{"timestamp":1734114561377,"type":"change","change_id":15557283329,"instrument_name":"ETH-PERPETUAL","bids":[],"asks":[["change",3896.4,1.0e5]],"prev_change_id":15557283328}}}
{"jsonrpc":"2.0","method":"subscription","params":{"channel":"book.ETH-PERPETUAL.raw","data":{"timestamp":1734114561377,"type":"change","change_id":15557283329,"instrument_name":"ETH-PERPETUAL","bids":[],"asks":[["change",3896.4,1.0e5]],"prev_change_id":15557283328}}}
{"jsonrpc":"2.0","method":"subscription","params":{"channel":"book.ETH-PERPETUAL.raw","data":{"timestamp":1734114561379,"type":"change","change_id":15557283330,"instrument_name":"ETH-PERPETUAL","bids":[],"asks":[["change",3896.4,1.8e5]],"prev_change_id":15557283329}}}
{"jsonrpc":"2.0","method":"subscription","params":{"channel":"book.ETH-PERPETUAL.raw","data":{"timestamp":1734114561379,"type":"change","change_id":15557283330,"instrument_name":"ETH-PERPETUAL","bids":[],"asks":[["change",3896.4,1.8e5]],"prev_change_id":15557283329}}}
{"jsonrpc":"2.0","method":"subscription","params":{"channel":"book.ETH-PERPETUAL.raw","data":{"timestamp":1734114561381,"type":"change","change_id":15557283331,"instrument_name":"ETH-PERPETUAL","bids":[["change",3881.25,1.8e5]],"asks":[],"prev_change_id":15557283330}}}
{"jsonrpc":"2.0","method":"subscription","params":{"channel":"book.ETH-PERPETUAL.raw","data":{"timestamp":1734114561381,"type":"change","change_id":15557283331,"instrument_name":"ETH-PERPETUAL","bids":[["change",3881.25,1.8e5]],"asks":[],"prev_change_id":15557283330}}}
{"jsonrpc":"2.0","method":"subscription","params":{"channel":"book.ETH-PERPETUAL.raw","data":{"timestamp":1734114561382,"type":"change","change_id":15557283332,"instrument_name":"ETH-PERPETUAL","bids":[["change",3881.25,2.0e5]],"asks":[],"prev_change_id":15557283331}}}
{"jsonrpc":"2.0","method":"subscription","params":{"channel":"book.ETH-PERPETUAL.raw","data":{"timestamp":1734114561382,"type":"change","change_id":15557283332,"instrument_name":"ETH-PERPETUAL","bids":[["change",3881.25,2.0e5]],"asks":[],"prev_change_id":15557283331}}}
{"jsonrpc":"2.0","method":"subscription","params":{"channel":"book.ETH-PERPETUAL.raw","data":{"timestamp":1734114561384,"type":"change","change_id":15557283333,"instrument_name":"ETH-PERPETUAL","bids":[],"asks":[["change",3896.4,2.0e5]],"prev_change_id":15557283332}}}
{"jsonrpc":"2.0","method":"subscription","params":{"channel":"book.ETH-PERPETUAL.raw","data":{"timestamp":1734114561384,"type":"change","change_id":15557283333,"instrument_name":"ETH-PERPETUAL","bids":[],"asks":[["change",3896.4,2.0e5]],"prev_change_id":15557283332}}}
{"jsonrpc":"2.0","method":"subscription","params":{"channel":"book.ETH-PERPETUAL.raw","data":{"timestamp":1734114561532,"type":"change","change_id":15557283334,"instrument_name":"ETH-PERPETUAL","bids":[["delete",3881.25,0.0]],"asks":[["delete",3896.4,0.0]],"prev_change_id":15557283333}}}
{"jsonrpc":"2.0","method":"subscription","params":{"channel":"book.ETH-PERPETUAL.raw","data":{"timestamp":1734114561532,"type":"change","change_id":15557283334,"instrument_name":"ETH-PERPETUAL","bids":[["delete",3881.25,0.0]],"asks":[["delete",3896.4,0.0]],"prev_change_id":15557283333}}}
{"jsonrpc":"2.0","method":"subscription","params":{"channel":"book.ETH-PERPETUAL.raw","data":{"timestamp":1734114561734,"type":"change","change_id":15557283341,"instrument_name":"ETH-PERPETUAL","bids":[],"asks":[["new",3896.4,8.0e4]],"prev_change_id":15557283334}}}
{"jsonrpc":"2.0","method":"subscription","params":{"channel":"book.ETH-PERPETUAL.raw","data":{"timestamp":1734114561734,"type":"change","change_id":15557283341,"instrument_name":"ETH-PERPETUAL","bids":[],"asks":[["new",3896.4,8.0e4]],"prev_change_id":15557283334}}}
{"jsonrpc":"2.0","method":"subscription","params":{"channel":"book.ETH-PERPETUAL.raw","data":{"timestamp":1734114561736,"type":"change","change_id":15557283342,"instrument_name":"ETH-PERPETUAL","bids":[["new",3881.25,8.0e4]],"asks":[],"prev_change_id":15557283341}}}
{"jsonrpc":"2.0","method":"subscription","params":{"channel":"book.ETH-PERPETUAL.raw","data":{"timestamp":1734114561736,"type":"change","change_id":15557283342,"instrument_name":"ETH-PERPETUAL","bids":[["new",3881.25,8.0e4]],"asks":[],"prev_change_id":15557283341}}}
{"jsonrpc":"2.0","method":"subscription","params":{"channel":"book.ETH-PERPETUAL.raw","data":{"timestamp":1734114561742,"type":"change","change_id":15557283343,"instrument_name":"ETH-PERPETUAL","bids":[],"asks":[["change",3896.4,1.6e5]],"prev_change_id":15557283342}}}
{"jsonrpc":"2.0","method":"subscription","params":{"channel":"book.ETH-PERPETUAL.raw","data":{"timestamp":1734114561742,"type":"change","change_id":15557283343,"instrument_name":"ETH-PERPETUAL","bids":[],"asks":[["change",3896.4,1.6e5]],"prev_change_id":15557283342}}}
{"jsonrpc":"2.0","method":"subscription","params":{"channel":"book.ETH-PERPETUAL.raw","data":{"timestamp":1734114561743,"type":"change","change_id":15557283344,"instrument_name":"ETH-PERPETUAL","bids":[["change",3881.25,1.6e5]],"asks":[],"prev_change_id":15557283343}}}
{"jsonrpc":"2.0","method":"subscription","params":{"channel":"book.ETH-PERPETUAL.raw","data":{"timestamp":1734114561743,"type":"change","change_id":15557283344,"instrument_name":"ETH-PERPETUAL","bids":[["change",3881.25,1.6e5]],"asks":[],"prev_change_id":15557283343}}}
{"jsonrpc":"2.0","method":"subscription","params":{"channel":"book.ETH-PERPETUAL.raw","data":{"timestamp":1734114561744,"type":"change","change_id":15557283345,"instrument_name":"ETH-PERPETUAL","bids":[["change",3881.25,1.8e5]],"asks":[],"prev_change_id":15557283344}}}
{"jsonrpc":"2.0","method":"subscription","params":{"channel":"book.ETH-PERPETUAL.raw","data":{"timestamp":1734114561744,"type":"change","change_id":15557283345,"instrument_name":"ETH-PERPETUAL","bids":[["change",3881.25,1.8e5]],"asks":[],"prev_change_id":15557283344}}}
{"jsonrpc":"2.0","method":"subscription","params":{"channel":"book.ETH-PERPETUAL.raw","data":{"timestamp":1734114561829,"type":"change","change_id":15557283346,"instrument_name":"ETH-PERPETUAL","bids":[["delete",3881.25,0.0]],"asks":[["delete",3896.4,0.0]],"prev_change_id":15557283345}}}
{"jsonrpc":"2.0","method":"subscription","params":{"channel":"book.ETH-PERPETUAL.raw","data":{"timestamp":1734114561829,"type":"change","change_id":15557283346,"instrument_name":"ETH-PERPETUAL","bids":[["delete",3881.25,0.0]],"asks":[["delete",3896.4,0.0]],"prev_change_id":15557283345}}}
{"jsonrpc":"2.0","method":"subscription","params":{"channel":"book.ETH-PERPETUAL.raw","data":{"timestamp":1734114561984,"type":"change","change_id":15557283347,"instrument_name":"ETH-PERPETUAL","bids":[["delete",1942.0,0.0]],"asks":[],"prev_change_id":15557283346}}}
{"jsonrpc":"2.0","method":"subscription","params":{"channel":"book.ETH-PERPETUAL.raw","data":{"timestamp":1734114561984,"type":"change","change_id":15557283347,"instrument_name":"ETH-PERPETUAL","bids":[["delete",1942.0,0.0]],"asks":[],"prev_change_id":15557283346}}}
{"jsonrpc":"2.0","method":"subscription","params":{"channel":"book.ETH-PERPETUAL.raw","data":{"timestamp":1734114562014,"type":"change","change_id":15557283348,"instrument_name":"ETH-PERPETUAL","bids":[],"asks":[["new",3896.4,8.0e4]],"prev_change_id":15557283347}}}
{"jsonrpc":"2.0","method":"subscription","params":{"channel":"book.ETH-PERPETUAL.raw","data":{"timestamp":1734114562014,"type":"change","change_id":15557283348,"instrument_name":"ETH-PERPETUAL","bids":[],"asks":[["new",3896.4,8.0e4]],"prev_change_id":15557283347}}}
{"jsonrpc":"2.0","method":"subscription","params":{"channel":"book.ETH-PERPETUAL.raw","data":{"timestamp":1734114562015,"type":"change","change_id":15557283349,"instrument_name":"ETH-PERPETUAL","bids":[["new",3881.25,8.0e4]],"asks":[],"prev_change_id":15557283348}}}
{"jsonrpc":"2.0","method":"subscription","params":{"channel":"book.ETH-PERPETUAL.raw","data":{"timestamp":1734114562015,"type":"change","change_id":15557283349,"instrument_name":"ETH-PERPETUAL","bids":[["new",3881.25,8.0e4]],"asks":[],"prev_change_id":15557283348}}}
{"jsonrpc":"2.0","method":"subscription","params":{"channel":"book.ETH-PERPETUAL.raw","data":{"timestamp":1734114562017,"type":"change","change_id":15557283350,"instrument_name":"ETH-PERPETUAL","bids":[["change",3881.25,1.0e5]],"asks":[],"prev_change_id":15557283349}}}
{"jsonrpc":"2.0","method":"subscription","params":{"channel":"book.ETH-PERPETUAL.raw","data":{"timestamp":1734114562017,"type":"change","change_id":15557283350,"instrument_name":"ETH-PERPETUAL","bids":[["change",3881.25,1.0e5]],"asks":[],"prev_change_id":15557283349}}}
{"jsonrpc":"2.0","method":"subscription","params":{"channel":"book.ETH-PERPETUAL.raw","data":{"timestamp":1734114562020,"type":"change","change_id":15557283351,"instrument_name":"ETH-PERPETUAL","bids":[],"asks":[["change",3896.4,1.6e5]],"prev_change_id":15557283350}}}
{"jsonrpc":"2.0","method":"subscription","params":{"channel":"book.ETH-PERPETUAL.raw","data":{"timestamp":1734114562020,"type":"change","change_id":15557283351,"instrument_name":"ETH-PERPETUAL","bids":[],"asks":[["change",3896.4,1.6e5]],"prev_change_id":15557283350}}}
{"jsonrpc":"2.0","method":"subscription","params":{"channel":"book.ETH-PERPETUAL.raw","data":{"timestamp":1734114562021,"type":"change","change_id":15557283352,"instrument_name":"ETH-PERPETUAL","bids":[["change",3881.25,1.8e5]],"asks":[],"prev_change_id":15557283351}}}
{"jsonrpc":"2.0","method":"subscription","params":{"channel":"book.ETH-PERPETUAL.raw","data":{"timestamp":1734114562021,"type":"change","change_id":15557283352,"instrument_name":"ETH-PERPETUAL","bids":[["change",3881.25,1.8e5]],"asks":[],"prev_change_id":15557283351}}}
{"jsonrpc":"2.0","method":"subscription","params":{"channel":"book.ETH-PERPETUAL.raw","data":{"timestamp":1734114562023,"type":"change","change_id":15557283353,"instrument_name":"ETH-PERPETUAL","bids":[["change",3881.25,2.0e5]],"asks":[],"prev_change_id":15557283352}}}
{"jsonrpc":"2.0","method":"subscription","params":{"channel":"book.ETH-PERPETUAL.raw","data":{"timestamp":1734114562023,"type":"change","change_id":15557283353,"instrument_name":"ETH-PERPETUAL","bids":[["change",3881.25,2.0e5]],"asks":[],"prev_change_id":15557283352}}}
{"jsonrpc":"2.0","method":"subscription","params":{"channel":"book.ETH-PERPETUAL.raw","data":{"timestamp":1734114562112,"type":"change","change_id":15557283354,"instrument_name":"ETH-PERPETUAL","bids":[["delete",3881.25,0.0]],"asks":[["delete",3896.4,0.0]],"prev_change_id":15557283353}}}
{"jsonrpc":"2.0","method":"subscription","params":{"channel":"book.ETH-PERPETUAL.raw","data":{"timestamp":1734114562112,"type":"change","change_id":15557283354,"instrument_name":"ETH-PERPETUAL","bids":[["delete",3881.25,0.0]],"asks":[["delete",3896.4,0.0]],"prev_change_id":15557283353}}}
{"jsonrpc":"2.0","method":"subscription","params":{"channel":"book.ETH-PERPETUAL.raw","data":{"timestamp":1734114562309,"type":"change","change_id":15557283356,"instrument_name":"ETH-PERPETUAL","bids":[],"asks":[["new",3896.4,8.0e4]],"prev_change_id":15557283354}}}
{"jsonrpc":"2.0","method":"subscription","params":{"channel":"book.ETH-PERPETUAL.raw","data":{"timestamp":1734114562309,"type":"change","change_id":15557283356,"instrument_name":"ETH-PERPETUAL","bids":[],"asks":[["new",3896.4,8.0e4]],"prev_change_id":15557283354}}}
{"jsonrpc":"2.0","method":"subscription","params":{"channel":"book.ETH-PERPETUAL.raw","data":{"timestamp":1734114562311,"type":"change","change_id":15557283357,"instrument_name":"ETH-PERPETUAL","bids":[["new",3881.25,8.0e4]],"asks":[],"prev_change_id":15557283356}}}
{"jsonrpc":"2.0","method":"subscription","params":{"channel":"book.ETH-PERPETUAL.raw","data":{"timestamp":1734114562311,"type":"change","change_id":15557283357,"instrument_name":"ETH-PERPETUAL","bids":[["new",3881.25,8.0e4]],"asks":[],"prev_change_id":15557283356}}}
{"jsonrpc":"2.0","method":"subscription","params":{"channel":"book.ETH-PERPETUAL.raw","data":{"timestamp":1734114562312,"type":"change","change_id":15557283358,"instrument_name":"ETH-PERPETUAL","bids":[["change",3881.25,1.0e5]],"asks":[],"prev_change_id":15557283357}}}
{"jsonrpc":"2.0","method":"subscription","params":{"channel":"book.ETH-PERPETUAL.raw","data":{"timestamp":1734114562312,"type":"change","change_id":15557283358,"instrument_name":"ETH-PERPETUAL","bids":[["change",3881.25,1.0e5]],"asks":[],"prev_change_id":15557283357}}}
{"jsonrpc":"2.0","method":"subscription","params":{"channel":"book.ETH-PERPETUAL.raw","data":{"timestamp":1734114562314,"type":"change","change_id":15557283359,"instrument_name":"ETH-PERPETUAL","bids":[],"asks":[["change",3896.4,1.6e5]],"prev_change_id":15557283358}}}
{"jsonrpc":"2.0","method":"subscription","params":{"channel":"book.ETH-PERPETUAL.raw","data":{"timestamp":1734114562314,"type":"change","change_id":15557283359,"instrument_name":"ETH-PERPETUAL","bids":[],"asks":[["change",3896.4,1.6e5]],"prev_change_id":15557283358}}}
{"jsonrpc":"2.0","method":"subscription","params":{"channel":"book.ETH-PERPETUAL.raw","data":{"timestamp":1734114562316,"type":"change","change_id":15557283360,"instrument_name":"ETH-PERPETUAL","bids":[["change",3881.25,1.8e5]],"asks":[],"prev_change_id":15557283359}}}
{"jsonrpc":"2.0","method":"subscription","params":{"channel":"book.ETH-PERPETUAL.raw","data":{"timestamp":1734114562316,"type":"change","change_id":15557283360,"instrument_name":"ETH-PERPETUAL","bids":[["change",3881.25,1.8e5]],"asks":[],"prev_change_id":15557283359}}}
{"jsonrpc":"2.0","method":"subscription","params":{"channel":"book.ETH-PERPETUAL.raw","data":{"timestamp":1734114562317,"type":"change","change_id":15557283361,"instrument_name":"ETH-PERPETUAL","bids":[["change",3881.25,2.0e5]],"asks":[],"prev_change_id":15557283360}}}
{"jsonrpc":"2.0","method":"subscription","params":{"channel":"book.ETH-PERPETUAL.raw","data":{"timestamp":1734114562317,"type":"change","change_id":15557283361,"instrument_name":"ETH-PERPETUAL","bids":[["change",3881.25,2.0e5]],"asks":[],"prev_change_id":15557283360}}}
{"jsonrpc":"2.0","method":"subscription","params":{"channel":"book.ETH-PERPETUAL.raw","data":{"timestamp":1734114562487,"type":"change","change_id":15557283362,"instrument_name":"ETH-PERPETUAL","bids":[],"asks":[["new",3908.1,500.0],["delete",3920.3,0.0]],"prev_change_id":15557283361}}}
{"jsonrpc":"2.0","method":"subscription","params":{"channel":"book.ETH-PERPETUAL.raw","data":{"timestamp":1734114562487,"type":"change","change_id":15557283362,"instrument_name":"ETH-PERPETUAL","bids":[],"asks":[["new",3908.1,500.0],["delete",3920.3,0.0]],"prev_change_id":15557283361}}}
{"jsonrpc":"2.0","method":"subscription","params":{"channel":"book.ETH-PERPETUAL.raw","data":{"timestamp":1734114562487,"type":"change","change_id":15557283363,"instrument_name":"ETH-PERPETUAL","bids":[["delete",3881.25,0.0]],"asks":[["delete",3896.4,0.0]],"prev_change_id":15557283362}}}
{"jsonrpc":"2.0","method":"subscription","params":{"channel":"book.ETH-PERPETUAL.raw","data":{"timestamp":1734114562487,"type":"change","change_id":15557283363,"instrument_name":"ETH-PERPETUAL","bids":[["delete",3881.25,0.0]],"asks":[["delete",3896.4,0.0]],"prev_change_id":15557283362}}}
{"jsonrpc":"2.0","method":"subscription","params":{"channel":"book.ETH-PERPETUAL.raw","data":{"timestamp":1734114562680,"type":"change","change_id":15557283364,"instrument_name":"ETH-PERPETUAL","bids":[["new",3881.25,8.0e4]],"asks":[],"prev_change_id":15557283363}}}
{"jsonrpc":"2.0","method":"subscription","params":{"channel":"book.ETH-PERPETUAL.raw","data":{"timestamp":1734114562680,"type":"change","change_id":15557283364,"instrument_name":"ETH-PERPETUAL","bids":[["new",3881.25,8.0e4]],"asks":[],"prev_change_id":15557283363}}}
{"jsonrpc":"2.0","method":"subscription","params":{"channel":"book.ETH-PERPETUAL.raw","data":{"timestamp":1734114562681,"type":"change","change_id":15557283365,"instrument_name":"ETH-PERPETUAL","bids":[],"asks":[["new",3896.4,8.0e4]],"prev_change_id":15557283364}}}
{"jsonrpc":"2.0","method":"subscription","params":{"channel":"book.ETH-PERPETUAL.raw","data":{"timestamp":1734114562681,"type":"change","change_id":15557283365,"instrument_name":"ETH-PERPETUAL","bids":[],"asks":[["new",3896.4,8.0e4]],"prev_change_id":15557283364}}}
{"jsonrpc":"2.0","method":"subscription","params":{"channel":"book.ETH-PERPETUAL.raw","data":{"timestamp":1734114562682,"type":"change","change_id":15557283366,"instrument_name":"ETH-PERPETUAL","bids":[["change",3881.25,1.0e5]],"asks":[],"prev_change_id":15557283365}}}
{"jsonrpc":"2.0","method":"subscription","params":{"channel":"book.ETH-PERPETUAL.raw","data":{"timestamp":1734114562682,"type":"change","change_id":15557283366,"instrument_name":"ETH-PERPETUAL","bids":[["change",3881.25,1.0e5]],"asks":[],"prev_change_id":15557283365}}}
{"jsonrpc":"2.0","method":"subscription","params":{"channel":"book.ETH-PERPETUAL.raw","data":{"timestamp":1734114562685,"type":"change","change_id":15557283367,"instrument_name":"ETH-PERPETUAL","bids":[],"asks":[["change",3896.4,1.0e5]],"prev_change_id":15557283366}}}
{"jsonrpc":"2.0","method":"subscription","params":{"channel":"book.ETH-PERPETUAL.raw","data":{"timestamp":1734114562685,"type":"change","change_id":15557283367,"instrument_name":"ETH-PERPETUAL","bids":[],"asks":[["change",3896.4,1.0e5]],"prev_change_id":15557283366}}}
{"jsonrpc":"2.0","method":"subscription","params":{"channel":"book.ETH-PERPETUAL.raw","data":{"timestamp":1734114562692,"type":"change","change_id":15557283368,"instrument_name":"ETH-PERPETUAL","bids":[["change",3881.25,1.8e5]],"asks":[],"prev_change_id":15557283367}}}
{"jsonrpc":"2.0","method":"subscription","params":{"channel":"book.ETH-PERPETUAL.raw","data":{"timestamp":1734114562692,"type":"change","change_id":15557283368,"instrument_name":"ETH-PERPETUAL","bids":[["change",3881.25,1.8e5]],"asks":[],"prev_change_id":15557283367}}}
{"jsonrpc":"2.0","method":"subscription","params":{"channel":"book.ETH-PERPETUAL.raw","data":{"timestamp":1734114562693,"type":"change","change_id":15557283369,"instrument_name":"ETH-PERPETUAL","bids":[],"asks":[["change",3896.4,1.8e5]],"prev_change_id":15557283368}}}
{"jsonrpc":"2.0","method":"subscription","params":{"channel":"book.ETH-PERPETUAL.raw","data":{"timestamp":1734114562693,"type":"change","change_id":15557283369,"instrument_name":"ETH-PERPETUAL","bids":[],"asks":[["change",3896.4,1.8e5]],"prev_change_id":15557283368}}}
{"jsonrpc":"2.0","method":"subscription","params":{"channel":"book.ETH-PERPETUAL.raw","data":{"timestamp":1734114562694,"type":"change","change_id":15557283370,"instrument_name":"ETH-PERPETUAL","bids":[["change",3881.25,2.0e5]],"asks":[],"prev_change_id":15557283369}}}
{"jsonrpc":"2.0","method":"subscription","params":{"channel":"book.ETH-PERPETUAL.raw","data":{"timestamp":1734114562694,"type":"change","change_id":15557283370,"instrument_name":"ETH-PERPETUAL","bids":[["change",3881.25,2.0e5]],"asks":[],"prev_change_id":15557283369}}}
{"jsonrpc":"2.0","method":"subscription","params":{"channel":"book.ETH-PERPETUAL.raw","data":{"timestamp":1734114562695,"type":"change","change_id":15557283371,"instrument_name":"ETH-PERPETUAL","bids":[],"asks":[["change",3896.4,2.0e5]],"prev_change_id":15557283370}}}
{"jsonrpc":"2.0","method":"subscription","params":{"channel":"book.ETH-PERPETUAL.raw","data":{"timestamp":1734114562695,"type":"change","change_id":15557283371,"instrument_name":"ETH-PERPETUAL","bids":[],"asks":[["change",3896.4,2.0e5]],"prev_change_id":15557283370}}}
{"jsonrpc":"2.0","method":"subscription","params":{"channel":"book.ETH-PERPETUAL.raw","data":{"timestamp":1734114562789,"type":"change","change_id":15557283384,"instrument_name":"ETH-PERPETUAL","bids":[["delete",3881.25,0.0]],"asks":[["delete",3896.4,0.0]],"prev_change_id":15557283371}}}
{"jsonrpc":"2.0","method":"subscription","params":{"channel":"book.ETH-PERPETUAL.raw","data":{"timestamp":1734114562789,"type":"change","change_id":15557283384,"instrument_name":"ETH-PERPETUAL","bids":[["delete",3881.25,0.0]],"asks":[["delete",3896.4,0.0]],"prev_change_id":15557283371}}}
{"jsonrpc":"2.0","method":"subscription","params":{"channel":"book.ETH-PERPETUAL.raw","data":{"timestamp":1734114562938,"type":"change","change_id":15557283392,"instrument_name":"ETH-PERPETUAL","bids":[],"asks":[["delete",3915.9,0.0],["new",3927.65,500.0]],"prev_change_id":15557283384}}}
{"jsonrpc":"2.0","method":"subscription","params":{"channel":"book.ETH-PERPETUAL.raw","data":{"timestamp":1734114562938,"type":"change","change_id":15557283392,"instrument_name":"ETH-PERPETUAL","bids":[],"asks":[["delete",3915.9,0.0],["new",3927.65,500.0]],"prev_change_id":15557283384}}}
{"jsonrpc":"2.0","method":"subscription","params":{"channel":"book.ETH-PERPETUAL.raw","data":{"timestamp":1734114562994,"type":"change","change_id":15557283393,"instrument_name":"ETH-PERPETUAL","bids":[["new",3881.35,8.0e4]],"asks":[],"prev_change_id":15557283392}}}
{"jsonrpc":"2.0","method":"subscription","params":{"channel":"book.ETH-PERPETUAL.raw","data":{"timestamp":1734114562994,"type":"change","change_id":15557283393,"instrument_name":"ETH-PERPETUAL","bids":[["new",3881.35,8.0e4]],"asks":[],"prev_change_id":15557283392}}}
{"jsonrpc":"2.0","method":"subscription","params":{"channel":"book.ETH-PERPETUAL.raw","data":{"timestamp":1734114562995,"type":"change","change_id":15557283394,"instrument_name":"ETH-PERPETUAL","bids":[],"asks":[["new",3896.45,8.0e4]],"prev_change_id":15557283393}}}
{"jsonrpc":"2.0","method":"subscription","params":{"channel":"book.ETH-PERPETUAL.raw","data":{"timestamp":1734114562995,"type":"change","change_id":15557283394,"instrument_name":"ETH-PERPETUAL","bids":[],"asks":[["new",3896.45,8.0e4]],"prev_change_id":15557283393}}}
{"jsonrpc":"2.0","method":"subscription","params":{"channel":"book.ETH-PERPETUAL.raw","data":{"timestamp":1734114562996,"type":"change","change_id":15557283395,"instrument_name":"ETH-PERPETUAL","bids":[["change",3881.35,1.0e5]],"asks":[],"prev_change_id":15557283394}}}
{"jsonrpc":"2.0","method":"subscription","params":{"channel":"book.ETH-PERPETUAL.raw","data":{"timestamp":1734114562996,"type":"change","change_id":15557283395,"instrument_name":"ETH-PERPETUAL","bids":[["change",3881.35,1.0e5]],"asks":[],"prev_change_id":15557283394}}}
{"jsonrpc":"2.0","method":"subscription","params":{"channel":"book.ETH-PERPETUAL.raw","data":{"timestamp":1734114562997,"type":"change","change_id":15557283396,"instrument_name":"ETH-PERPETUAL","bids":[["change",3881.35,1.8e5]],"asks":[],"prev_change_id":15557283395}}}
{"jsonrpc":"2.0","method":"subscription","params":{"channel":"book.ETH-PERPETUAL.raw","data":{"timestamp":1734114562997,"type":"change","change_id":15557283396,"instrument_name":"ETH-PERPETUAL","bids":[["change",3881.35,1.8e5]],"asks":[],"prev_change_id":15557283395}}}
{"jsonrpc":"2.0","method":"subscription","params":{"channel":"book.ETH-PERPETUAL.raw","data":{"timestamp":1734114562999,"type":"change","change_id":15557283397,"instrument_name":"ETH-PERPETUAL","bids":[],"asks":[["change",3896.45,1.6e5]],"prev_change_id":15557283396}}}
{"jsonrpc":"2.0","method":"subscription","params":{"channel":"book.ETH-PERPETUAL.raw","data":{"timestamp":1734114562999,"type":"change","change_id":15557283397,"instrument_name":"ETH-PERPETUAL","bids":[],"asks":[["change",3896.45,1.6e5]],"prev_change_id":15557283396}}}
{"jsonrpc":"2.0","method":"subscription","params":{"channel":"book.ETH-PERPETUAL.raw","data":{"timestamp":1734114562999,"type":"change","change_id":15557283398,"instrument_name":"ETH-PERPETUAL","bids":[["change",3881.35,2.0e5]],"asks":[],"prev_change_id":15557283397}}}
{"jsonrpc":"2.0","method":"subscription","params":{"channel":"book.ETH-PERPETUAL.raw","data":{"timestamp":1734114562999,"type":"change","change_id":15557283398,"instrument_name":"ETH-PERPETUAL","bids":[["change",3881.35,2.0e5]],"asks":[],"prev_change_id":15557283397}}}
{"jsonrpc":"2.0","method":"subscription","params":{"channel":"book.ETH-PERPETUAL.raw","data":{"timestamp":1734114563135,"type":"change","change_id":15557283399,"instrument_name":"ETH-PERPETUAL","bids":[["delete",3881.35,0.0]],"asks":[["delete",3896.45,0.0]],"prev_change_id":15557283398}}}
{"jsonrpc":"2.0","method":"subscription","params":{"channel":"book.ETH-PERPETUAL.raw","data":{"timestamp":1734114563135,"type":"change","change_id":15557283399,"instrument_name":"ETH-PERPETUAL","bids":[["delete",3881.35,0.0]],"asks":[["delete",3896.45,0.0]],"prev_change_id":15557283398}}}
{"jsonrpc":"2.0","method":"subscription","params":{"channel":"book.ETH-PERPETUAL.raw","data":{"timestamp":1734114563330,"type":"change","change_id":15557283401,"instrument_name":"ETH-PERPETUAL","bids":[["new",3881.35,8.0e4]],"asks":[],"prev_change_id":15557283399}}}
{"jsonrpc":"2.0","method":"subscription","params":{"channel":"book.ETH-PERPETUAL.raw","data":{"timestamp":1734114563330,"type":"change","change_id":15557283401,"instrument_name":"ETH-PERPETUAL","bids":[["new",3881.35,8.0e4]],"asks":[],"prev_change_id":15557283399}}}
{"jsonrpc":"2.0","method":"subscription","params":{"channel":"book.ETH-PERPETUAL.raw","data":{"timestamp":1734114563332,"type":"change","change_id":15557283402,"instrument_name":"ETH-PERPETUAL","bids":[],"asks":[["new",3896.45,8.0e4]],"prev_change_id":15557283401}}}
{"jsonrpc":"2.0","method":"subscription","params":{"channel":"book.ETH-PERPETUAL.raw","data":{"timestamp":1734114563332,"type":"change","change_id":15557283402,"instrument_name":"ETH-PERPETUAL","bids":[],"asks":[["new",3896.45,8.0e4]],"prev_change_id":15557283401}}}
{"jsonrpc":"2.0","method":"subscription","params":{"channel":"book.ETH-PERPETUAL.raw","data":{"timestamp":1734114563333,"type":"change","change_id":15557283403,"instrument_name":"ETH-PERPETUAL","bids":[["change",3881.35,1.0e5]],"asks":[],"prev_change_id":15557283402}}}
{"jsonrpc":"2.0","method":"subscription","params":{"channel":"book.ETH-PERPETUAL.raw","data":{"timestamp":1734114563333,"type":"change","change_id":15557283403,"instrument_name":"ETH-PERPETUAL","bids":[["change",3881.35,1.0e5]],"asks":[],"prev_change_id":15557283402}}}
{"jsonrpc":"2.0","method":"subscription","params":{"channel":"book.ETH-PERPETUAL.raw","data":{"timestamp":1734114563335,"type":"change","change_id":15557283404,"instrument_name":"ETH-PERPETUAL","bids":[["change",3881.35,1.8e5]],"asks":[],"prev_change_id":15557283403}}}
{"jsonrpc":"2.0","method":"subscription","params":{"channel":"book.ETH-PERPETUAL.raw","data":{"timestamp":1734114563335,"type":"change","change_id":15557283404,"instrument_name":"ETH-PERPETUAL","bids":[["change",3881.35,1.8e5]],"asks":[],"prev_change_id":15557283403}}}
{"jsonrpc":"2.0","method":"subscription","params":{"channel":"book.ETH-PERPETUAL.raw","data":{"timestamp":1734114563337,"type":"change","change_id":15557283405,"instrument_name":"ETH-PERPETUAL","bids":[],"asks":[["change",3896.45,1.6e5]],"prev_change_id":15557283404}}}
{"jsonrpc":"2.0","method":"subscription","params":{"channel":"book.ETH-PERPETUAL.raw","data":{"timestamp":1734114563337,"type":"change","change_id":15557283405,"instrument_name":"ETH-PERPETUAL","bids":[],"asks":[["change",3896.45,1.6e5]],"prev_change_id":15557283404}}}
{"jsonrpc":"2.0","method":"subscription","params":{"channel":"book.ETH-PERPETUAL.raw","data":{"timestamp":1734114563338,"type":"change","change_id":15557283406,"instrument_name":"ETH-PERPETUAL","bids":[["change",3881.35,2.0e5]],"asks":[],"prev_change_id":15557283405}}}
{"jsonrpc":"2.0","method":"subscription","params":{"channel":"book.ETH-PERPETUAL.raw","data":{"timestamp":1734114563338,"type":"change","change_id":15557283406,"instrument_name":"ETH-PERPETUAL","bids":[["change",3881.35,2.0e5]],"asks":[],"prev_change_id":15557283405}}}
{"jsonrpc":"2.0","method":"subscription","params":{"channel":"book.ETH-PERPETUAL.raw","data":{"timestamp":1734114563495,"type":"change","change_id":15557283407,"instrument_name":"ETH-PERPETUAL","bids":[["delete",3881.35,0.0]],"asks":[["delete",3896.45,0.0]],"prev_change_id":15557283406}}}
{"jsonrpc":"2.0","method":"subscription","params":{"channel":"book.ETH-PERPETUAL.raw","data":{"timestamp":1734114563495,"type":"change","change_id":15557283407,"instrument_name":"ETH-PERPETUAL","bids":[["delete",3881.35,0.0]],"asks":[["delete",3896.45,0.0]],"prev_change_id":15557283406}}}
{"jsonrpc":"2.0","method":"subscription","params":{"channel":"book.ETH-PERPETUAL.raw","data":{"timestamp":1734114563696,"type":"change","change_id":15557283411,"instrument_name":"ETH-PERPETUAL","bids":[["new",3881.35,8.0e4]],"asks":[],"prev_change_id":15557283407}}}
{"jsonrpc":"2.0","method":"subscription","params":{"channel":"book.ETH-PERPETUAL.raw","data":{"timestamp":1734114563696,"type":"change","change_id":15557283411,"instrument_name":"ETH-PERPETUAL","bids":[["new",3881.35,8.0e4]],"asks":[],"prev_change_id":15557283407}}}
{"jsonrpc":"2.0","method":"subscription","params":{"channel":"book.ETH-PERPETUAL.raw","data":{"timestamp":1734114563697,"type":"change","change_id":15557283412,"instrument_name":"ETH-PERPETUAL","bids":[],"asks":[["new",3896.45,8.0e4]],"prev_change_id":15557283411}}}
{"jsonrpc":"2.0","method":"subscription","params":{"channel":"book.ETH-PERPETUAL.raw","data":{"timestamp":1734114563697,"type":"change","change_id":15557283412,"instrument_name":"ETH-PERPETUAL","bids":[],"asks":[["new",3896.45,8.0e4]],"prev_change_id":15557283411}}}
{"jsonrpc":"2.0","method":"subscription","params":{"channel":"book.ETH-PERPETUAL.raw","data":{"timestamp":1734114563698,"type":"change","change_id":15557283413,"instrument_name":"ETH-PERPETUAL","bids":[["change",3881.35,1.0e5]],"asks":[],"prev_change_id":15557283412}}}
{"jsonrpc":"2.0","method":"subscription","params":{"channel":"book.ETH-PERPETUAL.raw","data":{"timestamp":1734114563698,"type":"change","change_id":15557283413,"instrument_name":"ETH-PERPETUAL","bids":[["change",3881.35,1.0e5]],"asks":[],"prev_change_id":15557283412}}}
{"jsonrpc":"2.0","method":"subscription","params":{"channel":"book.ETH-PERPETUAL.raw","data":{"timestamp":1734114563700,"type":"change","change_id":15557283414,"instrument_name":"ETH-PERPETUAL","bids":[],"asks":[["change",3896.45,1.0e5]],"prev_change_id":15557283413}}}
{"jsonrpc":"2.0","method":"subscription","params":{"channel":"book.ETH-PERPETUAL.raw","data":{"timestamp":1734114563700,"type":"change","change_id":15557283414,"instrument_name":"ETH-PERPETUAL","bids":[],"asks":[["change",3896.45,1.0e5]],"prev_change_id":15557283413}}}
{"jsonrpc":"2.0","method":"subscription","params":{"channel":"book.ETH-PERPETUAL.raw","data":{"timestamp":1734114563701,"type":"change","change_id":15557283415,"instrument_name":"ETH-PERPETUAL","bids":[["change",3881.35,1.8e5]],"asks":[],"prev_change_id":15557283414}}}
{"jsonrpc":"2.0","method":"subscription","params":{"channel":"book.ETH-PERPETUAL.raw","data":{"timestamp":1734114563701,"type":"change","change_id":15557283415,"instrument_name":"ETH-PERPETUAL","bids":[["change",3881.35,1.8e5]],"asks":[],"prev_change_id":15557283414}}}
{"jsonrpc":"2.0","method":"subscription","params":{"channel":"book.ETH-PERPETUAL.raw","data":{"timestamp":1734114563703,"type":"change","change_id":15557283416,"instrument_name":"ETH-PERPETUAL","bids":[],"asks":[["change",3896.45,1.8e5]],"prev_change_id":15557283415}}}
{"jsonrpc":"2.0","method":"subscription","params":{"channel":"book.ETH-PERPETUAL.raw","data":{"timestamp":1734114563703,"type":"change","change_id":15557283416,"instrument_name":"ETH-PERPETUAL","bids":[],"asks":[["change",3896.45,1.8e5]],"prev_change_id":15557283415}}}
{"jsonrpc":"2.0","method":"subscription","params":{"channel":"book.ETH-PERPETUAL.raw","data":{"timestamp":1734114563705,"type":"change","change_id":15557283417,"instrument_name":"ETH-PERPETUAL","bids":[["change",3881.35,2.0e5]],"asks":[],"prev_change_id":15557283416}}}
{"jsonrpc":"2.0","method":"subscription","params":{"channel":"book.ETH-PERPETUAL.raw","data":{"timestamp":1734114563705,"type":"change","change_id":15557283417,"instrument_name":"ETH-PERPETUAL","bids":[["change",3881.35,2.0e5]],"asks":[],"prev_change_id":15557283416}}}
{"jsonrpc":"2.0","method":"subscription","params":{"channel":"book.ETH-PERPETUAL.raw","data":{"timestamp":1734114563853,"type":"change","change_id":15557283420,"instrument_name":"ETH-PERPETUAL","bids":[["delete",3881.35,0.0]],"asks":[["delete",3896.45,0.0]],"prev_change_id":15557283417}}}
{"jsonrpc":"2.0","method":"subscription","params":{"channel":"book.ETH-PERPETUAL.raw","data":{"timestamp":1734114563853,"type":"change","change_id":15557283420,"instrument_name":"ETH-PERPETUAL","bids":[["delete",3881.35,0.0]],"asks":[["delete",3896.45,0.0]],"prev_change_id":15557283417}}}
{"jsonrpc":"2.0","method":"subscription","params":{"channel":"book.ETH-PERPETUAL.raw","data":{"timestamp":1734114564084,"type":"change","change_id":15557283423,"instrument_name":"ETH-PERPETUAL","bids":[],"asks":[["new",3896.55,8.0e4]],"prev_change_id":15557283420}}}
{"jsonrpc":"2.0","method":"subscription","params":{"channel":"book.ETH-PERPETUAL.raw","data":{"timestamp":1734114564084,"type":"change","change_id":15557283423,"instrument_name":"ETH-PERPETUAL","bids":[],"asks":[["new",3896.55,8.0e4]],"prev_change_id":15557283420}}}
{"jsonrpc":"2.0","method":"subscription","params":{"channel":"book.ETH-PERPETUAL.raw","data":{"timestamp":1734114564085,"type":"change","change_id":15557283424,"instrument_name":"ETH-PERPETUAL","bids":[["new",3881.45,8.0e4]],"asks":[],"prev_change_id":15557283423}}}
{"jsonrpc":"2.0","method":"subscription","params":{"channel":"book.ETH-PERPETUAL.raw","data":{"timestamp":1734114564085,"type":"change","change_id":15557283424,"instrument_name":"ETH-PERPETUAL","bids":[["new",3881.45,8.0e4]],"asks":[],"prev_change_id":15557283423}}}
{"jsonrpc":"2.0","method":"subscription","params":{"channel":"book.ETH-PERPETUAL.raw","data":{"timestamp":1734114564087,"type":"change","change_id":15557283425,"instrument_name":"ETH-PERPETUAL","bids":[],"asks":[["change",3896.55,1.0e5]],"prev_change_id":15557283424}}}
{"jsonrpc":"2.0","method":"subscription","params":{"channel":"book.ETH-PERPETUAL.raw","data":{"timestamp":1734114564087,"type":"change","change_id":15557283425,"instrument_name":"ETH-PERPETUAL","bids":[],"asks":[["change",3896.55,1.0e5]],"prev_change_id":15557283424}}}
{"jsonrpc":"2.0","method":"subscription","params":{"channel":"book.ETH-PERPETUAL.raw","data":{"timestamp":1734114564089,"type":"change","change_id":15557283426,"instrument_name":"ETH-PERPETUAL","bids":[["change",3881.45,1.0e5]],"asks":[],"prev_change_id":15557283425}}}
{"jsonrpc":"2.0","method":"subscription","params":{"channel":"book.ETH-PERPETUAL.raw","data":{"timestamp":1734114564089,"type":"change","change_id":15557283426,"instrument_name":"ETH-PERPETUAL","bids":[["change",3881.45,1.0e5]],"asks":[],"prev_change_id":15557283425}}}
{"jsonrpc":"2.0","method":"subscription","params":{"channel":"book.ETH-PERPETUAL.raw","data":{"timestamp":1734114564090,"type":"change","change_id":15557283427,"instrument_name":"ETH-PERPETUAL","bids":[],"asks":[["change",3896.55,1.8e5]],"prev_change_id":15557283426}}}
{"jsonrpc":"2.0","method":"subscription","params":{"channel":"book.ETH-PERPETUAL.raw","data":{"timestamp":1734114564090,"type":"change","change_id":15557283427,"instrument_name":"ETH-PERPETUAL","bids":[],"asks":[["change",3896.55,1.8e5]],"prev_change_id":15557283426}}}
{"jsonrpc":"2.0","method":"subscription","params":{"channel":"book.ETH-PERPETUAL.raw","data":{"timestamp":1734114564098,"type":"change","change_id":15557283428,"instrument_name":"ETH-PERPETUAL","bids":[["change",3881.45,1.8e5]],"asks":[],"prev_change_id":15557283427}}}
{"jsonrpc":"2.0","method":"subscription","params":{"channel":"book.ETH-PERPETUAL.raw","data":{"timestamp":1734114564098,"type":"change","change_id":15557283428,"instrument_name":"ETH-PERPETUAL","bids":[["change",3881.45,1.8e5]],"asks":[],"prev_change_id":15557283427}}}
{"jsonrpc":"2.0","method":"subscription","params":{"channel":"book.ETH-PERPETUAL.raw","data":{"timestamp":1734114564101,"type":"change","change_id":15557283429,"instrument_name":"ETH-PERPETUAL","bids":[],"asks":[["change",3896.55,2.0e5]],"prev_change_id":15557283428}}}
{"jsonrpc":"2.0","method":"subscription","params":{"channel":"book.ETH-PERPETUAL.raw","data":{"timestamp":1734114564101,"type":"change","change_id":15557283429,"instrument_name":"ETH-PERPETUAL","bids":[],"asks":[["change",3896.55,2.0e5]],"prev_change_id":15557283428}}}
{"jsonrpc":"2.0","method":"subscription","params":{"channel":"book.ETH-PERPETUAL.raw","data":{"timestamp":1734114564102,"type":"change","change_id":15557283430,"instrument_name":"ETH-PERPETUAL","bids":[["change",3881.45,2.0e5]],"asks":[],"prev_change_id":15557283429}}}
{"jsonrpc":"2.0","method":"subscription","params":{"channel":"book.ETH-PERPETUAL.raw","data":{"timestamp":1734114564102,"type":"change","change_id":15557283430,"instrument_name":"ETH-PERPETUAL","bids":[["change",3881.45,2.0e5]],"asks":[],"prev_change_id":15557283429}}}
{"jsonrpc":"2.0","method":"subscription","params":{"channel":"book.ETH-PERPETUAL.raw","data":{"timestamp":1734114564186,"type":"change","change_id":15557283431,"instrument_name":"ETH-PERPETUAL","bids":[["delete",3881.45,0.0]],"asks":[["delete",3896.55,0.0]],"prev_change_id":15557283430}}}
{"jsonrpc":"2.0","method":"subscription","params":{"channel":"book.ETH-PERPETUAL.raw","data":{"timestamp":1734114564186,"type":"change","change_id":15557283431,"instrument_name":"ETH-PERPETUAL","bids":[["delete",3881.45,0.0]],"asks":[["delete",3896.55,0.0]],"prev_change_id":15557283430}}}
{"jsonrpc":"2.0","method":"subscription","params":{"channel":"book.ETH-PERPETUAL.raw","data":{"timestamp":1734114564229,"type":"change","change_id":15557283432,"instrument_name":"ETH-PERPETUAL","bids":[["delete",3828.75,0.0],["new",3817.25,700.0]],"asks":[],"prev_change_id":15557283431}}}
{"jsonrpc":"2.0","method":"subscription","params":{"channel":"book.ETH-PERPETUAL.raw","data":{"timestamp":1734114564229,"type":"change","change_id":15557283432,"instrument_name":"ETH-PERPETUAL","bids":[["delete",3828.75,0.0],["new",3817.25,700.0]],"asks":[],"prev_change_id":15557283431}}}
{"jsonrpc":"2.0","method":"subscription","params":{"channel":"book.ETH-PERPETUAL.raw","data":{"timestamp":1734114564230,"type":"change","change_id":15557283433,"instrument_name":"ETH-PERPETUAL","bids":[["delete",3850.35,0.0],["new",3838.75,500.0]],"asks":[],"prev_change_id":15557283432}}}
{"jsonrpc":"2.0","method":"subscription","params":{"channel":"book.ETH-PERPETUAL.raw","data":{"timestamp":1734114564230,"type":"change","change_id":15557283433,"instrument_name":"ETH-PERPETUAL","bids":[["delete",3850.35,0.0],["new",3838.75,500.0]],"asks":[],"prev_change_id":15557283432}}}
{"jsonrpc":"2.0","method":"subscription","params":{"channel":"book.ETH-PERPETUAL.raw","data":{"timestamp":1734114564376,"type":"change","change_id":15557283434,"instrument_name":"ETH-PERPETUAL","bids":[["new",3881.45,8.0e4]],"asks":[],"prev_change_id":15557283433}}}
{"jsonrpc":"2.0","method":"subscription","params":{"channel":"book.ETH-PERPETUAL.raw","data":{"timestamp":1734114564376,"type":"change","change_id":15557283434,"instrument_name":"ETH-PERPETUAL","bids":[["new",3881.45,8.0e4]],"asks":[],"prev_change_id":15557283433}}}
{"jsonrpc":"2.0","method":"subscription","params":{"channel":"book.ETH-PERPETUAL.raw","data":{"timestamp":1734114564378,"type":"change","change_id":15557283435,"instrument_name":"ETH-PERPETUAL","bids":[],"asks":[["new",3896.55,8.0e4]],"prev_change_id":15557283434}}}
{"jsonrpc":"2.0","method":"subscription","params":{"channel":"book.ETH-PERPETUAL.raw","data":{"timestamp":1734114564378,"type":"change","change_id":15557283435,"instrument_name":"ETH-PERPETUAL","bids":[],"asks":[["new",3896.55,8.0e4]],"prev_change_id":15557283434}}}
{"jsonrpc":"2.0","method":"subscription","params":{"channel":"book.ETH-PERPETUAL.raw","data":{"timestamp":1734114564380,"type":"change","change_id":15557283436,"instrument_name":"ETH-PERPETUAL","bids":[["change",3881.45,1.6e5]],"asks":[],"prev_change_id":15557283435}}}
{"jsonrpc":"2.0","method":"subscription","params":{"channel":"book.ETH-PERPETUAL.raw","data":{"timestamp":1734114564380,"type":"change","change_id":15557283436,"instrument_name":"ETH-PERPETUAL","bids":[["change",3881.45,1.6e5]],"asks":[],"prev_change_id":15557283435}}}
{"jsonrpc":"2.0","method":"subscription","params":{"channel":"book.ETH-PERPETUAL.raw","data":{"timestamp":1734114564382,"type":"change","change_id":15557283437,"instrument_name":"ETH-PERPETUAL","bids":[],"asks":[["change",3896.55,1.6e5]],"prev_change_id":15557283436}}}
{"jsonrpc":"2.0","method":"subscription","params":{"channel":"book.ETH-PERPETUAL.raw","data":{"timestamp":1734114564382,"type":"change","change_id":15557283437,"instrument_name":"ETH-PERPETUAL","bids":[],"asks":[["change",3896.55,1.6e5]],"prev_change_id":15557283436}}}
{"jsonrpc":"2.0","method":"subscription","params":{"channel":"book.ETH-PERPETUAL.raw","data":{"timestamp":1734114564515,"type":"change","change_id":15557283439,"instrument_name":"ETH-PERPETUAL","bids":[["delete",3881.45,0.0]],"asks":[["delete",3896.55,0.0]],"prev_change_id":15557283437}}}
{"jsonrpc":"2.0","method":"subscription","params":{"channel":"book.ETH-PERPETUAL.raw","data":{"timestamp":1734114564515,"type":"change","change_id":15557283439,"instrument_name":"ETH-PERPETUAL","bids":[["delete",3881.45,0.0]],"asks":[["delete",3896.55,0.0]],"prev_change_id":15557283437}}}
{"jsonrpc":"2.0","method":"subscription","params":{"channel":"book.ETH-PERPETUAL.raw","data":{"timestamp":1734114564521,"type":"change","change_id":15557283440,"instrument_name":"ETH-PERPETUAL","bids":[["new",3869.8,500.0],["delete",3858.05,0.0]],"asks":[],"prev_change_id":15557283439}}}
{"jsonrpc":"2.0","method":"subscription","params":{"channel":"book.ETH-PERPETUAL.raw","data":{"timestamp":1734114564521,"type":"change","change_id":15557283440,"instrument_name":"ETH-PERPETUAL","bids":[["new",3869.8,500.0],["delete",3858.05,0.0]],"asks":[],"prev_change_id":15557283439}}}
{"jsonrpc":"2.0","method":"subscription","params":{"channel":"book.ETH-PERPETUAL.raw","data":{"timestamp":1734114564723,"type":"change","change_id":15557283441,"instrument_name":"ETH-PERPETUAL","bids":[["new",3881.45,8.0e4]],"asks":[],"prev_change_id":15557283440}}}
{"jsonrpc":"2.0","method":"subscription","params":{"channel":"book.ETH-PERPETUAL.raw","data":{"timestamp":1734114564723,"type":"change","change_id":15557283441,"instrument_name":"ETH-PERPETUAL","bids":[["new",3881.45,8.0e4]],"asks":[],"prev_change_id":15557283440}}}
{"jsonrpc":"2.0","method":"subscription","params":{"channel":"book.ETH-PERPETUAL.raw","data":{"timestamp":1734114564725,"type":"change","change_id":15557283442,"instrument_name":"ETH-PERPETUAL","bids":[],"asks":[["new",3896.55,8.0e4]],"prev_change_id":15557283441}}}
{"jsonrpc":"2.0","method":"subscription","params":{"channel":"book.ETH-PERPETUAL.raw","data":{"timestamp":1734114564725,"type":"change","change_id":15557283442,"instrument_name":"ETH-PERPETUAL","bids":[],"asks":[["new",3896.55,8.0e4]],"prev_change_id":15557283441}}}
{"jsonrpc":"2.0","method":"subscription","params":{"channel":"book.ETH-PERPETUAL.raw","data":{"timestamp":1734114564726,"type":"change","change_id":15557283443,"instrument_name":"ETH-PERPETUAL","bids":[["change",3881.45,1.0e5]],"asks":[],"prev_change_id":15557283442}}}
{"jsonrpc":"2.0","method":"subscription","params":{"channel":"book.ETH-PERPETUAL.raw","data":{"timestamp":1734114564726,"type":"change","change_id":15557283443,"instrument_name":"ETH-PERPETUAL","bids":[["change",3881.45,1.0e5]],"asks":[],"prev_change_id":15557283442}}}
{"jsonrpc":"2.0","method":"subscription","params":{"channel":"book.ETH-PERPETUAL.raw","data":{"timestamp":1734114564728,"type":"change","change_id":15557283444,"instrument_name":"ETH-PERPETUAL","bids":[],"asks":[["change",3896.55,1.0e5]],"prev_change_id":15557283443}}}
{"jsonrpc":"2.0","method":"subscription","params":{"channel":"book.ETH-PERPETUAL.raw","data":{"timestamp":1734114564728,"type":"change","change_id":15557283444,"instrument_name":"ETH-PERPETUAL","bids":[],"asks":[["change",3896.55,1.0e5]],"prev_change_id":15557283443}}}
{"jsonrpc":"2.0","method":"subscription","params":{"channel":"book.ETH-PERPETUAL.raw","data":{"timestamp":1734114564730,"type":"change","change_id":15557283445,"instrument_name":"ETH-PERPETUAL","bids":[["change",3881.45,1.8e5]],"asks":[],"prev_change_id":15557283444}}}
{"jsonrpc":"2.0","method":"subscription","params":{"channel":"book.ETH-PERPETUAL.raw","data":{"timestamp":1734114564730,"type":"change","change_id":15557283445,"instrument_name":"ETH-PERPETUAL","bids":[["change",3881.45,1.8e5]],"asks":[],"prev_change_id":15557283444}}}
{"jsonrpc":"2.0","method":"subscription","params":{"channel":"book.ETH-PERPETUAL.raw","data":{"timestamp":1734114564731,"type":"change","change_id":15557283447,"instrument_name":"ETH-PERPETUAL","bids":[],"asks":[["change",3896.55,1.8e5]],"prev_change_id":15557283445}}}
{"jsonrpc":"2.0","method":"subscription","params":{"channel":"book.ETH-PERPETUAL.raw","data":{"timestamp":1734114564731,"type":"change","change_id":15557283447,"instrument_name":"ETH-PERPETUAL","bids":[],"asks":[["change",3896.55,1.8e5]],"prev_change_id":15557283445}}}
{"jsonrpc":"2.0","method":"subscription","params":{"channel":"book.ETH-PERPETUAL.raw","data":{"timestamp":1734114564733,"type":"change","change_id":15557283449,"instrument_name":"ETH-PERPETUAL","bids":[["change",3881.45,2.0e5]],"asks":[],"prev_change_id":15557283447}}}
{"jsonrpc":"2.0","method":"subscription","params":{"channel":"book.ETH-PERPETUAL.raw","data":{"timestamp":1734114564733,"type":"change","change_id":15557283449,"instrument_name":"ETH-PERPETUAL","bids":[["change",3881.45,2.0e5]],"asks":[],"prev_change_id":15557283447}}}
{"jsonrpc":"2.0","method":"subscription","params":{"channel":"book.ETH-PERPETUAL.raw","data":{"timestamp":1734114564735,"type":"change","change_id":15557283450,"instrument_name":"ETH-PERPETUAL","bids":[],"asks":[["change",3896.55,2.0e5]],"prev_change_id":15557283449}}}
{"jsonrpc":"2.0","method":"subscription","params":{"channel":"book.ETH-PERPETUAL.raw","data":{"timestamp":1734114564735,"type":"change","change_id":15557283450,"instrument_name":"ETH-PERPETUAL","bids":[],"asks":[["change",3896.55,2.0e5]],"prev_change_id":15557283449}}}
{"jsonrpc":"2.0","method":"subscription","params":{"channel":"book.ETH-PERPETUAL.raw","data":{"timestamp":1734114564821,"type":"change","change_id":15557283481,"instrument_name":"ETH-PERPETUAL","bids":[["delete",3881.45,0.0]],"asks":[["delete",3896.55,0.0]],"prev_change_id":15557283450}}}
{"jsonrpc":"2.0","method":"subscription","params":{"channel":"book.ETH-PERPETUAL.raw","data":{"timestamp":1734114564821,"type":"change","change_id":15557283481,"instrument_name":"ETH-PERPETUAL","bids":[["delete",3881.45,0.0]],"asks":[["delete",3896.55,0.0]],"prev_change_id":15557283450}}}
{"jsonrpc":"2.0","method":"subscription","params":{"channel":"book.ETH-PERPETUAL.raw","data":{"timestamp":1734114565002,"type":"change","change_id":15557283483,"instrument_name":"ETH-PERPETUAL","bids":[["new",3881.45,8.0e4]],"asks":[],"prev_change_id":15557283481}}}
{"jsonrpc":"2.0","method":"subscription","params":{"channel":"book.ETH-PERPETUAL.raw","data":{"timestamp":1734114565002,"type":"change","change_id":15557283483,"instrument_name":"ETH-PERPETUAL","bids":[["new",3881.45,8.0e4]],"asks":[],"prev_change_id":15557283481}}}
{"jsonrpc":"2.0","method":"subscription","params":{"channel":"book.ETH-PERPETUAL.raw","data":{"timestamp":1734114565004,"type":"change","change_id":15557283484,"instrument_name":"ETH-PERPETUAL","bids":[],"asks":[["new",3896.55,8.0e4]],"prev_change_id":15557283483}}}
{"jsonrpc":"2.0","method":"subscription","params":{"channel":"book.ETH-PERPETUAL.raw","data":{"timestamp":1734114565004,"type":"change","change_id":15557283484,"instrument_name":"ETH-PERPETUAL","bids":[],"asks":[["new",3896.55,8.0e4]],"prev_change_id":15557283483}}}
{"jsonrpc":"2.0","method":"subscription","params":{"channel":"book.ETH-PERPETUAL.raw","data":{"timestamp":1734114565006,"type":"change","change_id":15557283485,"instrument_name":"ETH-PERPETUAL","bids":[["change",3881.45,1.6e5]],"asks":[],"prev_change_id":15557283484}}}
{"jsonrpc":"2.0","method":"subscription","params":{"channel":"book.ETH-PERPETUAL.raw","data":{"timestamp":1734114565006,"type":"change","change_id":15557283485,"instrument_name":"ETH-PERPETUAL","bids":[["change",3881.45,1.6e5]],"asks":[],"prev_change_id":15557283484}}}
{"jsonrpc":"2.0","method":"subscription","params":{"channel":"book.ETH-PERPETUAL.raw","data":{"timestamp":1734114565007,"type":"change","change_id":15557283486,"instrument_name":"ETH-PERPETUAL","bids":[],"asks":[["change",3896.55,1.6e5]],"prev_change_id":15557283485}}}
{"jsonrpc":"2.0","method":"subscription","params":{"channel":"book.ETH-PERPETUAL.raw","data":{"timestamp":1734114565007,"type":"change","change_id":15557283486,"instrument_name":"ETH-PERPETUAL","bids":[],"asks":[["change",3896.55,1.6e5]],"prev_change_id":15557283485}}}
{"jsonrpc":"2.0","method":"subscription","params":{"channel":"book.ETH-PERPETUAL.raw","data":{"timestamp":1734114565145,"type":"change","change_id":15557283487,"instrument_name":"ETH-PERPETUAL","bids":[["delete",3881.45,0.0]],"asks":[["delete",3896.55,0.0]],"prev_change_id":15557283486}}}
{"jsonrpc":"2.0","method":"subscription","params":{"channel":"book.ETH-PERPETUAL.raw","data":{"timestamp":1734114565145,"type":"change","change_id":15557283487,"instrument_name":"ETH-PERPETUAL","bids":[["delete",3881.45,0.0]],"asks":[["delete",3896.55,0.0]],"prev_change_id":15557283486}}}
{"jsonrpc":"2.0","method":"subscription","params":{"channel":"book.ETH-PERPETUAL.raw","data":{"timestamp":1734114565332,"type":"change","change_id":15557283488,"instrument_name":"ETH-PERPETUAL","bids":[["new",3881.45,8.0e4]],"asks":[],"prev_change_id":15557283487}}}
{"jsonrpc":"2.0","method":"subscription","params":{"channel":"book.ETH-PERPETUAL.raw","data":{"timestamp":1734114565332,"type":"change","change_id":15557283488,"instrument_name":"ETH-PERPETUAL","bids":[["new",3881.45,8.0e4]],"asks":[],"prev_change_id":15557283487}}}
{"jsonrpc":"2.0","method":"subscription","params":{"channel":"book.ETH-PERPETUAL.raw","data":{"timestamp":1734114565334,"type":"change","change_id":15557283489,"instrument_name":"ETH-PERPETUAL","bids":[],"asks":[["new",3896.55,8.0e4]],"prev_change_id":15557283488}}}
{"jsonrpc":"2.0","method":"subscription","params":{"channel":"book.ETH-PERPETUAL.raw","data":{"timestamp":1734114565334,"type":"change","change_id":15557283489,"instrument_name":"ETH-PERPETUAL","bids":[],"asks":[["new",3896.55,8.0e4]],"prev_change_id":15557283488}}}
{"jsonrpc":"2.0","method":"subscription","params":{"channel":"book.ETH-PERPETUAL.raw","data":{"timestamp":1734114565336,"type":"change","change_id":15557283490,"instrument_name":"ETH-PERPETUAL","bids":[["change",3881.45,1.0e5]],"asks":[],"prev_change_id":15557283489}}}
{"jsonrpc":"2.0","method":"subscription","params":{"channel":"book.ETH-PERPETUAL.raw","data":{"timestamp":1734114565336,"type":"change","change_id":15557283490,"instrument_name":"ETH-PERPETUAL","bids":[["change",3881.45,1.0e5]],"asks":[],"prev_change_id":15557283489}}}
{"jsonrpc":"2.0","method":"subscription","params":{"channel":"book.ETH-PERPETUAL.raw","data":{"timestamp":1734114565337,"type":"change","change_id":15557283491,"instrument_name":"ETH-PERPETUAL","bids":[],"asks":[["change",3896.55,1.0e5]],"prev_change_id":15557283490}}}
{"jsonrpc":"2.0","method":"subscription","params":{"channel":"book.ETH-PERPETUAL.raw","data":{"timestamp":1734114565337,"type":"change","change_id":15557283491,"instrument_name":"ETH-PERPETUAL","bids":[],"asks":[["change",3896.55,1.0e5]],"prev_change_id":15557283490}}}
{"jsonrpc":"2.0","method":"subscription","params":{"channel":"book.ETH-PERPETUAL.raw","data":{"timestamp":1734114565339,"type":"change","change_id":15557283492,"instrument_name":"ETH-PERPETUAL","bids":[["change",3881.45,1.8e5]],"asks":[],"prev_change_id":15557283491}}}
{"jsonrpc":"2.0","method":"subscription","params":{"channel":"book.ETH-PERPETUAL.raw","data":{"timestamp":1734114565339,"type":"change","change_id":15557283492,"instrument_name":"ETH-PERPETUAL","bids":[["change",3881.45,1.8e5]],"asks":[],"prev_change_id":15557283491}}}
{"jsonrpc":"2.0","method":"subscription","params":{"channel":"book.ETH-PERPETUAL.raw","data":{"timestamp":1734114565340,"type":"change","change_id":15557283493,"instrument_name":"ETH-PERPETUAL","bids":[],"asks":[["change",3896.55,1.8e5]],"prev_change_id":15557283492}}}
{"jsonrpc":"2.0","method":"subscription","params":{"channel":"book.ETH-PERPETUAL.raw","data":{"timestamp":1734114565340,"type":"change","change_id":15557283493,"instrument_name":"ETH-PERPETUAL","bids":[],"asks":[["change",3896.55,1.8e5]],"prev_change_id":15557283492}}}
{"jsonrpc":"2.0","method":"subscription","params":{"channel":"book.ETH-PERPETUAL.raw","data":{"timestamp":1734114565341,"type":"change","change_id":15557283494,"instrument_name":"ETH-PERPETUAL","bids":[["change",3881.45,2.0e5]],"asks":[],"prev_change_id":15557283493}}}
{"jsonrpc":"2.0","method":"subscription","params":{"channel":"book.ETH-PERPETUAL.raw","data":{"timestamp":1734114565341,"type":"change","change_id":15557283494,"instrument_name":"ETH-PERPETUAL","bids":[["change",3881.45,2.0e5]],"asks":[],"prev_change_id":15557283493}}}
{"jsonrpc":"2.0","method":"subscription","params":{"channel":"book.ETH-PERPETUAL.raw","data":{"timestamp":1734114565343,"type":"change","change_id":15557283495,"instrument_name":"ETH-PERPETUAL","bids":[],"asks":[["change",3896.55,2.0e5]],"prev_change_id":15557283494}}}
{"jsonrpc":"2.0","method":"subscription","params":{"channel":"book.ETH-PERPETUAL.raw","data":{"timestamp":1734114565343,"type":"change","change_id":15557283495,"instrument_name":"ETH-PERPETUAL","bids":[],"asks":[["change",3896.55,2.0e5]],"prev_change_id":15557283494}}}
{"jsonrpc":"2.0","method":"subscription","params":{"channel":"book.ETH-PERPETUAL.raw","data":{"timestamp":1734114565495,"type":"change","change_id":15557283496,"instrument_name":"ETH-PERPETUAL","bids":[["delete",3881.45,0.0]],"asks":[["delete",3896.55,0.0]],"prev_change_id":15557283495}}}
{"jsonrpc":"2.0","method":"subscription","params":{"channel":"book.ETH-PERPETUAL.raw","data":{"timestamp":1734114565495,"type":"change","change_id":15557283496,"instrument_name":"ETH-PERPETUAL","bids":[["delete",3881.45,0.0]],"asks":[["delete",3896.55,0.0]],"prev_change_id":15557283495}}}
{"jsonrpc":"2.0","method":"subscription","params":{"channel":"book.ETH-PERPETUAL.raw","data":{"timestamp":1734114565675,"type":"change","change_id":15557283499,"instrument_name":"ETH-PERPETUAL","bids":[["new",3881.45,8.0e4]],"asks":[],"prev_change_id":15557283496}}}
{"jsonrpc":"2.0","method":"subscription","params":{"channel":"book.ETH-PERPETUAL.raw","data":{"timestamp":1734114565675,"type":"change","change_id":15557283499,"instrument_name":"ETH-PERPETUAL","bids":[["new",3881.45,8.0e4]],"asks":[],"prev_change_id":15557283496}}}
{"jsonrpc":"2.0","method":"subscription","params":{"channel":"book.ETH-PERPETUAL.raw","data":{"timestamp":1734114565677,"type":"change","change_id":15557283500,"instrument_name":"ETH-PERPETUAL","bids":[],"asks":[["new",3896.55,8.0e4]],"prev_change_id":15557283499}}}
{"jsonrpc":"2.0","method":"subscription","params":{"channel":"book.ETH-PERPETUAL.raw","data":{"timestamp":1734114565677,"type":"change","change_id":15557283500,"instrument_name":"ETH-PERPETUAL","bids":[],"asks":[["new",3896.55,8.0e4]],"prev_change_id":15557283499}}}
{"jsonrpc":"2.0","method":"subscription","params":{"channel":"book.ETH-PERPETUAL.raw","data":{"timestamp":1734114565678,"type":"change","change_id":15557283501,"instrument_name":"ETH-PERPETUAL","bids":[["change",3881.45,1.6e5]],"asks":[],"prev_change_id":15557283500}}}
{"jsonrpc":"2.0","method":"subscription","params":{"channel":"book.ETH-PERPETUAL.raw","data":{"timestamp":1734114565678,"type":"change","change_id":15557283501,"instrument_name":"ETH-PERPETUAL","bids":[["change",3881.45,1.6e5]],"asks":[],"prev_change_id":15557283500}}}
{"jsonrpc":"2.0","method":"subscription","params":{"channel":"book.ETH-PERPETUAL.raw","data":{"timestamp":1734114565683,"type":"change","change_id":15557283502,"instrument_name":"ETH-PERPETUAL","bids":[],"asks":[["change",3896.55,1.6e5]],"prev_change_id":15557283501}}}
{"jsonrpc":"2.0","method":"subscription","params":{"channel":"book.ETH-PERPETUAL.raw","data":{"timestamp":1734114565683,"type":"change","change_id":15557283502,"instrument_name":"ETH-PERPETUAL","bids":[],"asks":[["change",3896.55,1.6e5]],"prev_change_id":15557283501}}}
{"jsonrpc":"2.0","method":"subscription","params":{"channel":"book.ETH-PERPETUAL.raw","data":{"timestamp":1734114565807,"type":"change","change_id":15557283504,"instrument_name":"ETH-PERPETUAL","bids":[["delete",3881.45,0.0]],"asks":[["delete",3896.55,0.0]],"prev_change_id":15557283502}}}
{"jsonrpc":"2.0","method":"subscription","params":{"channel":"book.ETH-PERPETUAL.raw","data":{"timestamp":1734114565807,"type":"change","change_id":15557283504,"instrument_name":"ETH-PERPETUAL","bids":[["delete",3881.45,0.0]],"asks":[["delete",3896.55,0.0]],"prev_change_id":15557283502}}}
{"jsonrpc":"2.0","method":"subscription","params":{"channel":"book.ETH-PERPETUAL.raw","data":{"timestamp":1734114565822,"type":"change","change_id":15557283505,"instrument_name":"ETH-PERPETUAL","bids":[["change",3869.8,4370.0]],"asks":[],"prev_change_id":15557283504}}}
{"jsonrpc":"2.0","method":"subscription","params":{"channel":"book.ETH-PERPETUAL.raw","data":{"timestamp":1734114565822,"type":"change","change_id":15557283505,"instrument_name":"ETH-PERPETUAL","bids":[["change",3869.8,4370.0]],"asks":[],"prev_change_id":15557283504}}}
{"jsonrpc":"2.0","method":"subscription","params":{"channel":"book.ETH-PERPETUAL.raw","data":{"timestamp":1734114565976,"type":"change","change_id":15557283507,"instrument_name":"ETH-PERPETUAL","bids":[],"asks":[["delete",3935.35,0.0],["new",3947.75,700.0]],"prev_change_id":15557283505}}}
{"jsonrpc":"2.0","method":"subscription","params":{"channel":"book.ETH-PERPETUAL.raw","data":{"timestamp":1734114565976,"type":"change","change_id":15557283507,"instrument_name":"ETH-PERPETUAL","bids":[],"asks":[["delete",3935.35,0.0],["new",3947.75,700.0]],"prev_change_id":15557283505}}}
{"jsonrpc":"2.0","method":"subscription","params":{"channel":"book.ETH-PERPETUAL.raw","data":{"timestamp":1734114566019,"type":"change","change_id":15557283508,"instrument_name":"ETH-PERPETUAL","bids":[["new",3881.45,8.0e4]],"asks":[],"prev_change_id":15557283507}}}
{"jsonrpc":"2.0","method":"subscription","params":{"channel":"book.ETH-PERPETUAL.raw","data":{"timestamp":1734114566019,"type":"change","change_id":15557283508,"instrument_name":"ETH-PERPETUAL","bids":[["new",3881.45,8.0e4]],"asks":[],"prev_change_id":15557283507}}}
{"jsonrpc":"2.0","method":"subscription","params":{"channel":"book.ETH-PERPETUAL.raw","data":{"timestamp":1734114566021,"type":"change","change_id":15557283509,"instrument_name":"ETH-PERPETUAL","bids":[],"asks":[["new",3896.55,8.0e4]],"prev_change_id":15557283508}}}
{"jsonrpc":"2.0","method":"subscription","params":{"channel":"book.ETH-PERPETUAL.raw","data":{"timestamp":1734114566021,"type":"change","change_id":15557283509,"instrument_name":"ETH-PERPETUAL","bids":[],"asks":[["new",3896.55,8.0e4]],"prev_change_id":15557283508}}}
{"jsonrpc":"2.0","method":"subscription","params":{"channel":"book.ETH-PERPETUAL.raw","data":{"timestamp":1734114566022,"type":"change","change_id":15557283510,"instrument_name":"ETH-PERPETUAL","bids":[["change",3881.45,1.0e5]],"asks":[],"prev_change_id":15557283509}}}
{"jsonrpc":"2.0","method":"subscription","params":{"channel":"book.ETH-PERPETUAL.raw","data":{"timestamp":1734114566022,"type":"change","change_id":15557283510,"instrument_name":"ETH-PERPETUAL","bids":[["change",3881.45,1.0e5]],"asks":[],"prev_change_id":15557283509}}}
{"jsonrpc":"2.0","method":"subscription","params":{"channel":"book.ETH-PERPETUAL.raw","data":{"timestamp":1734114566024,"type":"change","change_id":15557283511,"instrument_name":"ETH-PERPETUAL","bids":[],"asks":[["change",3896.55,1.0e5]],"prev_change_id":15557283510}}}
{"jsonrpc":"2.0","method":"subscription","params":{"channel":"book.ETH-PERPETUAL.raw","data":{"timestamp":1734114566024,"type":"change","change_id":15557283511,"instrument_name":"ETH-PERPETUAL","bids":[],"asks":[["change",3896.55,1.0e5]],"prev_change_id":15557283510}}}
{"jsonrpc":"2.0","method":"subscription","params":{"channel":"book.ETH-PERPETUAL.raw","data":{"timestamp":1734114566026,"type":"change","change_id":15557283512,"instrument_name":"ETH-PERPETUAL","bids":[["change",3881.45,1.8e5]],"asks":[],"prev_change_id":15557283511}}}
{"jsonrpc":"2.0","method":"subscription","params":{"channel":"book.ETH-PERPETUAL.raw","data":{"timestamp":1734114566026,"type":"change","change_id":15557283512,"instrument_name":"ETH-PERPETUAL","bids":[["change",3881.45,1.8e5]],"asks":[],"prev_change_id":15557283511}}}
{"jsonrpc":"2.0","method":"subscription","params":{"channel":"book.ETH-PERPETUAL.raw","data":{"timestamp":1734114566028,"type":"change","change_id":15557283513,"instrument_name":"ETH-PERPETUAL","bids":[],"asks":[["change",3896.55,1.8e5]],"prev_change_id":15557283512}}}
{"jsonrpc":"2.0","method":"subscription","params":{"channel":"book.ETH-PERPETUAL.raw","data":{"timestamp":1734114566028,"type":"change","change_id":15557283513,"instrument_name":"ETH-PERPETUAL","bids":[],"asks":[["change",3896.55,1.8e5]],"prev_change_id":15557283512}}}
{"jsonrpc":"2.0","method":"subscription","params":{"channel":"book.ETH-PERPETUAL.raw","data":{"timestamp":1734114566030,"type":"change","change_id":15557283514,"instrument_name":"ETH-PERPETUAL","bids":[["change",3881.45,2.0e5]],"asks":[],"prev_change_id":15557283513}}}
{"jsonrpc":"2.0","method":"subscription","params":{"channel":"book.ETH-PERPETUAL.raw","data":{"timestamp":1734114566030,"type":"change","change_id":15557283514,"instrument_name":"ETH-PERPETUAL","bids":[["change",3881.45,2.0e5]],"asks":[],"prev_change_id":15557283513}}}
{"jsonrpc":"2.0","method":"subscription","params":{"channel":"book.ETH-PERPETUAL.raw","data":{"timestamp":1734114566031,"type":"change","change_id":15557283515,"instrument_name":"ETH-PERPETUAL","bids":[],"asks":[["change",3896.55,2.0e5]],"prev_change_id":15557283514}}}
{"jsonrpc":"2.0","method":"subscription","params":{"channel":"book.ETH-PERPETUAL.raw","data":{"timestamp":1734114566031,"type":"change","change_id":15557283515,"instrument_name":"ETH-PERPETUAL","bids":[],"asks":[["change",3896.55,2.0e5]],"prev_change_id":15557283514}}}
{"jsonrpc":"2.0","method":"subscription","params":{"channel":"book.ETH-PERPETUAL.raw","data":{"timestamp":1734114566186,"type":"change","change_id":15557283516,"instrument_name":"ETH-PERPETUAL","bids":[["delete",3881.45,0.0]],"asks":[["delete",3896.55,0.0]],"prev_change_id":15557283515}}}
{"jsonrpc":"2.0","method":"subscription","params":{"channel":"book.ETH-PERPETUAL.raw","data":{"timestamp":1734114566186,"type":"change","change_id":15557283516,"instrument_name":"ETH-PERPETUAL","bids":[["delete",3881.45,0.0]],"asks":[["delete",3896.55,0.0]],"prev_change_id":15557283515}}}
{"jsonrpc":"2.0","method":"subscription","params":{"channel":"book.ETH-PERPETUAL.raw","data":{"timestamp":1734114566389,"type":"change","change_id":15557283517,"instrument_name":"ETH-PERPETUAL","bids":[["new",3881.45,8.0e4]],"asks":[],"prev_change_id":15557283516}}}
{"jsonrpc":"2.0","method":"subscription","params":{"channel":"book.ETH-PERPETUAL.raw","data":{"timestamp":1734114566389,"type":"change","change_id":15557283517,"instrument_name":"ETH-PERPETUAL","bids":[["new",3881.45,8.0e4]],"asks":[],"prev_change_id":15557283516}}}
{"jsonrpc":"2.0","method":"subscription","params":{"channel":"book.ETH-PERPETUAL.raw","data":{"timestamp":1734114566391,"type":"change","change_id":15557283518,"instrument_name":"ETH-PERPETUAL","bids":[],"asks":[["new",3896.55,8.0e4]],"prev_change_id":15557283517}}}
{"jsonrpc":"2.0","method":"subscription","params":{"channel":"book.ETH-PERPETUAL.raw","data":{"timestamp":1734114566391,"type":"change","change_id":15557283518,"instrument_name":"ETH-PERPETUAL","bids":[],"asks":[["new",3896.55,8.0e4]],"prev_change_id":15557283517}}}
{"jsonrpc":"2.0","method":"subscription","params":{"channel":"book.ETH-PERPETUAL.raw","data":{"timestamp":1734114566392,"type":"change","change_id":15557283519,"instrument_name":"ETH-PERPETUAL","bids":[["change",3881.45,1.0e5]],"asks":[],"prev_change_id":15557283518}}}
{"jsonrpc":"2.0","method":"subscription","params":{"channel":"book.ETH-PERPETUAL.raw","data":{"timestamp":1734114566392,"type":"change","change_id":15557283519,"instrument_name":"ETH-PERPETUAL","bids":[["change",3881.45,1.0e5]],"asks":[],"prev_change_id":15557283518}}}
{"jsonrpc":"2.0","method":"subscription","params":{"channel":"book.ETH-PERPETUAL.raw","data":{"timestamp":1734114566394,"type":"change","change_id":15557283520,"instrument_name":"ETH-PERPETUAL","bids":[["change",3881.45,1.8e5]],"asks":[],"prev_change_id":15557283519}}}
{"jsonrpc":"2.0","method":"subscription","params":{"channel":"book.ETH-PERPETUAL.raw","data":{"timestamp":1734114566394,"type":"change","change_id":15557283520,"instrument_name":"ETH-PERPETUAL","bids":[["change",3881.45,1.8e5]],"asks":[],"prev_change_id":15557283519}}}
{"jsonrpc":"2.0","method":"subscription","params":{"channel":"book.ETH-PERPETUAL.raw","data":{"timestamp":1734114566395,"type":"change","change_id":15557283521,"instrument_name":"ETH-PERPETUAL","bids":[],"asks":[["change",3896.55,1.6e5]],"prev_change_id":15557283520}}}
{"jsonrpc":"2.0","method":"subscription","params":{"channel":"book.ETH-PERPETUAL.raw","data":{"timestamp":1734114566395,"type":"change","change_id":15557283521,"instrument_name":"ETH-PERPETUAL","bids":[],"asks":[["change",3896.55,1.6e5]],"prev_change_id":15557283520}}}
{"jsonrpc":"2.0","method":"subscription","params":{"channel":"book.ETH-PERPETUAL.raw","data":{"timestamp":1734114566397,"type":"change","change_id":15557283522,"instrument_name":"ETH-PERPETUAL","bids":[["change",3881.45,2.0e5]],"asks":[],"prev_change_id":15557283521}}}
{"jsonrpc":"2.0","method":"subscription","params":{"channel":"book.ETH-PERPETUAL.raw","data":{"timestamp":1734114566397,"type":"change","change_id":15557283522,"instrument_name":"ETH-PERPETUAL","bids":[["change",3881.45,2.0e5]],"asks":[],"prev_change_id":15557283521}}}
{"jsonrpc":"2.0","method":"subscription","params":{"channel":"book.ETH-PERPETUAL.raw","data":{"timestamp":1734114566529,"type":"change","change_id":15557283524,"instrument_name":"ETH-PERPETUAL","bids":[["delete",3881.45,0.0]],"asks":[["delete",3896.55,0.0]],"prev_change_id":15557283522}}}
{"jsonrpc":"2.0","method":"subscription","params":{"channel":"book.ETH-PERPETUAL.raw","data":{"timestamp":1734114566529,"type":"change","change_id":15557283524,"instrument_name":"ETH-PERPETUAL","bids":[["delete",3881.45,0.0]],"asks":[["delete",3896.55,0.0]],"prev_change_id":15557283522}}}
{"jsonrpc":"2.0","method":"subscription","params":{"channel":"book.ETH-PERPETUAL.raw","data":{"timestamp":1734114566746,"type":"change","change_id":15557283527,"instrument_name":"ETH-PERPETUAL","bids":[["new",3881.45,8.0e4]],"asks":[],"prev_change_id":15557283524}}}
{"jsonrpc":"2.0","method":"subscription","params":{"channel":"book.ETH-PERPETUAL.raw","data":{"timestamp":1734114566746,"type":"change","change_id":15557283527,"instrument_name":"ETH-PERPETUAL","bids":[["new",3881.45,8.0e4]],"asks":[],"prev_change_id":15557283524}}}
{"jsonrpc":"2.0","method":"subscription","params":{"channel":"book.ETH-PERPETUAL.raw","data":{"timestamp":1734114566748,"type":"change","change_id":15557283529,"instrument_name":"ETH-PERPETUAL","bids":[],"asks":[["new",3896.55,8.0e4]],"prev_change_id":15557283527}}}
{"jsonrpc":"2.0","method":"subscription","params":{"channel":"book.ETH-PERPETUAL.raw","data":{"timestamp":1734114566748,"type":"change","change_id":15557283529,"instrument_name":"ETH-PERPETUAL","bids":[],"asks":[["new",3896.55,8.0e4]],"prev_change_id":15557283527}}}
{"jsonrpc":"2.0","method":"subscription","params":{"channel":"book.ETH-PERPETUAL.raw","data":{"timestamp":1734114566750,"type":"change","change_id":15557283530,"instrument_name":"ETH-PERPETUAL","bids":[["change",3881.45,1.0e5]],"asks":[],"prev_change_id":15557283529}}}
{"jsonrpc":"2.0","method":"subscription","params":{"channel":"book.ETH-PERPETUAL.raw","data":{"timestamp":1734114566750,"type":"change","change_id":15557283530,"instrument_name":"ETH-PERPETUAL","bids":[["change",3881.45,1.0e5]],"asks":[],"prev_change_id":15557283529}}}
{"jsonrpc":"2.0","method":"subscription","params":{"channel":"book.ETH-PERPETUAL.raw","data":{"timestamp":1734114566751,"type":"change","change_id":15557283531,"instrument_name":"ETH-PERPETUAL","bids":[["change",3881.45,1.8e5]],"asks":[],"prev_change_id":15557283530}}}
{"jsonrpc":"2.0","method":"subscription","params":{"channel":"book.ETH-PERPETUAL.raw","data":{"timestamp":1734114566751,"type":"change","change_id":15557283531,"instrument_name":"ETH-PERPETUAL","bids":[["change",3881.45,1.8e5]],"asks":[],"prev_change_id":15557283530}}}
{"jsonrpc":"2.0","method":"subscription","params":{"channel":"book.ETH-PERPETUAL.raw","data":{"timestamp":1734114566753,"type":"change","change_id":15557283532,"instrument_name":"ETH-PERPETUAL","bids":[],"asks":[["change",3896.55,1.6e5]],"prev_change_id":15557283531}}}
{"jsonrpc":"2.0","method":"subscription","params":{"channel":"book.ETH-PERPETUAL.raw","data":{"timestamp":1734114566753,"type":"change","change_id":15557283532,"instrument_name":"ETH-PERPETUAL","bids":[],"asks":[["change",3896.55,1.6e5]],"prev_change_id":15557283531}}}
{"jsonrpc":"2.0","method":"subscription","params":{"channel":"book.ETH-PERPETUAL.raw","data":{"timestamp":1734114566754,"type":"change","change_id":15557283533,"instrument_name":"ETH-PERPETUAL","bids":[["change",3881.45,2.0e5]],"asks":[],"prev_change_id":15557283532}}}
{"jsonrpc":"2.0","method":"subscription","params":{"channel":"book.ETH-PERPETUAL.raw","data":{"timestamp":1734114566754,"type":"change","change_id":15557283533,"instrument_name":"ETH-PERPETUAL","bids":[["change",3881.45,2.0e5]],"asks":[],"prev_change_id":15557283532}}}
{"jsonrpc":"2.0","method":"subscription","params":{"channel":"book.ETH-PERPETUAL.raw","data":{"timestamp":1734114566757,"type":"change","change_id":15557283534,"instrument_name":"ETH-PERPETUAL","bids":[],"asks":[["change",3896.55,1.8e5]],"prev_change_id":15557283533}}}
{"jsonrpc":"2.0","method":"subscription","params":{"channel":"book.ETH-PERPETUAL.raw","data":{"timestamp":1734114566757,"type":"change","change_id":15557283534,"instrument_name":"ETH-PERPETUAL","bids":[],"asks":[["change",3896.55,1.8e5]],"prev_change_id":15557283533}}}
{"jsonrpc":"2.0","method":"subscription","params":{"channel":"book.ETH-PERPETUAL.raw","data":{"timestamp":1734114566904,"type":"change","change_id":15557283553,"instrument_name":"ETH-PERPETUAL","bids":[["delete",3881.45,0.0]],"asks":[["delete",3896.55,0.0]],"prev_change_id":15557283534}}}
{"jsonrpc":"2.0","method":"subscription","params":{"channel":"book.ETH-PERPETUAL.raw","data":{"timestamp":1734114566904,"type":"change","change_id":15557283553,"instrument_name":"ETH-PERPETUAL","bids":[["delete",3881.45,0.0]],"asks":[["delete",3896.55,0.0]],"prev_change_id":15557283534}}}
{"jsonrpc":"2.0","method":"subscription","params":{"channel":"book.ETH-PERPETUAL.raw","data":{"timestamp":1734114567125,"type":"change","change_id":15557283555,"instrument_name":"ETH-PERPETUAL","bids":[["new",3881.45,8.0e4]],"asks":[],"prev_change_id":15557283553}}}
{"jsonrpc":"2.0","method":"subscription","params":{"channel":"book.ETH-PERPETUAL.raw","data":{"timestamp":1734114567125,"type":"change","change_id":15557283555,"instrument_name":"ETH-PERPETUAL","bids":[["new",3881.45,8.0e4]],"asks":[],"prev_change_id":15557283553}}}
{"jsonrpc":"2.0","method":"subscription","params":{"channel":"book.ETH-PERPETUAL.raw","data":{"timestamp":1734114567131,"type":"change","change_id":15557283556,"instrument_name":"ETH-PERPETUAL","bids":[],"asks":[["new",3896.55,8.0e4]],"prev_change_id":15557283555}}}
{"jsonrpc":"2.0","method":"subscription","params":{"channel":"book.ETH-PERPETUAL.raw","data":{"timestamp":1734114567131,"type":"change","change_id":15557283556,"instrument_name":"ETH-PERPETUAL","bids":[],"asks":[["new",3896.55,8.0e4]],"prev_change_id":15557283555}}}
{"jsonrpc":"2.0","method":"subscription","params":{"channel":"book.ETH-PERPETUAL.raw","data":{"timestamp":1734114567132,"type":"change","change_id":15557283557,"instrument_name":"ETH-PERPETUAL","bids":[["change",3881.45,1.0e5]],"asks":[],"prev_change_id":15557283556}}}
{"jsonrpc":"2.0","method":"subscription","params":{"channel":"book.ETH-PERPETUAL.raw","data":{"timestamp":1734114567132,"type":"change","change_id":15557283557,"instrument_name":"ETH-PERPETUAL","bids":[["change",3881.45,1.0e5]],"asks":[],"prev_change_id":15557283556}}}
{"jsonrpc":"2.0","method":"subscription","params":{"channel":"book.ETH-PERPETUAL.raw","data":{"timestamp":1734114567133,"type":"change","change_id":15557283558,"instrument_name":"ETH-PERPETUAL","bids":[["change",3881.45,1.8e5]],"asks":[],"prev_change_id":15557283557}}}
{"jsonrpc":"2.0","method":"subscription","params":{"channel":"book.ETH-PERPETUAL.raw","data":{"timestamp":1734114567133,"type":"change","change_id":15557283558,"instrument_name":"ETH-PERPETUAL","bids":[["change",3881.45,1.8e5]],"asks":[],"prev_change_id":15557283557}}}
{"jsonrpc":"2.0","method":"subscription","params":{"channel":"book.ETH-PERPETUAL.raw","data":{"timestamp":1734114567137,"type":"change","change_id":15557283559,"instrument_name":"ETH-PERPETUAL","bids":[],"asks":[["change",3896.55,1.6e5]],"prev_change_id":15557283558}}}
{"jsonrpc":"2.0","method":"subscription","params":{"channel":"book.ETH-PERPETUAL.raw","data":{"timestamp":1734114567137,"type":"change","change_id":15557283559,"instrument_name":"ETH-PERPETUAL","bids":[],"asks":[["change",3896.55,1.6e5]],"prev_change_id":15557283558}}}
{"jsonrpc":"2.0","method":"subscription","params":{"channel":"book.ETH-PERPETUAL.raw","data":{"timestamp":1734114567138,"type":"change","change_id":15557283560,"instrument_name":"ETH-PERPETUAL","bids":[["change",3881.45,2.0e5]],"asks":[],"prev_change_id":15557283559}}}
{"jsonrpc":"2.0","method":"subscription","params":{"channel":"book.ETH-PERPETUAL.raw","data":{"timestamp":1734114567138,"type":"change","change_id":15557283560,"instrument_name":"ETH-PERPETUAL","bids":[["change",3881.45,2.0e5]],"asks":[],"prev_change_id":15557283559}}}
{"jsonrpc":"2.0","method":"subscription","params":{"channel":"book.ETH-PERPETUAL.raw","data":{"timestamp":1734114567141,"type":"change","change_id":15557283561,"instrument_name":"ETH-PERPETUAL","bids":[],"asks":[["change",3896.55,1.8e5]],"prev_change_id":15557283560}}}
{"jsonrpc":"2.0","method":"subscription","params":{"channel":"book.ETH-PERPETUAL.raw","data":{"timestamp":1734114567141,"type":"change","change_id":15557283561,"instrument_name":"ETH-PERPETUAL","bids":[],"asks":[["change",3896.55,1.8e5]],"prev_change_id":15557283560}}}
{"jsonrpc":"2.0","method":"subscription","params":{"channel":"book.ETH-PERPETUAL.raw","data":{"timestamp":1734114567291,"type":"change","change_id":15557283562,"instrument_name":"ETH-PERPETUAL","bids":[["delete",3881.45,0.0]],"asks":[["delete",3896.55,0.0]],"prev_change_id":15557283561}}}
{"jsonrpc":"2.0","method":"subscription","params":{"channel":"book.ETH-PERPETUAL.raw","data":{"timestamp":1734114567291,"type":"change","change_id":15557283562,"instrument_name":"ETH-PERPETUAL","bids":[["delete",3881.45,0.0]],"asks":[["delete",3896.55,0.0]],"prev_change_id":15557283561}}}
{"jsonrpc":"2.0","method":"subscription","params":{"channel":"book.ETH-PERPETUAL.raw","data":{"timestamp":1734114567510,"type":"change","change_id":15557283563,"instrument_name":"ETH-PERPETUAL","bids":[["new",3881.45,8.0e4]],"asks":[],"prev_change_id":15557283562}}}
{"jsonrpc":"2.0","method":"subscription","params":{"channel":"book.ETH-PERPETUAL.raw","data":{"timestamp":1734114567510,"type":"change","change_id":15557283563,"instrument_name":"ETH-PERPETUAL","bids":[["new",3881.45,8.0e4]],"asks":[],"prev_change_id":15557283562}}}
{"jsonrpc":"2.0","method":"subscription","params":{"channel":"book.ETH-PERPETUAL.raw","data":{"timestamp":1734114567522,"type":"change","change_id":15557283564,"instrument_name":"ETH-PERPETUAL","bids":[],"asks":[["new",3896.55,8.0e4]],"prev_change_id":15557283563}}}
{"jsonrpc":"2.0","method":"subscription","params":{"channel":"book.ETH-PERPETUAL.raw","data":{"timestamp":1734114567522,"type":"change","change_id":15557283564,"instrument_name":"ETH-PERPETUAL","bids":[],"asks":[["new",3896.55,8.0e4]],"prev_change_id":15557283563}}}
{"jsonrpc":"2.0","method":"subscription","params":{"channel":"book.ETH-PERPETUAL.raw","data":{"timestamp":1734114567529,"type":"change","change_id":15557283565,"instrument_name":"ETH-PERPETUAL","bids":[["change",3881.45,1.0e5]],"asks":[],"prev_change_id":15557283564}}}
{"jsonrpc":"2.0","method":"subscription","params":{"channel":"book.ETH-PERPETUAL.raw","data":{"timestamp":1734114567529,"type":"change","change_id":15557283565,"instrument_name":"ETH-PERPETUAL","bids":[["change",3881.45,1.0e5]],"asks":[],"prev_change_id":15557283564}}}
{"jsonrpc":"2.0","method":"subscription","params":{"channel":"book.ETH-PERPETUAL.raw","data":{"timestamp":1734114567531,"type":"change","change_id":15557283567,"instrument_name":"ETH-PERPETUAL","bids":[["change",3881.45,1.8e5]],"asks":[],"prev_change_id":15557283565}}}
{"jsonrpc":"2.0","method":"subscription","params":{"channel":"book.ETH-PERPETUAL.raw","data":{"timestamp":1734114567531,"type":"change","change_id":15557283567,"instrument_name":"ETH-PERPETUAL","bids":[["change",3881.45,1.8e5]],"asks":[],"prev_change_id":15557283565}}}
{"jsonrpc":"2.0","method":"subscription","params":{"channel":"book.ETH-PERPETUAL.raw","data":{"timestamp":1734114567532,"type":"change","change_id":15557283568,"instrument_name":"ETH-PERPETUAL","bids":[],"asks":[["change",3896.55,1.6e5]],"prev_change_id":15557283567}}}
{"jsonrpc":"2.0","method":"subscription","params":{"channel":"book.ETH-PERPETUAL.raw","data":{"timestamp":1734114567532,"type":"change","change_id":15557283568,"instrument_name":"ETH-PERPETUAL","bids":[],"asks":[["change",3896.55,1.6e5]],"prev_change_id":15557283567}}}
{"jsonrpc":"2.0","method":"subscription","params":{"channel":"book.ETH-PERPETUAL.raw","data":{"timestamp":1734114567533,"type":"change","change_id":15557283569,"instrument_name":"ETH-PERPETUAL","bids":[["change",3881.45,2.0e5]],"asks":[],"prev_change_id":15557283568}}}
{"jsonrpc":"2.0","method":"subscription","params":{"channel":"book.ETH-PERPETUAL.raw","data":{"timestamp":1734114567533,"type":"change","change_id":15557283569,"instrument_name":"ETH-PERPETUAL","bids":[["change",3881.45,2.0e5]],"asks":[],"prev_change_id":15557283568}}}
{"jsonrpc":"2.0","method":"subscription","params":{"channel":"book.ETH-PERPETUAL.raw","data":{"timestamp":1734114567658,"type":"change","change_id":15557283570,"instrument_name":"ETH-PERPETUAL","bids":[],"asks":[["delete",3908.1,0.0],["new",3919.85,500.0]],"prev_change_id":15557283569}}}
{"jsonrpc":"2.0","method":"subscription","params":{"channel":"book.ETH-PERPETUAL.raw","data":{"timestamp":1734114567658,"type":"change","change_id":15557283570,"instrument_name":"ETH-PERPETUAL","bids":[],"asks":[["delete",3908.1,0.0],["new",3919.85,500.0]],"prev_change_id":15557283569}}}
{"jsonrpc":"2.0","method":"subscription","params":{"channel":"book.ETH-PERPETUAL.raw","data":{"timestamp":1734114567703,"type":"change","change_id":15557283571,"instrument_name":"ETH-PERPETUAL","bids":[["delete",3881.45,0.0]],"asks":[["delete",3896.55,0.0]],"prev_change_id":15557283570}}}
{"jsonrpc":"2.0","method":"subscription","params":{"channel":"book.ETH-PERPETUAL.raw","data":{"timestamp":1734114567703,"type":"change","change_id":15557283571,"instrument_name":"ETH-PERPETUAL","bids":[["delete",3881.45,0.0]],"asks":[["delete",3896.55,0.0]],"prev_change_id":15557283570}}}
{"jsonrpc":"2.0","method":"subscription","params":{"channel":"book.ETH-PERPETUAL.raw","data":{"timestamp":1734114567912,"type":"change","change_id":15557283596,"instrument_name":"ETH-PERPETUAL","bids":[["new",3881.45,8.0e4]],"asks":[],"prev_change_id":15557283571}}}
{"jsonrpc":"2.0","method":"subscription","params":{"channel":"book.ETH-PERPETUAL.raw","data":{"timestamp":1734114567912,"type":"change","change_id":15557283596,"instrument_name":"ETH-PERPETUAL","bids":[["new",3881.45,8.0e4]],"asks":[],"prev_change_id":15557283571}}}
{"jsonrpc":"2.0","method":"subscription","params":{"channel":"book.ETH-PERPETUAL.raw","data":{"timestamp":1734114567915,"type":"change","change_id":15557283597,"instrument_name":"ETH-PERPETUAL","bids":[],"asks":[["new",3896.55,8.0e4]],"prev_change_id":15557283596}}}
{"jsonrpc":"2.0","method":"subscription","params":{"channel":"book.ETH-PERPETUAL.raw","data":{"timestamp":1734114567915,"type":"change","change_id":15557283597,"instrument_name":"ETH-PERPETUAL","bids":[],"asks":[["new",3896.55,8.0e4]],"prev_change_id":15557283596}}}
{"jsonrpc":"2.0","method":"subscription","params":{"channel":"book.ETH-PERPETUAL.raw","data":{"timestamp":1734114567916,"type":"change","change_id":15557283598,"instrument_name":"ETH-PERPETUAL","bids":[["change",3881.45,1.0e5]],"asks":[],"prev_change_id":15557283597}}}
{"jsonrpc":"2.0","method":"subscription","params":{"channel":"book.ETH-PERPETUAL.raw","data":{"timestamp":1734114567916,"type":"change","change_id":15557283598,"instrument_name":"ETH-PERPETUAL","bids":[["change",3881.45,1.0e5]],"asks":[],"prev_change_id":15557283597}}}
{"jsonrpc":"2.0","method":"subscription","params":{"channel":"book.ETH-PERPETUAL.raw","data":{"timestamp":1734114567919,"type":"change","change_id":15557283599,"instrument_name":"ETH-PERPETUAL","bids":[],"asks":[["change",3896.55,1.0e5]],"prev_change_id":15557283598}}}
{"jsonrpc":"2.0","method":"subscription","params":{"channel":"book.ETH-PERPETUAL.raw","data":{"timestamp":1734114567919,"type":"change","change_id":15557283599,"instrument_name":"ETH-PERPETUAL","bids":[],"asks":[["change",3896.55,1.0e5]],"prev_change_id":15557283598}}}
{"jsonrpc":"2.0","method":"subscription","params":{"channel":"book.ETH-PERPETUAL.raw","data":{"timestamp":1734114567921,"type":"change","change_id":15557283600,"instrument_name":"ETH-PERPETUAL","bids":[["change",3881.45,1.8e5]],"asks":[],"prev_change_id":15557283599}}}
{"jsonrpc":"2.0","method":"subscription","params":{"channel":"book.ETH-PERPETUAL.raw","data":{"timestamp":1734114567921,"type":"change","change_id":15557283600,"instrument_name":"ETH-PERPETUAL","bids":[["change",3881.45,1.8e5]],"asks":[],"prev_change_id":15557283599}}}
{"jsonrpc":"2.0","method":"subscription","params":{"channel":"book.ETH-PERPETUAL.raw","data":{"timestamp":1734114567924,"type":"change","change_id":15557283601,"instrument_name":"ETH-PERPETUAL","bids":[],"asks":[["change",3896.55,1.8e5]],"prev_change_id":15557283600}}}
{"jsonrpc":"2.0","method":"subscription","params":{"channel":"book.ETH-PERPETUAL.raw","data":{"timestamp":1734114567924,"type":"change","change_id":15557283601,"instrument_name":"ETH-PERPETUAL","bids":[],"asks":[["change",3896.55,1.8e5]],"prev_change_id":15557283600}}}
{"jsonrpc":"2.0","method":"subscription","params":{"channel":"book.ETH-PERPETUAL.raw","data":{"timestamp":1734114567926,"type":"change","change_id":15557283602,"instrument_name":"ETH-PERPETUAL","bids":[["change",3881.45,2.0e5]],"asks":[],"prev_change_id":15557283601}}}
{"jsonrpc":"2.0","method":"subscription","params":{"channel":"book.ETH-PERPETUAL.raw","data":{"timestamp":1734114567926,"type":"change","change_id":15557283602,"instrument_name":"ETH-PERPETUAL","bids":[["change",3881.45,2.0e5]],"asks":[],"prev_change_id":15557283601}}}
{"jsonrpc":"2.0","method":"subscription","params":{"channel":"book.ETH-PERPETUAL.raw","data":{"timestamp":1734114567929,"type":"change","change_id":15557283603,"instrument_name":"ETH-PERPETUAL","bids":[],"asks":[["change",3896.55,2.0e5]],"prev_change_id":15557283602}}}
{"jsonrpc":"2.0","method":"subscription","params":{"channel":"book.ETH-PERPETUAL.raw","data":{"timestamp":1734114567929,"type":"change","change_id":15557283603,"instrument_name":"ETH-PERPETUAL","bids":[],"asks":[["change",3896.55,2.0e5]],"prev_change_id":15557283602}}}
{"jsonrpc":"2.0","method":"subscription","params":{"channel":"book.ETH-PERPETUAL.raw","data":{"timestamp":1734114568012,"type":"change","change_id":15557283605,"instrument_name":"ETH-PERPETUAL","bids":[["delete",3881.45,0.0]],"asks":[["delete",3896.55,0.0]],"prev_change_id":15557283603}}}
{"jsonrpc":"2.0","method":"subscription","params":{"channel":"book.ETH-PERPETUAL.raw","data":{"timestamp":1734114568012,"type":"change","change_id":15557283605,"instrument_name":"ETH-PERPETUAL","bids":[["delete",3881.45,0.0]],"asks":[["delete",3896.55,0.0]],"prev_change_id":15557283603}}}
{"jsonrpc":"2.0","method":"subscription","params":{"channel":"book.ETH-PERPETUAL.raw","data":{"timestamp":1734114568201,"type":"change","change_id":15557283607,"instrument_name":"ETH-PERPETUAL","bids":[["new",3881.45,8.0e4]],"asks":[],"prev_change_id":15557283605}}}
{"jsonrpc":"2.0","method":"subscription","params":{"channel":"book.ETH-PERPETUAL.raw","data":{"timestamp":1734114568201,"type":"change","change_id":15557283607,"instrument_name":"ETH-PERPETUAL","bids":[["new",3881.45,8.0e4]],"asks":[],"prev_change_id":15557283605}}}
{"jsonrpc":"2.0","method":"subscription","params":{"channel":"book.ETH-PERPETUAL.raw","data":{"timestamp":1734114568203,"type":"change","change_id":15557283608,"instrument_name":"ETH-PERPETUAL","bids":[],"asks":[["new",3896.55,8.0e4]],"prev_change_id":15557283607}}}
{"jsonrpc":"2.0","method":"subscription","params":{"channel":"book.ETH-PERPETUAL.raw","data":{"timestamp":1734114568203,"type":"change","change_id":15557283608,"instrument_name":"ETH-PERPETUAL","bids":[],"asks":[["new",3896.55,8.0e4]],"prev_change_id":15557283607}}}
{"jsonrpc":"2.0","method":"subscription","params":{"channel":"book.ETH-PERPETUAL.raw","data":{"timestamp":1734114568205,"type":"change","change_id":15557283609,"instrument_name":"ETH-PERPETUAL","bids":[["change",3881.45,1.0e5]],"asks":[],"prev_change_id":15557283608}}}
{"jsonrpc":"2.0","method":"subscription","params":{"channel":"book.ETH-PERPETUAL.raw","data":{"timestamp":1734114568205,"type":"change","change_id":15557283609,"instrument_name":"ETH-PERPETUAL","bids":[["change",3881.45,1.0e5]],"asks":[],"prev_change_id":15557283608}}}
{"jsonrpc":"2.0","method":"subscription","params":{"channel":"book.ETH-PERPETUAL.raw","data":{"timestamp":1734114568206,"type":"change","change_id":15557283610,"instrument_name":"ETH-PERPETUAL","bids":[["change",3881.45,1.8e5]],"asks":[],"prev_change_id":15557283609}}}
{"jsonrpc":"2.0","method":"subscription","params":{"channel":"book.ETH-PERPETUAL.raw","data":{"timestamp":1734114568206,"type":"change","change_id":15557283610,"instrument_name":"ETH-PERPETUAL","bids":[["change",3881.45,1.8e5]],"asks":[],"prev_change_id":15557283609}}}
{"jsonrpc":"2.0","method":"subscription","params":{"channel":"book.ETH-PERPETUAL.raw","data":{"timestamp":1734114568208,"type":"change","change_id":15557283611,"instrument_name":"ETH-PERPETUAL","bids":[],"asks":[["change",3896.55,1.6e5]],"prev_change_id":15557283610}}}
{"jsonrpc":"2.0","method":"subscription","params":{"channel":"book.ETH-PERPETUAL.raw","data":{"timestamp":1734114568208,"type":"change","change_id":15557283611,"instrument_name":"ETH-PERPETUAL","bids":[],"asks":[["change",3896.55,1.6e5]],"prev_change_id":15557283610}}}
{"jsonrpc":"2.0","method":"subscription","params":{"channel":"book.ETH-PERPETUAL.raw","data":{"timestamp":1734114568209,"type":"change","change_id":15557283612,"instrument_name":"ETH-PERPETUAL","bids":[["change",3881.45,2.0e5]],"asks":[],"prev_change_id":15557283611}}}
{"jsonrpc":"2.0","method":"subscription","params":{"channel":"book.ETH-PERPETUAL.raw","data":{"timestamp":1734114568209,"type":"change","change_id":15557283612,"instrument_name":"ETH-PERPETUAL","bids":[["change",3881.45,2.0e5]],"asks":[],"prev_change_id":15557283611}}}
{"jsonrpc":"2.0","method":"subscription","params":{"channel":"book.ETH-PERPETUAL.raw","data":{"timestamp":1734114568292,"type":"change","change_id":15557283613,"instrument_name":"ETH-PERPETUAL","bids":[["delete",3881.45,0.0]],"asks":[["delete",3896.55,0.0]],"prev_change_id":15557283612}}}
{"jsonrpc":"2.0","method":"subscription","params":{"channel":"book.ETH-PERPETUAL.raw","data":{"timestamp":1734114568292,"type":"change","change_id":15557283613,"instrument_name":"ETH-PERPETUAL","bids":[["delete",3881.45,0.0]],"asks":[["delete",3896.55,0.0]],"prev_change_id":15557283612}}}
{"jsonrpc":"2.0","method":"subscription","params":{"channel":"book.ETH-PERPETUAL.raw","data":{"timestamp":1734114568352,"type":"change","change_id":15557283614,"instrument_name":"ETH-PERPETUAL","bids":[],"asks":[["new",3916.05,500.0],["delete",3927.65,0.0]],"prev_change_id":15557283613}}}
{"jsonrpc":"2.0","method":"subscription","params":{"channel":"book.ETH-PERPETUAL.raw","data":{"timestamp":1734114568352,"type":"change","change_id":15557283614,"instrument_name":"ETH-PERPETUAL","bids":[],"asks":[["new",3916.05,500.0],["delete",3927.65,0.0]],"prev_change_id":15557283613}}}
{"jsonrpc":"2.0","method":"subscription","params":{"channel":"book.ETH-PERPETUAL.raw","data":{"timestamp":1734114568526,"type":"change","change_id":15557283615,"instrument_name":"ETH-PERPETUAL","bids":[["new",3881.45,8.0e4]],"asks":[],"prev_change_id":15557283614}}}
{"jsonrpc":"2.0","method":"subscription","params":{"channel":"book.ETH-PERPETUAL.raw","data":{"timestamp":1734114568526,"type":"change","change_id":15557283615,"instrument_name":"ETH-PERPETUAL","bids":[["new",3881.45,8.0e4]],"asks":[],"prev_change_id":15557283614}}}
{"jsonrpc":"2.0","method":"subscription","params":{"channel":"book.ETH-PERPETUAL.raw","data":{"timestamp":1734114568536,"type":"change","change_id":15557283616,"instrument_name":"ETH-PERPETUAL","bids":[],"asks":[["new",3896.55,8.0e4]],"prev_change_id":15557283615}}}
{"jsonrpc":"2.0","method":"subscription","params":{"channel":"book.ETH-PERPETUAL.raw","data":{"timestamp":1734114568536,"type":"change","change_id":15557283616,"instrument_name":"ETH-PERPETUAL","bids":[],"asks":[["new",3896.55,8.0e4]],"prev_change_id":15557283615}}}
{"jsonrpc":"2.0","method":"subscription","params":{"channel":"book.ETH-PERPETUAL.raw","data":{"timestamp":1734114568537,"type":"change","change_id":15557283618,"instrument_name":"ETH-PERPETUAL","bids":[["change",3881.45,1.0e5]],"asks":[],"prev_change_id":15557283616}}}
{"jsonrpc":"2.0","method":"subscription","params":{"channel":"book.ETH-PERPETUAL.raw","data":{"timestamp":1734114568537,"type":"change","change_id":15557283618,"instrument_name":"ETH-PERPETUAL","bids":[["change",3881.45,1.0e5]],"asks":[],"prev_change_id":15557283616}}}
{"jsonrpc":"2.0","method":"subscription","params":{"channel":"book.ETH-PERPETUAL.raw","data":{"timestamp":1734114568538,"type":"change","change_id":15557283619,"instrument_name":"ETH-PERPETUAL","bids":[["change",3881.45,1.8e5]],"asks":[],"prev_change_id":15557283618}}}
{"jsonrpc":"2.0","method":"subscription","params":{"channel":"book.ETH-PERPETUAL.raw","data":{"timestamp":1734114568538,"type":"change","change_id":15557283619,"instrument_name":"ETH-PERPETUAL","bids":[["change",3881.45,1.8e5]],"asks":[],"prev_change_id":15557283618}}}
{"jsonrpc":"2.0","method":"subscription","params":{"channel":"book.ETH-PERPETUAL.raw","data":{"timestamp":1734114568539,"type":"change","change_id":15557283620,"instrument_name":"ETH-PERPETUAL","bids":[],"asks":[["change",3896.55,1.6e5]],"prev_change_id":15557283619}}}
{"jsonrpc":"2.0","method":"subscription","params":{"channel":"book.ETH-PERPETUAL.raw","data":{"timestamp":1734114568539,"type":"change","change_id":15557283620,"instrument_name":"ETH-PERPETUAL","bids":[],"asks":[["change",3896.55,1.6e5]],"prev_change_id":15557283619}}}
{"jsonrpc":"2.0","method":"subscription","params":{"channel":"book.ETH-PERPETUAL.raw","data":{"timestamp":1734114568540,"type":"change","change_id":15557283621,"instrument_name":"ETH-PERPETUAL","bids":[["change",3881.45,2.0e5]],"asks":[],"prev_change_id":15557283620}}}
{"jsonrpc":"2.0","method":"subscription","params":{"channel":"book.ETH-PERPETUAL.raw","data":{"timestamp":1734114568540,"type":"change","change_id":15557283621,"instrument_name":"ETH-PERPETUAL","bids":[["change",3881.45,2.0e5]],"asks":[],"prev_change_id":15557283620}}}
{"jsonrpc":"2.0","method":"subscription","params":{"channel":"book.ETH-PERPETUAL.raw","data":{"timestamp":1734114568632,"type":"change","change_id":15557283623,"instrument_name":"ETH-PERPETUAL","bids":[["delete",3881.45,0.0]],"asks":[["delete",3896.55,0.0]],"prev_change_id":15557283621}}}
{"jsonrpc":"2.0","method":"subscription","params":{"channel":"book.ETH-PERPETUAL.raw","data":{"timestamp":1734114568632,"type":"change","change_id":15557283623,"instrument_name":"ETH-PERPETUAL","bids":[["delete",3881.45,0.0]],"asks":[["delete",3896.55,0.0]],"prev_change_id":15557283621}}}
{"jsonrpc":"2.0","method":"subscription","params":{"channel":"book.ETH-PERPETUAL.raw","data":{"timestamp":1734114568819,"type":"change","change_id":15557283633,"instrument_name":"ETH-PERPETUAL","bids":[],"asks":[["new",3896.65,8.0e4]],"prev_change_id":15557283623}}}
{"jsonrpc":"2.0","method":"subscription","params":{"channel":"book.ETH-PERPETUAL.raw","data":{"timestamp":1734114568819,"type":"change","change_id":15557283633,"instrument_name":"ETH-PERPETUAL","bids":[],"asks":[["new",3896.65,8.0e4]],"prev_change_id":15557283623}}}
{"jsonrpc":"2.0","method":"subscription","params":{"channel":"book.ETH-PERPETUAL.raw","data":{"timestamp":1734114568822,"type":"change","change_id":15557283634,"instrument_name":"ETH-PERPETUAL","bids":[["new",3881.55,8.0e4]],"asks":[],"prev_change_id":15557283633}}}
{"jsonrpc":"2.0","method":"subscription","params":{"channel":"book.ETH-PERPETUAL.raw","data":{"timestamp":1734114568822,"type":"change","change_id":15557283634,"instrument_name":"ETH-PERPETUAL","bids":[["new",3881.55,8.0e4]],"asks":[],"prev_change_id":15557283633}}}
{"jsonrpc":"2.0","method":"subscription","params":{"channel":"book.ETH-PERPETUAL.raw","data":{"timestamp":1734114568822,"type":"change","change_id":15557283635,"instrument_name":"ETH-PERPETUAL","bids":[],"asks":[["change",3896.65,1.0e5]],"prev_change_id":15557283634}}}
{"jsonrpc":"2.0","method":"subscription","params":{"channel":"book.ETH-PERPETUAL.raw","data":{"timestamp":1734114568822,"type":"change","change_id":15557283635,"instrument_name":"ETH-PERPETUAL","bids":[],"asks":[["change",3896.65,1.0e5]],"prev_change_id":15557283634}}}
{"jsonrpc":"2.0","method":"subscription","params":{"channel":"book.ETH-PERPETUAL.raw","data":{"timestamp":1734114568824,"type":"change","change_id":15557283636,"instrument_name":"ETH-PERPETUAL","bids":[["change",3881.55,1.0e5]],"asks":[],"prev_change_id":15557283635}}}
{"jsonrpc":"2.0","method":"subscription","params":{"channel":"book.ETH-PERPETUAL.raw","data":{"timestamp":1734114568824,"type":"change","change_id":15557283636,"instrument_name":"ETH-PERPETUAL","bids":[["change",3881.55,1.0e5]],"asks":[],"prev_change_id":15557283635}}}
{"jsonrpc":"2.0","method":"subscription","params":{"channel":"book.ETH-PERPETUAL.raw","data":{"timestamp":1734114568826,"type":"change","change_id":15557283637,"instrument_name":"ETH-PERPETUAL","bids":[],"asks":[["change",3896.65,1.8e5]],"prev_change_id":15557283636}}}
{"jsonrpc":"2.0","method":"subscription","params":{"channel":"book.ETH-PERPETUAL.raw","data":{"timestamp":1734114568826,"type":"change","change_id":15557283637,"instrument_name":"ETH-PERPETUAL","bids":[],"asks":[["change",3896.65,1.8e5]],"prev_change_id":15557283636}}}
{"jsonrpc":"2.0","method":"subscription","params":{"channel":"book.ETH-PERPETUAL.raw","data":{"timestamp":1734114568827,"type":"change","change_id":15557283638,"instrument_name":"ETH-PERPETUAL","bids":[["change",3881.55,1.8e5]],"asks":[],"prev_change_id":15557283637}}}
{"jsonrpc":"2.0","method":"subscription","params":{"channel":"book.ETH-PERPETUAL.raw","data":{"timestamp":1734114568827,"type":"change","change_id":15557283638,"instrument_name":"ETH-PERPETUAL","bids":[["change",3881.55,1.8e5]],"asks":[],"prev_change_id":15557283637}}}
{"jsonrpc":"2.0","method":"subscription","params":{"channel":"book.ETH-PERPETUAL.raw","data":{"timestamp":1734114568828,"type":"change","change_id":15557283639,"instrument_name":"ETH-PERPETUAL","bids":[],"asks":[["change",3896.65,2.0e5]],"prev_change_id":15557283638}}}
{"jsonrpc":"2.0","method":"subscription","params":{"channel":"book.ETH-PERPETUAL.raw","data":{"timestamp":1734114568828,"type":"change","change_id":15557283639,"instrument_name":"ETH-PERPETUAL","bids":[],"asks":[["change",3896.65,2.0e5]],"prev_change_id":15557283638}}}
{"jsonrpc":"2.0","method":"subscription","params":{"channel":"book.ETH-PERPETUAL.raw","data":{"timestamp":1734114568829,"type":"change","change_id":15557283640,"instrument_name":"ETH-PERPETUAL","bids":[["change",3881.55,2.0e5]],"asks":[],"prev_change_id":15557283639}}}
{"jsonrpc":"2.0","method":"subscription","params":{"channel":"book.ETH-PERPETUAL.raw","data":{"timestamp":1734114568829,"type":"change","change_id":15557283640,"instrument_name":"ETH-PERPETUAL","bids":[["change",3881.55,2.0e5]],"asks":[],"prev_change_id":15557283639}}}
{"jsonrpc":"2.0","method":"subscription","params":{"channel":"book.ETH-PERPETUAL.raw","data":{"timestamp":1734114569017,"type":"change","change_id":15557283643,"instrument_name":"ETH-PERPETUAL","bids":[["delete",3881.55,0.0]],"asks":[["delete",3896.65,0.0]],"prev_change_id":15557283640}}}
{"jsonrpc":"2.0","method":"subscription","params":{"channel":"book.ETH-PERPETUAL.raw","data":{"timestamp":1734114569017,"type":"change","change_id":15557283643,"instrument_name":"ETH-PERPETUAL","bids":[["delete",3881.55,0.0]],"asks":[["delete",3896.65,0.0]],"prev_change_id":15557283640}}}
{"jsonrpc":"2.0","method":"subscription","params":{"channel":"book.ETH-PERPETUAL.raw","data":{"timestamp":1734114569227,"type":"change","change_id":15557283644,"instrument_name":"ETH-PERPETUAL","bids":[],"asks":[["new",3896.65,8.0e4]],"prev_change_id":15557283643}}}
{"jsonrpc":"2.0","method":"subscription","params":{"channel":"book.ETH-PERPETUAL.raw","data":{"timestamp":1734114569227,"type":"change","change_id":15557283644,"instrument_name":"ETH-PERPETUAL","bids":[],"asks":[["new",3896.65,8.0e4]],"prev_change_id":15557283643}}}
{"jsonrpc":"2.0","method":"subscription","params":{"channel":"book.ETH-PERPETUAL.raw","data":{"timestamp":1734114569229,"type":"change","change_id":15557283645,"instrument_name":"ETH-PERPETUAL","bids":[["new",3881.6,8.0e4]],"asks":[],"prev_change_id":15557283644}}}
{"jsonrpc":"2.0","method":"subscription","params":{"channel":"book.ETH-PERPETUAL.raw","data":{"timestamp":1734114569229,"type":"change","change_id":15557283645,"instrument_name":"ETH-PERPETUAL","bids":[["new",3881.6,8.0e4]],"asks":[],"prev_change_id":15557283644}}}
{"jsonrpc":"2.0","method":"subscription","params":{"channel":"book.ETH-PERPETUAL.raw","data":{"timestamp":1734114569230,"type":"change","change_id":15557283646,"instrument_name":"ETH-PERPETUAL","bids":[],"asks":[["change",3896.65,1.0e5]],"prev_change_id":15557283645}}}
{"jsonrpc":"2.0","method":"subscription","params":{"channel":"book.ETH-PERPETUAL.raw","data":{"timestamp":1734114569230,"type":"change","change_id":15557283646,"instrument_name":"ETH-PERPETUAL","bids":[],"asks":[["change",3896.65,1.0e5]],"prev_change_id":15557283645}}}
{"jsonrpc":"2.0","method":"subscription","params":{"channel":"book.ETH-PERPETUAL.raw","data":{"timestamp":1734114569232,"type":"change","change_id":15557283647,"instrument_name":"ETH-PERPETUAL","bids":[["change",3881.6,1.0e5]],"asks":[],"prev_change_id":15557283646}}}
{"jsonrpc":"2.0","method":"subscription","params":{"channel":"book.ETH-PERPETUAL.raw","data":{"timestamp":1734114569232,"type":"change","change_id":15557283647,"instrument_name":"ETH-PERPETUAL","bids":[["change",3881.6,1.0e5]],"asks":[],"prev_change_id":15557283646}}}
{"jsonrpc":"2.0","method":"subscription","params":{"channel":"book.ETH-PERPETUAL.raw","data":{"timestamp":1734114569234,"type":"change","change_id":15557283648,"instrument_name":"ETH-PERPETUAL","bids":[],"asks":[["change",3896.65,1.8e5]],"prev_change_id":15557283647}}}
{"jsonrpc":"2.0","method":"subscription","params":{"channel":"book.ETH-PERPETUAL.raw","data":{"timestamp":1734114569234,"type":"change","change_id":15557283648,"instrument_name":"ETH-PERPETUAL","bids":[],"asks":[["change",3896.65,1.8e5]],"prev_change_id":15557283647}}}
{"jsonrpc":"2.0","method":"subscription","params":{"channel":"book.ETH-PERPETUAL.raw","data":{"timestamp":1734114569235,"type":"change","change_id":15557283649,"instrument_name":"ETH-PERPETUAL","bids":[["change",3881.6,1.8e5]],"asks":[],"prev_change_id":15557283648}}}
{"jsonrpc":"2.0","method":"subscription","params":{"channel":"book.ETH-PERPETUAL.raw","data":{"timestamp":1734114569235,"type":"change","change_id":15557283649,"instrument_name":"ETH-PERPETUAL","bids":[["change",3881.6,1.8e5]],"asks":[],"prev_change_id":15557283648}}}
{"jsonrpc":"2.0","method":"subscription","params":{"channel":"book.ETH-PERPETUAL.raw","data":{"timestamp":1734114569237,"type":"change","change_id":15557283650,"instrument_name":"ETH-PERPETUAL","bids":[],"asks":[["change",3896.65,2.0e5]],"prev_change_id":15557283649}}}
{"jsonrpc":"2.0","method":"subscription","params":{"channel":"book.ETH-PERPETUAL.raw","data":{"timestamp":1734114569237,"type":"change","change_id":15557283650,"instrument_name":"ETH-PERPETUAL","bids":[],"asks":[["change",3896.65,2.0e5]],"prev_change_id":15557283649}}}
{"jsonrpc":"2.0","method":"subscription","params":{"channel":"book.ETH-PERPETUAL.raw","data":{"timestamp":1734114569238,"type":"change","change_id":15557283651,"instrument_name":"ETH-PERPETUAL","bids":[["change",3881.6,2.0e5]],"asks":[],"prev_change_id":15557283650}}}
{"jsonrpc":"2.0","method":"subscription","params":{"channel":"book.ETH-PERPETUAL.raw","data":{"timestamp":1734114569238,"type":"change","change_id":15557283651,"instrument_name":"ETH-PERPETUAL","bids":[["change",3881.6,2.0e5]],"asks":[],"prev_change_id":15557283650}}}
{"jsonrpc":"2.0","method":"subscription","params":{"channel":"book.ETH-PERPETUAL.raw","data":{"timestamp":1734114569375,"type":"change","change_id":15557283653,"instrument_name":"ETH-PERPETUAL","bids":[["delete",3881.6,0.0]],"asks":[["delete",3896.65,0.0]],"prev_change_id":15557283651}}}
{"jsonrpc":"2.0","method":"subscription","params":{"channel":"book.ETH-PERPETUAL.raw","data":{"timestamp":1734114569375,"type":"change","change_id":15557283653,"instrument_name":"ETH-PERPETUAL","bids":[["delete",3881.6,0.0]],"asks":[["delete",3896.65,0.0]],"prev_change_id":15557283651}}}
{"jsonrpc":"2.0","method":"subscription","params":{"channel":"book.ETH-PERPETUAL.raw","data":{"timestamp":1734114569378,"type":"change","change_id":15557283654,"instrument_name":"ETH-PERPETUAL","bids":[["new",3842.75,700.0],["delete",3817.25,0.0]],"asks":[],"prev_change_id":15557283653}}}
{"jsonrpc":"2.0","method":"subscription","params":{"channel":"book.ETH-PERPETUAL.raw","data":{"timestamp":1734114569378,"type":"change","change_id":15557283654,"instrument_name":"ETH-PERPETUAL","bids":[["new",3842.75,700.0],["delete",3817.25,0.0]],"asks":[],"prev_change_id":15557283653}}}
{"jsonrpc":"2.0","method":"subscription","params":{"channel":"book.ETH-PERPETUAL.raw","data":{"timestamp":1734114569379,"type":"change","change_id":15557283655,"instrument_name":"ETH-PERPETUAL","bids":[["new",3862.15,500.0],["delete",3838.75,0.0]],"asks":[],"prev_change_id":15557283654}}}
{"jsonrpc":"2.0","method":"subscription","params":{"channel":"book.ETH-PERPETUAL.raw","data":{"timestamp":1734114569379,"type":"change","change_id":15557283655,"instrument_name":"ETH-PERPETUAL","bids":[["new",3862.15,500.0],["delete",3838.75,0.0]],"asks":[],"prev_change_id":15557283654}}}
{"jsonrpc":"2.0","method":"subscription","params":{"channel":"book.ETH-PERPETUAL.raw","data":{"timestamp":1734114569560,"type":"change","change_id":15557283659,"instrument_name":"ETH-PERPETUAL","bids":[],"asks":[["new",3896.65,8.0e4]],"prev_change_id":15557283655}}}
{"jsonrpc":"2.0","method":"subscription","params":{"channel":"book.ETH-PERPETUAL.raw","data":{"timestamp":1734114569560,"type":"change","change_id":15557283659,"instrument_name":"ETH-PERPETUAL","bids":[],"asks":[["new",3896.65,8.0e4]],"prev_change_id":15557283655}}}
{"jsonrpc":"2.0","method":"subscription","params":{"channel":"book.ETH-PERPETUAL.raw","data":{"timestamp":1734114569562,"type":"change","change_id":15557283660,"instrument_name":"ETH-PERPETUAL","bids":[["new",3881.6,8.0e4]],"asks":[],"prev_change_id":15557283659}}}
{"jsonrpc":"2.0","method":"subscription","params":{"channel":"book.ETH-PERPETUAL.raw","data":{"timestamp":1734114569562,"type":"change","change_id":15557283660,"instrument_name":"ETH-PERPETUAL","bids":[["new",3881.6,8.0e4]],"asks":[],"prev_change_id":15557283659}}}
{"jsonrpc":"2.0","method":"subscription","params":{"channel":"book.ETH-PERPETUAL.raw","data":{"timestamp":1734114569564,"type":"change","change_id":15557283661,"instrument_name":"ETH-PERPETUAL","bids":[],"asks":[["change",3896.65,1.6e5]],"prev_change_id":15557283660}}}
{"jsonrpc":"2.0","method":"subscription","params":{"channel":"book.ETH-PERPETUAL.raw","data":{"timestamp":1734114569564,"type":"change","change_id":15557283661,"instrument_name":"ETH-PERPETUAL","bids":[],"asks":[["change",3896.65,1.6e5]],"prev_change_id":15557283660}}}
{"jsonrpc":"2.0","method":"subscription","params":{"channel":"book.ETH-PERPETUAL.raw","data":{"timestamp":1734114569566,"type":"change","change_id":15557283662,"instrument_name":"ETH-PERPETUAL","bids":[["change",3881.6,1.6e5]],"asks":[],"prev_change_id":15557283661}}}
{"jsonrpc":"2.0","method":"subscription","params":{"channel":"book.ETH-PERPETUAL.raw","data":{"timestamp":1734114569566,"type":"change","change_id":15557283662,"instrument_name":"ETH-PERPETUAL","bids":[["change",3881.6,1.6e5]],"asks":[],"prev_change_id":15557283661}}}
{"jsonrpc":"2.0","method":"subscription","params":{"channel":"book.ETH-PERPETUAL.raw","data":{"timestamp":1734114569701,"type":"change","change_id":15557283664,"instrument_name":"ETH-PERPETUAL","bids":[["delete",3881.6,0.0]],"asks":[["delete",3896.65,0.0]],"prev_change_id":15557283662}}}
{"jsonrpc":"2.0","method":"subscription","params":{"channel":"book.ETH-PERPETUAL.raw","data":{"timestamp":1734114569701,"type":"change","change_id":15557283664,"instrument_name":"ETH-PERPETUAL","bids":[["delete",3881.6,0.0]],"asks":[["delete",3896.65,0.0]],"prev_change_id":15557283662}}}
{"jsonrpc":"2.0","method":"subscription","params":{"channel":"book.ETH-PERPETUAL.raw","data":{"timestamp":1734114569705,"type":"change","change_id":15557283665,"instrument_name":"ETH-PERPETUAL","bids":[["change",3869.8,3870.0],["new",3858.15,500.0]],"asks":[],"prev_change_id":15557283664}}}
{"jsonrpc":"2.0","method":"subscription","params":{"channel":"book.ETH-PERPETUAL.raw","data":{"timestamp":1734114569705,"type":"change","change_id":15557283665,"instrument_name":"ETH-PERPETUAL","bids":[["change",3869.8,3870.0],["new",3858.15,500.0]],"asks":[],"prev_change_id":15557283664}}}
{"jsonrpc":"2.0","method":"subscription","params":{"channel":"book.ETH-PERPETUAL.raw","data":{"timestamp":1734114569909,"type":"change","change_id":15557283694,"instrument_name":"ETH-PERPETUAL","bids":[["new",3881.6,8.0e4]],"asks":[],"prev_change_id":15557283665}}}
{"jsonrpc":"2.0","method":"subscription","params":{"channel":"book.ETH-PERPETUAL.raw","data":{"timestamp":1734114569909,"type":"change","change_id":15557283694,"instrument_name":"ETH-PERPETUAL","bids":[["new",3881.6,8.0e4]],"asks":[],"prev_change_id":15557283665}}}
{"jsonrpc":"2.0","method":"subscription","params":{"channel":"book.ETH-PERPETUAL.raw","data":{"timestamp":1734114569911,"type":"change","change_id":15557283695,"instrument_name":"ETH-PERPETUAL","bids":[],"asks":[["new",3896.65,8.0e4]],"prev_change_id":15557283694}}}
{"jsonrpc":"2.0","method":"subscription","params":{"channel":"book.ETH-PERPETUAL.raw","data":{"timestamp":1734114569911,"type":"change","change_id":15557283695,"instrument_name":"ETH-PERPETUAL","bids":[],"asks":[["new",3896.65,8.0e4]],"prev_change_id":15557283694}}}
{"jsonrpc":"2.0","method":"subscription","params":{"channel":"book.ETH-PERPETUAL.raw","data":{"timestamp":1734114569913,"type":"change","change_id":15557283696,"instrument_name":"ETH-PERPETUAL","bids":[],"asks":[["change",3896.65,1.0e5]],"prev_change_id":15557283695}}}
{"jsonrpc":"2.0","method":"subscription","params":{"channel":"book.ETH-PERPETUAL.raw","data":{"timestamp":1734114569913,"type":"change","change_id":15557283696,"instrument_name":"ETH-PERPETUAL","bids":[],"asks":[["change",3896.65,1.0e5]],"prev_change_id":15557283695}}}
{"jsonrpc":"2.0","method":"subscription","params":{"channel":"book.ETH-PERPETUAL.raw","data":{"timestamp":1734114569915,"type":"change","change_id":15557283697,"instrument_name":"ETH-PERPETUAL","bids":[["change",3881.6,1.0e5]],"asks":[],"prev_change_id":15557283696}}}
{"jsonrpc":"2.0","method":"subscription","params":{"channel":"book.ETH-PERPETUAL.raw","data":{"timestamp":1734114569915,"type":"change","change_id":15557283697,"instrument_name":"ETH-PERPETUAL","bids":[["change",3881.6,1.0e5]],"asks":[],"prev_change_id":15557283696}}}
{"jsonrpc":"2.0","method":"subscription","params":{"channel":"book.ETH-PERPETUAL.raw","data":{"timestamp":1734114569918,"type":"change","change_id":15557283698,"instrument_name":"ETH-PERPETUAL","bids":[["change",3881.6,1.8e5]],"asks":[],"prev_change_id":15557283697}}}
{"jsonrpc":"2.0","method":"subscription","params":{"channel":"book.ETH-PERPETUAL.raw","data":{"timestamp":1734114569918,"type":"change","change_id":15557283698,"instrument_name":"ETH-PERPETUAL","bids":[["change",3881.6,1.8e5]],"asks":[],"prev_change_id":15557283697}}}
{"jsonrpc":"2.0","method":"subscription","params":{"channel":"book.ETH-PERPETUAL.raw","data":{"timestamp":1734114569920,"type":"change","change_id":15557283699,"instrument_name":"ETH-PERPETUAL","bids":[],"asks":[["change",3896.65,1.8e5]],"prev_change_id":15557283698}}}
{"jsonrpc":"2.0","method":"subscription","params":{"channel":"book.ETH-PERPETUAL.raw","data":{"timestamp":1734114569920,"type":"change","change_id":15557283699,"instrument_name":"ETH-PERPETUAL","bids":[],"asks":[["change",3896.65,1.8e5]],"prev_change_id":15557283698}}}
{"jsonrpc":"2.0","method":"subscription","params":{"channel":"book.ETH-PERPETUAL.raw","data":{"timestamp":1734114569922,"type":"change","change_id":15557283700,"instrument_name":"ETH-PERPETUAL","bids":[],"asks":[["change",3896.65,2.0e5]],"prev_change_id":15557283699}}}
{"jsonrpc":"2.0","method":"subscription","params":{"channel":"book.ETH-PERPETUAL.raw","data":{"timestamp":1734114569922,"type":"change","change_id":15557283700,"instrument_name":"ETH-PERPETUAL","bids":[],"asks":[["change",3896.65,2.0e5]],"prev_change_id":15557283699}}}
{"jsonrpc":"2.0","method":"subscription","params":{"channel":"book.ETH-PERPETUAL.raw","data":{"timestamp":1734114569924,"type":"change","change_id":15557283701,"instrument_name":"ETH-PERPETUAL","bids":[["change",3881.6,2.0e5]],"asks":[],"prev_change_id":15557283700}}}
{"jsonrpc":"2.0","method":"subscription","params":{"channel":"book.ETH-PERPETUAL.raw","data":{"timestamp":1734114569924,"type":"change","change_id":15557283701,"instrument_name":"ETH-PERPETUAL","bids":[["change",3881.6,2.0e5]],"asks":[],"prev_change_id":15557283700}}}
{"jsonrpc":"2.0","method":"subscription","params":{"channel":"book.ETH-PERPETUAL.raw","data":{"timestamp":1734114570064,"type":"change","change_id":15557283702,"instrument_name":"ETH-PERPETUAL","bids":[["delete",3881.6,0.0]],"asks":[["delete",3896.65,0.0]],"prev_change_id":15557283701}}}
{"jsonrpc":"2.0","method":"subscription","params":{"channel":"book.ETH-PERPETUAL.raw","data":{"timestamp":1734114570064,"type":"change","change_id":15557283702,"instrument_name":"ETH-PERPETUAL","bids":[["delete",3881.6,0.0]],"asks":[["delete",3896.65,0.0]],"prev_change_id":15557283701}}}
{"jsonrpc":"2.0","method":"subscription","params":{"channel":"book.ETH-PERPETUAL.raw","data":{"timestamp":1734114570334,"type":"change","change_id":15557283704,"instrument_name":"ETH-PERPETUAL","bids":[["new",3881.6,8.0e4]],"asks":[],"prev_change_id":15557283702}}}
{"jsonrpc":"2.0","method":"subscription","params":{"channel":"book.ETH-PERPETUAL.raw","data":{"timestamp":1734114570334,"type":"change","change_id":15557283704,"instrument_name":"ETH-PERPETUAL","bids":[["new",3881.6,8.0e4]],"asks":[],"prev_change_id":15557283702}}}
{"jsonrpc":"2.0","method":"subscription","params":{"channel":"book.ETH-PERPETUAL.raw","data":{"timestamp":1734114570336,"type":"change","change_id":15557283705,"instrument_name":"ETH-PERPETUAL","bids":[],"asks":[["new",3896.65,8.0e4]],"prev_change_id":15557283704}}}
{"jsonrpc":"2.0","method":"subscription","params":{"channel":"book.ETH-PERPETUAL.raw","data":{"timestamp":1734114570336,"type":"change","change_id":15557283705,"instrument_name":"ETH-PERPETUAL","bids":[],"asks":[["new",3896.65,8.0e4]],"prev_change_id":15557283704}}}
{"jsonrpc":"2.0","method":"subscription","params":{"channel":"book.ETH-PERPETUAL.raw","data":{"timestamp":1734114570338,"type":"change","change_id":15557283706,"instrument_name":"ETH-PERPETUAL","bids":[],"asks":[["change",3896.65,1.0e5]],"prev_change_id":15557283705}}}
{"jsonrpc":"2.0","method":"subscription","params":{"channel":"book.ETH-PERPETUAL.raw","data":{"timestamp":1734114570338,"type":"change","change_id":15557283706,"instrument_name":"ETH-PERPETUAL","bids":[],"asks":[["change",3896.65,1.0e5]],"prev_change_id":15557283705}}}
{"jsonrpc":"2.0","method":"subscription","params":{"channel":"book.ETH-PERPETUAL.raw","data":{"timestamp":1734114570341,"type":"change","change_id":15557283707,"instrument_name":"ETH-PERPETUAL","bids":[["change",3881.6,1.0e5]],"asks":[],"prev_change_id":15557283706}}}
{"jsonrpc":"2.0","method":"subscription","params":{"channel":"book.ETH-PERPETUAL.raw","data":{"timestamp":1734114570341,"type":"change","change_id":15557283707,"instrument_name":"ETH-PERPETUAL","bids":[["change",3881.6,1.0e5]],"asks":[],"prev_change_id":15557283706}}}
{"jsonrpc":"2.0","method":"subscription","params":{"channel":"book.ETH-PERPETUAL.raw","data":{"timestamp":1734114570343,"type":"change","change_id":15557283708,"instrument_name":"ETH-PERPETUAL","bids":[["change",3881.6,1.8e5]],"asks":[],"prev_change_id":15557283707}}}
{"jsonrpc":"2.0","method":"subscription","params":{"channel":"book.ETH-PERPETUAL.raw","data":{"timestamp":1734114570343,"type":"change","change_id":15557283708,"instrument_name":"ETH-PERPETUAL","bids":[["change",3881.6,1.8e5]],"asks":[],"prev_change_id":15557283707}}}
{"jsonrpc":"2.0","method":"subscription","params":{"channel":"book.ETH-PERPETUAL.raw","data":{"timestamp":1734114570345,"type":"change","change_id":15557283709,"instrument_name":"ETH-PERPETUAL","bids":[],"asks":[["change",3896.65,1.8e5]],"prev_change_id":15557283708}}}
{"jsonrpc":"2.0","method":"subscription","params":{"channel":"book.ETH-PERPETUAL.raw","data":{"timestamp":1734114570345,"type":"change","change_id":15557283709,"instrument_name":"ETH-PERPETUAL","bids":[],"asks":[["change",3896.65,1.8e5]],"prev_change_id":15557283708}}}
{"jsonrpc":"2.0","method":"subscription","params":{"channel":"book.ETH-PERPETUAL.raw","data":{"timestamp":1734114570347,"type":"change","change_id":15557283710,"instrument_name":"ETH-PERPETUAL","bids":[],"asks":[["change",3896.65,2.0e5]],"prev_change_id":15557283709}}}
{"jsonrpc":"2.0","method":"subscription","params":{"channel":"book.ETH-PERPETUAL.raw","data":{"timestamp":1734114570347,"type":"change","change_id":15557283710,"instrument_name":"ETH-PERPETUAL","bids":[],"asks":[["change",3896.65,2.0e5]],"prev_change_id":15557283709}}}
{"jsonrpc":"2.0","method":"subscription","params":{"channel":"book.ETH-PERPETUAL.raw","data":{"timestamp":1734114570350,"type":"change","change_id":15557283711,"instrument_name":"ETH-PERPETUAL","bids":[["change",3881.6,2.0e5]],"asks":[],"prev_change_id":15557283710}}}
{"jsonrpc":"2.0","method":"subscription","params":{"channel":"book.ETH-PERPETUAL.raw","data":{"timestamp":1734114570350,"type":"change","change_id":15557283711,"instrument_name":"ETH-PERPETUAL","bids":[["change",3881.6,2.0e5]],"asks":[],"prev_change_id":15557283710}}}
{"jsonrpc":"2.0","method":"subscription","params":{"channel":"book.ETH-PERPETUAL.raw","data":{"timestamp":1734114570477,"type":"change","change_id":15557283712,"instrument_name":"ETH-PERPETUAL","bids":[["delete",3881.6,0.0]],"asks":[["delete",3896.65,0.0]],"prev_change_id":15557283711}}}
{"jsonrpc":"2.0","method":"subscription","params":{"channel":"book.ETH-PERPETUAL.raw","data":{"timestamp":1734114570477,"type":"change","change_id":15557283712,"instrument_name":"ETH-PERPETUAL","bids":[["delete",3881.6,0.0]],"asks":[["delete",3896.65,0.0]],"prev_change_id":15557283711}}}
{"jsonrpc":"2.0","method":"subscription","params":{"channel":"book.ETH-PERPETUAL.raw","data":{"timestamp":1734114570675,"type":"change","change_id":15557283714,"instrument_name":"ETH-PERPETUAL","bids":[["new",3881.6,8.0e4]],"asks":[],"prev_change_id":15557283712}}}
{"jsonrpc":"2.0","method":"subscription","params":{"channel":"book.ETH-PERPETUAL.raw","data":{"timestamp":1734114570675,"type":"change","change_id":15557283714,"instrument_name":"ETH-PERPETUAL","bids":[["new",3881.6,8.0e4]],"asks":[],"prev_change_id":15557283712}}}
{"jsonrpc":"2.0","method":"subscription","params":{"channel":"book.ETH-PERPETUAL.raw","data":{"timestamp":1734114570677,"type":"change","change_id":15557283715,"instrument_name":"ETH-PERPETUAL","bids":[],"asks":[["new",3896.65,8.0e4]],"prev_change_id":15557283714}}}
{"jsonrpc":"2.0","method":"subscription","params":{"channel":"book.ETH-PERPETUAL.raw","data":{"timestamp":1734114570677,"type":"change","change_id":15557283715,"instrument_name":"ETH-PERPETUAL","bids":[],"asks":[["new",3896.65,8.0e4]],"prev_change_id":15557283714}}}
{"jsonrpc":"2.0","method":"subscription","params":{"channel":"book.ETH-PERPETUAL.raw","data":{"timestamp":1734114570678,"type":"change","change_id":15557283716,"instrument_name":"ETH-PERPETUAL","bids":[],"asks":[["change",3896.65,1.0e5]],"prev_change_id":15557283715}}}
{"jsonrpc":"2.0","method":"subscription","params":{"channel":"book.ETH-PERPETUAL.raw","data":{"timestamp":1734114570678,"type":"change","change_id":15557283716,"instrument_name":"ETH-PERPETUAL","bids":[],"asks":[["change",3896.65,1.0e5]],"prev_change_id":15557283715}}}
{"jsonrpc":"2.0","method":"subscription","params":{"channel":"book.ETH-PERPETUAL.raw","data":{"timestamp":1734114570680,"type":"change","change_id":15557283717,"instrument_name":"ETH-PERPETUAL","bids":[["change",3881.6,1.6e5]],"asks":[],"prev_change_id":15557283716}}}
{"jsonrpc":"2.0","method":"subscription","params":{"channel":"book.ETH-PERPETUAL.raw","data":{"timestamp":1734114570680,"type":"change","change_id":15557283717,"instrument_name":"ETH-PERPETUAL","bids":[["change",3881.6,1.6e5]],"asks":[],"prev_change_id":15557283716}}}
{"jsonrpc":"2.0","method":"subscription","params":{"channel":"book.ETH-PERPETUAL.raw","data":{"timestamp":1734114570681,"type":"change","change_id":15557283718,"instrument_name":"ETH-PERPETUAL","bids":[],"asks":[["change",3896.65,1.8e5]],"prev_change_id":15557283717}}}
{"jsonrpc":"2.0","method":"subscription","params":{"channel":"book.ETH-PERPETUAL.raw","data":{"timestamp":1734114570681,"type":"change","change_id":15557283718,"instrument_name":"ETH-PERPETUAL","bids":[],"asks":[["change",3896.65,1.8e5]],"prev_change_id":15557283717}}}
{"jsonrpc":"2.0","method":"subscription","params":{"channel":"book.ETH-PERPETUAL.raw","data":{"timestamp":1734114570682,"type":"change","change_id":15557283719,"instrument_name":"ETH-PERPETUAL","bids":[],"asks":[["change",3896.65,2.0e5]],"prev_change_id":15557283718}}}
{"jsonrpc":"2.0","method":"subscription","params":{"channel":"book.ETH-PERPETUAL.raw","data":{"timestamp":1734114570682,"type":"change","change_id":15557283719,"instrument_name":"ETH-PERPETUAL","bids":[],"asks":[["change",3896.65,2.0e5]],"prev_change_id":15557283718}}}
{"jsonrpc":"2.0","method":"subscription","params":{"channel":"book.ETH-PERPETUAL.raw","data":{"timestamp":1734114570820,"type":"change","change_id":15557283726,"instrument_name":"ETH-PERPETUAL","bids":[["delete",3881.6,0.0]],"asks":[["delete",3896.65,0.0]],"prev_change_id":15557283719}}}
{"jsonrpc":"2.0","method":"subscription","params":{"channel":"book.ETH-PERPETUAL.raw","data":{"timestamp":1734114570820,"type":"change","change_id":15557283726,"instrument_name":"ETH-PERPETUAL","bids":[["delete",3881.6,0.0]],"asks":[["delete",3896.65,0.0]],"prev_change_id":15557283719}}}
{"jsonrpc":"2.0","method":"subscription","params":{"channel":"book.ETH-PERPETUAL.raw","data":{"timestamp":1734114570992,"type":"change","change_id":15557283729,"instrument_name":"ETH-PERPETUAL","bids":[["new",3881.6,8.0e4]],"asks":[],"prev_change_id":15557283726}}}
{"jsonrpc":"2.0","method":"subscription","params":{"channel":"book.ETH-PERPETUAL.raw","data":{"timestamp":1734114570992,"type":"change","change_id":15557283729,"instrument_name":"ETH-PERPETUAL","bids":[["new",3881.6,8.0e4]],"asks":[],"prev_change_id":15557283726}}}
{"jsonrpc":"2.0","method":"subscription","params":{"channel":"book.ETH-PERPETUAL.raw","data":{"timestamp":1734114570993,"type":"change","change_id":15557283730,"instrument_name":"ETH-PERPETUAL","bids":[],"asks":[["new",3896.65,8.0e4]],"prev_change_id":15557283729}}}
{"jsonrpc":"2.0","method":"subscription","params":{"channel":"book.ETH-PERPETUAL.raw","data":{"timestamp":1734114570993,"type":"change","change_id":15557283730,"instrument_name":"ETH-PERPETUAL","bids":[],"asks":[["new",3896.65,8.0e4]],"prev_change_id":15557283729}}}
{"jsonrpc":"2.0","method":"subscription","params":{"channel":"book.ETH-PERPETUAL.raw","data":{"timestamp":1734114570995,"type":"change","change_id":15557283731,"instrument_name":"ETH-PERPETUAL","bids":[["change",3881.6,1.0e5]],"asks":[],"prev_change_id":15557283730}}}
{"jsonrpc":"2.0","method":"subscription","params":{"channel":"book.ETH-PERPETUAL.raw","data":{"timestamp":1734114570995,"type":"change","change_id":15557283731,"instrument_name":"ETH-PERPETUAL","bids":[["change",3881.6,1.0e5]],"asks":[],"prev_change_id":15557283730}}}
{"jsonrpc":"2.0","method":"subscription","params":{"channel":"book.ETH-PERPETUAL.raw","data":{"timestamp":1734114570997,"type":"change","change_id":15557283732,"instrument_name":"ETH-PERPETUAL","bids":[["change",3881.6,1.8e5]],"asks":[],"prev_change_id":15557283731}}}
{"jsonrpc":"2.0","method":"subscription","params":{"channel":"book.ETH-PERPETUAL.raw","data":{"timestamp":1734114570997,"type":"change","change_id":15557283732,"instrument_name":"ETH-PERPETUAL","bids":[["change",3881.6,1.8e5]],"asks":[],"prev_change_id":15557283731}}}
{"jsonrpc":"2.0","method":"subscription","params":{"channel":"book.ETH-PERPETUAL.raw","data":{"timestamp":1734114570998,"type":"change","change_id":15557283733,"instrument_name":"ETH-PERPETUAL","bids":[],"asks":[["change",3896.65,1.6e5]],"prev_change_id":15557283732}}}
{"jsonrpc":"2.0","method":"subscription","params":{"channel":"book.ETH-PERPETUAL.raw","data":{"timestamp":1734114570998,"type":"change","change_id":15557283733,"instrument_name":"ETH-PERPETUAL","bids":[],"asks":[["change",3896.65,1.6e5]],"prev_change_id":15557283732}}}
{"jsonrpc":"2.0","method":"subscription","params":{"channel":"book.ETH-PERPETUAL.raw","data":{"timestamp":1734114571000,"type":"change","change_id":15557283734,"instrument_name":"ETH-PERPETUAL","bids":[["change",3881.6,2.0e5]],"asks":[],"prev_change_id":15557283733}}}
{"jsonrpc":"2.0","method":"subscription","params":{"channel":"book.ETH-PERPETUAL.raw","data":{"timestamp":1734114571000,"type":"change","change_id":15557283734,"instrument_name":"ETH-PERPETUAL","bids":[["change",3881.6,2.0e5]],"asks":[],"prev_change_id":15557283733}}}
{"jsonrpc":"2.0","method":"subscription","params":{"channel":"book.ETH-PERPETUAL.raw","data":{"timestamp":1734114571116,"type":"change","change_id":15557283735,"instrument_name":"ETH-PERPETUAL","bids":[["delete",3881.6,0.0]],"asks":[["delete",3896.65,0.0]],"prev_change_id":15557283734}}}
{"jsonrpc":"2.0","method":"subscription","params":{"channel":"book.ETH-PERPETUAL.raw","data":{"timestamp":1734114571116,"type":"change","change_id":15557283735,"instrument_name":"ETH-PERPETUAL","bids":[["delete",3881.6,0.0]],"asks":[["delete",3896.65,0.0]],"prev_change_id":15557283734}}}
{"jsonrpc":"2.0","method":"subscription","params":{"channel":"book.ETH-PERPETUAL.raw","data":{"timestamp":1734114571142,"type":"change","change_id":15557283736,"instrument_name":"ETH-PERPETUAL","bids":[],"asks":[["new",3935.65,700.0],["delete",3947.75,0.0]],"prev_change_id":15557283735}}}
{"jsonrpc":"2.0","method":"subscription","params":{"channel":"book.ETH-PERPETUAL.raw","data":{"timestamp":1734114571142,"type":"change","change_id":15557283736,"instrument_name":"ETH-PERPETUAL","bids":[],"asks":[["new",3935.65,700.0],["delete",3947.75,0.0]],"prev_change_id":15557283735}}}
{"jsonrpc":"2.0","method":"subscription","params":{"channel":"book.ETH-PERPETUAL.raw","data":{"timestamp":1734114571305,"type":"change","change_id":15557283740,"instrument_name":"ETH-PERPETUAL","bids":[],"asks":[["new",3896.75,8.0e4]],"prev_change_id":15557283736}}}
{"jsonrpc":"2.0","method":"subscription","params":{"channel":"book.ETH-PERPETUAL.raw","data":{"timestamp":1734114571305,"type":"change","change_id":15557283740,"instrument_name":"ETH-PERPETUAL","bids":[],"asks":[["new",3896.75,8.0e4]],"prev_change_id":15557283736}}}
{"jsonrpc":"2.0","method":"subscription","params":{"channel":"book.ETH-PERPETUAL.raw","data":{"timestamp":1734114571306,"type":"change","change_id":15557283741,"instrument_name":"ETH-PERPETUAL","bids":[["new",3881.65,8.0e4]],"asks":[],"prev_change_id":15557283740}}}
{"jsonrpc":"2.0","method":"subscription","params":{"channel":"book.ETH-PERPETUAL.raw","data":{"timestamp":1734114571306,"type":"change","change_id":15557283741,"instrument_name":"ETH-PERPETUAL","bids":[["new",3881.65,8.0e4]],"asks":[],"prev_change_id":15557283740}}}
{"jsonrpc":"2.0","method":"subscription","params":{"channel":"book.ETH-PERPETUAL.raw","data":{"timestamp":1734114571308,"type":"change","change_id":15557283742,"instrument_name":"ETH-PERPETUAL","bids":[],"asks":[["change",3896.75,1.6e5]],"prev_change_id":15557283741}}}
{"jsonrpc":"2.0","method":"subscription","params":{"channel":"book.ETH-PERPETUAL.raw","data":{"timestamp":1734114571308,"type":"change","change_id":15557283742,"instrument_name":"ETH-PERPETUAL","bids":[],"asks":[["change",3896.75,1.6e5]],"prev_change_id":15557283741}}}
{"jsonrpc":"2.0","method":"subscription","params":{"channel":"book.ETH-PERPETUAL.raw","data":{"timestamp":1734114571309,"type":"change","change_id":15557283743,"instrument_name":"ETH-PERPETUAL","bids":[["change",3881.65,1.6e5]],"asks":[],"prev_change_id":15557283742}}}
{"jsonrpc":"2.0","method":"subscription","params":{"channel":"book.ETH-PERPETUAL.raw","data":{"timestamp":1734114571309,"type":"change","change_id":15557283743,"instrument_name":"ETH-PERPETUAL","bids":[["change",3881.65,1.6e5]],"asks":[],"prev_change_id":15557283742}}}
{"jsonrpc":"2.0","method":"subscription","params":{"channel":"book.ETH-PERPETUAL.raw","data":{"timestamp":1734114571443,"type":"change","change_id":15557283744,"instrument_name":"ETH-PERPETUAL","bids":[["delete",3881.65,0.0]],"asks":[["delete",3896.75,0.0]],"prev_change_id":15557283743}}}
{"jsonrpc":"2.0","method":"subscription","params":{"channel":"book.ETH-PERPETUAL.raw","data":{"timestamp":1734114571443,"type":"change","change_id":15557283744,"instrument_name":"ETH-PERPETUAL","bids":[["delete",3881.65,0.0]],"asks":[["delete",3896.75,0.0]],"prev_change_id":15557283743}}}
{"jsonrpc":"2.0","method":"subscription","params":{"channel":"book.ETH-PERPETUAL.raw","data":{"timestamp":1734114571638,"type":"change","change_id":15557283750,"instrument_name":"ETH-PERPETUAL","bids":[["new",3881.6,8.0e4]],"asks":[],"prev_change_id":15557283744}}}
{"jsonrpc":"2.0","method":"subscription","params":{"channel":"book.ETH-PERPETUAL.raw","data":{"timestamp":1734114571638,"type":"change","change_id":15557283750,"instrument_name":"ETH-PERPETUAL","bids":[["new",3881.6,8.0e4]],"asks":[],"prev_change_id":15557283744}}}
{"jsonrpc":"2.0","method":"subscription","params":{"channel":"book.ETH-PERPETUAL.raw","data":{"timestamp":1734114571640,"type":"change","change_id":15557283751,"instrument_name":"ETH-PERPETUAL","bids":[],"asks":[["new",3896.65,8.0e4]],"prev_change_id":15557283750}}}
{"jsonrpc":"2.0","method":"subscription","params":{"channel":"book.ETH-PERPETUAL.raw","data":{"timestamp":1734114571640,"type":"change","change_id":15557283751,"instrument_name":"ETH-PERPETUAL","bids":[],"asks":[["new",3896.65,8.0e4]],"prev_change_id":15557283750}}}
{"jsonrpc":"2.0","method":"subscription","params":{"channel":"book.ETH-PERPETUAL.raw","data":{"timestamp":1734114571641,"type":"change","change_id":15557283752,"instrument_name":"ETH-PERPETUAL","bids":[],"asks":[["change",3896.65,1.0e5]],"prev_change_id":15557283751}}}
{"jsonrpc":"2.0","method":"subscription","params":{"channel":"book.ETH-PERPETUAL.raw","data":{"timestamp":1734114571641,"type":"change","change_id":15557283752,"instrument_name":"ETH-PERPETUAL","bids":[],"asks":[["change",3896.65,1.0e5]],"prev_change_id":15557283751}}}
{"jsonrpc":"2.0","method":"subscription","params":{"channel":"book.ETH-PERPETUAL.raw","data":{"timestamp":1734114571643,"type":"change","change_id":15557283753,"instrument_name":"ETH-PERPETUAL","bids":[["change",3881.6,1.0e5]],"asks":[],"prev_change_id":15557283752}}}
{"jsonrpc":"2.0","method":"subscription","params":{"channel":"book.ETH-PERPETUAL.raw","data":{"timestamp":1734114571643,"type":"change","change_id":15557283753,"instrument_name":"ETH-PERPETUAL","bids":[["change",3881.6,1.0e5]],"asks":[],"prev_change_id":15557283752}}}
{"jsonrpc":"2.0","method":"subscription","params":{"channel":"book.ETH-PERPETUAL.raw","data":{"timestamp":1734114571644,"type":"change","change_id":15557283754,"instrument_name":"ETH-PERPETUAL","bids":[["change",3881.6,1.8e5]],"asks":[],"prev_change_id":15557283753}}}
{"jsonrpc":"2.0","method":"subscription","params":{"channel":"book.ETH-PERPETUAL.raw","data":{"timestamp":1734114571644,"type":"change","change_id":15557283754,"instrument_name":"ETH-PERPETUAL","bids":[["change",3881.6,1.8e5]],"asks":[],"prev_change_id":15557283753}}}
{"jsonrpc":"2.0","method":"subscription","params":{"channel":"book.ETH-PERPETUAL.raw","data":{"timestamp":1734114571646,"type":"change","change_id":15557283755,"instrument_name":"ETH-PERPETUAL","bids":[],"asks":[["change",3896.65,1.8e5]],"prev_change_id":15557283754}}}
{"jsonrpc":"2.0","method":"subscription","params":{"channel":"book.ETH-PERPETUAL.raw","data":{"timestamp":1734114571646,"type":"change","change_id":15557283755,"instrument_name":"ETH-PERPETUAL","bids":[],"asks":[["change",3896.65,1.8e5]],"prev_change_id":15557283754}}}
{"jsonrpc":"2.0","method":"subscription","params":{"channel":"book.ETH-PERPETUAL.raw","data":{"timestamp":1734114571648,"type":"change","change_id":15557283756,"instrument_name":"ETH-PERPETUAL","bids":[],"asks":[["change",3896.65,2.0e5]],"prev_change_id":15557283755}}}
{"jsonrpc":"2.0","method":"subscription","params":{"channel":"book.ETH-PERPETUAL.raw","data":{"timestamp":1734114571648,"type":"change","change_id":15557283756,"instrument_name":"ETH-PERPETUAL","bids":[],"asks":[["change",3896.65,2.0e5]],"prev_change_id":15557283755}}}
{"jsonrpc":"2.0","method":"subscription","params":{"channel":"book.ETH-PERPETUAL.raw","data":{"timestamp":1734114571649,"type":"change","change_id":15557283757,"instrument_name":"ETH-PERPETUAL","bids":[["change",3881.6,2.0e5]],"asks":[],"prev_change_id":15557283756}}}
{"jsonrpc":"2.0","method":"subscription","params":{"channel":"book.ETH-PERPETUAL.raw","data":{"timestamp":1734114571649,"type":"change","change_id":15557283757,"instrument_name":"ETH-PERPETUAL","bids":[["change",3881.6,2.0e5]],"asks":[],"prev_change_id":15557283756}}}
{"jsonrpc":"2.0","method":"subscription","params":{"channel":"book.ETH-PERPETUAL.raw","data":{"timestamp":1734114571795,"type":"change","change_id":15557283760,"instrument_name":"ETH-PERPETUAL","bids":[["delete",3881.6,0.0]],"asks":[["delete",3896.65,0.0]],"prev_change_id":15557283757}}}
{"jsonrpc":"2.0","method":"subscription","params":{"channel":"book.ETH-PERPETUAL.raw","data":{"timestamp":1734114571795,"type":"change","change_id":15557283760,"instrument_name":"ETH-PERPETUAL","bids":[["delete",3881.6,0.0]],"asks":[["delete",3896.65,0.0]],"prev_change_id":15557283757}}}
{"jsonrpc":"2.0","method":"subscription","params":{"channel":"book.ETH-PERPETUAL.raw","data":{"timestamp":1734114572028,"type":"change","change_id":15557283797,"instrument_name":"ETH-PERPETUAL","bids":[["new",3881.55,8.0e4]],"asks":[],"prev_change_id":15557283760}}}
{"jsonrpc":"2.0","method":"subscription","params":{"channel":"book.ETH-PERPETUAL.raw","data":{"timestamp":1734114572028,"type":"change","change_id":15557283797,"instrument_name":"ETH-PERPETUAL","bids":[["new",3881.55,8.0e4]],"asks":[],"prev_change_id":15557283760}}}
{"jsonrpc":"2.0","method":"subscription","params":{"channel":"book.ETH-PERPETUAL.raw","data":{"timestamp":1734114572030,"type":"change","change_id":15557283798,"instrument_name":"ETH-PERPETUAL","bids":[],"asks":[["new",3896.6,8.0e4]],"prev_change_id":15557283797}}}
{"jsonrpc":"2.0","method":"subscription","params":{"channel":"book.ETH-PERPETUAL.raw","data":{"timestamp":1734114572030,"type":"change","change_id":15557283798,"instrument_name":"ETH-PERPETUAL","bids":[],"asks":[["new",3896.6,8.0e4]],"prev_change_id":15557283797}}}
{"jsonrpc":"2.0","method":"subscription","params":{"channel":"book.ETH-PERPETUAL.raw","data":{"timestamp":1734114572032,"type":"change","change_id":15557283799,"instrument_name":"ETH-PERPETUAL","bids":[["change",3881.55,1.0e5]],"asks":[],"prev_change_id":15557283798}}}
{"jsonrpc":"2.0","method":"subscription","params":{"channel":"book.ETH-PERPETUAL.raw","data":{"timestamp":1734114572032,"type":"change","change_id":15557283799,"instrument_name":"ETH-PERPETUAL","bids":[["change",3881.55,1.0e5]],"asks":[],"prev_change_id":15557283798}}}
{"jsonrpc":"2.0","method":"subscription","params":{"channel":"book.ETH-PERPETUAL.raw","data":{"timestamp":1734114572033,"type":"change","change_id":15557283800,"instrument_name":"ETH-PERPETUAL","bids":[["change",3881.55,1.8e5]],"asks":[],"prev_change_id":15557283799}}}
{"jsonrpc":"2.0","method":"subscription","params":{"channel":"book.ETH-PERPETUAL.raw","data":{"timestamp":1734114572033,"type":"change","change_id":15557283800,"instrument_name":"ETH-PERPETUAL","bids":[["change",3881.55,1.8e5]],"asks":[],"prev_change_id":15557283799}}}
{"jsonrpc":"2.0","method":"subscription","params":{"channel":"book.ETH-PERPETUAL.raw","data":{"timestamp":1734114572036,"type":"change","change_id":15557283801,"instrument_name":"ETH-PERPETUAL","bids":[],"asks":[["change",3896.6,1.6e5]],"prev_change_id":15557283800}}}
{"jsonrpc":"2.0","method":"subscription","params":{"channel":"book.ETH-PERPETUAL.raw","data":{"timestamp":1734114572036,"type":"change","change_id":15557283801,"instrument_name":"ETH-PERPETUAL","bids":[],"asks":[["change",3896.6,1.6e5]],"prev_change_id":15557283800}}}
{"jsonrpc":"2.0","method":"subscription","params":{"channel":"book.ETH-PERPETUAL.raw","data":{"timestamp":1734114572038,"type":"change","change_id":15557283802,"instrument_name":"ETH-PERPETUAL","bids":[["change",3881.55,2.0e5]],"asks":[],"prev_change_id":15557283801}}}
{"jsonrpc":"2.0","method":"subscription","params":{"channel":"book.ETH-PERPETUAL.raw","data":{"timestamp":1734114572038,"type":"change","change_id":15557283802,"instrument_name":"ETH-PERPETUAL","bids":[["change",3881.55,2.0e5]],"asks":[],"prev_change_id":15557283801}}}
{"jsonrpc":"2.0","method":"subscription","params":{"channel":"book.ETH-PERPETUAL.raw","data":{"timestamp":1734114572122,"type":"change","change_id":15557283803,"instrument_name":"ETH-PERPETUAL","bids":[["delete",3881.55,0.0]],"asks":[["delete",3896.6,0.0]],"prev_change_id":15557283802}}}
{"jsonrpc":"2.0","method":"subscription","params":{"channel":"book.ETH-PERPETUAL.raw","data":{"timestamp":1734114572122,"type":"change","change_id":15557283803,"instrument_name":"ETH-PERPETUAL","bids":[["delete",3881.55,0.0]],"asks":[["delete",3896.6,0.0]],"prev_change_id":15557283802}}}
{"jsonrpc":"2.0","method":"subscription","params":{"channel":"book.ETH-PERPETUAL.raw","data":{"timestamp":1734114572320,"type":"change","change_id":15557283806,"instrument_name":"ETH-PERPETUAL","bids":[["new",3881.4,8.0e4]],"asks":[],"prev_change_id":15557283803}}}
{"jsonrpc":"2.0","method":"subscription","params":{"channel":"book.ETH-PERPETUAL.raw","data":{"timestamp":1734114572320,"type":"change","change_id":15557283806,"instrument_name":"ETH-PERPETUAL","bids":[["new",3881.4,8.0e4]],"asks":[],"prev_change_id":15557283803}}}
{"jsonrpc":"2.0","method":"subscription","params":{"channel":"book.ETH-PERPETUAL.raw","data":{"timestamp":1734114572322,"type":"change","change_id":15557283807,"instrument_name":"ETH-PERPETUAL","bids":[],"asks":[["new",3896.45,8.0e4]],"prev_change_id":15557283806}}}
{"jsonrpc":"2.0","method":"subscription","params":{"channel":"book.ETH-PERPETUAL.raw","data":{"timestamp":1734114572322,"type":"change","change_id":15557283807,"instrument_name":"ETH-PERPETUAL","bids":[],"asks":[["new",3896.45,8.0e4]],"prev_change_id":15557283806}}}
{"jsonrpc":"2.0","method":"subscription","params":{"channel":"book.ETH-PERPETUAL.raw","data":{"timestamp":1734114572323,"type":"change","change_id":15557283808,"instrument_name":"ETH-PERPETUAL","bids":[["change",3881.4,1.0e5]],"asks":[],"prev_change_id":15557283807}}}
{"jsonrpc":"2.0","method":"subscription","params":{"channel":"book.ETH-PERPETUAL.raw","data":{"timestamp":1734114572323,"type":"change","change_id":15557283808,"instrument_name":"ETH-PERPETUAL","bids":[["change",3881.4,1.0e5]],"asks":[],"prev_change_id":15557283807}}}
{"jsonrpc":"2.0","method":"subscription","params":{"channel":"book.ETH-PERPETUAL.raw","data":{"timestamp":1734114572325,"type":"change","change_id":15557283809,"instrument_name":"ETH-PERPETUAL","bids":[["change",3881.4,1.8e5]],"asks":[],"prev_change_id":15557283808}}}
{"jsonrpc":"2.0","method":"subscription","params":{"channel":"book.ETH-PERPETUAL.raw","data":{"timestamp":1734114572325,"type":"change","change_id":15557283809,"instrument_name":"ETH-PERPETUAL","bids":[["change",3881.4,1.8e5]],"asks":[],"prev_change_id":15557283808}}}
{"jsonrpc":"2.0","method":"subscription","params":{"channel":"book.ETH-PERPETUAL.raw","data":{"timestamp":1734114572326,"type":"change","change_id":15557283810,"instrument_name":"ETH-PERPETUAL","bids":[],"asks":[["change",3896.45,1.6e5]],"prev_change_id":15557283809}}}
{"jsonrpc":"2.0","method":"subscription","params":{"channel":"book.ETH-PERPETUAL.raw","data":{"timestamp":1734114572326,"type":"change","change_id":15557283810,"instrument_name":"ETH-PERPETUAL","bids":[],"asks":[["change",3896.45,1.6e5]],"prev_change_id":15557283809}}}
{"jsonrpc":"2.0","method":"subscription","params":{"channel":"book.ETH-PERPETUAL.raw","data":{"timestamp":1734114572328,"type":"change","change_id":15557283811,"instrument_name":"ETH-PERPETUAL","bids":[["change",3881.4,2.0e5]],"asks":[],"prev_change_id":15557283810}}}
{"jsonrpc":"2.0","method":"subscription","params":{"channel":"book.ETH-PERPETUAL.raw","data":{"timestamp":1734114572328,"type":"change","change_id":15557283811,"instrument_name":"ETH-PERPETUAL","bids":[["change",3881.4,2.0e5]],"asks":[],"prev_change_id":15557283810}}}
{"jsonrpc":"2.0","method":"subscription","params":{"channel":"book.ETH-PERPETUAL.raw","data":{"timestamp":1734114572426,"type":"change","change_id":15557283814,"instrument_name":"ETH-PERPETUAL","bids":[["delete",3881.4,0.0]],"asks":[["delete",3896.45,0.0]],"prev_change_id":15557283811}}}
{"jsonrpc":"2.0","method":"subscription","params":{"channel":"book.ETH-PERPETUAL.raw","data":{"timestamp":1734114572426,"type":"change","change_id":15557283814,"instrument_name":"ETH-PERPETUAL","bids":[["delete",3881.4,0.0]],"asks":[["delete",3896.45,0.0]],"prev_change_id":15557283811}}}
{"jsonrpc":"2.0","method":"subscription","params":{"channel":"book.ETH-PERPETUAL.raw","data":{"timestamp":1734114572655,"type":"change","change_id":15557283818,"instrument_name":"ETH-PERPETUAL","bids":[["new",3881.4,8.0e4]],"asks":[],"prev_change_id":15557283814}}}
{"jsonrpc":"2.0","method":"subscription","params":{"channel":"book.ETH-PERPETUAL.raw","data":{"timestamp":1734114572655,"type":"change","change_id":15557283818,"instrument_name":"ETH-PERPETUAL","bids":[["new",3881.4,8.0e4]],"asks":[],"prev_change_id":15557283814}}}
{"jsonrpc":"2.0","method":"subscription","params":{"channel":"book.ETH-PERPETUAL.raw","data":{"timestamp":1734114572658,"type":"change","change_id":15557283819,"instrument_name":"ETH-PERPETUAL","bids":[],"asks":[["new",3896.45,8.0e4]],"prev_change_id":15557283818}}}
{"jsonrpc":"2.0","method":"subscription","params":{"channel":"book.ETH-PERPETUAL.raw","data":{"timestamp":1734114572658,"type":"change","change_id":15557283819,"instrument_name":"ETH-PERPETUAL","bids":[],"asks":[["new",3896.45,8.0e4]],"prev_change_id":15557283818}}}
{"jsonrpc":"2.0","method":"subscription","params":{"channel":"book.ETH-PERPETUAL.raw","data":{"timestamp":1734114572660,"type":"change","change_id":15557283820,"instrument_name":"ETH-PERPETUAL","bids":[["change",3881.4,1.0e5]],"asks":[],"prev_change_id":15557283819}}}
{"jsonrpc":"2.0","method":"subscription","params":{"channel":"book.ETH-PERPETUAL.raw","data":{"timestamp":1734114572660,"type":"change","change_id":15557283820,"instrument_name":"ETH-PERPETUAL","bids":[["change",3881.4,1.0e5]],"asks":[],"prev_change_id":15557283819}}}
{"jsonrpc":"2.0","method":"subscription","params":{"channel":"book.ETH-PERPETUAL.raw","data":{"timestamp":1734114572663,"type":"change","change_id":15557283821,"instrument_name":"ETH-PERPETUAL","bids":[],"asks":[["change",3896.45,1.0e5]],"prev_change_id":15557283820}}}
{"jsonrpc":"2.0","method":"subscription","params":{"channel":"book.ETH-PERPETUAL.raw","data":{"timestamp":1734114572663,"type":"change","change_id":15557283821,"instrument_name":"ETH-PERPETUAL","bids":[],"asks":[["change",3896.45,1.0e5]],"prev_change_id":15557283820}}}
{"jsonrpc":"2.0","method":"subscription","params":{"channel":"book.ETH-PERPETUAL.raw","data":{"timestamp":1734114572665,"type":"change","change_id":15557283822,"instrument_name":"ETH-PERPETUAL","bids":[["change",3881.4,1.8e5]],"asks":[],"prev_change_id":15557283821}}}
{"jsonrpc":"2.0","method":"subscription","params":{"channel":"book.ETH-PERPETUAL.raw","data":{"timestamp":1734114572665,"type":"change","change_id":15557283822,"instrument_name":"ETH-PERPETUAL","bids":[["change",3881.4,1.8e5]],"asks":[],"prev_change_id":15557283821}}}
{"jsonrpc":"2.0","method":"subscription","params":{"channel":"book.ETH-PERPETUAL.raw","data":{"timestamp":1734114572668,"type":"change","change_id":15557283823,"instrument_name":"ETH-PERPETUAL","bids":[],"asks":[["change",3896.45,1.8e5]],"prev_change_id":15557283822}}}
{"jsonrpc":"2.0","method":"subscription","params":{"channel":"book.ETH-PERPETUAL.raw","data":{"timestamp":1734114572668,"type":"change","change_id":15557283823,"instrument_name":"ETH-PERPETUAL","bids":[],"asks":[["change",3896.45,1.8e5]],"prev_change_id":15557283822}}}
{"jsonrpc":"2.0","method":"subscription","params":{"channel":"book.ETH-PERPETUAL.raw","data":{"timestamp":1734114572670,"type":"change","change_id":15557283824,"instrument_name":"ETH-PERPETUAL","bids":[["change",3881.4,2.0e5]],"asks":[],"prev_change_id":15557283823}}}
{"jsonrpc":"2.0","method":"subscription","params":{"channel":"book.ETH-PERPETUAL.raw","data":{"timestamp":1734114572670,"type":"change","change_id":15557283824,"instrument_name":"ETH-PERPETUAL","bids":[["change",3881.4,2.0e5]],"asks":[],"prev_change_id":15557283823}}}
