{"jsonrpc":"2.0","method":"subscription","params":{"channel":"book.ETH-PERPETUAL.raw","data":{"timestamp":1734114572673,"type":"change","change_id":15557283825,"instrument_name":"ETH-PERPETUAL","bids":[],"asks":[["change",3896.45,2.0e5]],"prev_change_id":15557283824}}}
{"jsonrpc":"2.0","method":"subscription","params":{"channel":"book.ETH-PERPETUAL.raw","data":{"timestamp":1734114572673,"type":"change","change_id":15557283825,"instrument_name":"ETH-PERPETUAL","bids":[],"asks":[["change",3896.45,2.0e5]],"prev_change_id":15557283824}}}
{"jsonrpc":"2.0","method":"subscription","params":{"channel":"book.ETH-PERPETUAL.raw","data":{"timestamp":1734114572811,"type":"change","change_id":15557283833,"instrument_name":"ETH-PERPETUAL","bids":[],"asks":[["new",3908.15,500.0],["delete",3919.85,0.0]],"prev_change_id":15557283825}}}
{"jsonrpc":"2.0","method":"subscription","params":{"channel":"book.ETH-PERPETUAL.raw","data":{"timestamp":1734114572811,"type":"change","change_id":15557283833,"instrument_name":"ETH-PERPETUAL","bids":[],"asks":[["new",3908.15,500.0],["delete",3919.85,0.0]],"prev_change_id":15557283825}}}
{"jsonrpc":"2.0","method":"subscription","params":{"channel":"book.ETH-PERPETUAL.raw","data":{"timestamp":1734114572811,"type":"change","change_id":15557283834,"instrument_name":"ETH-PERPETUAL","bids":[["delete",3881.4,0.0]],"asks":[["delete",3896.45,0.0]],"prev_change_id":15557283833}}}
{"jsonrpc":"2.0","method":"subscription","params":{"channel":"book.ETH-PERPETUAL.raw","data":{"timestamp":1734114572811,"type":"change","change_id":15557283834,"instrument_name":"ETH-PERPETUAL","bids":[["delete",3881.4,0.0]],"asks":[["delete",3896.45,0.0]],"prev_change_id":15557283833}}}
{"jsonrpc":"2.0","method":"subscription","params":{"channel":"book.ETH-PERPETUAL.raw","data":{"timestamp":1734114573043,"type":"change","change_id":15557283840,"instrument_name":"ETH-PERPETUAL","bids":[["new",3881.45,8.0e4]],"asks":[],"prev_change_id":15557283834}}}
{"jsonrpc":"2.0","method":"subscription","params":{"channel":"book.ETH-PERPETUAL.raw","data":{"timestamp":1734114573043,"type":"change","change_id":15557283840,"instrument_name":"ETH-PERPETUAL","bids":[["new",3881.45,8.0e4]],"asks":[],"prev_change_id":15557283834}}}
{"jsonrpc":"2.0","method":"subscription","params":{"channel":"book.ETH-PERPETUAL.raw","data":{"timestamp":1734114573045,"type":"change","change_id":15557283841,"instrument_name":"ETH-PERPETUAL","bids":[],"asks":[["new",3896.5,8.0e4]],"prev_change_id":15557283840}}}
{"jsonrpc":"2.0","method":"subscription","params":{"channel":"book.ETH-PERPETUAL.raw","data":{"timestamp":1734114573045,"type":"change","change_id":15557283841,"instrument_name":"ETH-PERPETUAL","bids":[],"asks":[["new",3896.5,8.0e4]],"prev_change_id":15557283840}}}
{"jsonrpc":"2.0","method":"subscription","params":{"channel":"book.ETH-PERPETUAL.raw","data":{"timestamp":1734114573046,"type":"change","change_id":15557283842,"instrument_name":"ETH-PERPETUAL","bids":[["change",3881.45,1.0e5]],"asks":[],"prev_change_id":15557283841}}}
{"jsonrpc":"2.0","method":"subscription","params":{"channel":"book.ETH-PERPETUAL.raw","data":{"timestamp":1734114573046,"type":"change","change_id":15557283842,"instrument_name":"ETH-PERPETUAL","bids":[["change",3881.45,1.0e5]],"asks":[],"prev_change_id":15557283841}}}
{"jsonrpc":"2.0","method":"subscription","params":{"channel":"book.ETH-PERPETUAL.raw","data":{"timestamp":1734114573049,"type":"change","change_id":15557283843,"instrument_name":"ETH-PERPETUAL","bids":[],"asks":[["change",3896.5,1.0e5]],"prev_change_id":15557283842}}}
{"jsonrpc":"2.0","method":"subscription","params":{"channel":"book.ETH-PERPETUAL.raw","data":{"timestamp":1734114573049,"type":"change","change_id":15557283843,"instrument_name":"ETH-PERPETUAL","bids":[],"asks":[["change",3896.5,1.0e5]],"prev_change_id":15557283842}}}
{"jsonrpc":"2.0","method":"subscription","params":{"channel":"book.ETH-PERPETUAL.raw","data":{"timestamp":1734114573050,"type":"change","change_id":15557283844,"instrument_name":"ETH-PERPETUAL","bids":[["change",3881.45,1.8e5]],"asks":[],"prev_change_id":15557283843}}}
{"jsonrpc":"2.0","method":"subscription","params":{"channel":"book.ETH-PERPETUAL.raw","data":{"timestamp":1734114573050,"type":"change","change_id":15557283844,"instrument_name":"ETH-PERPETUAL","bids":[["change",3881.45,1.8e5]],"asks":[],"prev_change_id":15557283843}}}
{"jsonrpc":"2.0","method":"subscription","params":{"channel":"book.ETH-PERPETUAL.raw","data":{"timestamp":1734114573053,"type":"change","change_id":15557283845,"instrument_name":"ETH-PERPETUAL","bids":[],"asks":[["change",3896.5,1.8e5]],"prev_change_id":15557283844}}}
{"jsonrpc":"2.0","method":"subscription","params":{"channel":"book.ETH-PERPETUAL.raw","data":{"timestamp":1734114573053,"type":"change","change_id":15557283845,"instrument_name":"ETH-PERPETUAL","bids":[],"asks":[["change",3896.5,1.8e5]],"prev_change_id":15557283844}}}
{"jsonrpc":"2.0","method":"subscription","params":{"channel":"book.ETH-PERPETUAL.raw","data":{"timestamp":1734114573054,"type":"change","change_id":15557283846,"instrument_name":"ETH-PERPETUAL","bids":[["change",3881.45,2.0e5]],"asks":[],"prev_change_id":15557283845}}}
{"jsonrpc":"2.0","method":"subscription","params":{"channel":"book.ETH-PERPETUAL.raw","data":{"timestamp":1734114573054,"type":"change","change_id":15557283846,"instrument_name":"ETH-PERPETUAL","bids":[["change",3881.45,2.0e5]],"asks":[],"prev_change_id":15557283845}}}
{"jsonrpc":"2.0","method":"subscription","params":{"channel":"book.ETH-PERPETUAL.raw","data":{"timestamp":1734114573056,"type":"change","change_id":15557283847,"instrument_name":"ETH-PERPETUAL","bids":[],"asks":[["change",3896.5,2.0e5]],"prev_change_id":15557283846}}}
{"jsonrpc":"2.0","method":"subscription","params":{"channel":"book.ETH-PERPETUAL.raw","data":{"timestamp":1734114573056,"type":"change","change_id":15557283847,"instrument_name":"ETH-PERPETUAL","bids":[],"asks":[["change",3896.5,2.0e5]],"prev_change_id":15557283846}}}
{"jsonrpc":"2.0","method":"subscription","params":{"channel":"book.ETH-PERPETUAL.raw","data":{"timestamp":1734114573143,"type":"change","change_id":15557283848,"instrument_name":"ETH-PERPETUAL","bids":[["delete",3881.45,0.0]],"asks":[["delete",3896.5,0.0]],"prev_change_id":15557283847}}}
{"jsonrpc":"2.0","method":"subscription","params":{"channel":"book.ETH-PERPETUAL.raw","data":{"timestamp":1734114573143,"type":"change","change_id":15557283848,"instrument_name":"ETH-PERPETUAL","bids":[["delete",3881.45,0.0]],"asks":[["delete",3896.5,0.0]],"prev_change_id":15557283847}}}
{"jsonrpc":"2.0","method":"subscription","params":{"channel":"book.ETH-PERPETUAL.raw","data":{"timestamp":1734114573332,"type":"change","change_id":15557283849,"instrument_name":"ETH-PERPETUAL","bids":[],"asks":[["new",3896.55,8.0e4]],"prev_change_id":15557283848}}}
{"jsonrpc":"2.0","method":"subscription","params":{"channel":"book.ETH-PERPETUAL.raw","data":{"timestamp":1734114573332,"type":"change","change_id":15557283849,"instrument_name":"ETH-PERPETUAL","bids":[],"asks":[["new",3896.55,8.0e4]],"prev_change_id":15557283848}}}
{"jsonrpc":"2.0","method":"subscription","params":{"channel":"book.ETH-PERPETUAL.raw","data":{"timestamp":1734114573333,"type":"change","change_id":15557283850,"instrument_name":"ETH-PERPETUAL","bids":[["new",3881.5,8.0e4]],"asks":[],"prev_change_id":15557283849}}}
{"jsonrpc":"2.0","method":"subscription","params":{"channel":"book.ETH-PERPETUAL.raw","data":{"timestamp":1734114573333,"type":"change","change_id":15557283850,"instrument_name":"ETH-PERPETUAL","bids":[["new",3881.5,8.0e4]],"asks":[],"prev_change_id":15557283849}}}
{"jsonrpc":"2.0","method":"subscription","params":{"channel":"book.ETH-PERPETUAL.raw","data":{"timestamp":1734114573334,"type":"change","change_id":15557283851,"instrument_name":"ETH-PERPETUAL","bids":[["change",3881.5,1.0e5]],"asks":[],"prev_change_id":15557283850}}}
{"jsonrpc":"2.0","method":"subscription","params":{"channel":"book.ETH-PERPETUAL.raw","data":{"timestamp":1734114573334,"type":"change","change_id":15557283851,"instrument_name":"ETH-PERPETUAL","bids":[["change",3881.5,1.0e5]],"asks":[],"prev_change_id":15557283850}}}
{"jsonrpc":"2.0","method":"subscription","params":{"channel":"book.ETH-PERPETUAL.raw","data":{"timestamp":1734114573336,"type":"change","change_id":15557283852,"instrument_name":"ETH-PERPETUAL","bids":[],"asks":[["change",3896.55,1.6e5]],"prev_change_id":15557283851}}}
{"jsonrpc":"2.0","method":"subscription","params":{"channel":"book.ETH-PERPETUAL.raw","data":{"timestamp":1734114573336,"type":"change","change_id":15557283852,"instrument_name":"ETH-PERPETUAL","bids":[],"asks":[["change",3896.55,1.6e5]],"prev_change_id":15557283851}}}
{"jsonrpc":"2.0","method":"subscription","params":{"channel":"book.ETH-PERPETUAL.raw","data":{"timestamp":1734114573337,"type":"change","change_id":15557283853,"instrument_name":"ETH-PERPETUAL","bids":[["change",3881.5,1.8e5]],"asks":[],"prev_change_id":15557283852}}}
{"jsonrpc":"2.0","method":"subscription","params":{"channel":"book.ETH-PERPETUAL.raw","data":{"timestamp":1734114573337,"type":"change","change_id":15557283853,"instrument_name":"ETH-PERPETUAL","bids":[["change",3881.5,1.8e5]],"asks":[],"prev_change_id":15557283852}}}
{"jsonrpc":"2.0","method":"subscription","params":{"channel":"book.ETH-PERPETUAL.raw","data":{"timestamp":1734114573338,"type":"change","change_id":15557283854,"instrument_name":"ETH-PERPETUAL","bids":[["change",3881.5,2.0e5]],"asks":[],"prev_change_id":15557283853}}}
{"jsonrpc":"2.0","method":"subscription","params":{"channel":"book.ETH-PERPETUAL.raw","data":{"timestamp":1734114573338,"type":"change","change_id":15557283854,"instrument_name":"ETH-PERPETUAL","bids":[["change",3881.5,2.0e5]],"asks":[],"prev_change_id":15557283853}}}
{"jsonrpc":"2.0","method":"subscription","params":{"channel":"book.ETH-PERPETUAL.raw","data":{"timestamp":1734114573474,"type":"change","change_id":15557283856,"instrument_name":"ETH-PERPETUAL","bids":[["delete",3881.5,0.0]],"asks":[["delete",3896.55,0.0]],"prev_change_id":15557283854}}}
{"jsonrpc":"2.0","method":"subscription","params":{"channel":"book.ETH-PERPETUAL.raw","data":{"timestamp":1734114573474,"type":"change","change_id":15557283856,"instrument_name":"ETH-PERPETUAL","bids":[["delete",3881.5,0.0]],"asks":[["delete",3896.55,0.0]],"prev_change_id":15557283854}}}
{"jsonrpc":"2.0","method":"subscription","params":{"channel":"book.ETH-PERPETUAL.raw","data":{"timestamp":1734114573620,"type":"change","change_id":15557283873,"instrument_name":"ETH-PERPETUAL","bids":[],"asks":[["delete",3916.05,0.0],["new",3927.7,500.0]],"prev_change_id":15557283856}}}
{"jsonrpc":"2.0","method":"subscription","params":{"channel":"book.ETH-PERPETUAL.raw","data":{"timestamp":1734114573620,"type":"change","change_id":15557283873,"instrument_name":"ETH-PERPETUAL","bids":[],"asks":[["delete",3916.05,0.0],["new",3927.7,500.0]],"prev_change_id":15557283856}}}
{"jsonrpc":"2.0","method":"subscription","params":{"channel":"book.ETH-PERPETUAL.raw","data":{"timestamp":1734114573675,"type":"change","change_id":15557283874,"instrument_name":"ETH-PERPETUAL","bids":[["new",3881.5,8.0e4]],"asks":[],"prev_change_id":15557283873}}}
{"jsonrpc":"2.0","method":"subscription","params":{"channel":"book.ETH-PERPETUAL.raw","data":{"timestamp":1734114573675,"type":"change","change_id":15557283874,"instrument_name":"ETH-PERPETUAL","bids":[["new",3881.5,8.0e4]],"asks":[],"prev_change_id":15557283873}}}
{"jsonrpc":"2.0","method":"subscription","params":{"channel":"book.ETH-PERPETUAL.raw","data":{"timestamp":1734114573677,"type":"change","change_id":15557283875,"instrument_name":"ETH-PERPETUAL","bids":[],"asks":[["new",3896.55,8.0e4]],"prev_change_id":15557283874}}}
{"jsonrpc":"2.0","method":"subscription","params":{"channel":"book.ETH-PERPETUAL.raw","data":{"timestamp":1734114573677,"type":"change","change_id":15557283875,"instrument_name":"ETH-PERPETUAL","bids":[],"asks":[["new",3896.55,8.0e4]],"prev_change_id":15557283874}}}
{"jsonrpc":"2.0","method":"subscription","params":{"channel":"book.ETH-PERPETUAL.raw","data":{"timestamp":1734114573679,"type":"change","change_id":15557283876,"instrument_name":"ETH-PERPETUAL","bids":[["change",3881.5,1.0e5]],"asks":[],"prev_change_id":15557283875}}}
{"jsonrpc":"2.0","method":"subscription","params":{"channel":"book.ETH-PERPETUAL.raw","data":{"timestamp":1734114573679,"type":"change","change_id":15557283876,"instrument_name":"ETH-PERPETUAL","bids":[["change",3881.5,1.0e5]],"asks":[],"prev_change_id":15557283875}}}
{"jsonrpc":"2.0","method":"subscription","params":{"channel":"book.ETH-PERPETUAL.raw","data":{"timestamp":1734114573681,"type":"change","change_id":15557283877,"instrument_name":"ETH-PERPETUAL","bids":[["change",3881.5,1.8e5]],"asks":[],"prev_change_id":15557283876}}}
{"jsonrpc":"2.0","method":"subscription","params":{"channel":"book.ETH-PERPETUAL.raw","data":{"timestamp":1734114573681,"type":"change","change_id":15557283877,"instrument_name":"ETH-PERPETUAL","bids":[["change",3881.5,1.8e5]],"asks":[],"prev_change_id":15557283876}}}
{"jsonrpc":"2.0","method":"subscription","params":{"channel":"book.ETH-PERPETUAL.raw","data":{"timestamp":1734114573683,"type":"change","change_id":15557283878,"instrument_name":"ETH-PERPETUAL","bids":[],"asks":[["change",3896.55,1.6e5]],"prev_change_id":15557283877}}}
{"jsonrpc":"2.0","method":"subscription","params":{"channel":"book.ETH-PERPETUAL.raw","data":{"timestamp":1734114573683,"type":"change","change_id":15557283878,"instrument_name":"ETH-PERPETUAL","bids":[],"asks":[["change",3896.55,1.6e5]],"prev_change_id":15557283877}}}
{"jsonrpc":"2.0","method":"subscription","params":{"channel":"book.ETH-PERPETUAL.raw","data":{"timestamp":1734114573684,"type":"change","change_id":15557283879,"instrument_name":"ETH-PERPETUAL","bids":[["change",3881.5,2.0e5]],"asks":[],"prev_change_id":15557283878}}}
{"jsonrpc":"2.0","method":"subscription","params":{"channel":"book.ETH-PERPETUAL.raw","data":{"timestamp":1734114573684,"type":"change","change_id":15557283879,"instrument_name":"ETH-PERPETUAL","bids":[["change",3881.5,2.0e5]],"asks":[],"prev_change_id":15557283878}}}
{"jsonrpc":"2.0","method":"subscription","params":{"channel":"book.ETH-PERPETUAL.raw","data":{"timestamp":1734114573864,"type":"change","change_id":15557283880,"instrument_name":"ETH-PERPETUAL","bids":[["delete",3881.5,0.0]],"asks":[["delete",3896.55,0.0]],"prev_change_id":15557283879}}}
{"jsonrpc":"2.0","method":"subscription","params":{"channel":"book.ETH-PERPETUAL.raw","data":{"timestamp":1734114573864,"type":"change","change_id":15557283880,"instrument_name":"ETH-PERPETUAL","bids":[["delete",3881.5,0.0]],"asks":[["delete",3896.55,0.0]],"prev_change_id":15557283879}}}
{"jsonrpc":"2.0","method":"subscription","params":{"channel":"book.ETH-PERPETUAL.raw","data":{"timestamp":1734114574075,"type":"change","change_id":15557283905,"instrument_name":"ETH-PERPETUAL","bids":[["new",3881.5,8.0e4]],"asks":[],"prev_change_id":15557283880}}}
{"jsonrpc":"2.0","method":"subscription","params":{"channel":"book.ETH-PERPETUAL.raw","data":{"timestamp":1734114574075,"type":"change","change_id":15557283905,"instrument_name":"ETH-PERPETUAL","bids":[["new",3881.5,8.0e4]],"asks":[],"prev_change_id":15557283880}}}
{"jsonrpc":"2.0","method":"subscription","params":{"channel":"book.ETH-PERPETUAL.raw","data":{"timestamp":1734114574077,"type":"change","change_id":15557283906,"instrument_name":"ETH-PERPETUAL","bids":[],"asks":[["new",3896.55,8.0e4]],"prev_change_id":15557283905}}}
{"jsonrpc":"2.0","method":"subscription","params":{"channel":"book.ETH-PERPETUAL.raw","data":{"timestamp":1734114574077,"type":"change","change_id":15557283906,"instrument_name":"ETH-PERPETUAL","bids":[],"asks":[["new",3896.55,8.0e4]],"prev_change_id":15557283905}}}
{"jsonrpc":"2.0","method":"subscription","params":{"channel":"book.ETH-PERPETUAL.raw","data":{"timestamp":1734114574078,"type":"change","change_id":15557283907,"instrument_name":"ETH-PERPETUAL","bids":[["change",3881.5,1.0e5]],"asks":[],"prev_change_id":15557283906}}}
{"jsonrpc":"2.0","method":"subscription","params":{"channel":"book.ETH-PERPETUAL.raw","data":{"timestamp":1734114574078,"type":"change","change_id":15557283907,"instrument_name":"ETH-PERPETUAL","bids":[["change",3881.5,1.0e5]],"asks":[],"prev_change_id":15557283906}}}
{"jsonrpc":"2.0","method":"subscription","params":{"channel":"book.ETH-PERPETUAL.raw","data":{"timestamp":1734114574087,"type":"change","change_id":15557283908,"instrument_name":"ETH-PERPETUAL","bids":[],"asks":[["change",3896.55,1.0e5]],"prev_change_id":15557283907}}}
{"jsonrpc":"2.0","method":"subscription","params":{"channel":"book.ETH-PERPETUAL.raw","data":{"timestamp":1734114574087,"type":"change","change_id":15557283908,"instrument_name":"ETH-PERPETUAL","bids":[],"asks":[["change",3896.55,1.0e5]],"prev_change_id":15557283907}}}
{"jsonrpc":"2.0","method":"subscription","params":{"channel":"book.ETH-PERPETUAL.raw","data":{"timestamp":1734114574092,"type":"change","change_id":15557283909,"instrument_name":"ETH-PERPETUAL","bids":[["change",3881.5,1.8e5]],"asks":[],"prev_change_id":15557283908}}}
{"jsonrpc":"2.0","method":"subscription","params":{"channel":"book.ETH-PERPETUAL.raw","data":{"timestamp":1734114574092,"type":"change","change_id":15557283909,"instrument_name":"ETH-PERPETUAL","bids":[["change",3881.5,1.8e5]],"asks":[],"prev_change_id":15557283908}}}
{"jsonrpc":"2.0","method":"subscription","params":{"channel":"book.ETH-PERPETUAL.raw","data":{"timestamp":1734114574093,"type":"change","change_id":15557283910,"instrument_name":"ETH-PERPETUAL","bids":[],"asks":[["change",3896.55,1.8e5]],"prev_change_id":15557283909}}}
{"jsonrpc":"2.0","method":"subscription","params":{"channel":"book.ETH-PERPETUAL.raw","data":{"timestamp":1734114574093,"type":"change","change_id":15557283910,"instrument_name":"ETH-PERPETUAL","bids":[],"asks":[["change",3896.55,1.8e5]],"prev_change_id":15557283909}}}
{"jsonrpc":"2.0","method":"subscription","params":{"channel":"book.ETH-PERPETUAL.raw","data":{"timestamp":1734114574094,"type":"change","change_id":15557283911,"instrument_name":"ETH-PERPETUAL","bids":[["change",3881.5,2.0e5]],"asks":[],"prev_change_id":15557283910}}}
{"jsonrpc":"2.0","method":"subscription","params":{"channel":"book.ETH-PERPETUAL.raw","data":{"timestamp":1734114574094,"type":"change","change_id":15557283911,"instrument_name":"ETH-PERPETUAL","bids":[["change",3881.5,2.0e5]],"asks":[],"prev_change_id":15557283910}}}
{"jsonrpc":"2.0","method":"subscription","params":{"channel":"book.ETH-PERPETUAL.raw","data":{"timestamp":1734114574096,"type":"change","change_id":15557283912,"instrument_name":"ETH-PERPETUAL","bids":[],"asks":[["change",3896.55,2.0e5]],"prev_change_id":15557283911}}}
{"jsonrpc":"2.0","method":"subscription","params":{"channel":"book.ETH-PERPETUAL.raw","data":{"timestamp":1734114574096,"type":"change","change_id":15557283912,"instrument_name":"ETH-PERPETUAL","bids":[],"asks":[["change",3896.55,2.0e5]],"prev_change_id":15557283911}}}
{"jsonrpc":"2.0","method":"subscription","params":{"channel":"book.ETH-PERPETUAL.raw","data":{"timestamp":1734114574248,"type":"change","change_id":15557283914,"instrument_name":"ETH-PERPETUAL","bids":[["delete",3881.5,0.0]],"asks":[["delete",3896.55,0.0]],"prev_change_id":15557283912}}}
{"jsonrpc":"2.0","method":"subscription","params":{"channel":"book.ETH-PERPETUAL.raw","data":{"timestamp":1734114574248,"type":"change","change_id":15557283914,"instrument_name":"ETH-PERPETUAL","bids":[["delete",3881.5,0.0]],"asks":[["delete",3896.55,0.0]],"prev_change_id":15557283912}}}
{"jsonrpc":"2.0","method":"subscription","params":{"channel":"book.ETH-PERPETUAL.raw","data":{"timestamp":1734114574491,"type":"change","change_id":15557283915,"instrument_name":"ETH-PERPETUAL","bids":[["new",3881.4,8.0e4]],"asks":[],"prev_change_id":15557283914}}}
{"jsonrpc":"2.0","method":"subscription","params":{"channel":"book.ETH-PERPETUAL.raw","data":{"timestamp":1734114574491,"type":"change","change_id":15557283915,"instrument_name":"ETH-PERPETUAL","bids":[["new",3881.4,8.0e4]],"asks":[],"prev_change_id":15557283914}}}
{"jsonrpc":"2.0","method":"subscription","params":{"channel":"book.ETH-PERPETUAL.raw","data":{"timestamp":1734114574493,"type":"change","change_id":15557283916,"instrument_name":"ETH-PERPETUAL","bids":[],"asks":[["new",3896.45,8.0e4]],"prev_change_id":15557283915}}}
{"jsonrpc":"2.0","method":"subscription","params":{"channel":"book.ETH-PERPETUAL.raw","data":{"timestamp":1734114574493,"type":"change","change_id":15557283916,"instrument_name":"ETH-PERPETUAL","bids":[],"asks":[["new",3896.45,8.0e4]],"prev_change_id":15557283915}}}
{"jsonrpc":"2.0","method":"subscription","params":{"channel":"book.ETH-PERPETUAL.raw","data":{"timestamp":1734114574495,"type":"change","change_id":15557283917,"instrument_name":"ETH-PERPETUAL","bids":[["change",3881.4,1.0e5]],"asks":[],"prev_change_id":15557283916}}}
{"jsonrpc":"2.0","method":"subscription","params":{"channel":"book.ETH-PERPETUAL.raw","data":{"timestamp":1734114574495,"type":"change","change_id":15557283917,"instrument_name":"ETH-PERPETUAL","bids":[["change",3881.4,1.0e5]],"asks":[],"prev_change_id":15557283916}}}
{"jsonrpc":"2.0","method":"subscription","params":{"channel":"book.ETH-PERPETUAL.raw","data":{"timestamp":1734114574496,"type":"change","change_id":15557283918,"instrument_name":"ETH-PERPETUAL","bids":[],"asks":[["change",3896.45,1.0e5]],"prev_change_id":15557283917}}}
{"jsonrpc":"2.0","method":"subscription","params":{"channel":"book.ETH-PERPETUAL.raw","data":{"timestamp":1734114574496,"type":"change","change_id":15557283918,"instrument_name":"ETH-PERPETUAL","bids":[],"asks":[["change",3896.45,1.0e5]],"prev_change_id":15557283917}}}
{"jsonrpc":"2.0","method":"subscription","params":{"channel":"book.ETH-PERPETUAL.raw","data":{"timestamp":1734114574497,"type":"change","change_id":15557283919,"instrument_name":"ETH-PERPETUAL","bids":[["change",3881.4,1.8e5]],"asks":[],"prev_change_id":15557283918}}}
{"jsonrpc":"2.0","method":"subscription","params":{"channel":"book.ETH-PERPETUAL.raw","data":{"timestamp":1734114574497,"type":"change","change_id":15557283919,"instrument_name":"ETH-PERPETUAL","bids":[["change",3881.4,1.8e5]],"asks":[],"prev_change_id":15557283918}}}
{"jsonrpc":"2.0","method":"subscription","params":{"channel":"book.ETH-PERPETUAL.raw","data":{"timestamp":1734114574498,"type":"change","change_id":15557283920,"instrument_name":"ETH-PERPETUAL","bids":[],"asks":[["change",3896.45,1.8e5]],"prev_change_id":15557283919}}}
{"jsonrpc":"2.0","method":"subscription","params":{"channel":"book.ETH-PERPETUAL.raw","data":{"timestamp":1734114574498,"type":"change","change_id":15557283920,"instrument_name":"ETH-PERPETUAL","bids":[],"asks":[["change",3896.45,1.8e5]],"prev_change_id":15557283919}}}
{"jsonrpc":"2.0","method":"subscription","params":{"channel":"book.ETH-PERPETUAL.raw","data":{"timestamp":1734114574500,"type":"change","change_id":15557283921,"instrument_name":"ETH-PERPETUAL","bids":[["change",3881.4,2.0e5]],"asks":[],"prev_change_id":15557283920}}}
{"jsonrpc":"2.0","method":"subscription","params":{"channel":"book.ETH-PERPETUAL.raw","data":{"timestamp":1734114574500,"type":"change","change_id":15557283921,"instrument_name":"ETH-PERPETUAL","bids":[["change",3881.4,2.0e5]],"asks":[],"prev_change_id":15557283920}}}
{"jsonrpc":"2.0","method":"subscription","params":{"channel":"book.ETH-PERPETUAL.raw","data":{"timestamp":1734114574501,"type":"change","change_id":15557283922,"instrument_name":"ETH-PERPETUAL","bids":[],"asks":[["change",3896.45,2.0e5]],"prev_change_id":15557283921}}}
{"jsonrpc":"2.0","method":"subscription","params":{"channel":"book.ETH-PERPETUAL.raw","data":{"timestamp":1734114574501,"type":"change","change_id":15557283922,"instrument_name":"ETH-PERPETUAL","bids":[],"asks":[["change",3896.45,2.0e5]],"prev_change_id":15557283921}}}
{"jsonrpc":"2.0","method":"subscription","params":{"channel":"book.ETH-PERPETUAL.raw","data":{"timestamp":1734114574643,"type":"change","change_id":15557283925,"instrument_name":"ETH-PERPETUAL","bids":[["delete",3881.4,0.0]],"asks":[["delete",3896.45,0.0]],"prev_change_id":15557283922}}}
{"jsonrpc":"2.0","method":"subscription","params":{"channel":"book.ETH-PERPETUAL.raw","data":{"timestamp":1734114574643,"type":"change","change_id":15557283925,"instrument_name":"ETH-PERPETUAL","bids":[["delete",3881.4,0.0]],"asks":[["delete",3896.45,0.0]],"prev_change_id":15557283922}}}
{"jsonrpc":"2.0","method":"subscription","params":{"channel":"book.ETH-PERPETUAL.raw","data":{"timestamp":1734114574788,"type":"change","change_id":15557283926,"instrument_name":"ETH-PERPETUAL","bids":[["delete",3842.75,0.0],["new",3831.1,700.0]],"asks":[],"prev_change_id":15557283925}}}
{"jsonrpc":"2.0","method":"subscription","params":{"channel":"book.ETH-PERPETUAL.raw","data":{"timestamp":1734114574788,"type":"change","change_id":15557283926,"instrument_name":"ETH-PERPETUAL","bids":[["delete",3842.75,0.0],["new",3831.1,700.0]],"asks":[],"prev_change_id":15557283925}}}
{"jsonrpc":"2.0","method":"subscription","params":{"channel":"book.ETH-PERPETUAL.raw","data":{"timestamp":1734114574789,"type":"change","change_id":15557283927,"instrument_name":"ETH-PERPETUAL","bids":[["delete",3862.15,0.0],["new",3850.45,500.0]],"asks":[],"prev_change_id":15557283926}}}
{"jsonrpc":"2.0","method":"subscription","params":{"channel":"book.ETH-PERPETUAL.raw","data":{"timestamp":1734114574789,"type":"change","change_id":15557283927,"instrument_name":"ETH-PERPETUAL","bids":[["delete",3862.15,0.0],["new",3850.45,500.0]],"asks":[],"prev_change_id":15557283926}}}
{"jsonrpc":"2.0","method":"subscription","params":{"channel":"book.ETH-PERPETUAL.raw","data":{"timestamp":1734114574844,"type":"change","change_id":15557283939,"instrument_name":"ETH-PERPETUAL","bids":[["new",3881.4,8.0e4]],"asks":[],"prev_change_id":15557283927}}}
{"jsonrpc":"2.0","method":"subscription","params":{"channel":"book.ETH-PERPETUAL.raw","data":{"timestamp":1734114574844,"type":"change","change_id":15557283939,"instrument_name":"ETH-PERPETUAL","bids":[["new",3881.4,8.0e4]],"asks":[],"prev_change_id":15557283927}}}
{"jsonrpc":"2.0","method":"subscription","params":{"channel":"book.ETH-PERPETUAL.raw","data":{"timestamp":1734114574845,"type":"change","change_id":15557283941,"instrument_name":"ETH-PERPETUAL","bids":[],"asks":[["new",3896.45,8.0e4]],"prev_change_id":15557283939}}}
{"jsonrpc":"2.0","method":"subscription","params":{"channel":"book.ETH-PERPETUAL.raw","data":{"timestamp":1734114574845,"type":"change","change_id":15557283941,"instrument_name":"ETH-PERPETUAL","bids":[],"asks":[["new",3896.45,8.0e4]],"prev_change_id":15557283939}}}
{"jsonrpc":"2.0","method":"subscription","params":{"channel":"book.ETH-PERPETUAL.raw","data":{"timestamp":1734114574846,"type":"change","change_id":15557283942,"instrument_name":"ETH-PERPETUAL","bids":[["change",3881.4,1.0e5]],"asks":[],"prev_change_id":15557283941}}}
{"jsonrpc":"2.0","method":"subscription","params":{"channel":"book.ETH-PERPETUAL.raw","data":{"timestamp":1734114574846,"type":"change","change_id":15557283942,"instrument_name":"ETH-PERPETUAL","bids":[["change",3881.4,1.0e5]],"asks":[],"prev_change_id":15557283941}}}
{"jsonrpc":"2.0","method":"subscription","params":{"channel":"book.ETH-PERPETUAL.raw","data":{"timestamp":1734114574848,"type":"change","change_id":15557283943,"instrument_name":"ETH-PERPETUAL","bids":[["change",3881.4,1.8e5]],"asks":[],"prev_change_id":15557283942}}}
{"jsonrpc":"2.0","method":"subscription","params":{"channel":"book.ETH-PERPETUAL.raw","data":{"timestamp":1734114574848,"type":"change","change_id":15557283943,"instrument_name":"ETH-PERPETUAL","bids":[["change",3881.4,1.8e5]],"asks":[],"prev_change_id":15557283942}}}
{"jsonrpc":"2.0","method":"subscription","params":{"channel":"book.ETH-PERPETUAL.raw","data":{"timestamp":1734114574849,"type":"change","change_id":15557283944,"instrument_name":"ETH-PERPETUAL","bids":[],"asks":[["change",3896.45,1.6e5]],"prev_change_id":15557283943}}}
{"jsonrpc":"2.0","method":"subscription","params":{"channel":"book.ETH-PERPETUAL.raw","data":{"timestamp":1734114574849,"type":"change","change_id":15557283944,"instrument_name":"ETH-PERPETUAL","bids":[],"asks":[["change",3896.45,1.6e5]],"prev_change_id":15557283943}}}
{"jsonrpc":"2.0","method":"subscription","params":{"channel":"book.ETH-PERPETUAL.raw","data":{"timestamp":1734114574850,"type":"change","change_id":15557283945,"instrument_name":"ETH-PERPETUAL","bids":[["change",3881.4,2.0e5]],"asks":[],"prev_change_id":15557283944}}}
{"jsonrpc":"2.0","method":"subscription","params":{"channel":"book.ETH-PERPETUAL.raw","data":{"timestamp":1734114574850,"type":"change","change_id":15557283945,"instrument_name":"ETH-PERPETUAL","bids":[["change",3881.4,2.0e5]],"asks":[],"prev_change_id":15557283944}}}
{"jsonrpc":"2.0","method":"subscription","params":{"channel":"book.ETH-PERPETUAL.raw","data":{"timestamp":1734114575003,"type":"change","change_id":15557283955,"instrument_name":"ETH-PERPETUAL","bids":[["new",1942.0,1.0]],"asks":[],"prev_change_id":15557283945}}}
{"jsonrpc":"2.0","method":"subscription","params":{"channel":"book.ETH-PERPETUAL.raw","data":{"timestamp":1734114575003,"type":"change","change_id":15557283955,"instrument_name":"ETH-PERPETUAL","bids":[["new",1942.0,1.0]],"asks":[],"prev_change_id":15557283945}}}
{"jsonrpc":"2.0","method":"subscription","params":{"channel":"book.ETH-PERPETUAL.raw","data":{"timestamp":1734114575005,"type":"change","change_id":15557283956,"instrument_name":"ETH-PERPETUAL","bids":[["delete",3881.4,0.0]],"asks":[["delete",3896.45,0.0]],"prev_change_id":15557283955}}}
{"jsonrpc":"2.0","method":"subscription","params":{"channel":"book.ETH-PERPETUAL.raw","data":{"timestamp":1734114575005,"type":"change","change_id":15557283956,"instrument_name":"ETH-PERPETUAL","bids":[["delete",3881.4,0.0]],"asks":[["delete",3896.45,0.0]],"prev_change_id":15557283955}}}
{"jsonrpc":"2.0","method":"subscription","params":{"channel":"book.ETH-PERPETUAL.raw","data":{"timestamp":1734114575005,"type":"change","change_id":15557283957,"instrument_name":"ETH-PERPETUAL","bids":[["new",3869.75,500.0],["delete",3858.15,0.0]],"asks":[],"prev_change_id":15557283956}}}
{"jsonrpc":"2.0","method":"subscription","params":{"channel":"book.ETH-PERPETUAL.raw","data":{"timestamp":1734114575005,"type":"change","change_id":15557283957,"instrument_name":"ETH-PERPETUAL","bids":[["new",3869.75,500.0],["delete",3858.15,0.0]],"asks":[],"prev_change_id":15557283956}}}
{"jsonrpc":"2.0","method":"subscription","params":{"channel":"book.ETH-PERPETUAL.raw","data":{"timestamp":1734114575208,"type":"change","change_id":15557283958,"instrument_name":"ETH-PERPETUAL","bids":[["new",3881.4,8.0e4]],"asks":[],"prev_change_id":15557283957}}}
{"jsonrpc":"2.0","method":"subscription","params":{"channel":"book.ETH-PERPETUAL.raw","data":{"timestamp":1734114575208,"type":"change","change_id":15557283958,"instrument_name":"ETH-PERPETUAL","bids":[["new",3881.4,8.0e4]],"asks":[],"prev_change_id":15557283957}}}
{"jsonrpc":"2.0","method":"subscription","params":{"channel":"book.ETH-PERPETUAL.raw","data":{"timestamp":1734114575210,"type":"change","change_id":15557283959,"instrument_name":"ETH-PERPETUAL","bids":[],"asks":[["new",3896.45,8.0e4]],"prev_change_id":15557283958}}}
{"jsonrpc":"2.0","method":"subscription","params":{"channel":"book.ETH-PERPETUAL.raw","data":{"timestamp":1734114575210,"type":"change","change_id":15557283959,"instrument_name":"ETH-PERPETUAL","bids":[],"asks":[["new",3896.45,8.0e4]],"prev_change_id":15557283958}}}
{"jsonrpc":"2.0","method":"subscription","params":{"channel":"book.ETH-PERPETUAL.raw","data":{"timestamp":1734114575211,"type":"change","change_id":15557283960,"instrument_name":"ETH-PERPETUAL","bids":[["change",3881.4,1.0e5]],"asks":[],"prev_change_id":15557283959}}}
{"jsonrpc":"2.0","method":"subscription","params":{"channel":"book.ETH-PERPETUAL.raw","data":{"timestamp":1734114575211,"type":"change","change_id":15557283960,"instrument_name":"ETH-PERPETUAL","bids":[["change",3881.4,1.0e5]],"asks":[],"prev_change_id":15557283959}}}
{"jsonrpc":"2.0","method":"subscription","params":{"channel":"book.ETH-PERPETUAL.raw","data":{"timestamp":1734114575213,"type":"change","change_id":15557283961,"instrument_name":"ETH-PERPETUAL","bids":[],"asks":[["change",3896.45,1.0e5]],"prev_change_id":15557283960}}}
{"jsonrpc":"2.0","method":"subscription","params":{"channel":"book.ETH-PERPETUAL.raw","data":{"timestamp":1734114575213,"type":"change","change_id":15557283961,"instrument_name":"ETH-PERPETUAL","bids":[],"asks":[["change",3896.45,1.0e5]],"prev_change_id":15557283960}}}
{"jsonrpc":"2.0","method":"subscription","params":{"channel":"book.ETH-PERPETUAL.raw","data":{"timestamp":1734114575215,"type":"change","change_id":15557283962,"instrument_name":"ETH-PERPETUAL","bids":[["change",3881.4,1.8e5]],"asks":[],"prev_change_id":15557283961}}}
{"jsonrpc":"2.0","method":"subscription","params":{"channel":"book.ETH-PERPETUAL.raw","data":{"timestamp":1734114575215,"type":"change","change_id":15557283962,"instrument_name":"ETH-PERPETUAL","bids":[["change",3881.4,1.8e5]],"asks":[],"prev_change_id":15557283961}}}
{"jsonrpc":"2.0","method":"subscription","params":{"channel":"book.ETH-PERPETUAL.raw","data":{"timestamp":1734114575217,"type":"change","change_id":15557283963,"instrument_name":"ETH-PERPETUAL","bids":[],"asks":[["change",3896.45,1.8e5]],"prev_change_id":15557283962}}}
{"jsonrpc":"2.0","method":"subscription","params":{"channel":"book.ETH-PERPETUAL.raw","data":{"timestamp":1734114575217,"type":"change","change_id":15557283963,"instrument_name":"ETH-PERPETUAL","bids":[],"asks":[["change",3896.45,1.8e5]],"prev_change_id":15557283962}}}
{"jsonrpc":"2.0","method":"subscription","params":{"channel":"book.ETH-PERPETUAL.raw","data":{"timestamp":1734114575218,"type":"change","change_id":15557283964,"instrument_name":"ETH-PERPETUAL","bids":[["change",3881.4,2.0e5]],"asks":[],"prev_change_id":15557283963}}}
{"jsonrpc":"2.0","method":"subscription","params":{"channel":"book.ETH-PERPETUAL.raw","data":{"timestamp":1734114575218,"type":"change","change_id":15557283964,"instrument_name":"ETH-PERPETUAL","bids":[["change",3881.4,2.0e5]],"asks":[],"prev_change_id":15557283963}}}
{"jsonrpc":"2.0","method":"subscription","params":{"channel":"book.ETH-PERPETUAL.raw","data":{"timestamp":1734114575220,"type":"change","change_id":15557283965,"instrument_name":"ETH-PERPETUAL","bids":[],"asks":[["change",3896.45,2.0e5]],"prev_change_id":15557283964}}}
{"jsonrpc":"2.0","method":"subscription","params":{"channel":"book.ETH-PERPETUAL.raw","data":{"timestamp":1734114575220,"type":"change","change_id":15557283965,"instrument_name":"ETH-PERPETUAL","bids":[],"asks":[["change",3896.45,2.0e5]],"prev_change_id":15557283964}}}
{"jsonrpc":"2.0","method":"subscription","params":{"channel":"book.ETH-PERPETUAL.raw","data":{"timestamp":1734114575361,"type":"change","change_id":15557283966,"instrument_name":"ETH-PERPETUAL","bids":[["delete",3881.4,0.0]],"asks":[["delete",3896.45,0.0]],"prev_change_id":15557283965}}}
{"jsonrpc":"2.0","method":"subscription","params":{"channel":"book.ETH-PERPETUAL.raw","data":{"timestamp":1734114575361,"type":"change","change_id":15557283966,"instrument_name":"ETH-PERPETUAL","bids":[["delete",3881.4,0.0]],"asks":[["delete",3896.45,0.0]],"prev_change_id":15557283965}}}
{"jsonrpc":"2.0","method":"subscription","params":{"channel":"book.ETH-PERPETUAL.raw","data":{"timestamp":1734114575568,"type":"change","change_id":15557283967,"instrument_name":"ETH-PERPETUAL","bids":[["new",3881.4,8.0e4]],"asks":[],"prev_change_id":15557283966}}}
{"jsonrpc":"2.0","method":"subscription","params":{"channel":"book.ETH-PERPETUAL.raw","data":{"timestamp":1734114575568,"type":"change","change_id":15557283967,"instrument_name":"ETH-PERPETUAL","bids":[["new",3881.4,8.0e4]],"asks":[],"prev_change_id":15557283966}}}
{"jsonrpc":"2.0","method":"subscription","params":{"channel":"book.ETH-PERPETUAL.raw","data":{"timestamp":1734114575569,"type":"change","change_id":15557283968,"instrument_name":"ETH-PERPETUAL","bids":[],"asks":[["new",3896.45,8.0e4]],"prev_change_id":15557283967}}}
{"jsonrpc":"2.0","method":"subscription","params":{"channel":"book.ETH-PERPETUAL.raw","data":{"timestamp":1734114575569,"type":"change","change_id":15557283968,"instrument_name":"ETH-PERPETUAL","bids":[],"asks":[["new",3896.45,8.0e4]],"prev_change_id":15557283967}}}
{"jsonrpc":"2.0","method":"subscription","params":{"channel":"book.ETH-PERPETUAL.raw","data":{"timestamp":1734114575570,"type":"change","change_id":15557283969,"instrument_name":"ETH-PERPETUAL","bids":[["change",3881.4,1.6e5]],"asks":[],"prev_change_id":15557283968}}}
{"jsonrpc":"2.0","method":"subscription","params":{"channel":"book.ETH-PERPETUAL.raw","data":{"timestamp":1734114575570,"type":"change","change_id":15557283969,"instrument_name":"ETH-PERPETUAL","bids":[["change",3881.4,1.6e5]],"asks":[],"prev_change_id":15557283968}}}
{"jsonrpc":"2.0","method":"subscription","params":{"channel":"book.ETH-PERPETUAL.raw","data":{"timestamp":1734114575571,"type":"change","change_id":15557283970,"instrument_name":"ETH-PERPETUAL","bids":[],"asks":[["change",3896.45,1.6e5]],"prev_change_id":15557283969}}}
{"jsonrpc":"2.0","method":"subscription","params":{"channel":"book.ETH-PERPETUAL.raw","data":{"timestamp":1734114575571,"type":"change","change_id":15557283970,"instrument_name":"ETH-PERPETUAL","bids":[],"asks":[["change",3896.45,1.6e5]],"prev_change_id":15557283969}}}
{"jsonrpc":"2.0","method":"subscription","params":{"channel":"book.ETH-PERPETUAL.raw","data":{"timestamp":1734114575709,"type":"change","change_id":15557283972,"instrument_name":"ETH-PERPETUAL","bids":[["delete",3881.4,0.0]],"asks":[["delete",3896.45,0.0]],"prev_change_id":15557283970}}}
{"jsonrpc":"2.0","method":"subscription","params":{"channel":"book.ETH-PERPETUAL.raw","data":{"timestamp":1734114575709,"type":"change","change_id":15557283972,"instrument_name":"ETH-PERPETUAL","bids":[["delete",3881.4,0.0]],"asks":[["delete",3896.45,0.0]],"prev_change_id":15557283970}}}
{"jsonrpc":"2.0","method":"subscription","params":{"channel":"book.ETH-PERPETUAL.raw","data":{"timestamp":1734114575903,"type":"change","change_id":15557283978,"instrument_name":"ETH-PERPETUAL","bids":[["new",3881.35,8.0e4]],"asks":[],"prev_change_id":15557283972}}}
{"jsonrpc":"2.0","method":"subscription","params":{"channel":"book.ETH-PERPETUAL.raw","data":{"timestamp":1734114575903,"type":"change","change_id":15557283978,"instrument_name":"ETH-PERPETUAL","bids":[["new",3881.35,8.0e4]],"asks":[],"prev_change_id":15557283972}}}
{"jsonrpc":"2.0","method":"subscription","params":{"channel":"book.ETH-PERPETUAL.raw","data":{"timestamp":1734114575905,"type":"change","change_id":15557283979,"instrument_name":"ETH-PERPETUAL","bids":[],"asks":[["new",3896.4,8.0e4]],"prev_change_id":15557283978}}}
{"jsonrpc":"2.0","method":"subscription","params":{"channel":"book.ETH-PERPETUAL.raw","data":{"timestamp":1734114575905,"type":"change","change_id":15557283979,"instrument_name":"ETH-PERPETUAL","bids":[],"asks":[["new",3896.4,8.0e4]],"prev_change_id":15557283978}}}
{"jsonrpc":"2.0","method":"subscription","params":{"channel":"book.ETH-PERPETUAL.raw","data":{"timestamp":1734114575907,"type":"change","change_id":15557283980,"instrument_name":"ETH-PERPETUAL","bids":[["change",3881.35,1.0e5]],"asks":[],"prev_change_id":15557283979}}}
{"jsonrpc":"2.0","method":"subscription","params":{"channel":"book.ETH-PERPETUAL.raw","data":{"timestamp":1734114575907,"type":"change","change_id":15557283980,"instrument_name":"ETH-PERPETUAL","bids":[["change",3881.35,1.0e5]],"asks":[],"prev_change_id":15557283979}}}
{"jsonrpc":"2.0","method":"subscription","params":{"channel":"book.ETH-PERPETUAL.raw","data":{"timestamp":1734114575908,"type":"change","change_id":15557283981,"instrument_name":"ETH-PERPETUAL","bids":[],"asks":[["change",3896.4,1.0e5]],"prev_change_id":15557283980}}}
{"jsonrpc":"2.0","method":"subscription","params":{"channel":"book.ETH-PERPETUAL.raw","data":{"timestamp":1734114575908,"type":"change","change_id":15557283981,"instrument_name":"ETH-PERPETUAL","bids":[],"asks":[["change",3896.4,1.0e5]],"prev_change_id":15557283980}}}
{"jsonrpc":"2.0","method":"subscription","params":{"channel":"book.ETH-PERPETUAL.raw","data":{"timestamp":1734114575910,"type":"change","change_id":15557283982,"instrument_name":"ETH-PERPETUAL","bids":[["change",3881.35,1.8e5]],"asks":[],"prev_change_id":15557283981}}}
{"jsonrpc":"2.0","method":"subscription","params":{"channel":"book.ETH-PERPETUAL.raw","data":{"timestamp":1734114575910,"type":"change","change_id":15557283982,"instrument_name":"ETH-PERPETUAL","bids":[["change",3881.35,1.8e5]],"asks":[],"prev_change_id":15557283981}}}
{"jsonrpc":"2.0","method":"subscription","params":{"channel":"book.ETH-PERPETUAL.raw","data":{"timestamp":1734114575912,"type":"change","change_id":15557283983,"instrument_name":"ETH-PERPETUAL","bids":[],"asks":[["change",3896.4,1.8e5]],"prev_change_id":15557283982}}}
{"jsonrpc":"2.0","method":"subscription","params":{"channel":"book.ETH-PERPETUAL.raw","data":{"timestamp":1734114575912,"type":"change","change_id":15557283983,"instrument_name":"ETH-PERPETUAL","bids":[],"asks":[["change",3896.4,1.8e5]],"prev_change_id":15557283982}}}
{"jsonrpc":"2.0","method":"subscription","params":{"channel":"book.ETH-PERPETUAL.raw","data":{"timestamp":1734114575913,"type":"change","change_id":15557283984,"instrument_name":"ETH-PERPETUAL","bids":[["change",3881.35,2.0e5]],"asks":[],"prev_change_id":15557283983}}}
{"jsonrpc":"2.0","method":"subscription","params":{"channel":"book.ETH-PERPETUAL.raw","data":{"timestamp":1734114575913,"type":"change","change_id":15557283984,"instrument_name":"ETH-PERPETUAL","bids":[["change",3881.35,2.0e5]],"asks":[],"prev_change_id":15557283983}}}
{"jsonrpc":"2.0","method":"subscription","params":{"channel":"book.ETH-PERPETUAL.raw","data":{"timestamp":1734114575915,"type":"change","change_id":15557283985,"instrument_name":"ETH-PERPETUAL","bids":[],"asks":[["change",3896.4,2.0e5]],"prev_change_id":15557283984}}}
{"jsonrpc":"2.0","method":"subscription","params":{"channel":"book.ETH-PERPETUAL.raw","data":{"timestamp":1734114575915,"type":"change","change_id":15557283985,"instrument_name":"ETH-PERPETUAL","bids":[],"asks":[["change",3896.4,2.0e5]],"prev_change_id":15557283984}}}
{"jsonrpc":"2.0","method":"subscription","params":{"channel":"book.ETH-PERPETUAL.raw","data":{"timestamp":1734114576001,"type":"change","change_id":15557283986,"instrument_name":"ETH-PERPETUAL","bids":[["delete",3881.35,0.0]],"asks":[["delete",3896.4,0.0]],"prev_change_id":15557283985}}}
{"jsonrpc":"2.0","method":"subscription","params":{"channel":"book.ETH-PERPETUAL.raw","data":{"timestamp":1734114576001,"type":"change","change_id":15557283986,"instrument_name":"ETH-PERPETUAL","bids":[["delete",3881.35,0.0]],"asks":[["delete",3896.4,0.0]],"prev_change_id":15557283985}}}
{"jsonrpc":"2.0","method":"subscription","params":{"channel":"book.ETH-PERPETUAL.raw","data":{"timestamp":1734114576218,"type":"change","change_id":15557283988,"instrument_name":"ETH-PERPETUAL","bids":[["new",3881.35,8.0e4]],"asks":[],"prev_change_id":15557283986}}}
{"jsonrpc":"2.0","method":"subscription","params":{"channel":"book.ETH-PERPETUAL.raw","data":{"timestamp":1734114576218,"type":"change","change_id":15557283988,"instrument_name":"ETH-PERPETUAL","bids":[["new",3881.35,8.0e4]],"asks":[],"prev_change_id":15557283986}}}
{"jsonrpc":"2.0","method":"subscription","params":{"channel":"book.ETH-PERPETUAL.raw","data":{"timestamp":1734114576219,"type":"change","change_id":15557283989,"instrument_name":"ETH-PERPETUAL","bids":[],"asks":[["new",3896.4,8.0e4]],"prev_change_id":15557283988}}}
{"jsonrpc":"2.0","method":"subscription","params":{"channel":"book.ETH-PERPETUAL.raw","data":{"timestamp":1734114576219,"type":"change","change_id":15557283989,"instrument_name":"ETH-PERPETUAL","bids":[],"asks":[["new",3896.4,8.0e4]],"prev_change_id":15557283988}}}
{"jsonrpc":"2.0","method":"subscription","params":{"channel":"book.ETH-PERPETUAL.raw","data":{"timestamp":1734114576221,"type":"change","change_id":15557283990,"instrument_name":"ETH-PERPETUAL","bids":[["change",3881.35,1.0e5]],"asks":[],"prev_change_id":15557283989}}}
{"jsonrpc":"2.0","method":"subscription","params":{"channel":"book.ETH-PERPETUAL.raw","data":{"timestamp":1734114576221,"type":"change","change_id":15557283990,"instrument_name":"ETH-PERPETUAL","bids":[["change",3881.35,1.0e5]],"asks":[],"prev_change_id":15557283989}}}
{"jsonrpc":"2.0","method":"subscription","params":{"channel":"book.ETH-PERPETUAL.raw","data":{"timestamp":1734114576222,"type":"change","change_id":15557283991,"instrument_name":"ETH-PERPETUAL","bids":[],"asks":[["change",3896.4,1.0e5]],"prev_change_id":15557283990}}}
{"jsonrpc":"2.0","method":"subscription","params":{"channel":"book.ETH-PERPETUAL.raw","data":{"timestamp":1734114576222,"type":"change","change_id":15557283991,"instrument_name":"ETH-PERPETUAL","bids":[],"asks":[["change",3896.4,1.0e5]],"prev_change_id":15557283990}}}
{"jsonrpc":"2.0","method":"subscription","params":{"channel":"book.ETH-PERPETUAL.raw","data":{"timestamp":1734114576224,"type":"change","change_id":15557283992,"instrument_name":"ETH-PERPETUAL","bids":[["change",3881.35,1.8e5]],"asks":[],"prev_change_id":15557283991}}}
{"jsonrpc":"2.0","method":"subscription","params":{"channel":"book.ETH-PERPETUAL.raw","data":{"timestamp":1734114576224,"type":"change","change_id":15557283992,"instrument_name":"ETH-PERPETUAL","bids":[["change",3881.35,1.8e5]],"asks":[],"prev_change_id":15557283991}}}
{"jsonrpc":"2.0","method":"subscription","params":{"channel":"book.ETH-PERPETUAL.raw","data":{"timestamp":1734114576225,"type":"change","change_id":15557283993,"instrument_name":"ETH-PERPETUAL","bids":[],"asks":[["change",3896.4,1.8e5]],"prev_change_id":15557283992}}}
{"jsonrpc":"2.0","method":"subscription","params":{"channel":"book.ETH-PERPETUAL.raw","data":{"timestamp":1734114576225,"type":"change","change_id":15557283993,"instrument_name":"ETH-PERPETUAL","bids":[],"asks":[["change",3896.4,1.8e5]],"prev_change_id":15557283992}}}
{"jsonrpc":"2.0","method":"subscription","params":{"channel":"book.ETH-PERPETUAL.raw","data":{"timestamp":1734114576226,"type":"change","change_id":15557283994,"instrument_name":"ETH-PERPETUAL","bids":[["change",3881.35,2.0e5]],"asks":[],"prev_change_id":15557283993}}}
{"jsonrpc":"2.0","method":"subscription","params":{"channel":"book.ETH-PERPETUAL.raw","data":{"timestamp":1734114576226,"type":"change","change_id":15557283994,"instrument_name":"ETH-PERPETUAL","bids":[["change",3881.35,2.0e5]],"asks":[],"prev_change_id":15557283993}}}
{"jsonrpc":"2.0","method":"subscription","params":{"channel":"book.ETH-PERPETUAL.raw","data":{"timestamp":1734114576228,"type":"change","change_id":15557283995,"instrument_name":"ETH-PERPETUAL","bids":[],"asks":[["change",3896.4,2.0e5]],"prev_change_id":15557283994}}}
{"jsonrpc":"2.0","method":"subscription","params":{"channel":"book.ETH-PERPETUAL.raw","data":{"timestamp":1734114576228,"type":"change","change_id":15557283995,"instrument_name":"ETH-PERPETUAL","bids":[],"asks":[["change",3896.4,2.0e5]],"prev_change_id":15557283994}}}
{"jsonrpc":"2.0","method":"subscription","params":{"channel":"book.ETH-PERPETUAL.raw","data":{"timestamp":1734114576310,"type":"change","change_id":15557283996,"instrument_name":"ETH-PERPETUAL","bids":[["delete",3881.35,0.0]],"asks":[["delete",3896.4,0.0]],"prev_change_id":15557283995}}}
{"jsonrpc":"2.0","method":"subscription","params":{"channel":"book.ETH-PERPETUAL.raw","data":{"timestamp":1734114576310,"type":"change","change_id":15557283996,"instrument_name":"ETH-PERPETUAL","bids":[["delete",3881.35,0.0]],"asks":[["delete",3896.4,0.0]],"prev_change_id":15557283995}}}
{"jsonrpc":"2.0","method":"subscription","params":{"channel":"book.ETH-PERPETUAL.raw","data":{"timestamp":1734114576363,"type":"change","change_id":15557283997,"instrument_name":"ETH-PERPETUAL","bids":[],"asks":[["delete",3935.65,0.0],["new",3947.8,700.0]],"prev_change_id":15557283996}}}
{"jsonrpc":"2.0","method":"subscription","params":{"channel":"book.ETH-PERPETUAL.raw","data":{"timestamp":1734114576363,"type":"change","change_id":15557283997,"instrument_name":"ETH-PERPETUAL","bids":[],"asks":[["delete",3935.65,0.0],["new",3947.8,700.0]],"prev_change_id":15557283996}}}
{"jsonrpc":"2.0","method":"subscription","params":{"channel":"book.ETH-PERPETUAL.raw","data":{"timestamp":1734114576509,"type":"change","change_id":15557283999,"instrument_name":"ETH-PERPETUAL","bids":[["new",3881.35,3870.0],["delete",3869.8,0.0]],"asks":[],"prev_change_id":15557283997}}}
{"jsonrpc":"2.0","method":"subscription","params":{"channel":"book.ETH-PERPETUAL.raw","data":{"timestamp":1734114576509,"type":"change","change_id":15557283999,"instrument_name":"ETH-PERPETUAL","bids":[["new",3881.35,3870.0],["delete",3869.8,0.0]],"asks":[],"prev_change_id":15557283997}}}
{"jsonrpc":"2.0","method":"subscription","params":{"channel":"book.ETH-PERPETUAL.raw","data":{"timestamp":1734114576513,"type":"change","change_id":15557284000,"instrument_name":"ETH-PERPETUAL","bids":[["change",3881.35,83870.0]],"asks":[],"prev_change_id":15557283999}}}
{"jsonrpc":"2.0","method":"subscription","params":{"channel":"book.ETH-PERPETUAL.raw","data":{"timestamp":1734114576513,"type":"change","change_id":15557284000,"instrument_name":"ETH-PERPETUAL","bids":[["change",3881.35,83870.0]],"asks":[],"prev_change_id":15557283999}}}
{"jsonrpc":"2.0","method":"subscription","params":{"channel":"book.ETH-PERPETUAL.raw","data":{"timestamp":1734114576515,"type":"change","change_id":15557284001,"instrument_name":"ETH-PERPETUAL","bids":[],"asks":[["new",3896.4,8.0e4]],"prev_change_id":15557284000}}}
{"jsonrpc":"2.0","method":"subscription","params":{"channel":"book.ETH-PERPETUAL.raw","data":{"timestamp":1734114576515,"type":"change","change_id":15557284001,"instrument_name":"ETH-PERPETUAL","bids":[],"asks":[["new",3896.4,8.0e4]],"prev_change_id":15557284000}}}
{"jsonrpc":"2.0","method":"subscription","params":{"channel":"book.ETH-PERPETUAL.raw","data":{"timestamp":1734114576517,"type":"change","change_id":15557284002,"instrument_name":"ETH-PERPETUAL","bids":[["change",3881.35,163870.0]],"asks":[],"prev_change_id":15557284001}}}
{"jsonrpc":"2.0","method":"subscription","params":{"channel":"book.ETH-PERPETUAL.raw","data":{"timestamp":1734114576517,"type":"change","change_id":15557284002,"instrument_name":"ETH-PERPETUAL","bids":[["change",3881.35,163870.0]],"asks":[],"prev_change_id":15557284001}}}
{"jsonrpc":"2.0","method":"subscription","params":{"channel":"book.ETH-PERPETUAL.raw","data":{"timestamp":1734114576519,"type":"change","change_id":15557284003,"instrument_name":"ETH-PERPETUAL","bids":[],"asks":[["change",3896.4,1.6e5]],"prev_change_id":15557284002}}}
{"jsonrpc":"2.0","method":"subscription","params":{"channel":"book.ETH-PERPETUAL.raw","data":{"timestamp":1734114576519,"type":"change","change_id":15557284003,"instrument_name":"ETH-PERPETUAL","bids":[],"asks":[["change",3896.4,1.6e5]],"prev_change_id":15557284002}}}
{"jsonrpc":"2.0","method":"subscription","params":{"channel":"book.ETH-PERPETUAL.raw","data":{"timestamp":1734114576655,"type":"change","change_id":15557284006,"instrument_name":"ETH-PERPETUAL","bids":[["change",3881.35,3870.0]],"asks":[["delete",3896.4,0.0]],"prev_change_id":15557284003}}}
{"jsonrpc":"2.0","method":"subscription","params":{"channel":"book.ETH-PERPETUAL.raw","data":{"timestamp":1734114576655,"type":"change","change_id":15557284006,"instrument_name":"ETH-PERPETUAL","bids":[["change",3881.35,3870.0]],"asks":[["delete",3896.4,0.0]],"prev_change_id":15557284003}}}
{"jsonrpc":"2.0","method":"subscription","params":{"channel":"book.ETH-PERPETUAL.raw","data":{"timestamp":1734114576895,"type":"change","change_id":15557284025,"instrument_name":"ETH-PERPETUAL","bids":[],"asks":[["new",3896.4,8.0e4]],"prev_change_id":15557284006}}}
{"jsonrpc":"2.0","method":"subscription","params":{"channel":"book.ETH-PERPETUAL.raw","data":{"timestamp":1734114576895,"type":"change","change_id":15557284025,"instrument_name":"ETH-PERPETUAL","bids":[],"asks":[["new",3896.4,8.0e4]],"prev_change_id":15557284006}}}
{"jsonrpc":"2.0","method":"subscription","params":{"channel":"book.ETH-PERPETUAL.raw","data":{"timestamp":1734114576898,"type":"change","change_id":15557284026,"instrument_name":"ETH-PERPETUAL","bids":[["change",3881.35,83870.0]],"asks":[],"prev_change_id":15557284025}}}
{"jsonrpc":"2.0","method":"subscription","params":{"channel":"book.ETH-PERPETUAL.raw","data":{"timestamp":1734114576898,"type":"change","change_id":15557284026,"instrument_name":"ETH-PERPETUAL","bids":[["change",3881.35,83870.0]],"asks":[],"prev_change_id":15557284025}}}
{"jsonrpc":"2.0","method":"subscription","params":{"channel":"book.ETH-PERPETUAL.raw","data":{"timestamp":1734114576899,"type":"change","change_id":15557284027,"instrument_name":"ETH-PERPETUAL","bids":[],"asks":[["change",3896.4,1.0e5]],"prev_change_id":15557284026}}}
{"jsonrpc":"2.0","method":"subscription","params":{"channel":"book.ETH-PERPETUAL.raw","data":{"timestamp":1734114576899,"type":"change","change_id":15557284027,"instrument_name":"ETH-PERPETUAL","bids":[],"asks":[["change",3896.4,1.0e5]],"prev_change_id":15557284026}}}
{"jsonrpc":"2.0","method":"subscription","params":{"channel":"book.ETH-PERPETUAL.raw","data":{"timestamp":1734114576900,"type":"change","change_id":15557284028,"instrument_name":"ETH-PERPETUAL","bids":[["change",3881.35,103870.0]],"asks":[],"prev_change_id":15557284027}}}
{"jsonrpc":"2.0","method":"subscription","params":{"channel":"book.ETH-PERPETUAL.raw","data":{"timestamp":1734114576900,"type":"change","change_id":15557284028,"instrument_name":"ETH-PERPETUAL","bids":[["change",3881.35,103870.0]],"asks":[],"prev_change_id":15557284027}}}
{"jsonrpc":"2.0","method":"subscription","params":{"channel":"book.ETH-PERPETUAL.raw","data":{"timestamp":1734114576901,"type":"change","change_id":15557284029,"instrument_name":"ETH-PERPETUAL","bids":[],"asks":[["change",3896.4,1.8e5]],"prev_change_id":15557284028}}}
{"jsonrpc":"2.0","method":"subscription","params":{"channel":"book.ETH-PERPETUAL.raw","data":{"timestamp":1734114576901,"type":"change","change_id":15557284029,"instrument_name":"ETH-PERPETUAL","bids":[],"asks":[["change",3896.4,1.8e5]],"prev_change_id":15557284028}}}
{"jsonrpc":"2.0","method":"subscription","params":{"channel":"book.ETH-PERPETUAL.raw","data":{"timestamp":1734114576902,"type":"change","change_id":15557284030,"instrument_name":"ETH-PERPETUAL","bids":[["change",3881.35,183870.0]],"asks":[],"prev_change_id":15557284029}}}
{"jsonrpc":"2.0","method":"subscription","params":{"channel":"book.ETH-PERPETUAL.raw","data":{"timestamp":1734114576902,"type":"change","change_id":15557284030,"instrument_name":"ETH-PERPETUAL","bids":[["change",3881.35,183870.0]],"asks":[],"prev_change_id":15557284029}}}
{"jsonrpc":"2.0","method":"subscription","params":{"channel":"book.ETH-PERPETUAL.raw","data":{"timestamp":1734114576903,"type":"change","change_id":15557284031,"instrument_name":"ETH-PERPETUAL","bids":[],"asks":[["change",3896.4,2.0e5]],"prev_change_id":15557284030}}}
{"jsonrpc":"2.0","method":"subscription","params":{"channel":"book.ETH-PERPETUAL.raw","data":{"timestamp":1734114576903,"type":"change","change_id":15557284031,"instrument_name":"ETH-PERPETUAL","bids":[],"asks":[["change",3896.4,2.0e5]],"prev_change_id":15557284030}}}
{"jsonrpc":"2.0","method":"subscription","params":{"channel":"book.ETH-PERPETUAL.raw","data":{"timestamp":1734114576904,"type":"change","change_id":15557284032,"instrument_name":"ETH-PERPETUAL","bids":[["change",3881.35,203870.0]],"asks":[],"prev_change_id":15557284031}}}
{"jsonrpc":"2.0","method":"subscription","params":{"channel":"book.ETH-PERPETUAL.raw","data":{"timestamp":1734114576904,"type":"change","change_id":15557284032,"instrument_name":"ETH-PERPETUAL","bids":[["change",3881.35,203870.0]],"asks":[],"prev_change_id":15557284031}}}
{"jsonrpc":"2.0","method":"subscription","params":{"channel":"book.ETH-PERPETUAL.raw","data":{"timestamp":1734114576997,"type":"change","change_id":15557284033,"instrument_name":"ETH-PERPETUAL","bids":[["change",3881.35,3870.0]],"asks":[["delete",3896.4,0.0]],"prev_change_id":15557284032}}}
{"jsonrpc":"2.0","method":"subscription","params":{"channel":"book.ETH-PERPETUAL.raw","data":{"timestamp":1734114576997,"type":"change","change_id":15557284033,"instrument_name":"ETH-PERPETUAL","bids":[["change",3881.35,3870.0]],"asks":[["delete",3896.4,0.0]],"prev_change_id":15557284032}}}
{"jsonrpc":"2.0","method":"subscription","params":{"channel":"book.ETH-PERPETUAL.raw","data":{"timestamp":1734114577186,"type":"change","change_id":15557284034,"instrument_name":"ETH-PERPETUAL","bids":[],"asks":[["new",3896.4,8.0e4]],"prev_change_id":15557284033}}}
{"jsonrpc":"2.0","method":"subscription","params":{"channel":"book.ETH-PERPETUAL.raw","data":{"timestamp":1734114577186,"type":"change","change_id":15557284034,"instrument_name":"ETH-PERPETUAL","bids":[],"asks":[["new",3896.4,8.0e4]],"prev_change_id":15557284033}}}
{"jsonrpc":"2.0","method":"subscription","params":{"channel":"book.ETH-PERPETUAL.raw","data":{"timestamp":1734114577190,"type":"change","change_id":15557284035,"instrument_name":"ETH-PERPETUAL","bids":[["change",3881.35,83870.0]],"asks":[],"prev_change_id":15557284034}}}
{"jsonrpc":"2.0","method":"subscription","params":{"channel":"book.ETH-PERPETUAL.raw","data":{"timestamp":1734114577190,"type":"change","change_id":15557284035,"instrument_name":"ETH-PERPETUAL","bids":[["change",3881.35,83870.0]],"asks":[],"prev_change_id":15557284034}}}
{"jsonrpc":"2.0","method":"subscription","params":{"channel":"book.ETH-PERPETUAL.raw","data":{"timestamp":1734114577191,"type":"change","change_id":15557284036,"instrument_name":"ETH-PERPETUAL","bids":[],"asks":[["change",3896.4,1.0e5]],"prev_change_id":15557284035}}}
{"jsonrpc":"2.0","method":"subscription","params":{"channel":"book.ETH-PERPETUAL.raw","data":{"timestamp":1734114577191,"type":"change","change_id":15557284036,"instrument_name":"ETH-PERPETUAL","bids":[],"asks":[["change",3896.4,1.0e5]],"prev_change_id":15557284035}}}
{"jsonrpc":"2.0","method":"subscription","params":{"channel":"book.ETH-PERPETUAL.raw","data":{"timestamp":1734114577192,"type":"change","change_id":15557284037,"instrument_name":"ETH-PERPETUAL","bids":[],"asks":[["change",3896.4,1.8e5]],"prev_change_id":15557284036}}}
{"jsonrpc":"2.0","method":"subscription","params":{"channel":"book.ETH-PERPETUAL.raw","data":{"timestamp":1734114577192,"type":"change","change_id":15557284037,"instrument_name":"ETH-PERPETUAL","bids":[],"asks":[["change",3896.4,1.8e5]],"prev_change_id":15557284036}}}
{"jsonrpc":"2.0","method":"subscription","params":{"channel":"book.ETH-PERPETUAL.raw","data":{"timestamp":1734114577193,"type":"change","change_id":15557284038,"instrument_name":"ETH-PERPETUAL","bids":[["change",3881.35,163870.0]],"asks":[],"prev_change_id":15557284037}}}
{"jsonrpc":"2.0","method":"subscription","params":{"channel":"book.ETH-PERPETUAL.raw","data":{"timestamp":1734114577193,"type":"change","change_id":15557284038,"instrument_name":"ETH-PERPETUAL","bids":[["change",3881.35,163870.0]],"asks":[],"prev_change_id":15557284037}}}
{"jsonrpc":"2.0","method":"subscription","params":{"channel":"book.ETH-PERPETUAL.raw","data":{"timestamp":1734114577198,"type":"change","change_id":15557284039,"instrument_name":"ETH-PERPETUAL","bids":[],"asks":[["change",3896.4,2.0e5]],"prev_change_id":15557284038}}}
{"jsonrpc":"2.0","method":"subscription","params":{"channel":"book.ETH-PERPETUAL.raw","data":{"timestamp":1734114577198,"type":"change","change_id":15557284039,"instrument_name":"ETH-PERPETUAL","bids":[],"asks":[["change",3896.4,2.0e5]],"prev_change_id":15557284038}}}
{"jsonrpc":"2.0","method":"subscription","params":{"channel":"book.ETH-PERPETUAL.raw","data":{"timestamp":1734114577286,"type":"change","change_id":15557284040,"instrument_name":"ETH-PERPETUAL","bids":[["change",3881.35,3870.0]],"asks":[["delete",3896.4,0.0]],"prev_change_id":15557284039}}}
{"jsonrpc":"2.0","method":"subscription","params":{"channel":"book.ETH-PERPETUAL.raw","data":{"timestamp":1734114577286,"type":"change","change_id":15557284040,"instrument_name":"ETH-PERPETUAL","bids":[["change",3881.35,3870.0]],"asks":[["delete",3896.4,0.0]],"prev_change_id":15557284039}}}
{"jsonrpc":"2.0","method":"subscription","params":{"channel":"book.ETH-PERPETUAL.raw","data":{"timestamp":1734114577468,"type":"change","change_id":15557284041,"instrument_name":"ETH-PERPETUAL","bids":[],"asks":[["new",3896.35,8.0e4]],"prev_change_id":15557284040}}}
{"jsonrpc":"2.0","method":"subscription","params":{"channel":"book.ETH-PERPETUAL.raw","data":{"timestamp":1734114577468,"type":"change","change_id":15557284041,"instrument_name":"ETH-PERPETUAL","bids":[],"asks":[["new",3896.35,8.0e4]],"prev_change_id":15557284040}}}
{"jsonrpc":"2.0","method":"subscription","params":{"channel":"book.ETH-PERPETUAL.raw","data":{"timestamp":1734114577469,"type":"change","change_id":15557284042,"instrument_name":"ETH-PERPETUAL","bids":[["change",3881.35,83870.0]],"asks":[],"prev_change_id":15557284041}}}
{"jsonrpc":"2.0","method":"subscription","params":{"channel":"book.ETH-PERPETUAL.raw","data":{"timestamp":1734114577469,"type":"change","change_id":15557284042,"instrument_name":"ETH-PERPETUAL","bids":[["change",3881.35,83870.0]],"asks":[],"prev_change_id":15557284041}}}
{"jsonrpc":"2.0","method":"subscription","params":{"channel":"book.ETH-PERPETUAL.raw","data":{"timestamp":1734114577471,"type":"change","change_id":15557284043,"instrument_name":"ETH-PERPETUAL","bids":[],"asks":[["change",3896.35,1.0e5]],"prev_change_id":15557284042}}}
{"jsonrpc":"2.0","method":"subscription","params":{"channel":"book.ETH-PERPETUAL.raw","data":{"timestamp":1734114577471,"type":"change","change_id":15557284043,"instrument_name":"ETH-PERPETUAL","bids":[],"asks":[["change",3896.35,1.0e5]],"prev_change_id":15557284042}}}
{"jsonrpc":"2.0","method":"subscription","params":{"channel":"book.ETH-PERPETUAL.raw","data":{"timestamp":1734114577473,"type":"change","change_id":15557284044,"instrument_name":"ETH-PERPETUAL","bids":[],"asks":[["change",3896.35,1.8e5]],"prev_change_id":15557284043}}}
{"jsonrpc":"2.0","method":"subscription","params":{"channel":"book.ETH-PERPETUAL.raw","data":{"timestamp":1734114577473,"type":"change","change_id":15557284044,"instrument_name":"ETH-PERPETUAL","bids":[],"asks":[["change",3896.35,1.8e5]],"prev_change_id":15557284043}}}
{"jsonrpc":"2.0","method":"subscription","params":{"channel":"book.ETH-PERPETUAL.raw","data":{"timestamp":1734114577475,"type":"change","change_id":15557284045,"instrument_name":"ETH-PERPETUAL","bids":[["change",3881.35,163870.0]],"asks":[],"prev_change_id":15557284044}}}
{"jsonrpc":"2.0","method":"subscription","params":{"channel":"book.ETH-PERPETUAL.raw","data":{"timestamp":1734114577475,"type":"change","change_id":15557284045,"instrument_name":"ETH-PERPETUAL","bids":[["change",3881.35,163870.0]],"asks":[],"prev_change_id":15557284044}}}
{"jsonrpc":"2.0","method":"subscription","params":{"channel":"book.ETH-PERPETUAL.raw","data":{"timestamp":1734114577476,"type":"change","change_id":15557284046,"instrument_name":"ETH-PERPETUAL","bids":[],"asks":[["change",3896.35,2.0e5]],"prev_change_id":15557284045}}}
{"jsonrpc":"2.0","method":"subscription","params":{"channel":"book.ETH-PERPETUAL.raw","data":{"timestamp":1734114577476,"type":"change","change_id":15557284046,"instrument_name":"ETH-PERPETUAL","bids":[],"asks":[["change",3896.35,2.0e5]],"prev_change_id":15557284045}}}
{"jsonrpc":"2.0","method":"subscription","params":{"channel":"book.ETH-PERPETUAL.raw","data":{"timestamp":1734114577615,"type":"change","change_id":15557284047,"instrument_name":"ETH-PERPETUAL","bids":[["change",3881.35,3870.0]],"asks":[["delete",3896.35,0.0]],"prev_change_id":15557284046}}}
{"jsonrpc":"2.0","method":"subscription","params":{"channel":"book.ETH-PERPETUAL.raw","data":{"timestamp":1734114577615,"type":"change","change_id":15557284047,"instrument_name":"ETH-PERPETUAL","bids":[["change",3881.35,3870.0]],"asks":[["delete",3896.35,0.0]],"prev_change_id":15557284046}}}
{"jsonrpc":"2.0","method":"subscription","params":{"channel":"book.ETH-PERPETUAL.raw","data":{"timestamp":1734114577833,"type":"change","change_id":15557284051,"instrument_name":"ETH-PERPETUAL","bids":[],"asks":[["new",3896.35,8.0e4]],"prev_change_id":15557284047}}}
{"jsonrpc":"2.0","method":"subscription","params":{"channel":"book.ETH-PERPETUAL.raw","data":{"timestamp":1734114577833,"type":"change","change_id":15557284051,"instrument_name":"ETH-PERPETUAL","bids":[],"asks":[["new",3896.35,8.0e4]],"prev_change_id":15557284047}}}
{"jsonrpc":"2.0","method":"subscription","params":{"channel":"book.ETH-PERPETUAL.raw","data":{"timestamp":1734114577834,"type":"change","change_id":15557284053,"instrument_name":"ETH-PERPETUAL","bids":[["change",3881.35,83870.0]],"asks":[],"prev_change_id":15557284051}}}
{"jsonrpc":"2.0","method":"subscription","params":{"channel":"book.ETH-PERPETUAL.raw","data":{"timestamp":1734114577834,"type":"change","change_id":15557284053,"instrument_name":"ETH-PERPETUAL","bids":[["change",3881.35,83870.0]],"asks":[],"prev_change_id":15557284051}}}
{"jsonrpc":"2.0","method":"subscription","params":{"channel":"book.ETH-PERPETUAL.raw","data":{"timestamp":1734114577836,"type":"change","change_id":15557284055,"instrument_name":"ETH-PERPETUAL","bids":[],"asks":[["change",3896.35,1.0e5]],"prev_change_id":15557284053}}}
{"jsonrpc":"2.0","method":"subscription","params":{"channel":"book.ETH-PERPETUAL.raw","data":{"timestamp":1734114577836,"type":"change","change_id":15557284055,"instrument_name":"ETH-PERPETUAL","bids":[],"asks":[["change",3896.35,1.0e5]],"prev_change_id":15557284053}}}
{"jsonrpc":"2.0","method":"subscription","params":{"channel":"book.ETH-PERPETUAL.raw","data":{"timestamp":1734114577837,"type":"change","change_id":15557284056,"instrument_name":"ETH-PERPETUAL","bids":[],"asks":[["change",3896.35,1.8e5]],"prev_change_id":15557284055}}}
{"jsonrpc":"2.0","method":"subscription","params":{"channel":"book.ETH-PERPETUAL.raw","data":{"timestamp":1734114577837,"type":"change","change_id":15557284056,"instrument_name":"ETH-PERPETUAL","bids":[],"asks":[["change",3896.35,1.8e5]],"prev_change_id":15557284055}}}
{"jsonrpc":"2.0","method":"subscription","params":{"channel":"book.ETH-PERPETUAL.raw","data":{"timestamp":1734114577838,"type":"change","change_id":15557284058,"instrument_name":"ETH-PERPETUAL","bids":[["change",3881.35,163870.0]],"asks":[],"prev_change_id":15557284056}}}
{"jsonrpc":"2.0","method":"subscription","params":{"channel":"book.ETH-PERPETUAL.raw","data":{"timestamp":1734114577838,"type":"change","change_id":15557284058,"instrument_name":"ETH-PERPETUAL","bids":[["change",3881.35,163870.0]],"asks":[],"prev_change_id":15557284056}}}
{"jsonrpc":"2.0","method":"subscription","params":{"channel":"book.ETH-PERPETUAL.raw","data":{"timestamp":1734114577843,"type":"change","change_id":15557284059,"instrument_name":"ETH-PERPETUAL","bids":[],"asks":[["change",3896.35,2.0e5]],"prev_change_id":15557284058}}}
{"jsonrpc":"2.0","method":"subscription","params":{"channel":"book.ETH-PERPETUAL.raw","data":{"timestamp":1734114577843,"type":"change","change_id":15557284059,"instrument_name":"ETH-PERPETUAL","bids":[],"asks":[["change",3896.35,2.0e5]],"prev_change_id":15557284058}}}
{"jsonrpc":"2.0","method":"subscription","params":{"channel":"book.ETH-PERPETUAL.raw","data":{"timestamp":1734114578006,"type":"change","change_id":15557284074,"instrument_name":"ETH-PERPETUAL","bids":[["change",3881.35,3870.0]],"asks":[["delete",3896.35,0.0]],"prev_change_id":15557284059}}}
{"jsonrpc":"2.0","method":"subscription","params":{"channel":"book.ETH-PERPETUAL.raw","data":{"timestamp":1734114578006,"type":"change","change_id":15557284074,"instrument_name":"ETH-PERPETUAL","bids":[["change",3881.35,3870.0]],"asks":[["delete",3896.35,0.0]],"prev_change_id":15557284059}}}
{"jsonrpc":"2.0","method":"subscription","params":{"channel":"book.ETH-PERPETUAL.raw","data":{"timestamp":1734114578151,"type":"change","change_id":15557284075,"instrument_name":"ETH-PERPETUAL","bids":[],"asks":[["delete",3908.15,0.0],["new",3919.9,500.0]],"prev_change_id":15557284074}}}
{"jsonrpc":"2.0","method":"subscription","params":{"channel":"book.ETH-PERPETUAL.raw","data":{"timestamp":1734114578151,"type":"change","change_id":15557284075,"instrument_name":"ETH-PERPETUAL","bids":[],"asks":[["delete",3908.15,0.0],["new",3919.9,500.0]],"prev_change_id":15557284074}}}
{"jsonrpc":"2.0","method":"subscription","params":{"channel":"book.ETH-PERPETUAL.raw","data":{"timestamp":1734114578209,"type":"change","change_id":15557284076,"instrument_name":"ETH-PERPETUAL","bids":[],"asks":[["new",3896.4,8.0e4]],"prev_change_id":15557284075}}}
{"jsonrpc":"2.0","method":"subscription","params":{"channel":"book.ETH-PERPETUAL.raw","data":{"timestamp":1734114578209,"type":"change","change_id":15557284076,"instrument_name":"ETH-PERPETUAL","bids":[],"asks":[["new",3896.4,8.0e4]],"prev_change_id":15557284075}}}
{"jsonrpc":"2.0","method":"subscription","params":{"channel":"book.ETH-PERPETUAL.raw","data":{"timestamp":1734114578211,"type":"change","change_id":15557284077,"instrument_name":"ETH-PERPETUAL","bids":[["change",3881.35,83870.0]],"asks":[],"prev_change_id":15557284076}}}
{"jsonrpc":"2.0","method":"subscription","params":{"channel":"book.ETH-PERPETUAL.raw","data":{"timestamp":1734114578211,"type":"change","change_id":15557284077,"instrument_name":"ETH-PERPETUAL","bids":[["change",3881.35,83870.0]],"asks":[],"prev_change_id":15557284076}}}
{"jsonrpc":"2.0","method":"subscription","params":{"channel":"book.ETH-PERPETUAL.raw","data":{"timestamp":1734114578212,"type":"change","change_id":15557284078,"instrument_name":"ETH-PERPETUAL","bids":[],"asks":[["change",3896.4,1.0e5]],"prev_change_id":15557284077}}}
{"jsonrpc":"2.0","method":"subscription","params":{"channel":"book.ETH-PERPETUAL.raw","data":{"timestamp":1734114578212,"type":"change","change_id":15557284078,"instrument_name":"ETH-PERPETUAL","bids":[],"asks":[["change",3896.4,1.0e5]],"prev_change_id":15557284077}}}
{"jsonrpc":"2.0","method":"subscription","params":{"channel":"book.ETH-PERPETUAL.raw","data":{"timestamp":1734114578213,"type":"change","change_id":15557284079,"instrument_name":"ETH-PERPETUAL","bids":[["change",3881.35,103870.0]],"asks":[],"prev_change_id":15557284078}}}
{"jsonrpc":"2.0","method":"subscription","params":{"channel":"book.ETH-PERPETUAL.raw","data":{"timestamp":1734114578213,"type":"change","change_id":15557284079,"instrument_name":"ETH-PERPETUAL","bids":[["change",3881.35,103870.0]],"asks":[],"prev_change_id":15557284078}}}
{"jsonrpc":"2.0","method":"subscription","params":{"channel":"book.ETH-PERPETUAL.raw","data":{"timestamp":1734114578214,"type":"change","change_id":15557284080,"instrument_name":"ETH-PERPETUAL","bids":[],"asks":[["change",3896.4,1.8e5]],"prev_change_id":15557284079}}}
{"jsonrpc":"2.0","method":"subscription","params":{"channel":"book.ETH-PERPETUAL.raw","data":{"timestamp":1734114578214,"type":"change","change_id":15557284080,"instrument_name":"ETH-PERPETUAL","bids":[],"asks":[["change",3896.4,1.8e5]],"prev_change_id":15557284079}}}
{"jsonrpc":"2.0","method":"subscription","params":{"channel":"book.ETH-PERPETUAL.raw","data":{"timestamp":1734114578215,"type":"change","change_id":15557284081,"instrument_name":"ETH-PERPETUAL","bids":[["change",3881.35,183870.0]],"asks":[],"prev_change_id":15557284080}}}
{"jsonrpc":"2.0","method":"subscription","params":{"channel":"book.ETH-PERPETUAL.raw","data":{"timestamp":1734114578215,"type":"change","change_id":15557284081,"instrument_name":"ETH-PERPETUAL","bids":[["change",3881.35,183870.0]],"asks":[],"prev_change_id":15557284080}}}
{"jsonrpc":"2.0","method":"subscription","params":{"channel":"book.ETH-PERPETUAL.raw","data":{"timestamp":1734114578216,"type":"change","change_id":15557284082,"instrument_name":"ETH-PERPETUAL","bids":[],"asks":[["change",3896.4,2.0e5]],"prev_change_id":15557284081}}}
{"jsonrpc":"2.0","method":"subscription","params":{"channel":"book.ETH-PERPETUAL.raw","data":{"timestamp":1734114578216,"type":"change","change_id":15557284082,"instrument_name":"ETH-PERPETUAL","bids":[],"asks":[["change",3896.4,2.0e5]],"prev_change_id":15557284081}}}
{"jsonrpc":"2.0","method":"subscription","params":{"channel":"book.ETH-PERPETUAL.raw","data":{"timestamp":1734114578217,"type":"change","change_id":15557284083,"instrument_name":"ETH-PERPETUAL","bids":[["change",3881.35,203870.0]],"asks":[],"prev_change_id":15557284082}}}
{"jsonrpc":"2.0","method":"subscription","params":{"channel":"book.ETH-PERPETUAL.raw","data":{"timestamp":1734114578217,"type":"change","change_id":15557284083,"instrument_name":"ETH-PERPETUAL","bids":[["change",3881.35,203870.0]],"asks":[],"prev_change_id":15557284082}}}
{"jsonrpc":"2.0","method":"subscription","params":{"channel":"book.ETH-PERPETUAL.raw","data":{"timestamp":1734114578365,"type":"change","change_id":15557284084,"instrument_name":"ETH-PERPETUAL","bids":[["change",3881.35,3870.0]],"asks":[["delete",3896.4,0.0]],"prev_change_id":15557284083}}}
{"jsonrpc":"2.0","method":"subscription","params":{"channel":"book.ETH-PERPETUAL.raw","data":{"timestamp":1734114578365,"type":"change","change_id":15557284084,"instrument_name":"ETH-PERPETUAL","bids":[["change",3881.35,3870.0]],"asks":[["delete",3896.4,0.0]],"prev_change_id":15557284083}}}
{"jsonrpc":"2.0","method":"subscription","params":{"channel":"book.ETH-PERPETUAL.raw","data":{"timestamp":1734114578573,"type":"change","change_id":15557284085,"instrument_name":"ETH-PERPETUAL","bids":[],"asks":[["new",3896.4,8.0e4]],"prev_change_id":15557284084}}}
{"jsonrpc":"2.0","method":"subscription","params":{"channel":"book.ETH-PERPETUAL.raw","data":{"timestamp":1734114578573,"type":"change","change_id":15557284085,"instrument_name":"ETH-PERPETUAL","bids":[],"asks":[["new",3896.4,8.0e4]],"prev_change_id":15557284084}}}
{"jsonrpc":"2.0","method":"subscription","params":{"channel":"book.ETH-PERPETUAL.raw","data":{"timestamp":1734114578588,"type":"change","change_id":15557284086,"instrument_name":"ETH-PERPETUAL","bids":[["change",3881.35,83870.0]],"asks":[],"prev_change_id":15557284085}}}
{"jsonrpc":"2.0","method":"subscription","params":{"channel":"book.ETH-PERPETUAL.raw","data":{"timestamp":1734114578588,"type":"change","change_id":15557284086,"instrument_name":"ETH-PERPETUAL","bids":[["change",3881.35,83870.0]],"asks":[],"prev_change_id":15557284085}}}
{"jsonrpc":"2.0","method":"subscription","params":{"channel":"book.ETH-PERPETUAL.raw","data":{"timestamp":1734114578590,"type":"change","change_id":15557284087,"instrument_name":"ETH-PERPETUAL","bids":[],"asks":[["change",3896.4,1.0e5]],"prev_change_id":15557284086}}}
{"jsonrpc":"2.0","method":"subscription","params":{"channel":"book.ETH-PERPETUAL.raw","data":{"timestamp":1734114578590,"type":"change","change_id":15557284087,"instrument_name":"ETH-PERPETUAL","bids":[],"asks":[["change",3896.4,1.0e5]],"prev_change_id":15557284086}}}
{"jsonrpc":"2.0","method":"subscription","params":{"channel":"book.ETH-PERPETUAL.raw","data":{"timestamp":1734114578591,"type":"change","change_id":15557284088,"instrument_name":"ETH-PERPETUAL","bids":[],"asks":[["change",3896.4,1.8e5]],"prev_change_id":15557284087}}}
{"jsonrpc":"2.0","method":"subscription","params":{"channel":"book.ETH-PERPETUAL.raw","data":{"timestamp":1734114578591,"type":"change","change_id":15557284088,"instrument_name":"ETH-PERPETUAL","bids":[],"asks":[["change",3896.4,1.8e5]],"prev_change_id":15557284087}}}
{"jsonrpc":"2.0","method":"subscription","params":{"channel":"book.ETH-PERPETUAL.raw","data":{"timestamp":1734114578592,"type":"change","change_id":15557284089,"instrument_name":"ETH-PERPETUAL","bids":[["change",3881.35,163870.0]],"asks":[],"prev_change_id":15557284088}}}
{"jsonrpc":"2.0","method":"subscription","params":{"channel":"book.ETH-PERPETUAL.raw","data":{"timestamp":1734114578592,"type":"change","change_id":15557284089,"instrument_name":"ETH-PERPETUAL","bids":[["change",3881.35,163870.0]],"asks":[],"prev_change_id":15557284088}}}
{"jsonrpc":"2.0","method":"subscription","params":{"channel":"book.ETH-PERPETUAL.raw","data":{"timestamp":1734114578593,"type":"change","change_id":15557284090,"instrument_name":"ETH-PERPETUAL","bids":[],"asks":[["change",3896.4,2.0e5]],"prev_change_id":15557284089}}}
{"jsonrpc":"2.0","method":"subscription","params":{"channel":"book.ETH-PERPETUAL.raw","data":{"timestamp":1734114578593,"type":"change","change_id":15557284090,"instrument_name":"ETH-PERPETUAL","bids":[],"asks":[["change",3896.4,2.0e5]],"prev_change_id":15557284089}}}
{"jsonrpc":"2.0","method":"subscription","params":{"channel":"book.ETH-PERPETUAL.raw","data":{"timestamp":1734114578713,"type":"change","change_id":15557284091,"instrument_name":"ETH-PERPETUAL","bids":[["change",3881.35,3870.0]],"asks":[["delete",3896.4,0.0]],"prev_change_id":15557284090}}}
{"jsonrpc":"2.0","method":"subscription","params":{"channel":"book.ETH-PERPETUAL.raw","data":{"timestamp":1734114578713,"type":"change","change_id":15557284091,"instrument_name":"ETH-PERPETUAL","bids":[["change",3881.35,3870.0]],"asks":[["delete",3896.4,0.0]],"prev_change_id":15557284090}}}
{"jsonrpc":"2.0","method":"subscription","params":{"channel":"book.ETH-PERPETUAL.raw","data":{"timestamp":1734114578892,"type":"change","change_id":15557284101,"instrument_name":"ETH-PERPETUAL","bids":[],"asks":[["new",3896.4,8.0e4]],"prev_change_id":15557284091}}}
{"jsonrpc":"2.0","method":"subscription","params":{"channel":"book.ETH-PERPETUAL.raw","data":{"timestamp":1734114578892,"type":"change","change_id":15557284101,"instrument_name":"ETH-PERPETUAL","bids":[],"asks":[["new",3896.4,8.0e4]],"prev_change_id":15557284091}}}
{"jsonrpc":"2.0","method":"subscription","params":{"channel":"book.ETH-PERPETUAL.raw","data":{"timestamp":1734114578894,"type":"change","change_id":15557284102,"instrument_name":"ETH-PERPETUAL","bids":[["change",3881.35,83870.0]],"asks":[],"prev_change_id":15557284101}}}
{"jsonrpc":"2.0","method":"subscription","params":{"channel":"book.ETH-PERPETUAL.raw","data":{"timestamp":1734114578894,"type":"change","change_id":15557284102,"instrument_name":"ETH-PERPETUAL","bids":[["change",3881.35,83870.0]],"asks":[],"prev_change_id":15557284101}}}
{"jsonrpc":"2.0","method":"subscription","params":{"channel":"book.ETH-PERPETUAL.raw","data":{"timestamp":1734114578902,"type":"change","change_id":15557284104,"instrument_name":"ETH-PERPETUAL","bids":[],"asks":[["change",3896.4,1.0e5]],"prev_change_id":15557284102}}}
{"jsonrpc":"2.0","method":"subscription","params":{"channel":"book.ETH-PERPETUAL.raw","data":{"timestamp":1734114578902,"type":"change","change_id":15557284104,"instrument_name":"ETH-PERPETUAL","bids":[],"asks":[["change",3896.4,1.0e5]],"prev_change_id":15557284102}}}
{"jsonrpc":"2.0","method":"subscription","params":{"channel":"book.ETH-PERPETUAL.raw","data":{"timestamp":1734114578903,"type":"change","change_id":15557284105,"instrument_name":"ETH-PERPETUAL","bids":[["change",3881.35,103870.0]],"asks":[],"prev_change_id":15557284104}}}
{"jsonrpc":"2.0","method":"subscription","params":{"channel":"book.ETH-PERPETUAL.raw","data":{"timestamp":1734114578903,"type":"change","change_id":15557284105,"instrument_name":"ETH-PERPETUAL","bids":[["change",3881.35,103870.0]],"asks":[],"prev_change_id":15557284104}}}
{"jsonrpc":"2.0","method":"subscription","params":{"channel":"book.ETH-PERPETUAL.raw","data":{"timestamp":1734114578904,"type":"change","change_id":15557284106,"instrument_name":"ETH-PERPETUAL","bids":[],"asks":[["change",3896.4,1.8e5]],"prev_change_id":15557284105}}}
{"jsonrpc":"2.0","method":"subscription","params":{"channel":"book.ETH-PERPETUAL.raw","data":{"timestamp":1734114578904,"type":"change","change_id":15557284106,"instrument_name":"ETH-PERPETUAL","bids":[],"asks":[["change",3896.4,1.8e5]],"prev_change_id":15557284105}}}
{"jsonrpc":"2.0","method":"subscription","params":{"channel":"book.ETH-PERPETUAL.raw","data":{"timestamp":1734114578905,"type":"change","change_id":15557284107,"instrument_name":"ETH-PERPETUAL","bids":[["change",3881.35,183870.0]],"asks":[],"prev_change_id":15557284106}}}
{"jsonrpc":"2.0","method":"subscription","params":{"channel":"book.ETH-PERPETUAL.raw","data":{"timestamp":1734114578905,"type":"change","change_id":15557284107,"instrument_name":"ETH-PERPETUAL","bids":[["change",3881.35,183870.0]],"asks":[],"prev_change_id":15557284106}}}
{"jsonrpc":"2.0","method":"subscription","params":{"channel":"book.ETH-PERPETUAL.raw","data":{"timestamp":1734114578906,"type":"change","change_id":15557284108,"instrument_name":"ETH-PERPETUAL","bids":[],"asks":[["change",3896.4,2.0e5]],"prev_change_id":15557284107}}}
{"jsonrpc":"2.0","method":"subscription","params":{"channel":"book.ETH-PERPETUAL.raw","data":{"timestamp":1734114578906,"type":"change","change_id":15557284108,"instrument_name":"ETH-PERPETUAL","bids":[],"asks":[["change",3896.4,2.0e5]],"prev_change_id":15557284107}}}
{"jsonrpc":"2.0","method":"subscription","params":{"channel":"book.ETH-PERPETUAL.raw","data":{"timestamp":1734114578908,"type":"change","change_id":15557284110,"instrument_name":"ETH-PERPETUAL","bids":[["change",3881.35,203870.0]],"asks":[],"prev_change_id":15557284108}}}
{"jsonrpc":"2.0","method":"subscription","params":{"channel":"book.ETH-PERPETUAL.raw","data":{"timestamp":1734114578908,"type":"change","change_id":15557284110,"instrument_name":"ETH-PERPETUAL","bids":[["change",3881.35,203870.0]],"asks":[],"prev_change_id":15557284108}}}
{"jsonrpc":"2.0","method":"subscription","params":{"channel":"book.ETH-PERPETUAL.raw","data":{"timestamp":1734114579024,"type":"change","change_id":15557284111,"instrument_name":"ETH-PERPETUAL","bids":[["change",3881.35,3870.0]],"asks":[["delete",3896.4,0.0]],"prev_change_id":15557284110}}}
{"jsonrpc":"2.0","method":"subscription","params":{"channel":"book.ETH-PERPETUAL.raw","data":{"timestamp":1734114579024,"type":"change","change_id":15557284111,"instrument_name":"ETH-PERPETUAL","bids":[["change",3881.35,3870.0]],"asks":[["delete",3896.4,0.0]],"prev_change_id":15557284110}}}
{"jsonrpc":"2.0","method":"subscription","params":{"channel":"book.ETH-PERPETUAL.raw","data":{"timestamp":1734114579036,"type":"change","change_id":15557284112,"instrument_name":"ETH-PERPETUAL","bids":[],"asks":[["new",3915.9,500.0],["delete",3927.7,0.0]],"prev_change_id":15557284111}}}
{"jsonrpc":"2.0","method":"subscription","params":{"channel":"book.ETH-PERPETUAL.raw","data":{"timestamp":1734114579036,"type":"change","change_id":15557284112,"instrument_name":"ETH-PERPETUAL","bids":[],"asks":[["new",3915.9,500.0],["delete",3927.7,0.0]],"prev_change_id":15557284111}}}
{"jsonrpc":"2.0","method":"subscription","params":{"channel":"book.ETH-PERPETUAL.raw","data":{"timestamp":1734114579262,"type":"change","change_id":15557284113,"instrument_name":"ETH-PERPETUAL","bids":[],"asks":[["new",3896.4,8.0e4]],"prev_change_id":15557284112}}}
{"jsonrpc":"2.0","method":"subscription","params":{"channel":"book.ETH-PERPETUAL.raw","data":{"timestamp":1734114579262,"type":"change","change_id":15557284113,"instrument_name":"ETH-PERPETUAL","bids":[],"asks":[["new",3896.4,8.0e4]],"prev_change_id":15557284112}}}
{"jsonrpc":"2.0","method":"subscription","params":{"channel":"book.ETH-PERPETUAL.raw","data":{"timestamp":1734114579264,"type":"change","change_id":15557284114,"instrument_name":"ETH-PERPETUAL","bids":[["change",3881.35,83870.0]],"asks":[],"prev_change_id":15557284113}}}
{"jsonrpc":"2.0","method":"subscription","params":{"channel":"book.ETH-PERPETUAL.raw","data":{"timestamp":1734114579264,"type":"change","change_id":15557284114,"instrument_name":"ETH-PERPETUAL","bids":[["change",3881.35,83870.0]],"asks":[],"prev_change_id":15557284113}}}
{"jsonrpc":"2.0","method":"subscription","params":{"channel":"book.ETH-PERPETUAL.raw","data":{"timestamp":1734114579265,"type":"change","change_id":15557284115,"instrument_name":"ETH-PERPETUAL","bids":[],"asks":[["change",3896.4,1.0e5]],"prev_change_id":15557284114}}}
{"jsonrpc":"2.0","method":"subscription","params":{"channel":"book.ETH-PERPETUAL.raw","data":{"timestamp":1734114579265,"type":"change","change_id":15557284115,"instrument_name":"ETH-PERPETUAL","bids":[],"asks":[["change",3896.4,1.0e5]],"prev_change_id":15557284114}}}
{"jsonrpc":"2.0","method":"subscription","params":{"channel":"book.ETH-PERPETUAL.raw","data":{"timestamp":1734114579266,"type":"change","change_id":15557284116,"instrument_name":"ETH-PERPETUAL","bids":[],"asks":[["change",3896.4,1.8e5]],"prev_change_id":15557284115}}}
{"jsonrpc":"2.0","method":"subscription","params":{"channel":"book.ETH-PERPETUAL.raw","data":{"timestamp":1734114579266,"type":"change","change_id":15557284116,"instrument_name":"ETH-PERPETUAL","bids":[],"asks":[["change",3896.4,1.8e5]],"prev_change_id":15557284115}}}
{"jsonrpc":"2.0","method":"subscription","params":{"channel":"book.ETH-PERPETUAL.raw","data":{"timestamp":1734114579267,"type":"change","change_id":15557284117,"instrument_name":"ETH-PERPETUAL","bids":[["change",3881.35,163870.0]],"asks":[],"prev_change_id":15557284116}}}
{"jsonrpc":"2.0","method":"subscription","params":{"channel":"book.ETH-PERPETUAL.raw","data":{"timestamp":1734114579267,"type":"change","change_id":15557284117,"instrument_name":"ETH-PERPETUAL","bids":[["change",3881.35,163870.0]],"asks":[],"prev_change_id":15557284116}}}
{"jsonrpc":"2.0","method":"subscription","params":{"channel":"book.ETH-PERPETUAL.raw","data":{"timestamp":1734114579268,"type":"change","change_id":15557284118,"instrument_name":"ETH-PERPETUAL","bids":[],"asks":[["change",3896.4,2.0e5]],"prev_change_id":15557284117}}}
{"jsonrpc":"2.0","method":"subscription","params":{"channel":"book.ETH-PERPETUAL.raw","data":{"timestamp":1734114579268,"type":"change","change_id":15557284118,"instrument_name":"ETH-PERPETUAL","bids":[],"asks":[["change",3896.4,2.0e5]],"prev_change_id":15557284117}}}
{"jsonrpc":"2.0","method":"subscription","params":{"channel":"book.ETH-PERPETUAL.raw","data":{"timestamp":1734114579269,"type":"change","change_id":15557284119,"instrument_name":"ETH-PERPETUAL","bids":[["change",3881.35,183870.0]],"asks":[],"prev_change_id":15557284118}}}
{"jsonrpc":"2.0","method":"subscription","params":{"channel":"book.ETH-PERPETUAL.raw","data":{"timestamp":1734114579269,"type":"change","change_id":15557284119,"instrument_name":"ETH-PERPETUAL","bids":[["change",3881.35,183870.0]],"asks":[],"prev_change_id":15557284118}}}
{"jsonrpc":"2.0","method":"subscription","params":{"channel":"book.ETH-PERPETUAL.raw","data":{"timestamp":1734114579404,"type":"change","change_id":15557284120,"instrument_name":"ETH-PERPETUAL","bids":[["change",3881.35,3870.0]],"asks":[["delete",3896.4,0.0]],"prev_change_id":15557284119}}}
{"jsonrpc":"2.0","method":"subscription","params":{"channel":"book.ETH-PERPETUAL.raw","data":{"timestamp":1734114579404,"type":"change","change_id":15557284120,"instrument_name":"ETH-PERPETUAL","bids":[["change",3881.35,3870.0]],"asks":[["delete",3896.4,0.0]],"prev_change_id":15557284119}}}
{"jsonrpc":"2.0","method":"subscription","params":{"channel":"book.ETH-PERPETUAL.raw","data":{"timestamp":1734114579591,"type":"change","change_id":15557284121,"instrument_name":"ETH-PERPETUAL","bids":[],"asks":[["new",3896.45,8.0e4]],"prev_change_id":15557284120}}}
{"jsonrpc":"2.0","method":"subscription","params":{"channel":"book.ETH-PERPETUAL.raw","data":{"timestamp":1734114579591,"type":"change","change_id":15557284121,"instrument_name":"ETH-PERPETUAL","bids":[],"asks":[["new",3896.45,8.0e4]],"prev_change_id":15557284120}}}
{"jsonrpc":"2.0","method":"subscription","params":{"channel":"book.ETH-PERPETUAL.raw","data":{"timestamp":1734114579593,"type":"change","change_id":15557284122,"instrument_name":"ETH-PERPETUAL","bids":[["new",3881.4,8.0e4]],"asks":[],"prev_change_id":15557284121}}}
{"jsonrpc":"2.0","method":"subscription","params":{"channel":"book.ETH-PERPETUAL.raw","data":{"timestamp":1734114579593,"type":"change","change_id":15557284122,"instrument_name":"ETH-PERPETUAL","bids":[["new",3881.4,8.0e4]],"asks":[],"prev_change_id":15557284121}}}
{"jsonrpc":"2.0","method":"subscription","params":{"channel":"book.ETH-PERPETUAL.raw","data":{"timestamp":1734114579594,"type":"change","change_id":15557284123,"instrument_name":"ETH-PERPETUAL","bids":[["change",3881.4,1.0e5]],"asks":[],"prev_change_id":15557284122}}}
{"jsonrpc":"2.0","method":"subscription","params":{"channel":"book.ETH-PERPETUAL.raw","data":{"timestamp":1734114579594,"type":"change","change_id":15557284123,"instrument_name":"ETH-PERPETUAL","bids":[["change",3881.4,1.0e5]],"asks":[],"prev_change_id":15557284122}}}
{"jsonrpc":"2.0","method":"subscription","params":{"channel":"book.ETH-PERPETUAL.raw","data":{"timestamp":1734114579599,"type":"change","change_id":15557284124,"instrument_name":"ETH-PERPETUAL","bids":[],"asks":[["change",3896.45,1.6e5]],"prev_change_id":15557284123}}}
{"jsonrpc":"2.0","method":"subscription","params":{"channel":"book.ETH-PERPETUAL.raw","data":{"timestamp":1734114579599,"type":"change","change_id":15557284124,"instrument_name":"ETH-PERPETUAL","bids":[],"asks":[["change",3896.45,1.6e5]],"prev_change_id":15557284123}}}
{"jsonrpc":"2.0","method":"subscription","params":{"channel":"book.ETH-PERPETUAL.raw","data":{"timestamp":1734114579600,"type":"change","change_id":15557284125,"instrument_name":"ETH-PERPETUAL","bids":[["change",3881.4,1.8e5]],"asks":[],"prev_change_id":15557284124}}}
{"jsonrpc":"2.0","method":"subscription","params":{"channel":"book.ETH-PERPETUAL.raw","data":{"timestamp":1734114579600,"type":"change","change_id":15557284125,"instrument_name":"ETH-PERPETUAL","bids":[["change",3881.4,1.8e5]],"asks":[],"prev_change_id":15557284124}}}
{"jsonrpc":"2.0","method":"subscription","params":{"channel":"book.ETH-PERPETUAL.raw","data":{"timestamp":1734114579601,"type":"change","change_id":15557284126,"instrument_name":"ETH-PERPETUAL","bids":[["change",3881.4,2.0e5]],"asks":[],"prev_change_id":15557284125}}}
{"jsonrpc":"2.0","method":"subscription","params":{"channel":"book.ETH-PERPETUAL.raw","data":{"timestamp":1734114579601,"type":"change","change_id":15557284126,"instrument_name":"ETH-PERPETUAL","bids":[["change",3881.4,2.0e5]],"asks":[],"prev_change_id":15557284125}}}
{"jsonrpc":"2.0","method":"subscription","params":{"channel":"book.ETH-PERPETUAL.raw","data":{"timestamp":1734114579684,"type":"change","change_id":15557284128,"instrument_name":"ETH-PERPETUAL","bids":[["delete",3881.4,0.0]],"asks":[["delete",3896.45,0.0]],"prev_change_id":15557284126}}}
{"jsonrpc":"2.0","method":"subscription","params":{"channel":"book.ETH-PERPETUAL.raw","data":{"timestamp":1734114579684,"type":"change","change_id":15557284128,"instrument_name":"ETH-PERPETUAL","bids":[["delete",3881.4,0.0]],"asks":[["delete",3896.45,0.0]],"prev_change_id":15557284126}}}
{"jsonrpc":"2.0","method":"subscription","params":{"channel":"book.ETH-PERPETUAL.raw","data":{"timestamp":1734114579859,"type":"change","change_id":15557284135,"instrument_name":"ETH-PERPETUAL","bids":[["new",3881.4,8.0e4]],"asks":[],"prev_change_id":15557284128}}}
{"jsonrpc":"2.0","method":"subscription","params":{"channel":"book.ETH-PERPETUAL.raw","data":{"timestamp":1734114579859,"type":"change","change_id":15557284135,"instrument_name":"ETH-PERPETUAL","bids":[["new",3881.4,8.0e4]],"asks":[],"prev_change_id":15557284128}}}
{"jsonrpc":"2.0","method":"subscription","params":{"channel":"book.ETH-PERPETUAL.raw","data":{"timestamp":1734114579861,"type":"change","change_id":15557284137,"instrument_name":"ETH-PERPETUAL","bids":[],"asks":[["new",3896.45,8.0e4]],"prev_change_id":15557284135}}}
{"jsonrpc":"2.0","method":"subscription","params":{"channel":"book.ETH-PERPETUAL.raw","data":{"timestamp":1734114579861,"type":"change","change_id":15557284137,"instrument_name":"ETH-PERPETUAL","bids":[],"asks":[["new",3896.45,8.0e4]],"prev_change_id":15557284135}}}
{"jsonrpc":"2.0","method":"subscription","params":{"channel":"book.ETH-PERPETUAL.raw","data":{"timestamp":1734114579867,"type":"change","change_id":15557284139,"instrument_name":"ETH-PERPETUAL","bids":[["change",3881.4,1.6e5]],"asks":[],"prev_change_id":15557284137}}}
{"jsonrpc":"2.0","method":"subscription","params":{"channel":"book.ETH-PERPETUAL.raw","data":{"timestamp":1734114579867,"type":"change","change_id":15557284139,"instrument_name":"ETH-PERPETUAL","bids":[["change",3881.4,1.6e5]],"asks":[],"prev_change_id":15557284137}}}
{"jsonrpc":"2.0","method":"subscription","params":{"channel":"book.ETH-PERPETUAL.raw","data":{"timestamp":1734114579868,"type":"change","change_id":15557284140,"instrument_name":"ETH-PERPETUAL","bids":[],"asks":[["change",3896.45,1.6e5]],"prev_change_id":15557284139}}}
{"jsonrpc":"2.0","method":"subscription","params":{"channel":"book.ETH-PERPETUAL.raw","data":{"timestamp":1734114579868,"type":"change","change_id":15557284140,"instrument_name":"ETH-PERPETUAL","bids":[],"asks":[["change",3896.45,1.6e5]],"prev_change_id":15557284139}}}
{"jsonrpc":"2.0","method":"subscription","params":{"channel":"book.ETH-PERPETUAL.raw","data":{"timestamp":1734114579869,"type":"change","change_id":15557284141,"instrument_name":"ETH-PERPETUAL","bids":[["change",3881.4,1.8e5]],"asks":[],"prev_change_id":15557284140}}}
{"jsonrpc":"2.0","method":"subscription","params":{"channel":"book.ETH-PERPETUAL.raw","data":{"timestamp":1734114579869,"type":"change","change_id":15557284141,"instrument_name":"ETH-PERPETUAL","bids":[["change",3881.4,1.8e5]],"asks":[],"prev_change_id":15557284140}}}
{"jsonrpc":"2.0","method":"subscription","params":{"channel":"book.ETH-PERPETUAL.raw","data":{"timestamp":1734114579945,"type":"change","change_id":15557284143,"instrument_name":"ETH-PERPETUAL","bids":[["delete",3881.4,0.0]],"asks":[["delete",3896.45,0.0]],"prev_change_id":15557284141}}}
{"jsonrpc":"2.0","method":"subscription","params":{"channel":"book.ETH-PERPETUAL.raw","data":{"timestamp":1734114579945,"type":"change","change_id":15557284143,"instrument_name":"ETH-PERPETUAL","bids":[["delete",3881.4,0.0]],"asks":[["delete",3896.45,0.0]],"prev_change_id":15557284141}}}
{"jsonrpc":"2.0","method":"subscription","params":{"channel":"book.ETH-PERPETUAL.raw","data":{"timestamp":1734114580009,"type":"change","change_id":15557284144,"instrument_name":"ETH-PERPETUAL","bids":[["new",3842.55,700.0],["delete",3831.1,0.0]],"asks":[],"prev_change_id":15557284143}}}
{"jsonrpc":"2.0","method":"subscription","params":{"channel":"book.ETH-PERPETUAL.raw","data":{"timestamp":1734114580009,"type":"change","change_id":15557284144,"instrument_name":"ETH-PERPETUAL","bids":[["new",3842.55,700.0],["delete",3831.1,0.0]],"asks":[],"prev_change_id":15557284143}}}
{"jsonrpc":"2.0","method":"subscription","params":{"channel":"book.ETH-PERPETUAL.raw","data":{"timestamp":1734114580011,"type":"change","change_id":15557284145,"instrument_name":"ETH-PERPETUAL","bids":[["new",3861.95,500.0],["delete",3850.45,0.0]],"asks":[],"prev_change_id":15557284144}}}
{"jsonrpc":"2.0","method":"subscription","params":{"channel":"book.ETH-PERPETUAL.raw","data":{"timestamp":1734114580011,"type":"change","change_id":15557284145,"instrument_name":"ETH-PERPETUAL","bids":[["new",3861.95,500.0],["delete",3850.45,0.0]],"asks":[],"prev_change_id":15557284144}}}
{"jsonrpc":"2.0","method":"subscription","params":{"channel":"book.ETH-PERPETUAL.raw","data":{"timestamp":1734114580144,"type":"change","change_id":15557284147,"instrument_name":"ETH-PERPETUAL","bids":[["new",3881.4,8.0e4]],"asks":[],"prev_change_id":15557284145}}}
{"jsonrpc":"2.0","method":"subscription","params":{"channel":"book.ETH-PERPETUAL.raw","data":{"timestamp":1734114580144,"type":"change","change_id":15557284147,"instrument_name":"ETH-PERPETUAL","bids":[["new",3881.4,8.0e4]],"asks":[],"prev_change_id":15557284145}}}
{"jsonrpc":"2.0","method":"subscription","params":{"channel":"book.ETH-PERPETUAL.raw","data":{"timestamp":1734114580146,"type":"change","change_id":15557284148,"instrument_name":"ETH-PERPETUAL","bids":[],"asks":[["new",3896.45,8.0e4]],"prev_change_id":15557284147}}}
{"jsonrpc":"2.0","method":"subscription","params":{"channel":"book.ETH-PERPETUAL.raw","data":{"timestamp":1734114580146,"type":"change","change_id":15557284148,"instrument_name":"ETH-PERPETUAL","bids":[],"asks":[["new",3896.45,8.0e4]],"prev_change_id":15557284147}}}
{"jsonrpc":"2.0","method":"subscription","params":{"channel":"book.ETH-PERPETUAL.raw","data":{"timestamp":1734114580150,"type":"change","change_id":15557284149,"instrument_name":"ETH-PERPETUAL","bids":[["change",3881.4,1.0e5]],"asks":[],"prev_change_id":15557284148}}}
{"jsonrpc":"2.0","method":"subscription","params":{"channel":"book.ETH-PERPETUAL.raw","data":{"timestamp":1734114580150,"type":"change","change_id":15557284149,"instrument_name":"ETH-PERPETUAL","bids":[["change",3881.4,1.0e5]],"asks":[],"prev_change_id":15557284148}}}
{"jsonrpc":"2.0","method":"subscription","params":{"channel":"book.ETH-PERPETUAL.raw","data":{"timestamp":1734114580151,"type":"change","change_id":15557284150,"instrument_name":"ETH-PERPETUAL","bids":[["change",3881.4,1.8e5]],"asks":[],"prev_change_id":15557284149}}}
{"jsonrpc":"2.0","method":"subscription","params":{"channel":"book.ETH-PERPETUAL.raw","data":{"timestamp":1734114580151,"type":"change","change_id":15557284150,"instrument_name":"ETH-PERPETUAL","bids":[["change",3881.4,1.8e5]],"asks":[],"prev_change_id":15557284149}}}
{"jsonrpc":"2.0","method":"subscription","params":{"channel":"book.ETH-PERPETUAL.raw","data":{"timestamp":1734114580152,"type":"change","change_id":15557284151,"instrument_name":"ETH-PERPETUAL","bids":[],"asks":[["change",3896.45,1.6e5]],"prev_change_id":15557284150}}}
{"jsonrpc":"2.0","method":"subscription","params":{"channel":"book.ETH-PERPETUAL.raw","data":{"timestamp":1734114580152,"type":"change","change_id":15557284151,"instrument_name":"ETH-PERPETUAL","bids":[],"asks":[["change",3896.45,1.6e5]],"prev_change_id":15557284150}}}
{"jsonrpc":"2.0","method":"subscription","params":{"channel":"book.ETH-PERPETUAL.raw","data":{"timestamp":1734114580154,"type":"change","change_id":15557284152,"instrument_name":"ETH-PERPETUAL","bids":[["change",3881.4,2.0e5]],"asks":[],"prev_change_id":15557284151}}}
{"jsonrpc":"2.0","method":"subscription","params":{"channel":"book.ETH-PERPETUAL.raw","data":{"timestamp":1734114580154,"type":"change","change_id":15557284152,"instrument_name":"ETH-PERPETUAL","bids":[["change",3881.4,2.0e5]],"asks":[],"prev_change_id":15557284151}}}
{"jsonrpc":"2.0","method":"subscription","params":{"channel":"book.ETH-PERPETUAL.raw","data":{"timestamp":1734114580244,"type":"change","change_id":15557284153,"instrument_name":"ETH-PERPETUAL","bids":[["delete",3881.4,0.0]],"asks":[["delete",3896.45,0.0]],"prev_change_id":15557284152}}}
{"jsonrpc":"2.0","method":"subscription","params":{"channel":"book.ETH-PERPETUAL.raw","data":{"timestamp":1734114580244,"type":"change","change_id":15557284153,"instrument_name":"ETH-PERPETUAL","bids":[["delete",3881.4,0.0]],"asks":[["delete",3896.45,0.0]],"prev_change_id":15557284152}}}
{"jsonrpc":"2.0","method":"subscription","params":{"channel":"book.ETH-PERPETUAL.raw","data":{"timestamp":1734114580537,"type":"change","change_id":15557284154,"instrument_name":"ETH-PERPETUAL","bids":[["new",3881.4,8.0e4]],"asks":[],"prev_change_id":15557284153}}}
{"jsonrpc":"2.0","method":"subscription","params":{"channel":"book.ETH-PERPETUAL.raw","data":{"timestamp":1734114580537,"type":"change","change_id":15557284154,"instrument_name":"ETH-PERPETUAL","bids":[["new",3881.4,8.0e4]],"asks":[],"prev_change_id":15557284153}}}
{"jsonrpc":"2.0","method":"subscription","params":{"channel":"book.ETH-PERPETUAL.raw","data":{"timestamp":1734114580540,"type":"change","change_id":15557284155,"instrument_name":"ETH-PERPETUAL","bids":[],"asks":[["new",3896.45,8.0e4]],"prev_change_id":15557284154}}}
{"jsonrpc":"2.0","method":"subscription","params":{"channel":"book.ETH-PERPETUAL.raw","data":{"timestamp":1734114580540,"type":"change","change_id":15557284155,"instrument_name":"ETH-PERPETUAL","bids":[],"asks":[["new",3896.45,8.0e4]],"prev_change_id":15557284154}}}
{"jsonrpc":"2.0","method":"subscription","params":{"channel":"book.ETH-PERPETUAL.raw","data":{"timestamp":1734114580543,"type":"change","change_id":15557284156,"instrument_name":"ETH-PERPETUAL","bids":[["change",3881.4,1.0e5]],"asks":[],"prev_change_id":15557284155}}}
{"jsonrpc":"2.0","method":"subscription","params":{"channel":"book.ETH-PERPETUAL.raw","data":{"timestamp":1734114580543,"type":"change","change_id":15557284156,"instrument_name":"ETH-PERPETUAL","bids":[["change",3881.4,1.0e5]],"asks":[],"prev_change_id":15557284155}}}
{"jsonrpc":"2.0","method":"subscription","params":{"channel":"book.ETH-PERPETUAL.raw","data":{"timestamp":1734114580546,"type":"change","change_id":15557284157,"instrument_name":"ETH-PERPETUAL","bids":[],"asks":[["change",3896.45,1.0e5]],"prev_change_id":15557284156}}}
{"jsonrpc":"2.0","method":"subscription","params":{"channel":"book.ETH-PERPETUAL.raw","data":{"timestamp":1734114580546,"type":"change","change_id":15557284157,"instrument_name":"ETH-PERPETUAL","bids":[],"asks":[["change",3896.45,1.0e5]],"prev_change_id":15557284156}}}
{"jsonrpc":"2.0","method":"subscription","params":{"channel":"book.ETH-PERPETUAL.raw","data":{"timestamp":1734114580549,"type":"change","change_id":15557284158,"instrument_name":"ETH-PERPETUAL","bids":[["change",3881.4,1.8e5]],"asks":[],"prev_change_id":15557284157}}}
{"jsonrpc":"2.0","method":"subscription","params":{"channel":"book.ETH-PERPETUAL.raw","data":{"timestamp":1734114580549,"type":"change","change_id":15557284158,"instrument_name":"ETH-PERPETUAL","bids":[["change",3881.4,1.8e5]],"asks":[],"prev_change_id":15557284157}}}
{"jsonrpc":"2.0","method":"subscription","params":{"channel":"book.ETH-PERPETUAL.raw","data":{"timestamp":1734114580552,"type":"change","change_id":15557284159,"instrument_name":"ETH-PERPETUAL","bids":[],"asks":[["change",3896.45,1.8e5]],"prev_change_id":15557284158}}}
{"jsonrpc":"2.0","method":"subscription","params":{"channel":"book.ETH-PERPETUAL.raw","data":{"timestamp":1734114580552,"type":"change","change_id":15557284159,"instrument_name":"ETH-PERPETUAL","bids":[],"asks":[["change",3896.45,1.8e5]],"prev_change_id":15557284158}}}
{"jsonrpc":"2.0","method":"subscription","params":{"channel":"book.ETH-PERPETUAL.raw","data":{"timestamp":1734114580555,"type":"change","change_id":15557284160,"instrument_name":"ETH-PERPETUAL","bids":[["change",3881.4,2.0e5]],"asks":[],"prev_change_id":15557284159}}}
{"jsonrpc":"2.0","method":"subscription","params":{"channel":"book.ETH-PERPETUAL.raw","data":{"timestamp":1734114580555,"type":"change","change_id":15557284160,"instrument_name":"ETH-PERPETUAL","bids":[["change",3881.4,2.0e5]],"asks":[],"prev_change_id":15557284159}}}
{"jsonrpc":"2.0","method":"subscription","params":{"channel":"book.ETH-PERPETUAL.raw","data":{"timestamp":1734114580560,"type":"change","change_id":15557284161,"instrument_name":"ETH-PERPETUAL","bids":[],"asks":[["change",3896.45,2.0e5]],"prev_change_id":15557284160}}}
{"jsonrpc":"2.0","method":"subscription","params":{"channel":"book.ETH-PERPETUAL.raw","data":{"timestamp":1734114580560,"type":"change","change_id":15557284161,"instrument_name":"ETH-PERPETUAL","bids":[],"asks":[["change",3896.45,2.0e5]],"prev_change_id":15557284160}}}
{"jsonrpc":"2.0","method":"subscription","params":{"channel":"book.ETH-PERPETUAL.raw","data":{"timestamp":1734114580679,"type":"change","change_id":15557284163,"instrument_name":"ETH-PERPETUAL","bids":[["delete",3881.4,0.0]],"asks":[["delete",3896.45,0.0]],"prev_change_id":15557284161}}}
{"jsonrpc":"2.0","method":"subscription","params":{"channel":"book.ETH-PERPETUAL.raw","data":{"timestamp":1734114580679,"type":"change","change_id":15557284163,"instrument_name":"ETH-PERPETUAL","bids":[["delete",3881.4,0.0]],"asks":[["delete",3896.45,0.0]],"prev_change_id":15557284161}}}
{"jsonrpc":"2.0","method":"subscription","params":{"channel":"book.ETH-PERPETUAL.raw","data":{"timestamp":1734114580919,"type":"change","change_id":15557284165,"instrument_name":"ETH-PERPETUAL","bids":[["new",3881.4,8.0e4]],"asks":[],"prev_change_id":15557284163}}}
{"jsonrpc":"2.0","method":"subscription","params":{"channel":"book.ETH-PERPETUAL.raw","data":{"timestamp":1734114580919,"type":"change","change_id":15557284165,"instrument_name":"ETH-PERPETUAL","bids":[["new",3881.4,8.0e4]],"asks":[],"prev_change_id":15557284163}}}
{"jsonrpc":"2.0","method":"subscription","params":{"channel":"book.ETH-PERPETUAL.raw","data":{"timestamp":1734114580921,"type":"change","change_id":15557284166,"instrument_name":"ETH-PERPETUAL","bids":[],"asks":[["new",3896.45,8.0e4]],"prev_change_id":15557284165}}}
{"jsonrpc":"2.0","method":"subscription","params":{"channel":"book.ETH-PERPETUAL.raw","data":{"timestamp":1734114580921,"type":"change","change_id":15557284166,"instrument_name":"ETH-PERPETUAL","bids":[],"asks":[["new",3896.45,8.0e4]],"prev_change_id":15557284165}}}
{"jsonrpc":"2.0","method":"subscription","params":{"channel":"book.ETH-PERPETUAL.raw","data":{"timestamp":1734114580924,"type":"change","change_id":15557284167,"instrument_name":"ETH-PERPETUAL","bids":[["change",3881.4,1.0e5]],"asks":[],"prev_change_id":15557284166}}}
{"jsonrpc":"2.0","method":"subscription","params":{"channel":"book.ETH-PERPETUAL.raw","data":{"timestamp":1734114580924,"type":"change","change_id":15557284167,"instrument_name":"ETH-PERPETUAL","bids":[["change",3881.4,1.0e5]],"asks":[],"prev_change_id":15557284166}}}
{"jsonrpc":"2.0","method":"subscription","params":{"channel":"book.ETH-PERPETUAL.raw","data":{"timestamp":1734114580927,"type":"change","change_id":15557284168,"instrument_name":"ETH-PERPETUAL","bids":[],"asks":[["change",3896.45,1.0e5]],"prev_change_id":15557284167}}}
{"jsonrpc":"2.0","method":"subscription","params":{"channel":"book.ETH-PERPETUAL.raw","data":{"timestamp":1734114580927,"type":"change","change_id":15557284168,"instrument_name":"ETH-PERPETUAL","bids":[],"asks":[["change",3896.45,1.0e5]],"prev_change_id":15557284167}}}
{"jsonrpc":"2.0","method":"subscription","params":{"channel":"book.ETH-PERPETUAL.raw","data":{"timestamp":1734114580929,"type":"change","change_id":15557284169,"instrument_name":"ETH-PERPETUAL","bids":[["change",3881.4,1.8e5]],"asks":[],"prev_change_id":15557284168}}}
{"jsonrpc":"2.0","method":"subscription","params":{"channel":"book.ETH-PERPETUAL.raw","data":{"timestamp":1734114580929,"type":"change","change_id":15557284169,"instrument_name":"ETH-PERPETUAL","bids":[["change",3881.4,1.8e5]],"asks":[],"prev_change_id":15557284168}}}
{"jsonrpc":"2.0","method":"subscription","params":{"channel":"book.ETH-PERPETUAL.raw","data":{"timestamp":1734114580931,"type":"change","change_id":15557284170,"instrument_name":"ETH-PERPETUAL","bids":[],"asks":[["change",3896.45,1.8e5]],"prev_change_id":15557284169}}}
{"jsonrpc":"2.0","method":"subscription","params":{"channel":"book.ETH-PERPETUAL.raw","data":{"timestamp":1734114580931,"type":"change","change_id":15557284170,"instrument_name":"ETH-PERPETUAL","bids":[],"asks":[["change",3896.45,1.8e5]],"prev_change_id":15557284169}}}
{"jsonrpc":"2.0","method":"subscription","params":{"channel":"book.ETH-PERPETUAL.raw","data":{"timestamp":1734114580933,"type":"change","change_id":15557284171,"instrument_name":"ETH-PERPETUAL","bids":[["change",3881.4,2.0e5]],"asks":[],"prev_change_id":15557284170}}}
{"jsonrpc":"2.0","method":"subscription","params":{"channel":"book.ETH-PERPETUAL.raw","data":{"timestamp":1734114580933,"type":"change","change_id":15557284171,"instrument_name":"ETH-PERPETUAL","bids":[["change",3881.4,2.0e5]],"asks":[],"prev_change_id":15557284170}}}
{"jsonrpc":"2.0","method":"subscription","params":{"channel":"book.ETH-PERPETUAL.raw","data":{"timestamp":1734114580936,"type":"change","change_id":15557284172,"instrument_name":"ETH-PERPETUAL","bids":[],"asks":[["change",3896.45,2.0e5]],"prev_change_id":15557284171}}}
{"jsonrpc":"2.0","method":"subscription","params":{"channel":"book.ETH-PERPETUAL.raw","data":{"timestamp":1734114580936,"type":"change","change_id":15557284172,"instrument_name":"ETH-PERPETUAL","bids":[],"asks":[["change",3896.45,2.0e5]],"prev_change_id":15557284171}}}
{"jsonrpc":"2.0","method":"subscription","params":{"channel":"book.ETH-PERPETUAL.raw","data":{"timestamp":1734114581059,"type":"change","change_id":15557284173,"instrument_name":"ETH-PERPETUAL","bids":[["delete",3881.4,0.0]],"asks":[["delete",3896.45,0.0]],"prev_change_id":15557284172}}}
{"jsonrpc":"2.0","method":"subscription","params":{"channel":"book.ETH-PERPETUAL.raw","data":{"timestamp":1734114581059,"type":"change","change_id":15557284173,"instrument_name":"ETH-PERPETUAL","bids":[["delete",3881.4,0.0]],"asks":[["delete",3896.45,0.0]],"prev_change_id":15557284172}}}
{"jsonrpc":"2.0","method":"subscription","params":{"channel":"book.ETH-PERPETUAL.raw","data":{"timestamp":1734114581243,"type":"change","change_id":15557284174,"instrument_name":"ETH-PERPETUAL","bids":[["new",3881.4,8.0e4]],"asks":[],"prev_change_id":15557284173}}}
{"jsonrpc":"2.0","method":"subscription","params":{"channel":"book.ETH-PERPETUAL.raw","data":{"timestamp":1734114581243,"type":"change","change_id":15557284174,"instrument_name":"ETH-PERPETUAL","bids":[["new",3881.4,8.0e4]],"asks":[],"prev_change_id":15557284173}}}
{"jsonrpc":"2.0","method":"subscription","params":{"channel":"book.ETH-PERPETUAL.raw","data":{"timestamp":1734114581245,"type":"change","change_id":15557284175,"instrument_name":"ETH-PERPETUAL","bids":[],"asks":[["new",3896.4,8.0e4]],"prev_change_id":15557284174}}}
{"jsonrpc":"2.0","method":"subscription","params":{"channel":"book.ETH-PERPETUAL.raw","data":{"timestamp":1734114581245,"type":"change","change_id":15557284175,"instrument_name":"ETH-PERPETUAL","bids":[],"asks":[["new",3896.4,8.0e4]],"prev_change_id":15557284174}}}
{"jsonrpc":"2.0","method":"subscription","params":{"channel":"book.ETH-PERPETUAL.raw","data":{"timestamp":1734114581247,"type":"change","change_id":15557284176,"instrument_name":"ETH-PERPETUAL","bids":[["change",3881.4,1.0e5]],"asks":[],"prev_change_id":15557284175}}}
{"jsonrpc":"2.0","method":"subscription","params":{"channel":"book.ETH-PERPETUAL.raw","data":{"timestamp":1734114581247,"type":"change","change_id":15557284176,"instrument_name":"ETH-PERPETUAL","bids":[["change",3881.4,1.0e5]],"asks":[],"prev_change_id":15557284175}}}
{"jsonrpc":"2.0","method":"subscription","params":{"channel":"book.ETH-PERPETUAL.raw","data":{"timestamp":1734114581248,"type":"change","change_id":15557284177,"instrument_name":"ETH-PERPETUAL","bids":[],"asks":[["change",3896.4,1.0e5]],"prev_change_id":15557284176}}}
{"jsonrpc":"2.0","method":"subscription","params":{"channel":"book.ETH-PERPETUAL.raw","data":{"timestamp":1734114581248,"type":"change","change_id":15557284177,"instrument_name":"ETH-PERPETUAL","bids":[],"asks":[["change",3896.4,1.0e5]],"prev_change_id":15557284176}}}
{"jsonrpc":"2.0","method":"subscription","params":{"channel":"book.ETH-PERPETUAL.raw","data":{"timestamp":1734114581250,"type":"change","change_id":15557284178,"instrument_name":"ETH-PERPETUAL","bids":[["change",3881.4,1.8e5]],"asks":[],"prev_change_id":15557284177}}}
{"jsonrpc":"2.0","method":"subscription","params":{"channel":"book.ETH-PERPETUAL.raw","data":{"timestamp":1734114581250,"type":"change","change_id":15557284178,"instrument_name":"ETH-PERPETUAL","bids":[["change",3881.4,1.8e5]],"asks":[],"prev_change_id":15557284177}}}
{"jsonrpc":"2.0","method":"subscription","params":{"channel":"book.ETH-PERPETUAL.raw","data":{"timestamp":1734114581251,"type":"change","change_id":15557284179,"instrument_name":"ETH-PERPETUAL","bids":[],"asks":[["change",3896.4,1.8e5]],"prev_change_id":15557284178}}}
{"jsonrpc":"2.0","method":"subscription","params":{"channel":"book.ETH-PERPETUAL.raw","data":{"timestamp":1734114581251,"type":"change","change_id":15557284179,"instrument_name":"ETH-PERPETUAL","bids":[],"asks":[["change",3896.4,1.8e5]],"prev_change_id":15557284178}}}
{"jsonrpc":"2.0","method":"subscription","params":{"channel":"book.ETH-PERPETUAL.raw","data":{"timestamp":1734114581253,"type":"change","change_id":15557284180,"instrument_name":"ETH-PERPETUAL","bids":[["change",3881.4,2.0e5]],"asks":[],"prev_change_id":15557284179}}}
{"jsonrpc":"2.0","method":"subscription","params":{"channel":"book.ETH-PERPETUAL.raw","data":{"timestamp":1734114581253,"type":"change","change_id":15557284180,"instrument_name":"ETH-PERPETUAL","bids":[["change",3881.4,2.0e5]],"asks":[],"prev_change_id":15557284179}}}
{"jsonrpc":"2.0","method":"subscription","params":{"channel":"book.ETH-PERPETUAL.raw","data":{"timestamp":1734114581254,"type":"change","change_id":15557284181,"instrument_name":"ETH-PERPETUAL","bids":[],"asks":[["change",3896.4,2.0e5]],"prev_change_id":15557284180}}}
{"jsonrpc":"2.0","method":"subscription","params":{"channel":"book.ETH-PERPETUAL.raw","data":{"timestamp":1734114581254,"type":"change","change_id":15557284181,"instrument_name":"ETH-PERPETUAL","bids":[],"asks":[["change",3896.4,2.0e5]],"prev_change_id":15557284180}}}
{"jsonrpc":"2.0","method":"subscription","params":{"channel":"book.ETH-PERPETUAL.raw","data":{"timestamp":1734114581334,"type":"change","change_id":15557284182,"instrument_name":"ETH-PERPETUAL","bids":[["delete",3881.4,0.0]],"asks":[["delete",3896.4,0.0]],"prev_change_id":15557284181}}}
{"jsonrpc":"2.0","method":"subscription","params":{"channel":"book.ETH-PERPETUAL.raw","data":{"timestamp":1734114581334,"type":"change","change_id":15557284182,"instrument_name":"ETH-PERPETUAL","bids":[["delete",3881.4,0.0]],"asks":[["delete",3896.4,0.0]],"prev_change_id":15557284181}}}
{"jsonrpc":"2.0","method":"subscription","params":{"channel":"book.ETH-PERPETUAL.raw","data":{"timestamp":1734114581507,"type":"change","change_id":15557284183,"instrument_name":"ETH-PERPETUAL","bids":[["new",3881.4,8.0e4]],"asks":[],"prev_change_id":15557284182}}}
{"jsonrpc":"2.0","method":"subscription","params":{"channel":"book.ETH-PERPETUAL.raw","data":{"timestamp":1734114581507,"type":"change","change_id":15557284183,"instrument_name":"ETH-PERPETUAL","bids":[["new",3881.4,8.0e4]],"asks":[],"prev_change_id":15557284182}}}
{"jsonrpc":"2.0","method":"subscription","params":{"channel":"book.ETH-PERPETUAL.raw","data":{"timestamp":1734114581508,"type":"change","change_id":15557284184,"instrument_name":"ETH-PERPETUAL","bids":[],"asks":[["new",3896.4,8.0e4]],"prev_change_id":15557284183}}}
{"jsonrpc":"2.0","method":"subscription","params":{"channel":"book.ETH-PERPETUAL.raw","data":{"timestamp":1734114581508,"type":"change","change_id":15557284184,"instrument_name":"ETH-PERPETUAL","bids":[],"asks":[["new",3896.4,8.0e4]],"prev_change_id":15557284183}}}
{"jsonrpc":"2.0","method":"subscription","params":{"channel":"book.ETH-PERPETUAL.raw","data":{"timestamp":1734114581510,"type":"change","change_id":15557284185,"instrument_name":"ETH-PERPETUAL","bids":[["change",3881.4,1.6e5]],"asks":[],"prev_change_id":15557284184}}}
{"jsonrpc":"2.0","method":"subscription","params":{"channel":"book.ETH-PERPETUAL.raw","data":{"timestamp":1734114581510,"type":"change","change_id":15557284185,"instrument_name":"ETH-PERPETUAL","bids":[["change",3881.4,1.6e5]],"asks":[],"prev_change_id":15557284184}}}
{"jsonrpc":"2.0","method":"subscription","params":{"channel":"book.ETH-PERPETUAL.raw","data":{"timestamp":1734114581512,"type":"change","change_id":15557284186,"instrument_name":"ETH-PERPETUAL","bids":[],"asks":[["change",3896.4,1.6e5]],"prev_change_id":15557284185}}}
{"jsonrpc":"2.0","method":"subscription","params":{"channel":"book.ETH-PERPETUAL.raw","data":{"timestamp":1734114581512,"type":"change","change_id":15557284186,"instrument_name":"ETH-PERPETUAL","bids":[],"asks":[["change",3896.4,1.6e5]],"prev_change_id":15557284185}}}
{"jsonrpc":"2.0","method":"subscription","params":{"channel":"book.ETH-PERPETUAL.raw","data":{"timestamp":1734114581654,"type":"change","change_id":15557284188,"instrument_name":"ETH-PERPETUAL","bids":[["delete",3881.4,0.0]],"asks":[["delete",3896.4,0.0]],"prev_change_id":15557284186}}}
{"jsonrpc":"2.0","method":"subscription","params":{"channel":"book.ETH-PERPETUAL.raw","data":{"timestamp":1734114581654,"type":"change","change_id":15557284188,"instrument_name":"ETH-PERPETUAL","bids":[["delete",3881.4,0.0]],"asks":[["delete",3896.4,0.0]],"prev_change_id":15557284186}}}
{"jsonrpc":"2.0","method":"subscription","params":{"channel":"book.ETH-PERPETUAL.raw","data":{"timestamp":1734114581657,"type":"change","change_id":15557284189,"instrument_name":"ETH-PERPETUAL","bids":[],"asks":[["new",3935.4,700.0],["delete",3947.8,0.0]],"prev_change_id":15557284188}}}
{"jsonrpc":"2.0","method":"subscription","params":{"channel":"book.ETH-PERPETUAL.raw","data":{"timestamp":1734114581657,"type":"change","change_id":15557284189,"instrument_name":"ETH-PERPETUAL","bids":[],"asks":[["new",3935.4,700.0],["delete",3947.8,0.0]],"prev_change_id":15557284188}}}
{"jsonrpc":"2.0","method":"subscription","params":{"channel":"book.ETH-PERPETUAL.raw","data":{"timestamp":1734114581848,"type":"change","change_id":15557284190,"instrument_name":"ETH-PERPETUAL","bids":[["new",3881.4,8.0e4]],"asks":[],"prev_change_id":15557284189}}}
{"jsonrpc":"2.0","method":"subscription","params":{"channel":"book.ETH-PERPETUAL.raw","data":{"timestamp":1734114581848,"type":"change","change_id":15557284190,"instrument_name":"ETH-PERPETUAL","bids":[["new",3881.4,8.0e4]],"asks":[],"prev_change_id":15557284189}}}
{"jsonrpc":"2.0","method":"subscription","params":{"channel":"book.ETH-PERPETUAL.raw","data":{"timestamp":1734114581850,"type":"change","change_id":15557284191,"instrument_name":"ETH-PERPETUAL","bids":[],"asks":[["new",3896.4,8.0e4]],"prev_change_id":15557284190}}}
{"jsonrpc":"2.0","method":"subscription","params":{"channel":"book.ETH-PERPETUAL.raw","data":{"timestamp":1734114581850,"type":"change","change_id":15557284191,"instrument_name":"ETH-PERPETUAL","bids":[],"asks":[["new",3896.4,8.0e4]],"prev_change_id":15557284190}}}
{"jsonrpc":"2.0","method":"subscription","params":{"channel":"book.ETH-PERPETUAL.raw","data":{"timestamp":1734114581851,"type":"change","change_id":15557284192,"instrument_name":"ETH-PERPETUAL","bids":[["change",3881.4,1.0e5]],"asks":[],"prev_change_id":15557284191}}}
{"jsonrpc":"2.0","method":"subscription","params":{"channel":"book.ETH-PERPETUAL.raw","data":{"timestamp":1734114581851,"type":"change","change_id":15557284192,"instrument_name":"ETH-PERPETUAL","bids":[["change",3881.4,1.0e5]],"asks":[],"prev_change_id":15557284191}}}
{"jsonrpc":"2.0","method":"subscription","params":{"channel":"book.ETH-PERPETUAL.raw","data":{"timestamp":1734114581853,"type":"change","change_id":15557284193,"instrument_name":"ETH-PERPETUAL","bids":[],"asks":[["change",3896.4,1.0e5]],"prev_change_id":15557284192}}}
{"jsonrpc":"2.0","method":"subscription","params":{"channel":"book.ETH-PERPETUAL.raw","data":{"timestamp":1734114581853,"type":"change","change_id":15557284193,"instrument_name":"ETH-PERPETUAL","bids":[],"asks":[["change",3896.4,1.0e5]],"prev_change_id":15557284192}}}
{"jsonrpc":"2.0","method":"subscription","params":{"channel":"book.ETH-PERPETUAL.raw","data":{"timestamp":1734114581855,"type":"change","change_id":15557284194,"instrument_name":"ETH-PERPETUAL","bids":[["change",3881.4,1.8e5]],"asks":[],"prev_change_id":15557284193}}}
{"jsonrpc":"2.0","method":"subscription","params":{"channel":"book.ETH-PERPETUAL.raw","data":{"timestamp":1734114581855,"type":"change","change_id":15557284194,"instrument_name":"ETH-PERPETUAL","bids":[["change",3881.4,1.8e5]],"asks":[],"prev_change_id":15557284193}}}
{"jsonrpc":"2.0","method":"subscription","params":{"channel":"book.ETH-PERPETUAL.raw","data":{"timestamp":1734114581856,"type":"change","change_id":15557284196,"instrument_name":"ETH-PERPETUAL","bids":[],"asks":[["change",3896.4,1.8e5]],"prev_change_id":15557284194}}}
{"jsonrpc":"2.0","method":"subscription","params":{"channel":"book.ETH-PERPETUAL.raw","data":{"timestamp":1734114581856,"type":"change","change_id":15557284196,"instrument_name":"ETH-PERPETUAL","bids":[],"asks":[["change",3896.4,1.8e5]],"prev_change_id":15557284194}}}
{"jsonrpc":"2.0","method":"subscription","params":{"channel":"book.ETH-PERPETUAL.raw","data":{"timestamp":1734114581857,"type":"change","change_id":15557284197,"instrument_name":"ETH-PERPETUAL","bids":[["change",3881.4,2.0e5]],"asks":[],"prev_change_id":15557284196}}}
{"jsonrpc":"2.0","method":"subscription","params":{"channel":"book.ETH-PERPETUAL.raw","data":{"timestamp":1734114581857,"type":"change","change_id":15557284197,"instrument_name":"ETH-PERPETUAL","bids":[["change",3881.4,2.0e5]],"asks":[],"prev_change_id":15557284196}}}
{"jsonrpc":"2.0","method":"subscription","params":{"channel":"book.ETH-PERPETUAL.raw","data":{"timestamp":1734114581859,"type":"change","change_id":15557284198,"instrument_name":"ETH-PERPETUAL","bids":[],"asks":[["change",3896.4,2.0e5]],"prev_change_id":15557284197}}}
{"jsonrpc":"2.0","method":"subscription","params":{"channel":"book.ETH-PERPETUAL.raw","data":{"timestamp":1734114581859,"type":"change","change_id":15557284198,"instrument_name":"ETH-PERPETUAL","bids":[],"asks":[["change",3896.4,2.0e5]],"prev_change_id":15557284197}}}
{"jsonrpc":"2.0","method":"subscription","params":{"channel":"book.ETH-PERPETUAL.raw","data":{"timestamp":1734114581938,"type":"change","change_id":15557284215,"instrument_name":"ETH-PERPETUAL","bids":[["delete",3881.4,0.0]],"asks":[["delete",3896.4,0.0]],"prev_change_id":15557284198}}}
{"jsonrpc":"2.0","method":"subscription","params":{"channel":"book.ETH-PERPETUAL.raw","data":{"timestamp":1734114581938,"type":"change","change_id":15557284215,"instrument_name":"ETH-PERPETUAL","bids":[["delete",3881.4,0.0]],"asks":[["delete",3896.4,0.0]],"prev_change_id":15557284198}}}
{"jsonrpc":"2.0","method":"subscription","params":{"channel":"book.ETH-PERPETUAL.raw","data":{"timestamp":1734114582118,"type":"change","change_id":15557284216,"instrument_name":"ETH-PERPETUAL","bids":[["new",3881.4,8.0e4]],"asks":[],"prev_change_id":15557284215}}}
{"jsonrpc":"2.0","method":"subscription","params":{"channel":"book.ETH-PERPETUAL.raw","data":{"timestamp":1734114582118,"type":"change","change_id":15557284216,"instrument_name":"ETH-PERPETUAL","bids":[["new",3881.4,8.0e4]],"asks":[],"prev_change_id":15557284215}}}
{"jsonrpc":"2.0","method":"subscription","params":{"channel":"book.ETH-PERPETUAL.raw","data":{"timestamp":1734114582120,"type":"change","change_id":15557284217,"instrument_name":"ETH-PERPETUAL","bids":[],"asks":[["new",3896.4,8.0e4]],"prev_change_id":15557284216}}}
{"jsonrpc":"2.0","method":"subscription","params":{"channel":"book.ETH-PERPETUAL.raw","data":{"timestamp":1734114582120,"type":"change","change_id":15557284217,"instrument_name":"ETH-PERPETUAL","bids":[],"asks":[["new",3896.4,8.0e4]],"prev_change_id":15557284216}}}
{"jsonrpc":"2.0","method":"subscription","params":{"channel":"book.ETH-PERPETUAL.raw","data":{"timestamp":1734114582121,"type":"change","change_id":15557284218,"instrument_name":"ETH-PERPETUAL","bids":[["change",3881.4,1.6e5]],"asks":[],"prev_change_id":15557284217}}}
{"jsonrpc":"2.0","method":"subscription","params":{"channel":"book.ETH-PERPETUAL.raw","data":{"timestamp":1734114582121,"type":"change","change_id":15557284218,"instrument_name":"ETH-PERPETUAL","bids":[["change",3881.4,1.6e5]],"asks":[],"prev_change_id":15557284217}}}
{"jsonrpc":"2.0","method":"subscription","params":{"channel":"book.ETH-PERPETUAL.raw","data":{"timestamp":1734114582122,"type":"change","change_id":15557284219,"instrument_name":"ETH-PERPETUAL","bids":[],"asks":[["change",3896.4,1.6e5]],"prev_change_id":15557284218}}}
{"jsonrpc":"2.0","method":"subscription","params":{"channel":"book.ETH-PERPETUAL.raw","data":{"timestamp":1734114582122,"type":"change","change_id":15557284219,"instrument_name":"ETH-PERPETUAL","bids":[],"asks":[["change",3896.4,1.6e5]],"prev_change_id":15557284218}}}
{"jsonrpc":"2.0","method":"subscription","params":{"channel":"book.ETH-PERPETUAL.raw","data":{"timestamp":1734114582211,"type":"change","change_id":15557284220,"instrument_name":"ETH-PERPETUAL","bids":[["delete",3881.4,0.0]],"asks":[["delete",3896.4,0.0]],"prev_change_id":15557284219}}}
{"jsonrpc":"2.0","method":"subscription","params":{"channel":"book.ETH-PERPETUAL.raw","data":{"timestamp":1734114582211,"type":"change","change_id":15557284220,"instrument_name":"ETH-PERPETUAL","bids":[["delete",3881.4,0.0]],"asks":[["delete",3896.4,0.0]],"prev_change_id":15557284219}}}
{"jsonrpc":"2.0","method":"subscription","params":{"channel":"book.ETH-PERPETUAL.raw","data":{"timestamp":1734114582402,"type":"change","change_id":15557284221,"instrument_name":"ETH-PERPETUAL","bids":[["new",3881.4,8.0e4]],"asks":[],"prev_change_id":15557284220}}}
{"jsonrpc":"2.0","method":"subscription","params":{"channel":"book.ETH-PERPETUAL.raw","data":{"timestamp":1734114582402,"type":"change","change_id":15557284221,"instrument_name":"ETH-PERPETUAL","bids":[["new",3881.4,8.0e4]],"asks":[],"prev_change_id":15557284220}}}
{"jsonrpc":"2.0","method":"subscription","params":{"channel":"book.ETH-PERPETUAL.raw","data":{"timestamp":1734114582405,"type":"change","change_id":15557284222,"instrument_name":"ETH-PERPETUAL","bids":[],"asks":[["new",3896.4,8.0e4]],"prev_change_id":15557284221}}}
{"jsonrpc":"2.0","method":"subscription","params":{"channel":"book.ETH-PERPETUAL.raw","data":{"timestamp":1734114582405,"type":"change","change_id":15557284222,"instrument_name":"ETH-PERPETUAL","bids":[],"asks":[["new",3896.4,8.0e4]],"prev_change_id":15557284221}}}
{"jsonrpc":"2.0","method":"subscription","params":{"channel":"book.ETH-PERPETUAL.raw","data":{"timestamp":1734114582406,"type":"change","change_id":15557284223,"instrument_name":"ETH-PERPETUAL","bids":[["change",3881.4,1.0e5]],"asks":[],"prev_change_id":15557284222}}}
{"jsonrpc":"2.0","method":"subscription","params":{"channel":"book.ETH-PERPETUAL.raw","data":{"timestamp":1734114582406,"type":"change","change_id":15557284223,"instrument_name":"ETH-PERPETUAL","bids":[["change",3881.4,1.0e5]],"asks":[],"prev_change_id":15557284222}}}
{"jsonrpc":"2.0","method":"subscription","params":{"channel":"book.ETH-PERPETUAL.raw","data":{"timestamp":1734114582408,"type":"change","change_id":15557284224,"instrument_name":"ETH-PERPETUAL","bids":[["change",3881.4,1.8e5]],"asks":[],"prev_change_id":15557284223}}}
{"jsonrpc":"2.0","method":"subscription","params":{"channel":"book.ETH-PERPETUAL.raw","data":{"timestamp":1734114582408,"type":"change","change_id":15557284224,"instrument_name":"ETH-PERPETUAL","bids":[["change",3881.4,1.8e5]],"asks":[],"prev_change_id":15557284223}}}
{"jsonrpc":"2.0","method":"subscription","params":{"channel":"book.ETH-PERPETUAL.raw","data":{"timestamp":1734114582410,"type":"change","change_id":15557284225,"instrument_name":"ETH-PERPETUAL","bids":[],"asks":[["change",3896.4,1.6e5]],"prev_change_id":15557284224}}}
{"jsonrpc":"2.0","method":"subscription","params":{"channel":"book.ETH-PERPETUAL.raw","data":{"timestamp":1734114582410,"type":"change","change_id":15557284225,"instrument_name":"ETH-PERPETUAL","bids":[],"asks":[["change",3896.4,1.6e5]],"prev_change_id":15557284224}}}
{"jsonrpc":"2.0","method":"subscription","params":{"channel":"book.ETH-PERPETUAL.raw","data":{"timestamp":1734114582412,"type":"change","change_id":15557284226,"instrument_name":"ETH-PERPETUAL","bids":[["change",3881.4,2.0e5]],"asks":[],"prev_change_id":15557284225}}}
{"jsonrpc":"2.0","method":"subscription","params":{"channel":"book.ETH-PERPETUAL.raw","data":{"timestamp":1734114582412,"type":"change","change_id":15557284226,"instrument_name":"ETH-PERPETUAL","bids":[["change",3881.4,2.0e5]],"asks":[],"prev_change_id":15557284225}}}
{"jsonrpc":"2.0","method":"subscription","params":{"channel":"book.ETH-PERPETUAL.raw","data":{"timestamp":1734114582492,"type":"change","change_id":15557284227,"instrument_name":"ETH-PERPETUAL","bids":[["delete",3881.4,0.0]],"asks":[["delete",3896.4,0.0]],"prev_change_id":15557284226}}}
{"jsonrpc":"2.0","method":"subscription","params":{"channel":"book.ETH-PERPETUAL.raw","data":{"timestamp":1734114582492,"type":"change","change_id":15557284227,"instrument_name":"ETH-PERPETUAL","bids":[["delete",3881.4,0.0]],"asks":[["delete",3896.4,0.0]],"prev_change_id":15557284226}}}
{"jsonrpc":"2.0","method":"subscription","params":{"channel":"book.ETH-PERPETUAL.raw","data":{"timestamp":1734114582665,"type":"change","change_id":15557284229,"instrument_name":"ETH-PERPETUAL","bids":[["new",3881.4,8.0e4]],"asks":[],"prev_change_id":15557284227}}}
{"jsonrpc":"2.0","method":"subscription","params":{"channel":"book.ETH-PERPETUAL.raw","data":{"timestamp":1734114582665,"type":"change","change_id":15557284229,"instrument_name":"ETH-PERPETUAL","bids":[["new",3881.4,8.0e4]],"asks":[],"prev_change_id":15557284227}}}
{"jsonrpc":"2.0","method":"subscription","params":{"channel":"book.ETH-PERPETUAL.raw","data":{"timestamp":1734114582667,"type":"change","change_id":15557284230,"instrument_name":"ETH-PERPETUAL","bids":[],"asks":[["new",3896.4,8.0e4]],"prev_change_id":15557284229}}}
{"jsonrpc":"2.0","method":"subscription","params":{"channel":"book.ETH-PERPETUAL.raw","data":{"timestamp":1734114582667,"type":"change","change_id":15557284230,"instrument_name":"ETH-PERPETUAL","bids":[],"asks":[["new",3896.4,8.0e4]],"prev_change_id":15557284229}}}
{"jsonrpc":"2.0","method":"subscription","params":{"channel":"book.ETH-PERPETUAL.raw","data":{"timestamp":1734114582668,"type":"change","change_id":15557284231,"instrument_name":"ETH-PERPETUAL","bids":[["change",3881.4,1.0e5]],"asks":[],"prev_change_id":15557284230}}}
{"jsonrpc":"2.0","method":"subscription","params":{"channel":"book.ETH-PERPETUAL.raw","data":{"timestamp":1734114582668,"type":"change","change_id":15557284231,"instrument_name":"ETH-PERPETUAL","bids":[["change",3881.4,1.0e5]],"asks":[],"prev_change_id":15557284230}}}
{"jsonrpc":"2.0","method":"subscription","params":{"channel":"book.ETH-PERPETUAL.raw","data":{"timestamp":1734114582669,"type":"change","change_id":15557284232,"instrument_name":"ETH-PERPETUAL","bids":[["change",3881.4,1.8e5]],"asks":[],"prev_change_id":15557284231}}}
{"jsonrpc":"2.0","method":"subscription","params":{"channel":"book.ETH-PERPETUAL.raw","data":{"timestamp":1734114582669,"type":"change","change_id":15557284232,"instrument_name":"ETH-PERPETUAL","bids":[["change",3881.4,1.8e5]],"asks":[],"prev_change_id":15557284231}}}
{"jsonrpc":"2.0","method":"subscription","params":{"channel":"book.ETH-PERPETUAL.raw","data":{"timestamp":1734114582670,"type":"change","change_id":15557284233,"instrument_name":"ETH-PERPETUAL","bids":[],"asks":[["change",3896.4,1.6e5]],"prev_change_id":15557284232}}}
{"jsonrpc":"2.0","method":"subscription","params":{"channel":"book.ETH-PERPETUAL.raw","data":{"timestamp":1734114582670,"type":"change","change_id":15557284233,"instrument_name":"ETH-PERPETUAL","bids":[],"asks":[["change",3896.4,1.6e5]],"prev_change_id":15557284232}}}
{"jsonrpc":"2.0","method":"subscription","params":{"channel":"book.ETH-PERPETUAL.raw","data":{"timestamp":1734114582672,"type":"change","change_id":15557284234,"instrument_name":"ETH-PERPETUAL","bids":[["change",3881.4,2.0e5]],"asks":[],"prev_change_id":15557284233}}}
{"jsonrpc":"2.0","method":"subscription","params":{"channel":"book.ETH-PERPETUAL.raw","data":{"timestamp":1734114582672,"type":"change","change_id":15557284234,"instrument_name":"ETH-PERPETUAL","bids":[["change",3881.4,2.0e5]],"asks":[],"prev_change_id":15557284233}}}
{"jsonrpc":"2.0","method":"subscription","params":{"channel":"book.ETH-PERPETUAL.raw","data":{"timestamp":1734114582868,"type":"change","change_id":15557284238,"instrument_name":"ETH-PERPETUAL","bids":[["delete",3881.4,0.0]],"asks":[["delete",3896.4,0.0]],"prev_change_id":15557284234}}}
{"jsonrpc":"2.0","method":"subscription","params":{"channel":"book.ETH-PERPETUAL.raw","data":{"timestamp":1734114582868,"type":"change","change_id":15557284238,"instrument_name":"ETH-PERPETUAL","bids":[["delete",3881.4,0.0]],"asks":[["delete",3896.4,0.0]],"prev_change_id":15557284234}}}
{"jsonrpc":"2.0","method":"subscription","params":{"channel":"book.ETH-PERPETUAL.raw","data":{"timestamp":1734114583052,"type":"change","change_id":15557284257,"instrument_name":"ETH-PERPETUAL","bids":[["change",3881.35,83870.0]],"asks":[],"prev_change_id":15557284238}}}
{"jsonrpc":"2.0","method":"subscription","params":{"channel":"book.ETH-PERPETUAL.raw","data":{"timestamp":1734114583052,"type":"change","change_id":15557284257,"instrument_name":"ETH-PERPETUAL","bids":[["change",3881.35,83870.0]],"asks":[],"prev_change_id":15557284238}}}
{"jsonrpc":"2.0","method":"subscription","params":{"channel":"book.ETH-PERPETUAL.raw","data":{"timestamp":1734114583053,"type":"change","change_id":15557284258,"instrument_name":"ETH-PERPETUAL","bids":[],"asks":[["new",3896.4,8.0e4]],"prev_change_id":15557284257}}}
{"jsonrpc":"2.0","method":"subscription","params":{"channel":"book.ETH-PERPETUAL.raw","data":{"timestamp":1734114583053,"type":"change","change_id":15557284258,"instrument_name":"ETH-PERPETUAL","bids":[],"asks":[["new",3896.4,8.0e4]],"prev_change_id":15557284257}}}
{"jsonrpc":"2.0","method":"subscription","params":{"channel":"book.ETH-PERPETUAL.raw","data":{"timestamp":1734114583054,"type":"change","change_id":15557284259,"instrument_name":"ETH-PERPETUAL","bids":[["change",3881.35,103870.0]],"asks":[],"prev_change_id":15557284258}}}
{"jsonrpc":"2.0","method":"subscription","params":{"channel":"book.ETH-PERPETUAL.raw","data":{"timestamp":1734114583054,"type":"change","change_id":15557284259,"instrument_name":"ETH-PERPETUAL","bids":[["change",3881.35,103870.0]],"asks":[],"prev_change_id":15557284258}}}
{"jsonrpc":"2.0","method":"subscription","params":{"channel":"book.ETH-PERPETUAL.raw","data":{"timestamp":1734114583056,"type":"change","change_id":15557284260,"instrument_name":"ETH-PERPETUAL","bids":[],"asks":[["change",3896.4,1.0e5]],"prev_change_id":15557284259}}}
{"jsonrpc":"2.0","method":"subscription","params":{"channel":"book.ETH-PERPETUAL.raw","data":{"timestamp":1734114583056,"type":"change","change_id":15557284260,"instrument_name":"ETH-PERPETUAL","bids":[],"asks":[["change",3896.4,1.0e5]],"prev_change_id":15557284259}}}
{"jsonrpc":"2.0","method":"subscription","params":{"channel":"book.ETH-PERPETUAL.raw","data":{"timestamp":1734114583057,"type":"change","change_id":15557284261,"instrument_name":"ETH-PERPETUAL","bids":[["change",3881.35,183870.0]],"asks":[],"prev_change_id":15557284260}}}
{"jsonrpc":"2.0","method":"subscription","params":{"channel":"book.ETH-PERPETUAL.raw","data":{"timestamp":1734114583057,"type":"change","change_id":15557284261,"instrument_name":"ETH-PERPETUAL","bids":[["change",3881.35,183870.0]],"asks":[],"prev_change_id":15557284260}}}
{"jsonrpc":"2.0","method":"subscription","params":{"channel":"book.ETH-PERPETUAL.raw","data":{"timestamp":1734114583059,"type":"change","change_id":15557284262,"instrument_name":"ETH-PERPETUAL","bids":[],"asks":[["change",3896.4,1.8e5]],"prev_change_id":15557284261}}}
{"jsonrpc":"2.0","method":"subscription","params":{"channel":"book.ETH-PERPETUAL.raw","data":{"timestamp":1734114583059,"type":"change","change_id":15557284262,"instrument_name":"ETH-PERPETUAL","bids":[],"asks":[["change",3896.4,1.8e5]],"prev_change_id":15557284261}}}
{"jsonrpc":"2.0","method":"subscription","params":{"channel":"book.ETH-PERPETUAL.raw","data":{"timestamp":1734114583060,"type":"change","change_id":15557284263,"instrument_name":"ETH-PERPETUAL","bids":[["change",3881.35,203870.0]],"asks":[],"prev_change_id":15557284262}}}
{"jsonrpc":"2.0","method":"subscription","params":{"channel":"book.ETH-PERPETUAL.raw","data":{"timestamp":1734114583060,"type":"change","change_id":15557284263,"instrument_name":"ETH-PERPETUAL","bids":[["change",3881.35,203870.0]],"asks":[],"prev_change_id":15557284262}}}
{"jsonrpc":"2.0","method":"subscription","params":{"channel":"book.ETH-PERPETUAL.raw","data":{"timestamp":1734114583061,"type":"change","change_id":15557284264,"instrument_name":"ETH-PERPETUAL","bids":[],"asks":[["change",3896.4,2.0e5]],"prev_change_id":15557284263}}}
{"jsonrpc":"2.0","method":"subscription","params":{"channel":"book.ETH-PERPETUAL.raw","data":{"timestamp":1734114583061,"type":"change","change_id":15557284264,"instrument_name":"ETH-PERPETUAL","bids":[],"asks":[["change",3896.4,2.0e5]],"prev_change_id":15557284263}}}
{"jsonrpc":"2.0","method":"subscription","params":{"channel":"book.ETH-PERPETUAL.raw","data":{"timestamp":1734114583196,"type":"change","change_id":15557284265,"instrument_name":"ETH-PERPETUAL","bids":[["change",3881.35,3870.0]],"asks":[["delete",3896.4,0.0]],"prev_change_id":15557284264}}}
{"jsonrpc":"2.0","method":"subscription","params":{"channel":"book.ETH-PERPETUAL.raw","data":{"timestamp":1734114583196,"type":"change","change_id":15557284265,"instrument_name":"ETH-PERPETUAL","bids":[["change",3881.35,3870.0]],"asks":[["delete",3896.4,0.0]],"prev_change_id":15557284264}}}
{"jsonrpc":"2.0","method":"subscription","params":{"channel":"book.ETH-PERPETUAL.raw","data":{"timestamp":1734114583383,"type":"change","change_id":15557284266,"instrument_name":"ETH-PERPETUAL","bids":[],"asks":[["new",3896.4,8.0e4]],"prev_change_id":15557284265}}}
{"jsonrpc":"2.0","method":"subscription","params":{"channel":"book.ETH-PERPETUAL.raw","data":{"timestamp":1734114583383,"type":"change","change_id":15557284266,"instrument_name":"ETH-PERPETUAL","bids":[],"asks":[["new",3896.4,8.0e4]],"prev_change_id":15557284265}}}
{"jsonrpc":"2.0","method":"subscription","params":{"channel":"book.ETH-PERPETUAL.raw","data":{"timestamp":1734114583385,"type":"change","change_id":15557284267,"instrument_name":"ETH-PERPETUAL","bids":[["change",3881.35,83870.0]],"asks":[],"prev_change_id":15557284266}}}
{"jsonrpc":"2.0","method":"subscription","params":{"channel":"book.ETH-PERPETUAL.raw","data":{"timestamp":1734114583385,"type":"change","change_id":15557284267,"instrument_name":"ETH-PERPETUAL","bids":[["change",3881.35,83870.0]],"asks":[],"prev_change_id":15557284266}}}
{"jsonrpc":"2.0","method":"subscription","params":{"channel":"book.ETH-PERPETUAL.raw","data":{"timestamp":1734114583387,"type":"change","change_id":15557284268,"instrument_name":"ETH-PERPETUAL","bids":[],"asks":[["change",3896.4,1.6e5]],"prev_change_id":15557284267}}}
{"jsonrpc":"2.0","method":"subscription","params":{"channel":"book.ETH-PERPETUAL.raw","data":{"timestamp":1734114583387,"type":"change","change_id":15557284268,"instrument_name":"ETH-PERPETUAL","bids":[],"asks":[["change",3896.4,1.6e5]],"prev_change_id":15557284267}}}
{"jsonrpc":"2.0","method":"subscription","params":{"channel":"book.ETH-PERPETUAL.raw","data":{"timestamp":1734114583388,"type":"change","change_id":15557284269,"instrument_name":"ETH-PERPETUAL","bids":[["change",3881.35,163870.0]],"asks":[],"prev_change_id":15557284268}}}
{"jsonrpc":"2.0","method":"subscription","params":{"channel":"book.ETH-PERPETUAL.raw","data":{"timestamp":1734114583388,"type":"change","change_id":15557284269,"instrument_name":"ETH-PERPETUAL","bids":[["change",3881.35,163870.0]],"asks":[],"prev_change_id":15557284268}}}
{"jsonrpc":"2.0","method":"subscription","params":{"channel":"book.ETH-PERPETUAL.raw","data":{"timestamp":1734114583510,"type":"change","change_id":15557284270,"instrument_name":"ETH-PERPETUAL","bids":[["change",3881.35,3870.0]],"asks":[["delete",3896.4,0.0]],"prev_change_id":15557284269}}}
{"jsonrpc":"2.0","method":"subscription","params":{"channel":"book.ETH-PERPETUAL.raw","data":{"timestamp":1734114583510,"type":"change","change_id":15557284270,"instrument_name":"ETH-PERPETUAL","bids":[["change",3881.35,3870.0]],"asks":[["delete",3896.4,0.0]],"prev_change_id":15557284269}}}
{"jsonrpc":"2.0","method":"subscription","params":{"channel":"book.ETH-PERPETUAL.raw","data":{"timestamp":1734114583528,"type":"change","change_id":15557284271,"instrument_name":"ETH-PERPETUAL","bids":[],"asks":[["new",3908.1,500.0],["delete",3919.9,0.0]],"prev_change_id":15557284270}}}
{"jsonrpc":"2.0","method":"subscription","params":{"channel":"book.ETH-PERPETUAL.raw","data":{"timestamp":1734114583528,"type":"change","change_id":15557284271,"instrument_name":"ETH-PERPETUAL","bids":[],"asks":[["new",3908.1,500.0],["delete",3919.9,0.0]],"prev_change_id":15557284270}}}
{"jsonrpc":"2.0","method":"subscription","params":{"channel":"book.ETH-PERPETUAL.raw","data":{"timestamp":1734114583693,"type":"change","change_id":15557284273,"instrument_name":"ETH-PERPETUAL","bids":[],"asks":[["new",3896.4,8.0e4]],"prev_change_id":15557284271}}}
{"jsonrpc":"2.0","method":"subscription","params":{"channel":"book.ETH-PERPETUAL.raw","data":{"timestamp":1734114583693,"type":"change","change_id":15557284273,"instrument_name":"ETH-PERPETUAL","bids":[],"asks":[["new",3896.4,8.0e4]],"prev_change_id":15557284271}}}
{"jsonrpc":"2.0","method":"subscription","params":{"channel":"book.ETH-PERPETUAL.raw","data":{"timestamp":1734114583694,"type":"change","change_id":15557284274,"instrument_name":"ETH-PERPETUAL","bids":[["change",3881.35,83870.0]],"asks":[],"prev_change_id":15557284273}}}
{"jsonrpc":"2.0","method":"subscription","params":{"channel":"book.ETH-PERPETUAL.raw","data":{"timestamp":1734114583694,"type":"change","change_id":15557284274,"instrument_name":"ETH-PERPETUAL","bids":[["change",3881.35,83870.0]],"asks":[],"prev_change_id":15557284273}}}
{"jsonrpc":"2.0","method":"subscription","params":{"channel":"book.ETH-PERPETUAL.raw","data":{"timestamp":1734114583696,"type":"change","change_id":15557284275,"instrument_name":"ETH-PERPETUAL","bids":[],"asks":[["change",3896.4,1.0e5]],"prev_change_id":15557284274}}}
{"jsonrpc":"2.0","method":"subscription","params":{"channel":"book.ETH-PERPETUAL.raw","data":{"timestamp":1734114583696,"type":"change","change_id":15557284275,"instrument_name":"ETH-PERPETUAL","bids":[],"asks":[["change",3896.4,1.0e5]],"prev_change_id":15557284274}}}
{"jsonrpc":"2.0","method":"subscription","params":{"channel":"book.ETH-PERPETUAL.raw","data":{"timestamp":1734114583700,"type":"change","change_id":15557284276,"instrument_name":"ETH-PERPETUAL","bids":[],"asks":[["change",3896.4,1.8e5]],"prev_change_id":15557284275}}}
{"jsonrpc":"2.0","method":"subscription","params":{"channel":"book.ETH-PERPETUAL.raw","data":{"timestamp":1734114583700,"type":"change","change_id":15557284276,"instrument_name":"ETH-PERPETUAL","bids":[],"asks":[["change",3896.4,1.8e5]],"prev_change_id":15557284275}}}
{"jsonrpc":"2.0","method":"subscription","params":{"channel":"book.ETH-PERPETUAL.raw","data":{"timestamp":1734114583701,"type":"change","change_id":15557284277,"instrument_name":"ETH-PERPETUAL","bids":[["change",3881.35,163870.0]],"asks":[],"prev_change_id":15557284276}}}
{"jsonrpc":"2.0","method":"subscription","params":{"channel":"book.ETH-PERPETUAL.raw","data":{"timestamp":1734114583701,"type":"change","change_id":15557284277,"instrument_name":"ETH-PERPETUAL","bids":[["change",3881.35,163870.0]],"asks":[],"prev_change_id":15557284276}}}
{"jsonrpc":"2.0","method":"subscription","params":{"channel":"book.ETH-PERPETUAL.raw","data":{"timestamp":1734114583704,"type":"change","change_id":15557284278,"instrument_name":"ETH-PERPETUAL","bids":[],"asks":[["change",3896.4,2.0e5]],"prev_change_id":15557284277}}}
{"jsonrpc":"2.0","method":"subscription","params":{"channel":"book.ETH-PERPETUAL.raw","data":{"timestamp":1734114583704,"type":"change","change_id":15557284278,"instrument_name":"ETH-PERPETUAL","bids":[],"asks":[["change",3896.4,2.0e5]],"prev_change_id":15557284277}}}
{"jsonrpc":"2.0","method":"subscription","params":{"channel":"book.ETH-PERPETUAL.raw","data":{"timestamp":1734114583790,"type":"change","change_id":15557284279,"instrument_name":"ETH-PERPETUAL","bids":[["change",3881.35,3870.0]],"asks":[["delete",3896.4,0.0]],"prev_change_id":15557284278}}}
{"jsonrpc":"2.0","method":"subscription","params":{"channel":"book.ETH-PERPETUAL.raw","data":{"timestamp":1734114583790,"type":"change","change_id":15557284279,"instrument_name":"ETH-PERPETUAL","bids":[["change",3881.35,3870.0]],"asks":[["delete",3896.4,0.0]],"prev_change_id":15557284278}}}
{"jsonrpc":"2.0","method":"subscription","params":{"channel":"book.ETH-PERPETUAL.raw","data":{"timestamp":1734114584017,"type":"change","change_id":15557284281,"instrument_name":"ETH-PERPETUAL","bids":[],"asks":[["new",3896.4,8.0e4]],"prev_change_id":15557284279}}}
{"jsonrpc":"2.0","method":"subscription","params":{"channel":"book.ETH-PERPETUAL.raw","data":{"timestamp":1734114584017,"type":"change","change_id":15557284281,"instrument_name":"ETH-PERPETUAL","bids":[],"asks":[["new",3896.4,8.0e4]],"prev_change_id":15557284279}}}
{"jsonrpc":"2.0","method":"subscription","params":{"channel":"book.ETH-PERPETUAL.raw","data":{"timestamp":1734114584019,"type":"change","change_id":15557284282,"instrument_name":"ETH-PERPETUAL","bids":[["change",3881.35,83870.0]],"asks":[],"prev_change_id":15557284281}}}
{"jsonrpc":"2.0","method":"subscription","params":{"channel":"book.ETH-PERPETUAL.raw","data":{"timestamp":1734114584019,"type":"change","change_id":15557284282,"instrument_name":"ETH-PERPETUAL","bids":[["change",3881.35,83870.0]],"asks":[],"prev_change_id":15557284281}}}
{"jsonrpc":"2.0","method":"subscription","params":{"channel":"book.ETH-PERPETUAL.raw","data":{"timestamp":1734114584020,"type":"change","change_id":15557284283,"instrument_name":"ETH-PERPETUAL","bids":[],"asks":[["change",3896.4,1.0e5]],"prev_change_id":15557284282}}}
{"jsonrpc":"2.0","method":"subscription","params":{"channel":"book.ETH-PERPETUAL.raw","data":{"timestamp":1734114584020,"type":"change","change_id":15557284283,"instrument_name":"ETH-PERPETUAL","bids":[],"asks":[["change",3896.4,1.0e5]],"prev_change_id":15557284282}}}
{"jsonrpc":"2.0","method":"subscription","params":{"channel":"book.ETH-PERPETUAL.raw","data":{"timestamp":1734114584021,"type":"change","change_id":15557284284,"instrument_name":"ETH-PERPETUAL","bids":[],"asks":[["change",3896.4,1.8e5]],"prev_change_id":15557284283}}}
{"jsonrpc":"2.0","method":"subscription","params":{"channel":"book.ETH-PERPETUAL.raw","data":{"timestamp":1734114584021,"type":"change","change_id":15557284284,"instrument_name":"ETH-PERPETUAL","bids":[],"asks":[["change",3896.4,1.8e5]],"prev_change_id":15557284283}}}
{"jsonrpc":"2.0","method":"subscription","params":{"channel":"book.ETH-PERPETUAL.raw","data":{"timestamp":1734114584022,"type":"change","change_id":15557284285,"instrument_name":"ETH-PERPETUAL","bids":[["change",3881.35,163870.0]],"asks":[],"prev_change_id":15557284284}}}
{"jsonrpc":"2.0","method":"subscription","params":{"channel":"book.ETH-PERPETUAL.raw","data":{"timestamp":1734114584022,"type":"change","change_id":15557284285,"instrument_name":"ETH-PERPETUAL","bids":[["change",3881.35,163870.0]],"asks":[],"prev_change_id":15557284284}}}
{"jsonrpc":"2.0","method":"subscription","params":{"channel":"book.ETH-PERPETUAL.raw","data":{"timestamp":1734114584023,"type":"change","change_id":15557284286,"instrument_name":"ETH-PERPETUAL","bids":[],"asks":[["change",3896.4,2.0e5]],"prev_change_id":15557284285}}}
{"jsonrpc":"2.0","method":"subscription","params":{"channel":"book.ETH-PERPETUAL.raw","data":{"timestamp":1734114584023,"type":"change","change_id":15557284286,"instrument_name":"ETH-PERPETUAL","bids":[],"asks":[["change",3896.4,2.0e5]],"prev_change_id":15557284285}}}
{"jsonrpc":"2.0","method":"subscription","params":{"channel":"book.ETH-PERPETUAL.raw","data":{"timestamp":1734114584170,"type":"change","change_id":15557284288,"instrument_name":"ETH-PERPETUAL","bids":[["change",3881.35,3870.0]],"asks":[["delete",3896.4,0.0]],"prev_change_id":15557284286}}}
{"jsonrpc":"2.0","method":"subscription","params":{"channel":"book.ETH-PERPETUAL.raw","data":{"timestamp":1734114584170,"type":"change","change_id":15557284288,"instrument_name":"ETH-PERPETUAL","bids":[["change",3881.35,3870.0]],"asks":[["delete",3896.4,0.0]],"prev_change_id":15557284286}}}
{"jsonrpc":"2.0","method":"subscription","params":{"channel":"book.ETH-PERPETUAL.raw","data":{"timestamp":1734114584316,"type":"change","change_id":15557284289,"instrument_name":"ETH-PERPETUAL","bids":[],"asks":[["delete",3915.9,0.0],["new",3927.65,500.0]],"prev_change_id":15557284288}}}
{"jsonrpc":"2.0","method":"subscription","params":{"channel":"book.ETH-PERPETUAL.raw","data":{"timestamp":1734114584316,"type":"change","change_id":15557284289,"instrument_name":"ETH-PERPETUAL","bids":[],"asks":[["delete",3915.9,0.0],["new",3927.65,500.0]],"prev_change_id":15557284288}}}
{"jsonrpc":"2.0","method":"subscription","params":{"channel":"book.ETH-PERPETUAL.raw","data":{"timestamp":1734114584465,"type":"change","change_id":15557284290,"instrument_name":"ETH-PERPETUAL","bids":[["new",3881.4,8.0e4]],"asks":[],"prev_change_id":15557284289}}}
{"jsonrpc":"2.0","method":"subscription","params":{"channel":"book.ETH-PERPETUAL.raw","data":{"timestamp":1734114584465,"type":"change","change_id":15557284290,"instrument_name":"ETH-PERPETUAL","bids":[["new",3881.4,8.0e4]],"asks":[],"prev_change_id":15557284289}}}
{"jsonrpc":"2.0","method":"subscription","params":{"channel":"book.ETH-PERPETUAL.raw","data":{"timestamp":1734114584467,"type":"change","change_id":15557284291,"instrument_name":"ETH-PERPETUAL","bids":[],"asks":[["new",3896.4,8.0e4]],"prev_change_id":15557284290}}}
{"jsonrpc":"2.0","method":"subscription","params":{"channel":"book.ETH-PERPETUAL.raw","data":{"timestamp":1734114584467,"type":"change","change_id":15557284291,"instrument_name":"ETH-PERPETUAL","bids":[],"asks":[["new",3896.4,8.0e4]],"prev_change_id":15557284290}}}
{"jsonrpc":"2.0","method":"subscription","params":{"channel":"book.ETH-PERPETUAL.raw","data":{"timestamp":1734114584468,"type":"change","change_id":15557284292,"instrument_name":"ETH-PERPETUAL","bids":[["change",3881.4,1.0e5]],"asks":[],"prev_change_id":15557284291}}}
{"jsonrpc":"2.0","method":"subscription","params":{"channel":"book.ETH-PERPETUAL.raw","data":{"timestamp":1734114584468,"type":"change","change_id":15557284292,"instrument_name":"ETH-PERPETUAL","bids":[["change",3881.4,1.0e5]],"asks":[],"prev_change_id":15557284291}}}
{"jsonrpc":"2.0","method":"subscription","params":{"channel":"book.ETH-PERPETUAL.raw","data":{"timestamp":1734114584470,"type":"change","change_id":15557284293,"instrument_name":"ETH-PERPETUAL","bids":[],"asks":[["change",3896.4,1.0e5]],"prev_change_id":15557284292}}}
{"jsonrpc":"2.0","method":"subscription","params":{"channel":"book.ETH-PERPETUAL.raw","data":{"timestamp":1734114584470,"type":"change","change_id":15557284293,"instrument_name":"ETH-PERPETUAL","bids":[],"asks":[["change",3896.4,1.0e5]],"prev_change_id":15557284292}}}
{"jsonrpc":"2.0","method":"subscription","params":{"channel":"book.ETH-PERPETUAL.raw","data":{"timestamp":1734114584471,"type":"change","change_id":15557284294,"instrument_name":"ETH-PERPETUAL","bids":[["change",3881.4,1.8e5]],"asks":[],"prev_change_id":15557284293}}}
{"jsonrpc":"2.0","method":"subscription","params":{"channel":"book.ETH-PERPETUAL.raw","data":{"timestamp":1734114584471,"type":"change","change_id":15557284294,"instrument_name":"ETH-PERPETUAL","bids":[["change",3881.4,1.8e5]],"asks":[],"prev_change_id":15557284293}}}
{"jsonrpc":"2.0","method":"subscription","params":{"channel":"book.ETH-PERPETUAL.raw","data":{"timestamp":1734114584473,"type":"change","change_id":15557284295,"instrument_name":"ETH-PERPETUAL","bids":[],"asks":[["change",3896.4,1.8e5]],"prev_change_id":15557284294}}}
{"jsonrpc":"2.0","method":"subscription","params":{"channel":"book.ETH-PERPETUAL.raw","data":{"timestamp":1734114584473,"type":"change","change_id":15557284295,"instrument_name":"ETH-PERPETUAL","bids":[],"asks":[["change",3896.4,1.8e5]],"prev_change_id":15557284294}}}
{"jsonrpc":"2.0","method":"subscription","params":{"channel":"book.ETH-PERPETUAL.raw","data":{"timestamp":1734114584474,"type":"change","change_id":15557284296,"instrument_name":"ETH-PERPETUAL","bids":[["change",3881.4,2.0e5]],"asks":[],"prev_change_id":15557284295}}}
{"jsonrpc":"2.0","method":"subscription","params":{"channel":"book.ETH-PERPETUAL.raw","data":{"timestamp":1734114584474,"type":"change","change_id":15557284296,"instrument_name":"ETH-PERPETUAL","bids":[["change",3881.4,2.0e5]],"asks":[],"prev_change_id":15557284295}}}
{"jsonrpc":"2.0","method":"subscription","params":{"channel":"book.ETH-PERPETUAL.raw","data":{"timestamp":1734114584476,"type":"change","change_id":15557284297,"instrument_name":"ETH-PERPETUAL","bids":[],"asks":[["change",3896.4,2.0e5]],"prev_change_id":15557284296}}}
{"jsonrpc":"2.0","method":"subscription","params":{"channel":"book.ETH-PERPETUAL.raw","data":{"timestamp":1734114584476,"type":"change","change_id":15557284297,"instrument_name":"ETH-PERPETUAL","bids":[],"asks":[["change",3896.4,2.0e5]],"prev_change_id":15557284296}}}
{"jsonrpc":"2.0","method":"subscription","params":{"channel":"book.ETH-PERPETUAL.raw","data":{"timestamp":1734114584560,"type":"change","change_id":15557284298,"instrument_name":"ETH-PERPETUAL","bids":[["delete",3881.4,0.0]],"asks":[["delete",3896.4,0.0]],"prev_change_id":15557284297}}}
{"jsonrpc":"2.0","method":"subscription","params":{"channel":"book.ETH-PERPETUAL.raw","data":{"timestamp":1734114584560,"type":"change","change_id":15557284298,"instrument_name":"ETH-PERPETUAL","bids":[["delete",3881.4,0.0]],"asks":[["delete",3896.4,0.0]],"prev_change_id":15557284297}}}
{"jsonrpc":"2.0","method":"subscription","params":{"channel":"book.ETH-PERPETUAL.raw","data":{"timestamp":1734114584826,"type":"change","change_id":15557284300,"instrument_name":"ETH-PERPETUAL","bids":[["change",10.0,112.0],["new",3.0,3.0]],"asks":[],"prev_change_id":15557284298}}}
{"jsonrpc":"2.0","method":"subscription","params":{"channel":"book.ETH-PERPETUAL.raw","data":{"timestamp":1734114584826,"type":"change","change_id":15557284300,"instrument_name":"ETH-PERPETUAL","bids":[["change",10.0,112.0],["new",3.0,3.0]],"asks":[],"prev_change_id":15557284298}}}
{"jsonrpc":"2.0","method":"subscription","params":{"channel":"book.ETH-PERPETUAL.raw","data":{"timestamp":1734114584910,"type":"change","change_id":15557284310,"instrument_name":"ETH-PERPETUAL","bids":[],"asks":[["new",3896.5,8.0e4]],"prev_change_id":15557284300}}}
{"jsonrpc":"2.0","method":"subscription","params":{"channel":"book.ETH-PERPETUAL.raw","data":{"timestamp":1734114584910,"type":"change","change_id":15557284310,"instrument_name":"ETH-PERPETUAL","bids":[],"asks":[["new",3896.5,8.0e4]],"prev_change_id":15557284300}}}
{"jsonrpc":"2.0","method":"subscription","params":{"channel":"book.ETH-PERPETUAL.raw","data":{"timestamp":1734114584912,"type":"change","change_id":15557284311,"instrument_name":"ETH-PERPETUAL","bids":[["new",3881.5,8.0e4]],"asks":[],"prev_change_id":15557284310}}}
{"jsonrpc":"2.0","method":"subscription","params":{"channel":"book.ETH-PERPETUAL.raw","data":{"timestamp":1734114584912,"type":"change","change_id":15557284311,"instrument_name":"ETH-PERPETUAL","bids":[["new",3881.5,8.0e4]],"asks":[],"prev_change_id":15557284310}}}
{"jsonrpc":"2.0","method":"subscription","params":{"channel":"book.ETH-PERPETUAL.raw","data":{"timestamp":1734114584914,"type":"change","change_id":15557284313,"instrument_name":"ETH-PERPETUAL","bids":[],"asks":[["change",3896.5,1.0e5]],"prev_change_id":15557284311}}}
{"jsonrpc":"2.0","method":"subscription","params":{"channel":"book.ETH-PERPETUAL.raw","data":{"timestamp":1734114584914,"type":"change","change_id":15557284313,"instrument_name":"ETH-PERPETUAL","bids":[],"asks":[["change",3896.5,1.0e5]],"prev_change_id":15557284311}}}
{"jsonrpc":"2.0","method":"subscription","params":{"channel":"book.ETH-PERPETUAL.raw","data":{"timestamp":1734114584916,"type":"change","change_id":15557284315,"instrument_name":"ETH-PERPETUAL","bids":[["change",3881.5,1.0e5]],"asks":[],"prev_change_id":15557284313}}}
{"jsonrpc":"2.0","method":"subscription","params":{"channel":"book.ETH-PERPETUAL.raw","data":{"timestamp":1734114584916,"type":"change","change_id":15557284315,"instrument_name":"ETH-PERPETUAL","bids":[["change",3881.5,1.0e5]],"asks":[],"prev_change_id":15557284313}}}
{"jsonrpc":"2.0","method":"subscription","params":{"channel":"book.ETH-PERPETUAL.raw","data":{"timestamp":1734114584923,"type":"change","change_id":15557284316,"instrument_name":"ETH-PERPETUAL","bids":[],"asks":[["change",3896.5,1.8e5]],"prev_change_id":15557284315}}}
{"jsonrpc":"2.0","method":"subscription","params":{"channel":"book.ETH-PERPETUAL.raw","data":{"timestamp":1734114584923,"type":"change","change_id":15557284316,"instrument_name":"ETH-PERPETUAL","bids":[],"asks":[["change",3896.5,1.8e5]],"prev_change_id":15557284315}}}
{"jsonrpc":"2.0","method":"subscription","params":{"channel":"book.ETH-PERPETUAL.raw","data":{"timestamp":1734114584925,"type":"change","change_id":15557284317,"instrument_name":"ETH-PERPETUAL","bids":[["change",3881.5,1.8e5]],"asks":[],"prev_change_id":15557284316}}}
{"jsonrpc":"2.0","method":"subscription","params":{"channel":"book.ETH-PERPETUAL.raw","data":{"timestamp":1734114584925,"type":"change","change_id":15557284317,"instrument_name":"ETH-PERPETUAL","bids":[["change",3881.5,1.8e5]],"asks":[],"prev_change_id":15557284316}}}
{"jsonrpc":"2.0","method":"subscription","params":{"channel":"book.ETH-PERPETUAL.raw","data":{"timestamp":1734114584927,"type":"change","change_id":15557284318,"instrument_name":"ETH-PERPETUAL","bids":[],"asks":[["change",3896.5,2.0e5]],"prev_change_id":15557284317}}}
{"jsonrpc":"2.0","method":"subscription","params":{"channel":"book.ETH-PERPETUAL.raw","data":{"timestamp":1734114584927,"type":"change","change_id":15557284318,"instrument_name":"ETH-PERPETUAL","bids":[],"asks":[["change",3896.5,2.0e5]],"prev_change_id":15557284317}}}
{"jsonrpc":"2.0","method":"subscription","params":{"channel":"book.ETH-PERPETUAL.raw","data":{"timestamp":1734114584930,"type":"change","change_id":15557284319,"instrument_name":"ETH-PERPETUAL","bids":[["change",3881.5,2.0e5]],"asks":[],"prev_change_id":15557284318}}}
{"jsonrpc":"2.0","method":"subscription","params":{"channel":"book.ETH-PERPETUAL.raw","data":{"timestamp":1734114584930,"type":"change","change_id":15557284319,"instrument_name":"ETH-PERPETUAL","bids":[["change",3881.5,2.0e5]],"asks":[],"prev_change_id":15557284318}}}
{"jsonrpc":"2.0","method":"subscription","params":{"channel":"book.ETH-PERPETUAL.raw","data":{"timestamp":1734114585009,"type":"change","change_id":15557284321,"instrument_name":"ETH-PERPETUAL","bids":[["delete",3881.5,0.0]],"asks":[["delete",3896.5,0.0]],"prev_change_id":15557284319}}}
{"jsonrpc":"2.0","method":"subscription","params":{"channel":"book.ETH-PERPETUAL.raw","data":{"timestamp":1734114585009,"type":"change","change_id":15557284321,"instrument_name":"ETH-PERPETUAL","bids":[["delete",3881.5,0.0]],"asks":[["delete",3896.5,0.0]],"prev_change_id":15557284319}}}
{"jsonrpc":"2.0","method":"subscription","params":{"channel":"book.ETH-PERPETUAL.raw","data":{"timestamp":1734114585192,"type":"change","change_id":15557284323,"instrument_name":"ETH-PERPETUAL","bids":[],"asks":[["new",3896.5,8.0e4]],"prev_change_id":15557284321}}}
{"jsonrpc":"2.0","method":"subscription","params":{"channel":"book.ETH-PERPETUAL.raw","data":{"timestamp":1734114585192,"type":"change","change_id":15557284323,"instrument_name":"ETH-PERPETUAL","bids":[],"asks":[["new",3896.5,8.0e4]],"prev_change_id":15557284321}}}
{"jsonrpc":"2.0","method":"subscription","params":{"channel":"book.ETH-PERPETUAL.raw","data":{"timestamp":1734114585199,"type":"change","change_id":15557284324,"instrument_name":"ETH-PERPETUAL","bids":[["new",3881.5,8.0e4]],"asks":[],"prev_change_id":15557284323}}}
{"jsonrpc":"2.0","method":"subscription","params":{"channel":"book.ETH-PERPETUAL.raw","data":{"timestamp":1734114585199,"type":"change","change_id":15557284324,"instrument_name":"ETH-PERPETUAL","bids":[["new",3881.5,8.0e4]],"asks":[],"prev_change_id":15557284323}}}
{"jsonrpc":"2.0","method":"subscription","params":{"channel":"book.ETH-PERPETUAL.raw","data":{"timestamp":1734114585200,"type":"change","change_id":15557284325,"instrument_name":"ETH-PERPETUAL","bids":[],"asks":[["change",3896.5,1.0e5]],"prev_change_id":15557284324}}}
{"jsonrpc":"2.0","method":"subscription","params":{"channel":"book.ETH-PERPETUAL.raw","data":{"timestamp":1734114585200,"type":"change","change_id":15557284325,"instrument_name":"ETH-PERPETUAL","bids":[],"asks":[["change",3896.5,1.0e5]],"prev_change_id":15557284324}}}
{"jsonrpc":"2.0","method":"subscription","params":{"channel":"book.ETH-PERPETUAL.raw","data":{"timestamp":1734114585205,"type":"change","change_id":15557284326,"instrument_name":"ETH-PERPETUAL","bids":[["change",3881.5,1.0e5]],"asks":[],"prev_change_id":15557284325}}}
{"jsonrpc":"2.0","method":"subscription","params":{"channel":"book.ETH-PERPETUAL.raw","data":{"timestamp":1734114585205,"type":"change","change_id":15557284326,"instrument_name":"ETH-PERPETUAL","bids":[["change",3881.5,1.0e5]],"asks":[],"prev_change_id":15557284325}}}
{"jsonrpc":"2.0","method":"subscription","params":{"channel":"book.ETH-PERPETUAL.raw","data":{"timestamp":1734114585206,"type":"change","change_id":15557284327,"instrument_name":"ETH-PERPETUAL","bids":[],"asks":[["change",3896.5,1.8e5]],"prev_change_id":15557284326}}}
{"jsonrpc":"2.0","method":"subscription","params":{"channel":"book.ETH-PERPETUAL.raw","data":{"timestamp":1734114585206,"type":"change","change_id":15557284327,"instrument_name":"ETH-PERPETUAL","bids":[],"asks":[["change",3896.5,1.8e5]],"prev_change_id":15557284326}}}
{"jsonrpc":"2.0","method":"subscription","params":{"channel":"book.ETH-PERPETUAL.raw","data":{"timestamp":1734114585209,"type":"change","change_id":15557284328,"instrument_name":"ETH-PERPETUAL","bids":[["change",3881.5,1.8e5]],"asks":[],"prev_change_id":15557284327}}}
{"jsonrpc":"2.0","method":"subscription","params":{"channel":"book.ETH-PERPETUAL.raw","data":{"timestamp":1734114585209,"type":"change","change_id":15557284328,"instrument_name":"ETH-PERPETUAL","bids":[["change",3881.5,1.8e5]],"asks":[],"prev_change_id":15557284327}}}
{"jsonrpc":"2.0","method":"subscription","params":{"channel":"book.ETH-PERPETUAL.raw","data":{"timestamp":1734114585210,"type":"change","change_id":15557284329,"instrument_name":"ETH-PERPETUAL","bids":[],"asks":[["change",3896.5,2.0e5]],"prev_change_id":15557284328}}}
{"jsonrpc":"2.0","method":"subscription","params":{"channel":"book.ETH-PERPETUAL.raw","data":{"timestamp":1734114585210,"type":"change","change_id":15557284329,"instrument_name":"ETH-PERPETUAL","bids":[],"asks":[["change",3896.5,2.0e5]],"prev_change_id":15557284328}}}
{"jsonrpc":"2.0","method":"subscription","params":{"channel":"book.ETH-PERPETUAL.raw","data":{"timestamp":1734114585210,"type":"change","change_id":15557284330,"instrument_name":"ETH-PERPETUAL","bids":[["change",3881.5,2.0e5]],"asks":[],"prev_change_id":15557284329}}}
{"jsonrpc":"2.0","method":"subscription","params":{"channel":"book.ETH-PERPETUAL.raw","data":{"timestamp":1734114585210,"type":"change","change_id":15557284330,"instrument_name":"ETH-PERPETUAL","bids":[["change",3881.5,2.0e5]],"asks":[],"prev_change_id":15557284329}}}
{"jsonrpc":"2.0","method":"subscription","params":{"channel":"book.ETH-PERPETUAL.raw","data":{"timestamp":1734114585300,"type":"change","change_id":15557284331,"instrument_name":"ETH-PERPETUAL","bids":[["delete",3881.5,0.0]],"asks":[["delete",3896.5,0.0]],"prev_change_id":15557284330}}}
{"jsonrpc":"2.0","method":"subscription","params":{"channel":"book.ETH-PERPETUAL.raw","data":{"timestamp":1734114585300,"type":"change","change_id":15557284331,"instrument_name":"ETH-PERPETUAL","bids":[["delete",3881.5,0.0]],"asks":[["delete",3896.5,0.0]],"prev_change_id":15557284330}}}
{"jsonrpc":"2.0","method":"subscription","params":{"channel":"book.ETH-PERPETUAL.raw","data":{"timestamp":1734114585473,"type":"change","change_id":15557284333,"instrument_name":"ETH-PERPETUAL","bids":[],"asks":[["new",3896.55,8.0e4]],"prev_change_id":15557284331}}}
{"jsonrpc":"2.0","method":"subscription","params":{"channel":"book.ETH-PERPETUAL.raw","data":{"timestamp":1734114585473,"type":"change","change_id":15557284333,"instrument_name":"ETH-PERPETUAL","bids":[],"asks":[["new",3896.55,8.0e4]],"prev_change_id":15557284331}}}
{"jsonrpc":"2.0","method":"subscription","params":{"channel":"book.ETH-PERPETUAL.raw","data":{"timestamp":1734114585475,"type":"change","change_id":15557284334,"instrument_name":"ETH-PERPETUAL","bids":[["new",3881.5,8.0e4]],"asks":[],"prev_change_id":15557284333}}}
{"jsonrpc":"2.0","method":"subscription","params":{"channel":"book.ETH-PERPETUAL.raw","data":{"timestamp":1734114585475,"type":"change","change_id":15557284334,"instrument_name":"ETH-PERPETUAL","bids":[["new",3881.5,8.0e4]],"asks":[],"prev_change_id":15557284333}}}
{"jsonrpc":"2.0","method":"subscription","params":{"channel":"book.ETH-PERPETUAL.raw","data":{"timestamp":1734114585476,"type":"change","change_id":15557284335,"instrument_name":"ETH-PERPETUAL","bids":[],"asks":[["change",3896.55,1.0e5]],"prev_change_id":15557284334}}}
{"jsonrpc":"2.0","method":"subscription","params":{"channel":"book.ETH-PERPETUAL.raw","data":{"timestamp":1734114585476,"type":"change","change_id":15557284335,"instrument_name":"ETH-PERPETUAL","bids":[],"asks":[["change",3896.55,1.0e5]],"prev_change_id":15557284334}}}
{"jsonrpc":"2.0","method":"subscription","params":{"channel":"book.ETH-PERPETUAL.raw","data":{"timestamp":1734114585478,"type":"change","change_id":15557284336,"instrument_name":"ETH-PERPETUAL","bids":[["change",3881.5,1.0e5]],"asks":[],"prev_change_id":15557284335}}}
{"jsonrpc":"2.0","method":"subscription","params":{"channel":"book.ETH-PERPETUAL.raw","data":{"timestamp":1734114585478,"type":"change","change_id":15557284336,"instrument_name":"ETH-PERPETUAL","bids":[["change",3881.5,1.0e5]],"asks":[],"prev_change_id":15557284335}}}
{"jsonrpc":"2.0","method":"subscription","params":{"channel":"book.ETH-PERPETUAL.raw","data":{"timestamp":1734114585479,"type":"change","change_id":15557284337,"instrument_name":"ETH-PERPETUAL","bids":[],"asks":[["change",3896.55,1.8e5]],"prev_change_id":15557284336}}}
{"jsonrpc":"2.0","method":"subscription","params":{"channel":"book.ETH-PERPETUAL.raw","data":{"timestamp":1734114585479,"type":"change","change_id":15557284337,"instrument_name":"ETH-PERPETUAL","bids":[],"asks":[["change",3896.55,1.8e5]],"prev_change_id":15557284336}}}
{"jsonrpc":"2.0","method":"subscription","params":{"channel":"book.ETH-PERPETUAL.raw","data":{"timestamp":1734114585481,"type":"change","change_id":15557284338,"instrument_name":"ETH-PERPETUAL","bids":[["change",3881.5,1.8e5]],"asks":[],"prev_change_id":15557284337}}}
{"jsonrpc":"2.0","method":"subscription","params":{"channel":"book.ETH-PERPETUAL.raw","data":{"timestamp":1734114585481,"type":"change","change_id":15557284338,"instrument_name":"ETH-PERPETUAL","bids":[["change",3881.5,1.8e5]],"asks":[],"prev_change_id":15557284337}}}
{"jsonrpc":"2.0","method":"subscription","params":{"channel":"book.ETH-PERPETUAL.raw","data":{"timestamp":1734114585482,"type":"change","change_id":15557284339,"instrument_name":"ETH-PERPETUAL","bids":[],"asks":[["change",3896.55,2.0e5]],"prev_change_id":15557284338}}}
{"jsonrpc":"2.0","method":"subscription","params":{"channel":"book.ETH-PERPETUAL.raw","data":{"timestamp":1734114585482,"type":"change","change_id":15557284339,"instrument_name":"ETH-PERPETUAL","bids":[],"asks":[["change",3896.55,2.0e5]],"prev_change_id":15557284338}}}
{"jsonrpc":"2.0","method":"subscription","params":{"channel":"book.ETH-PERPETUAL.raw","data":{"timestamp":1734114585484,"type":"change","change_id":15557284340,"instrument_name":"ETH-PERPETUAL","bids":[["change",3881.5,2.0e5]],"asks":[],"prev_change_id":15557284339}}}
{"jsonrpc":"2.0","method":"subscription","params":{"channel":"book.ETH-PERPETUAL.raw","data":{"timestamp":1734114585484,"type":"change","change_id":15557284340,"instrument_name":"ETH-PERPETUAL","bids":[["change",3881.5,2.0e5]],"asks":[],"prev_change_id":15557284339}}}
{"jsonrpc":"2.0","method":"subscription","params":{"channel":"book.ETH-PERPETUAL.raw","data":{"timestamp":1734114585623,"type":"change","change_id":15557284341,"instrument_name":"ETH-PERPETUAL","bids":[["delete",3881.5,0.0]],"asks":[["delete",3896.55,0.0]],"prev_change_id":15557284340}}}
{"jsonrpc":"2.0","method":"subscription","params":{"channel":"book.ETH-PERPETUAL.raw","data":{"timestamp":1734114585623,"type":"change","change_id":15557284341,"instrument_name":"ETH-PERPETUAL","bids":[["delete",3881.5,0.0]],"asks":[["delete",3896.55,0.0]],"prev_change_id":15557284340}}}
{"jsonrpc":"2.0","method":"subscription","params":{"channel":"book.ETH-PERPETUAL.raw","data":{"timestamp":1734114585826,"type":"change","change_id":15557284343,"instrument_name":"ETH-PERPETUAL","bids":[],"asks":[["new",3896.55,8.0e4]],"prev_change_id":15557284341}}}
{"jsonrpc":"2.0","method":"subscription","params":{"channel":"book.ETH-PERPETUAL.raw","data":{"timestamp":1734114585826,"type":"change","change_id":15557284343,"instrument_name":"ETH-PERPETUAL","bids":[],"asks":[["new",3896.55,8.0e4]],"prev_change_id":15557284341}}}
{"jsonrpc":"2.0","method":"subscription","params":{"channel":"book.ETH-PERPETUAL.raw","data":{"timestamp":1734114585828,"type":"change","change_id":15557284344,"instrument_name":"ETH-PERPETUAL","bids":[["new",3881.5,8.0e4]],"asks":[],"prev_change_id":15557284343}}}
{"jsonrpc":"2.0","method":"subscription","params":{"channel":"book.ETH-PERPETUAL.raw","data":{"timestamp":1734114585828,"type":"change","change_id":15557284344,"instrument_name":"ETH-PERPETUAL","bids":[["new",3881.5,8.0e4]],"asks":[],"prev_change_id":15557284343}}}
{"jsonrpc":"2.0","method":"subscription","params":{"channel":"book.ETH-PERPETUAL.raw","data":{"timestamp":1734114585829,"type":"change","change_id":15557284345,"instrument_name":"ETH-PERPETUAL","bids":[],"asks":[["change",3896.55,1.0e5]],"prev_change_id":15557284344}}}
{"jsonrpc":"2.0","method":"subscription","params":{"channel":"book.ETH-PERPETUAL.raw","data":{"timestamp":1734114585829,"type":"change","change_id":15557284345,"instrument_name":"ETH-PERPETUAL","bids":[],"asks":[["change",3896.55,1.0e5]],"prev_change_id":15557284344}}}
{"jsonrpc":"2.0","method":"subscription","params":{"channel":"book.ETH-PERPETUAL.raw","data":{"timestamp":1734114585830,"type":"change","change_id":15557284346,"instrument_name":"ETH-PERPETUAL","bids":[],"asks":[["change",3896.55,1.8e5]],"prev_change_id":15557284345}}}
{"jsonrpc":"2.0","method":"subscription","params":{"channel":"book.ETH-PERPETUAL.raw","data":{"timestamp":1734114585830,"type":"change","change_id":15557284346,"instrument_name":"ETH-PERPETUAL","bids":[],"asks":[["change",3896.55,1.8e5]],"prev_change_id":15557284345}}}
{"jsonrpc":"2.0","method":"subscription","params":{"channel":"book.ETH-PERPETUAL.raw","data":{"timestamp":1734114585832,"type":"change","change_id":15557284347,"instrument_name":"ETH-PERPETUAL","bids":[["change",3881.5,1.6e5]],"asks":[],"prev_change_id":15557284346}}}
{"jsonrpc":"2.0","method":"subscription","params":{"channel":"book.ETH-PERPETUAL.raw","data":{"timestamp":1734114585832,"type":"change","change_id":15557284347,"instrument_name":"ETH-PERPETUAL","bids":[["change",3881.5,1.6e5]],"asks":[],"prev_change_id":15557284346}}}
{"jsonrpc":"2.0","method":"subscription","params":{"channel":"book.ETH-PERPETUAL.raw","data":{"timestamp":1734114585833,"type":"change","change_id":15557284348,"instrument_name":"ETH-PERPETUAL","bids":[],"asks":[["change",3896.55,2.0e5]],"prev_change_id":15557284347}}}
{"jsonrpc":"2.0","method":"subscription","params":{"channel":"book.ETH-PERPETUAL.raw","data":{"timestamp":1734114585833,"type":"change","change_id":15557284348,"instrument_name":"ETH-PERPETUAL","bids":[],"asks":[["change",3896.55,2.0e5]],"prev_change_id":15557284347}}}
{"jsonrpc":"2.0","method":"subscription","params":{"channel":"book.ETH-PERPETUAL.raw","data":{"timestamp":1734114585956,"type":"change","change_id":15557284349,"instrument_name":"ETH-PERPETUAL","bids":[["delete",3881.5,0.0]],"asks":[["delete",3896.55,0.0]],"prev_change_id":15557284348}}}
{"jsonrpc":"2.0","method":"subscription","params":{"channel":"book.ETH-PERPETUAL.raw","data":{"timestamp":1734114585956,"type":"change","change_id":15557284349,"instrument_name":"ETH-PERPETUAL","bids":[["delete",3881.5,0.0]],"asks":[["delete",3896.55,0.0]],"prev_change_id":15557284348}}}
{"jsonrpc":"2.0","method":"subscription","params":{"channel":"book.ETH-PERPETUAL.raw","data":{"timestamp":1734114586174,"type":"change","change_id":15557284350,"instrument_name":"ETH-PERPETUAL","bids":[],"asks":[["new",3896.55,8.0e4]],"prev_change_id":15557284349}}}
{"jsonrpc":"2.0","method":"subscription","params":{"channel":"book.ETH-PERPETUAL.raw","data":{"timestamp":1734114586174,"type":"change","change_id":15557284350,"instrument_name":"ETH-PERPETUAL","bids":[],"asks":[["new",3896.55,8.0e4]],"prev_change_id":15557284349}}}
{"jsonrpc":"2.0","method":"subscription","params":{"channel":"book.ETH-PERPETUAL.raw","data":{"timestamp":1734114586175,"type":"change","change_id":15557284351,"instrument_name":"ETH-PERPETUAL","bids":[["new",3881.5,8.0e4]],"asks":[],"prev_change_id":15557284350}}}
{"jsonrpc":"2.0","method":"subscription","params":{"channel":"book.ETH-PERPETUAL.raw","data":{"timestamp":1734114586175,"type":"change","change_id":15557284351,"instrument_name":"ETH-PERPETUAL","bids":[["new",3881.5,8.0e4]],"asks":[],"prev_change_id":15557284350}}}
{"jsonrpc":"2.0","method":"subscription","params":{"channel":"book.ETH-PERPETUAL.raw","data":{"timestamp":1734114586176,"type":"change","change_id":15557284352,"instrument_name":"ETH-PERPETUAL","bids":[],"asks":[["change",3896.55,1.0e5]],"prev_change_id":15557284351}}}
{"jsonrpc":"2.0","method":"subscription","params":{"channel":"book.ETH-PERPETUAL.raw","data":{"timestamp":1734114586176,"type":"change","change_id":15557284352,"instrument_name":"ETH-PERPETUAL","bids":[],"asks":[["change",3896.55,1.0e5]],"prev_change_id":15557284351}}}
{"jsonrpc":"2.0","method":"subscription","params":{"channel":"book.ETH-PERPETUAL.raw","data":{"timestamp":1734114586177,"type":"change","change_id":15557284353,"instrument_name":"ETH-PERPETUAL","bids":[],"asks":[["change",3896.55,1.8e5]],"prev_change_id":15557284352}}}
{"jsonrpc":"2.0","method":"subscription","params":{"channel":"book.ETH-PERPETUAL.raw","data":{"timestamp":1734114586177,"type":"change","change_id":15557284353,"instrument_name":"ETH-PERPETUAL","bids":[],"asks":[["change",3896.55,1.8e5]],"prev_change_id":15557284352}}}
{"jsonrpc":"2.0","method":"subscription","params":{"channel":"book.ETH-PERPETUAL.raw","data":{"timestamp":1734114586178,"type":"change","change_id":15557284354,"instrument_name":"ETH-PERPETUAL","bids":[["change",3881.5,1.6e5]],"asks":[],"prev_change_id":15557284353}}}
{"jsonrpc":"2.0","method":"subscription","params":{"channel":"book.ETH-PERPETUAL.raw","data":{"timestamp":1734114586178,"type":"change","change_id":15557284354,"instrument_name":"ETH-PERPETUAL","bids":[["change",3881.5,1.6e5]],"asks":[],"prev_change_id":15557284353}}}
{"jsonrpc":"2.0","method":"subscription","params":{"channel":"book.ETH-PERPETUAL.raw","data":{"timestamp":1734114586180,"type":"change","change_id":15557284355,"instrument_name":"ETH-PERPETUAL","bids":[],"asks":[["change",3896.55,2.0e5]],"prev_change_id":15557284354}}}
{"jsonrpc":"2.0","method":"subscription","params":{"channel":"book.ETH-PERPETUAL.raw","data":{"timestamp":1734114586180,"type":"change","change_id":15557284355,"instrument_name":"ETH-PERPETUAL","bids":[],"asks":[["change",3896.55,2.0e5]],"prev_change_id":15557284354}}}
{"jsonrpc":"2.0","method":"subscription","params":{"channel":"book.ETH-PERPETUAL.raw","data":{"timestamp":1734114586309,"type":"change","change_id":15557284356,"instrument_name":"ETH-PERPETUAL","bids":[["delete",3881.5,0.0]],"asks":[["delete",3896.55,0.0]],"prev_change_id":15557284355}}}
{"jsonrpc":"2.0","method":"subscription","params":{"channel":"book.ETH-PERPETUAL.raw","data":{"timestamp":1734114586309,"type":"change","change_id":15557284356,"instrument_name":"ETH-PERPETUAL","bids":[["delete",3881.5,0.0]],"asks":[["delete",3896.55,0.0]],"prev_change_id":15557284355}}}
{"jsonrpc":"2.0","method":"subscription","params":{"channel":"book.ETH-PERPETUAL.raw","data":{"timestamp":1734114586477,"type":"change","change_id":15557284358,"instrument_name":"ETH-PERPETUAL","bids":[["new",3881.55,8.0e4]],"asks":[],"prev_change_id":15557284356}}}
{"jsonrpc":"2.0","method":"subscription","params":{"channel":"book.ETH-PERPETUAL.raw","data":{"timestamp":1734114586477,"type":"change","change_id":15557284358,"instrument_name":"ETH-PERPETUAL","bids":[["new",3881.55,8.0e4]],"asks":[],"prev_change_id":15557284356}}}
{"jsonrpc":"2.0","method":"subscription","params":{"channel":"book.ETH-PERPETUAL.raw","data":{"timestamp":1734114586478,"type":"change","change_id":15557284359,"instrument_name":"ETH-PERPETUAL","bids":[],"asks":[["new",3896.55,8.0e4]],"prev_change_id":15557284358}}}
{"jsonrpc":"2.0","method":"subscription","params":{"channel":"book.ETH-PERPETUAL.raw","data":{"timestamp":1734114586478,"type":"change","change_id":15557284359,"instrument_name":"ETH-PERPETUAL","bids":[],"asks":[["new",3896.55,8.0e4]],"prev_change_id":15557284358}}}
{"jsonrpc":"2.0","method":"subscription","params":{"channel":"book.ETH-PERPETUAL.raw","data":{"timestamp":1734114586480,"type":"change","change_id":15557284360,"instrument_name":"ETH-PERPETUAL","bids":[["change",3881.55,1.6e5]],"asks":[],"prev_change_id":15557284359}}}
{"jsonrpc":"2.0","method":"subscription","params":{"channel":"book.ETH-PERPETUAL.raw","data":{"timestamp":1734114586480,"type":"change","change_id":15557284360,"instrument_name":"ETH-PERPETUAL","bids":[["change",3881.55,1.6e5]],"asks":[],"prev_change_id":15557284359}}}
{"jsonrpc":"2.0","method":"subscription","params":{"channel":"book.ETH-PERPETUAL.raw","data":{"timestamp":1734114586481,"type":"change","change_id":15557284361,"instrument_name":"ETH-PERPETUAL","bids":[],"asks":[["change",3896.55,1.6e5]],"prev_change_id":15557284360}}}
{"jsonrpc":"2.0","method":"subscription","params":{"channel":"book.ETH-PERPETUAL.raw","data":{"timestamp":1734114586481,"type":"change","change_id":15557284361,"instrument_name":"ETH-PERPETUAL","bids":[],"asks":[["change",3896.55,1.6e5]],"prev_change_id":15557284360}}}
{"jsonrpc":"2.0","method":"subscription","params":{"channel":"book.ETH-PERPETUAL.raw","data":{"timestamp":1734114586658,"type":"change","change_id":15557284370,"instrument_name":"ETH-PERPETUAL","bids":[["delete",3881.55,0.0]],"asks":[["delete",3896.55,0.0]],"prev_change_id":15557284361}}}
{"jsonrpc":"2.0","method":"subscription","params":{"channel":"book.ETH-PERPETUAL.raw","data":{"timestamp":1734114586658,"type":"change","change_id":15557284370,"instrument_name":"ETH-PERPETUAL","bids":[["delete",3881.55,0.0]],"asks":[["delete",3896.55,0.0]],"prev_change_id":15557284361}}}
{"jsonrpc":"2.0","method":"subscription","params":{"channel":"book.ETH-PERPETUAL.raw","data":{"timestamp":1734114586804,"type":"change","change_id":15557284373,"instrument_name":"ETH-PERPETUAL","bids":[],"asks":[["delete",3935.4,0.0],["new",3947.75,700.0]],"prev_change_id":15557284370}}}
{"jsonrpc":"2.0","method":"subscription","params":{"channel":"book.ETH-PERPETUAL.raw","data":{"timestamp":1734114586804,"type":"change","change_id":15557284373,"instrument_name":"ETH-PERPETUAL","bids":[],"asks":[["delete",3935.4,0.0],["new",3947.75,700.0]],"prev_change_id":15557284370}}}
{"jsonrpc":"2.0","method":"subscription","params":{"channel":"book.ETH-PERPETUAL.raw","data":{"timestamp":1734114586844,"type":"change","change_id":15557284374,"instrument_name":"ETH-PERPETUAL","bids":[["new",3881.55,8.0e4]],"asks":[],"prev_change_id":15557284373}}}
{"jsonrpc":"2.0","method":"subscription","params":{"channel":"book.ETH-PERPETUAL.raw","data":{"timestamp":1734114586844,"type":"change","change_id":15557284374,"instrument_name":"ETH-PERPETUAL","bids":[["new",3881.55,8.0e4]],"asks":[],"prev_change_id":15557284373}}}
{"jsonrpc":"2.0","method":"subscription","params":{"channel":"book.ETH-PERPETUAL.raw","data":{"timestamp":1734114586845,"type":"change","change_id":15557284375,"instrument_name":"ETH-PERPETUAL","bids":[],"asks":[["new",3896.55,8.0e4]],"prev_change_id":15557284374}}}
{"jsonrpc":"2.0","method":"subscription","params":{"channel":"book.ETH-PERPETUAL.raw","data":{"timestamp":1734114586845,"type":"change","change_id":15557284375,"instrument_name":"ETH-PERPETUAL","bids":[],"asks":[["new",3896.55,8.0e4]],"prev_change_id":15557284374}}}
{"jsonrpc":"2.0","method":"subscription","params":{"channel":"book.ETH-PERPETUAL.raw","data":{"timestamp":1734114586846,"type":"change","change_id":15557284376,"instrument_name":"ETH-PERPETUAL","bids":[],"asks":[["change",3896.55,1.0e5]],"prev_change_id":15557284375}}}
{"jsonrpc":"2.0","method":"subscription","params":{"channel":"book.ETH-PERPETUAL.raw","data":{"timestamp":1734114586846,"type":"change","change_id":15557284376,"instrument_name":"ETH-PERPETUAL","bids":[],"asks":[["change",3896.55,1.0e5]],"prev_change_id":15557284375}}}
{"jsonrpc":"2.0","method":"subscription","params":{"channel":"book.ETH-PERPETUAL.raw","data":{"timestamp":1734114586847,"type":"change","change_id":15557284377,"instrument_name":"ETH-PERPETUAL","bids":[["change",3881.55,1.0e5]],"asks":[],"prev_change_id":15557284376}}}
{"jsonrpc":"2.0","method":"subscription","params":{"channel":"book.ETH-PERPETUAL.raw","data":{"timestamp":1734114586847,"type":"change","change_id":15557284377,"instrument_name":"ETH-PERPETUAL","bids":[["change",3881.55,1.0e5]],"asks":[],"prev_change_id":15557284376}}}
{"jsonrpc":"2.0","method":"subscription","params":{"channel":"book.ETH-PERPETUAL.raw","data":{"timestamp":1734114586853,"type":"change","change_id":15557284378,"instrument_name":"ETH-PERPETUAL","bids":[["change",3881.55,1.8e5]],"asks":[],"prev_change_id":15557284377}}}
{"jsonrpc":"2.0","method":"subscription","params":{"channel":"book.ETH-PERPETUAL.raw","data":{"timestamp":1734114586853,"type":"change","change_id":15557284378,"instrument_name":"ETH-PERPETUAL","bids":[["change",3881.55,1.8e5]],"asks":[],"prev_change_id":15557284377}}}
{"jsonrpc":"2.0","method":"subscription","params":{"channel":"book.ETH-PERPETUAL.raw","data":{"timestamp":1734114586854,"type":"change","change_id":15557284379,"instrument_name":"ETH-PERPETUAL","bids":[],"asks":[["change",3896.55,1.8e5]],"prev_change_id":15557284378}}}
{"jsonrpc":"2.0","method":"subscription","params":{"channel":"book.ETH-PERPETUAL.raw","data":{"timestamp":1734114586854,"type":"change","change_id":15557284379,"instrument_name":"ETH-PERPETUAL","bids":[],"asks":[["change",3896.55,1.8e5]],"prev_change_id":15557284378}}}
{"jsonrpc":"2.0","method":"subscription","params":{"channel":"book.ETH-PERPETUAL.raw","data":{"timestamp":1734114586855,"type":"change","change_id":15557284380,"instrument_name":"ETH-PERPETUAL","bids":[],"asks":[["change",3896.55,2.0e5]],"prev_change_id":15557284379}}}
{"jsonrpc":"2.0","method":"subscription","params":{"channel":"book.ETH-PERPETUAL.raw","data":{"timestamp":1734114586855,"type":"change","change_id":15557284380,"instrument_name":"ETH-PERPETUAL","bids":[],"asks":[["change",3896.55,2.0e5]],"prev_change_id":15557284379}}}
{"jsonrpc":"2.0","method":"subscription","params":{"channel":"book.ETH-PERPETUAL.raw","data":{"timestamp":1734114586856,"type":"change","change_id":15557284381,"instrument_name":"ETH-PERPETUAL","bids":[["change",3881.55,2.0e5]],"asks":[],"prev_change_id":15557284380}}}
{"jsonrpc":"2.0","method":"subscription","params":{"channel":"book.ETH-PERPETUAL.raw","data":{"timestamp":1734114586856,"type":"change","change_id":15557284381,"instrument_name":"ETH-PERPETUAL","bids":[["change",3881.55,2.0e5]],"asks":[],"prev_change_id":15557284380}}}
{"jsonrpc":"2.0","method":"subscription","params":{"channel":"book.ETH-PERPETUAL.raw","data":{"timestamp":1734114586935,"type":"change","change_id":15557284395,"instrument_name":"ETH-PERPETUAL","bids":[["delete",3881.55,0.0]],"asks":[["delete",3896.55,0.0]],"prev_change_id":15557284381}}}
{"jsonrpc":"2.0","method":"subscription","params":{"channel":"book.ETH-PERPETUAL.raw","data":{"timestamp":1734114586935,"type":"change","change_id":15557284395,"instrument_name":"ETH-PERPETUAL","bids":[["delete",3881.55,0.0]],"asks":[["delete",3896.55,0.0]],"prev_change_id":15557284381}}}
{"jsonrpc":"2.0","method":"subscription","params":{"channel":"book.ETH-PERPETUAL.raw","data":{"timestamp":1734114587106,"type":"change","change_id":15557284396,"instrument_name":"ETH-PERPETUAL","bids":[["new",3881.55,8.0e4]],"asks":[],"prev_change_id":15557284395}}}
{"jsonrpc":"2.0","method":"subscription","params":{"channel":"book.ETH-PERPETUAL.raw","data":{"timestamp":1734114587106,"type":"change","change_id":15557284396,"instrument_name":"ETH-PERPETUAL","bids":[["new",3881.55,8.0e4]],"asks":[],"prev_change_id":15557284395}}}
{"jsonrpc":"2.0","method":"subscription","params":{"channel":"book.ETH-PERPETUAL.raw","data":{"timestamp":1734114587108,"type":"change","change_id":15557284397,"instrument_name":"ETH-PERPETUAL","bids":[],"asks":[["new",3896.55,8.0e4]],"prev_change_id":15557284396}}}
{"jsonrpc":"2.0","method":"subscription","params":{"channel":"book.ETH-PERPETUAL.raw","data":{"timestamp":1734114587108,"type":"change","change_id":15557284397,"instrument_name":"ETH-PERPETUAL","bids":[],"asks":[["new",3896.55,8.0e4]],"prev_change_id":15557284396}}}
{"jsonrpc":"2.0","method":"subscription","params":{"channel":"book.ETH-PERPETUAL.raw","data":{"timestamp":1734114587110,"type":"change","change_id":15557284398,"instrument_name":"ETH-PERPETUAL","bids":[["change",3881.55,1.6e5]],"asks":[],"prev_change_id":15557284397}}}
{"jsonrpc":"2.0","method":"subscription","params":{"channel":"book.ETH-PERPETUAL.raw","data":{"timestamp":1734114587110,"type":"change","change_id":15557284398,"instrument_name":"ETH-PERPETUAL","bids":[["change",3881.55,1.6e5]],"asks":[],"prev_change_id":15557284397}}}
{"jsonrpc":"2.0","method":"subscription","params":{"channel":"book.ETH-PERPETUAL.raw","data":{"timestamp":1734114587112,"type":"change","change_id":15557284399,"instrument_name":"ETH-PERPETUAL","bids":[],"asks":[["change",3896.55,1.6e5]],"prev_change_id":15557284398}}}
{"jsonrpc":"2.0","method":"subscription","params":{"channel":"book.ETH-PERPETUAL.raw","data":{"timestamp":1734114587112,"type":"change","change_id":15557284399,"instrument_name":"ETH-PERPETUAL","bids":[],"asks":[["change",3896.55,1.6e5]],"prev_change_id":15557284398}}}
{"jsonrpc":"2.0","method":"subscription","params":{"channel":"book.ETH-PERPETUAL.raw","data":{"timestamp":1734114587200,"type":"change","change_id":15557284400,"instrument_name":"ETH-PERPETUAL","bids":[["delete",3881.55,0.0]],"asks":[["delete",3896.55,0.0]],"prev_change_id":15557284399}}}
{"jsonrpc":"2.0","method":"subscription","params":{"channel":"book.ETH-PERPETUAL.raw","data":{"timestamp":1734114587200,"type":"change","change_id":15557284400,"instrument_name":"ETH-PERPETUAL","bids":[["delete",3881.55,0.0]],"asks":[["delete",3896.55,0.0]],"prev_change_id":15557284399}}}
{"jsonrpc":"2.0","method":"subscription","params":{"channel":"book.ETH-PERPETUAL.raw","data":{"timestamp":1734114587367,"type":"change","change_id":15557284401,"instrument_name":"ETH-PERPETUAL","bids":[["new",3881.55,8.0e4]],"asks":[],"prev_change_id":15557284400}}}
{"jsonrpc":"2.0","method":"subscription","params":{"channel":"book.ETH-PERPETUAL.raw","data":{"timestamp":1734114587367,"type":"change","change_id":15557284401,"instrument_name":"ETH-PERPETUAL","bids":[["new",3881.55,8.0e4]],"asks":[],"prev_change_id":15557284400}}}
{"jsonrpc":"2.0","method":"subscription","params":{"channel":"book.ETH-PERPETUAL.raw","data":{"timestamp":1734114587368,"type":"change","change_id":15557284402,"instrument_name":"ETH-PERPETUAL","bids":[],"asks":[["new",3896.55,8.0e4]],"prev_change_id":15557284401}}}
{"jsonrpc":"2.0","method":"subscription","params":{"channel":"book.ETH-PERPETUAL.raw","data":{"timestamp":1734114587368,"type":"change","change_id":15557284402,"instrument_name":"ETH-PERPETUAL","bids":[],"asks":[["new",3896.55,8.0e4]],"prev_change_id":15557284401}}}
{"jsonrpc":"2.0","method":"subscription","params":{"channel":"book.ETH-PERPETUAL.raw","data":{"timestamp":1734114587369,"type":"change","change_id":15557284403,"instrument_name":"ETH-PERPETUAL","bids":[],"asks":[["change",3896.55,1.0e5]],"prev_change_id":15557284402}}}
{"jsonrpc":"2.0","method":"subscription","params":{"channel":"book.ETH-PERPETUAL.raw","data":{"timestamp":1734114587369,"type":"change","change_id":15557284403,"instrument_name":"ETH-PERPETUAL","bids":[],"asks":[["change",3896.55,1.0e5]],"prev_change_id":15557284402}}}
{"jsonrpc":"2.0","method":"subscription","params":{"channel":"book.ETH-PERPETUAL.raw","data":{"timestamp":1734114587371,"type":"change","change_id":15557284404,"instrument_name":"ETH-PERPETUAL","bids":[["change",3881.55,1.0e5]],"asks":[],"prev_change_id":15557284403}}}
{"jsonrpc":"2.0","method":"subscription","params":{"channel":"book.ETH-PERPETUAL.raw","data":{"timestamp":1734114587371,"type":"change","change_id":15557284404,"instrument_name":"ETH-PERPETUAL","bids":[["change",3881.55,1.0e5]],"asks":[],"prev_change_id":15557284403}}}
{"jsonrpc":"2.0","method":"subscription","params":{"channel":"book.ETH-PERPETUAL.raw","data":{"timestamp":1734114587373,"type":"change","change_id":15557284405,"instrument_name":"ETH-PERPETUAL","bids":[["change",3881.55,1.8e5]],"asks":[],"prev_change_id":15557284404}}}
{"jsonrpc":"2.0","method":"subscription","params":{"channel":"book.ETH-PERPETUAL.raw","data":{"timestamp":1734114587373,"type":"change","change_id":15557284405,"instrument_name":"ETH-PERPETUAL","bids":[["change",3881.55,1.8e5]],"asks":[],"prev_change_id":15557284404}}}
{"jsonrpc":"2.0","method":"subscription","params":{"channel":"book.ETH-PERPETUAL.raw","data":{"timestamp":1734114587374,"type":"change","change_id":15557284406,"instrument_name":"ETH-PERPETUAL","bids":[],"asks":[["change",3896.55,1.8e5]],"prev_change_id":15557284405}}}
{"jsonrpc":"2.0","method":"subscription","params":{"channel":"book.ETH-PERPETUAL.raw","data":{"timestamp":1734114587374,"type":"change","change_id":15557284406,"instrument_name":"ETH-PERPETUAL","bids":[],"asks":[["change",3896.55,1.8e5]],"prev_change_id":15557284405}}}
{"jsonrpc":"2.0","method":"subscription","params":{"channel":"book.ETH-PERPETUAL.raw","data":{"timestamp":1734114587375,"type":"change","change_id":15557284407,"instrument_name":"ETH-PERPETUAL","bids":[],"asks":[["change",3896.55,2.0e5]],"prev_change_id":15557284406}}}
{"jsonrpc":"2.0","method":"subscription","params":{"channel":"book.ETH-PERPETUAL.raw","data":{"timestamp":1734114587375,"type":"change","change_id":15557284407,"instrument_name":"ETH-PERPETUAL","bids":[],"asks":[["change",3896.55,2.0e5]],"prev_change_id":15557284406}}}
{"jsonrpc":"2.0","method":"subscription","params":{"channel":"book.ETH-PERPETUAL.raw","data":{"timestamp":1734114587376,"type":"change","change_id":15557284408,"instrument_name":"ETH-PERPETUAL","bids":[["change",3881.55,2.0e5]],"asks":[],"prev_change_id":15557284407}}}
{"jsonrpc":"2.0","method":"subscription","params":{"channel":"book.ETH-PERPETUAL.raw","data":{"timestamp":1734114587376,"type":"change","change_id":15557284408,"instrument_name":"ETH-PERPETUAL","bids":[["change",3881.55,2.0e5]],"asks":[],"prev_change_id":15557284407}}}
{"jsonrpc":"2.0","method":"subscription","params":{"channel":"book.ETH-PERPETUAL.raw","data":{"timestamp":1734114587457,"type":"change","change_id":15557284409,"instrument_name":"ETH-PERPETUAL","bids":[["delete",3881.55,0.0]],"asks":[["delete",3896.55,0.0]],"prev_change_id":15557284408}}}
{"jsonrpc":"2.0","method":"subscription","params":{"channel":"book.ETH-PERPETUAL.raw","data":{"timestamp":1734114587457,"type":"change","change_id":15557284409,"instrument_name":"ETH-PERPETUAL","bids":[["delete",3881.55,0.0]],"asks":[["delete",3896.55,0.0]],"prev_change_id":15557284408}}}
{"jsonrpc":"2.0","method":"subscription","params":{"channel":"book.ETH-PERPETUAL.raw","data":{"timestamp":1734114587722,"type":"change","change_id":15557284411,"instrument_name":"ETH-PERPETUAL","bids":[],"asks":[["new",3896.65,8.0e4]],"prev_change_id":15557284409}}}
{"jsonrpc":"2.0","method":"subscription","params":{"channel":"book.ETH-PERPETUAL.raw","data":{"timestamp":1734114587722,"type":"change","change_id":15557284411,"instrument_name":"ETH-PERPETUAL","bids":[],"asks":[["new",3896.65,8.0e4]],"prev_change_id":15557284409}}}
{"jsonrpc":"2.0","method":"subscription","params":{"channel":"book.ETH-PERPETUAL.raw","data":{"timestamp":1734114587726,"type":"change","change_id":15557284412,"instrument_name":"ETH-PERPETUAL","bids":[["new",3881.65,8.0e4]],"asks":[],"prev_change_id":15557284411}}}
{"jsonrpc":"2.0","method":"subscription","params":{"channel":"book.ETH-PERPETUAL.raw","data":{"timestamp":1734114587726,"type":"change","change_id":15557284412,"instrument_name":"ETH-PERPETUAL","bids":[["new",3881.65,8.0e4]],"asks":[],"prev_change_id":15557284411}}}
{"jsonrpc":"2.0","method":"subscription","params":{"channel":"book.ETH-PERPETUAL.raw","data":{"timestamp":1734114587727,"type":"change","change_id":15557284413,"instrument_name":"ETH-PERPETUAL","bids":[],"asks":[["change",3896.65,1.0e5]],"prev_change_id":15557284412}}}
{"jsonrpc":"2.0","method":"subscription","params":{"channel":"book.ETH-PERPETUAL.raw","data":{"timestamp":1734114587727,"type":"change","change_id":15557284413,"instrument_name":"ETH-PERPETUAL","bids":[],"asks":[["change",3896.65,1.0e5]],"prev_change_id":15557284412}}}
{"jsonrpc":"2.0","method":"subscription","params":{"channel":"book.ETH-PERPETUAL.raw","data":{"timestamp":1734114587729,"type":"change","change_id":15557284414,"instrument_name":"ETH-PERPETUAL","bids":[],"asks":[["change",3896.65,1.8e5]],"prev_change_id":15557284413}}}
{"jsonrpc":"2.0","method":"subscription","params":{"channel":"book.ETH-PERPETUAL.raw","data":{"timestamp":1734114587729,"type":"change","change_id":15557284414,"instrument_name":"ETH-PERPETUAL","bids":[],"asks":[["change",3896.65,1.8e5]],"prev_change_id":15557284413}}}
{"jsonrpc":"2.0","method":"subscription","params":{"channel":"book.ETH-PERPETUAL.raw","data":{"timestamp":1734114587732,"type":"change","change_id":15557284415,"instrument_name":"ETH-PERPETUAL","bids":[["change",3881.65,1.6e5]],"asks":[],"prev_change_id":15557284414}}}
{"jsonrpc":"2.0","method":"subscription","params":{"channel":"book.ETH-PERPETUAL.raw","data":{"timestamp":1734114587732,"type":"change","change_id":15557284415,"instrument_name":"ETH-PERPETUAL","bids":[["change",3881.65,1.6e5]],"asks":[],"prev_change_id":15557284414}}}
{"jsonrpc":"2.0","method":"subscription","params":{"channel":"book.ETH-PERPETUAL.raw","data":{"timestamp":1734114587739,"type":"change","change_id":15557284416,"instrument_name":"ETH-PERPETUAL","bids":[],"asks":[["change",3896.65,2.0e5]],"prev_change_id":15557284415}}}
{"jsonrpc":"2.0","method":"subscription","params":{"channel":"book.ETH-PERPETUAL.raw","data":{"timestamp":1734114587739,"type":"change","change_id":15557284416,"instrument_name":"ETH-PERPETUAL","bids":[],"asks":[["change",3896.65,2.0e5]],"prev_change_id":15557284415}}}
{"jsonrpc":"2.0","method":"subscription","params":{"channel":"book.ETH-PERPETUAL.raw","data":{"timestamp":1734114587844,"type":"change","change_id":15557284419,"instrument_name":"ETH-PERPETUAL","bids":[["delete",3881.65,0.0]],"asks":[["delete",3896.65,0.0]],"prev_change_id":15557284416}}}
{"jsonrpc":"2.0","method":"subscription","params":{"channel":"book.ETH-PERPETUAL.raw","data":{"timestamp":1734114587844,"type":"change","change_id":15557284419,"instrument_name":"ETH-PERPETUAL","bids":[["delete",3881.65,0.0]],"asks":[["delete",3896.65,0.0]],"prev_change_id":15557284416}}}
{"jsonrpc":"2.0","method":"subscription","params":{"channel":"book.ETH-PERPETUAL.raw","data":{"timestamp":1734114588057,"type":"change","change_id":15557284432,"instrument_name":"ETH-PERPETUAL","bids":[],"asks":[["new",3896.65,8.0e4]],"prev_change_id":15557284419}}}
{"jsonrpc":"2.0","method":"subscription","params":{"channel":"book.ETH-PERPETUAL.raw","data":{"timestamp":1734114588057,"type":"change","change_id":15557284432,"instrument_name":"ETH-PERPETUAL","bids":[],"asks":[["new",3896.65,8.0e4]],"prev_change_id":15557284419}}}
{"jsonrpc":"2.0","method":"subscription","params":{"channel":"book.ETH-PERPETUAL.raw","data":{"timestamp":1734114588060,"type":"change","change_id":15557284433,"instrument_name":"ETH-PERPETUAL","bids":[["new",3881.65,8.0e4]],"asks":[],"prev_change_id":15557284432}}}
{"jsonrpc":"2.0","method":"subscription","params":{"channel":"book.ETH-PERPETUAL.raw","data":{"timestamp":1734114588060,"type":"change","change_id":15557284433,"instrument_name":"ETH-PERPETUAL","bids":[["new",3881.65,8.0e4]],"asks":[],"prev_change_id":15557284432}}}
{"jsonrpc":"2.0","method":"subscription","params":{"channel":"book.ETH-PERPETUAL.raw","data":{"timestamp":1734114588062,"type":"change","change_id":15557284434,"instrument_name":"ETH-PERPETUAL","bids":[],"asks":[["change",3896.65,1.0e5]],"prev_change_id":15557284433}}}
{"jsonrpc":"2.0","method":"subscription","params":{"channel":"book.ETH-PERPETUAL.raw","data":{"timestamp":1734114588062,"type":"change","change_id":15557284434,"instrument_name":"ETH-PERPETUAL","bids":[],"asks":[["change",3896.65,1.0e5]],"prev_change_id":15557284433}}}
{"jsonrpc":"2.0","method":"subscription","params":{"channel":"book.ETH-PERPETUAL.raw","data":{"timestamp":1734114588064,"type":"change","change_id":15557284435,"instrument_name":"ETH-PERPETUAL","bids":[["change",3881.65,1.0e5]],"asks":[],"prev_change_id":15557284434}}}
{"jsonrpc":"2.0","method":"subscription","params":{"channel":"book.ETH-PERPETUAL.raw","data":{"timestamp":1734114588064,"type":"change","change_id":15557284435,"instrument_name":"ETH-PERPETUAL","bids":[["change",3881.65,1.0e5]],"asks":[],"prev_change_id":15557284434}}}
{"jsonrpc":"2.0","method":"subscription","params":{"channel":"book.ETH-PERPETUAL.raw","data":{"timestamp":1734114588065,"type":"change","change_id":15557284436,"instrument_name":"ETH-PERPETUAL","bids":[],"asks":[["change",3896.65,1.8e5]],"prev_change_id":15557284435}}}
{"jsonrpc":"2.0","method":"subscription","params":{"channel":"book.ETH-PERPETUAL.raw","data":{"timestamp":1734114588065,"type":"change","change_id":15557284436,"instrument_name":"ETH-PERPETUAL","bids":[],"asks":[["change",3896.65,1.8e5]],"prev_change_id":15557284435}}}
{"jsonrpc":"2.0","method":"subscription","params":{"channel":"book.ETH-PERPETUAL.raw","data":{"timestamp":1734114588067,"type":"change","change_id":15557284437,"instrument_name":"ETH-PERPETUAL","bids":[["change",3881.65,1.8e5]],"asks":[],"prev_change_id":15557284436}}}
{"jsonrpc":"2.0","method":"subscription","params":{"channel":"book.ETH-PERPETUAL.raw","data":{"timestamp":1734114588067,"type":"change","change_id":15557284437,"instrument_name":"ETH-PERPETUAL","bids":[["change",3881.65,1.8e5]],"asks":[],"prev_change_id":15557284436}}}
{"jsonrpc":"2.0","method":"subscription","params":{"channel":"book.ETH-PERPETUAL.raw","data":{"timestamp":1734114588068,"type":"change","change_id":15557284438,"instrument_name":"ETH-PERPETUAL","bids":[],"asks":[["change",3896.65,2.0e5]],"prev_change_id":15557284437}}}
{"jsonrpc":"2.0","method":"subscription","params":{"channel":"book.ETH-PERPETUAL.raw","data":{"timestamp":1734114588068,"type":"change","change_id":15557284438,"instrument_name":"ETH-PERPETUAL","bids":[],"asks":[["change",3896.65,2.0e5]],"prev_change_id":15557284437}}}
