{"jsonrpc":"2.0","id":42,"result":["book.ETH-PERPETUAL.raw"],"usIn":1734114525270509,"usOut":1734114525270630,"usDiff":121,"testnet":true}
{"jsonrpc":"2.0","id":42,"result":["book.ETH-PERPETUAL.raw"],"usIn":1734114525270509,"usOut":1734114525270630,"usDiff":121,"testnet":true}
{"jsonrpc":"2.0","method":"subscription","params":{"channel":"book.ETH-PERPETUAL.raw","data":{"timestamp":1734114525220,"type":"snapshot","change_id":15557280931,"instrument_name":"ETH-PERPETUAL","bids":[["new",3884.1,1.6e5],["new",3872.45,500.0],["new",3872.15,3848.0],["new",3864.7,500.0],["new",3845.3,700.0],["new",3296.95,30.0],["new",3290.5,329.0],["new",3.2e3,42.0],["new",3.0e3,1.0],["new",2937.65,9.0],["new",2933.05,16.0],["new",2928.4,28.0],["new",2923.8,48.0],["new",2919.2,84.0],["new",2914.6,148.0],["new",2909.95,259.0],["new",2905.35,452.0],["new",2.5e3,9.0],["new",2363.0,100.0],["new",2320.0,46.0],["new",2307.0,1.0e3],["new",2.3e3,20.0],["new",2.2e3,4.0],["new",2032.0,100.0],["new",2027.05,1.0],["new",2.0e3,62.0],["new",1988.5,199.0],["new",1988.3,199.0],["new",1953.5,390.0],["new",1.9e3,100.0],["new",1867.1,28.0],["new",1856.8,186.0],["new",1855.7,744.0],["new",1.5e3,1402018.0],["new",1242.0,64580.0],["new",1215.1,223.0],["new",1.2e3,1.0],["new",1199.9,1.0e4],["new",1193.9,2.0e4],["new",1102.0,43740.0],["new",1.0e3,107.0],["new",942.0,131220.0],["new",900.0,4.5e3],["new",800.0,1.74e4],["new",762.0,393660.0],["new",750.8,386.0],["new",701.0,45.0],["new",691.0,49.0],["new",681.0,53.0],["new",671.0,56.0],["new",661.0,59.0],["new",651.0,61.0],["new",641.0,61.0],["new",631.0,62.0],["new",623.45,915.0],["new",621.0,62.0],["new",611.0,60.0],["new",601.0,58.0],["new",600.0,2.5e3],["new",591.0,55.0],["new",581.0,52.0],["new",571.0,47.0],["new",561.0,43.0],["new",551.0,37.0],["new",541.0,32.0],["new",531.0,27.0],["new",521.0,22.0],["new",511.0,17.0],["new",501.0,13.0],["new",500.0,3090.0],["new",400.0,250029.0],["new",332.1,301.0],["new",324.65,482.0],["new",317.2,784.0],["new",309.75,1267.0],["new",302.35,2052.0],["new",300.0,251006.0],["new",294.9,3320.0],["new",287.45,5372.0],["new",280.75,186374.0],["new",260.0,5.0e5],["new",212.0,2.0],["new",200.0,20.0],["new",195.0,2.0e3],["new",181.0,1.2e5],["new",172.05,30.0],["new",143.55,20.0],["new",140.0,1.0e5],["new",135.0,200010.0],["new",130.0,300020.0],["new",125.0,400020.0],["new",120.0,30.0],["new",115.0,20.0],["new",110.0,30.0],["new",105.0,20.0],["new",100.0,72.0],["new",58.0,1.0],["new",50.0,680.0],["new",45.0,1.0e7],["new",22.2,1.0],["new",21.0,10.0],["new",20.0,2140.0],["new",10.0,112.0],["new",9.95,1.0],["new",5.0,3.0],["new",1.45,1330.0],["new",1.0,10.0],["new",0.5,1.0]],"asks":[["new",3899.6,2.0e5],["new",3910.0,1117705140.0],["new",3910.2,1.0],["new",3911.55,500.0],["new",3922.6,100.0],["new",3929.55,500.0],["new",3936.75,5687648.0],["new",3949.1,800.0],["new",4.5e3,135.0],["new",5.0e3,15450.0],["new",5349.75,2140.0],["new",5555.0,10001.0],["new",5932.7,593.0],["new",6023.55,1204.0],["new",6068.0,607.0],["new",7180.4,1.0],["new",9999.95,1.0],["new",1.0e4,5.0],["new",18285.0,3.0e4],["new",2.0e4,3.4e3],["new",3.85e4,40.0],["new",51853.0,10.0]]}}}
{"jsonrpc":"2.0","method":"subscription","params":{"channel":"book.ETH-PERPETUAL.raw","data":{"timestamp":1734114525220,"type":"snapshot","change_id":15557280931,"instrument_name":"ETH-PERPETUAL","bids":[["new",3884.1,1.6e5],["new",3872.45,500.0],["new",3872.15,3848.0],["new",3864.7,500.0],["new",3845.3,700.0],["new",3296.95,30.0],["new",3290.5,329.0],["new",3.2e3,42.0],["new",3.0e3,1.0],["new",2937.65,9.0],["new",2933.05,16.0],["new",2928.4,28.0],["new",2923.8,48.0],["new",2919.2,84.0],["new",2914.6,148.0],["new",2909.95,259.0],["new",2905.35,452.0],["new",2.5e3,9.0],["new",2363.0,100.0],["new",2320.0,46.0],["new",2307.0,1.0e3],["new",2.3e3,20.0],["new",2.2e3,4.0],["new",2032.0,100.0],["new",2027.05,1.0],["new",2.0e3,62.0],["new",1988.5,199.0],["new",1988.3,199.0],["new",1953.5,390.0],["new",1.9e3,100.0],["new",1867.1,28.0],["new",1856.8,186.0],["new",1855.7,744.0],["new",1.5e3,1402018.0],["new",1242.0,64580.0],["new",1215.1,223.0],["new",1.2e3,1.0],["new",1199.9,1.0e4],["new",1193.9,2.0e4],["new",1102.0,43740.0],["new",1.0e3,107.0],["new",942.0,131220.0],["new",900.0,4.5e3],["new",800.0,1.74e4],["new",762.0,393660.0],["new",750.8,386.0],["new",701.0,45.0],["new",691.0,49.0],["new",681.0,53.0],["new",671.0,56.0],["new",661.0,59.0],["new",651.0,61.0],["new",641.0,61.0],["new",631.0,62.0],["new",623.45,915.0],["new",621.0,62.0],["new",611.0,60.0],["new",601.0,58.0],["new",600.0,2.5e3],["new",591.0,55.0],["new",581.0,52.0],["new",571.0,47.0],["new",561.0,43.0],["new",551.0,37.0],["new",541.0,32.0],["new",531.0,27.0],["new",521.0,22.0],["new",511.0,17.0],["new",501.0,13.0],["new",500.0,3090.0],["new",400.0,250029.0],["new",332.1,301.0],["new",324.65,482.0],["new",317.2,784.0],["new",309.75,1267.0],["new",302.35,2052.0],["new",300.0,251006.0],["new",294.9,3320.0],["new",287.45,5372.0],["new",280.75,186374.0],["new",260.0,5.0e5],["new",212.0,2.0],["new",200.0,20.0],["new",195.0,2.0e3],["new",181.0,1.2e5],["new",172.05,30.0],["new",143.55,20.0],["new",140.0,1.0e5],["new",135.0,200010.0],["new",130.0,300020.0],["new",125.0,400020.0],["new",120.0,30.0],["new",115.0,20.0],["new",110.0,30.0],["new",105.0,20.0],["new",100.0,72.0],["new",58.0,1.0],["new",50.0,680.0],["new",45.0,1.0e7],["new",22.2,1.0],["new",21.0,10.0],["new",20.0,2140.0],["new",10.0,112.0],["new",9.95,1.0],["new",5.0,3.0],["new",1.45,1330.0],["new",1.0,10.0],["new",0.5,1.0]],"asks":[["new",3899.6,2.0e5],["new",3910.0,1117705140.0],["new",3910.2,1.0],["new",3911.55,500.0],["new",3922.6,100.0],["new",3929.55,500.0],["new",3936.75,5687648.0],["new",3949.1,800.0],["new",4.5e3,135.0],["new",5.0e3,15450.0],["new",5349.75,2140.0],["new",5555.0,10001.0],["new",5932.7,593.0],["new",6023.55,1204.0],["new",6068.0,607.0],["new",7180.4,1.0],["new",9999.95,1.0],["new",1.0e4,5.0],["new",18285.0,3.0e4],["new",2.0e4,3.4e3],["new",3.85e4,40.0],["new",51853.0,10.0]]}}}
{"jsonrpc":"2.0","method":"subscription","params":{"channel":"book.ETH-PERPETUAL.raw","data":{"timestamp":1734114525341,"type":"change","change_id":15557280932,"instrument_name":"ETH-PERPETUAL","bids":[["delete",3884.1,0.0]],"asks":[["delete",3899.6,0.0]],"prev_change_id":15557280931}}}
{"jsonrpc":"2.0","method":"subscription","params":{"channel":"book.ETH-PERPETUAL.raw","data":{"timestamp":1734114525341,"type":"change","change_id":15557280932,"instrument_name":"ETH-PERPETUAL","bids":[["delete",3884.1,0.0]],"asks":[["delete",3899.6,0.0]],"prev_change_id":15557280931}}}
{"jsonrpc":"2.0","method":"subscription","params":{"channel":"book.ETH-PERPETUAL.raw","data":{"timestamp":1734114525525,"type":"change","change_id":15557280946,"instrument_name":"ETH-PERPETUAL","bids":[],"asks":[["new",3899.55,8.0e4]],"prev_change_id":15557280932}}}
{"jsonrpc":"2.0","method":"subscription","params":{"channel":"book.ETH-PERPETUAL.raw","data":{"timestamp":1734114525525,"type":"change","change_id":15557280946,"instrument_name":"ETH-PERPETUAL","bids":[],"asks":[["new",3899.55,8.0e4]],"prev_change_id":15557280932}}}
{"jsonrpc":"2.0","method":"subscription","params":{"channel":"book.ETH-PERPETUAL.raw","data":{"timestamp":1734114525527,"type":"change","change_id":15557280947,"instrument_name":"ETH-PERPETUAL","bids":[["new",3884.15,8.0e4]],"asks":[],"prev_change_id":15557280946}}}
{"jsonrpc":"2.0","method":"subscription","params":{"channel":"book.ETH-PERPETUAL.raw","data":{"timestamp":1734114525527,"type":"change","change_id":15557280947,"instrument_name":"ETH-PERPETUAL","bids":[["new",3884.15,8.0e4]],"asks":[],"prev_change_id":15557280946}}}
{"jsonrpc":"2.0","method":"subscription","params":{"channel":"book.ETH-PERPETUAL.raw","data":{"timestamp":1734114525528,"type":"change","change_id":15557280948,"instrument_name":"ETH-PERPETUAL","bids":[],"asks":[["change",3899.55,1.0e5]],"prev_change_id":15557280947}}}
{"jsonrpc":"2.0","method":"subscription","params":{"channel":"book.ETH-PERPETUAL.raw","data":{"timestamp":1734114525528,"type":"change","change_id":15557280948,"instrument_name":"ETH-PERPETUAL","bids":[],"asks":[["change",3899.55,1.0e5]],"prev_change_id":15557280947}}}
{"jsonrpc":"2.0","method":"subscription","params":{"channel":"book.ETH-PERPETUAL.raw","data":{"timestamp":1734114525530,"type":"change","change_id":15557280949,"instrument_name":"ETH-PERPETUAL","bids":[["change",3884.15,1.0e5]],"asks":[],"prev_change_id":15557280948}}}
{"jsonrpc":"2.0","method":"subscription","params":{"channel":"book.ETH-PERPETUAL.raw","data":{"timestamp":1734114525530,"type":"change","change_id":15557280949,"instrument_name":"ETH-PERPETUAL","bids":[["change",3884.15,1.0e5]],"asks":[],"prev_change_id":15557280948}}}
{"jsonrpc":"2.0","method":"subscription","params":{"channel":"book.ETH-PERPETUAL.raw","data":{"timestamp":1734114525531,"type":"change","change_id":15557280950,"instrument_name":"ETH-PERPETUAL","bids":[],"asks":[["change",3899.55,1.8e5]],"prev_change_id":15557280949}}}
{"jsonrpc":"2.0","method":"subscription","params":{"channel":"book.ETH-PERPETUAL.raw","data":{"timestamp":1734114525531,"type":"change","change_id":15557280950,"instrument_name":"ETH-PERPETUAL","bids":[],"asks":[["change",3899.55,1.8e5]],"prev_change_id":15557280949}}}
{"jsonrpc":"2.0","method":"subscription","params":{"channel":"book.ETH-PERPETUAL.raw","data":{"timestamp":1734114525532,"type":"change","change_id":15557280951,"instrument_name":"ETH-PERPETUAL","bids":[["change",3884.15,1.8e5]],"asks":[],"prev_change_id":15557280950}}}
{"jsonrpc":"2.0","method":"subscription","params":{"channel":"book.ETH-PERPETUAL.raw","data":{"timestamp":1734114525532,"type":"change","change_id":15557280951,"instrument_name":"ETH-PERPETUAL","bids":[["change",3884.15,1.8e5]],"asks":[],"prev_change_id":15557280950}}}
{"jsonrpc":"2.0","method":"subscription","params":{"channel":"book.ETH-PERPETUAL.raw","data":{"timestamp":1734114525534,"type":"change","change_id":15557280952,"instrument_name":"ETH-PERPETUAL","bids":[],"asks":[["change",3899.55,2.0e5]],"prev_change_id":15557280951}}}
{"jsonrpc":"2.0","method":"subscription","params":{"channel":"book.ETH-PERPETUAL.raw","data":{"timestamp":1734114525534,"type":"change","change_id":15557280952,"instrument_name":"ETH-PERPETUAL","bids":[],"asks":[["change",3899.55,2.0e5]],"prev_change_id":15557280951}}}
{"jsonrpc":"2.0","method":"subscription","params":{"channel":"book.ETH-PERPETUAL.raw","data":{"timestamp":1734114525535,"type":"change","change_id":15557280953,"instrument_name":"ETH-PERPETUAL","bids":[["change",3884.15,2.0e5]],"asks":[],"prev_change_id":15557280952}}}
{"jsonrpc":"2.0","method":"subscription","params":{"channel":"book.ETH-PERPETUAL.raw","data":{"timestamp":1734114525535,"type":"change","change_id":15557280953,"instrument_name":"ETH-PERPETUAL","bids":[["change",3884.15,2.0e5]],"asks":[],"prev_change_id":15557280952}}}
{"jsonrpc":"2.0","method":"subscription","params":{"channel":"book.ETH-PERPETUAL.raw","data":{"timestamp":1734114525658,"type":"change","change_id":15557280954,"instrument_name":"ETH-PERPETUAL","bids":[["delete",3884.15,0.0]],"asks":[["delete",3899.55,0.0]],"prev_change_id":15557280953}}}
{"jsonrpc":"2.0","method":"subscription","params":{"channel":"book.ETH-PERPETUAL.raw","data":{"timestamp":1734114525658,"type":"change","change_id":15557280954,"instrument_name":"ETH-PERPETUAL","bids":[["delete",3884.15,0.0]],"asks":[["delete",3899.55,0.0]],"prev_change_id":15557280953}}}
{"jsonrpc":"2.0","method":"subscription","params":{"channel":"book.ETH-PERPETUAL.raw","data":{"timestamp":1734114525828,"type":"change","change_id":15557280955,"instrument_name":"ETH-PERPETUAL","bids":[],"asks":[["new",3899.55,8.0e4]],"prev_change_id":15557280954}}}
{"jsonrpc":"2.0","method":"subscription","params":{"channel":"book.ETH-PERPETUAL.raw","data":{"timestamp":1734114525828,"type":"change","change_id":15557280955,"instrument_name":"ETH-PERPETUAL","bids":[],"asks":[["new",3899.55,8.0e4]],"prev_change_id":15557280954}}}
{"jsonrpc":"2.0","method":"subscription","params":{"channel":"book.ETH-PERPETUAL.raw","data":{"timestamp":1734114525829,"type":"change","change_id":15557280956,"instrument_name":"ETH-PERPETUAL","bids":[["new",3884.15,8.0e4]],"asks":[],"prev_change_id":15557280955}}}
{"jsonrpc":"2.0","method":"subscription","params":{"channel":"book.ETH-PERPETUAL.raw","data":{"timestamp":1734114525829,"type":"change","change_id":15557280956,"instrument_name":"ETH-PERPETUAL","bids":[["new",3884.15,8.0e4]],"asks":[],"prev_change_id":15557280955}}}
{"jsonrpc":"2.0","method":"subscription","params":{"channel":"book.ETH-PERPETUAL.raw","data":{"timestamp":1734114525830,"type":"change","change_id":15557280957,"instrument_name":"ETH-PERPETUAL","bids":[],"asks":[["change",3899.55,1.6e5]],"prev_change_id":15557280956}}}
{"jsonrpc":"2.0","method":"subscription","params":{"channel":"book.ETH-PERPETUAL.raw","data":{"timestamp":1734114525830,"type":"change","change_id":15557280957,"instrument_name":"ETH-PERPETUAL","bids":[],"asks":[["change",3899.55,1.6e5]],"prev_change_id":15557280956}}}
{"jsonrpc":"2.0","method":"subscription","params":{"channel":"book.ETH-PERPETUAL.raw","data":{"timestamp":1734114525832,"type":"change","change_id":15557280958,"instrument_name":"ETH-PERPETUAL","bids":[["change",3884.15,1.6e5]],"asks":[],"prev_change_id":15557280957}}}
{"jsonrpc":"2.0","method":"subscription","params":{"channel":"book.ETH-PERPETUAL.raw","data":{"timestamp":1734114525832,"type":"change","change_id":15557280958,"instrument_name":"ETH-PERPETUAL","bids":[["change",3884.15,1.6e5]],"asks":[],"prev_change_id":15557280957}}}
{"jsonrpc":"2.0","method":"subscription","params":{"channel":"book.ETH-PERPETUAL.raw","data":{"timestamp":1734114525971,"type":"change","change_id":15557280959,"instrument_name":"ETH-PERPETUAL","bids":[["delete",3884.15,0.0]],"asks":[["delete",3899.55,0.0]],"prev_change_id":15557280958}}}
{"jsonrpc":"2.0","method":"subscription","params":{"channel":"book.ETH-PERPETUAL.raw","data":{"timestamp":1734114525971,"type":"change","change_id":15557280959,"instrument_name":"ETH-PERPETUAL","bids":[["delete",3884.15,0.0]],"asks":[["delete",3899.55,0.0]],"prev_change_id":15557280958}}}
{"jsonrpc":"2.0","method":"subscription","params":{"channel":"book.ETH-PERPETUAL.raw","data":{"timestamp":1734114526118,"type":"change","change_id":15557280960,"instrument_name":"ETH-PERPETUAL","bids":[],"asks":[["delete",3911.55,0.0],["new",3921.75,500.0]],"prev_change_id":15557280959}}}
{"jsonrpc":"2.0","method":"subscription","params":{"channel":"book.ETH-PERPETUAL.raw","data":{"timestamp":1734114526118,"type":"change","change_id":15557280960,"instrument_name":"ETH-PERPETUAL","bids":[],"asks":[["delete",3911.55,0.0],["new",3921.75,500.0]],"prev_change_id":15557280959}}}
{"jsonrpc":"2.0","method":"subscription","params":{"channel":"book.ETH-PERPETUAL.raw","data":{"timestamp":1734114526159,"type":"change","change_id":15557280961,"instrument_name":"ETH-PERPETUAL","bids":[],"asks":[["new",3899.55,8.0e4]],"prev_change_id":15557280960}}}
{"jsonrpc":"2.0","method":"subscription","params":{"channel":"book.ETH-PERPETUAL.raw","data":{"timestamp":1734114526159,"type":"change","change_id":15557280961,"instrument_name":"ETH-PERPETUAL","bids":[],"asks":[["new",3899.55,8.0e4]],"prev_change_id":15557280960}}}
{"jsonrpc":"2.0","method":"subscription","params":{"channel":"book.ETH-PERPETUAL.raw","data":{"timestamp":1734114526160,"type":"change","change_id":15557280962,"instrument_name":"ETH-PERPETUAL","bids":[["new",3884.15,8.0e4]],"asks":[],"prev_change_id":15557280961}}}
{"jsonrpc":"2.0","method":"subscription","params":{"channel":"book.ETH-PERPETUAL.raw","data":{"timestamp":1734114526160,"type":"change","change_id":15557280962,"instrument_name":"ETH-PERPETUAL","bids":[["new",3884.15,8.0e4]],"asks":[],"prev_change_id":15557280961}}}
{"jsonrpc":"2.0","method":"subscription","params":{"channel":"book.ETH-PERPETUAL.raw","data":{"timestamp":1734114526161,"type":"change","change_id":15557280963,"instrument_name":"ETH-PERPETUAL","bids":[],"asks":[["change",3899.55,1.0e5]],"prev_change_id":15557280962}}}
{"jsonrpc":"2.0","method":"subscription","params":{"channel":"book.ETH-PERPETUAL.raw","data":{"timestamp":1734114526161,"type":"change","change_id":15557280963,"instrument_name":"ETH-PERPETUAL","bids":[],"asks":[["change",3899.55,1.0e5]],"prev_change_id":15557280962}}}
{"jsonrpc":"2.0","method":"subscription","params":{"channel":"book.ETH-PERPETUAL.raw","data":{"timestamp":1734114526163,"type":"change","change_id":15557280964,"instrument_name":"ETH-PERPETUAL","bids":[],"asks":[["change",3899.55,1.8e5]],"prev_change_id":15557280963}}}
{"jsonrpc":"2.0","method":"subscription","params":{"channel":"book.ETH-PERPETUAL.raw","data":{"timestamp":1734114526163,"type":"change","change_id":15557280964,"instrument_name":"ETH-PERPETUAL","bids":[],"asks":[["change",3899.55,1.8e5]],"prev_change_id":15557280963}}}
{"jsonrpc":"2.0","method":"subscription","params":{"channel":"book.ETH-PERPETUAL.raw","data":{"timestamp":1734114526164,"type":"change","change_id":15557280965,"instrument_name":"ETH-PERPETUAL","bids":[["change",3884.15,1.6e5]],"asks":[],"prev_change_id":15557280964}}}
{"jsonrpc":"2.0","method":"subscription","params":{"channel":"book.ETH-PERPETUAL.raw","data":{"timestamp":1734114526164,"type":"change","change_id":15557280965,"instrument_name":"ETH-PERPETUAL","bids":[["change",3884.15,1.6e5]],"asks":[],"prev_change_id":15557280964}}}
{"jsonrpc":"2.0","method":"subscription","params":{"channel":"book.ETH-PERPETUAL.raw","data":{"timestamp":1734114526165,"type":"change","change_id":15557280966,"instrument_name":"ETH-PERPETUAL","bids":[],"asks":[["change",3899.55,2.0e5]],"prev_change_id":15557280965}}}
{"jsonrpc":"2.0","method":"subscription","params":{"channel":"book.ETH-PERPETUAL.raw","data":{"timestamp":1734114526165,"type":"change","change_id":15557280966,"instrument_name":"ETH-PERPETUAL","bids":[],"asks":[["change",3899.55,2.0e5]],"prev_change_id":15557280965}}}
{"jsonrpc":"2.0","method":"subscription","params":{"channel":"book.ETH-PERPETUAL.raw","data":{"timestamp":1734114526304,"type":"change","change_id":15557280967,"instrument_name":"ETH-PERPETUAL","bids":[],"asks":[["new",3919.05,500.0],["delete",3929.55,0.0]],"prev_change_id":15557280966}}}
{"jsonrpc":"2.0","method":"subscription","params":{"channel":"book.ETH-PERPETUAL.raw","data":{"timestamp":1734114526304,"type":"change","change_id":15557280967,"instrument_name":"ETH-PERPETUAL","bids":[],"asks":[["new",3919.05,500.0],["delete",3929.55,0.0]],"prev_change_id":15557280966}}}
{"jsonrpc":"2.0","method":"subscription","params":{"channel":"book.ETH-PERPETUAL.raw","data":{"timestamp":1734114526307,"type":"change","change_id":15557280968,"instrument_name":"ETH-PERPETUAL","bids":[["delete",3884.15,0.0]],"asks":[["delete",3899.55,0.0]],"prev_change_id":15557280967}}}
{"jsonrpc":"2.0","method":"subscription","params":{"channel":"book.ETH-PERPETUAL.raw","data":{"timestamp":1734114526307,"type":"change","change_id":15557280968,"instrument_name":"ETH-PERPETUAL","bids":[["delete",3884.15,0.0]],"asks":[["delete",3899.55,0.0]],"prev_change_id":15557280967}}}
{"jsonrpc":"2.0","method":"subscription","params":{"channel":"book.ETH-PERPETUAL.raw","data":{"timestamp":1734114526482,"type":"change","change_id":15557280978,"instrument_name":"ETH-PERPETUAL","bids":[],"asks":[["new",3899.55,8.0e4]],"prev_change_id":15557280968}}}
{"jsonrpc":"2.0","method":"subscription","params":{"channel":"book.ETH-PERPETUAL.raw","data":{"timestamp":1734114526482,"type":"change","change_id":15557280978,"instrument_name":"ETH-PERPETUAL","bids":[],"asks":[["new",3899.55,8.0e4]],"prev_change_id":15557280968}}}
{"jsonrpc":"2.0","method":"subscription","params":{"channel":"book.ETH-PERPETUAL.raw","data":{"timestamp":1734114526484,"type":"change","change_id":15557280980,"instrument_name":"ETH-PERPETUAL","bids":[["new",3884.15,8.0e4]],"asks":[],"prev_change_id":15557280978}}}
{"jsonrpc":"2.0","method":"subscription","params":{"channel":"book.ETH-PERPETUAL.raw","data":{"timestamp":1734114526484,"type":"change","change_id":15557280980,"instrument_name":"ETH-PERPETUAL","bids":[["new",3884.15,8.0e4]],"asks":[],"prev_change_id":15557280978}}}
{"jsonrpc":"2.0","method":"subscription","params":{"channel":"book.ETH-PERPETUAL.raw","data":{"timestamp":1734114526486,"type":"change","change_id":15557280981,"instrument_name":"ETH-PERPETUAL","bids":[],"asks":[["change",3899.55,1.0e5]],"prev_change_id":15557280980}}}
{"jsonrpc":"2.0","method":"subscription","params":{"channel":"book.ETH-PERPETUAL.raw","data":{"timestamp":1734114526486,"type":"change","change_id":15557280981,"instrument_name":"ETH-PERPETUAL","bids":[],"asks":[["change",3899.55,1.0e5]],"prev_change_id":15557280980}}}
{"jsonrpc":"2.0","method":"subscription","params":{"channel":"book.ETH-PERPETUAL.raw","data":{"timestamp":1734114526487,"type":"change","change_id":15557280982,"instrument_name":"ETH-PERPETUAL","bids":[],"asks":[["change",3899.55,1.8e5]],"prev_change_id":15557280981}}}
{"jsonrpc":"2.0","method":"subscription","params":{"channel":"book.ETH-PERPETUAL.raw","data":{"timestamp":1734114526487,"type":"change","change_id":15557280982,"instrument_name":"ETH-PERPETUAL","bids":[],"asks":[["change",3899.55,1.8e5]],"prev_change_id":15557280981}}}
{"jsonrpc":"2.0","method":"subscription","params":{"channel":"book.ETH-PERPETUAL.raw","data":{"timestamp":1734114526489,"type":"change","change_id":15557280983,"instrument_name":"ETH-PERPETUAL","bids":[["change",3884.15,1.6e5]],"asks":[],"prev_change_id":15557280982}}}
{"jsonrpc":"2.0","method":"subscription","params":{"channel":"book.ETH-PERPETUAL.raw","data":{"timestamp":1734114526489,"type":"change","change_id":15557280983,"instrument_name":"ETH-PERPETUAL","bids":[["change",3884.15,1.6e5]],"asks":[],"prev_change_id":15557280982}}}
{"jsonrpc":"2.0","method":"subscription","params":{"channel":"book.ETH-PERPETUAL.raw","data":{"timestamp":1734114526490,"type":"change","change_id":15557280984,"instrument_name":"ETH-PERPETUAL","bids":[],"asks":[["change",3899.55,2.0e5]],"prev_change_id":15557280983}}}
{"jsonrpc":"2.0","method":"subscription","params":{"channel":"book.ETH-PERPETUAL.raw","data":{"timestamp":1734114526490,"type":"change","change_id":15557280984,"instrument_name":"ETH-PERPETUAL","bids":[],"asks":[["change",3899.55,2.0e5]],"prev_change_id":15557280983}}}
{"jsonrpc":"2.0","method":"subscription","params":{"channel":"book.ETH-PERPETUAL.raw","data":{"timestamp":1734114526601,"type":"change","change_id":15557281007,"instrument_name":"ETH-PERPETUAL","bids":[["delete",3884.15,0.0]],"asks":[["delete",3899.55,0.0]],"prev_change_id":15557280984}}}
{"jsonrpc":"2.0","method":"subscription","params":{"channel":"book.ETH-PERPETUAL.raw","data":{"timestamp":1734114526601,"type":"change","change_id":15557281007,"instrument_name":"ETH-PERPETUAL","bids":[["delete",3884.15,0.0]],"asks":[["delete",3899.55,0.0]],"prev_change_id":15557280984}}}
{"jsonrpc":"2.0","method":"subscription","params":{"channel":"book.ETH-PERPETUAL.raw","data":{"timestamp":1734114526771,"type":"change","change_id":15557281008,"instrument_name":"ETH-PERPETUAL","bids":[],"asks":[["new",3899.5,8.0e4]],"prev_change_id":15557281007}}}
{"jsonrpc":"2.0","method":"subscription","params":{"channel":"book.ETH-PERPETUAL.raw","data":{"timestamp":1734114526771,"type":"change","change_id":15557281008,"instrument_name":"ETH-PERPETUAL","bids":[],"asks":[["new",3899.5,8.0e4]],"prev_change_id":15557281007}}}
{"jsonrpc":"2.0","method":"subscription","params":{"channel":"book.ETH-PERPETUAL.raw","data":{"timestamp":1734114526775,"type":"change","change_id":15557281009,"instrument_name":"ETH-PERPETUAL","bids":[["new",3884.15,8.0e4]],"asks":[],"prev_change_id":15557281008}}}
{"jsonrpc":"2.0","method":"subscription","params":{"channel":"book.ETH-PERPETUAL.raw","data":{"timestamp":1734114526775,"type":"change","change_id":15557281009,"instrument_name":"ETH-PERPETUAL","bids":[["new",3884.15,8.0e4]],"asks":[],"prev_change_id":15557281008}}}
{"jsonrpc":"2.0","method":"subscription","params":{"channel":"book.ETH-PERPETUAL.raw","data":{"timestamp":1734114526780,"type":"change","change_id":15557281010,"instrument_name":"ETH-PERPETUAL","bids":[],"asks":[["change",3899.5,1.6e5]],"prev_change_id":15557281009}}}
{"jsonrpc":"2.0","method":"subscription","params":{"channel":"book.ETH-PERPETUAL.raw","data":{"timestamp":1734114526780,"type":"change","change_id":15557281010,"instrument_name":"ETH-PERPETUAL","bids":[],"asks":[["change",3899.5,1.6e5]],"prev_change_id":15557281009}}}
{"jsonrpc":"2.0","method":"subscription","params":{"channel":"book.ETH-PERPETUAL.raw","data":{"timestamp":1734114526781,"type":"change","change_id":15557281011,"instrument_name":"ETH-PERPETUAL","bids":[["change",3884.15,1.6e5]],"asks":[],"prev_change_id":15557281010}}}
{"jsonrpc":"2.0","method":"subscription","params":{"channel":"book.ETH-PERPETUAL.raw","data":{"timestamp":1734114526781,"type":"change","change_id":15557281011,"instrument_name":"ETH-PERPETUAL","bids":[["change",3884.15,1.6e5]],"asks":[],"prev_change_id":15557281010}}}
{"jsonrpc":"2.0","method":"subscription","params":{"channel":"book.ETH-PERPETUAL.raw","data":{"timestamp":1734114526924,"type":"change","change_id":15557281013,"instrument_name":"ETH-PERPETUAL","bids":[["delete",3884.15,0.0]],"asks":[["delete",3899.5,0.0]],"prev_change_id":15557281011}}}
{"jsonrpc":"2.0","method":"subscription","params":{"channel":"book.ETH-PERPETUAL.raw","data":{"timestamp":1734114526924,"type":"change","change_id":15557281013,"instrument_name":"ETH-PERPETUAL","bids":[["delete",3884.15,0.0]],"asks":[["delete",3899.5,0.0]],"prev_change_id":15557281011}}}
{"jsonrpc":"2.0","method":"subscription","params":{"channel":"book.ETH-PERPETUAL.raw","data":{"timestamp":1734114527108,"type":"change","change_id":15557281014,"instrument_name":"ETH-PERPETUAL","bids":[["new",3884.15,8.0e4]],"asks":[],"prev_change_id":15557281013}}}
{"jsonrpc":"2.0","method":"subscription","params":{"channel":"book.ETH-PERPETUAL.raw","data":{"timestamp":1734114527108,"type":"change","change_id":15557281014,"instrument_name":"ETH-PERPETUAL","bids":[["new",3884.15,8.0e4]],"asks":[],"prev_change_id":15557281013}}}
{"jsonrpc":"2.0","method":"subscription","params":{"channel":"book.ETH-PERPETUAL.raw","data":{"timestamp":1734114527109,"type":"change","change_id":15557281015,"instrument_name":"ETH-PERPETUAL","bids":[],"asks":[["new",3899.5,8.0e4]],"prev_change_id":15557281014}}}
{"jsonrpc":"2.0","method":"subscription","params":{"channel":"book.ETH-PERPETUAL.raw","data":{"timestamp":1734114527109,"type":"change","change_id":15557281015,"instrument_name":"ETH-PERPETUAL","bids":[],"asks":[["new",3899.5,8.0e4]],"prev_change_id":15557281014}}}
{"jsonrpc":"2.0","method":"subscription","params":{"channel":"book.ETH-PERPETUAL.raw","data":{"timestamp":1734114527110,"type":"change","change_id":15557281016,"instrument_name":"ETH-PERPETUAL","bids":[],"asks":[["change",3899.5,1.0e5]],"prev_change_id":15557281015}}}
{"jsonrpc":"2.0","method":"subscription","params":{"channel":"book.ETH-PERPETUAL.raw","data":{"timestamp":1734114527110,"type":"change","change_id":15557281016,"instrument_name":"ETH-PERPETUAL","bids":[],"asks":[["change",3899.5,1.0e5]],"prev_change_id":15557281015}}}
{"jsonrpc":"2.0","method":"subscription","params":{"channel":"book.ETH-PERPETUAL.raw","data":{"timestamp":1734114527112,"type":"change","change_id":15557281017,"instrument_name":"ETH-PERPETUAL","bids":[["change",3884.15,1.0e5]],"asks":[],"prev_change_id":15557281016}}}
{"jsonrpc":"2.0","method":"subscription","params":{"channel":"book.ETH-PERPETUAL.raw","data":{"timestamp":1734114527112,"type":"change","change_id":15557281017,"instrument_name":"ETH-PERPETUAL","bids":[["change",3884.15,1.0e5]],"asks":[],"prev_change_id":15557281016}}}
{"jsonrpc":"2.0","method":"subscription","params":{"channel":"book.ETH-PERPETUAL.raw","data":{"timestamp":1734114527114,"type":"change","change_id":15557281018,"instrument_name":"ETH-PERPETUAL","bids":[["change",3884.15,1.8e5]],"asks":[],"prev_change_id":15557281017}}}
{"jsonrpc":"2.0","method":"subscription","params":{"channel":"book.ETH-PERPETUAL.raw","data":{"timestamp":1734114527114,"type":"change","change_id":15557281018,"instrument_name":"ETH-PERPETUAL","bids":[["change",3884.15,1.8e5]],"asks":[],"prev_change_id":15557281017}}}
{"jsonrpc":"2.0","method":"subscription","params":{"channel":"book.ETH-PERPETUAL.raw","data":{"timestamp":1734114527116,"type":"change","change_id":15557281019,"instrument_name":"ETH-PERPETUAL","bids":[],"asks":[["change",3899.5,1.8e5]],"prev_change_id":15557281018}}}
{"jsonrpc":"2.0","method":"subscription","params":{"channel":"book.ETH-PERPETUAL.raw","data":{"timestamp":1734114527116,"type":"change","change_id":15557281019,"instrument_name":"ETH-PERPETUAL","bids":[],"asks":[["change",3899.5,1.8e5]],"prev_change_id":15557281018}}}
{"jsonrpc":"2.0","method":"subscription","params":{"channel":"book.ETH-PERPETUAL.raw","data":{"timestamp":1734114527118,"type":"change","change_id":15557281020,"instrument_name":"ETH-PERPETUAL","bids":[],"asks":[["change",3899.5,2.0e5]],"prev_change_id":15557281019}}}
{"jsonrpc":"2.0","method":"subscription","params":{"channel":"book.ETH-PERPETUAL.raw","data":{"timestamp":1734114527118,"type":"change","change_id":15557281020,"instrument_name":"ETH-PERPETUAL","bids":[],"asks":[["change",3899.5,2.0e5]],"prev_change_id":15557281019}}}
{"jsonrpc":"2.0","method":"subscription","params":{"channel":"book.ETH-PERPETUAL.raw","data":{"timestamp":1734114527119,"type":"change","change_id":15557281021,"instrument_name":"ETH-PERPETUAL","bids":[["change",3884.15,2.0e5]],"asks":[],"prev_change_id":15557281020}}}
{"jsonrpc":"2.0","method":"subscription","params":{"channel":"book.ETH-PERPETUAL.raw","data":{"timestamp":1734114527119,"type":"change","change_id":15557281021,"instrument_name":"ETH-PERPETUAL","bids":[["change",3884.15,2.0e5]],"asks":[],"prev_change_id":15557281020}}}
{"jsonrpc":"2.0","method":"subscription","params":{"channel":"book.ETH-PERPETUAL.raw","data":{"timestamp":1734114527243,"type":"change","change_id":15557281022,"instrument_name":"ETH-PERPETUAL","bids":[["delete",3884.15,0.0]],"asks":[["delete",3899.5,0.0]],"prev_change_id":15557281021}}}
{"jsonrpc":"2.0","method":"subscription","params":{"channel":"book.ETH-PERPETUAL.raw","data":{"timestamp":1734114527243,"type":"change","change_id":15557281022,"instrument_name":"ETH-PERPETUAL","bids":[["delete",3884.15,0.0]],"asks":[["delete",3899.5,0.0]],"prev_change_id":15557281021}}}
{"jsonrpc":"2.0","method":"subscription","params":{"channel":"book.ETH-PERPETUAL.raw","data":{"timestamp":1734114527389,"type":"change","change_id":15557281023,"instrument_name":"ETH-PERPETUAL","bids":[["delete",3845.3,0.0],["new",3833.6,700.0]],"asks":[],"prev_change_id":15557281022}}}
{"jsonrpc":"2.0","method":"subscription","params":{"channel":"book.ETH-PERPETUAL.raw","data":{"timestamp":1734114527389,"type":"change","change_id":15557281023,"instrument_name":"ETH-PERPETUAL","bids":[["delete",3845.3,0.0],["new",3833.6,700.0]],"asks":[],"prev_change_id":15557281022}}}
{"jsonrpc":"2.0","method":"subscription","params":{"channel":"book.ETH-PERPETUAL.raw","data":{"timestamp":1734114527390,"type":"change","change_id":15557281024,"instrument_name":"ETH-PERPETUAL","bids":[["delete",3864.7,0.0],["new",3853.05,500.0]],"asks":[],"prev_change_id":15557281023}}}
{"jsonrpc":"2.0","method":"subscription","params":{"channel":"book.ETH-PERPETUAL.raw","data":{"timestamp":1734114527390,"type":"change","change_id":15557281024,"instrument_name":"ETH-PERPETUAL","bids":[["delete",3864.7,0.0],["new",3853.05,500.0]],"asks":[],"prev_change_id":15557281023}}}
{"jsonrpc":"2.0","method":"subscription","params":{"channel":"book.ETH-PERPETUAL.raw","data":{"timestamp":1734114527391,"type":"change","change_id":15557281025,"instrument_name":"ETH-PERPETUAL","bids":[["delete",3872.45,0.0],["new",3860.8,500.0]],"asks":[],"prev_change_id":15557281024}}}
{"jsonrpc":"2.0","method":"subscription","params":{"channel":"book.ETH-PERPETUAL.raw","data":{"timestamp":1734114527391,"type":"change","change_id":15557281025,"instrument_name":"ETH-PERPETUAL","bids":[["delete",3872.45,0.0],["new",3860.8,500.0]],"asks":[],"prev_change_id":15557281024}}}
{"jsonrpc":"2.0","method":"subscription","params":{"channel":"book.ETH-PERPETUAL.raw","data":{"timestamp":1734114527428,"type":"change","change_id":15557281026,"instrument_name":"ETH-PERPETUAL","bids":[["new",3884.1,8.0e4]],"asks":[],"prev_change_id":15557281025}}}
{"jsonrpc":"2.0","method":"subscription","params":{"channel":"book.ETH-PERPETUAL.raw","data":{"timestamp":1734114527428,"type":"change","change_id":15557281026,"instrument_name":"ETH-PERPETUAL","bids":[["new",3884.1,8.0e4]],"asks":[],"prev_change_id":15557281025}}}
{"jsonrpc":"2.0","method":"subscription","params":{"channel":"book.ETH-PERPETUAL.raw","data":{"timestamp":1734114527429,"type":"change","change_id":15557281027,"instrument_name":"ETH-PERPETUAL","bids":[],"asks":[["new",3899.45,8.0e4]],"prev_change_id":15557281026}}}
{"jsonrpc":"2.0","method":"subscription","params":{"channel":"book.ETH-PERPETUAL.raw","data":{"timestamp":1734114527429,"type":"change","change_id":15557281027,"instrument_name":"ETH-PERPETUAL","bids":[],"asks":[["new",3899.45,8.0e4]],"prev_change_id":15557281026}}}
{"jsonrpc":"2.0","method":"subscription","params":{"channel":"book.ETH-PERPETUAL.raw","data":{"timestamp":1734114527430,"type":"change","change_id":15557281028,"instrument_name":"ETH-PERPETUAL","bids":[["change",3884.1,1.6e5]],"asks":[],"prev_change_id":15557281027}}}
{"jsonrpc":"2.0","method":"subscription","params":{"channel":"book.ETH-PERPETUAL.raw","data":{"timestamp":1734114527430,"type":"change","change_id":15557281028,"instrument_name":"ETH-PERPETUAL","bids":[["change",3884.1,1.6e5]],"asks":[],"prev_change_id":15557281027}}}
{"jsonrpc":"2.0","method":"subscription","params":{"channel":"book.ETH-PERPETUAL.raw","data":{"timestamp":1734114527431,"type":"change","change_id":15557281029,"instrument_name":"ETH-PERPETUAL","bids":[],"asks":[["change",3899.45,1.6e5]],"prev_change_id":15557281028}}}
{"jsonrpc":"2.0","method":"subscription","params":{"channel":"book.ETH-PERPETUAL.raw","data":{"timestamp":1734114527431,"type":"change","change_id":15557281029,"instrument_name":"ETH-PERPETUAL","bids":[],"asks":[["change",3899.45,1.6e5]],"prev_change_id":15557281028}}}
{"jsonrpc":"2.0","method":"subscription","params":{"channel":"book.ETH-PERPETUAL.raw","data":{"timestamp":1734114527560,"type":"change","change_id":15557281059,"instrument_name":"ETH-PERPETUAL","bids":[["delete",3884.1,0.0]],"asks":[["delete",3899.45,0.0]],"prev_change_id":15557281029}}}
{"jsonrpc":"2.0","method":"subscription","params":{"channel":"book.ETH-PERPETUAL.raw","data":{"timestamp":1734114527560,"type":"change","change_id":15557281059,"instrument_name":"ETH-PERPETUAL","bids":[["delete",3884.1,0.0]],"asks":[["delete",3899.45,0.0]],"prev_change_id":15557281029}}}
{"jsonrpc":"2.0","method":"subscription","params":{"channel":"book.ETH-PERPETUAL.raw","data":{"timestamp":1734114527736,"type":"change","change_id":15557281061,"instrument_name":"ETH-PERPETUAL","bids":[["new",3884.0,8.0e4]],"asks":[],"prev_change_id":15557281059}}}
{"jsonrpc":"2.0","method":"subscription","params":{"channel":"book.ETH-PERPETUAL.raw","data":{"timestamp":1734114527736,"type":"change","change_id":15557281061,"instrument_name":"ETH-PERPETUAL","bids":[["new",3884.0,8.0e4]],"asks":[],"prev_change_id":15557281059}}}
{"jsonrpc":"2.0","method":"subscription","params":{"channel":"book.ETH-PERPETUAL.raw","data":{"timestamp":1734114527738,"type":"change","change_id":15557281062,"instrument_name":"ETH-PERPETUAL","bids":[],"asks":[["new",3899.35,8.0e4]],"prev_change_id":15557281061}}}
{"jsonrpc":"2.0","method":"subscription","params":{"channel":"book.ETH-PERPETUAL.raw","data":{"timestamp":1734114527738,"type":"change","change_id":15557281062,"instrument_name":"ETH-PERPETUAL","bids":[],"asks":[["new",3899.35,8.0e4]],"prev_change_id":15557281061}}}
{"jsonrpc":"2.0","method":"subscription","params":{"channel":"book.ETH-PERPETUAL.raw","data":{"timestamp":1734114527739,"type":"change","change_id":15557281063,"instrument_name":"ETH-PERPETUAL","bids":[["change",3884.0,1.0e5]],"asks":[],"prev_change_id":15557281062}}}
{"jsonrpc":"2.0","method":"subscription","params":{"channel":"book.ETH-PERPETUAL.raw","data":{"timestamp":1734114527739,"type":"change","change_id":15557281063,"instrument_name":"ETH-PERPETUAL","bids":[["change",3884.0,1.0e5]],"asks":[],"prev_change_id":15557281062}}}
{"jsonrpc":"2.0","method":"subscription","params":{"channel":"book.ETH-PERPETUAL.raw","data":{"timestamp":1734114527740,"type":"change","change_id":15557281064,"instrument_name":"ETH-PERPETUAL","bids":[["change",3884.0,1.8e5]],"asks":[],"prev_change_id":15557281063}}}
{"jsonrpc":"2.0","method":"subscription","params":{"channel":"book.ETH-PERPETUAL.raw","data":{"timestamp":1734114527740,"type":"change","change_id":15557281064,"instrument_name":"ETH-PERPETUAL","bids":[["change",3884.0,1.8e5]],"asks":[],"prev_change_id":15557281063}}}
{"jsonrpc":"2.0","method":"subscription","params":{"channel":"book.ETH-PERPETUAL.raw","data":{"timestamp":1734114527742,"type":"change","change_id":15557281065,"instrument_name":"ETH-PERPETUAL","bids":[],"asks":[["change",3899.35,1.6e5]],"prev_change_id":15557281064}}}
{"jsonrpc":"2.0","method":"subscription","params":{"channel":"book.ETH-PERPETUAL.raw","data":{"timestamp":1734114527742,"type":"change","change_id":15557281065,"instrument_name":"ETH-PERPETUAL","bids":[],"asks":[["change",3899.35,1.6e5]],"prev_change_id":15557281064}}}
{"jsonrpc":"2.0","method":"subscription","params":{"channel":"book.ETH-PERPETUAL.raw","data":{"timestamp":1734114527743,"type":"change","change_id":15557281066,"instrument_name":"ETH-PERPETUAL","bids":[["change",3884.0,2.0e5]],"asks":[],"prev_change_id":15557281065}}}
{"jsonrpc":"2.0","method":"subscription","params":{"channel":"book.ETH-PERPETUAL.raw","data":{"timestamp":1734114527743,"type":"change","change_id":15557281066,"instrument_name":"ETH-PERPETUAL","bids":[["change",3884.0,2.0e5]],"asks":[],"prev_change_id":15557281065}}}
{"jsonrpc":"2.0","method":"subscription","params":{"channel":"book.ETH-PERPETUAL.raw","data":{"timestamp":1734114527870,"type":"change","change_id":15557281069,"instrument_name":"ETH-PERPETUAL","bids":[["delete",3884.0,0.0]],"asks":[["delete",3899.35,0.0]],"prev_change_id":15557281066}}}
{"jsonrpc":"2.0","method":"subscription","params":{"channel":"book.ETH-PERPETUAL.raw","data":{"timestamp":1734114527870,"type":"change","change_id":15557281069,"instrument_name":"ETH-PERPETUAL","bids":[["delete",3884.0,0.0]],"asks":[["delete",3899.35,0.0]],"prev_change_id":15557281066}}}
{"jsonrpc":"2.0","method":"subscription","params":{"channel":"book.ETH-PERPETUAL.raw","data":{"timestamp":1734114528054,"type":"change","change_id":15557281071,"instrument_name":"ETH-PERPETUAL","bids":[["new",3883.9,8.0e4]],"asks":[],"prev_change_id":15557281069}}}
{"jsonrpc":"2.0","method":"subscription","params":{"channel":"book.ETH-PERPETUAL.raw","data":{"timestamp":1734114528054,"type":"change","change_id":15557281071,"instrument_name":"ETH-PERPETUAL","bids":[["new",3883.9,8.0e4]],"asks":[],"prev_change_id":15557281069}}}
{"jsonrpc":"2.0","method":"subscription","params":{"channel":"book.ETH-PERPETUAL.raw","data":{"timestamp":1734114528056,"type":"change","change_id":15557281072,"instrument_name":"ETH-PERPETUAL","bids":[],"asks":[["new",3899.25,8.0e4]],"prev_change_id":15557281071}}}
{"jsonrpc":"2.0","method":"subscription","params":{"channel":"book.ETH-PERPETUAL.raw","data":{"timestamp":1734114528056,"type":"change","change_id":15557281072,"instrument_name":"ETH-PERPETUAL","bids":[],"asks":[["new",3899.25,8.0e4]],"prev_change_id":15557281071}}}
{"jsonrpc":"2.0","method":"subscription","params":{"channel":"book.ETH-PERPETUAL.raw","data":{"timestamp":1734114528058,"type":"change","change_id":15557281073,"instrument_name":"ETH-PERPETUAL","bids":[["change",3883.9,1.6e5]],"asks":[],"prev_change_id":15557281072}}}
{"jsonrpc":"2.0","method":"subscription","params":{"channel":"book.ETH-PERPETUAL.raw","data":{"timestamp":1734114528058,"type":"change","change_id":15557281073,"instrument_name":"ETH-PERPETUAL","bids":[["change",3883.9,1.6e5]],"asks":[],"prev_change_id":15557281072}}}
{"jsonrpc":"2.0","method":"subscription","params":{"channel":"book.ETH-PERPETUAL.raw","data":{"timestamp":1734114528070,"type":"change","change_id":15557281074,"instrument_name":"ETH-PERPETUAL","bids":[],"asks":[["change",3899.25,1.6e5]],"prev_change_id":15557281073}}}
{"jsonrpc":"2.0","method":"subscription","params":{"channel":"book.ETH-PERPETUAL.raw","data":{"timestamp":1734114528070,"type":"change","change_id":15557281074,"instrument_name":"ETH-PERPETUAL","bids":[],"asks":[["change",3899.25,1.6e5]],"prev_change_id":15557281073}}}
{"jsonrpc":"2.0","method":"subscription","params":{"channel":"book.ETH-PERPETUAL.raw","data":{"timestamp":1734114528144,"type":"change","change_id":15557281075,"instrument_name":"ETH-PERPETUAL","bids":[["delete",3883.9,0.0]],"asks":[["delete",3899.25,0.0]],"prev_change_id":15557281074}}}
{"jsonrpc":"2.0","method":"subscription","params":{"channel":"book.ETH-PERPETUAL.raw","data":{"timestamp":1734114528144,"type":"change","change_id":15557281075,"instrument_name":"ETH-PERPETUAL","bids":[["delete",3883.9,0.0]],"asks":[["delete",3899.25,0.0]],"prev_change_id":15557281074}}}
{"jsonrpc":"2.0","method":"subscription","params":{"channel":"book.ETH-PERPETUAL.raw","data":{"timestamp":1734114528321,"type":"change","change_id":15557281078,"instrument_name":"ETH-PERPETUAL","bids":[["new",3883.6,8.0e4]],"asks":[],"prev_change_id":15557281075}}}
{"jsonrpc":"2.0","method":"subscription","params":{"channel":"book.ETH-PERPETUAL.raw","data":{"timestamp":1734114528321,"type":"change","change_id":15557281078,"instrument_name":"ETH-PERPETUAL","bids":[["new",3883.6,8.0e4]],"asks":[],"prev_change_id":15557281075}}}
{"jsonrpc":"2.0","method":"subscription","params":{"channel":"book.ETH-PERPETUAL.raw","data":{"timestamp":1734114528323,"type":"change","change_id":15557281079,"instrument_name":"ETH-PERPETUAL","bids":[],"asks":[["new",3898.9,8.0e4]],"prev_change_id":15557281078}}}
{"jsonrpc":"2.0","method":"subscription","params":{"channel":"book.ETH-PERPETUAL.raw","data":{"timestamp":1734114528323,"type":"change","change_id":15557281079,"instrument_name":"ETH-PERPETUAL","bids":[],"asks":[["new",3898.9,8.0e4]],"prev_change_id":15557281078}}}
{"jsonrpc":"2.0","method":"subscription","params":{"channel":"book.ETH-PERPETUAL.raw","data":{"timestamp":1734114528324,"type":"change","change_id":15557281080,"instrument_name":"ETH-PERPETUAL","bids":[["change",3883.6,1.0e5]],"asks":[],"prev_change_id":15557281079}}}
{"jsonrpc":"2.0","method":"subscription","params":{"channel":"book.ETH-PERPETUAL.raw","data":{"timestamp":1734114528324,"type":"change","change_id":15557281080,"instrument_name":"ETH-PERPETUAL","bids":[["change",3883.6,1.0e5]],"asks":[],"prev_change_id":15557281079}}}
{"jsonrpc":"2.0","method":"subscription","params":{"channel":"book.ETH-PERPETUAL.raw","data":{"timestamp":1734114528325,"type":"change","change_id":15557281081,"instrument_name":"ETH-PERPETUAL","bids":[["change",3883.6,1.8e5]],"asks":[],"prev_change_id":15557281080}}}
{"jsonrpc":"2.0","method":"subscription","params":{"channel":"book.ETH-PERPETUAL.raw","data":{"timestamp":1734114528325,"type":"change","change_id":15557281081,"instrument_name":"ETH-PERPETUAL","bids":[["change",3883.6,1.8e5]],"asks":[],"prev_change_id":15557281080}}}
{"jsonrpc":"2.0","method":"subscription","params":{"channel":"book.ETH-PERPETUAL.raw","data":{"timestamp":1734114528327,"type":"change","change_id":15557281082,"instrument_name":"ETH-PERPETUAL","bids":[],"asks":[["change",3898.9,1.6e5]],"prev_change_id":15557281081}}}
{"jsonrpc":"2.0","method":"subscription","params":{"channel":"book.ETH-PERPETUAL.raw","data":{"timestamp":1734114528327,"type":"change","change_id":15557281082,"instrument_name":"ETH-PERPETUAL","bids":[],"asks":[["change",3898.9,1.6e5]],"prev_change_id":15557281081}}}
{"jsonrpc":"2.0","method":"subscription","params":{"channel":"book.ETH-PERPETUAL.raw","data":{"timestamp":1734114528328,"type":"change","change_id":15557281083,"instrument_name":"ETH-PERPETUAL","bids":[["change",3883.6,2.0e5]],"asks":[],"prev_change_id":15557281082}}}
{"jsonrpc":"2.0","method":"subscription","params":{"channel":"book.ETH-PERPETUAL.raw","data":{"timestamp":1734114528328,"type":"change","change_id":15557281083,"instrument_name":"ETH-PERPETUAL","bids":[["change",3883.6,2.0e5]],"asks":[],"prev_change_id":15557281082}}}
{"jsonrpc":"2.0","method":"subscription","params":{"channel":"book.ETH-PERPETUAL.raw","data":{"timestamp":1734114528442,"type":"change","change_id":15557281084,"instrument_name":"ETH-PERPETUAL","bids":[["delete",3883.6,0.0]],"asks":[["delete",3898.9,0.0]],"prev_change_id":15557281083}}}
{"jsonrpc":"2.0","method":"subscription","params":{"channel":"book.ETH-PERPETUAL.raw","data":{"timestamp":1734114528442,"type":"change","change_id":15557281084,"instrument_name":"ETH-PERPETUAL","bids":[["delete",3883.6,0.0]],"asks":[["delete",3898.9,0.0]],"prev_change_id":15557281083}}}
{"jsonrpc":"2.0","method":"subscription","params":{"channel":"book.ETH-PERPETUAL.raw","data":{"timestamp":1734114528678,"type":"change","change_id":15557281097,"instrument_name":"ETH-PERPETUAL","bids":[["new",3883.6,8.0e4]],"asks":[],"prev_change_id":15557281084}}}
{"jsonrpc":"2.0","method":"subscription","params":{"channel":"book.ETH-PERPETUAL.raw","data":{"timestamp":1734114528678,"type":"change","change_id":15557281097,"instrument_name":"ETH-PERPETUAL","bids":[["new",3883.6,8.0e4]],"asks":[],"prev_change_id":15557281084}}}
{"jsonrpc":"2.0","method":"subscription","params":{"channel":"book.ETH-PERPETUAL.raw","data":{"timestamp":1734114528679,"type":"change","change_id":15557281098,"instrument_name":"ETH-PERPETUAL","bids":[],"asks":[["new",3898.9,8.0e4]],"prev_change_id":15557281097}}}
{"jsonrpc":"2.0","method":"subscription","params":{"channel":"book.ETH-PERPETUAL.raw","data":{"timestamp":1734114528679,"type":"change","change_id":15557281098,"instrument_name":"ETH-PERPETUAL","bids":[],"asks":[["new",3898.9,8.0e4]],"prev_change_id":15557281097}}}
{"jsonrpc":"2.0","method":"subscription","params":{"channel":"book.ETH-PERPETUAL.raw","data":{"timestamp":1734114528681,"type":"change","change_id":15557281099,"instrument_name":"ETH-PERPETUAL","bids":[["change",3883.6,1.0e5]],"asks":[],"prev_change_id":15557281098}}}
{"jsonrpc":"2.0","method":"subscription","params":{"channel":"book.ETH-PERPETUAL.raw","data":{"timestamp":1734114528681,"type":"change","change_id":15557281099,"instrument_name":"ETH-PERPETUAL","bids":[["change",3883.6,1.0e5]],"asks":[],"prev_change_id":15557281098}}}
{"jsonrpc":"2.0","method":"subscription","params":{"channel":"book.ETH-PERPETUAL.raw","data":{"timestamp":1734114528682,"type":"change","change_id":15557281100,"instrument_name":"ETH-PERPETUAL","bids":[],"asks":[["change",3898.9,1.0e5]],"prev_change_id":15557281099}}}
{"jsonrpc":"2.0","method":"subscription","params":{"channel":"book.ETH-PERPETUAL.raw","data":{"timestamp":1734114528682,"type":"change","change_id":15557281100,"instrument_name":"ETH-PERPETUAL","bids":[],"asks":[["change",3898.9,1.0e5]],"prev_change_id":15557281099}}}
{"jsonrpc":"2.0","method":"subscription","params":{"channel":"book.ETH-PERPETUAL.raw","data":{"timestamp":1734114528684,"type":"change","change_id":15557281101,"instrument_name":"ETH-PERPETUAL","bids":[["change",3883.6,1.8e5]],"asks":[],"prev_change_id":15557281100}}}
{"jsonrpc":"2.0","method":"subscription","params":{"channel":"book.ETH-PERPETUAL.raw","data":{"timestamp":1734114528684,"type":"change","change_id":15557281101,"instrument_name":"ETH-PERPETUAL","bids":[["change",3883.6,1.8e5]],"asks":[],"prev_change_id":15557281100}}}
{"jsonrpc":"2.0","method":"subscription","params":{"channel":"book.ETH-PERPETUAL.raw","data":{"timestamp":1734114528685,"type":"change","change_id":15557281102,"instrument_name":"ETH-PERPETUAL","bids":[],"asks":[["change",3898.9,1.8e5]],"prev_change_id":15557281101}}}
{"jsonrpc":"2.0","method":"subscription","params":{"channel":"book.ETH-PERPETUAL.raw","data":{"timestamp":1734114528685,"type":"change","change_id":15557281102,"instrument_name":"ETH-PERPETUAL","bids":[],"asks":[["change",3898.9,1.8e5]],"prev_change_id":15557281101}}}
{"jsonrpc":"2.0","method":"subscription","params":{"channel":"book.ETH-PERPETUAL.raw","data":{"timestamp":1734114528686,"type":"change","change_id":15557281103,"instrument_name":"ETH-PERPETUAL","bids":[["change",3883.6,2.0e5]],"asks":[],"prev_change_id":15557281102}}}
{"jsonrpc":"2.0","method":"subscription","params":{"channel":"book.ETH-PERPETUAL.raw","data":{"timestamp":1734114528686,"type":"change","change_id":15557281103,"instrument_name":"ETH-PERPETUAL","bids":[["change",3883.6,2.0e5]],"asks":[],"prev_change_id":15557281102}}}
{"jsonrpc":"2.0","method":"subscription","params":{"channel":"book.ETH-PERPETUAL.raw","data":{"timestamp":1734114528688,"type":"change","change_id":15557281104,"instrument_name":"ETH-PERPETUAL","bids":[],"asks":[["change",3898.9,2.0e5]],"prev_change_id":15557281103}}}
{"jsonrpc":"2.0","method":"subscription","params":{"channel":"book.ETH-PERPETUAL.raw","data":{"timestamp":1734114528688,"type":"change","change_id":15557281104,"instrument_name":"ETH-PERPETUAL","bids":[],"asks":[["change",3898.9,2.0e5]],"prev_change_id":15557281103}}}
{"jsonrpc":"2.0","method":"subscription","params":{"channel":"book.ETH-PERPETUAL.raw","data":{"timestamp":1734114528827,"type":"change","change_id":15557281107,"instrument_name":"ETH-PERPETUAL","bids":[],"asks":[["new",3937.9,700.0],["change",3949.1,100.0]],"prev_change_id":15557281104}}}
{"jsonrpc":"2.0","method":"subscription","params":{"channel":"book.ETH-PERPETUAL.raw","data":{"timestamp":1734114528827,"type":"change","change_id":15557281107,"instrument_name":"ETH-PERPETUAL","bids":[],"asks":[["new",3937.9,700.0],["change",3949.1,100.0]],"prev_change_id":15557281104}}}
{"jsonrpc":"2.0","method":"subscription","params":{"channel":"book.ETH-PERPETUAL.raw","data":{"timestamp":1734114528878,"type":"change","change_id":15557281109,"instrument_name":"ETH-PERPETUAL","bids":[["delete",3883.6,0.0]],"asks":[["delete",3898.9,0.0]],"prev_change_id":15557281107}}}
{"jsonrpc":"2.0","method":"subscription","params":{"channel":"book.ETH-PERPETUAL.raw","data":{"timestamp":1734114528878,"type":"change","change_id":15557281109,"instrument_name":"ETH-PERPETUAL","bids":[["delete",3883.6,0.0]],"asks":[["delete",3898.9,0.0]],"prev_change_id":15557281107}}}
{"jsonrpc":"2.0","method":"subscription","params":{"channel":"book.ETH-PERPETUAL.raw","data":{"timestamp":1734114529064,"type":"change","change_id":15557281110,"instrument_name":"ETH-PERPETUAL","bids":[["new",3883.6,8.0e4]],"asks":[],"prev_change_id":15557281109}}}
{"jsonrpc":"2.0","method":"subscription","params":{"channel":"book.ETH-PERPETUAL.raw","data":{"timestamp":1734114529064,"type":"change","change_id":15557281110,"instrument_name":"ETH-PERPETUAL","bids":[["new",3883.6,8.0e4]],"asks":[],"prev_change_id":15557281109}}}
{"jsonrpc":"2.0","method":"subscription","params":{"channel":"book.ETH-PERPETUAL.raw","data":{"timestamp":1734114529069,"type":"change","change_id":15557281111,"instrument_name":"ETH-PERPETUAL","bids":[],"asks":[["new",3898.9,8.0e4]],"prev_change_id":15557281110}}}
{"jsonrpc":"2.0","method":"subscription","params":{"channel":"book.ETH-PERPETUAL.raw","data":{"timestamp":1734114529069,"type":"change","change_id":15557281111,"instrument_name":"ETH-PERPETUAL","bids":[],"asks":[["new",3898.9,8.0e4]],"prev_change_id":15557281110}}}
{"jsonrpc":"2.0","method":"subscription","params":{"channel":"book.ETH-PERPETUAL.raw","data":{"timestamp":1734114529070,"type":"change","change_id":15557281112,"instrument_name":"ETH-PERPETUAL","bids":[["change",3883.6,1.0e5]],"asks":[],"prev_change_id":15557281111}}}
{"jsonrpc":"2.0","method":"subscription","params":{"channel":"book.ETH-PERPETUAL.raw","data":{"timestamp":1734114529070,"type":"change","change_id":15557281112,"instrument_name":"ETH-PERPETUAL","bids":[["change",3883.6,1.0e5]],"asks":[],"prev_change_id":15557281111}}}
{"jsonrpc":"2.0","method":"subscription","params":{"channel":"book.ETH-PERPETUAL.raw","data":{"timestamp":1734114529071,"type":"change","change_id":15557281113,"instrument_name":"ETH-PERPETUAL","bids":[["change",3883.6,1.8e5]],"asks":[],"prev_change_id":15557281112}}}
{"jsonrpc":"2.0","method":"subscription","params":{"channel":"book.ETH-PERPETUAL.raw","data":{"timestamp":1734114529071,"type":"change","change_id":15557281113,"instrument_name":"ETH-PERPETUAL","bids":[["change",3883.6,1.8e5]],"asks":[],"prev_change_id":15557281112}}}
{"jsonrpc":"2.0","method":"subscription","params":{"channel":"book.ETH-PERPETUAL.raw","data":{"timestamp":1734114529072,"type":"change","change_id":15557281114,"instrument_name":"ETH-PERPETUAL","bids":[],"asks":[["change",3898.9,1.6e5]],"prev_change_id":15557281113}}}
{"jsonrpc":"2.0","method":"subscription","params":{"channel":"book.ETH-PERPETUAL.raw","data":{"timestamp":1734114529072,"type":"change","change_id":15557281114,"instrument_name":"ETH-PERPETUAL","bids":[],"asks":[["change",3898.9,1.6e5]],"prev_change_id":15557281113}}}
{"jsonrpc":"2.0","method":"subscription","params":{"channel":"book.ETH-PERPETUAL.raw","data":{"timestamp":1734114529075,"type":"change","change_id":15557281115,"instrument_name":"ETH-PERPETUAL","bids":[["change",3883.6,2.0e5]],"asks":[],"prev_change_id":15557281114}}}
{"jsonrpc":"2.0","method":"subscription","params":{"channel":"book.ETH-PERPETUAL.raw","data":{"timestamp":1734114529075,"type":"change","change_id":15557281115,"instrument_name":"ETH-PERPETUAL","bids":[["change",3883.6,2.0e5]],"asks":[],"prev_change_id":15557281114}}}
{"jsonrpc":"2.0","method":"subscription","params":{"channel":"book.ETH-PERPETUAL.raw","data":{"timestamp":1734114529075,"type":"change","change_id":15557281116,"instrument_name":"ETH-PERPETUAL","bids":[],"asks":[["change",3898.9,1.8e5]],"prev_change_id":15557281115}}}
{"jsonrpc":"2.0","method":"subscription","params":{"channel":"book.ETH-PERPETUAL.raw","data":{"timestamp":1734114529075,"type":"change","change_id":15557281116,"instrument_name":"ETH-PERPETUAL","bids":[],"asks":[["change",3898.9,1.8e5]],"prev_change_id":15557281115}}}
{"jsonrpc":"2.0","method":"subscription","params":{"channel":"book.ETH-PERPETUAL.raw","data":{"timestamp":1734114529251,"type":"change","change_id":15557281117,"instrument_name":"ETH-PERPETUAL","bids":[["delete",3883.6,0.0]],"asks":[["delete",3898.9,0.0]],"prev_change_id":15557281116}}}
{"jsonrpc":"2.0","method":"subscription","params":{"channel":"book.ETH-PERPETUAL.raw","data":{"timestamp":1734114529251,"type":"change","change_id":15557281117,"instrument_name":"ETH-PERPETUAL","bids":[["delete",3883.6,0.0]],"asks":[["delete",3898.9,0.0]],"prev_change_id":15557281116}}}
{"jsonrpc":"2.0","method":"subscription","params":{"channel":"book.ETH-PERPETUAL.raw","data":{"timestamp":1734114529432,"type":"change","change_id":15557281118,"instrument_name":"ETH-PERPETUAL","bids":[["new",3884.0,8.0e4]],"asks":[],"prev_change_id":15557281117}}}
{"jsonrpc":"2.0","method":"subscription","params":{"channel":"book.ETH-PERPETUAL.raw","data":{"timestamp":1734114529432,"type":"change","change_id":15557281118,"instrument_name":"ETH-PERPETUAL","bids":[["new",3884.0,8.0e4]],"asks":[],"prev_change_id":15557281117}}}
{"jsonrpc":"2.0","method":"subscription","params":{"channel":"book.ETH-PERPETUAL.raw","data":{"timestamp":1734114529434,"type":"change","change_id":15557281119,"instrument_name":"ETH-PERPETUAL","bids":[],"asks":[["new",3899.3,8.0e4]],"prev_change_id":15557281118}}}
{"jsonrpc":"2.0","method":"subscription","params":{"channel":"book.ETH-PERPETUAL.raw","data":{"timestamp":1734114529434,"type":"change","change_id":15557281119,"instrument_name":"ETH-PERPETUAL","bids":[],"asks":[["new",3899.3,8.0e4]],"prev_change_id":15557281118}}}
{"jsonrpc":"2.0","method":"subscription","params":{"channel":"book.ETH-PERPETUAL.raw","data":{"timestamp":1734114529435,"type":"change","change_id":15557281120,"instrument_name":"ETH-PERPETUAL","bids":[["change",3884.0,1.0e5]],"asks":[],"prev_change_id":15557281119}}}
{"jsonrpc":"2.0","method":"subscription","params":{"channel":"book.ETH-PERPETUAL.raw","data":{"timestamp":1734114529435,"type":"change","change_id":15557281120,"instrument_name":"ETH-PERPETUAL","bids":[["change",3884.0,1.0e5]],"asks":[],"prev_change_id":15557281119}}}
{"jsonrpc":"2.0","method":"subscription","params":{"channel":"book.ETH-PERPETUAL.raw","data":{"timestamp":1734114529436,"type":"change","change_id":15557281121,"instrument_name":"ETH-PERPETUAL","bids":[["change",3884.0,1.8e5]],"asks":[],"prev_change_id":15557281120}}}
{"jsonrpc":"2.0","method":"subscription","params":{"channel":"book.ETH-PERPETUAL.raw","data":{"timestamp":1734114529436,"type":"change","change_id":15557281121,"instrument_name":"ETH-PERPETUAL","bids":[["change",3884.0,1.8e5]],"asks":[],"prev_change_id":15557281120}}}
{"jsonrpc":"2.0","method":"subscription","params":{"channel":"book.ETH-PERPETUAL.raw","data":{"timestamp":1734114529438,"type":"change","change_id":15557281122,"instrument_name":"ETH-PERPETUAL","bids":[],"asks":[["change",3899.3,1.6e5]],"prev_change_id":15557281121}}}
{"jsonrpc":"2.0","method":"subscription","params":{"channel":"book.ETH-PERPETUAL.raw","data":{"timestamp":1734114529438,"type":"change","change_id":15557281122,"instrument_name":"ETH-PERPETUAL","bids":[],"asks":[["change",3899.3,1.6e5]],"prev_change_id":15557281121}}}
{"jsonrpc":"2.0","method":"subscription","params":{"channel":"book.ETH-PERPETUAL.raw","data":{"timestamp":1734114529439,"type":"change","change_id":15557281123,"instrument_name":"ETH-PERPETUAL","bids":[["change",3884.0,2.0e5]],"asks":[],"prev_change_id":15557281122}}}
{"jsonrpc":"2.0","method":"subscription","params":{"channel":"book.ETH-PERPETUAL.raw","data":{"timestamp":1734114529439,"type":"change","change_id":15557281123,"instrument_name":"ETH-PERPETUAL","bids":[["change",3884.0,2.0e5]],"asks":[],"prev_change_id":15557281122}}}
{"jsonrpc":"2.0","method":"subscription","params":{"channel":"book.ETH-PERPETUAL.raw","data":{"timestamp":1734114529576,"type":"change","change_id":15557281172,"instrument_name":"ETH-PERPETUAL","bids":[["delete",3884.0,0.0]],"asks":[["delete",3899.3,0.0]],"prev_change_id":15557281123}}}
{"jsonrpc":"2.0","method":"subscription","params":{"channel":"book.ETH-PERPETUAL.raw","data":{"timestamp":1734114529576,"type":"change","change_id":15557281172,"instrument_name":"ETH-PERPETUAL","bids":[["delete",3884.0,0.0]],"asks":[["delete",3899.3,0.0]],"prev_change_id":15557281123}}}
{"jsonrpc":"2.0","method":"subscription","params":{"channel":"book.ETH-PERPETUAL.raw","data":{"timestamp":1734114529769,"type":"change","change_id":15557281240,"instrument_name":"ETH-PERPETUAL","bids":[["new",3884.0,8.0e4]],"asks":[],"prev_change_id":15557281172}}}
{"jsonrpc":"2.0","method":"subscription","params":{"channel":"book.ETH-PERPETUAL.raw","data":{"timestamp":1734114529769,"type":"change","change_id":15557281240,"instrument_name":"ETH-PERPETUAL","bids":[["new",3884.0,8.0e4]],"asks":[],"prev_change_id":15557281172}}}
{"jsonrpc":"2.0","method":"subscription","params":{"channel":"book.ETH-PERPETUAL.raw","data":{"timestamp":1734114529770,"type":"change","change_id":15557281241,"instrument_name":"ETH-PERPETUAL","bids":[],"asks":[["new",3899.3,8.0e4]],"prev_change_id":15557281240}}}
{"jsonrpc":"2.0","method":"subscription","params":{"channel":"book.ETH-PERPETUAL.raw","data":{"timestamp":1734114529770,"type":"change","change_id":15557281241,"instrument_name":"ETH-PERPETUAL","bids":[],"asks":[["new",3899.3,8.0e4]],"prev_change_id":15557281240}}}
{"jsonrpc":"2.0","method":"subscription","params":{"channel":"book.ETH-PERPETUAL.raw","data":{"timestamp":1734114529771,"type":"change","change_id":15557281242,"instrument_name":"ETH-PERPETUAL","bids":[["change",3884.0,1.0e5]],"asks":[],"prev_change_id":15557281241}}}
{"jsonrpc":"2.0","method":"subscription","params":{"channel":"book.ETH-PERPETUAL.raw","data":{"timestamp":1734114529771,"type":"change","change_id":15557281242,"instrument_name":"ETH-PERPETUAL","bids":[["change",3884.0,1.0e5]],"asks":[],"prev_change_id":15557281241}}}
{"jsonrpc":"2.0","method":"subscription","params":{"channel":"book.ETH-PERPETUAL.raw","data":{"timestamp":1734114529772,"type":"change","change_id":15557281243,"instrument_name":"ETH-PERPETUAL","bids":[["change",3884.0,1.8e5]],"asks":[],"prev_change_id":15557281242}}}
{"jsonrpc":"2.0","method":"subscription","params":{"channel":"book.ETH-PERPETUAL.raw","data":{"timestamp":1734114529772,"type":"change","change_id":15557281243,"instrument_name":"ETH-PERPETUAL","bids":[["change",3884.0,1.8e5]],"asks":[],"prev_change_id":15557281242}}}
{"jsonrpc":"2.0","method":"subscription","params":{"channel":"book.ETH-PERPETUAL.raw","data":{"timestamp":1734114529773,"type":"change","change_id":15557281244,"instrument_name":"ETH-PERPETUAL","bids":[],"asks":[["change",3899.3,1.6e5]],"prev_change_id":15557281243}}}
{"jsonrpc":"2.0","method":"subscription","params":{"channel":"book.ETH-PERPETUAL.raw","data":{"timestamp":1734114529773,"type":"change","change_id":15557281244,"instrument_name":"ETH-PERPETUAL","bids":[],"asks":[["change",3899.3,1.6e5]],"prev_change_id":15557281243}}}
{"jsonrpc":"2.0","method":"subscription","params":{"channel":"book.ETH-PERPETUAL.raw","data":{"timestamp":1734114529774,"type":"change","change_id":15557281245,"instrument_name":"ETH-PERPETUAL","bids":[["change",3884.0,2.0e5]],"asks":[],"prev_change_id":15557281244}}}
{"jsonrpc":"2.0","method":"subscription","params":{"channel":"book.ETH-PERPETUAL.raw","data":{"timestamp":1734114529774,"type":"change","change_id":15557281245,"instrument_name":"ETH-PERPETUAL","bids":[["change",3884.0,2.0e5]],"asks":[],"prev_change_id":15557281244}}}
{"jsonrpc":"2.0","method":"subscription","params":{"channel":"book.ETH-PERPETUAL.raw","data":{"timestamp":1734114529942,"type":"change","change_id":15557281248,"instrument_name":"ETH-PERPETUAL","bids":[["delete",3884.0,0.0]],"asks":[["delete",3899.3,0.0]],"prev_change_id":15557281245}}}
{"jsonrpc":"2.0","method":"subscription","params":{"channel":"book.ETH-PERPETUAL.raw","data":{"timestamp":1734114529942,"type":"change","change_id":15557281248,"instrument_name":"ETH-PERPETUAL","bids":[["delete",3884.0,0.0]],"asks":[["delete",3899.3,0.0]],"prev_change_id":15557281245}}}
{"jsonrpc":"2.0","method":"subscription","params":{"channel":"book.ETH-PERPETUAL.raw","data":{"timestamp":1734114530128,"type":"change","change_id":15557281249,"instrument_name":"ETH-PERPETUAL","bids":[["new",3884.0,8.0e4]],"asks":[],"prev_change_id":15557281248}}}
{"jsonrpc":"2.0","method":"subscription","params":{"channel":"book.ETH-PERPETUAL.raw","data":{"timestamp":1734114530128,"type":"change","change_id":15557281249,"instrument_name":"ETH-PERPETUAL","bids":[["new",3884.0,8.0e4]],"asks":[],"prev_change_id":15557281248}}}
{"jsonrpc":"2.0","method":"subscription","params":{"channel":"book.ETH-PERPETUAL.raw","data":{"timestamp":1734114530129,"type":"change","change_id":15557281250,"instrument_name":"ETH-PERPETUAL","bids":[],"asks":[["new",3899.3,8.0e4]],"prev_change_id":15557281249}}}
{"jsonrpc":"2.0","method":"subscription","params":{"channel":"book.ETH-PERPETUAL.raw","data":{"timestamp":1734114530129,"type":"change","change_id":15557281250,"instrument_name":"ETH-PERPETUAL","bids":[],"asks":[["new",3899.3,8.0e4]],"prev_change_id":15557281249}}}
{"jsonrpc":"2.0","method":"subscription","params":{"channel":"book.ETH-PERPETUAL.raw","data":{"timestamp":1734114530131,"type":"change","change_id":15557281251,"instrument_name":"ETH-PERPETUAL","bids":[["change",3884.0,1.0e5]],"asks":[],"prev_change_id":15557281250}}}
{"jsonrpc":"2.0","method":"subscription","params":{"channel":"book.ETH-PERPETUAL.raw","data":{"timestamp":1734114530131,"type":"change","change_id":15557281251,"instrument_name":"ETH-PERPETUAL","bids":[["change",3884.0,1.0e5]],"asks":[],"prev_change_id":15557281250}}}
{"jsonrpc":"2.0","method":"subscription","params":{"channel":"book.ETH-PERPETUAL.raw","data":{"timestamp":1734114530132,"type":"change","change_id":15557281252,"instrument_name":"ETH-PERPETUAL","bids":[],"asks":[["change",3899.3,1.0e5]],"prev_change_id":15557281251}}}
{"jsonrpc":"2.0","method":"subscription","params":{"channel":"book.ETH-PERPETUAL.raw","data":{"timestamp":1734114530132,"type":"change","change_id":15557281252,"instrument_name":"ETH-PERPETUAL","bids":[],"asks":[["change",3899.3,1.0e5]],"prev_change_id":15557281251}}}
{"jsonrpc":"2.0","method":"subscription","params":{"channel":"book.ETH-PERPETUAL.raw","data":{"timestamp":1734114530133,"type":"change","change_id":15557281253,"instrument_name":"ETH-PERPETUAL","bids":[["change",3884.0,1.8e5]],"asks":[],"prev_change_id":15557281252}}}
{"jsonrpc":"2.0","method":"subscription","params":{"channel":"book.ETH-PERPETUAL.raw","data":{"timestamp":1734114530133,"type":"change","change_id":15557281253,"instrument_name":"ETH-PERPETUAL","bids":[["change",3884.0,1.8e5]],"asks":[],"prev_change_id":15557281252}}}
{"jsonrpc":"2.0","method":"subscription","params":{"channel":"book.ETH-PERPETUAL.raw","data":{"timestamp":1734114530135,"type":"change","change_id":15557281254,"instrument_name":"ETH-PERPETUAL","bids":[],"asks":[["change",3899.3,1.8e5]],"prev_change_id":15557281253}}}
{"jsonrpc":"2.0","method":"subscription","params":{"channel":"book.ETH-PERPETUAL.raw","data":{"timestamp":1734114530135,"type":"change","change_id":15557281254,"instrument_name":"ETH-PERPETUAL","bids":[],"asks":[["change",3899.3,1.8e5]],"prev_change_id":15557281253}}}
{"jsonrpc":"2.0","method":"subscription","params":{"channel":"book.ETH-PERPETUAL.raw","data":{"timestamp":1734114530137,"type":"change","change_id":15557281255,"instrument_name":"ETH-PERPETUAL","bids":[["change",3884.0,2.0e5]],"asks":[],"prev_change_id":15557281254}}}
{"jsonrpc":"2.0","method":"subscription","params":{"channel":"book.ETH-PERPETUAL.raw","data":{"timestamp":1734114530137,"type":"change","change_id":15557281255,"instrument_name":"ETH-PERPETUAL","bids":[["change",3884.0,2.0e5]],"asks":[],"prev_change_id":15557281254}}}
{"jsonrpc":"2.0","method":"subscription","params":{"channel":"book.ETH-PERPETUAL.raw","data":{"timestamp":1734114530138,"type":"change","change_id":15557281256,"instrument_name":"ETH-PERPETUAL","bids":[],"asks":[["change",3899.3,2.0e5]],"prev_change_id":15557281255}}}
{"jsonrpc":"2.0","method":"subscription","params":{"channel":"book.ETH-PERPETUAL.raw","data":{"timestamp":1734114530138,"type":"change","change_id":15557281256,"instrument_name":"ETH-PERPETUAL","bids":[],"asks":[["change",3899.3,2.0e5]],"prev_change_id":15557281255}}}
{"jsonrpc":"2.0","method":"subscription","params":{"channel":"book.ETH-PERPETUAL.raw","data":{"timestamp":1734114530283,"type":"change","change_id":15557281257,"instrument_name":"ETH-PERPETUAL","bids":[["delete",3884.0,0.0]],"asks":[["delete",3899.3,0.0]],"prev_change_id":15557281256}}}
{"jsonrpc":"2.0","method":"subscription","params":{"channel":"book.ETH-PERPETUAL.raw","data":{"timestamp":1734114530283,"type":"change","change_id":15557281257,"instrument_name":"ETH-PERPETUAL","bids":[["delete",3884.0,0.0]],"asks":[["delete",3899.3,0.0]],"prev_change_id":15557281256}}}
{"jsonrpc":"2.0","method":"subscription","params":{"channel":"book.ETH-PERPETUAL.raw","data":{"timestamp":1734114530469,"type":"change","change_id":15557281258,"instrument_name":"ETH-PERPETUAL","bids":[["new",3883.9,8.0e4]],"asks":[],"prev_change_id":15557281257}}}
{"jsonrpc":"2.0","method":"subscription","params":{"channel":"book.ETH-PERPETUAL.raw","data":{"timestamp":1734114530469,"type":"change","change_id":15557281258,"instrument_name":"ETH-PERPETUAL","bids":[["new",3883.9,8.0e4]],"asks":[],"prev_change_id":15557281257}}}
{"jsonrpc":"2.0","method":"subscription","params":{"channel":"book.ETH-PERPETUAL.raw","data":{"timestamp":1734114530471,"type":"change","change_id":15557281259,"instrument_name":"ETH-PERPETUAL","bids":[],"asks":[["new",3899.2,8.0e4]],"prev_change_id":15557281258}}}
{"jsonrpc":"2.0","method":"subscription","params":{"channel":"book.ETH-PERPETUAL.raw","data":{"timestamp":1734114530471,"type":"change","change_id":15557281259,"instrument_name":"ETH-PERPETUAL","bids":[],"asks":[["new",3899.2,8.0e4]],"prev_change_id":15557281258}}}
{"jsonrpc":"2.0","method":"subscription","params":{"channel":"book.ETH-PERPETUAL.raw","data":{"timestamp":1734114530472,"type":"change","change_id":15557281260,"instrument_name":"ETH-PERPETUAL","bids":[["change",3883.9,1.6e5]],"asks":[],"prev_change_id":15557281259}}}
{"jsonrpc":"2.0","method":"subscription","params":{"channel":"book.ETH-PERPETUAL.raw","data":{"timestamp":1734114530472,"type":"change","change_id":15557281260,"instrument_name":"ETH-PERPETUAL","bids":[["change",3883.9,1.6e5]],"asks":[],"prev_change_id":15557281259}}}
{"jsonrpc":"2.0","method":"subscription","params":{"channel":"book.ETH-PERPETUAL.raw","data":{"timestamp":1734114530474,"type":"change","change_id":15557281261,"instrument_name":"ETH-PERPETUAL","bids":[],"asks":[["change",3899.2,1.6e5]],"prev_change_id":15557281260}}}
{"jsonrpc":"2.0","method":"subscription","params":{"channel":"book.ETH-PERPETUAL.raw","data":{"timestamp":1734114530474,"type":"change","change_id":15557281261,"instrument_name":"ETH-PERPETUAL","bids":[],"asks":[["change",3899.2,1.6e5]],"prev_change_id":15557281260}}}
{"jsonrpc":"2.0","method":"subscription","params":{"channel":"book.ETH-PERPETUAL.raw","data":{"timestamp":1734114530590,"type":"change","change_id":15557281271,"instrument_name":"ETH-PERPETUAL","bids":[["delete",3883.9,0.0]],"asks":[["delete",3899.2,0.0]],"prev_change_id":15557281261}}}
{"jsonrpc":"2.0","method":"subscription","params":{"channel":"book.ETH-PERPETUAL.raw","data":{"timestamp":1734114530590,"type":"change","change_id":15557281271,"instrument_name":"ETH-PERPETUAL","bids":[["delete",3883.9,0.0]],"asks":[["delete",3899.2,0.0]],"prev_change_id":15557281261}}}
{"jsonrpc":"2.0","method":"subscription","params":{"channel":"book.ETH-PERPETUAL.raw","data":{"timestamp":1734114530769,"type":"change","change_id":15557281272,"instrument_name":"ETH-PERPETUAL","bids":[["new",3883.9,8.0e4]],"asks":[],"prev_change_id":15557281271}}}
{"jsonrpc":"2.0","method":"subscription","params":{"channel":"book.ETH-PERPETUAL.raw","data":{"timestamp":1734114530769,"type":"change","change_id":15557281272,"instrument_name":"ETH-PERPETUAL","bids":[["new",3883.9,8.0e4]],"asks":[],"prev_change_id":15557281271}}}
{"jsonrpc":"2.0","method":"subscription","params":{"channel":"book.ETH-PERPETUAL.raw","data":{"timestamp":1734114530770,"type":"change","change_id":15557281273,"instrument_name":"ETH-PERPETUAL","bids":[],"asks":[["new",3899.2,8.0e4]],"prev_change_id":15557281272}}}
{"jsonrpc":"2.0","method":"subscription","params":{"channel":"book.ETH-PERPETUAL.raw","data":{"timestamp":1734114530770,"type":"change","change_id":15557281273,"instrument_name":"ETH-PERPETUAL","bids":[],"asks":[["new",3899.2,8.0e4]],"prev_change_id":15557281272}}}
{"jsonrpc":"2.0","method":"subscription","params":{"channel":"book.ETH-PERPETUAL.raw","data":{"timestamp":1734114530771,"type":"change","change_id":15557281274,"instrument_name":"ETH-PERPETUAL","bids":[["change",3883.9,1.0e5]],"asks":[],"prev_change_id":15557281273}}}
{"jsonrpc":"2.0","method":"subscription","params":{"channel":"book.ETH-PERPETUAL.raw","data":{"timestamp":1734114530771,"type":"change","change_id":15557281274,"instrument_name":"ETH-PERPETUAL","bids":[["change",3883.9,1.0e5]],"asks":[],"prev_change_id":15557281273}}}
{"jsonrpc":"2.0","method":"subscription","params":{"channel":"book.ETH-PERPETUAL.raw","data":{"timestamp":1734114530772,"type":"change","change_id":15557281275,"instrument_name":"ETH-PERPETUAL","bids":[["change",3883.9,1.8e5]],"asks":[],"prev_change_id":15557281274}}}
{"jsonrpc":"2.0","method":"subscription","params":{"channel":"book.ETH-PERPETUAL.raw","data":{"timestamp":1734114530772,"type":"change","change_id":15557281275,"instrument_name":"ETH-PERPETUAL","bids":[["change",3883.9,1.8e5]],"asks":[],"prev_change_id":15557281274}}}
{"jsonrpc":"2.0","method":"subscription","params":{"channel":"book.ETH-PERPETUAL.raw","data":{"timestamp":1734114530773,"type":"change","change_id":15557281276,"instrument_name":"ETH-PERPETUAL","bids":[],"asks":[["change",3899.2,1.6e5]],"prev_change_id":15557281275}}}
{"jsonrpc":"2.0","method":"subscription","params":{"channel":"book.ETH-PERPETUAL.raw","data":{"timestamp":1734114530773,"type":"change","change_id":15557281276,"instrument_name":"ETH-PERPETUAL","bids":[],"asks":[["change",3899.2,1.6e5]],"prev_change_id":15557281275}}}
{"jsonrpc":"2.0","method":"subscription","params":{"channel":"book.ETH-PERPETUAL.raw","data":{"timestamp":1734114530774,"type":"change","change_id":15557281277,"instrument_name":"ETH-PERPETUAL","bids":[["change",3883.9,2.0e5]],"asks":[],"prev_change_id":15557281276}}}
{"jsonrpc":"2.0","method":"subscription","params":{"channel":"book.ETH-PERPETUAL.raw","data":{"timestamp":1734114530774,"type":"change","change_id":15557281277,"instrument_name":"ETH-PERPETUAL","bids":[["change",3883.9,2.0e5]],"asks":[],"prev_change_id":15557281276}}}
{"jsonrpc":"2.0","method":"subscription","params":{"channel":"book.ETH-PERPETUAL.raw","data":{"timestamp":1734114530904,"type":"change","change_id":15557281280,"instrument_name":"ETH-PERPETUAL","bids":[["delete",3883.9,0.0]],"asks":[["delete",3899.2,0.0]],"prev_change_id":15557281277}}}
{"jsonrpc":"2.0","method":"subscription","params":{"channel":"book.ETH-PERPETUAL.raw","data":{"timestamp":1734114530904,"type":"change","change_id":15557281280,"instrument_name":"ETH-PERPETUAL","bids":[["delete",3883.9,0.0]],"asks":[["delete",3899.2,0.0]],"prev_change_id":15557281277}}}
{"jsonrpc":"2.0","method":"subscription","params":{"channel":"book.ETH-PERPETUAL.raw","data":{"timestamp":1734114531133,"type":"change","change_id":15557281281,"instrument_name":"ETH-PERPETUAL","bids":[["new",3883.9,8.0e4]],"asks":[],"prev_change_id":15557281280}}}
{"jsonrpc":"2.0","method":"subscription","params":{"channel":"book.ETH-PERPETUAL.raw","data":{"timestamp":1734114531133,"type":"change","change_id":15557281281,"instrument_name":"ETH-PERPETUAL","bids":[["new",3883.9,8.0e4]],"asks":[],"prev_change_id":15557281280}}}
{"jsonrpc":"2.0","method":"subscription","params":{"channel":"book.ETH-PERPETUAL.raw","data":{"timestamp":1734114531136,"type":"change","change_id":15557281282,"instrument_name":"ETH-PERPETUAL","bids":[],"asks":[["new",3899.2,8.0e4]],"prev_change_id":15557281281}}}
{"jsonrpc":"2.0","method":"subscription","params":{"channel":"book.ETH-PERPETUAL.raw","data":{"timestamp":1734114531136,"type":"change","change_id":15557281282,"instrument_name":"ETH-PERPETUAL","bids":[],"asks":[["new",3899.2,8.0e4]],"prev_change_id":15557281281}}}
{"jsonrpc":"2.0","method":"subscription","params":{"channel":"book.ETH-PERPETUAL.raw","data":{"timestamp":1734114531138,"type":"change","change_id":15557281283,"instrument_name":"ETH-PERPETUAL","bids":[["change",3883.9,1.0e5]],"asks":[],"prev_change_id":15557281282}}}
{"jsonrpc":"2.0","method":"subscription","params":{"channel":"book.ETH-PERPETUAL.raw","data":{"timestamp":1734114531138,"type":"change","change_id":15557281283,"instrument_name":"ETH-PERPETUAL","bids":[["change",3883.9,1.0e5]],"asks":[],"prev_change_id":15557281282}}}
{"jsonrpc":"2.0","method":"subscription","params":{"channel":"book.ETH-PERPETUAL.raw","data":{"timestamp":1734114531139,"type":"change","change_id":15557281284,"instrument_name":"ETH-PERPETUAL","bids":[],"asks":[["change",3899.2,1.0e5]],"prev_change_id":15557281283}}}
{"jsonrpc":"2.0","method":"subscription","params":{"channel":"book.ETH-PERPETUAL.raw","data":{"timestamp":1734114531139,"type":"change","change_id":15557281284,"instrument_name":"ETH-PERPETUAL","bids":[],"asks":[["change",3899.2,1.0e5]],"prev_change_id":15557281283}}}
{"jsonrpc":"2.0","method":"subscription","params":{"channel":"book.ETH-PERPETUAL.raw","data":{"timestamp":1734114531140,"type":"change","change_id":15557281285,"instrument_name":"ETH-PERPETUAL","bids":[["change",3883.9,1.8e5]],"asks":[],"prev_change_id":15557281284}}}
{"jsonrpc":"2.0","method":"subscription","params":{"channel":"book.ETH-PERPETUAL.raw","data":{"timestamp":1734114531140,"type":"change","change_id":15557281285,"instrument_name":"ETH-PERPETUAL","bids":[["change",3883.9,1.8e5]],"asks":[],"prev_change_id":15557281284}}}
{"jsonrpc":"2.0","method":"subscription","params":{"channel":"book.ETH-PERPETUAL.raw","data":{"timestamp":1734114531141,"type":"change","change_id":15557281286,"instrument_name":"ETH-PERPETUAL","bids":[],"asks":[["change",3899.2,1.8e5]],"prev_change_id":15557281285}}}
{"jsonrpc":"2.0","method":"subscription","params":{"channel":"book.ETH-PERPETUAL.raw","data":{"timestamp":1734114531141,"type":"change","change_id":15557281286,"instrument_name":"ETH-PERPETUAL","bids":[],"asks":[["change",3899.2,1.8e5]],"prev_change_id":15557281285}}}
{"jsonrpc":"2.0","method":"subscription","params":{"channel":"book.ETH-PERPETUAL.raw","data":{"timestamp":1734114531143,"type":"change","change_id":15557281287,"instrument_name":"ETH-PERPETUAL","bids":[["change",3883.9,2.0e5]],"asks":[],"prev_change_id":15557281286}}}
{"jsonrpc":"2.0","method":"subscription","params":{"channel":"book.ETH-PERPETUAL.raw","data":{"timestamp":1734114531143,"type":"change","change_id":15557281287,"instrument_name":"ETH-PERPETUAL","bids":[["change",3883.9,2.0e5]],"asks":[],"prev_change_id":15557281286}}}
{"jsonrpc":"2.0","method":"subscription","params":{"channel":"book.ETH-PERPETUAL.raw","data":{"timestamp":1734114531147,"type":"change","change_id":15557281288,"instrument_name":"ETH-PERPETUAL","bids":[],"asks":[["change",3899.2,2.0e5]],"prev_change_id":15557281287}}}
{"jsonrpc":"2.0","method":"subscription","params":{"channel":"book.ETH-PERPETUAL.raw","data":{"timestamp":1734114531147,"type":"change","change_id":15557281288,"instrument_name":"ETH-PERPETUAL","bids":[],"asks":[["change",3899.2,2.0e5]],"prev_change_id":15557281287}}}
{"jsonrpc":"2.0","method":"subscription","params":{"channel":"book.ETH-PERPETUAL.raw","data":{"timestamp":1734114531283,"type":"change","change_id":15557281289,"instrument_name":"ETH-PERPETUAL","bids":[],"asks":[["new",3910.9,500.0],["delete",3921.75,0.0]],"prev_change_id":15557281288}}}
{"jsonrpc":"2.0","method":"subscription","params":{"channel":"book.ETH-PERPETUAL.raw","data":{"timestamp":1734114531283,"type":"change","change_id":15557281289,"instrument_name":"ETH-PERPETUAL","bids":[],"asks":[["new",3910.9,500.0],["delete",3921.75,0.0]],"prev_change_id":15557281288}}}
{"jsonrpc":"2.0","method":"subscription","params":{"channel":"book.ETH-PERPETUAL.raw","data":{"timestamp":1734114531332,"type":"change","change_id":15557281290,"instrument_name":"ETH-PERPETUAL","bids":[["delete",3883.9,0.0]],"asks":[["delete",3899.2,0.0]],"prev_change_id":15557281289}}}
{"jsonrpc":"2.0","method":"subscription","params":{"channel":"book.ETH-PERPETUAL.raw","data":{"timestamp":1734114531332,"type":"change","change_id":15557281290,"instrument_name":"ETH-PERPETUAL","bids":[["delete",3883.9,0.0]],"asks":[["delete",3899.2,0.0]],"prev_change_id":15557281289}}}
{"jsonrpc":"2.0","method":"subscription","params":{"channel":"book.ETH-PERPETUAL.raw","data":{"timestamp":1734114531477,"type":"change","change_id":15557281291,"instrument_name":"ETH-PERPETUAL","bids":[],"asks":[["delete",3919.05,0.0],["new",3929.55,500.0]],"prev_change_id":15557281290}}}
{"jsonrpc":"2.0","method":"subscription","params":{"channel":"book.ETH-PERPETUAL.raw","data":{"timestamp":1734114531477,"type":"change","change_id":15557281291,"instrument_name":"ETH-PERPETUAL","bids":[],"asks":[["delete",3919.05,0.0],["new",3929.55,500.0]],"prev_change_id":15557281290}}}
{"jsonrpc":"2.0","method":"subscription","params":{"channel":"book.ETH-PERPETUAL.raw","data":{"timestamp":1734114531521,"type":"change","change_id":15557281302,"instrument_name":"ETH-PERPETUAL","bids":[["new",3883.9,8.0e4]],"asks":[],"prev_change_id":15557281291}}}
{"jsonrpc":"2.0","method":"subscription","params":{"channel":"book.ETH-PERPETUAL.raw","data":{"timestamp":1734114531521,"type":"change","change_id":15557281302,"instrument_name":"ETH-PERPETUAL","bids":[["new",3883.9,8.0e4]],"asks":[],"prev_change_id":15557281291}}}
{"jsonrpc":"2.0","method":"subscription","params":{"channel":"book.ETH-PERPETUAL.raw","data":{"timestamp":1734114531522,"type":"change","change_id":15557281303,"instrument_name":"ETH-PERPETUAL","bids":[],"asks":[["new",3899.15,8.0e4]],"prev_change_id":15557281302}}}
{"jsonrpc":"2.0","method":"subscription","params":{"channel":"book.ETH-PERPETUAL.raw","data":{"timestamp":1734114531522,"type":"change","change_id":15557281303,"instrument_name":"ETH-PERPETUAL","bids":[],"asks":[["new",3899.15,8.0e4]],"prev_change_id":15557281302}}}
{"jsonrpc":"2.0","method":"subscription","params":{"channel":"book.ETH-PERPETUAL.raw","data":{"timestamp":1734114531523,"type":"change","change_id":15557281304,"instrument_name":"ETH-PERPETUAL","bids":[["change",3883.9,1.0e5]],"asks":[],"prev_change_id":15557281303}}}
{"jsonrpc":"2.0","method":"subscription","params":{"channel":"book.ETH-PERPETUAL.raw","data":{"timestamp":1734114531523,"type":"change","change_id":15557281304,"instrument_name":"ETH-PERPETUAL","bids":[["change",3883.9,1.0e5]],"asks":[],"prev_change_id":15557281303}}}
{"jsonrpc":"2.0","method":"subscription","params":{"channel":"book.ETH-PERPETUAL.raw","data":{"timestamp":1734114531529,"type":"change","change_id":15557281307,"instrument_name":"ETH-PERPETUAL","bids":[["change",3883.9,1.8e5]],"asks":[],"prev_change_id":15557281304}}}
{"jsonrpc":"2.0","method":"subscription","params":{"channel":"book.ETH-PERPETUAL.raw","data":{"timestamp":1734114531529,"type":"change","change_id":15557281307,"instrument_name":"ETH-PERPETUAL","bids":[["change",3883.9,1.8e5]],"asks":[],"prev_change_id":15557281304}}}
{"jsonrpc":"2.0","method":"subscription","params":{"channel":"book.ETH-PERPETUAL.raw","data":{"timestamp":1734114531530,"type":"change","change_id":15557281308,"instrument_name":"ETH-PERPETUAL","bids":[],"asks":[["change",3899.15,1.6e5]],"prev_change_id":15557281307}}}
{"jsonrpc":"2.0","method":"subscription","params":{"channel":"book.ETH-PERPETUAL.raw","data":{"timestamp":1734114531530,"type":"change","change_id":15557281308,"instrument_name":"ETH-PERPETUAL","bids":[],"asks":[["change",3899.15,1.6e5]],"prev_change_id":15557281307}}}
{"jsonrpc":"2.0","method":"subscription","params":{"channel":"book.ETH-PERPETUAL.raw","data":{"timestamp":1734114531531,"type":"change","change_id":15557281310,"instrument_name":"ETH-PERPETUAL","bids":[["change",3883.9,2.0e5]],"asks":[],"prev_change_id":15557281308}}}
{"jsonrpc":"2.0","method":"subscription","params":{"channel":"book.ETH-PERPETUAL.raw","data":{"timestamp":1734114531531,"type":"change","change_id":15557281310,"instrument_name":"ETH-PERPETUAL","bids":[["change",3883.9,2.0e5]],"asks":[],"prev_change_id":15557281308}}}
{"jsonrpc":"2.0","method":"subscription","params":{"channel":"book.ETH-PERPETUAL.raw","data":{"timestamp":1734114531665,"type":"change","change_id":15557281328,"instrument_name":"ETH-PERPETUAL","bids":[["delete",3883.9,0.0]],"asks":[["delete",3899.15,0.0]],"prev_change_id":15557281310}}}
{"jsonrpc":"2.0","method":"subscription","params":{"channel":"book.ETH-PERPETUAL.raw","data":{"timestamp":1734114531665,"type":"change","change_id":15557281328,"instrument_name":"ETH-PERPETUAL","bids":[["delete",3883.9,0.0]],"asks":[["delete",3899.15,0.0]],"prev_change_id":15557281310}}}
{"jsonrpc":"2.0","method":"subscription","params":{"channel":"book.ETH-PERPETUAL.raw","data":{"timestamp":1734114531883,"type":"change","change_id":15557281331,"instrument_name":"ETH-PERPETUAL","bids":[["new",3883.85,8.0e4]],"asks":[],"prev_change_id":15557281328}}}
{"jsonrpc":"2.0","method":"subscription","params":{"channel":"book.ETH-PERPETUAL.raw","data":{"timestamp":1734114531883,"type":"change","change_id":15557281331,"instrument_name":"ETH-PERPETUAL","bids":[["new",3883.85,8.0e4]],"asks":[],"prev_change_id":15557281328}}}
{"jsonrpc":"2.0","method":"subscription","params":{"channel":"book.ETH-PERPETUAL.raw","data":{"timestamp":1734114531886,"type":"change","change_id":15557281333,"instrument_name":"ETH-PERPETUAL","bids":[],"asks":[["new",3899.1,8.0e4]],"prev_change_id":15557281331}}}
{"jsonrpc":"2.0","method":"subscription","params":{"channel":"book.ETH-PERPETUAL.raw","data":{"timestamp":1734114531886,"type":"change","change_id":15557281333,"instrument_name":"ETH-PERPETUAL","bids":[],"asks":[["new",3899.1,8.0e4]],"prev_change_id":15557281331}}}
{"jsonrpc":"2.0","method":"subscription","params":{"channel":"book.ETH-PERPETUAL.raw","data":{"timestamp":1734114531888,"type":"change","change_id":15557281334,"instrument_name":"ETH-PERPETUAL","bids":[["change",3883.85,1.0e5]],"asks":[],"prev_change_id":15557281333}}}
{"jsonrpc":"2.0","method":"subscription","params":{"channel":"book.ETH-PERPETUAL.raw","data":{"timestamp":1734114531888,"type":"change","change_id":15557281334,"instrument_name":"ETH-PERPETUAL","bids":[["change",3883.85,1.0e5]],"asks":[],"prev_change_id":15557281333}}}
{"jsonrpc":"2.0","method":"subscription","params":{"channel":"book.ETH-PERPETUAL.raw","data":{"timestamp":1734114531891,"type":"change","change_id":15557281336,"instrument_name":"ETH-PERPETUAL","bids":[],"asks":[["change",3899.1,1.0e5]],"prev_change_id":15557281334}}}
{"jsonrpc":"2.0","method":"subscription","params":{"channel":"book.ETH-PERPETUAL.raw","data":{"timestamp":1734114531891,"type":"change","change_id":15557281336,"instrument_name":"ETH-PERPETUAL","bids":[],"asks":[["change",3899.1,1.0e5]],"prev_change_id":15557281334}}}
{"jsonrpc":"2.0","method":"subscription","params":{"channel":"book.ETH-PERPETUAL.raw","data":{"timestamp":1734114531893,"type":"change","change_id":15557281337,"instrument_name":"ETH-PERPETUAL","bids":[["change",3883.85,1.8e5]],"asks":[],"prev_change_id":15557281336}}}
{"jsonrpc":"2.0","method":"subscription","params":{"channel":"book.ETH-PERPETUAL.raw","data":{"timestamp":1734114531893,"type":"change","change_id":15557281337,"instrument_name":"ETH-PERPETUAL","bids":[["change",3883.85,1.8e5]],"asks":[],"prev_change_id":15557281336}}}
{"jsonrpc":"2.0","method":"subscription","params":{"channel":"book.ETH-PERPETUAL.raw","data":{"timestamp":1734114531896,"type":"change","change_id":15557281338,"instrument_name":"ETH-PERPETUAL","bids":[],"asks":[["change",3899.1,1.8e5]],"prev_change_id":15557281337}}}
{"jsonrpc":"2.0","method":"subscription","params":{"channel":"book.ETH-PERPETUAL.raw","data":{"timestamp":1734114531896,"type":"change","change_id":15557281338,"instrument_name":"ETH-PERPETUAL","bids":[],"asks":[["change",3899.1,1.8e5]],"prev_change_id":15557281337}}}
{"jsonrpc":"2.0","method":"subscription","params":{"channel":"book.ETH-PERPETUAL.raw","data":{"timestamp":1734114531897,"type":"change","change_id":15557281339,"instrument_name":"ETH-PERPETUAL","bids":[["change",3883.85,2.0e5]],"asks":[],"prev_change_id":15557281338}}}
{"jsonrpc":"2.0","method":"subscription","params":{"channel":"book.ETH-PERPETUAL.raw","data":{"timestamp":1734114531897,"type":"change","change_id":15557281339,"instrument_name":"ETH-PERPETUAL","bids":[["change",3883.85,2.0e5]],"asks":[],"prev_change_id":15557281338}}}
{"jsonrpc":"2.0","method":"subscription","params":{"channel":"book.ETH-PERPETUAL.raw","data":{"timestamp":1734114531901,"type":"change","change_id":15557281340,"instrument_name":"ETH-PERPETUAL","bids":[],"asks":[["change",3899.1,2.0e5]],"prev_change_id":15557281339}}}
{"jsonrpc":"2.0","method":"subscription","params":{"channel":"book.ETH-PERPETUAL.raw","data":{"timestamp":1734114531901,"type":"change","change_id":15557281340,"instrument_name":"ETH-PERPETUAL","bids":[],"asks":[["change",3899.1,2.0e5]],"prev_change_id":15557281339}}}
{"jsonrpc":"2.0","method":"subscription","params":{"channel":"book.ETH-PERPETUAL.raw","data":{"timestamp":1734114532017,"type":"change","change_id":15557281341,"instrument_name":"ETH-PERPETUAL","bids":[["delete",3883.85,0.0]],"asks":[["delete",3899.1,0.0]],"prev_change_id":15557281340}}}
{"jsonrpc":"2.0","method":"subscription","params":{"channel":"book.ETH-PERPETUAL.raw","data":{"timestamp":1734114532017,"type":"change","change_id":15557281341,"instrument_name":"ETH-PERPETUAL","bids":[["delete",3883.85,0.0]],"asks":[["delete",3899.1,0.0]],"prev_change_id":15557281340}}}
{"jsonrpc":"2.0","method":"subscription","params":{"channel":"book.ETH-PERPETUAL.raw","data":{"timestamp":1734114532201,"type":"change","change_id":15557281343,"instrument_name":"ETH-PERPETUAL","bids":[["new",3883.85,8.0e4]],"asks":[],"prev_change_id":15557281341}}}
{"jsonrpc":"2.0","method":"subscription","params":{"channel":"book.ETH-PERPETUAL.raw","data":{"timestamp":1734114532201,"type":"change","change_id":15557281343,"instrument_name":"ETH-PERPETUAL","bids":[["new",3883.85,8.0e4]],"asks":[],"prev_change_id":15557281341}}}
{"jsonrpc":"2.0","method":"subscription","params":{"channel":"book.ETH-PERPETUAL.raw","data":{"timestamp":1734114532203,"type":"change","change_id":15557281344,"instrument_name":"ETH-PERPETUAL","bids":[],"asks":[["new",3899.1,8.0e4]],"prev_change_id":15557281343}}}
{"jsonrpc":"2.0","method":"subscription","params":{"channel":"book.ETH-PERPETUAL.raw","data":{"timestamp":1734114532203,"type":"change","change_id":15557281344,"instrument_name":"ETH-PERPETUAL","bids":[],"asks":[["new",3899.1,8.0e4]],"prev_change_id":15557281343}}}
{"jsonrpc":"2.0","method":"subscription","params":{"channel":"book.ETH-PERPETUAL.raw","data":{"timestamp":1734114532205,"type":"change","change_id":15557281345,"instrument_name":"ETH-PERPETUAL","bids":[["change",3883.85,1.6e5]],"asks":[],"prev_change_id":15557281344}}}
{"jsonrpc":"2.0","method":"subscription","params":{"channel":"book.ETH-PERPETUAL.raw","data":{"timestamp":1734114532205,"type":"change","change_id":15557281345,"instrument_name":"ETH-PERPETUAL","bids":[["change",3883.85,1.6e5]],"asks":[],"prev_change_id":15557281344}}}
{"jsonrpc":"2.0","method":"subscription","params":{"channel":"book.ETH-PERPETUAL.raw","data":{"timestamp":1734114532206,"type":"change","change_id":15557281346,"instrument_name":"ETH-PERPETUAL","bids":[],"asks":[["change",3899.1,1.6e5]],"prev_change_id":15557281345}}}
{"jsonrpc":"2.0","method":"subscription","params":{"channel":"book.ETH-PERPETUAL.raw","data":{"timestamp":1734114532206,"type":"change","change_id":15557281346,"instrument_name":"ETH-PERPETUAL","bids":[],"asks":[["change",3899.1,1.6e5]],"prev_change_id":15557281345}}}
{"jsonrpc":"2.0","method":"subscription","params":{"channel":"book.ETH-PERPETUAL.raw","data":{"timestamp":1734114532357,"type":"change","change_id":15557281347,"instrument_name":"ETH-PERPETUAL","bids":[["delete",3883.85,0.0]],"asks":[["delete",3899.1,0.0]],"prev_change_id":15557281346}}}
{"jsonrpc":"2.0","method":"subscription","params":{"channel":"book.ETH-PERPETUAL.raw","data":{"timestamp":1734114532357,"type":"change","change_id":15557281347,"instrument_name":"ETH-PERPETUAL","bids":[["delete",3883.85,0.0]],"asks":[["delete",3899.1,0.0]],"prev_change_id":15557281346}}}
{"jsonrpc":"2.0","method":"subscription","params":{"channel":"book.ETH-PERPETUAL.raw","data":{"timestamp":1734114532560,"type":"change","change_id":15557281371,"instrument_name":"ETH-PERPETUAL","bids":[["new",3883.75,8.0e4]],"asks":[],"prev_change_id":15557281347}}}
{"jsonrpc":"2.0","method":"subscription","params":{"channel":"book.ETH-PERPETUAL.raw","data":{"timestamp":1734114532560,"type":"change","change_id":15557281371,"instrument_name":"ETH-PERPETUAL","bids":[["new",3883.75,8.0e4]],"asks":[],"prev_change_id":15557281347}}}
{"jsonrpc":"2.0","method":"subscription","params":{"channel":"book.ETH-PERPETUAL.raw","data":{"timestamp":1734114532562,"type":"change","change_id":15557281372,"instrument_name":"ETH-PERPETUAL","bids":[],"asks":[["new",3898.95,8.0e4]],"prev_change_id":15557281371}}}
{"jsonrpc":"2.0","method":"subscription","params":{"channel":"book.ETH-PERPETUAL.raw","data":{"timestamp":1734114532562,"type":"change","change_id":15557281372,"instrument_name":"ETH-PERPETUAL","bids":[],"asks":[["new",3898.95,8.0e4]],"prev_change_id":15557281371}}}
{"jsonrpc":"2.0","method":"subscription","params":{"channel":"book.ETH-PERPETUAL.raw","data":{"timestamp":1734114532563,"type":"change","change_id":15557281373,"instrument_name":"ETH-PERPETUAL","bids":[["change",3883.75,1.0e5]],"asks":[],"prev_change_id":15557281372}}}
{"jsonrpc":"2.0","method":"subscription","params":{"channel":"book.ETH-PERPETUAL.raw","data":{"timestamp":1734114532563,"type":"change","change_id":15557281373,"instrument_name":"ETH-PERPETUAL","bids":[["change",3883.75,1.0e5]],"asks":[],"prev_change_id":15557281372}}}
{"jsonrpc":"2.0","method":"subscription","params":{"channel":"book.ETH-PERPETUAL.raw","data":{"timestamp":1734114532566,"type":"change","change_id":15557281374,"instrument_name":"ETH-PERPETUAL","bids":[],"asks":[["change",3898.95,1.0e5]],"prev_change_id":15557281373}}}
{"jsonrpc":"2.0","method":"subscription","params":{"channel":"book.ETH-PERPETUAL.raw","data":{"timestamp":1734114532566,"type":"change","change_id":15557281374,"instrument_name":"ETH-PERPETUAL","bids":[],"asks":[["change",3898.95,1.0e5]],"prev_change_id":15557281373}}}
{"jsonrpc":"2.0","method":"subscription","params":{"channel":"book.ETH-PERPETUAL.raw","data":{"timestamp":1734114532567,"type":"change","change_id":15557281375,"instrument_name":"ETH-PERPETUAL","bids":[["change",3883.75,1.8e5]],"asks":[],"prev_change_id":15557281374}}}
{"jsonrpc":"2.0","method":"subscription","params":{"channel":"book.ETH-PERPETUAL.raw","data":{"timestamp":1734114532567,"type":"change","change_id":15557281375,"instrument_name":"ETH-PERPETUAL","bids":[["change",3883.75,1.8e5]],"asks":[],"prev_change_id":15557281374}}}
{"jsonrpc":"2.0","method":"subscription","params":{"channel":"book.ETH-PERPETUAL.raw","data":{"timestamp":1734114532568,"type":"change","change_id":15557281376,"instrument_name":"ETH-PERPETUAL","bids":[],"asks":[["change",3898.95,1.8e5]],"prev_change_id":15557281375}}}
{"jsonrpc":"2.0","method":"subscription","params":{"channel":"book.ETH-PERPETUAL.raw","data":{"timestamp":1734114532568,"type":"change","change_id":15557281376,"instrument_name":"ETH-PERPETUAL","bids":[],"asks":[["change",3898.95,1.8e5]],"prev_change_id":15557281375}}}
{"jsonrpc":"2.0","method":"subscription","params":{"channel":"book.ETH-PERPETUAL.raw","data":{"timestamp":1734114532569,"type":"change","change_id":15557281377,"instrument_name":"ETH-PERPETUAL","bids":[["change",3883.75,2.0e5]],"asks":[],"prev_change_id":15557281376}}}
{"jsonrpc":"2.0","method":"subscription","params":{"channel":"book.ETH-PERPETUAL.raw","data":{"timestamp":1734114532569,"type":"change","change_id":15557281377,"instrument_name":"ETH-PERPETUAL","bids":[["change",3883.75,2.0e5]],"asks":[],"prev_change_id":15557281376}}}
{"jsonrpc":"2.0","method":"subscription","params":{"channel":"book.ETH-PERPETUAL.raw","data":{"timestamp":1734114532573,"type":"change","change_id":15557281378,"instrument_name":"ETH-PERPETUAL","bids":[],"asks":[["change",3898.95,2.0e5]],"prev_change_id":15557281377}}}
{"jsonrpc":"2.0","method":"subscription","params":{"channel":"book.ETH-PERPETUAL.raw","data":{"timestamp":1734114532573,"type":"change","change_id":15557281378,"instrument_name":"ETH-PERPETUAL","bids":[],"asks":[["change",3898.95,2.0e5]],"prev_change_id":15557281377}}}
{"jsonrpc":"2.0","method":"subscription","params":{"channel":"book.ETH-PERPETUAL.raw","data":{"timestamp":1734114532650,"type":"change","change_id":15557281379,"instrument_name":"ETH-PERPETUAL","bids":[["delete",3883.75,0.0]],"asks":[["delete",3898.95,0.0]],"prev_change_id":15557281378}}}
{"jsonrpc":"2.0","method":"subscription","params":{"channel":"book.ETH-PERPETUAL.raw","data":{"timestamp":1734114532650,"type":"change","change_id":15557281379,"instrument_name":"ETH-PERPETUAL","bids":[["delete",3883.75,0.0]],"asks":[["delete",3898.95,0.0]],"prev_change_id":15557281378}}}
{"jsonrpc":"2.0","method":"subscription","params":{"channel":"book.ETH-PERPETUAL.raw","data":{"timestamp":1734114532706,"type":"change","change_id":15557281380,"instrument_name":"ETH-PERPETUAL","bids":[["new",3844.9,700.0],["delete",3833.6,0.0]],"asks":[],"prev_change_id":15557281379}}}
{"jsonrpc":"2.0","method":"subscription","params":{"channel":"book.ETH-PERPETUAL.raw","data":{"timestamp":1734114532706,"type":"change","change_id":15557281380,"instrument_name":"ETH-PERPETUAL","bids":[["new",3844.9,700.0],["delete",3833.6,0.0]],"asks":[],"prev_change_id":15557281379}}}
{"jsonrpc":"2.0","method":"subscription","params":{"channel":"book.ETH-PERPETUAL.raw","data":{"timestamp":1734114532707,"type":"change","change_id":15557281381,"instrument_name":"ETH-PERPETUAL","bids":[["new",3864.3,500.0],["delete",3853.05,0.0]],"asks":[],"prev_change_id":15557281380}}}
{"jsonrpc":"2.0","method":"subscription","params":{"channel":"book.ETH-PERPETUAL.raw","data":{"timestamp":1734114532707,"type":"change","change_id":15557281381,"instrument_name":"ETH-PERPETUAL","bids":[["new",3864.3,500.0],["delete",3853.05,0.0]],"asks":[],"prev_change_id":15557281380}}}
{"jsonrpc":"2.0","method":"subscription","params":{"channel":"book.ETH-PERPETUAL.raw","data":{"timestamp":1734114532708,"type":"change","change_id":15557281382,"instrument_name":"ETH-PERPETUAL","bids":[["new",3872.05,500.0],["delete",3860.8,0.0]],"asks":[],"prev_change_id":15557281381}}}
{"jsonrpc":"2.0","method":"subscription","params":{"channel":"book.ETH-PERPETUAL.raw","data":{"timestamp":1734114532708,"type":"change","change_id":15557281382,"instrument_name":"ETH-PERPETUAL","bids":[["new",3872.05,500.0],["delete",3860.8,0.0]],"asks":[],"prev_change_id":15557281381}}}
{"jsonrpc":"2.0","method":"subscription","params":{"channel":"book.ETH-PERPETUAL.raw","data":{"timestamp":1734114532821,"type":"change","change_id":15557281383,"instrument_name":"ETH-PERPETUAL","bids":[["new",3883.75,8.0e4]],"asks":[],"prev_change_id":15557281382}}}
{"jsonrpc":"2.0","method":"subscription","params":{"channel":"book.ETH-PERPETUAL.raw","data":{"timestamp":1734114532821,"type":"change","change_id":15557281383,"instrument_name":"ETH-PERPETUAL","bids":[["new",3883.75,8.0e4]],"asks":[],"prev_change_id":15557281382}}}
{"jsonrpc":"2.0","method":"subscription","params":{"channel":"book.ETH-PERPETUAL.raw","data":{"timestamp":1734114532823,"type":"change","change_id":15557281384,"instrument_name":"ETH-PERPETUAL","bids":[],"asks":[["new",3898.95,8.0e4]],"prev_change_id":15557281383}}}
{"jsonrpc":"2.0","method":"subscription","params":{"channel":"book.ETH-PERPETUAL.raw","data":{"timestamp":1734114532823,"type":"change","change_id":15557281384,"instrument_name":"ETH-PERPETUAL","bids":[],"asks":[["new",3898.95,8.0e4]],"prev_change_id":15557281383}}}
{"jsonrpc":"2.0","method":"subscription","params":{"channel":"book.ETH-PERPETUAL.raw","data":{"timestamp":1734114532824,"type":"change","change_id":15557281385,"instrument_name":"ETH-PERPETUAL","bids":[["change",3883.75,1.6e5]],"asks":[],"prev_change_id":15557281384}}}
{"jsonrpc":"2.0","method":"subscription","params":{"channel":"book.ETH-PERPETUAL.raw","data":{"timestamp":1734114532824,"type":"change","change_id":15557281385,"instrument_name":"ETH-PERPETUAL","bids":[["change",3883.75,1.6e5]],"asks":[],"prev_change_id":15557281384}}}
{"jsonrpc":"2.0","method":"subscription","params":{"channel":"book.ETH-PERPETUAL.raw","data":{"timestamp":1734114532825,"type":"change","change_id":15557281386,"instrument_name":"ETH-PERPETUAL","bids":[],"asks":[["change",3898.95,1.6e5]],"prev_change_id":15557281385}}}
{"jsonrpc":"2.0","method":"subscription","params":{"channel":"book.ETH-PERPETUAL.raw","data":{"timestamp":1734114532825,"type":"change","change_id":15557281386,"instrument_name":"ETH-PERPETUAL","bids":[],"asks":[["change",3898.95,1.6e5]],"prev_change_id":15557281385}}}
{"jsonrpc":"2.0","method":"subscription","params":{"channel":"book.ETH-PERPETUAL.raw","data":{"timestamp":1734114532914,"type":"change","change_id":15557281388,"instrument_name":"ETH-PERPETUAL","bids":[["new",1942.0,1.0]],"asks":[],"prev_change_id":15557281386}}}
{"jsonrpc":"2.0","method":"subscription","params":{"channel":"book.ETH-PERPETUAL.raw","data":{"timestamp":1734114532914,"type":"change","change_id":15557281388,"instrument_name":"ETH-PERPETUAL","bids":[["new",1942.0,1.0]],"asks":[],"prev_change_id":15557281386}}}
{"jsonrpc":"2.0","method":"subscription","params":{"channel":"book.ETH-PERPETUAL.raw","data":{"timestamp":1734114532960,"type":"change","change_id":15557281389,"instrument_name":"ETH-PERPETUAL","bids":[["delete",3883.75,0.0]],"asks":[["delete",3898.95,0.0]],"prev_change_id":15557281388}}}
{"jsonrpc":"2.0","method":"subscription","params":{"channel":"book.ETH-PERPETUAL.raw","data":{"timestamp":1734114532960,"type":"change","change_id":15557281389,"instrument_name":"ETH-PERPETUAL","bids":[["delete",3883.75,0.0]],"asks":[["delete",3898.95,0.0]],"prev_change_id":15557281388}}}
{"jsonrpc":"2.0","method":"subscription","params":{"channel":"book.ETH-PERPETUAL.raw","data":{"timestamp":1734114533142,"type":"change","change_id":15557281390,"instrument_name":"ETH-PERPETUAL","bids":[["new",3883.75,8.0e4]],"asks":[],"prev_change_id":15557281389}}}
{"jsonrpc":"2.0","method":"subscription","params":{"channel":"book.ETH-PERPETUAL.raw","data":{"timestamp":1734114533142,"type":"change","change_id":15557281390,"instrument_name":"ETH-PERPETUAL","bids":[["new",3883.75,8.0e4]],"asks":[],"prev_change_id":15557281389}}}
{"jsonrpc":"2.0","method":"subscription","params":{"channel":"book.ETH-PERPETUAL.raw","data":{"timestamp":1734114533144,"type":"change","change_id":15557281391,"instrument_name":"ETH-PERPETUAL","bids":[],"asks":[["new",3898.95,8.0e4]],"prev_change_id":15557281390}}}
{"jsonrpc":"2.0","method":"subscription","params":{"channel":"book.ETH-PERPETUAL.raw","data":{"timestamp":1734114533144,"type":"change","change_id":15557281391,"instrument_name":"ETH-PERPETUAL","bids":[],"asks":[["new",3898.95,8.0e4]],"prev_change_id":15557281390}}}
{"jsonrpc":"2.0","method":"subscription","params":{"channel":"book.ETH-PERPETUAL.raw","data":{"timestamp":1734114533148,"type":"change","change_id":15557281392,"instrument_name":"ETH-PERPETUAL","bids":[["change",3883.75,1.0e5]],"asks":[],"prev_change_id":15557281391}}}
{"jsonrpc":"2.0","method":"subscription","params":{"channel":"book.ETH-PERPETUAL.raw","data":{"timestamp":1734114533148,"type":"change","change_id":15557281392,"instrument_name":"ETH-PERPETUAL","bids":[["change",3883.75,1.0e5]],"asks":[],"prev_change_id":15557281391}}}
{"jsonrpc":"2.0","method":"subscription","params":{"channel":"book.ETH-PERPETUAL.raw","data":{"timestamp":1734114533149,"type":"change","change_id":15557281393,"instrument_name":"ETH-PERPETUAL","bids":[["change",3883.75,1.8e5]],"asks":[],"prev_change_id":15557281392}}}
{"jsonrpc":"2.0","method":"subscription","params":{"channel":"book.ETH-PERPETUAL.raw","data":{"timestamp":1734114533149,"type":"change","change_id":15557281393,"instrument_name":"ETH-PERPETUAL","bids":[["change",3883.75,1.8e5]],"asks":[],"prev_change_id":15557281392}}}
{"jsonrpc":"2.0","method":"subscription","params":{"channel":"book.ETH-PERPETUAL.raw","data":{"timestamp":1734114533150,"type":"change","change_id":15557281394,"instrument_name":"ETH-PERPETUAL","bids":[],"asks":[["change",3898.95,1.6e5]],"prev_change_id":15557281393}}}
{"jsonrpc":"2.0","method":"subscription","params":{"channel":"book.ETH-PERPETUAL.raw","data":{"timestamp":1734114533150,"type":"change","change_id":15557281394,"instrument_name":"ETH-PERPETUAL","bids":[],"asks":[["change",3898.95,1.6e5]],"prev_change_id":15557281393}}}
{"jsonrpc":"2.0","method":"subscription","params":{"channel":"book.ETH-PERPETUAL.raw","data":{"timestamp":1734114533151,"type":"change","change_id":15557281395,"instrument_name":"ETH-PERPETUAL","bids":[["change",3883.75,2.0e5]],"asks":[],"prev_change_id":15557281394}}}
{"jsonrpc":"2.0","method":"subscription","params":{"channel":"book.ETH-PERPETUAL.raw","data":{"timestamp":1734114533151,"type":"change","change_id":15557281395,"instrument_name":"ETH-PERPETUAL","bids":[["change",3883.75,2.0e5]],"asks":[],"prev_change_id":15557281394}}}
{"jsonrpc":"2.0","method":"subscription","params":{"channel":"book.ETH-PERPETUAL.raw","data":{"timestamp":1734114533288,"type":"change","change_id":15557281396,"instrument_name":"ETH-PERPETUAL","bids":[["delete",3883.75,0.0]],"asks":[["delete",3898.95,0.0]],"prev_change_id":15557281395}}}
{"jsonrpc":"2.0","method":"subscription","params":{"channel":"book.ETH-PERPETUAL.raw","data":{"timestamp":1734114533288,"type":"change","change_id":15557281396,"instrument_name":"ETH-PERPETUAL","bids":[["delete",3883.75,0.0]],"asks":[["delete",3898.95,0.0]],"prev_change_id":15557281395}}}
{"jsonrpc":"2.0","method":"subscription","params":{"channel":"book.ETH-PERPETUAL.raw","data":{"timestamp":1734114533458,"type":"change","change_id":15557281397,"instrument_name":"ETH-PERPETUAL","bids":[["new",3883.75,8.0e4]],"asks":[],"prev_change_id":15557281396}}}
{"jsonrpc":"2.0","method":"subscription","params":{"channel":"book.ETH-PERPETUAL.raw","data":{"timestamp":1734114533458,"type":"change","change_id":15557281397,"instrument_name":"ETH-PERPETUAL","bids":[["new",3883.75,8.0e4]],"asks":[],"prev_change_id":15557281396}}}
{"jsonrpc":"2.0","method":"subscription","params":{"channel":"book.ETH-PERPETUAL.raw","data":{"timestamp":1734114533460,"type":"change","change_id":15557281398,"instrument_name":"ETH-PERPETUAL","bids":[],"asks":[["new",3898.95,8.0e4]],"prev_change_id":15557281397}}}
{"jsonrpc":"2.0","method":"subscription","params":{"channel":"book.ETH-PERPETUAL.raw","data":{"timestamp":1734114533460,"type":"change","change_id":15557281398,"instrument_name":"ETH-PERPETUAL","bids":[],"asks":[["new",3898.95,8.0e4]],"prev_change_id":15557281397}}}
{"jsonrpc":"2.0","method":"subscription","params":{"channel":"book.ETH-PERPETUAL.raw","data":{"timestamp":1734114533461,"type":"change","change_id":15557281399,"instrument_name":"ETH-PERPETUAL","bids":[["change",3883.75,1.0e5]],"asks":[],"prev_change_id":15557281398}}}
{"jsonrpc":"2.0","method":"subscription","params":{"channel":"book.ETH-PERPETUAL.raw","data":{"timestamp":1734114533461,"type":"change","change_id":15557281399,"instrument_name":"ETH-PERPETUAL","bids":[["change",3883.75,1.0e5]],"asks":[],"prev_change_id":15557281398}}}
{"jsonrpc":"2.0","method":"subscription","params":{"channel":"book.ETH-PERPETUAL.raw","data":{"timestamp":1734114533462,"type":"change","change_id":15557281400,"instrument_name":"ETH-PERPETUAL","bids":[["change",3883.75,1.8e5]],"asks":[],"prev_change_id":15557281399}}}
{"jsonrpc":"2.0","method":"subscription","params":{"channel":"book.ETH-PERPETUAL.raw","data":{"timestamp":1734114533462,"type":"change","change_id":15557281400,"instrument_name":"ETH-PERPETUAL","bids":[["change",3883.75,1.8e5]],"asks":[],"prev_change_id":15557281399}}}
{"jsonrpc":"2.0","method":"subscription","params":{"channel":"book.ETH-PERPETUAL.raw","data":{"timestamp":1734114533464,"type":"change","change_id":15557281401,"instrument_name":"ETH-PERPETUAL","bids":[],"asks":[["change",3898.95,1.6e5]],"prev_change_id":15557281400}}}
{"jsonrpc":"2.0","method":"subscription","params":{"channel":"book.ETH-PERPETUAL.raw","data":{"timestamp":1734114533464,"type":"change","change_id":15557281401,"instrument_name":"ETH-PERPETUAL","bids":[],"asks":[["change",3898.95,1.6e5]],"prev_change_id":15557281400}}}
{"jsonrpc":"2.0","method":"subscription","params":{"channel":"book.ETH-PERPETUAL.raw","data":{"timestamp":1734114533465,"type":"change","change_id":15557281402,"instrument_name":"ETH-PERPETUAL","bids":[["change",3883.75,2.0e5]],"asks":[],"prev_change_id":15557281401}}}
{"jsonrpc":"2.0","method":"subscription","params":{"channel":"book.ETH-PERPETUAL.raw","data":{"timestamp":1734114533465,"type":"change","change_id":15557281402,"instrument_name":"ETH-PERPETUAL","bids":[["change",3883.75,2.0e5]],"asks":[],"prev_change_id":15557281401}}}
{"jsonrpc":"2.0","method":"subscription","params":{"channel":"book.ETH-PERPETUAL.raw","data":{"timestamp":1734114533603,"type":"change","change_id":15557281440,"instrument_name":"ETH-PERPETUAL","bids":[["delete",3883.75,0.0]],"asks":[["delete",3898.95,0.0]],"prev_change_id":15557281402}}}
{"jsonrpc":"2.0","method":"subscription","params":{"channel":"book.ETH-PERPETUAL.raw","data":{"timestamp":1734114533603,"type":"change","change_id":15557281440,"instrument_name":"ETH-PERPETUAL","bids":[["delete",3883.75,0.0]],"asks":[["delete",3898.95,0.0]],"prev_change_id":15557281402}}}
{"jsonrpc":"2.0","method":"subscription","params":{"channel":"book.ETH-PERPETUAL.raw","data":{"timestamp":1734114533802,"type":"change","change_id":15557281463,"instrument_name":"ETH-PERPETUAL","bids":[["new",3883.75,8.0e4]],"asks":[],"prev_change_id":15557281440}}}
{"jsonrpc":"2.0","method":"subscription","params":{"channel":"book.ETH-PERPETUAL.raw","data":{"timestamp":1734114533802,"type":"change","change_id":15557281463,"instrument_name":"ETH-PERPETUAL","bids":[["new",3883.75,8.0e4]],"asks":[],"prev_change_id":15557281440}}}
{"jsonrpc":"2.0","method":"subscription","params":{"channel":"book.ETH-PERPETUAL.raw","data":{"timestamp":1734114533803,"type":"change","change_id":15557281464,"instrument_name":"ETH-PERPETUAL","bids":[],"asks":[["new",3898.95,8.0e4]],"prev_change_id":15557281463}}}
{"jsonrpc":"2.0","method":"subscription","params":{"channel":"book.ETH-PERPETUAL.raw","data":{"timestamp":1734114533803,"type":"change","change_id":15557281464,"instrument_name":"ETH-PERPETUAL","bids":[],"asks":[["new",3898.95,8.0e4]],"prev_change_id":15557281463}}}
{"jsonrpc":"2.0","method":"subscription","params":{"channel":"book.ETH-PERPETUAL.raw","data":{"timestamp":1734114533805,"type":"change","change_id":15557281465,"instrument_name":"ETH-PERPETUAL","bids":[["change",3883.75,1.0e5]],"asks":[],"prev_change_id":15557281464}}}
{"jsonrpc":"2.0","method":"subscription","params":{"channel":"book.ETH-PERPETUAL.raw","data":{"timestamp":1734114533805,"type":"change","change_id":15557281465,"instrument_name":"ETH-PERPETUAL","bids":[["change",3883.75,1.0e5]],"asks":[],"prev_change_id":15557281464}}}
{"jsonrpc":"2.0","method":"subscription","params":{"channel":"book.ETH-PERPETUAL.raw","data":{"timestamp":1734114533806,"type":"change","change_id":15557281466,"instrument_name":"ETH-PERPETUAL","bids":[["change",3883.75,1.8e5]],"asks":[],"prev_change_id":15557281465}}}
{"jsonrpc":"2.0","method":"subscription","params":{"channel":"book.ETH-PERPETUAL.raw","data":{"timestamp":1734114533806,"type":"change","change_id":15557281466,"instrument_name":"ETH-PERPETUAL","bids":[["change",3883.75,1.8e5]],"asks":[],"prev_change_id":15557281465}}}
{"jsonrpc":"2.0","method":"subscription","params":{"channel":"book.ETH-PERPETUAL.raw","data":{"timestamp":1734114533808,"type":"change","change_id":15557281467,"instrument_name":"ETH-PERPETUAL","bids":[],"asks":[["change",3898.95,1.6e5]],"prev_change_id":15557281466}}}
{"jsonrpc":"2.0","method":"subscription","params":{"channel":"book.ETH-PERPETUAL.raw","data":{"timestamp":1734114533808,"type":"change","change_id":15557281467,"instrument_name":"ETH-PERPETUAL","bids":[],"asks":[["change",3898.95,1.6e5]],"prev_change_id":15557281466}}}
{"jsonrpc":"2.0","method":"subscription","params":{"channel":"book.ETH-PERPETUAL.raw","data":{"timestamp":1734114533809,"type":"change","change_id":15557281468,"instrument_name":"ETH-PERPETUAL","bids":[["change",3883.75,2.0e5]],"asks":[],"prev_change_id":15557281467}}}
{"jsonrpc":"2.0","method":"subscription","params":{"channel":"book.ETH-PERPETUAL.raw","data":{"timestamp":1734114533809,"type":"change","change_id":15557281468,"instrument_name":"ETH-PERPETUAL","bids":[["change",3883.75,2.0e5]],"asks":[],"prev_change_id":15557281467}}}
{"jsonrpc":"2.0","method":"subscription","params":{"channel":"book.ETH-PERPETUAL.raw","data":{"timestamp":1734114533975,"type":"change","change_id":15557281470,"instrument_name":"ETH-PERPETUAL","bids":[["delete",3883.75,0.0]],"asks":[["delete",3898.95,0.0]],"prev_change_id":15557281468}}}
{"jsonrpc":"2.0","method":"subscription","params":{"channel":"book.ETH-PERPETUAL.raw","data":{"timestamp":1734114533975,"type":"change","change_id":15557281470,"instrument_name":"ETH-PERPETUAL","bids":[["delete",3883.75,0.0]],"asks":[["delete",3898.95,0.0]],"prev_change_id":15557281468}}}
{"jsonrpc":"2.0","method":"subscription","params":{"channel":"book.ETH-PERPETUAL.raw","data":{"timestamp":1734114534126,"type":"change","change_id":15557281471,"instrument_name":"ETH-PERPETUAL","bids":[],"asks":[["delete",3937.9,0.0],["change",3949.1,800.0]],"prev_change_id":15557281470}}}
{"jsonrpc":"2.0","method":"subscription","params":{"channel":"book.ETH-PERPETUAL.raw","data":{"timestamp":1734114534126,"type":"change","change_id":15557281471,"instrument_name":"ETH-PERPETUAL","bids":[],"asks":[["delete",3937.9,0.0],["change",3949.1,800.0]],"prev_change_id":15557281470}}}
{"jsonrpc":"2.0","method":"subscription","params":{"channel":"book.ETH-PERPETUAL.raw","data":{"timestamp":1734114534168,"type":"change","change_id":15557281472,"instrument_name":"ETH-PERPETUAL","bids":[["new",3883.7,8.0e4]],"asks":[],"prev_change_id":15557281471}}}
{"jsonrpc":"2.0","method":"subscription","params":{"channel":"book.ETH-PERPETUAL.raw","data":{"timestamp":1734114534168,"type":"change","change_id":15557281472,"instrument_name":"ETH-PERPETUAL","bids":[["new",3883.7,8.0e4]],"asks":[],"prev_change_id":15557281471}}}
{"jsonrpc":"2.0","method":"subscription","params":{"channel":"book.ETH-PERPETUAL.raw","data":{"timestamp":1734114534169,"type":"change","change_id":15557281473,"instrument_name":"ETH-PERPETUAL","bids":[],"asks":[["new",3898.9,8.0e4]],"prev_change_id":15557281472}}}
{"jsonrpc":"2.0","method":"subscription","params":{"channel":"book.ETH-PERPETUAL.raw","data":{"timestamp":1734114534169,"type":"change","change_id":15557281473,"instrument_name":"ETH-PERPETUAL","bids":[],"asks":[["new",3898.9,8.0e4]],"prev_change_id":15557281472}}}
{"jsonrpc":"2.0","method":"subscription","params":{"channel":"book.ETH-PERPETUAL.raw","data":{"timestamp":1734114534170,"type":"change","change_id":15557281474,"instrument_name":"ETH-PERPETUAL","bids":[["change",3883.7,1.0e5]],"asks":[],"prev_change_id":15557281473}}}
{"jsonrpc":"2.0","method":"subscription","params":{"channel":"book.ETH-PERPETUAL.raw","data":{"timestamp":1734114534170,"type":"change","change_id":15557281474,"instrument_name":"ETH-PERPETUAL","bids":[["change",3883.7,1.0e5]],"asks":[],"prev_change_id":15557281473}}}
{"jsonrpc":"2.0","method":"subscription","params":{"channel":"book.ETH-PERPETUAL.raw","data":{"timestamp":1734114534172,"type":"change","change_id":15557281475,"instrument_name":"ETH-PERPETUAL","bids":[],"asks":[["change",3898.9,1.0e5]],"prev_change_id":15557281474}}}
{"jsonrpc":"2.0","method":"subscription","params":{"channel":"book.ETH-PERPETUAL.raw","data":{"timestamp":1734114534172,"type":"change","change_id":15557281475,"instrument_name":"ETH-PERPETUAL","bids":[],"asks":[["change",3898.9,1.0e5]],"prev_change_id":15557281474}}}
{"jsonrpc":"2.0","method":"subscription","params":{"channel":"book.ETH-PERPETUAL.raw","data":{"timestamp":1734114534173,"type":"change","change_id":15557281476,"instrument_name":"ETH-PERPETUAL","bids":[["change",3883.7,1.8e5]],"asks":[],"prev_change_id":15557281475}}}
{"jsonrpc":"2.0","method":"subscription","params":{"channel":"book.ETH-PERPETUAL.raw","data":{"timestamp":1734114534173,"type":"change","change_id":15557281476,"instrument_name":"ETH-PERPETUAL","bids":[["change",3883.7,1.8e5]],"asks":[],"prev_change_id":15557281475}}}
{"jsonrpc":"2.0","method":"subscription","params":{"channel":"book.ETH-PERPETUAL.raw","data":{"timestamp":1734114534174,"type":"change","change_id":15557281477,"instrument_name":"ETH-PERPETUAL","bids":[],"asks":[["change",3898.9,1.8e5]],"prev_change_id":15557281476}}}
{"jsonrpc":"2.0","method":"subscription","params":{"channel":"book.ETH-PERPETUAL.raw","data":{"timestamp":1734114534174,"type":"change","change_id":15557281477,"instrument_name":"ETH-PERPETUAL","bids":[],"asks":[["change",3898.9,1.8e5]],"prev_change_id":15557281476}}}
{"jsonrpc":"2.0","method":"subscription","params":{"channel":"book.ETH-PERPETUAL.raw","data":{"timestamp":1734114534175,"type":"change","change_id":15557281478,"instrument_name":"ETH-PERPETUAL","bids":[["change",3883.7,2.0e5]],"asks":[],"prev_change_id":15557281477}}}
{"jsonrpc":"2.0","method":"subscription","params":{"channel":"book.ETH-PERPETUAL.raw","data":{"timestamp":1734114534175,"type":"change","change_id":15557281478,"instrument_name":"ETH-PERPETUAL","bids":[["change",3883.7,2.0e5]],"asks":[],"prev_change_id":15557281477}}}
{"jsonrpc":"2.0","method":"subscription","params":{"channel":"book.ETH-PERPETUAL.raw","data":{"timestamp":1734114534176,"type":"change","change_id":15557281479,"instrument_name":"ETH-PERPETUAL","bids":[],"asks":[["change",3898.9,2.0e5]],"prev_change_id":15557281478}}}
{"jsonrpc":"2.0","method":"subscription","params":{"channel":"book.ETH-PERPETUAL.raw","data":{"timestamp":1734114534176,"type":"change","change_id":15557281479,"instrument_name":"ETH-PERPETUAL","bids":[],"asks":[["change",3898.9,2.0e5]],"prev_change_id":15557281478}}}
{"jsonrpc":"2.0","method":"subscription","params":{"channel":"book.ETH-PERPETUAL.raw","data":{"timestamp":1734114534315,"type":"change","change_id":15557281482,"instrument_name":"ETH-PERPETUAL","bids":[["delete",3883.7,0.0]],"asks":[["delete",3898.9,0.0]],"prev_change_id":15557281479}}}
{"jsonrpc":"2.0","method":"subscription","params":{"channel":"book.ETH-PERPETUAL.raw","data":{"timestamp":1734114534315,"type":"change","change_id":15557281482,"instrument_name":"ETH-PERPETUAL","bids":[["delete",3883.7,0.0]],"asks":[["delete",3898.9,0.0]],"prev_change_id":15557281479}}}
{"jsonrpc":"2.0","method":"subscription","params":{"channel":"book.ETH-PERPETUAL.raw","data":{"timestamp":1734114534521,"type":"change","change_id":15557281488,"instrument_name":"ETH-PERPETUAL","bids":[["new",3883.15,8.0e4]],"asks":[],"prev_change_id":15557281482}}}
{"jsonrpc":"2.0","method":"subscription","params":{"channel":"book.ETH-PERPETUAL.raw","data":{"timestamp":1734114534521,"type":"change","change_id":15557281488,"instrument_name":"ETH-PERPETUAL","bids":[["new",3883.15,8.0e4]],"asks":[],"prev_change_id":15557281482}}}
{"jsonrpc":"2.0","method":"subscription","params":{"channel":"book.ETH-PERPETUAL.raw","data":{"timestamp":1734114534523,"type":"change","change_id":15557281490,"instrument_name":"ETH-PERPETUAL","bids":[],"asks":[["new",3898.35,8.0e4]],"prev_change_id":15557281488}}}
{"jsonrpc":"2.0","method":"subscription","params":{"channel":"book.ETH-PERPETUAL.raw","data":{"timestamp":1734114534523,"type":"change","change_id":15557281490,"instrument_name":"ETH-PERPETUAL","bids":[],"asks":[["new",3898.35,8.0e4]],"prev_change_id":15557281488}}}
{"jsonrpc":"2.0","method":"subscription","params":{"channel":"book.ETH-PERPETUAL.raw","data":{"timestamp":1734114534524,"type":"change","change_id":15557281492,"instrument_name":"ETH-PERPETUAL","bids":[["change",3883.15,1.0e5]],"asks":[],"prev_change_id":15557281490}}}
{"jsonrpc":"2.0","method":"subscription","params":{"channel":"book.ETH-PERPETUAL.raw","data":{"timestamp":1734114534524,"type":"change","change_id":15557281492,"instrument_name":"ETH-PERPETUAL","bids":[["change",3883.15,1.0e5]],"asks":[],"prev_change_id":15557281490}}}
{"jsonrpc":"2.0","method":"subscription","params":{"channel":"book.ETH-PERPETUAL.raw","data":{"timestamp":1734114534526,"type":"change","change_id":15557281493,"instrument_name":"ETH-PERPETUAL","bids":[["change",3883.15,1.8e5]],"asks":[],"prev_change_id":15557281492}}}
{"jsonrpc":"2.0","method":"subscription","params":{"channel":"book.ETH-PERPETUAL.raw","data":{"timestamp":1734114534526,"type":"change","change_id":15557281493,"instrument_name":"ETH-PERPETUAL","bids":[["change",3883.15,1.8e5]],"asks":[],"prev_change_id":15557281492}}}
{"jsonrpc":"2.0","method":"subscription","params":{"channel":"book.ETH-PERPETUAL.raw","data":{"timestamp":1734114534527,"type":"change","change_id":15557281494,"instrument_name":"ETH-PERPETUAL","bids":[],"asks":[["change",3898.35,1.6e5]],"prev_change_id":15557281493}}}
{"jsonrpc":"2.0","method":"subscription","params":{"channel":"book.ETH-PERPETUAL.raw","data":{"timestamp":1734114534527,"type":"change","change_id":15557281494,"instrument_name":"ETH-PERPETUAL","bids":[],"asks":[["change",3898.35,1.6e5]],"prev_change_id":15557281493}}}
{"jsonrpc":"2.0","method":"subscription","params":{"channel":"book.ETH-PERPETUAL.raw","data":{"timestamp":1734114534528,"type":"change","change_id":15557281495,"instrument_name":"ETH-PERPETUAL","bids":[["change",3883.15,2.0e5]],"asks":[],"prev_change_id":15557281494}}}
{"jsonrpc":"2.0","method":"subscription","params":{"channel":"book.ETH-PERPETUAL.raw","data":{"timestamp":1734114534528,"type":"change","change_id":15557281495,"instrument_name":"ETH-PERPETUAL","bids":[["change",3883.15,2.0e5]],"asks":[],"prev_change_id":15557281494}}}
{"jsonrpc":"2.0","method":"subscription","params":{"channel":"book.ETH-PERPETUAL.raw","data":{"timestamp":1734114534646,"type":"change","change_id":15557281500,"instrument_name":"ETH-PERPETUAL","bids":[["delete",3883.15,0.0]],"asks":[["delete",3898.35,0.0]],"prev_change_id":15557281495}}}
{"jsonrpc":"2.0","method":"subscription","params":{"channel":"book.ETH-PERPETUAL.raw","data":{"timestamp":1734114534646,"type":"change","change_id":15557281500,"instrument_name":"ETH-PERPETUAL","bids":[["delete",3883.15,0.0]],"asks":[["delete",3898.35,0.0]],"prev_change_id":15557281495}}}
{"jsonrpc":"2.0","method":"subscription","params":{"channel":"book.ETH-PERPETUAL.raw","data":{"timestamp":1734114534835,"type":"change","change_id":15557281504,"instrument_name":"ETH-PERPETUAL","bids":[["new",3883.15,8.0e4]],"asks":[],"prev_change_id":15557281500}}}
{"jsonrpc":"2.0","method":"subscription","params":{"channel":"book.ETH-PERPETUAL.raw","data":{"timestamp":1734114534835,"type":"change","change_id":15557281504,"instrument_name":"ETH-PERPETUAL","bids":[["new",3883.15,8.0e4]],"asks":[],"prev_change_id":15557281500}}}
{"jsonrpc":"2.0","method":"subscription","params":{"channel":"book.ETH-PERPETUAL.raw","data":{"timestamp":1734114534837,"type":"change","change_id":15557281505,"instrument_name":"ETH-PERPETUAL","bids":[],"asks":[["new",3898.3,8.0e4]],"prev_change_id":15557281504}}}
{"jsonrpc":"2.0","method":"subscription","params":{"channel":"book.ETH-PERPETUAL.raw","data":{"timestamp":1734114534837,"type":"change","change_id":15557281505,"instrument_name":"ETH-PERPETUAL","bids":[],"asks":[["new",3898.3,8.0e4]],"prev_change_id":15557281504}}}
{"jsonrpc":"2.0","method":"subscription","params":{"channel":"book.ETH-PERPETUAL.raw","data":{"timestamp":1734114534839,"type":"change","change_id":15557281506,"instrument_name":"ETH-PERPETUAL","bids":[["change",3883.15,1.6e5]],"asks":[],"prev_change_id":15557281505}}}
{"jsonrpc":"2.0","method":"subscription","params":{"channel":"book.ETH-PERPETUAL.raw","data":{"timestamp":1734114534839,"type":"change","change_id":15557281506,"instrument_name":"ETH-PERPETUAL","bids":[["change",3883.15,1.6e5]],"asks":[],"prev_change_id":15557281505}}}
{"jsonrpc":"2.0","method":"subscription","params":{"channel":"book.ETH-PERPETUAL.raw","data":{"timestamp":1734114534840,"type":"change","change_id":15557281507,"instrument_name":"ETH-PERPETUAL","bids":[],"asks":[["change",3898.3,1.6e5]],"prev_change_id":15557281506}}}
{"jsonrpc":"2.0","method":"subscription","params":{"channel":"book.ETH-PERPETUAL.raw","data":{"timestamp":1734114534840,"type":"change","change_id":15557281507,"instrument_name":"ETH-PERPETUAL","bids":[],"asks":[["change",3898.3,1.6e5]],"prev_change_id":15557281506}}}
{"jsonrpc":"2.0","method":"subscription","params":{"channel":"book.ETH-PERPETUAL.raw","data":{"timestamp":1734114534952,"type":"change","change_id":15557281511,"instrument_name":"ETH-PERPETUAL","bids":[["delete",1942.0,0.0]],"asks":[],"prev_change_id":15557281507}}}
{"jsonrpc":"2.0","method":"subscription","params":{"channel":"book.ETH-PERPETUAL.raw","data":{"timestamp":1734114534952,"type":"change","change_id":15557281511,"instrument_name":"ETH-PERPETUAL","bids":[["delete",1942.0,0.0]],"asks":[],"prev_change_id":15557281507}}}
{"jsonrpc":"2.0","method":"subscription","params":{"channel":"book.ETH-PERPETUAL.raw","data":{"timestamp":1734114534978,"type":"change","change_id":15557281512,"instrument_name":"ETH-PERPETUAL","bids":[["delete",3883.15,0.0]],"asks":[["delete",3898.3,0.0]],"prev_change_id":15557281511}}}
{"jsonrpc":"2.0","method":"subscription","params":{"channel":"book.ETH-PERPETUAL.raw","data":{"timestamp":1734114534978,"type":"change","change_id":15557281512,"instrument_name":"ETH-PERPETUAL","bids":[["delete",3883.15,0.0]],"asks":[["delete",3898.3,0.0]],"prev_change_id":15557281511}}}
{"jsonrpc":"2.0","method":"subscription","params":{"channel":"book.ETH-PERPETUAL.raw","data":{"timestamp":1734114535164,"type":"change","change_id":15557281518,"instrument_name":"ETH-PERPETUAL","bids":[["new",3883.15,8.0e4]],"asks":[],"prev_change_id":15557281512}}}
{"jsonrpc":"2.0","method":"subscription","params":{"channel":"book.ETH-PERPETUAL.raw","data":{"timestamp":1734114535164,"type":"change","change_id":15557281518,"instrument_name":"ETH-PERPETUAL","bids":[["new",3883.15,8.0e4]],"asks":[],"prev_change_id":15557281512}}}
{"jsonrpc":"2.0","method":"subscription","params":{"channel":"book.ETH-PERPETUAL.raw","data":{"timestamp":1734114535166,"type":"change","change_id":15557281520,"instrument_name":"ETH-PERPETUAL","bids":[],"asks":[["new",3898.3,8.0e4]],"prev_change_id":15557281518}}}
{"jsonrpc":"2.0","method":"subscription","params":{"channel":"book.ETH-PERPETUAL.raw","data":{"timestamp":1734114535166,"type":"change","change_id":15557281520,"instrument_name":"ETH-PERPETUAL","bids":[],"asks":[["new",3898.3,8.0e4]],"prev_change_id":15557281518}}}
{"jsonrpc":"2.0","method":"subscription","params":{"channel":"book.ETH-PERPETUAL.raw","data":{"timestamp":1734114535168,"type":"change","change_id":15557281522,"instrument_name":"ETH-PERPETUAL","bids":[["change",3883.15,1.0e5]],"asks":[],"prev_change_id":15557281520}}}
{"jsonrpc":"2.0","method":"subscription","params":{"channel":"book.ETH-PERPETUAL.raw","data":{"timestamp":1734114535168,"type":"change","change_id":15557281522,"instrument_name":"ETH-PERPETUAL","bids":[["change",3883.15,1.0e5]],"asks":[],"prev_change_id":15557281520}}}
{"jsonrpc":"2.0","method":"subscription","params":{"channel":"book.ETH-PERPETUAL.raw","data":{"timestamp":1734114535170,"type":"change","change_id":15557281525,"instrument_name":"ETH-PERPETUAL","bids":[],"asks":[["change",3898.3,1.0e5]],"prev_change_id":15557281522}}}
{"jsonrpc":"2.0","method":"subscription","params":{"channel":"book.ETH-PERPETUAL.raw","data":{"timestamp":1734114535170,"type":"change","change_id":15557281525,"instrument_name":"ETH-PERPETUAL","bids":[],"asks":[["change",3898.3,1.0e5]],"prev_change_id":15557281522}}}
{"jsonrpc":"2.0","method":"subscription","params":{"channel":"book.ETH-PERPETUAL.raw","data":{"timestamp":1734114535171,"type":"change","change_id":15557281527,"instrument_name":"ETH-PERPETUAL","bids":[["change",3883.15,1.8e5]],"asks":[],"prev_change_id":15557281525}}}
{"jsonrpc":"2.0","method":"subscription","params":{"channel":"book.ETH-PERPETUAL.raw","data":{"timestamp":1734114535171,"type":"change","change_id":15557281527,"instrument_name":"ETH-PERPETUAL","bids":[["change",3883.15,1.8e5]],"asks":[],"prev_change_id":15557281525}}}
{"jsonrpc":"2.0","method":"subscription","params":{"channel":"book.ETH-PERPETUAL.raw","data":{"timestamp":1734114535173,"type":"change","change_id":15557281529,"instrument_name":"ETH-PERPETUAL","bids":[],"asks":[["change",3898.3,1.8e5]],"prev_change_id":15557281527}}}
{"jsonrpc":"2.0","method":"subscription","params":{"channel":"book.ETH-PERPETUAL.raw","data":{"timestamp":1734114535173,"type":"change","change_id":15557281529,"instrument_name":"ETH-PERPETUAL","bids":[],"asks":[["change",3898.3,1.8e5]],"prev_change_id":15557281527}}}
{"jsonrpc":"2.0","method":"subscription","params":{"channel":"book.ETH-PERPETUAL.raw","data":{"timestamp":1734114535174,"type":"change","change_id":15557281531,"instrument_name":"ETH-PERPETUAL","bids":[["change",3883.15,2.0e5]],"asks":[],"prev_change_id":15557281529}}}
{"jsonrpc":"2.0","method":"subscription","params":{"channel":"book.ETH-PERPETUAL.raw","data":{"timestamp":1734114535174,"type":"change","change_id":15557281531,"instrument_name":"ETH-PERPETUAL","bids":[["change",3883.15,2.0e5]],"asks":[],"prev_change_id":15557281529}}}
{"jsonrpc":"2.0","method":"subscription","params":{"channel":"book.ETH-PERPETUAL.raw","data":{"timestamp":1734114535176,"type":"change","change_id":15557281533,"instrument_name":"ETH-PERPETUAL","bids":[],"asks":[["change",3898.3,2.0e5]],"prev_change_id":15557281531}}}
{"jsonrpc":"2.0","method":"subscription","params":{"channel":"book.ETH-PERPETUAL.raw","data":{"timestamp":1734114535176,"type":"change","change_id":15557281533,"instrument_name":"ETH-PERPETUAL","bids":[],"asks":[["change",3898.3,2.0e5]],"prev_change_id":15557281531}}}
{"jsonrpc":"2.0","method":"subscription","params":{"channel":"book.ETH-PERPETUAL.raw","data":{"timestamp":1734114535293,"type":"change","change_id":15557281540,"instrument_name":"ETH-PERPETUAL","bids":[["delete",3883.15,0.0]],"asks":[["delete",3898.3,0.0]],"prev_change_id":15557281533}}}
{"jsonrpc":"2.0","method":"subscription","params":{"channel":"book.ETH-PERPETUAL.raw","data":{"timestamp":1734114535293,"type":"change","change_id":15557281540,"instrument_name":"ETH-PERPETUAL","bids":[["delete",3883.15,0.0]],"asks":[["delete",3898.3,0.0]],"prev_change_id":15557281533}}}
{"jsonrpc":"2.0","method":"subscription","params":{"channel":"book.ETH-PERPETUAL.raw","data":{"timestamp":1734114535490,"type":"change","change_id":15557281568,"instrument_name":"ETH-PERPETUAL","bids":[["new",3882.65,8.0e4]],"asks":[],"prev_change_id":15557281540}}}
{"jsonrpc":"2.0","method":"subscription","params":{"channel":"book.ETH-PERPETUAL.raw","data":{"timestamp":1734114535490,"type":"change","change_id":15557281568,"instrument_name":"ETH-PERPETUAL","bids":[["new",3882.65,8.0e4]],"asks":[],"prev_change_id":15557281540}}}
{"jsonrpc":"2.0","method":"subscription","params":{"channel":"book.ETH-PERPETUAL.raw","data":{"timestamp":1734114535492,"type":"change","change_id":15557281570,"instrument_name":"ETH-PERPETUAL","bids":[],"asks":[["new",3897.85,8.0e4]],"prev_change_id":15557281568}}}
{"jsonrpc":"2.0","method":"subscription","params":{"channel":"book.ETH-PERPETUAL.raw","data":{"timestamp":1734114535492,"type":"change","change_id":15557281570,"instrument_name":"ETH-PERPETUAL","bids":[],"asks":[["new",3897.85,8.0e4]],"prev_change_id":15557281568}}}
{"jsonrpc":"2.0","method":"subscription","params":{"channel":"book.ETH-PERPETUAL.raw","data":{"timestamp":1734114535494,"type":"change","change_id":15557281573,"instrument_name":"ETH-PERPETUAL","bids":[["change",3882.65,1.6e5]],"asks":[],"prev_change_id":15557281570}}}
{"jsonrpc":"2.0","method":"subscription","params":{"channel":"book.ETH-PERPETUAL.raw","data":{"timestamp":1734114535494,"type":"change","change_id":15557281573,"instrument_name":"ETH-PERPETUAL","bids":[["change",3882.65,1.6e5]],"asks":[],"prev_change_id":15557281570}}}
{"jsonrpc":"2.0","method":"subscription","params":{"channel":"book.ETH-PERPETUAL.raw","data":{"timestamp":1734114535496,"type":"change","change_id":15557281575,"instrument_name":"ETH-PERPETUAL","bids":[],"asks":[["change",3897.85,1.6e5]],"prev_change_id":15557281573}}}
{"jsonrpc":"2.0","method":"subscription","params":{"channel":"book.ETH-PERPETUAL.raw","data":{"timestamp":1734114535496,"type":"change","change_id":15557281575,"instrument_name":"ETH-PERPETUAL","bids":[],"asks":[["change",3897.85,1.6e5]],"prev_change_id":15557281573}}}
{"jsonrpc":"2.0","method":"subscription","params":{"channel":"book.ETH-PERPETUAL.raw","data":{"timestamp":1734114535620,"type":"change","change_id":15557281630,"instrument_name":"ETH-PERPETUAL","bids":[["delete",3882.65,0.0]],"asks":[["delete",3897.85,0.0]],"prev_change_id":15557281575}}}
{"jsonrpc":"2.0","method":"subscription","params":{"channel":"book.ETH-PERPETUAL.raw","data":{"timestamp":1734114535620,"type":"change","change_id":15557281630,"instrument_name":"ETH-PERPETUAL","bids":[["delete",3882.65,0.0]],"asks":[["delete",3897.85,0.0]],"prev_change_id":15557281575}}}
{"jsonrpc":"2.0","method":"subscription","params":{"channel":"book.ETH-PERPETUAL.raw","data":{"timestamp":1734114535822,"type":"change","change_id":15557281640,"instrument_name":"ETH-PERPETUAL","bids":[["new",3882.0,8.0e4]],"asks":[],"prev_change_id":15557281630}}}
{"jsonrpc":"2.0","method":"subscription","params":{"channel":"book.ETH-PERPETUAL.raw","data":{"timestamp":1734114535822,"type":"change","change_id":15557281640,"instrument_name":"ETH-PERPETUAL","bids":[["new",3882.0,8.0e4]],"asks":[],"prev_change_id":15557281630}}}
{"jsonrpc":"2.0","method":"subscription","params":{"channel":"book.ETH-PERPETUAL.raw","data":{"timestamp":1734114535824,"type":"change","change_id":15557281641,"instrument_name":"ETH-PERPETUAL","bids":[],"asks":[["new",3898.2,8.0e4]],"prev_change_id":15557281640}}}
{"jsonrpc":"2.0","method":"subscription","params":{"channel":"book.ETH-PERPETUAL.raw","data":{"timestamp":1734114535824,"type":"change","change_id":15557281641,"instrument_name":"ETH-PERPETUAL","bids":[],"asks":[["new",3898.2,8.0e4]],"prev_change_id":15557281640}}}
{"jsonrpc":"2.0","method":"subscription","params":{"channel":"book.ETH-PERPETUAL.raw","data":{"timestamp":1734114535825,"type":"change","change_id":15557281642,"instrument_name":"ETH-PERPETUAL","bids":[["change",3882.0,1.0e5]],"asks":[],"prev_change_id":15557281641}}}
{"jsonrpc":"2.0","method":"subscription","params":{"channel":"book.ETH-PERPETUAL.raw","data":{"timestamp":1734114535825,"type":"change","change_id":15557281642,"instrument_name":"ETH-PERPETUAL","bids":[["change",3882.0,1.0e5]],"asks":[],"prev_change_id":15557281641}}}
{"jsonrpc":"2.0","method":"subscription","params":{"channel":"book.ETH-PERPETUAL.raw","data":{"timestamp":1734114535827,"type":"change","change_id":15557281643,"instrument_name":"ETH-PERPETUAL","bids":[["change",3882.0,1.8e5]],"asks":[],"prev_change_id":15557281642}}}
{"jsonrpc":"2.0","method":"subscription","params":{"channel":"book.ETH-PERPETUAL.raw","data":{"timestamp":1734114535827,"type":"change","change_id":15557281643,"instrument_name":"ETH-PERPETUAL","bids":[["change",3882.0,1.8e5]],"asks":[],"prev_change_id":15557281642}}}
{"jsonrpc":"2.0","method":"subscription","params":{"channel":"book.ETH-PERPETUAL.raw","data":{"timestamp":1734114535829,"type":"change","change_id":15557281644,"instrument_name":"ETH-PERPETUAL","bids":[],"asks":[["change",3898.2,1.6e5]],"prev_change_id":15557281643}}}
{"jsonrpc":"2.0","method":"subscription","params":{"channel":"book.ETH-PERPETUAL.raw","data":{"timestamp":1734114535829,"type":"change","change_id":15557281644,"instrument_name":"ETH-PERPETUAL","bids":[],"asks":[["change",3898.2,1.6e5]],"prev_change_id":15557281643}}}
{"jsonrpc":"2.0","method":"subscription","params":{"channel":"book.ETH-PERPETUAL.raw","data":{"timestamp":1734114535830,"type":"change","change_id":15557281645,"instrument_name":"ETH-PERPETUAL","bids":[["change",3882.0,2.0e5]],"asks":[],"prev_change_id":15557281644}}}
{"jsonrpc":"2.0","method":"subscription","params":{"channel":"book.ETH-PERPETUAL.raw","data":{"timestamp":1734114535830,"type":"change","change_id":15557281645,"instrument_name":"ETH-PERPETUAL","bids":[["change",3882.0,2.0e5]],"asks":[],"prev_change_id":15557281644}}}
{"jsonrpc":"2.0","method":"subscription","params":{"channel":"book.ETH-PERPETUAL.raw","data":{"timestamp":1734114535971,"type":"change","change_id":15557281652,"instrument_name":"ETH-PERPETUAL","bids":[["delete",3882.0,0.0]],"asks":[["delete",3898.2,0.0]],"prev_change_id":15557281645}}}
{"jsonrpc":"2.0","method":"subscription","params":{"channel":"book.ETH-PERPETUAL.raw","data":{"timestamp":1734114535971,"type":"change","change_id":15557281652,"instrument_name":"ETH-PERPETUAL","bids":[["delete",3882.0,0.0]],"asks":[["delete",3898.2,0.0]],"prev_change_id":15557281645}}}
{"jsonrpc":"2.0","method":"subscription","params":{"channel":"book.ETH-PERPETUAL.raw","data":{"timestamp":1734114536166,"type":"change","change_id":15557281654,"instrument_name":"ETH-PERPETUAL","bids":[["new",3881.7,8.0e4]],"asks":[],"prev_change_id":15557281652}}}
{"jsonrpc":"2.0","method":"subscription","params":{"channel":"book.ETH-PERPETUAL.raw","data":{"timestamp":1734114536166,"type":"change","change_id":15557281654,"instrument_name":"ETH-PERPETUAL","bids":[["new",3881.7,8.0e4]],"asks":[],"prev_change_id":15557281652}}}
{"jsonrpc":"2.0","method":"subscription","params":{"channel":"book.ETH-PERPETUAL.raw","data":{"timestamp":1734114536168,"type":"change","change_id":15557281655,"instrument_name":"ETH-PERPETUAL","bids":[],"asks":[["new",3898.55,8.0e4]],"prev_change_id":15557281654}}}
{"jsonrpc":"2.0","method":"subscription","params":{"channel":"book.ETH-PERPETUAL.raw","data":{"timestamp":1734114536168,"type":"change","change_id":15557281655,"instrument_name":"ETH-PERPETUAL","bids":[],"asks":[["new",3898.55,8.0e4]],"prev_change_id":15557281654}}}
{"jsonrpc":"2.0","method":"subscription","params":{"channel":"book.ETH-PERPETUAL.raw","data":{"timestamp":1734114536169,"type":"change","change_id":15557281656,"instrument_name":"ETH-PERPETUAL","bids":[["change",3881.7,1.0e5]],"asks":[],"prev_change_id":15557281655}}}
{"jsonrpc":"2.0","method":"subscription","params":{"channel":"book.ETH-PERPETUAL.raw","data":{"timestamp":1734114536169,"type":"change","change_id":15557281656,"instrument_name":"ETH-PERPETUAL","bids":[["change",3881.7,1.0e5]],"asks":[],"prev_change_id":15557281655}}}
{"jsonrpc":"2.0","method":"subscription","params":{"channel":"book.ETH-PERPETUAL.raw","data":{"timestamp":1734114536171,"type":"change","change_id":15557281657,"instrument_name":"ETH-PERPETUAL","bids":[],"asks":[["change",3898.55,1.0e5]],"prev_change_id":15557281656}}}
{"jsonrpc":"2.0","method":"subscription","params":{"channel":"book.ETH-PERPETUAL.raw","data":{"timestamp":1734114536171,"type":"change","change_id":15557281657,"instrument_name":"ETH-PERPETUAL","bids":[],"asks":[["change",3898.55,1.0e5]],"prev_change_id":15557281656}}}
{"jsonrpc":"2.0","method":"subscription","params":{"channel":"book.ETH-PERPETUAL.raw","data":{"timestamp":1734114536172,"type":"change","change_id":15557281658,"instrument_name":"ETH-PERPETUAL","bids":[["change",3881.7,1.8e5]],"asks":[],"prev_change_id":15557281657}}}
{"jsonrpc":"2.0","method":"subscription","params":{"channel":"book.ETH-PERPETUAL.raw","data":{"timestamp":1734114536172,"type":"change","change_id":15557281658,"instrument_name":"ETH-PERPETUAL","bids":[["change",3881.7,1.8e5]],"asks":[],"prev_change_id":15557281657}}}
{"jsonrpc":"2.0","method":"subscription","params":{"channel":"book.ETH-PERPETUAL.raw","data":{"timestamp":1734114536174,"type":"change","change_id":15557281659,"instrument_name":"ETH-PERPETUAL","bids":[],"asks":[["change",3898.55,1.8e5]],"prev_change_id":15557281658}}}
{"jsonrpc":"2.0","method":"subscription","params":{"channel":"book.ETH-PERPETUAL.raw","data":{"timestamp":1734114536174,"type":"change","change_id":15557281659,"instrument_name":"ETH-PERPETUAL","bids":[],"asks":[["change",3898.55,1.8e5]],"prev_change_id":15557281658}}}
{"jsonrpc":"2.0","method":"subscription","params":{"channel":"book.ETH-PERPETUAL.raw","data":{"timestamp":1734114536176,"type":"change","change_id":15557281660,"instrument_name":"ETH-PERPETUAL","bids":[["change",3881.7,2.0e5]],"asks":[],"prev_change_id":15557281659}}}
{"jsonrpc":"2.0","method":"subscription","params":{"channel":"book.ETH-PERPETUAL.raw","data":{"timestamp":1734114536176,"type":"change","change_id":15557281660,"instrument_name":"ETH-PERPETUAL","bids":[["change",3881.7,2.0e5]],"asks":[],"prev_change_id":15557281659}}}
{"jsonrpc":"2.0","method":"subscription","params":{"channel":"book.ETH-PERPETUAL.raw","data":{"timestamp":1734114536177,"type":"change","change_id":15557281661,"instrument_name":"ETH-PERPETUAL","bids":[],"asks":[["change",3898.55,2.0e5]],"prev_change_id":15557281660}}}
{"jsonrpc":"2.0","method":"subscription","params":{"channel":"book.ETH-PERPETUAL.raw","data":{"timestamp":1734114536177,"type":"change","change_id":15557281661,"instrument_name":"ETH-PERPETUAL","bids":[],"asks":[["change",3898.55,2.0e5]],"prev_change_id":15557281660}}}
{"jsonrpc":"2.0","method":"subscription","params":{"channel":"book.ETH-PERPETUAL.raw","data":{"timestamp":1734114536301,"type":"change","change_id":15557281666,"instrument_name":"ETH-PERPETUAL","bids":[["delete",3881.7,0.0]],"asks":[["delete",3898.55,0.0]],"prev_change_id":15557281661}}}
{"jsonrpc":"2.0","method":"subscription","params":{"channel":"book.ETH-PERPETUAL.raw","data":{"timestamp":1734114536301,"type":"change","change_id":15557281666,"instrument_name":"ETH-PERPETUAL","bids":[["delete",3881.7,0.0]],"asks":[["delete",3898.55,0.0]],"prev_change_id":15557281661}}}
{"jsonrpc":"2.0","method":"subscription","params":{"channel":"book.ETH-PERPETUAL.raw","data":{"timestamp":1734114536446,"type":"change","change_id":15557281683,"instrument_name":"ETH-PERPETUAL","bids":[],"asks":[["delete",3910.9,0.0],["new",3921.75,500.0]],"prev_change_id":15557281666}}}
{"jsonrpc":"2.0","method":"subscription","params":{"channel":"book.ETH-PERPETUAL.raw","data":{"timestamp":1734114536446,"type":"change","change_id":15557281683,"instrument_name":"ETH-PERPETUAL","bids":[],"asks":[["delete",3910.9,0.0],["new",3921.75,500.0]],"prev_change_id":15557281666}}}
{"jsonrpc":"2.0","method":"subscription","params":{"channel":"book.ETH-PERPETUAL.raw","data":{"timestamp":1734114536490,"type":"change","change_id":15557281684,"instrument_name":"ETH-PERPETUAL","bids":[["new",3881.25,8.0e4]],"asks":[],"prev_change_id":15557281683}}}
{"jsonrpc":"2.0","method":"subscription","params":{"channel":"book.ETH-PERPETUAL.raw","data":{"timestamp":1734114536490,"type":"change","change_id":15557281684,"instrument_name":"ETH-PERPETUAL","bids":[["new",3881.25,8.0e4]],"asks":[],"prev_change_id":15557281683}}}
{"jsonrpc":"2.0","method":"subscription","params":{"channel":"book.ETH-PERPETUAL.raw","data":{"timestamp":1734114536491,"type":"change","change_id":15557281685,"instrument_name":"ETH-PERPETUAL","bids":[],"asks":[["new",3898.45,8.0e4]],"prev_change_id":15557281684}}}
{"jsonrpc":"2.0","method":"subscription","params":{"channel":"book.ETH-PERPETUAL.raw","data":{"timestamp":1734114536491,"type":"change","change_id":15557281685,"instrument_name":"ETH-PERPETUAL","bids":[],"asks":[["new",3898.45,8.0e4]],"prev_change_id":15557281684}}}
{"jsonrpc":"2.0","method":"subscription","params":{"channel":"book.ETH-PERPETUAL.raw","data":{"timestamp":1734114536492,"type":"change","change_id":15557281686,"instrument_name":"ETH-PERPETUAL","bids":[["change",3881.25,1.6e5]],"asks":[],"prev_change_id":15557281685}}}
{"jsonrpc":"2.0","method":"subscription","params":{"channel":"book.ETH-PERPETUAL.raw","data":{"timestamp":1734114536492,"type":"change","change_id":15557281686,"instrument_name":"ETH-PERPETUAL","bids":[["change",3881.25,1.6e5]],"asks":[],"prev_change_id":15557281685}}}
{"jsonrpc":"2.0","method":"subscription","params":{"channel":"book.ETH-PERPETUAL.raw","data":{"timestamp":1734114536493,"type":"change","change_id":15557281687,"instrument_name":"ETH-PERPETUAL","bids":[],"asks":[["change",3898.45,1.6e5]],"prev_change_id":15557281686}}}
{"jsonrpc":"2.0","method":"subscription","params":{"channel":"book.ETH-PERPETUAL.raw","data":{"timestamp":1734114536493,"type":"change","change_id":15557281687,"instrument_name":"ETH-PERPETUAL","bids":[],"asks":[["change",3898.45,1.6e5]],"prev_change_id":15557281686}}}
{"jsonrpc":"2.0","method":"subscription","params":{"channel":"book.ETH-PERPETUAL.raw","data":{"timestamp":1734114536624,"type":"change","change_id":15557281741,"instrument_name":"ETH-PERPETUAL","bids":[["delete",3881.25,0.0]],"asks":[["delete",3898.45,0.0]],"prev_change_id":15557281687}}}
{"jsonrpc":"2.0","method":"subscription","params":{"channel":"book.ETH-PERPETUAL.raw","data":{"timestamp":1734114536624,"type":"change","change_id":15557281741,"instrument_name":"ETH-PERPETUAL","bids":[["delete",3881.25,0.0]],"asks":[["delete",3898.45,0.0]],"prev_change_id":15557281687}}}
{"jsonrpc":"2.0","method":"subscription","params":{"channel":"book.ETH-PERPETUAL.raw","data":{"timestamp":1734114536642,"type":"change","change_id":15557281754,"instrument_name":"ETH-PERPETUAL","bids":[],"asks":[["new",3917.95,500.0],["delete",3929.55,0.0]],"prev_change_id":15557281741}}}
{"jsonrpc":"2.0","method":"subscription","params":{"channel":"book.ETH-PERPETUAL.raw","data":{"timestamp":1734114536642,"type":"change","change_id":15557281754,"instrument_name":"ETH-PERPETUAL","bids":[],"asks":[["new",3917.95,500.0],["delete",3929.55,0.0]],"prev_change_id":15557281741}}}
{"jsonrpc":"2.0","method":"subscription","params":{"channel":"book.ETH-PERPETUAL.raw","data":{"timestamp":1734114536818,"type":"change","change_id":15557281838,"instrument_name":"ETH-PERPETUAL","bids":[["new",3880.9,8.0e4]],"asks":[],"prev_change_id":15557281754}}}
{"jsonrpc":"2.0","method":"subscription","params":{"channel":"book.ETH-PERPETUAL.raw","data":{"timestamp":1734114536818,"type":"change","change_id":15557281838,"instrument_name":"ETH-PERPETUAL","bids":[["new",3880.9,8.0e4]],"asks":[],"prev_change_id":15557281754}}}
{"jsonrpc":"2.0","method":"subscription","params":{"channel":"book.ETH-PERPETUAL.raw","data":{"timestamp":1734114536820,"type":"change","change_id":15557281839,"instrument_name":"ETH-PERPETUAL","bids":[],"asks":[["new",3898.8,8.0e4]],"prev_change_id":15557281838}}}
{"jsonrpc":"2.0","method":"subscription","params":{"channel":"book.ETH-PERPETUAL.raw","data":{"timestamp":1734114536820,"type":"change","change_id":15557281839,"instrument_name":"ETH-PERPETUAL","bids":[],"asks":[["new",3898.8,8.0e4]],"prev_change_id":15557281838}}}
{"jsonrpc":"2.0","method":"subscription","params":{"channel":"book.ETH-PERPETUAL.raw","data":{"timestamp":1734114536821,"type":"change","change_id":15557281840,"instrument_name":"ETH-PERPETUAL","bids":[["change",3880.9,1.0e5]],"asks":[],"prev_change_id":15557281839}}}
{"jsonrpc":"2.0","method":"subscription","params":{"channel":"book.ETH-PERPETUAL.raw","data":{"timestamp":1734114536821,"type":"change","change_id":15557281840,"instrument_name":"ETH-PERPETUAL","bids":[["change",3880.9,1.0e5]],"asks":[],"prev_change_id":15557281839}}}
{"jsonrpc":"2.0","method":"subscription","params":{"channel":"book.ETH-PERPETUAL.raw","data":{"timestamp":1734114536823,"type":"change","change_id":15557281841,"instrument_name":"ETH-PERPETUAL","bids":[],"asks":[["change",3898.8,1.0e5]],"prev_change_id":15557281840}}}
{"jsonrpc":"2.0","method":"subscription","params":{"channel":"book.ETH-PERPETUAL.raw","data":{"timestamp":1734114536823,"type":"change","change_id":15557281841,"instrument_name":"ETH-PERPETUAL","bids":[],"asks":[["change",3898.8,1.0e5]],"prev_change_id":15557281840}}}
{"jsonrpc":"2.0","method":"subscription","params":{"channel":"book.ETH-PERPETUAL.raw","data":{"timestamp":1734114536824,"type":"change","change_id":15557281842,"instrument_name":"ETH-PERPETUAL","bids":[["change",3880.9,1.8e5]],"asks":[],"prev_change_id":15557281841}}}
{"jsonrpc":"2.0","method":"subscription","params":{"channel":"book.ETH-PERPETUAL.raw","data":{"timestamp":1734114536824,"type":"change","change_id":15557281842,"instrument_name":"ETH-PERPETUAL","bids":[["change",3880.9,1.8e5]],"asks":[],"prev_change_id":15557281841}}}
{"jsonrpc":"2.0","method":"subscription","params":{"channel":"book.ETH-PERPETUAL.raw","data":{"timestamp":1734114536826,"type":"change","change_id":15557281843,"instrument_name":"ETH-PERPETUAL","bids":[],"asks":[["change",3898.8,1.8e5]],"prev_change_id":15557281842}}}
{"jsonrpc":"2.0","method":"subscription","params":{"channel":"book.ETH-PERPETUAL.raw","data":{"timestamp":1734114536826,"type":"change","change_id":15557281843,"instrument_name":"ETH-PERPETUAL","bids":[],"asks":[["change",3898.8,1.8e5]],"prev_change_id":15557281842}}}
{"jsonrpc":"2.0","method":"subscription","params":{"channel":"book.ETH-PERPETUAL.raw","data":{"timestamp":1734114536828,"type":"change","change_id":15557281844,"instrument_name":"ETH-PERPETUAL","bids":[["change",3880.9,2.0e5]],"asks":[],"prev_change_id":15557281843}}}
{"jsonrpc":"2.0","method":"subscription","params":{"channel":"book.ETH-PERPETUAL.raw","data":{"timestamp":1734114536828,"type":"change","change_id":15557281844,"instrument_name":"ETH-PERPETUAL","bids":[["change",3880.9,2.0e5]],"asks":[],"prev_change_id":15557281843}}}
{"jsonrpc":"2.0","method":"subscription","params":{"channel":"book.ETH-PERPETUAL.raw","data":{"timestamp":1734114536829,"type":"change","change_id":15557281845,"instrument_name":"ETH-PERPETUAL","bids":[],"asks":[["change",3898.8,2.0e5]],"prev_change_id":15557281844}}}
{"jsonrpc":"2.0","method":"subscription","params":{"channel":"book.ETH-PERPETUAL.raw","data":{"timestamp":1734114536829,"type":"change","change_id":15557281845,"instrument_name":"ETH-PERPETUAL","bids":[],"asks":[["change",3898.8,2.0e5]],"prev_change_id":15557281844}}}
{"jsonrpc":"2.0","method":"subscription","params":{"channel":"book.ETH-PERPETUAL.raw","data":{"timestamp":1734114536961,"type":"change","change_id":15557281846,"instrument_name":"ETH-PERPETUAL","bids":[["delete",3880.9,0.0]],"asks":[["delete",3898.8,0.0]],"prev_change_id":15557281845}}}
{"jsonrpc":"2.0","method":"subscription","params":{"channel":"book.ETH-PERPETUAL.raw","data":{"timestamp":1734114536961,"type":"change","change_id":15557281846,"instrument_name":"ETH-PERPETUAL","bids":[["delete",3880.9,0.0]],"asks":[["delete",3898.8,0.0]],"prev_change_id":15557281845}}}
{"jsonrpc":"2.0","method":"subscription","params":{"channel":"book.ETH-PERPETUAL.raw","data":{"timestamp":1734114537151,"type":"change","change_id":15557281847,"instrument_name":"ETH-PERPETUAL","bids":[["new",3880.7,8.0e4]],"asks":[],"prev_change_id":15557281846}}}
{"jsonrpc":"2.0","method":"subscription","params":{"channel":"book.ETH-PERPETUAL.raw","data":{"timestamp":1734114537151,"type":"change","change_id":15557281847,"instrument_name":"ETH-PERPETUAL","bids":[["new",3880.7,8.0e4]],"asks":[],"prev_change_id":15557281846}}}
{"jsonrpc":"2.0","method":"subscription","params":{"channel":"book.ETH-PERPETUAL.raw","data":{"timestamp":1734114537153,"type":"change","change_id":15557281848,"instrument_name":"ETH-PERPETUAL","bids":[],"asks":[["new",3899.0,8.0e4]],"prev_change_id":15557281847}}}
{"jsonrpc":"2.0","method":"subscription","params":{"channel":"book.ETH-PERPETUAL.raw","data":{"timestamp":1734114537153,"type":"change","change_id":15557281848,"instrument_name":"ETH-PERPETUAL","bids":[],"asks":[["new",3899.0,8.0e4]],"prev_change_id":15557281847}}}
{"jsonrpc":"2.0","method":"subscription","params":{"channel":"book.ETH-PERPETUAL.raw","data":{"timestamp":1734114537155,"type":"change","change_id":15557281849,"instrument_name":"ETH-PERPETUAL","bids":[["change",3880.7,1.6e5]],"asks":[],"prev_change_id":15557281848}}}
{"jsonrpc":"2.0","method":"subscription","params":{"channel":"book.ETH-PERPETUAL.raw","data":{"timestamp":1734114537155,"type":"change","change_id":15557281849,"instrument_name":"ETH-PERPETUAL","bids":[["change",3880.7,1.6e5]],"asks":[],"prev_change_id":15557281848}}}
{"jsonrpc":"2.0","method":"subscription","params":{"channel":"book.ETH-PERPETUAL.raw","data":{"timestamp":1734114537161,"type":"change","change_id":15557281850,"instrument_name":"ETH-PERPETUAL","bids":[],"asks":[["change",3899.0,1.6e5]],"prev_change_id":15557281849}}}
{"jsonrpc":"2.0","method":"subscription","params":{"channel":"book.ETH-PERPETUAL.raw","data":{"timestamp":1734114537161,"type":"change","change_id":15557281850,"instrument_name":"ETH-PERPETUAL","bids":[],"asks":[["change",3899.0,1.6e5]],"prev_change_id":15557281849}}}
{"jsonrpc":"2.0","method":"subscription","params":{"channel":"book.ETH-PERPETUAL.raw","data":{"timestamp":1734114537163,"type":"change","change_id":15557281851,"instrument_name":"ETH-PERPETUAL","bids":[["change",3880.7,1.8e5]],"asks":[],"prev_change_id":15557281850}}}
{"jsonrpc":"2.0","method":"subscription","params":{"channel":"book.ETH-PERPETUAL.raw","data":{"timestamp":1734114537163,"type":"change","change_id":15557281851,"instrument_name":"ETH-PERPETUAL","bids":[["change",3880.7,1.8e5]],"asks":[],"prev_change_id":15557281850}}}
{"jsonrpc":"2.0","method":"subscription","params":{"channel":"book.ETH-PERPETUAL.raw","data":{"timestamp":1734114537249,"type":"change","change_id":15557281852,"instrument_name":"ETH-PERPETUAL","bids":[["delete",3880.7,0.0]],"asks":[["delete",3899.0,0.0]],"prev_change_id":15557281851}}}
{"jsonrpc":"2.0","method":"subscription","params":{"channel":"book.ETH-PERPETUAL.raw","data":{"timestamp":1734114537249,"type":"change","change_id":15557281852,"instrument_name":"ETH-PERPETUAL","bids":[["delete",3880.7,0.0]],"asks":[["delete",3899.0,0.0]],"prev_change_id":15557281851}}}
{"jsonrpc":"2.0","method":"subscription","params":{"channel":"book.ETH-PERPETUAL.raw","data":{"timestamp":1734114537424,"type":"change","change_id":15557281855,"instrument_name":"ETH-PERPETUAL","bids":[["new",3880.5,8.0e4]],"asks":[],"prev_change_id":15557281852}}}
{"jsonrpc":"2.0","method":"subscription","params":{"channel":"book.ETH-PERPETUAL.raw","data":{"timestamp":1734114537424,"type":"change","change_id":15557281855,"instrument_name":"ETH-PERPETUAL","bids":[["new",3880.5,8.0e4]],"asks":[],"prev_change_id":15557281852}}}
{"jsonrpc":"2.0","method":"subscription","params":{"channel":"book.ETH-PERPETUAL.raw","data":{"timestamp":1734114537425,"type":"change","change_id":15557281856,"instrument_name":"ETH-PERPETUAL","bids":[],"asks":[["new",3898.9,8.0e4]],"prev_change_id":15557281855}}}
{"jsonrpc":"2.0","method":"subscription","params":{"channel":"book.ETH-PERPETUAL.raw","data":{"timestamp":1734114537425,"type":"change","change_id":15557281856,"instrument_name":"ETH-PERPETUAL","bids":[],"asks":[["new",3898.9,8.0e4]],"prev_change_id":15557281855}}}
{"jsonrpc":"2.0","method":"subscription","params":{"channel":"book.ETH-PERPETUAL.raw","data":{"timestamp":1734114537426,"type":"change","change_id":15557281857,"instrument_name":"ETH-PERPETUAL","bids":[["change",3880.5,1.0e5]],"asks":[],"prev_change_id":15557281856}}}
{"jsonrpc":"2.0","method":"subscription","params":{"channel":"book.ETH-PERPETUAL.raw","data":{"timestamp":1734114537426,"type":"change","change_id":15557281857,"instrument_name":"ETH-PERPETUAL","bids":[["change",3880.5,1.0e5]],"asks":[],"prev_change_id":15557281856}}}
{"jsonrpc":"2.0","method":"subscription","params":{"channel":"book.ETH-PERPETUAL.raw","data":{"timestamp":1734114537427,"type":"change","change_id":15557281858,"instrument_name":"ETH-PERPETUAL","bids":[["change",3880.5,1.8e5]],"asks":[],"prev_change_id":15557281857}}}
{"jsonrpc":"2.0","method":"subscription","params":{"channel":"book.ETH-PERPETUAL.raw","data":{"timestamp":1734114537427,"type":"change","change_id":15557281858,"instrument_name":"ETH-PERPETUAL","bids":[["change",3880.5,1.8e5]],"asks":[],"prev_change_id":15557281857}}}
{"jsonrpc":"2.0","method":"subscription","params":{"channel":"book.ETH-PERPETUAL.raw","data":{"timestamp":1734114537428,"type":"change","change_id":15557281859,"instrument_name":"ETH-PERPETUAL","bids":[],"asks":[["change",3898.9,1.6e5]],"prev_change_id":15557281858}}}
{"jsonrpc":"2.0","method":"subscription","params":{"channel":"book.ETH-PERPETUAL.raw","data":{"timestamp":1734114537428,"type":"change","change_id":15557281859,"instrument_name":"ETH-PERPETUAL","bids":[],"asks":[["change",3898.9,1.6e5]],"prev_change_id":15557281858}}}
{"jsonrpc":"2.0","method":"subscription","params":{"channel":"book.ETH-PERPETUAL.raw","data":{"timestamp":1734114537429,"type":"change","change_id":15557281860,"instrument_name":"ETH-PERPETUAL","bids":[["change",3880.5,2.0e5]],"asks":[],"prev_change_id":15557281859}}}
{"jsonrpc":"2.0","method":"subscription","params":{"channel":"book.ETH-PERPETUAL.raw","data":{"timestamp":1734114537429,"type":"change","change_id":15557281860,"instrument_name":"ETH-PERPETUAL","bids":[["change",3880.5,2.0e5]],"asks":[],"prev_change_id":15557281859}}}
{"jsonrpc":"2.0","method":"subscription","params":{"channel":"book.ETH-PERPETUAL.raw","data":{"timestamp":1734114537557,"type":"change","change_id":15557281871,"instrument_name":"ETH-PERPETUAL","bids":[["delete",3880.5,0.0]],"asks":[["delete",3898.9,0.0]],"prev_change_id":15557281860}}}
{"jsonrpc":"2.0","method":"subscription","params":{"channel":"book.ETH-PERPETUAL.raw","data":{"timestamp":1734114537557,"type":"change","change_id":15557281871,"instrument_name":"ETH-PERPETUAL","bids":[["delete",3880.5,0.0]],"asks":[["delete",3898.9,0.0]],"prev_change_id":15557281860}}}
{"jsonrpc":"2.0","method":"subscription","params":{"channel":"book.ETH-PERPETUAL.raw","data":{"timestamp":1734114537735,"type":"change","change_id":15557281909,"instrument_name":"ETH-PERPETUAL","bids":[["new",3880.35,8.0e4]],"asks":[],"prev_change_id":15557281871}}}
{"jsonrpc":"2.0","method":"subscription","params":{"channel":"book.ETH-PERPETUAL.raw","data":{"timestamp":1734114537735,"type":"change","change_id":15557281909,"instrument_name":"ETH-PERPETUAL","bids":[["new",3880.35,8.0e4]],"asks":[],"prev_change_id":15557281871}}}
{"jsonrpc":"2.0","method":"subscription","params":{"channel":"book.ETH-PERPETUAL.raw","data":{"timestamp":1734114537738,"type":"change","change_id":15557281910,"instrument_name":"ETH-PERPETUAL","bids":[],"asks":[["new",3899.05,8.0e4]],"prev_change_id":15557281909}}}
{"jsonrpc":"2.0","method":"subscription","params":{"channel":"book.ETH-PERPETUAL.raw","data":{"timestamp":1734114537738,"type":"change","change_id":15557281910,"instrument_name":"ETH-PERPETUAL","bids":[],"asks":[["new",3899.05,8.0e4]],"prev_change_id":15557281909}}}
{"jsonrpc":"2.0","method":"subscription","params":{"channel":"book.ETH-PERPETUAL.raw","data":{"timestamp":1734114537739,"type":"change","change_id":15557281911,"instrument_name":"ETH-PERPETUAL","bids":[["change",3880.35,1.0e5]],"asks":[],"prev_change_id":15557281910}}}
{"jsonrpc":"2.0","method":"subscription","params":{"channel":"book.ETH-PERPETUAL.raw","data":{"timestamp":1734114537739,"type":"change","change_id":15557281911,"instrument_name":"ETH-PERPETUAL","bids":[["change",3880.35,1.0e5]],"asks":[],"prev_change_id":15557281910}}}
{"jsonrpc":"2.0","method":"subscription","params":{"channel":"book.ETH-PERPETUAL.raw","data":{"timestamp":1734114537741,"type":"change","change_id":15557281912,"instrument_name":"ETH-PERPETUAL","bids":[["change",3880.35,1.8e5]],"asks":[],"prev_change_id":15557281911}}}
{"jsonrpc":"2.0","method":"subscription","params":{"channel":"book.ETH-PERPETUAL.raw","data":{"timestamp":1734114537741,"type":"change","change_id":15557281912,"instrument_name":"ETH-PERPETUAL","bids":[["change",3880.35,1.8e5]],"asks":[],"prev_change_id":15557281911}}}
{"jsonrpc":"2.0","method":"subscription","params":{"channel":"book.ETH-PERPETUAL.raw","data":{"timestamp":1734114537744,"type":"change","change_id":15557281913,"instrument_name":"ETH-PERPETUAL","bids":[],"asks":[["change",3899.05,1.6e5]],"prev_change_id":15557281912}}}
{"jsonrpc":"2.0","method":"subscription","params":{"channel":"book.ETH-PERPETUAL.raw","data":{"timestamp":1734114537744,"type":"change","change_id":15557281913,"instrument_name":"ETH-PERPETUAL","bids":[],"asks":[["change",3899.05,1.6e5]],"prev_change_id":15557281912}}}
{"jsonrpc":"2.0","method":"subscription","params":{"channel":"book.ETH-PERPETUAL.raw","data":{"timestamp":1734114537745,"type":"change","change_id":15557281914,"instrument_name":"ETH-PERPETUAL","bids":[["change",3880.35,2.0e5]],"asks":[],"prev_change_id":15557281913}}}
{"jsonrpc":"2.0","method":"subscription","params":{"channel":"book.ETH-PERPETUAL.raw","data":{"timestamp":1734114537745,"type":"change","change_id":15557281914,"instrument_name":"ETH-PERPETUAL","bids":[["change",3880.35,2.0e5]],"asks":[],"prev_change_id":15557281913}}}
{"jsonrpc":"2.0","method":"subscription","params":{"channel":"book.ETH-PERPETUAL.raw","data":{"timestamp":1734114537878,"type":"change","change_id":15557281915,"instrument_name":"ETH-PERPETUAL","bids":[["delete",3880.35,0.0]],"asks":[["delete",3899.05,0.0]],"prev_change_id":15557281914}}}
{"jsonrpc":"2.0","method":"subscription","params":{"channel":"book.ETH-PERPETUAL.raw","data":{"timestamp":1734114537878,"type":"change","change_id":15557281915,"instrument_name":"ETH-PERPETUAL","bids":[["delete",3880.35,0.0]],"asks":[["delete",3899.05,0.0]],"prev_change_id":15557281914}}}
{"jsonrpc":"2.0","method":"subscription","params":{"channel":"book.ETH-PERPETUAL.raw","data":{"timestamp":1734114538024,"type":"change","change_id":15557281919,"instrument_name":"ETH-PERPETUAL","bids":[["delete",3844.9,0.0],["new",3833.4,700.0]],"asks":[],"prev_change_id":15557281915}}}
{"jsonrpc":"2.0","method":"subscription","params":{"channel":"book.ETH-PERPETUAL.raw","data":{"timestamp":1734114538024,"type":"change","change_id":15557281919,"instrument_name":"ETH-PERPETUAL","bids":[["delete",3844.9,0.0],["new",3833.4,700.0]],"asks":[],"prev_change_id":15557281915}}}
{"jsonrpc":"2.0","method":"subscription","params":{"channel":"book.ETH-PERPETUAL.raw","data":{"timestamp":1734114538025,"type":"change","change_id":15557281920,"instrument_name":"ETH-PERPETUAL","bids":[["delete",3864.3,0.0],["new",3852.75,500.0]],"asks":[],"prev_change_id":15557281919}}}
{"jsonrpc":"2.0","method":"subscription","params":{"channel":"book.ETH-PERPETUAL.raw","data":{"timestamp":1734114538025,"type":"change","change_id":15557281920,"instrument_name":"ETH-PERPETUAL","bids":[["delete",3864.3,0.0],["new",3852.75,500.0]],"asks":[],"prev_change_id":15557281919}}}
{"jsonrpc":"2.0","method":"subscription","params":{"channel":"book.ETH-PERPETUAL.raw","data":{"timestamp":1734114538026,"type":"change","change_id":15557281921,"instrument_name":"ETH-PERPETUAL","bids":[["delete",3872.05,0.0],["new",3860.5,500.0]],"asks":[],"prev_change_id":15557281920}}}
{"jsonrpc":"2.0","method":"subscription","params":{"channel":"book.ETH-PERPETUAL.raw","data":{"timestamp":1734114538026,"type":"change","change_id":15557281921,"instrument_name":"ETH-PERPETUAL","bids":[["delete",3872.05,0.0],["new",3860.5,500.0]],"asks":[],"prev_change_id":15557281920}}}
{"jsonrpc":"2.0","method":"subscription","params":{"channel":"book.ETH-PERPETUAL.raw","data":{"timestamp":1734114538050,"type":"change","change_id":15557281922,"instrument_name":"ETH-PERPETUAL","bids":[["new",3880.3,8.0e4]],"asks":[],"prev_change_id":15557281921}}}
{"jsonrpc":"2.0","method":"subscription","params":{"channel":"book.ETH-PERPETUAL.raw","data":{"timestamp":1734114538050,"type":"change","change_id":15557281922,"instrument_name":"ETH-PERPETUAL","bids":[["new",3880.3,8.0e4]],"asks":[],"prev_change_id":15557281921}}}
{"jsonrpc":"2.0","method":"subscription","params":{"channel":"book.ETH-PERPETUAL.raw","data":{"timestamp":1734114538056,"type":"change","change_id":15557281923,"instrument_name":"ETH-PERPETUAL","bids":[],"asks":[["new",3899.1,8.0e4]],"prev_change_id":15557281922}}}
{"jsonrpc":"2.0","method":"subscription","params":{"channel":"book.ETH-PERPETUAL.raw","data":{"timestamp":1734114538056,"type":"change","change_id":15557281923,"instrument_name":"ETH-PERPETUAL","bids":[],"asks":[["new",3899.1,8.0e4]],"prev_change_id":15557281922}}}
{"jsonrpc":"2.0","method":"subscription","params":{"channel":"book.ETH-PERPETUAL.raw","data":{"timestamp":1734114538057,"type":"change","change_id":15557281924,"instrument_name":"ETH-PERPETUAL","bids":[["change",3880.3,1.6e5]],"asks":[],"prev_change_id":15557281923}}}
{"jsonrpc":"2.0","method":"subscription","params":{"channel":"book.ETH-PERPETUAL.raw","data":{"timestamp":1734114538057,"type":"change","change_id":15557281924,"instrument_name":"ETH-PERPETUAL","bids":[["change",3880.3,1.6e5]],"asks":[],"prev_change_id":15557281923}}}
{"jsonrpc":"2.0","method":"subscription","params":{"channel":"book.ETH-PERPETUAL.raw","data":{"timestamp":1734114538058,"type":"change","change_id":15557281925,"instrument_name":"ETH-PERPETUAL","bids":[],"asks":[["change",3899.1,1.6e5]],"prev_change_id":15557281924}}}
{"jsonrpc":"2.0","method":"subscription","params":{"channel":"book.ETH-PERPETUAL.raw","data":{"timestamp":1734114538058,"type":"change","change_id":15557281925,"instrument_name":"ETH-PERPETUAL","bids":[],"asks":[["change",3899.1,1.6e5]],"prev_change_id":15557281924}}}
{"jsonrpc":"2.0","method":"subscription","params":{"channel":"book.ETH-PERPETUAL.raw","data":{"timestamp":1734114538059,"type":"change","change_id":15557281926,"instrument_name":"ETH-PERPETUAL","bids":[["change",3880.3,1.8e5]],"asks":[],"prev_change_id":15557281925}}}
{"jsonrpc":"2.0","method":"subscription","params":{"channel":"book.ETH-PERPETUAL.raw","data":{"timestamp":1734114538059,"type":"change","change_id":15557281926,"instrument_name":"ETH-PERPETUAL","bids":[["change",3880.3,1.8e5]],"asks":[],"prev_change_id":15557281925}}}
{"jsonrpc":"2.0","method":"subscription","params":{"channel":"book.ETH-PERPETUAL.raw","data":{"timestamp":1734114538139,"type":"change","change_id":15557281927,"instrument_name":"ETH-PERPETUAL","bids":[["delete",3880.3,0.0]],"asks":[["delete",3899.1,0.0]],"prev_change_id":15557281926}}}
{"jsonrpc":"2.0","method":"subscription","params":{"channel":"book.ETH-PERPETUAL.raw","data":{"timestamp":1734114538139,"type":"change","change_id":15557281927,"instrument_name":"ETH-PERPETUAL","bids":[["delete",3880.3,0.0]],"asks":[["delete",3899.1,0.0]],"prev_change_id":15557281926}}}
{"jsonrpc":"2.0","method":"subscription","params":{"channel":"book.ETH-PERPETUAL.raw","data":{"timestamp":1734114538317,"type":"change","change_id":15557281928,"instrument_name":"ETH-PERPETUAL","bids":[["new",3880.3,8.0e4]],"asks":[],"prev_change_id":15557281927}}}
{"jsonrpc":"2.0","method":"subscription","params":{"channel":"book.ETH-PERPETUAL.raw","data":{"timestamp":1734114538317,"type":"change","change_id":15557281928,"instrument_name":"ETH-PERPETUAL","bids":[["new",3880.3,8.0e4]],"asks":[],"prev_change_id":15557281927}}}
{"jsonrpc":"2.0","method":"subscription","params":{"channel":"book.ETH-PERPETUAL.raw","data":{"timestamp":1734114538319,"type":"change","change_id":15557281929,"instrument_name":"ETH-PERPETUAL","bids":[],"asks":[["new",3899.1,8.0e4]],"prev_change_id":15557281928}}}
{"jsonrpc":"2.0","method":"subscription","params":{"channel":"book.ETH-PERPETUAL.raw","data":{"timestamp":1734114538319,"type":"change","change_id":15557281929,"instrument_name":"ETH-PERPETUAL","bids":[],"asks":[["new",3899.1,8.0e4]],"prev_change_id":15557281928}}}
{"jsonrpc":"2.0","method":"subscription","params":{"channel":"book.ETH-PERPETUAL.raw","data":{"timestamp":1734114538320,"type":"change","change_id":15557281930,"instrument_name":"ETH-PERPETUAL","bids":[["change",3880.3,1.0e5]],"asks":[],"prev_change_id":15557281929}}}
{"jsonrpc":"2.0","method":"subscription","params":{"channel":"book.ETH-PERPETUAL.raw","data":{"timestamp":1734114538320,"type":"change","change_id":15557281930,"instrument_name":"ETH-PERPETUAL","bids":[["change",3880.3,1.0e5]],"asks":[],"prev_change_id":15557281929}}}
{"jsonrpc":"2.0","method":"subscription","params":{"channel":"book.ETH-PERPETUAL.raw","data":{"timestamp":1734114538321,"type":"change","change_id":15557281931,"instrument_name":"ETH-PERPETUAL","bids":[["change",3880.3,1.8e5]],"asks":[],"prev_change_id":15557281930}}}
{"jsonrpc":"2.0","method":"subscription","params":{"channel":"book.ETH-PERPETUAL.raw","data":{"timestamp":1734114538321,"type":"change","change_id":15557281931,"instrument_name":"ETH-PERPETUAL","bids":[["change",3880.3,1.8e5]],"asks":[],"prev_change_id":15557281930}}}
{"jsonrpc":"2.0","method":"subscription","params":{"channel":"book.ETH-PERPETUAL.raw","data":{"timestamp":1734114538323,"type":"change","change_id":15557281932,"instrument_name":"ETH-PERPETUAL","bids":[],"asks":[["change",3899.1,1.6e5]],"prev_change_id":15557281931}}}
{"jsonrpc":"2.0","method":"subscription","params":{"channel":"book.ETH-PERPETUAL.raw","data":{"timestamp":1734114538323,"type":"change","change_id":15557281932,"instrument_name":"ETH-PERPETUAL","bids":[],"asks":[["change",3899.1,1.6e5]],"prev_change_id":15557281931}}}
{"jsonrpc":"2.0","method":"subscription","params":{"channel":"book.ETH-PERPETUAL.raw","data":{"timestamp":1734114538324,"type":"change","change_id":15557281933,"instrument_name":"ETH-PERPETUAL","bids":[["change",3880.3,2.0e5]],"asks":[],"prev_change_id":15557281932}}}
{"jsonrpc":"2.0","method":"subscription","params":{"channel":"book.ETH-PERPETUAL.raw","data":{"timestamp":1734114538324,"type":"change","change_id":15557281933,"instrument_name":"ETH-PERPETUAL","bids":[["change",3880.3,2.0e5]],"asks":[],"prev_change_id":15557281932}}}
{"jsonrpc":"2.0","method":"subscription","params":{"channel":"book.ETH-PERPETUAL.raw","data":{"timestamp":1734114538448,"type":"change","change_id":15557281934,"instrument_name":"ETH-PERPETUAL","bids":[["delete",3880.3,0.0]],"asks":[["delete",3899.1,0.0]],"prev_change_id":15557281933}}}
{"jsonrpc":"2.0","method":"subscription","params":{"channel":"book.ETH-PERPETUAL.raw","data":{"timestamp":1734114538448,"type":"change","change_id":15557281934,"instrument_name":"ETH-PERPETUAL","bids":[["delete",3880.3,0.0]],"asks":[["delete",3899.1,0.0]],"prev_change_id":15557281933}}}
{"jsonrpc":"2.0","method":"subscription","params":{"channel":"book.ETH-PERPETUAL.raw","data":{"timestamp":1734114538621,"type":"change","change_id":15557281970,"instrument_name":"ETH-PERPETUAL","bids":[["new",3880.35,8.0e4]],"asks":[],"prev_change_id":15557281934}}}
{"jsonrpc":"2.0","method":"subscription","params":{"channel":"book.ETH-PERPETUAL.raw","data":{"timestamp":1734114538621,"type":"change","change_id":15557281970,"instrument_name":"ETH-PERPETUAL","bids":[["new",3880.35,8.0e4]],"asks":[],"prev_change_id":15557281934}}}
{"jsonrpc":"2.0","method":"subscription","params":{"channel":"book.ETH-PERPETUAL.raw","data":{"timestamp":1734114538623,"type":"change","change_id":15557281971,"instrument_name":"ETH-PERPETUAL","bids":[],"asks":[["new",3899.1,8.0e4]],"prev_change_id":15557281970}}}
{"jsonrpc":"2.0","method":"subscription","params":{"channel":"book.ETH-PERPETUAL.raw","data":{"timestamp":1734114538623,"type":"change","change_id":15557281971,"instrument_name":"ETH-PERPETUAL","bids":[],"asks":[["new",3899.1,8.0e4]],"prev_change_id":15557281970}}}
{"jsonrpc":"2.0","method":"subscription","params":{"channel":"book.ETH-PERPETUAL.raw","data":{"timestamp":1734114538624,"type":"change","change_id":15557281972,"instrument_name":"ETH-PERPETUAL","bids":[["change",3880.35,1.6e5]],"asks":[],"prev_change_id":15557281971}}}
{"jsonrpc":"2.0","method":"subscription","params":{"channel":"book.ETH-PERPETUAL.raw","data":{"timestamp":1734114538624,"type":"change","change_id":15557281972,"instrument_name":"ETH-PERPETUAL","bids":[["change",3880.35,1.6e5]],"asks":[],"prev_change_id":15557281971}}}
{"jsonrpc":"2.0","method":"subscription","params":{"channel":"book.ETH-PERPETUAL.raw","data":{"timestamp":1734114538626,"type":"change","change_id":15557281973,"instrument_name":"ETH-PERPETUAL","bids":[],"asks":[["change",3899.1,1.6e5]],"prev_change_id":15557281972}}}
{"jsonrpc":"2.0","method":"subscription","params":{"channel":"book.ETH-PERPETUAL.raw","data":{"timestamp":1734114538626,"type":"change","change_id":15557281973,"instrument_name":"ETH-PERPETUAL","bids":[],"asks":[["change",3899.1,1.6e5]],"prev_change_id":15557281972}}}
{"jsonrpc":"2.0","method":"subscription","params":{"channel":"book.ETH-PERPETUAL.raw","data":{"timestamp":1734114538743,"type":"change","change_id":15557282036,"instrument_name":"ETH-PERPETUAL","bids":[["delete",3880.35,0.0]],"asks":[["delete",3899.1,0.0]],"prev_change_id":15557281973}}}
{"jsonrpc":"2.0","method":"subscription","params":{"channel":"book.ETH-PERPETUAL.raw","data":{"timestamp":1734114538743,"type":"change","change_id":15557282036,"instrument_name":"ETH-PERPETUAL","bids":[["delete",3880.35,0.0]],"asks":[["delete",3899.1,0.0]],"prev_change_id":15557281973}}}
{"jsonrpc":"2.0","method":"subscription","params":{"channel":"book.ETH-PERPETUAL.raw","data":{"timestamp":1734114538912,"type":"change","change_id":15557282081,"instrument_name":"ETH-PERPETUAL","bids":[["new",3880.4,8.0e4]],"asks":[],"prev_change_id":15557282036}}}
{"jsonrpc":"2.0","method":"subscription","params":{"channel":"book.ETH-PERPETUAL.raw","data":{"timestamp":1734114538912,"type":"change","change_id":15557282081,"instrument_name":"ETH-PERPETUAL","bids":[["new",3880.4,8.0e4]],"asks":[],"prev_change_id":15557282036}}}
{"jsonrpc":"2.0","method":"subscription","params":{"channel":"book.ETH-PERPETUAL.raw","data":{"timestamp":1734114538914,"type":"change","change_id":15557282082,"instrument_name":"ETH-PERPETUAL","bids":[],"asks":[["new",3899.0,8.0e4]],"prev_change_id":15557282081}}}
{"jsonrpc":"2.0","method":"subscription","params":{"channel":"book.ETH-PERPETUAL.raw","data":{"timestamp":1734114538914,"type":"change","change_id":15557282082,"instrument_name":"ETH-PERPETUAL","bids":[],"asks":[["new",3899.0,8.0e4]],"prev_change_id":15557282081}}}
{"jsonrpc":"2.0","method":"subscription","params":{"channel":"book.ETH-PERPETUAL.raw","data":{"timestamp":1734114538915,"type":"change","change_id":15557282083,"instrument_name":"ETH-PERPETUAL","bids":[["change",3880.4,4.0e5]],"asks":[],"prev_change_id":15557282082}}}
{"jsonrpc":"2.0","method":"subscription","params":{"channel":"book.ETH-PERPETUAL.raw","data":{"timestamp":1734114538915,"type":"change","change_id":15557282083,"instrument_name":"ETH-PERPETUAL","bids":[["change",3880.4,4.0e5]],"asks":[],"prev_change_id":15557282082}}}
{"jsonrpc":"2.0","method":"subscription","params":{"channel":"book.ETH-PERPETUAL.raw","data":{"timestamp":1734114538916,"type":"change","change_id":15557282084,"instrument_name":"ETH-PERPETUAL","bids":[["change",3880.4,4.8e5]],"asks":[],"prev_change_id":15557282083}}}
{"jsonrpc":"2.0","method":"subscription","params":{"channel":"book.ETH-PERPETUAL.raw","data":{"timestamp":1734114538916,"type":"change","change_id":15557282084,"instrument_name":"ETH-PERPETUAL","bids":[["change",3880.4,4.8e5]],"asks":[],"prev_change_id":15557282083}}}
{"jsonrpc":"2.0","method":"subscription","params":{"channel":"book.ETH-PERPETUAL.raw","data":{"timestamp":1734114538917,"type":"change","change_id":15557282085,"instrument_name":"ETH-PERPETUAL","bids":[],"asks":[["change",3899.0,1.6e5]],"prev_change_id":15557282084}}}
{"jsonrpc":"2.0","method":"subscription","params":{"channel":"book.ETH-PERPETUAL.raw","data":{"timestamp":1734114538917,"type":"change","change_id":15557282085,"instrument_name":"ETH-PERPETUAL","bids":[],"asks":[["change",3899.0,1.6e5]],"prev_change_id":15557282084}}}
{"jsonrpc":"2.0","method":"subscription","params":{"channel":"book.ETH-PERPETUAL.raw","data":{"timestamp":1734114538919,"type":"change","change_id":15557282086,"instrument_name":"ETH-PERPETUAL","bids":[["change",3880.4,8.0e5]],"asks":[],"prev_change_id":15557282085}}}
{"jsonrpc":"2.0","method":"subscription","params":{"channel":"book.ETH-PERPETUAL.raw","data":{"timestamp":1734114538919,"type":"change","change_id":15557282086,"instrument_name":"ETH-PERPETUAL","bids":[["change",3880.4,8.0e5]],"asks":[],"prev_change_id":15557282085}}}
{"jsonrpc":"2.0","method":"subscription","params":{"channel":"book.ETH-PERPETUAL.raw","data":{"timestamp":1734114539051,"type":"change","change_id":15557282087,"instrument_name":"ETH-PERPETUAL","bids":[["delete",3880.4,0.0]],"asks":[["delete",3899.0,0.0]],"prev_change_id":15557282086}}}
{"jsonrpc":"2.0","method":"subscription","params":{"channel":"book.ETH-PERPETUAL.raw","data":{"timestamp":1734114539051,"type":"change","change_id":15557282087,"instrument_name":"ETH-PERPETUAL","bids":[["delete",3880.4,0.0]],"asks":[["delete",3899.0,0.0]],"prev_change_id":15557282086}}}
{"jsonrpc":"2.0","method":"subscription","params":{"channel":"book.ETH-PERPETUAL.raw","data":{"timestamp":1734114539228,"type":"change","change_id":15557282089,"instrument_name":"ETH-PERPETUAL","bids":[["new",3880.45,8.0e4]],"asks":[],"prev_change_id":15557282087}}}
{"jsonrpc":"2.0","method":"subscription","params":{"channel":"book.ETH-PERPETUAL.raw","data":{"timestamp":1734114539228,"type":"change","change_id":15557282089,"instrument_name":"ETH-PERPETUAL","bids":[["new",3880.45,8.0e4]],"asks":[],"prev_change_id":15557282087}}}
{"jsonrpc":"2.0","method":"subscription","params":{"channel":"book.ETH-PERPETUAL.raw","data":{"timestamp":1734114539229,"type":"change","change_id":15557282090,"instrument_name":"ETH-PERPETUAL","bids":[],"asks":[["new",3898.95,8.0e4]],"prev_change_id":15557282089}}}
{"jsonrpc":"2.0","method":"subscription","params":{"channel":"book.ETH-PERPETUAL.raw","data":{"timestamp":1734114539229,"type":"change","change_id":15557282090,"instrument_name":"ETH-PERPETUAL","bids":[],"asks":[["new",3898.95,8.0e4]],"prev_change_id":15557282089}}}
{"jsonrpc":"2.0","method":"subscription","params":{"channel":"book.ETH-PERPETUAL.raw","data":{"timestamp":1734114539230,"type":"change","change_id":15557282091,"instrument_name":"ETH-PERPETUAL","bids":[["change",3880.45,4.0e5]],"asks":[],"prev_change_id":15557282090}}}
{"jsonrpc":"2.0","method":"subscription","params":{"channel":"book.ETH-PERPETUAL.raw","data":{"timestamp":1734114539230,"type":"change","change_id":15557282091,"instrument_name":"ETH-PERPETUAL","bids":[["change",3880.45,4.0e5]],"asks":[],"prev_change_id":15557282090}}}
{"jsonrpc":"2.0","method":"subscription","params":{"channel":"book.ETH-PERPETUAL.raw","data":{"timestamp":1734114539232,"type":"change","change_id":15557282092,"instrument_name":"ETH-PERPETUAL","bids":[["new",3880.1,8.0e4]],"asks":[],"prev_change_id":15557282091}}}
{"jsonrpc":"2.0","method":"subscription","params":{"channel":"book.ETH-PERPETUAL.raw","data":{"timestamp":1734114539232,"type":"change","change_id":15557282092,"instrument_name":"ETH-PERPETUAL","bids":[["new",3880.1,8.0e4]],"asks":[],"prev_change_id":15557282091}}}
{"jsonrpc":"2.0","method":"subscription","params":{"channel":"book.ETH-PERPETUAL.raw","data":{"timestamp":1734114539234,"type":"change","change_id":15557282093,"instrument_name":"ETH-PERPETUAL","bids":[],"asks":[["new",3898.55,8.0e4]],"prev_change_id":15557282092}}}
{"jsonrpc":"2.0","method":"subscription","params":{"channel":"book.ETH-PERPETUAL.raw","data":{"timestamp":1734114539234,"type":"change","change_id":15557282093,"instrument_name":"ETH-PERPETUAL","bids":[],"asks":[["new",3898.55,8.0e4]],"prev_change_id":15557282092}}}
{"jsonrpc":"2.0","method":"subscription","params":{"channel":"book.ETH-PERPETUAL.raw","data":{"timestamp":1734114539235,"type":"change","change_id":15557282094,"instrument_name":"ETH-PERPETUAL","bids":[["change",3880.1,4.0e5]],"asks":[],"prev_change_id":15557282093}}}
{"jsonrpc":"2.0","method":"subscription","params":{"channel":"book.ETH-PERPETUAL.raw","data":{"timestamp":1734114539235,"type":"change","change_id":15557282094,"instrument_name":"ETH-PERPETUAL","bids":[["change",3880.1,4.0e5]],"asks":[],"prev_change_id":15557282093}}}
{"jsonrpc":"2.0","method":"subscription","params":{"channel":"book.ETH-PERPETUAL.raw","data":{"timestamp":1734114539318,"type":"change","change_id":15557282096,"instrument_name":"ETH-PERPETUAL","bids":[["delete",3880.45,0.0],["delete",3880.1,0.0]],"asks":[["delete",3898.55,0.0],["delete",3898.95,0.0]],"prev_change_id":15557282094}}}
{"jsonrpc":"2.0","method":"subscription","params":{"channel":"book.ETH-PERPETUAL.raw","data":{"timestamp":1734114539318,"type":"change","change_id":15557282096,"instrument_name":"ETH-PERPETUAL","bids":[["delete",3880.45,0.0],["delete",3880.1,0.0]],"asks":[["delete",3898.55,0.0],["delete",3898.95,0.0]],"prev_change_id":15557282094}}}
{"jsonrpc":"2.0","method":"subscription","params":{"channel":"book.ETH-PERPETUAL.raw","data":{"timestamp":1734114539378,"type":"change","change_id":15557282097,"instrument_name":"ETH-PERPETUAL","bids":[],"asks":[["new",3937.95,700.0],["change",3949.1,100.0]],"prev_change_id":15557282096}}}
{"jsonrpc":"2.0","method":"subscription","params":{"channel":"book.ETH-PERPETUAL.raw","data":{"timestamp":1734114539378,"type":"change","change_id":15557282097,"instrument_name":"ETH-PERPETUAL","bids":[],"asks":[["new",3937.95,700.0],["change",3949.1,100.0]],"prev_change_id":15557282096}}}
{"jsonrpc":"2.0","method":"subscription","params":{"channel":"book.ETH-PERPETUAL.raw","data":{"timestamp":1734114539487,"type":"change","change_id":15557282098,"instrument_name":"ETH-PERPETUAL","bids":[["new",3880.15,8.0e4]],"asks":[],"prev_change_id":15557282097}}}
{"jsonrpc":"2.0","method":"subscription","params":{"channel":"book.ETH-PERPETUAL.raw","data":{"timestamp":1734114539487,"type":"change","change_id":15557282098,"instrument_name":"ETH-PERPETUAL","bids":[["new",3880.15,8.0e4]],"asks":[],"prev_change_id":15557282097}}}
{"jsonrpc":"2.0","method":"subscription","params":{"channel":"book.ETH-PERPETUAL.raw","data":{"timestamp":1734114539489,"type":"change","change_id":15557282099,"instrument_name":"ETH-PERPETUAL","bids":[],"asks":[["new",3898.5,8.0e4]],"prev_change_id":15557282098}}}
{"jsonrpc":"2.0","method":"subscription","params":{"channel":"book.ETH-PERPETUAL.raw","data":{"timestamp":1734114539489,"type":"change","change_id":15557282099,"instrument_name":"ETH-PERPETUAL","bids":[],"asks":[["new",3898.5,8.0e4]],"prev_change_id":15557282098}}}
{"jsonrpc":"2.0","method":"subscription","params":{"channel":"book.ETH-PERPETUAL.raw","data":{"timestamp":1734114539490,"type":"change","change_id":15557282100,"instrument_name":"ETH-PERPETUAL","bids":[["change",3880.15,1.6e5]],"asks":[],"prev_change_id":15557282099}}}
{"jsonrpc":"2.0","method":"subscription","params":{"channel":"book.ETH-PERPETUAL.raw","data":{"timestamp":1734114539490,"type":"change","change_id":15557282100,"instrument_name":"ETH-PERPETUAL","bids":[["change",3880.15,1.6e5]],"asks":[],"prev_change_id":15557282099}}}
{"jsonrpc":"2.0","method":"subscription","params":{"channel":"book.ETH-PERPETUAL.raw","data":{"timestamp":1734114539492,"type":"change","change_id":15557282101,"instrument_name":"ETH-PERPETUAL","bids":[],"asks":[["change",3898.5,1.6e5]],"prev_change_id":15557282100}}}
{"jsonrpc":"2.0","method":"subscription","params":{"channel":"book.ETH-PERPETUAL.raw","data":{"timestamp":1734114539492,"type":"change","change_id":15557282101,"instrument_name":"ETH-PERPETUAL","bids":[],"asks":[["change",3898.5,1.6e5]],"prev_change_id":15557282100}}}
{"jsonrpc":"2.0","method":"subscription","params":{"channel":"book.ETH-PERPETUAL.raw","data":{"timestamp":1734114539613,"type":"change","change_id":15557282103,"instrument_name":"ETH-PERPETUAL","bids":[["delete",3880.15,0.0]],"asks":[["delete",3898.5,0.0]],"prev_change_id":15557282101}}}
{"jsonrpc":"2.0","method":"subscription","params":{"channel":"book.ETH-PERPETUAL.raw","data":{"timestamp":1734114539613,"type":"change","change_id":15557282103,"instrument_name":"ETH-PERPETUAL","bids":[["delete",3880.15,0.0]],"asks":[["delete",3898.5,0.0]],"prev_change_id":15557282101}}}
{"jsonrpc":"2.0","method":"subscription","params":{"channel":"book.ETH-PERPETUAL.raw","data":{"timestamp":1734114539809,"type":"change","change_id":15557282104,"instrument_name":"ETH-PERPETUAL","bids":[["new",3880.25,8.0e4]],"asks":[],"prev_change_id":15557282103}}}
{"jsonrpc":"2.0","method":"subscription","params":{"channel":"book.ETH-PERPETUAL.raw","data":{"timestamp":1734114539809,"type":"change","change_id":15557282104,"instrument_name":"ETH-PERPETUAL","bids":[["new",3880.25,8.0e4]],"asks":[],"prev_change_id":15557282103}}}
{"jsonrpc":"2.0","method":"subscription","params":{"channel":"book.ETH-PERPETUAL.raw","data":{"timestamp":1734114539811,"type":"change","change_id":15557282105,"instrument_name":"ETH-PERPETUAL","bids":[],"asks":[["new",3898.4,8.0e4]],"prev_change_id":15557282104}}}
{"jsonrpc":"2.0","method":"subscription","params":{"channel":"book.ETH-PERPETUAL.raw","data":{"timestamp":1734114539811,"type":"change","change_id":15557282105,"instrument_name":"ETH-PERPETUAL","bids":[],"asks":[["new",3898.4,8.0e4]],"prev_change_id":15557282104}}}
{"jsonrpc":"2.0","method":"subscription","params":{"channel":"book.ETH-PERPETUAL.raw","data":{"timestamp":1734114539813,"type":"change","change_id":15557282106,"instrument_name":"ETH-PERPETUAL","bids":[["change",3880.25,4.0e5]],"asks":[],"prev_change_id":15557282105}}}
{"jsonrpc":"2.0","method":"subscription","params":{"channel":"book.ETH-PERPETUAL.raw","data":{"timestamp":1734114539813,"type":"change","change_id":15557282106,"instrument_name":"ETH-PERPETUAL","bids":[["change",3880.25,4.0e5]],"asks":[],"prev_change_id":15557282105}}}
{"jsonrpc":"2.0","method":"subscription","params":{"channel":"book.ETH-PERPETUAL.raw","data":{"timestamp":1734114539814,"type":"change","change_id":15557282107,"instrument_name":"ETH-PERPETUAL","bids":[["change",3880.25,4.2e5]],"asks":[],"prev_change_id":15557282106}}}
{"jsonrpc":"2.0","method":"subscription","params":{"channel":"book.ETH-PERPETUAL.raw","data":{"timestamp":1734114539814,"type":"change","change_id":15557282107,"instrument_name":"ETH-PERPETUAL","bids":[["change",3880.25,4.2e5]],"asks":[],"prev_change_id":15557282106}}}
{"jsonrpc":"2.0","method":"subscription","params":{"channel":"book.ETH-PERPETUAL.raw","data":{"timestamp":1734114539815,"type":"change","change_id":15557282108,"instrument_name":"ETH-PERPETUAL","bids":[["change",3880.25,5.0e5]],"asks":[],"prev_change_id":15557282107}}}
{"jsonrpc":"2.0","method":"subscription","params":{"channel":"book.ETH-PERPETUAL.raw","data":{"timestamp":1734114539815,"type":"change","change_id":15557282108,"instrument_name":"ETH-PERPETUAL","bids":[["change",3880.25,5.0e5]],"asks":[],"prev_change_id":15557282107}}}
{"jsonrpc":"2.0","method":"subscription","params":{"channel":"book.ETH-PERPETUAL.raw","data":{"timestamp":1734114539817,"type":"change","change_id":15557282109,"instrument_name":"ETH-PERPETUAL","bids":[],"asks":[["change",3898.4,1.6e5]],"prev_change_id":15557282108}}}
{"jsonrpc":"2.0","method":"subscription","params":{"channel":"book.ETH-PERPETUAL.raw","data":{"timestamp":1734114539817,"type":"change","change_id":15557282109,"instrument_name":"ETH-PERPETUAL","bids":[],"asks":[["change",3898.4,1.6e5]],"prev_change_id":15557282108}}}
{"jsonrpc":"2.0","method":"subscription","params":{"channel":"book.ETH-PERPETUAL.raw","data":{"timestamp":1734114539818,"type":"change","change_id":15557282110,"instrument_name":"ETH-PERPETUAL","bids":[["change",3880.25,8.2e5]],"asks":[],"prev_change_id":15557282109}}}
{"jsonrpc":"2.0","method":"subscription","params":{"channel":"book.ETH-PERPETUAL.raw","data":{"timestamp":1734114539818,"type":"change","change_id":15557282110,"instrument_name":"ETH-PERPETUAL","bids":[["change",3880.25,8.2e5]],"asks":[],"prev_change_id":15557282109}}}
{"jsonrpc":"2.0","method":"subscription","params":{"channel":"book.ETH-PERPETUAL.raw","data":{"timestamp":1734114539819,"type":"change","change_id":15557282111,"instrument_name":"ETH-PERPETUAL","bids":[["change",3880.25,8.4e5]],"asks":[],"prev_change_id":15557282110}}}
{"jsonrpc":"2.0","method":"subscription","params":{"channel":"book.ETH-PERPETUAL.raw","data":{"timestamp":1734114539819,"type":"change","change_id":15557282111,"instrument_name":"ETH-PERPETUAL","bids":[["change",3880.25,8.4e5]],"asks":[],"prev_change_id":15557282110}}}
{"jsonrpc":"2.0","method":"subscription","params":{"channel":"book.ETH-PERPETUAL.raw","data":{"timestamp":1734114539949,"type":"change","change_id":15557282112,"instrument_name":"ETH-PERPETUAL","bids":[["delete",3880.25,0.0]],"asks":[["delete",3898.4,0.0]],"prev_change_id":15557282111}}}
{"jsonrpc":"2.0","method":"subscription","params":{"channel":"book.ETH-PERPETUAL.raw","data":{"timestamp":1734114539949,"type":"change","change_id":15557282112,"instrument_name":"ETH-PERPETUAL","bids":[["delete",3880.25,0.0]],"asks":[["delete",3898.4,0.0]],"prev_change_id":15557282111}}}
{"jsonrpc":"2.0","method":"subscription","params":{"channel":"book.ETH-PERPETUAL.raw","data":{"timestamp":1734114540141,"type":"change","change_id":15557282115,"instrument_name":"ETH-PERPETUAL","bids":[["new",3880.35,8.0e4]],"asks":[],"prev_change_id":15557282112}}}
{"jsonrpc":"2.0","method":"subscription","params":{"channel":"book.ETH-PERPETUAL.raw","data":{"timestamp":1734114540141,"type":"change","change_id":15557282115,"instrument_name":"ETH-PERPETUAL","bids":[["new",3880.35,8.0e4]],"asks":[],"prev_change_id":15557282112}}}
{"jsonrpc":"2.0","method":"subscription","params":{"channel":"book.ETH-PERPETUAL.raw","data":{"timestamp":1734114540143,"type":"change","change_id":15557282116,"instrument_name":"ETH-PERPETUAL","bids":[],"asks":[["new",3898.3,8.0e4]],"prev_change_id":15557282115}}}
{"jsonrpc":"2.0","method":"subscription","params":{"channel":"book.ETH-PERPETUAL.raw","data":{"timestamp":1734114540143,"type":"change","change_id":15557282116,"instrument_name":"ETH-PERPETUAL","bids":[],"asks":[["new",3898.3,8.0e4]],"prev_change_id":15557282115}}}
{"jsonrpc":"2.0","method":"subscription","params":{"channel":"book.ETH-PERPETUAL.raw","data":{"timestamp":1734114540144,"type":"change","change_id":15557282117,"instrument_name":"ETH-PERPETUAL","bids":[["change",3880.35,1.6e5]],"asks":[],"prev_change_id":15557282116}}}
{"jsonrpc":"2.0","method":"subscription","params":{"channel":"book.ETH-PERPETUAL.raw","data":{"timestamp":1734114540144,"type":"change","change_id":15557282117,"instrument_name":"ETH-PERPETUAL","bids":[["change",3880.35,1.6e5]],"asks":[],"prev_change_id":15557282116}}}
{"jsonrpc":"2.0","method":"subscription","params":{"channel":"book.ETH-PERPETUAL.raw","data":{"timestamp":1734114540147,"type":"change","change_id":15557282118,"instrument_name":"ETH-PERPETUAL","bids":[],"asks":[["change",3898.3,1.6e5]],"prev_change_id":15557282117}}}
{"jsonrpc":"2.0","method":"subscription","params":{"channel":"book.ETH-PERPETUAL.raw","data":{"timestamp":1734114540147,"type":"change","change_id":15557282118,"instrument_name":"ETH-PERPETUAL","bids":[],"asks":[["change",3898.3,1.6e5]],"prev_change_id":15557282117}}}
{"jsonrpc":"2.0","method":"subscription","params":{"channel":"book.ETH-PERPETUAL.raw","data":{"timestamp":1734114540148,"type":"change","change_id":15557282119,"instrument_name":"ETH-PERPETUAL","bids":[["change",3880.35,1.8e5]],"asks":[],"prev_change_id":15557282118}}}
{"jsonrpc":"2.0","method":"subscription","params":{"channel":"book.ETH-PERPETUAL.raw","data":{"timestamp":1734114540148,"type":"change","change_id":15557282119,"instrument_name":"ETH-PERPETUAL","bids":[["change",3880.35,1.8e5]],"asks":[],"prev_change_id":15557282118}}}
{"jsonrpc":"2.0","method":"subscription","params":{"channel":"book.ETH-PERPETUAL.raw","data":{"timestamp":1734114540295,"type":"change","change_id":15557282120,"instrument_name":"ETH-PERPETUAL","bids":[["delete",3880.35,0.0]],"asks":[["delete",3898.3,0.0]],"prev_change_id":15557282119}}}
{"jsonrpc":"2.0","method":"subscription","params":{"channel":"book.ETH-PERPETUAL.raw","data":{"timestamp":1734114540295,"type":"change","change_id":15557282120,"instrument_name":"ETH-PERPETUAL","bids":[["delete",3880.35,0.0]],"asks":[["delete",3898.3,0.0]],"prev_change_id":15557282119}}}
{"jsonrpc":"2.0","method":"subscription","params":{"channel":"book.ETH-PERPETUAL.raw","data":{"timestamp":1734114540495,"type":"change","change_id":15557282121,"instrument_name":"ETH-PERPETUAL","bids":[["new",3880.7,8.0e4]],"asks":[],"prev_change_id":15557282120}}}
{"jsonrpc":"2.0","method":"subscription","params":{"channel":"book.ETH-PERPETUAL.raw","data":{"timestamp":1734114540495,"type":"change","change_id":15557282121,"instrument_name":"ETH-PERPETUAL","bids":[["new",3880.7,8.0e4]],"asks":[],"prev_change_id":15557282120}}}
{"jsonrpc":"2.0","method":"subscription","params":{"channel":"book.ETH-PERPETUAL.raw","data":{"timestamp":1734114540497,"type":"change","change_id":15557282123,"instrument_name":"ETH-PERPETUAL","bids":[],"asks":[["new",3898.45,8.0e4]],"prev_change_id":15557282121}}}
{"jsonrpc":"2.0","method":"subscription","params":{"channel":"book.ETH-PERPETUAL.raw","data":{"timestamp":1734114540497,"type":"change","change_id":15557282123,"instrument_name":"ETH-PERPETUAL","bids":[],"asks":[["new",3898.45,8.0e4]],"prev_change_id":15557282121}}}
{"jsonrpc":"2.0","method":"subscription","params":{"channel":"book.ETH-PERPETUAL.raw","data":{"timestamp":1734114540498,"type":"change","change_id":15557282124,"instrument_name":"ETH-PERPETUAL","bids":[["change",3880.7,1.0e5]],"asks":[],"prev_change_id":15557282123}}}
{"jsonrpc":"2.0","method":"subscription","params":{"channel":"book.ETH-PERPETUAL.raw","data":{"timestamp":1734114540498,"type":"change","change_id":15557282124,"instrument_name":"ETH-PERPETUAL","bids":[["change",3880.7,1.0e5]],"asks":[],"prev_change_id":15557282123}}}
{"jsonrpc":"2.0","method":"subscription","params":{"channel":"book.ETH-PERPETUAL.raw","data":{"timestamp":1734114540500,"type":"change","change_id":15557282125,"instrument_name":"ETH-PERPETUAL","bids":[],"asks":[["change",3898.45,1.0e5]],"prev_change_id":15557282124}}}
{"jsonrpc":"2.0","method":"subscription","params":{"channel":"book.ETH-PERPETUAL.raw","data":{"timestamp":1734114540500,"type":"change","change_id":15557282125,"instrument_name":"ETH-PERPETUAL","bids":[],"asks":[["change",3898.45,1.0e5]],"prev_change_id":15557282124}}}
{"jsonrpc":"2.0","method":"subscription","params":{"channel":"book.ETH-PERPETUAL.raw","data":{"timestamp":1734114540501,"type":"change","change_id":15557282126,"instrument_name":"ETH-PERPETUAL","bids":[["change",3880.7,1.8e5]],"asks":[],"prev_change_id":15557282125}}}
{"jsonrpc":"2.0","method":"subscription","params":{"channel":"book.ETH-PERPETUAL.raw","data":{"timestamp":1734114540501,"type":"change","change_id":15557282126,"instrument_name":"ETH-PERPETUAL","bids":[["change",3880.7,1.8e5]],"asks":[],"prev_change_id":15557282125}}}
{"jsonrpc":"2.0","method":"subscription","params":{"channel":"book.ETH-PERPETUAL.raw","data":{"timestamp":1734114540503,"type":"change","change_id":15557282127,"instrument_name":"ETH-PERPETUAL","bids":[],"asks":[["change",3898.45,1.8e5]],"prev_change_id":15557282126}}}
{"jsonrpc":"2.0","method":"subscription","params":{"channel":"book.ETH-PERPETUAL.raw","data":{"timestamp":1734114540503,"type":"change","change_id":15557282127,"instrument_name":"ETH-PERPETUAL","bids":[],"asks":[["change",3898.45,1.8e5]],"prev_change_id":15557282126}}}
{"jsonrpc":"2.0","method":"subscription","params":{"channel":"book.ETH-PERPETUAL.raw","data":{"timestamp":1734114540504,"type":"change","change_id":15557282128,"instrument_name":"ETH-PERPETUAL","bids":[["change",3880.7,2.0e5]],"asks":[],"prev_change_id":15557282127}}}
{"jsonrpc":"2.0","method":"subscription","params":{"channel":"book.ETH-PERPETUAL.raw","data":{"timestamp":1734114540504,"type":"change","change_id":15557282128,"instrument_name":"ETH-PERPETUAL","bids":[["change",3880.7,2.0e5]],"asks":[],"prev_change_id":15557282127}}}
{"jsonrpc":"2.0","method":"subscription","params":{"channel":"book.ETH-PERPETUAL.raw","data":{"timestamp":1734114540506,"type":"change","change_id":15557282129,"instrument_name":"ETH-PERPETUAL","bids":[],"asks":[["change",3898.45,2.0e5]],"prev_change_id":15557282128}}}
{"jsonrpc":"2.0","method":"subscription","params":{"channel":"book.ETH-PERPETUAL.raw","data":{"timestamp":1734114540506,"type":"change","change_id":15557282129,"instrument_name":"ETH-PERPETUAL","bids":[],"asks":[["change",3898.45,2.0e5]],"prev_change_id":15557282128}}}
{"jsonrpc":"2.0","method":"subscription","params":{"channel":"book.ETH-PERPETUAL.raw","data":{"timestamp":1734114540642,"type":"change","change_id":15557282156,"instrument_name":"ETH-PERPETUAL","bids":[["delete",3880.7,0.0]],"asks":[["delete",3898.45,0.0]],"prev_change_id":15557282129}}}
{"jsonrpc":"2.0","method":"subscription","params":{"channel":"book.ETH-PERPETUAL.raw","data":{"timestamp":1734114540642,"type":"change","change_id":15557282156,"instrument_name":"ETH-PERPETUAL","bids":[["delete",3880.7,0.0]],"asks":[["delete",3898.45,0.0]],"prev_change_id":15557282129}}}
{"jsonrpc":"2.0","method":"subscription","params":{"channel":"book.ETH-PERPETUAL.raw","data":{"timestamp":1734114540817,"type":"change","change_id":15557282157,"instrument_name":"ETH-PERPETUAL","bids":[["new",3880.8,8.0e4]],"asks":[],"prev_change_id":15557282156}}}
{"jsonrpc":"2.0","method":"subscription","params":{"channel":"book.ETH-PERPETUAL.raw","data":{"timestamp":1734114540817,"type":"change","change_id":15557282157,"instrument_name":"ETH-PERPETUAL","bids":[["new",3880.8,8.0e4]],"asks":[],"prev_change_id":15557282156}}}
{"jsonrpc":"2.0","method":"subscription","params":{"channel":"book.ETH-PERPETUAL.raw","data":{"timestamp":1734114540819,"type":"change","change_id":15557282158,"instrument_name":"ETH-PERPETUAL","bids":[],"asks":[["new",3898.35,8.0e4]],"prev_change_id":15557282157}}}
{"jsonrpc":"2.0","method":"subscription","params":{"channel":"book.ETH-PERPETUAL.raw","data":{"timestamp":1734114540819,"type":"change","change_id":15557282158,"instrument_name":"ETH-PERPETUAL","bids":[],"asks":[["new",3898.35,8.0e4]],"prev_change_id":15557282157}}}
{"jsonrpc":"2.0","method":"subscription","params":{"channel":"book.ETH-PERPETUAL.raw","data":{"timestamp":1734114540820,"type":"change","change_id":15557282159,"instrument_name":"ETH-PERPETUAL","bids":[["change",3880.8,1.6e5]],"asks":[],"prev_change_id":15557282158}}}
{"jsonrpc":"2.0","method":"subscription","params":{"channel":"book.ETH-PERPETUAL.raw","data":{"timestamp":1734114540820,"type":"change","change_id":15557282159,"instrument_name":"ETH-PERPETUAL","bids":[["change",3880.8,1.6e5]],"asks":[],"prev_change_id":15557282158}}}
{"jsonrpc":"2.0","method":"subscription","params":{"channel":"book.ETH-PERPETUAL.raw","data":{"timestamp":1734114540822,"type":"change","change_id":15557282160,"instrument_name":"ETH-PERPETUAL","bids":[],"asks":[["change",3898.35,1.6e5]],"prev_change_id":15557282159}}}
{"jsonrpc":"2.0","method":"subscription","params":{"channel":"book.ETH-PERPETUAL.raw","data":{"timestamp":1734114540822,"type":"change","change_id":15557282160,"instrument_name":"ETH-PERPETUAL","bids":[],"asks":[["change",3898.35,1.6e5]],"prev_change_id":15557282159}}}
{"jsonrpc":"2.0","method":"subscription","params":{"channel":"book.ETH-PERPETUAL.raw","data":{"timestamp":1734114540967,"type":"change","change_id":15557282161,"instrument_name":"ETH-PERPETUAL","bids":[["delete",3880.8,0.0]],"asks":[["delete",3898.35,0.0]],"prev_change_id":15557282160}}}
{"jsonrpc":"2.0","method":"subscription","params":{"channel":"book.ETH-PERPETUAL.raw","data":{"timestamp":1734114540967,"type":"change","change_id":15557282161,"instrument_name":"ETH-PERPETUAL","bids":[["delete",3880.8,0.0]],"asks":[["delete",3898.35,0.0]],"prev_change_id":15557282160}}}
{"jsonrpc":"2.0","method":"subscription","params":{"channel":"book.ETH-PERPETUAL.raw","data":{"timestamp":1734114541168,"type":"change","change_id":15557282162,"instrument_name":"ETH-PERPETUAL","bids":[["new",3880.85,8.0e4]],"asks":[],"prev_change_id":15557282161}}}
{"jsonrpc":"2.0","method":"subscription","params":{"channel":"book.ETH-PERPETUAL.raw","data":{"timestamp":1734114541168,"type":"change","change_id":15557282162,"instrument_name":"ETH-PERPETUAL","bids":[["new",3880.85,8.0e4]],"asks":[],"prev_change_id":15557282161}}}
